2022-04-06 14:35:54 WARNING (SyncWorker_0) [homeassistant.loader] We found a custom integration xiaomi_miio_airpurifier which has not been tested by Home Assistant. This component might cause stability problems, be sure to disable it if you experience issues with Home Assistant
2022-04-06 14:35:54 WARNING (SyncWorker_1) [homeassistant.loader] We found a custom integration average which has not been tested by Home Assistant. This component might cause stability problems, be sure to disable it if you experience issues with Home Assistant
2022-04-06 14:35:54 WARNING (SyncWorker_5) [homeassistant.loader] We found a custom integration monitor_docker which has not been tested by Home Assistant. This component might cause stability problems, be sure to disable it if you experience issues with Home Assistant
2022-04-06 14:35:54 WARNING (SyncWorker_13) [homeassistant.loader] We found a custom integration buienalarm which has not been tested by Home Assistant. This component might cause stability problems, be sure to disable it if you experience issues with Home Assistant
2022-04-06 14:35:54 WARNING (SyncWorker_6) [homeassistant.loader] We found a custom integration hacs which has not been tested by Home Assistant. This component might cause stability problems, be sure to disable it if you experience issues with Home Assistant
2022-04-06 14:35:54 WARNING (SyncWorker_4) [homeassistant.loader] We found a custom integration powercalc which has not been tested by Home Assistant. This component might cause stability problems, be sure to disable it if you experience issues with Home Assistant
2022-04-06 14:35:54 WARNING (SyncWorker_2) [homeassistant.loader] We found a custom integration adaptive_lighting which has not been tested by Home Assistant. This component might cause stability problems, be sure to disable it if you experience issues with Home Assistant
2022-04-06 14:35:54 WARNING (SyncWorker_11) [homeassistant.loader] We found a custom integration iphonedetect which has not been tested by Home Assistant. This component might cause stability problems, be sure to disable it if you experience issues with Home Assistant
2022-04-06 14:35:54 WARNING (SyncWorker_18) [homeassistant.loader] We found a custom integration xiaomi_miio_fan which has not been tested by Home Assistant. This component might cause stability problems, be sure to disable it if you experience issues with Home Assistant
2022-04-06 14:35:54 WARNING (SyncWorker_12) [homeassistant.loader] We found a custom integration huesyncbox which has not been tested by Home Assistant. This component might cause stability problems, be sure to disable it if you experience issues with Home Assistant
2022-04-06 14:35:54 WARNING (SyncWorker_16) [homeassistant.loader] We found a custom integration googlewifi which has not been tested by Home Assistant. This component might cause stability problems, be sure to disable it if you experience issues with Home Assistant
2022-04-06 14:35:54 WARNING (SyncWorker_3) [homeassistant.loader] We found a custom integration audiconnect which has not been tested by Home Assistant. This component might cause stability problems, be sure to disable it if you experience issues with Home Assistant
2022-04-06 14:35:54 WARNING (SyncWorker_15) [homeassistant.loader] We found a custom integration xiaomi_miot which has not been tested by Home Assistant. This component might cause stability problems, be sure to disable it if you experience issues with Home Assistant
2022-04-06 14:35:54 WARNING (SyncWorker_7) [homeassistant.loader] We found a custom integration localtuya which has not been tested by Home Assistant. This component might cause stability problems, be sure to disable it if you experience issues with Home Assistant
2022-04-06 14:35:54 WARNING (SyncWorker_22) [homeassistant.loader] We found a custom integration afvalbeheer which has not been tested by Home Assistant. This component might cause stability problems, be sure to disable it if you experience issues with Home Assistant
2022-04-06 14:35:54 WARNING (SyncWorker_19) [homeassistant.loader] We found a custom integration neerslag which has not been tested by Home Assistant. This component might cause stability problems, be sure to disable it if you experience issues with Home Assistant
2022-04-06 14:35:54 WARNING (SyncWorker_9) [homeassistant.loader] We found a custom integration tuya_v2 which has not been tested by Home Assistant. This component might cause stability problems, be sure to disable it if you experience issues with Home Assistant
2022-04-06 14:35:54 WARNING (SyncWorker_14) [homeassistant.loader] We found a custom integration thermal_comfort which has not been tested by Home Assistant. This component might cause stability problems, be sure to disable it if you experience issues with Home Assistant
2022-04-06 14:35:54 WARNING (SyncWorker_10) [homeassistant.loader] We found a custom integration battery_sim which has not been tested by Home Assistant. This component might cause stability problems, be sure to disable it if you experience issues with Home Assistant
2022-04-06 14:35:54 WARNING (SyncWorker_8) [homeassistant.loader] We found a custom integration xiaomi_miio_fan which has not been tested by Home Assistant. This component might cause stability problems, be sure to disable it if you experience issues with Home Assistant
2022-04-06 14:35:54 WARNING (SyncWorker_17) [homeassistant.loader] We found a custom integration anniversaries which has not been tested by Home Assistant. This component might cause stability problems, be sure to disable it if you experience issues with Home Assistant
2022-04-06 14:35:54 WARNING (SyncWorker_21) [homeassistant.loader] We found a custom integration google_home which has not been tested by Home Assistant. This component might cause stability problems, be sure to disable it if you experience issues with Home Assistant
2022-04-06 14:35:54 WARNING (SyncWorker_20) [homeassistant.loader] We found a custom integration ytube_music_player which has not been tested by Home Assistant. This component might cause stability problems, be sure to disable it if you experience issues with Home Assistant
2022-04-06 14:36:05 ERROR (MainThread) [homeassistant.config] Invalid config for [automation]: template value should be a string for dictionary value @ data['action'][0]['data']. Got None. (See ?, line ?). 
2022-04-06 14:36:06 ERROR (MainThread) [homeassistant.config] Invalid config for [automation]: required key not provided @ data['action']. Got None
required key not provided @ data['trigger']. Got None. (See ?, line ?). 
2022-04-06 14:36:07 ERROR (MainThread) [homeassistant.config] Invalid config for [automation]: template value should be a string for dictionary value @ data['action'][0]['data']. Got None. (See ?, line ?). 
2022-04-06 14:36:43 ERROR (MainThread) [homeassistant.components.websocket_api.http.connection] [281472739230864] Received invalid command: mobile_app/push_notification_channel
2022-04-06 14:37:36 WARNING (MainThread) [homeassistant.bootstrap] Waiting on integrations to complete setup: radio_browser, ytube_music_player, rpi_power, xiaomi_miio
2022-04-06 14:37:42 WARNING (MainThread) [homeassistant.config_entries] Config entry 'Fan 2' for xiaomi_miio integration not ready yet: Unable to discover the device 192.168.86.46; Retrying in background
2022-04-06 14:37:42 WARNING (MainThread) [homeassistant.config_entries] Config entry 'Fan 1' for xiaomi_miio integration not ready yet: Unable to discover the device 192.168.86.28; Retrying in background
2022-04-06 14:37:45 ERROR (MainThread) [custom_components.audiconnect.audi_connect_account] Unable to obtain the vehicle longTerm tripdata of WAUZZZGE6MB019131: 'NoneType' object is not subscriptable
2022-04-06 14:37:46 ERROR (MainThread) [custom_components.audiconnect.audi_connect_account] support_preheater set to False: 502
2022-04-06 14:38:42 WARNING (MainThread) [homeassistant.bootstrap] Waiting on integrations to complete setup: huesyncbox, hacs, forecast_solar, synology_dsm, speedtestdotnet, brother, weather.buienradar, openweathermap, camera
2022-04-06 14:38:45 WARNING (MainThread) [homeassistant.config_entries] Config entry '192.168.86.83' for synology_dsm integration not ready yet: ConnectionError = <urllib3.connection.HTTPSConnection object at 0xffff74f35790>: Failed to establish a new connection: [Errno 113] Host is unreachable; Retrying in background
2022-04-06 14:38:46 ERROR (MainThread) [homeassistant.components.version] Unexpected error fetching version data: Invalid control character at: line 7 column 177 (char 454)
Traceback (most recent call last):
  File "/usr/src/homeassistant/homeassistant/helpers/update_coordinator.py", line 190, in _async_refresh
    self.data = await self._async_update_data()
  File "/usr/src/homeassistant/homeassistant/components/version/coordinator.py", line 53, in _async_update_data
    self._version, self._version_data = await self._api.get_version()
  File "/usr/local/lib/python3.9/site-packages/pyhaversion/version.py", line 89, in get_version
    await self._handler.fetch(etag=etag)
  File "/usr/local/lib/python3.9/site-packages/pyhaversion/haio.py", line 41, in fetch
    self._data = await request.json()
  File "/usr/local/lib/python3.9/site-packages/aiohttp/client_reqrep.py", line 1119, in json
    return loads(stripped.decode(encoding))
  File "/usr/local/lib/python3.9/json/__init__.py", line 346, in loads
    return _default_decoder.decode(s)
  File "/usr/local/lib/python3.9/json/decoder.py", line 337, in decode
    obj, end = self.raw_decode(s, idx=_w(s, 0).end())
  File "/usr/local/lib/python3.9/json/decoder.py", line 353, in raw_decode
    obj, end = self.scan_once(s, idx)
json.decoder.JSONDecodeError: Invalid control character at: line 7 column 177 (char 454)
2022-04-06 14:38:46 WARNING (MainThread) [homeassistant.config_entries] Config entry 'Home Assistant Website' for version integration not ready yet: Invalid control character at: line 7 column 177 (char 454); Retrying in background
2022-04-06 14:38:54 ERROR (MainThread) [homeassistant.components.websocket_api.http.connection] [281472625720864] Received invalid command: mobile_app/push_notification_channel
2022-04-06 14:39:38 ERROR (SyncWorker_22) [homeassistant.util.package] Unable to install package grpcio==1.44.0: ERROR: Cannot install grpcio==1.44.0 because these package versions have conflicting dependencies.
ERROR: ResolutionImpossible: for help visit https://pip.pypa.io/en/latest/topics/dependency-resolution/#dealing-with-dependency-conflicts
WARNING: You are using pip version 22.0.3; however, version 22.0.4 is available.
You should consider upgrading via the '/usr/local/bin/python3 -m pip install --upgrade pip' command.
2022-04-06 14:39:50 ERROR (SyncWorker_4) [homeassistant.util.package] Unable to install package grpcio==1.44.0: ERROR: Cannot install grpcio==1.44.0 because these package versions have conflicting dependencies.
ERROR: ResolutionImpossible: for help visit https://pip.pypa.io/en/latest/topics/dependency-resolution/#dealing-with-dependency-conflicts
WARNING: You are using pip version 22.0.3; however, version 22.0.4 is available.
You should consider upgrading via the '/usr/local/bin/python3 -m pip install --upgrade pip' command.
2022-04-06 14:40:03 ERROR (SyncWorker_21) [homeassistant.util.package] Unable to install package grpcio==1.44.0: ERROR: Cannot install grpcio==1.44.0 because these package versions have conflicting dependencies.
ERROR: ResolutionImpossible: for help visit https://pip.pypa.io/en/latest/topics/dependency-resolution/#dealing-with-dependency-conflicts
WARNING: You are using pip version 22.0.3; however, version 22.0.4 is available.
You should consider upgrading via the '/usr/local/bin/python3 -m pip install --upgrade pip' command.
2022-04-06 14:40:03 ERROR (MainThread) [homeassistant.setup] Setup failed for custom integration googlewifi: Requirements for googlewifi not found: ['grpcio==1.44.0'].
2022-04-06 14:40:05 WARNING (MainThread) [homeassistant.bootstrap] Waiting on integrations to complete setup: tts, mobile_app, binary_sensor.template, binary_sensor.template_2, binary_sensor.template_3, binary_sensor.template_4, binary_sensor.trend, dlna_dmr, ping, binary_sensor.tado, binary_sensor.rpi_power, binary_sensor.xiaomi_miio, binary_sensor.pi_hole, binary_sensor.hue, binary_sensor.hue_2, binary_sensor.audiconnect, binary_sensor.nuki, binary_sensor.deconz, tuya, netatmo, dlna_dms, automation
2022-04-06 14:40:08 WARNING (MainThread) [homeassistant.components.media_player] Updating huesyncbox media_player took longer than the scheduled update interval 0:00:02
2022-04-06 14:40:19 WARNING (MainThread) [homeassistant.setup] Setup of default_config is taking over 10 seconds.
2022-04-06 14:40:37 WARNING (MainThread) [homeassistant.components.filesize.sensor] Configuration of the Filesize sensor platform in YAML is deprecated and will be removed in Home Assistant 2022.6; Your existing configuration has been imported into the UI automatically and can be safely removed from your configuration.yaml file
2022-04-06 14:40:37 ERROR (MainThread) [custom_components.powercalc.sensors.power] Skipping sensor setup light.amilya_plafond: Model not found in library (manufacturer: Signify Netherlands B.V., model: Room)
2022-04-06 14:40:37 ERROR (MainThread) [custom_components.powercalc.sensors.power] Skipping sensor setup light.amilya_staande_lamp: Model not found in library (manufacturer: Signify Netherlands B.V., model: Room)
2022-04-06 14:40:37 ERROR (MainThread) [custom_components.powercalc.sensors.power] Skipping sensor setup light.buiten: ('No lookup file found for mode', 'brightness')
2022-04-06 14:40:38 WARNING (MainThread) [homeassistant.components.sensor] Platform netatmo not ready yet: None; Retrying in background in 30 seconds
2022-04-06 14:40:39 ERROR (MainThread) [homeassistant.components.sensor] Error adding entities for domain sensor with platform audiconnect
Traceback (most recent call last):
  File "/usr/src/homeassistant/homeassistant/helpers/entity_platform.py", line 382, in async_add_entities
    await asyncio.gather(*tasks)
  File "/usr/src/homeassistant/homeassistant/helpers/entity_platform.py", line 614, in _async_add_entity
    await entity.add_to_platform_finish()
  File "/usr/src/homeassistant/homeassistant/helpers/entity.py", line 792, in add_to_platform_finish
    self.async_write_ha_state()
  File "/usr/src/homeassistant/homeassistant/helpers/entity.py", line 525, in async_write_ha_state
    self._async_write_ha_state()
  File "/usr/src/homeassistant/homeassistant/helpers/entity.py", line 672, in _async_write_ha_state
    self.hass.states.async_set(
  File "/usr/src/homeassistant/homeassistant/core.py", line 1361, in async_set
    state = State(
  File "/usr/src/homeassistant/homeassistant/core.py", line 1047, in __init__
    raise InvalidStateError(
homeassistant.exceptions.InvalidStateError: Invalid state encountered for entity ID: sensor.audi_e_tron_sportback_shortterm_trip_user_reset. State max length is 255 characters.
2022-04-06 14:40:39 WARNING (MainThread) [homeassistant.components.binary_sensor] Updating ping binary_sensor took longer than the scheduled update interval 0:00:05
2022-04-06 14:40:39 ERROR (MainThread) [homeassistant.components.sensor] Error while setting up audiconnect platform for sensor
Traceback (most recent call last):
  File "/usr/src/homeassistant/homeassistant/helpers/entity_platform.py", line 257, in _async_setup_platform
    await asyncio.gather(*pending)
  File "/usr/src/homeassistant/homeassistant/helpers/entity_platform.py", line 382, in async_add_entities
    await asyncio.gather(*tasks)
  File "/usr/src/homeassistant/homeassistant/helpers/entity_platform.py", line 614, in _async_add_entity
    await entity.add_to_platform_finish()
  File "/usr/src/homeassistant/homeassistant/helpers/entity.py", line 792, in add_to_platform_finish
    self.async_write_ha_state()
  File "/usr/src/homeassistant/homeassistant/helpers/entity.py", line 525, in async_write_ha_state
    self._async_write_ha_state()
  File "/usr/src/homeassistant/homeassistant/helpers/entity.py", line 672, in _async_write_ha_state
    self.hass.states.async_set(
  File "/usr/src/homeassistant/homeassistant/core.py", line 1361, in async_set
    state = State(
  File "/usr/src/homeassistant/homeassistant/core.py", line 1047, in __init__
    raise InvalidStateError(
homeassistant.exceptions.InvalidStateError: Invalid state encountered for entity ID: sensor.audi_e_tron_sportback_shortterm_trip_user_reset. State max length is 255 characters.
2022-04-06 14:40:39 WARNING (MainThread) [homeassistant.components.integration.sensor] Could not restore last state: [<class 'decimal.ConversionSyntax'>]
2022-04-06 14:40:39 WARNING (MainThread) [homeassistant.components.integration.sensor] Could not restore last state: [<class 'decimal.ConversionSyntax'>]
2022-04-06 14:40:39 WARNING (MainThread) [homeassistant.components.integration.sensor] Could not restore last state: [<class 'decimal.ConversionSyntax'>]
2022-04-06 14:40:40 WARNING (MainThread) [homeassistant.components.integration.sensor] Could not restore last state: [<class 'decimal.ConversionSyntax'>]
2022-04-06 14:40:41 ERROR (SyncWorker_16) [homeassistant.components.modbus.modbus] Pymodbus: laadpaal: Modbus Error: [Connection] ModbusTcpClient(192.168.1.4:502): Connection unexpectedly closed 0.010350 seconds into read of 8 bytes without response from unit before it closed connection
2022-04-06 14:40:46 ERROR (MainThread) [homeassistant.components.sensor] scrape: Error on device update!
Traceback (most recent call last):
  File "/usr/src/homeassistant/homeassistant/helpers/entity_platform.py", line 431, in _async_add_entity
    await entity.async_device_update(warning=False)
  File "/usr/src/homeassistant/homeassistant/helpers/entity.py", line 728, in async_device_update
    await task
  File "/usr/src/homeassistant/homeassistant/components/scrape/sensor.py", line 183, in async_update
    await self._async_update_from_rest_data()
  File "/usr/src/homeassistant/homeassistant/components/scrape/sensor.py", line 195, in _async_update_from_rest_data
    value = await self.hass.async_add_executor_job(self._extract_value)
  File "/usr/local/lib/python3.9/concurrent/futures/thread.py", line 58, in run
    result = self.fn(*self.args, **self.kwargs)
  File "/usr/src/homeassistant/homeassistant/components/scrape/sensor.py", line 164, in _extract_value
    tag = raw_data.select(self._select)[self._index]
  File "/usr/local/lib/python3.9/site-packages/bs4/element.py", line 1949, in select
    results = soupsieve.select(selector, self, namespaces, limit, **kwargs)
  File "/usr/local/lib/python3.9/site-packages/soupsieve/__init__.py", line 144, in select
    return compile(select, namespaces, flags, **kwargs).select(tag, limit)
  File "/usr/local/lib/python3.9/site-packages/soupsieve/__init__.py", line 67, in compile
    return cp._cached_css_compile(pattern, ns, cs, flags)
  File "/usr/local/lib/python3.9/site-packages/soupsieve/css_parser.py", line 218, in _cached_css_compile
    CSSParser(
  File "/usr/local/lib/python3.9/site-packages/soupsieve/css_parser.py", line 1159, in process_selectors
    return self.parse_selectors(self.selector_iter(self.pattern), index, flags)
  File "/usr/local/lib/python3.9/site-packages/soupsieve/css_parser.py", line 985, in parse_selectors
    key, m = next(iselector)
  File "/usr/local/lib/python3.9/site-packages/soupsieve/css_parser.py", line 1152, in selector_iter
    raise SelectorSyntaxError(msg, self.pattern, index)
soupsieve.util.SelectorSyntaxError: Invalid character '<' position 0
  line 1:
<span _ngcontent-app-root-c173="">Offline</span>
^
2022-04-06 14:40:47 WARNING (MainThread) [homeassistant.components.sensor] Setup of sensor platform scrape is taking over 10 seconds.
2022-04-06 14:40:47 WARNING (MainThread) [homeassistant.components.sensor] Setup of sensor platform scrape is taking over 10 seconds.
2022-04-06 14:40:49 WARNING (MainThread) [homeassistant.components.binary_sensor] Updating ping binary_sensor took longer than the scheduled update interval 0:00:05
2022-04-06 14:40:51 WARNING (Recorder) [homeassistant.components.recorder.migration] Database is about to upgrade. Schema version: 24
2022-04-06 14:40:51 WARNING (Recorder) [homeassistant.components.recorder.migration] Adding columns attributes_id to table states. Note: this can take several minutes on large databases and slow computers. Please be patient!
2022-04-06 14:40:52 WARNING (Recorder) [homeassistant.components.recorder.migration] Adding index `ix_states_attributes_id` to database. Note: this can take several minutes on large databases and slow computers. Please be patient!
2022-04-06 14:40:53 ERROR (MainThread) [homeassistant.components.automation.elek_set_the_chargepoint_current] Error setting up trigger [elek] Set the chargepoint current
Traceback (most recent call last):
  File "/usr/src/homeassistant/homeassistant/components/mqtt/trigger.py", line 90, in async_attach_trigger
    remove = await mqtt.async_subscribe(
  File "/usr/src/homeassistant/homeassistant/components/mqtt/__init__.py", line 559, in async_subscribe
    async_remove = await hass.data[DATA_MQTT].async_subscribe(
KeyError: 'mqtt'
2022-04-06 14:40:55 WARNING (MainThread) [homeassistant.components.media_player] Updating huesyncbox media_player took longer than the scheduled update interval 0:00:02
2022-04-06 14:41:11 ERROR (MainThread) [homeassistant.components.xiaomi_miio] Timeout fetching Mi Air data
2022-04-06 14:41:11 ERROR (MainThread) [homeassistant.components.mobile_app.notify] Timeout sending notification to https://mobile-apps.home-assistant.io/api/sendPush/android/v1
2022-04-06 14:41:11 ERROR (MainThread) [homeassistant] Error doing job: Task exception was never retrieved
Traceback (most recent call last):
  File "/usr/src/homeassistant/homeassistant/components/netatmo/__init__.py", line 198, in register_webhook
    await hass.data[DOMAIN][entry.entry_id][AUTH].async_addwebhook(webhook_url)
  File "/usr/local/lib/python3.9/site-packages/pyatmo/auth.py", line 377, in async_addwebhook
    resp = await self.async_post_request(WEBHOOK_URL_ADD, {"url": webhook_url})
  File "/usr/local/lib/python3.9/site-packages/pyatmo/auth.py", line 335, in async_post_request
    async with self.websession.post(
  File "/usr/local/lib/python3.9/site-packages/aiohttp/client.py", line 1138, in __aenter__
    self._resp = await self._coro
  File "/usr/local/lib/python3.9/site-packages/aiohttp/client.py", line 634, in _request
    break
  File "/usr/local/lib/python3.9/site-packages/aiohttp/helpers.py", line 721, in __exit__
    raise asyncio.TimeoutError from None
asyncio.exceptions.TimeoutError
2022-04-06 14:41:11 WARNING (MainThread) [homeassistant.components.binary_sensor] Updating ping binary_sensor took longer than the scheduled update interval 0:00:05
2022-04-06 14:41:11 WARNING (MainThread) [homeassistant.helpers.entity] Update of binary_sensor.google_server is taking over 10 seconds
2022-04-06 14:41:11 WARNING (MainThread) [homeassistant.components.media_player] Updating samsungtv media_player took longer than the scheduled update interval 0:00:10
2022-04-06 14:41:13 WARNING (MainThread) [homeassistant.components.media_player] Updating huesyncbox media_player took longer than the scheduled update interval 0:00:02
2022-04-06 14:41:18 WARNING (MainThread) [homeassistant.components.media_player] Updating huesyncbox media_player took longer than the scheduled update interval 0:00:02
2022-04-06 14:41:18 WARNING (MainThread) [homeassistant.components.binary_sensor] Updating ping binary_sensor took longer than the scheduled update interval 0:00:05
2022-04-06 14:41:21 ERROR (MainThread) [homeassistant.components.version] Unexpected error fetching version data: Invalid control character at: line 7 column 177 (char 454)
Traceback (most recent call last):
  File "/usr/src/homeassistant/homeassistant/helpers/update_coordinator.py", line 190, in _async_refresh
    self.data = await self._async_update_data()
  File "/usr/src/homeassistant/homeassistant/components/version/coordinator.py", line 53, in _async_update_data
    self._version, self._version_data = await self._api.get_version()
  File "/usr/local/lib/python3.9/site-packages/pyhaversion/version.py", line 89, in get_version
    await self._handler.fetch(etag=etag)
  File "/usr/local/lib/python3.9/site-packages/pyhaversion/haio.py", line 41, in fetch
    self._data = await request.json()
  File "/usr/local/lib/python3.9/site-packages/aiohttp/client_reqrep.py", line 1119, in json
    return loads(stripped.decode(encoding))
  File "/usr/local/lib/python3.9/json/__init__.py", line 346, in loads
    return _default_decoder.decode(s)
  File "/usr/local/lib/python3.9/json/decoder.py", line 337, in decode
    obj, end = self.raw_decode(s, idx=_w(s, 0).end())
  File "/usr/local/lib/python3.9/json/decoder.py", line 353, in raw_decode
    obj, end = self.scan_once(s, idx)
json.decoder.JSONDecodeError: Invalid control character at: line 7 column 177 (char 454)
2022-04-06 14:41:22 WARNING (MainThread) [homeassistant.components.media_player] Updating huesyncbox media_player took longer than the scheduled update interval 0:00:02
2022-04-06 14:41:41 ERROR (MainThread) [homeassistant.components.version] Unexpected error fetching version data: Invalid control character at: line 7 column 177 (char 454)
Traceback (most recent call last):
  File "/usr/src/homeassistant/homeassistant/helpers/update_coordinator.py", line 190, in _async_refresh
    self.data = await self._async_update_data()
  File "/usr/src/homeassistant/homeassistant/components/version/coordinator.py", line 53, in _async_update_data
    self._version, self._version_data = await self._api.get_version()
  File "/usr/local/lib/python3.9/site-packages/pyhaversion/version.py", line 89, in get_version
    await self._handler.fetch(etag=etag)
  File "/usr/local/lib/python3.9/site-packages/pyhaversion/haio.py", line 41, in fetch
    self._data = await request.json()
  File "/usr/local/lib/python3.9/site-packages/aiohttp/client_reqrep.py", line 1119, in json
    return loads(stripped.decode(encoding))
  File "/usr/local/lib/python3.9/json/__init__.py", line 346, in loads
    return _default_decoder.decode(s)
  File "/usr/local/lib/python3.9/json/decoder.py", line 337, in decode
    obj, end = self.raw_decode(s, idx=_w(s, 0).end())
  File "/usr/local/lib/python3.9/json/decoder.py", line 353, in raw_decode
    obj, end = self.scan_once(s, idx)
json.decoder.JSONDecodeError: Invalid control character at: line 7 column 177 (char 454)
2022-04-06 14:41:42 WARNING (MainThread) [homeassistant.components.recorder] Database currently not locked
2022-04-06 14:41:42 ERROR (MainThread) [homeassistant.components.websocket_api.http.connection] [281472737578624] Error handling message: Could not release database write lock (unknown_error)
2022-04-06 14:41:49 WARNING (Recorder) [homeassistant.components.sensor.recorder] sensor.living_alle_lichten_power has unit None which is unsupported for device_class power
2022-04-06 14:41:49 WARNING (Recorder) [homeassistant.components.sensor.recorder] sensor.living_alle_lichten_energy has unit None which is unsupported for device_class energy
2022-04-06 14:41:49 WARNING (Recorder) [homeassistant.components.sensor.recorder] sensor.amilya_alle_lichten_power has unit None which is unsupported for device_class power
2022-04-06 14:41:49 WARNING (Recorder) [homeassistant.components.sensor.recorder] sensor.amilya_alle_lichten_energy has unit None which is unsupported for device_class energy
2022-04-06 14:41:49 WARNING (Recorder) [homeassistant.components.sensor.recorder] sensor.alunya_alle_lichten_power has unit None which is unsupported for device_class power
2022-04-06 14:41:49 WARNING (Recorder) [homeassistant.components.sensor.recorder] sensor.alunya_alle_lichten_energy has unit None which is unsupported for device_class energy
2022-04-06 14:41:49 WARNING (Recorder) [homeassistant.components.sensor.recorder] sensor.master_bedroom_alle_lichten_power has unit None which is unsupported for device_class power
2022-04-06 14:41:49 WARNING (Recorder) [homeassistant.components.sensor.recorder] sensor.master_bedroom_alle_lichten_energy has unit None which is unsupported for device_class energy
2022-04-06 14:41:49 WARNING (Recorder) [homeassistant.components.sensor.recorder] sensor.master_bedroom_play_bar_lights_power has unit None which is unsupported for device_class power
2022-04-06 14:41:49 WARNING (Recorder) [homeassistant.components.sensor.recorder] sensor.master_bedroom_play_bar_lights_energy has unit None which is unsupported for device_class energy
2022-04-06 14:41:49 WARNING (Recorder) [homeassistant.components.sensor.recorder] sensor.unload_battery has unit None which is unsupported for device_class energy
2022-04-06 14:41:49 WARNING (Recorder) [homeassistant.components.sensor.recorder] sensor.zonnepanelen_sim has unit None which is unsupported for device_class energy
2022-04-06 14:41:54 ERROR (MainThread) [homeassistant.util.logging] Exception in async_schedule_update_ha_state when dispatching 'audiconnect.updated': ()
Traceback (most recent call last):
  File "/usr/src/homeassistant/homeassistant/helpers/entity.py", line 703, in async_schedule_update_ha_state
    self.async_write_ha_state()
  File "/usr/src/homeassistant/homeassistant/helpers/entity.py", line 525, in async_write_ha_state
    self._async_write_ha_state()
  File "/usr/src/homeassistant/homeassistant/helpers/entity.py", line 672, in _async_write_ha_state
    self.hass.states.async_set(
  File "/usr/src/homeassistant/homeassistant/core.py", line 1361, in async_set
    state = State(
  File "/usr/src/homeassistant/homeassistant/core.py", line 1047, in __init__
    raise InvalidStateError(
homeassistant.exceptions.InvalidStateError: Invalid state encountered for entity ID: sensor.audi_e_tron_sportback_shortterm_trip_user_reset. State max length is 255 characters.

2022-04-06 14:41:54 ERROR (MainThread) [homeassistant.util.logging] Exception in async_schedule_update_ha_state when dispatching 'audiconnect.updated': ()
Traceback (most recent call last):
  File "/usr/src/homeassistant/homeassistant/helpers/entity.py", line 703, in async_schedule_update_ha_state
    self.async_write_ha_state()
  File "/usr/src/homeassistant/homeassistant/helpers/entity.py", line 525, in async_write_ha_state
    self._async_write_ha_state()
  File "/usr/src/homeassistant/homeassistant/helpers/entity.py", line 672, in _async_write_ha_state
    self.hass.states.async_set(
  File "/usr/src/homeassistant/homeassistant/core.py", line 1361, in async_set
    state = State(
  File "/usr/src/homeassistant/homeassistant/core.py", line 1047, in __init__
    raise InvalidStateError(
homeassistant.exceptions.InvalidStateError: Invalid state encountered for entity ID: sensor.audi_e_tron_sportback_shortterm_trip_data. State max length is 255 characters.

2022-04-06 14:42:21 ERROR (MainThread) [homeassistant.components.version] Unexpected error fetching version data: Invalid control character at: line 7 column 177 (char 454)
Traceback (most recent call last):
  File "/usr/src/homeassistant/homeassistant/helpers/update_coordinator.py", line 190, in _async_refresh
    self.data = await self._async_update_data()
  File "/usr/src/homeassistant/homeassistant/components/version/coordinator.py", line 53, in _async_update_data
    self._version, self._version_data = await self._api.get_version()
  File "/usr/local/lib/python3.9/site-packages/pyhaversion/version.py", line 89, in get_version
    await self._handler.fetch(etag=etag)
  File "/usr/local/lib/python3.9/site-packages/pyhaversion/haio.py", line 41, in fetch
    self._data = await request.json()
  File "/usr/local/lib/python3.9/site-packages/aiohttp/client_reqrep.py", line 1119, in json
    return loads(stripped.decode(encoding))
  File "/usr/local/lib/python3.9/json/__init__.py", line 346, in loads
    return _default_decoder.decode(s)
  File "/usr/local/lib/python3.9/json/decoder.py", line 337, in decode
    obj, end = self.raw_decode(s, idx=_w(s, 0).end())
  File "/usr/local/lib/python3.9/json/decoder.py", line 353, in raw_decode
    obj, end = self.scan_once(s, idx)
json.decoder.JSONDecodeError: Invalid control character at: line 7 column 177 (char 454)
2022-04-06 14:43:41 ERROR (MainThread) [homeassistant.components.version] Unexpected error fetching version data: Invalid control character at: line 7 column 177 (char 454)
Traceback (most recent call last):
  File "/usr/src/homeassistant/homeassistant/helpers/update_coordinator.py", line 190, in _async_refresh
    self.data = await self._async_update_data()
  File "/usr/src/homeassistant/homeassistant/components/version/coordinator.py", line 53, in _async_update_data
    self._version, self._version_data = await self._api.get_version()
  File "/usr/local/lib/python3.9/site-packages/pyhaversion/version.py", line 89, in get_version
    await self._handler.fetch(etag=etag)
  File "/usr/local/lib/python3.9/site-packages/pyhaversion/haio.py", line 41, in fetch
    self._data = await request.json()
  File "/usr/local/lib/python3.9/site-packages/aiohttp/client_reqrep.py", line 1119, in json
    return loads(stripped.decode(encoding))
  File "/usr/local/lib/python3.9/json/__init__.py", line 346, in loads
    return _default_decoder.decode(s)
  File "/usr/local/lib/python3.9/json/decoder.py", line 337, in decode
    obj, end = self.raw_decode(s, idx=_w(s, 0).end())
  File "/usr/local/lib/python3.9/json/decoder.py", line 353, in raw_decode
    obj, end = self.scan_once(s, idx)
json.decoder.JSONDecodeError: Invalid control character at: line 7 column 177 (char 454)
2022-04-06 14:43:58 ERROR (MainThread) [homeassistant.util.logging] Exception in async_schedule_update_ha_state when dispatching 'audiconnect.updated': ()
Traceback (most recent call last):
  File "/usr/src/homeassistant/homeassistant/helpers/entity.py", line 703, in async_schedule_update_ha_state
    self.async_write_ha_state()
  File "/usr/src/homeassistant/homeassistant/helpers/entity.py", line 525, in async_write_ha_state
    self._async_write_ha_state()
  File "/usr/src/homeassistant/homeassistant/helpers/entity.py", line 672, in _async_write_ha_state
    self.hass.states.async_set(
  File "/usr/src/homeassistant/homeassistant/core.py", line 1361, in async_set
    state = State(
  File "/usr/src/homeassistant/homeassistant/core.py", line 1047, in __init__
    raise InvalidStateError(
homeassistant.exceptions.InvalidStateError: Invalid state encountered for entity ID: sensor.audi_e_tron_sportback_shortterm_trip_user_reset. State max length is 255 characters.

2022-04-06 14:43:58 ERROR (MainThread) [homeassistant.util.logging] Exception in async_schedule_update_ha_state when dispatching 'audiconnect.updated': ()
Traceback (most recent call last):
  File "/usr/src/homeassistant/homeassistant/helpers/entity.py", line 703, in async_schedule_update_ha_state
    self.async_write_ha_state()
  File "/usr/src/homeassistant/homeassistant/helpers/entity.py", line 525, in async_write_ha_state
    self._async_write_ha_state()
  File "/usr/src/homeassistant/homeassistant/helpers/entity.py", line 672, in _async_write_ha_state
    self.hass.states.async_set(
  File "/usr/src/homeassistant/homeassistant/core.py", line 1361, in async_set
    state = State(
  File "/usr/src/homeassistant/homeassistant/core.py", line 1047, in __init__
    raise InvalidStateError(
homeassistant.exceptions.InvalidStateError: Invalid state encountered for entity ID: sensor.audi_e_tron_sportback_shortterm_trip_data. State max length is 255 characters.

2022-04-06 14:44:17 WARNING (MainThread) [homeassistant.components.modbus.modbus] modbus laadpaal communication closed
2022-04-06 14:44:18 ERROR (MainThread) [homeassistant.helpers.entity] Update for sensor.veranda_speaker_aan_vandaag fails
Traceback (most recent call last):
  File "/usr/src/homeassistant/homeassistant/helpers/entity.py", line 507, in async_update_ha_state
    await self.async_device_update()
  File "/usr/src/homeassistant/homeassistant/helpers/entity.py", line 735, in async_device_update
    raise exc
  File "/usr/src/homeassistant/homeassistant/components/history_stats/sensor.py", line 228, in async_update
    await get_instance(self.hass).async_add_executor_job(
  File "/usr/local/lib/python3.9/concurrent/futures/thread.py", line 58, in run
    result = self.fn(*self.args, **self.kwargs)
  File "/usr/src/homeassistant/homeassistant/components/history_stats/sensor.py", line 234, in _update
    history_list = history.state_changes_during_period(
  File "/usr/src/homeassistant/homeassistant/components/recorder/history.py", line 267, in state_changes_during_period
    with session_scope(hass=hass) as session:
  File "/usr/local/lib/python3.9/contextlib.py", line 119, in __enter__
    return next(self.gen)
  File "/usr/src/homeassistant/homeassistant/components/recorder/util.py", line 82, in session_scope
    session = hass.data[DATA_INSTANCE].get_session()
TypeError: 'NoneType' object is not callable
