2021-11-13 18:10:18 WARNING (SyncWorker_0) [homeassistant.loader] We found a custom integration adaptive_lighting which has not been tested by Home Assistant. This component might cause stability problems, be sure to disable it if you experience issues with Home Assistant
2021-11-13 18:10:18 WARNING (SyncWorker_2) [homeassistant.loader] We found a custom integration xiaomi_miio_airpurifier which has not been tested by Home Assistant. This component might cause stability problems, be sure to disable it if you experience issues with Home Assistant
2021-11-13 18:10:18 WARNING (SyncWorker_3) [homeassistant.loader] We found a custom integration audiconnect which has not been tested by Home Assistant. This component might cause stability problems, be sure to disable it if you experience issues with Home Assistant
2021-11-13 18:10:18 WARNING (SyncWorker_0) [homeassistant.loader] We found a custom integration powercalc which has not been tested by Home Assistant. This component might cause stability problems, be sure to disable it if you experience issues with Home Assistant
2021-11-13 18:10:18 WARNING (SyncWorker_3) [homeassistant.loader] We found a custom integration hacs which has not been tested by Home Assistant. This component might cause stability problems, be sure to disable it if you experience issues with Home Assistant
2021-11-13 18:10:18 WARNING (SyncWorker_2) [homeassistant.loader] We found a custom integration monitor_docker which has not been tested by Home Assistant. This component might cause stability problems, be sure to disable it if you experience issues with Home Assistant
2021-11-13 18:10:18 WARNING (SyncWorker_1) [homeassistant.loader] We found a custom integration average which has not been tested by Home Assistant. This component might cause stability problems, be sure to disable it if you experience issues with Home Assistant
2021-11-13 18:10:18 WARNING (SyncWorker_4) [homeassistant.loader] We found a custom integration xiaomi_miio_fan which has not been tested by Home Assistant. This component might cause stability problems, be sure to disable it if you experience issues with Home Assistant
2021-11-13 18:10:18 WARNING (SyncWorker_0) [homeassistant.loader] We found a custom integration shelly which has not been tested by Home Assistant. This component might cause stability problems, be sure to disable it if you experience issues with Home Assistant
2021-11-13 18:10:18 WARNING (SyncWorker_3) [homeassistant.loader] We found a custom integration huesyncbox which has not been tested by Home Assistant. This component might cause stability problems, be sure to disable it if you experience issues with Home Assistant
2021-11-13 18:10:18 WARNING (SyncWorker_6) [homeassistant.loader] We found a custom integration localtuya which has not been tested by Home Assistant. This component might cause stability problems, be sure to disable it if you experience issues with Home Assistant
2021-11-13 18:10:18 WARNING (SyncWorker_0) [homeassistant.loader] We found a custom integration googlewifi which has not been tested by Home Assistant. This component might cause stability problems, be sure to disable it if you experience issues with Home Assistant
2021-11-13 18:10:18 WARNING (SyncWorker_1) [homeassistant.loader] We found a custom integration frigate which has not been tested by Home Assistant. This component might cause stability problems, be sure to disable it if you experience issues with Home Assistant
2021-11-13 18:10:18 WARNING (SyncWorker_2) [homeassistant.loader] We found a custom integration thermal_comfort which has not been tested by Home Assistant. This component might cause stability problems, be sure to disable it if you experience issues with Home Assistant
2021-11-13 18:10:18 WARNING (SyncWorker_7) [homeassistant.loader] We found a custom integration tuya_v2 which has not been tested by Home Assistant. This component might cause stability problems, be sure to disable it if you experience issues with Home Assistant
2021-11-13 18:10:18 WARNING (SyncWorker_5) [homeassistant.loader] We found a custom integration google_home which has not been tested by Home Assistant. This component might cause stability problems, be sure to disable it if you experience issues with Home Assistant
2021-11-13 18:10:18 WARNING (SyncWorker_1) [homeassistant.loader] We found a custom integration anniversaries which has not been tested by Home Assistant. This component might cause stability problems, be sure to disable it if you experience issues with Home Assistant
2021-11-13 18:10:18 WARNING (SyncWorker_2) [homeassistant.loader] We found a custom integration deepstack_face which has not been tested by Home Assistant. This component might cause stability problems, be sure to disable it if you experience issues with Home Assistant
2021-11-13 18:10:18 WARNING (SyncWorker_9) [homeassistant.loader] We found a custom integration xiaomi_miot which has not been tested by Home Assistant. This component might cause stability problems, be sure to disable it if you experience issues with Home Assistant
2021-11-13 18:10:18 WARNING (SyncWorker_7) [homeassistant.loader] We found a custom integration ytube_music_player which has not been tested by Home Assistant. This component might cause stability problems, be sure to disable it if you experience issues with Home Assistant
2021-11-13 18:10:18 WARNING (SyncWorker_3) [homeassistant.loader] We found a custom integration afvalbeheer which has not been tested by Home Assistant. This component might cause stability problems, be sure to disable it if you experience issues with Home Assistant
2021-11-13 18:10:18 WARNING (SyncWorker_8) [homeassistant.loader] We found a custom integration buienalarm which has not been tested by Home Assistant. This component might cause stability problems, be sure to disable it if you experience issues with Home Assistant
2021-11-13 18:10:26 ERROR (SyncWorker_7) [homeassistant.components.influxdb] Cannot connect to InfluxDB due to '<urllib3.connection.HTTPConnection object at 0xffff797da940>: Failed to establish a new connection: [Errno 111] Connection refused'. Please check that the provided connection details (host, port, etc.) are correct and that your InfluxDB server is running and accessible. Retrying in 60 seconds.
2021-11-13 18:10:28 ERROR (MainThread) [homeassistant.config] Invalid config for [automation]: expected str for dictionary value @ data['from']. Got None. (See ?, line ?). 
2021-11-13 18:10:28 ERROR (MainThread) [homeassistant.config] Invalid config for [automation]: required key not provided @ data['trigger'][1]['platform']. Got None. (See ?, line ?). 
2021-11-13 18:10:28 ERROR (MainThread) [homeassistant.config] Invalid config for [automation]: Unexpected value for condition: 'None'. Expected and, device, not, numeric_state, or, state, sun, template, time, trigger, zone @ data['condition'][0]. Got None. (See ?, line ?). 
2021-11-13 18:10:28 ERROR (MainThread) [homeassistant.config] Invalid config for [automation]: Unexpected value for condition: 'None'. Expected and, device, not, numeric_state, or, state, sun, template, time, trigger, zone @ data['condition'][0]. Got None. (See ?, line ?). 
2021-11-13 18:10:28 ERROR (MainThread) [homeassistant.config] Invalid config for [automation]: required key not provided @ data['action'][4]['domain']. Got None. (See ?, line ?). 
2021-11-13 18:10:28 ERROR (MainThread) [homeassistant.config] Invalid config for [automation]: must be a value between 0 and 59 for dictionary value @ data['minutes']. Got None. (See ?, line ?). 
2021-11-13 18:10:28 ERROR (MainThread) [homeassistant.config] Invalid config for [automation]: must be a value between 0 and 59 for dictionary value @ data['minutes']. Got None. (See ?, line ?). 
2021-11-13 18:10:33 WARNING (MainThread) [homeassistant.setup] Setup of input_datetime is taking over 10 seconds.
2021-11-13 18:10:33 WARNING (MainThread) [homeassistant.setup] Setup of input_text is taking over 10 seconds.
2021-11-13 18:10:33 WARNING (MainThread) [homeassistant.setup] Setup of counter is taking over 10 seconds.
2021-11-13 18:10:33 WARNING (MainThread) [homeassistant.setup] Setup of input_number is taking over 10 seconds.
2021-11-13 18:10:34 WARNING (MainThread) [homeassistant.setup] Setup of zone is taking over 10 seconds.
2021-11-13 18:10:34 WARNING (MainThread) [homeassistant.setup] Setup of timer is taking over 10 seconds.
2021-11-13 18:10:34 WARNING (MainThread) [homeassistant.components.fan] Platform xiaomi_miio_fan not ready yet: Unable to discover the device 192.168.86.29; Retrying in background in 30 seconds
2021-11-13 18:10:34 WARNING (MainThread) [homeassistant.components.fan] Platform xiaomi_miio_fan not ready yet: Unable to discover the device 192.168.86.28; Retrying in background in 30 seconds
2021-11-13 18:10:35 WARNING (MainThread) [homeassistant.components.webhook] Received message for unregistered webhook 80adf825ef6b969ee3c95fc54091652f8a80fe790532f31c6bff63908742af08 from 185.194.187.211
2021-11-13 18:10:37 WARNING (MainThread) [homeassistant.components.webhook] Received message for unregistered webhook 80adf825ef6b969ee3c95fc54091652f8a80fe790532f31c6bff63908742af08 from 185.194.187.211
2021-11-13 18:10:37 WARNING (MainThread) [homeassistant.config_entries] Config entry '192.168.86.83' for synology_dsm integration not ready yet: ConnectionError = <urllib3.connection.HTTPSConnection object at 0xffff6e4720a0>: Failed to establish a new connection: [Errno 113] Host is unreachable; Retrying in background
2021-11-13 18:10:42 ERROR (MainThread) [custom_components.powercalc.sensors.power] Skipping sensor setup light.buiten: ('No lookup file found for mode', 'brightness')
2021-11-13 18:10:42 WARNING (MainThread) [homeassistant.components.hue.light] Please check for software updates of the douche bulb in the Philips Hue App.
2021-11-13 18:10:42 WARNING (MainThread) [homeassistant.components.integration.sensor] Could not restore last state: [<class 'decimal.ConversionSyntax'>]
2021-11-13 18:10:42 WARNING (MainThread) [homeassistant.components.integration.sensor] Could not restore last state: [<class 'decimal.ConversionSyntax'>]
2021-11-13 18:10:43 ERROR (MainThread) [homeassistant.components.sensor] Error adding entities for domain sensor with platform pi_hole
Traceback (most recent call last):
  File "/usr/src/homeassistant/homeassistant/helpers/entity_platform.py", line 382, in async_add_entities
    await asyncio.gather(*tasks)
  File "/usr/src/homeassistant/homeassistant/helpers/entity_platform.py", line 607, in _async_add_entity
    await entity.add_to_platform_finish()
  File "/usr/src/homeassistant/homeassistant/helpers/entity.py", line 715, in add_to_platform_finish
    self.async_write_ha_state()
  File "/usr/src/homeassistant/homeassistant/helpers/entity.py", line 486, in async_write_ha_state
    self._async_write_ha_state()
  File "/usr/src/homeassistant/homeassistant/helpers/entity.py", line 519, in _async_write_ha_state
    state = self._stringify_state()
  File "/usr/src/homeassistant/homeassistant/helpers/entity.py", line 492, in _stringify_state
    if (state := self.state) is None:
  File "/usr/src/homeassistant/homeassistant/components/sensor/__init__.py", line 273, in state
    value = self.native_value
  File "/usr/src/homeassistant/homeassistant/components/pi_hole/sensor.py", line 68, in native_value
    return round(self.api.data[self.entity_description.key], 2)
KeyError: 'ads_blocked_today'
2021-11-13 18:10:43 WARNING (MainThread) [homeassistant.components.light] Platform netatmo not ready yet: None; Retrying in background in 30 seconds
2021-11-13 18:10:43 WARNING (MainThread) [homeassistant.components.select] Platform netatmo not ready yet: None; Retrying in background in 30 seconds
2021-11-13 18:10:43 ERROR (MainThread) [homeassistant.components.sensor] Error while setting up pi_hole platform for sensor
Traceback (most recent call last):
  File "/usr/src/homeassistant/homeassistant/helpers/entity_platform.py", line 257, in _async_setup_platform
    await asyncio.gather(*pending)
  File "/usr/src/homeassistant/homeassistant/helpers/entity_platform.py", line 382, in async_add_entities
    await asyncio.gather(*tasks)
  File "/usr/src/homeassistant/homeassistant/helpers/entity_platform.py", line 607, in _async_add_entity
    await entity.add_to_platform_finish()
  File "/usr/src/homeassistant/homeassistant/helpers/entity.py", line 715, in add_to_platform_finish
    self.async_write_ha_state()
  File "/usr/src/homeassistant/homeassistant/helpers/entity.py", line 486, in async_write_ha_state
    self._async_write_ha_state()
  File "/usr/src/homeassistant/homeassistant/helpers/entity.py", line 519, in _async_write_ha_state
    state = self._stringify_state()
  File "/usr/src/homeassistant/homeassistant/helpers/entity.py", line 492, in _stringify_state
    if (state := self.state) is None:
  File "/usr/src/homeassistant/homeassistant/components/sensor/__init__.py", line 273, in state
    value = self.native_value
  File "/usr/src/homeassistant/homeassistant/components/pi_hole/sensor.py", line 68, in native_value
    return round(self.api.data[self.entity_description.key], 2)
KeyError: 'ads_blocked_today'
2021-11-13 18:10:43 WARNING (MainThread) [homeassistant.components.energy.sensor] Found unexpected state_class None for sensor.tv_energy
2021-11-13 18:10:44 WARNING (MainThread) [homeassistant.components.sensor] Platform netatmo not ready yet: None; Retrying in background in 30 seconds
2021-11-13 18:10:46 WARNING (MainThread) [homeassistant.components.binary_sensor] Updating ping binary_sensor took longer than the scheduled update interval 0:00:05
2021-11-13 18:10:46 ERROR (MainThread) [homeassistant.components.sensor] scrape: Error on device update!
Traceback (most recent call last):
  File "/usr/src/homeassistant/homeassistant/helpers/entity_platform.py", line 431, in _async_add_entity
    await entity.async_device_update(warning=False)
  File "/usr/src/homeassistant/homeassistant/helpers/entity.py", line 651, in async_device_update
    await task
  File "/usr/src/homeassistant/homeassistant/components/scrape/sensor.py", line 166, in async_update
    await self._async_update_from_rest_data()
  File "/usr/src/homeassistant/homeassistant/components/scrape/sensor.py", line 179, in _async_update_from_rest_data
    value = await self.hass.async_add_executor_job(self._extract_value)
  File "/usr/local/lib/python3.9/concurrent/futures/thread.py", line 52, in run
    result = self.fn(*self.args, **self.kwargs)
  File "/usr/src/homeassistant/homeassistant/components/scrape/sensor.py", line 155, in _extract_value
    tag = raw_data.select(self._select)[self._index]
  File "/usr/local/lib/python3.9/site-packages/bs4/element.py", line 1949, in select
    results = soupsieve.select(selector, self, namespaces, limit, **kwargs)
  File "/usr/local/lib/python3.9/site-packages/soupsieve/__init__.py", line 144, in select
    return compile(select, namespaces, flags, **kwargs).select(tag, limit)
  File "/usr/local/lib/python3.9/site-packages/soupsieve/__init__.py", line 67, in compile
    return cp._cached_css_compile(pattern, ns, cs, flags)
  File "/usr/local/lib/python3.9/site-packages/soupsieve/css_parser.py", line 218, in _cached_css_compile
    CSSParser(
  File "/usr/local/lib/python3.9/site-packages/soupsieve/css_parser.py", line 1159, in process_selectors
    return self.parse_selectors(self.selector_iter(self.pattern), index, flags)
  File "/usr/local/lib/python3.9/site-packages/soupsieve/css_parser.py", line 985, in parse_selectors
    key, m = next(iselector)
  File "/usr/local/lib/python3.9/site-packages/soupsieve/css_parser.py", line 1152, in selector_iter
    raise SelectorSyntaxError(msg, self.pattern, index)
soupsieve.util.SelectorSyntaxError: Invalid character '<' position 0
  line 1:
<span _ngcontent-app-root-c173="">Offline</span>
^
2021-11-13 18:10:48 WARNING (MainThread) [homeassistant.config_entries] Config entry 'OnHub' for upnp integration not ready yet; Retrying in background
2021-11-13 18:10:48 ERROR (MainThread) [homeassistant.components.pi_hole] Unexpected exception from <bound method DataUpdateCoordinator.async_refresh of <homeassistant.helpers.update_coordinator.DataUpdateCoordinator object at 0xffff7086d7c0>>
Traceback (most recent call last):
  File "/usr/src/homeassistant/homeassistant/helpers/debounce.py", line 105, in _handle_timer_finish
    await task
  File "/usr/src/homeassistant/homeassistant/helpers/update_coordinator.py", line 165, in async_refresh
    await self._async_refresh(log_failures=True)
  File "/usr/src/homeassistant/homeassistant/helpers/update_coordinator.py", line 265, in _async_refresh
    update_callback()
  File "/usr/src/homeassistant/homeassistant/helpers/update_coordinator.py", line 325, in _handle_coordinator_update
    self.async_write_ha_state()
  File "/usr/src/homeassistant/homeassistant/helpers/entity.py", line 486, in async_write_ha_state
    self._async_write_ha_state()
  File "/usr/src/homeassistant/homeassistant/helpers/entity.py", line 519, in _async_write_ha_state
    state = self._stringify_state()
  File "/usr/src/homeassistant/homeassistant/helpers/entity.py", line 492, in _stringify_state
    if (state := self.state) is None:
  File "/usr/src/homeassistant/homeassistant/components/sensor/__init__.py", line 273, in state
    value = self.native_value
  File "/usr/src/homeassistant/homeassistant/components/pi_hole/sensor.py", line 68, in native_value
    return round(self.api.data[self.entity_description.key], 2)
KeyError: 'ads_blocked_today'
2021-11-13 18:10:55 ERROR (MainThread) [custom_components.audiconnect.audi_connect_account] Unable to update the vehicle position of WAUZZZGE6MB019131: 204, message='No Content', url=URL('https://fal-3a.prd.eu.dp.vwg-connect.com/fs-car/bs/cf/v1/Audi/BE/vehicles/WAUZZZGE6MB019131/position')
2021-11-13 18:11:17 WARNING (MainThread) [homeassistant.components.fan] Setup of fan platform xiaomi_miio_fan is taking over 10 seconds.
2021-11-13 18:11:17 WARNING (MainThread) [homeassistant.components.fan] Setup of fan platform xiaomi_miio_fan is taking over 10 seconds.
2021-11-13 18:11:17 ERROR (MainThread) [homeassistant.components.nuki] Timeout fetching nuki devices data
2021-11-13 18:11:21 WARNING (MainThread) [homeassistant.components.binary_sensor] Updating ping binary_sensor took longer than the scheduled update interval 0:00:05
2021-11-13 18:11:21 ERROR (MainThread) [homeassistant.components.hue.sensor_base] Timeout fetching sensor data
2021-11-13 18:11:21 WARNING (MainThread) [homeassistant.components.media_player] Updating samsungtv media_player took longer than the scheduled update interval 0:00:10
2021-11-13 18:11:21 WARNING (MainThread) [homeassistant.helpers.entity] Update of binary_sensor.google_server is taking over 10 seconds
2021-11-13 18:11:21 ERROR (MainThread) [homeassistant.components.mobile_app.notify] Timeout sending notification to https://mobile-apps.home-assistant.io/api/sendPush/android/v1
2021-11-13 18:11:22 WARNING (MainThread) [homeassistant.components.media_player] Updating huesyncbox media_player took longer than the scheduled update interval 0:00:02
2021-11-13 18:11:22 WARNING (MainThread) [homeassistant.components.binary_sensor] Updating ping binary_sensor took longer than the scheduled update interval 0:00:05
2021-11-13 18:11:23 ERROR (MainThread) [homeassistant.components.google_assistant.http] Request for https://homegraph.googleapis.com/v1/devices:requestSync failed: 500
2021-11-13 18:11:23 WARNING (MainThread) [homeassistant.components.media_player] Updating huesyncbox media_player took longer than the scheduled update interval 0:00:02
2021-11-13 18:11:26 ERROR (SyncWorker_14) [homeassistant.components.influxdb] Cannot connect to InfluxDB due to '<urllib3.connection.HTTPConnection object at 0xffff5c9086a0>: Failed to establish a new connection: [Errno 111] Connection refused'. Please check that the provided connection details (host, port, etc.) are correct and that your InfluxDB server is running and accessible. Retrying in 60 seconds.
2021-11-13 18:11:28 ERROR (MainThread) [homeassistant.components.google_assistant.http] Request for https://homegraph.googleapis.com/v1/devices:reportStateAndNotification failed: 404
2021-11-13 18:11:53 WARNING (MainThread) [homeassistant.components.binary_sensor] Updating ping binary_sensor took longer than the scheduled update interval 0:00:05
2021-11-13 18:12:03 WARNING (MainThread) [homeassistant.components.binary_sensor] Updating ping binary_sensor took longer than the scheduled update interval 0:00:05
2021-11-13 18:12:04 ERROR (MainThread) [homeassistant.components.google_assistant.http] Request for https://homegraph.googleapis.com/v1/devices:reportStateAndNotification failed: 404
2021-11-13 18:12:26 ERROR (SyncWorker_2) [homeassistant.components.influxdb] Cannot connect to InfluxDB due to '<urllib3.connection.HTTPConnection object at 0xffff5c9c4850>: Failed to establish a new connection: [Errno 111] Connection refused'. Please check that the provided connection details (host, port, etc.) are correct and that your InfluxDB server is running and accessible. Retrying in 60 seconds.
2021-11-13 18:13:26 ERROR (SyncWorker_11) [homeassistant.components.influxdb] Cannot connect to InfluxDB due to '<urllib3.connection.HTTPConnection object at 0xffff5ebbf850>: Failed to establish a new connection: [Errno 111] Connection refused'. Please check that the provided connection details (host, port, etc.) are correct and that your InfluxDB server is running and accessible. Retrying in 60 seconds.
2021-11-13 18:13:51 ERROR (Thread-11) [pychromecast.socket_client] [Groep_living_veranda(192.168.86.244):32106] Error reading from socket.
2021-11-13 18:13:51 WARNING (Thread-11) [pychromecast.socket_client] [Groep_living_veranda(192.168.86.244):32106] Error communicating with socket, resetting connection
2021-11-13 18:13:51 ERROR (Thread-9) [pychromecast.socket_client] [Living speaker(192.168.86.244):8009] Error reading from socket.
2021-11-13 18:13:51 WARNING (Thread-9) [pychromecast.socket_client] [Living speaker(192.168.86.244):8009] Error communicating with socket, resetting connection
2021-11-13 18:13:51 ERROR (Thread-11) [pychromecast.socket_client] [Groep_living_veranda(192.168.86.244):32106] Failed to connect to service ServiceInfo(type='host', data=('192.168.86.244', 32106)), retrying in 5.0s
2021-11-13 18:13:51 ERROR (Thread-9) [pychromecast.socket_client] [Living speaker(192.168.86.244):8009] Failed to connect to service ServiceInfo(type='host', data=('192.168.86.244', 8009)), retrying in 5.0s
2021-11-13 18:13:59 ERROR (Thread-11) [pychromecast.socket_client] [Groep_living_veranda(192.168.86.47):32106] Error reading from socket.
2021-11-13 18:13:59 WARNING (Thread-11) [pychromecast.socket_client] [Groep_living_veranda(192.168.86.47):32106] Error communicating with socket, resetting connection
2021-11-13 18:13:59 ERROR (Thread-11) [pychromecast.socket_client] [Groep_living_veranda(192.168.86.47):32106] Failed to connect to service ServiceInfo(type='mdns', data='Google-Cast-Group-90490c41565e4b21af61a4ecedd76c58._googlecast._tcp.local.'), retrying in 5.0s
2021-11-13 18:14:26 ERROR (SyncWorker_4) [homeassistant.components.influxdb] Cannot connect to InfluxDB due to '<urllib3.connection.HTTPConnection object at 0xffff5c029d60>: Failed to establish a new connection: [Errno 111] Connection refused'. Please check that the provided connection details (host, port, etc.) are correct and that your InfluxDB server is running and accessible. Retrying in 60 seconds.
2021-11-13 18:15:00 WARNING (MainThread) [homeassistant.helpers.script] Error in 'condition' evaluation:
In 'zone' condition: error matching person.alunya with zone.home: entity person.alunya has no 'latitude' attribute
2021-11-13 18:15:26 ERROR (SyncWorker_12) [homeassistant.components.influxdb] Cannot connect to InfluxDB due to '<urllib3.connection.HTTPConnection object at 0xffff5ca52dc0>: Failed to establish a new connection: [Errno 111] Connection refused'. Please check that the provided connection details (host, port, etc.) are correct and that your InfluxDB server is running and accessible. Retrying in 60 seconds.
2021-11-13 18:15:48 ERROR (MainThread) [homeassistant] Error doing job: Task exception was never retrieved
Traceback (most recent call last):
  File "/usr/src/homeassistant/homeassistant/helpers/update_coordinator.py", line 134, in _handle_refresh_interval
    await self._async_refresh(log_failures=True, scheduled=True)
  File "/usr/src/homeassistant/homeassistant/helpers/update_coordinator.py", line 265, in _async_refresh
    update_callback()
  File "/usr/src/homeassistant/homeassistant/helpers/update_coordinator.py", line 325, in _handle_coordinator_update
    self.async_write_ha_state()
  File "/usr/src/homeassistant/homeassistant/helpers/entity.py", line 486, in async_write_ha_state
    self._async_write_ha_state()
  File "/usr/src/homeassistant/homeassistant/helpers/entity.py", line 519, in _async_write_ha_state
    state = self._stringify_state()
  File "/usr/src/homeassistant/homeassistant/helpers/entity.py", line 492, in _stringify_state
    if (state := self.state) is None:
  File "/usr/src/homeassistant/homeassistant/components/sensor/__init__.py", line 273, in state
    value = self.native_value
  File "/usr/src/homeassistant/homeassistant/components/pi_hole/sensor.py", line 68, in native_value
    return round(self.api.data[self.entity_description.key], 2)
KeyError: 'ads_blocked_today'
2021-11-13 18:16:26 ERROR (SyncWorker_7) [homeassistant.components.influxdb] Cannot connect to InfluxDB due to '<urllib3.connection.HTTPConnection object at 0xffff4d2aad60>: Failed to establish a new connection: [Errno 111] Connection refused'. Please check that the provided connection details (host, port, etc.) are correct and that your InfluxDB server is running and accessible. Retrying in 60 seconds.
2021-11-13 18:17:26 ERROR (SyncWorker_12) [homeassistant.components.influxdb] Cannot connect to InfluxDB due to '<urllib3.connection.HTTPConnection object at 0xffff4d261f70>: Failed to establish a new connection: [Errno 111] Connection refused'. Please check that the provided connection details (host, port, etc.) are correct and that your InfluxDB server is running and accessible. Retrying in 60 seconds.
2021-11-13 18:18:26 ERROR (SyncWorker_0) [homeassistant.components.influxdb] Cannot connect to InfluxDB due to '<urllib3.connection.HTTPConnection object at 0xffff4d29a9a0>: Failed to establish a new connection: [Errno 111] Connection refused'. Please check that the provided connection details (host, port, etc.) are correct and that your InfluxDB server is running and accessible. Retrying in 60 seconds.
2021-11-13 18:19:26 ERROR (SyncWorker_14) [homeassistant.components.influxdb] Cannot connect to InfluxDB due to '<urllib3.connection.HTTPConnection object at 0xffff4c741970>: Failed to establish a new connection: [Errno 111] Connection refused'. Please check that the provided connection details (host, port, etc.) are correct and that your InfluxDB server is running and accessible. Retrying in 60 seconds.
2021-11-13 18:20:26 ERROR (SyncWorker_14) [homeassistant.components.influxdb] Cannot connect to InfluxDB due to '<urllib3.connection.HTTPConnection object at 0xffff4c5b0130>: Failed to establish a new connection: [Errno 111] Connection refused'. Please check that the provided connection details (host, port, etc.) are correct and that your InfluxDB server is running and accessible. Retrying in 60 seconds.
2021-11-13 18:20:48 ERROR (MainThread) [homeassistant] Error doing job: Task exception was never retrieved
Traceback (most recent call last):
  File "/usr/src/homeassistant/homeassistant/helpers/update_coordinator.py", line 134, in _handle_refresh_interval
    await self._async_refresh(log_failures=True, scheduled=True)
  File "/usr/src/homeassistant/homeassistant/helpers/update_coordinator.py", line 265, in _async_refresh
    update_callback()
  File "/usr/src/homeassistant/homeassistant/helpers/update_coordinator.py", line 325, in _handle_coordinator_update
    self.async_write_ha_state()
  File "/usr/src/homeassistant/homeassistant/helpers/entity.py", line 486, in async_write_ha_state
    self._async_write_ha_state()
  File "/usr/src/homeassistant/homeassistant/helpers/entity.py", line 519, in _async_write_ha_state
    state = self._stringify_state()
  File "/usr/src/homeassistant/homeassistant/helpers/entity.py", line 492, in _stringify_state
    if (state := self.state) is None:
  File "/usr/src/homeassistant/homeassistant/components/sensor/__init__.py", line 273, in state
    value = self.native_value
  File "/usr/src/homeassistant/homeassistant/components/pi_hole/sensor.py", line 68, in native_value
    return round(self.api.data[self.entity_description.key], 2)
KeyError: 'ads_blocked_today'
2021-11-13 18:21:26 ERROR (SyncWorker_12) [homeassistant.components.influxdb] Cannot connect to InfluxDB due to '<urllib3.connection.HTTPConnection object at 0xffff5e73b550>: Failed to establish a new connection: [Errno 111] Connection refused'. Please check that the provided connection details (host, port, etc.) are correct and that your InfluxDB server is running and accessible. Retrying in 60 seconds.
2021-11-13 18:22:26 ERROR (SyncWorker_14) [homeassistant.components.influxdb] Cannot connect to InfluxDB due to '<urllib3.connection.HTTPConnection object at 0xffff5f582640>: Failed to establish a new connection: [Errno 111] Connection refused'. Please check that the provided connection details (host, port, etc.) are correct and that your InfluxDB server is running and accessible. Retrying in 60 seconds.
2021-11-13 18:23:26 ERROR (SyncWorker_5) [homeassistant.components.influxdb] Cannot connect to InfluxDB due to '<urllib3.connection.HTTPConnection object at 0xffff5ec14fa0>: Failed to establish a new connection: [Errno 111] Connection refused'. Please check that the provided connection details (host, port, etc.) are correct and that your InfluxDB server is running and accessible. Retrying in 60 seconds.
2021-11-13 18:23:56 WARNING (MainThread) [homeassistant.helpers.service] Unable to find referenced entities media_player.veranda_speaker_2
2021-11-13 18:24:26 ERROR (SyncWorker_7) [homeassistant.components.influxdb] Cannot connect to InfluxDB due to '<urllib3.connection.HTTPConnection object at 0xffff4d0dcf10>: Failed to establish a new connection: [Errno 111] Connection refused'. Please check that the provided connection details (host, port, etc.) are correct and that your InfluxDB server is running and accessible. Retrying in 60 seconds.
2021-11-13 18:25:02 WARNING (stream_worker) [libav.hls] Failed to reload playlist 0
2021-11-13 18:25:02 WARNING (stream_worker) [libav.hls] Failed to reload playlist 0
2021-11-13 18:25:02 ERROR (stream_worker) [homeassistant.components.stream.worker] Error demuxing stream: 
2021-11-13 18:25:26 ERROR (SyncWorker_7) [homeassistant.components.influxdb] Cannot connect to InfluxDB due to '<urllib3.connection.HTTPConnection object at 0xffff4a1f89a0>: Failed to establish a new connection: [Errno 111] Connection refused'. Please check that the provided connection details (host, port, etc.) are correct and that your InfluxDB server is running and accessible. Retrying in 60 seconds.
2021-11-13 18:26:26 ERROR (SyncWorker_3) [homeassistant.components.influxdb] Cannot connect to InfluxDB due to '<urllib3.connection.HTTPConnection object at 0xffff5e892220>: Failed to establish a new connection: [Errno 111] Connection refused'. Please check that the provided connection details (host, port, etc.) are correct and that your InfluxDB server is running and accessible. Retrying in 60 seconds.
2021-11-13 18:27:26 ERROR (SyncWorker_1) [homeassistant.components.influxdb] Cannot connect to InfluxDB due to '<urllib3.connection.HTTPConnection object at 0xffff4d0b1d90>: Failed to establish a new connection: [Errno 111] Connection refused'. Please check that the provided connection details (host, port, etc.) are correct and that your InfluxDB server is running and accessible. Retrying in 60 seconds.
2021-11-13 18:28:27 ERROR (SyncWorker_10) [homeassistant.components.influxdb] Cannot connect to InfluxDB due to '<urllib3.connection.HTTPConnection object at 0xffff5ca181f0>: Failed to establish a new connection: [Errno 111] Connection refused'. Please check that the provided connection details (host, port, etc.) are correct and that your InfluxDB server is running and accessible. Retrying in 60 seconds.
2021-11-13 18:29:27 ERROR (SyncWorker_3) [homeassistant.components.influxdb] Cannot connect to InfluxDB due to '<urllib3.connection.HTTPConnection object at 0xffff4d1196a0>: Failed to establish a new connection: [Errno 111] Connection refused'. Please check that the provided connection details (host, port, etc.) are correct and that your InfluxDB server is running and accessible. Retrying in 60 seconds.
2021-11-13 18:30:27 ERROR (SyncWorker_9) [homeassistant.components.influxdb] Cannot connect to InfluxDB due to '<urllib3.connection.HTTPConnection object at 0xffff496fd9d0>: Failed to establish a new connection: [Errno 111] Connection refused'. Please check that the provided connection details (host, port, etc.) are correct and that your InfluxDB server is running and accessible. Retrying in 60 seconds.
2021-11-13 18:30:57 ERROR (MainThread) [homeassistant.components.scrape.sensor] Unable to extract data from HTML for temp_leuven24_wunderground
2021-11-13 18:31:27 ERROR (SyncWorker_5) [homeassistant.components.influxdb] Cannot connect to InfluxDB due to '<urllib3.connection.HTTPConnection object at 0xffff496920a0>: Failed to establish a new connection: [Errno 111] Connection refused'. Please check that the provided connection details (host, port, etc.) are correct and that your InfluxDB server is running and accessible. Retrying in 60 seconds.
2021-11-13 18:31:50 ERROR (MainThread) [homeassistant.components.scrape.sensor] Unable to extract data from HTML for precip_rate_leuven24_wunderground
2021-11-13 18:32:27 ERROR (SyncWorker_14) [homeassistant.components.influxdb] Cannot connect to InfluxDB due to '<urllib3.connection.HTTPConnection object at 0xffff48da8940>: Failed to establish a new connection: [Errno 111] Connection refused'. Please check that the provided connection details (host, port, etc.) are correct and that your InfluxDB server is running and accessible. Retrying in 60 seconds.
2021-11-13 18:33:25 ERROR (MainThread) [homeassistant.components.google_assistant.http] Request for https://homegraph.googleapis.com/v1/devices:reportStateAndNotification failed: 404
2021-11-13 18:33:27 ERROR (SyncWorker_14) [homeassistant.components.influxdb] Cannot connect to InfluxDB due to '<urllib3.connection.HTTPConnection object at 0xffff495e77c0>: Failed to establish a new connection: [Errno 111] Connection refused'. Please check that the provided connection details (host, port, etc.) are correct and that your InfluxDB server is running and accessible. Retrying in 60 seconds.
2021-11-13 18:34:27 ERROR (SyncWorker_13) [homeassistant.components.influxdb] Cannot connect to InfluxDB due to '<urllib3.connection.HTTPConnection object at 0xffff48df3700>: Failed to establish a new connection: [Errno 111] Connection refused'. Please check that the provided connection details (host, port, etc.) are correct and that your InfluxDB server is running and accessible. Retrying in 60 seconds.
2021-11-13 18:34:49 ERROR (MainThread) [homeassistant.components.scrape.sensor] Unable to extract data from HTML for humidity_leuven24_wunderground
2021-11-13 18:34:49 ERROR (MainThread) [homeassistant.components.scrape.sensor] Unable to extract data from HTML for temp_leuven24_wunderground
2021-11-13 18:34:49 ERROR (MainThread) [homeassistant.components.scrape.sensor] Unable to extract data from HTML for precip_rate_leuven24_wunderground
2021-11-13 18:35:27 ERROR (SyncWorker_4) [homeassistant.components.influxdb] Cannot connect to InfluxDB due to '<urllib3.connection.HTTPConnection object at 0xffff48c52d30>: Failed to establish a new connection: [Errno 111] Connection refused'. Please check that the provided connection details (host, port, etc.) are correct and that your InfluxDB server is running and accessible. Retrying in 60 seconds.
2021-11-13 18:35:43 ERROR (MainThread) [homeassistant.components.google_assistant.http] Request for https://homegraph.googleapis.com/v1/devices:reportStateAndNotification failed: 404
2021-11-13 18:36:17 ERROR (MainThread) [homeassistant.components.ipp.coordinator] Error fetching ipp data: Invalid response from API: Timeout occurred while connecting to IPP server.
2021-11-13 18:36:27 ERROR (SyncWorker_12) [homeassistant.components.influxdb] Cannot connect to InfluxDB due to '<urllib3.connection.HTTPConnection object at 0xffff48a16520>: Failed to establish a new connection: [Errno 111] Connection refused'. Please check that the provided connection details (host, port, etc.) are correct and that your InfluxDB server is running and accessible. Retrying in 60 seconds.
2021-11-13 18:37:27 ERROR (SyncWorker_11) [homeassistant.components.influxdb] Cannot connect to InfluxDB due to '<urllib3.connection.HTTPConnection object at 0xffff4c550b50>: Failed to establish a new connection: [Errno 111] Connection refused'. Please check that the provided connection details (host, port, etc.) are correct and that your InfluxDB server is running and accessible. Retrying in 60 seconds.
2021-11-13 18:38:27 ERROR (SyncWorker_15) [homeassistant.components.influxdb] Cannot connect to InfluxDB due to '<urllib3.connection.HTTPConnection object at 0xffff5c9c4820>: Failed to establish a new connection: [Errno 111] Connection refused'. Please check that the provided connection details (host, port, etc.) are correct and that your InfluxDB server is running and accessible. Retrying in 60 seconds.
2021-11-13 18:39:27 ERROR (SyncWorker_18) [homeassistant.components.influxdb] Cannot connect to InfluxDB due to '<urllib3.connection.HTTPConnection object at 0xffff5c065a90>: Failed to establish a new connection: [Errno 111] Connection refused'. Please check that the provided connection details (host, port, etc.) are correct and that your InfluxDB server is running and accessible. Retrying in 60 seconds.
2021-11-13 18:40:27 ERROR (SyncWorker_14) [homeassistant.components.influxdb] Cannot connect to InfluxDB due to '<urllib3.connection.HTTPConnection object at 0xffff4a144fa0>: Failed to establish a new connection: [Errno 111] Connection refused'. Please check that the provided connection details (host, port, etc.) are correct and that your InfluxDB server is running and accessible. Retrying in 60 seconds.
2021-11-13 18:41:27 ERROR (SyncWorker_16) [homeassistant.components.influxdb] Cannot connect to InfluxDB due to '<urllib3.connection.HTTPConnection object at 0xffff5e742f10>: Failed to establish a new connection: [Errno 111] Connection refused'. Please check that the provided connection details (host, port, etc.) are correct and that your InfluxDB server is running and accessible. Retrying in 60 seconds.
2021-11-13 18:42:27 ERROR (SyncWorker_9) [homeassistant.components.influxdb] Cannot connect to InfluxDB due to '<urllib3.connection.HTTPConnection object at 0xffff495e7790>: Failed to establish a new connection: [Errno 111] Connection refused'. Please check that the provided connection details (host, port, etc.) are correct and that your InfluxDB server is running and accessible. Retrying in 60 seconds.
2021-11-13 18:43:27 ERROR (SyncWorker_14) [homeassistant.components.influxdb] Cannot connect to InfluxDB due to '<urllib3.connection.HTTPConnection object at 0xffff5ec8a280>: Failed to establish a new connection: [Errno 111] Connection refused'. Please check that the provided connection details (host, port, etc.) are correct and that your InfluxDB server is running and accessible. Retrying in 60 seconds.
2021-11-13 18:43:53 WARNING (MainThread) [homeassistant.components.binary_sensor] Updating ping binary_sensor took longer than the scheduled update interval 0:00:05
2021-11-13 18:44:27 ERROR (SyncWorker_9) [homeassistant.components.influxdb] Cannot connect to InfluxDB due to '<urllib3.connection.HTTPConnection object at 0xffff4a1a6a90>: Failed to establish a new connection: [Errno 111] Connection refused'. Please check that the provided connection details (host, port, etc.) are correct and that your InfluxDB server is running and accessible. Retrying in 60 seconds.
2021-11-13 18:45:27 ERROR (SyncWorker_13) [homeassistant.components.influxdb] Cannot connect to InfluxDB due to '<urllib3.connection.HTTPConnection object at 0xffff4ca9a430>: Failed to establish a new connection: [Errno 111] Connection refused'. Please check that the provided connection details (host, port, etc.) are correct and that your InfluxDB server is running and accessible. Retrying in 60 seconds.
2021-11-13 18:46:27 ERROR (SyncWorker_19) [homeassistant.components.influxdb] Cannot connect to InfluxDB due to '<urllib3.connection.HTTPConnection object at 0xffff5ebbe220>: Failed to establish a new connection: [Errno 111] Connection refused'. Please check that the provided connection details (host, port, etc.) are correct and that your InfluxDB server is running and accessible. Retrying in 60 seconds.
2021-11-13 18:47:27 ERROR (SyncWorker_3) [homeassistant.components.influxdb] Cannot connect to InfluxDB due to '<urllib3.connection.HTTPConnection object at 0xffff5e725040>: Failed to establish a new connection: [Errno 111] Connection refused'. Please check that the provided connection details (host, port, etc.) are correct and that your InfluxDB server is running and accessible. Retrying in 60 seconds.
2021-11-13 18:48:27 ERROR (SyncWorker_12) [homeassistant.components.influxdb] Cannot connect to InfluxDB due to '<urllib3.connection.HTTPConnection object at 0xffff4d101b50>: Failed to establish a new connection: [Errno 111] Connection refused'. Please check that the provided connection details (host, port, etc.) are correct and that your InfluxDB server is running and accessible. Retrying in 60 seconds.
2021-11-13 18:49:27 ERROR (SyncWorker_15) [homeassistant.components.influxdb] Cannot connect to InfluxDB due to '<urllib3.connection.HTTPConnection object at 0xffff5eeeca30>: Failed to establish a new connection: [Errno 111] Connection refused'. Please check that the provided connection details (host, port, etc.) are correct and that your InfluxDB server is running and accessible. Retrying in 60 seconds.
2021-11-13 18:49:50 ERROR (MainThread) [homeassistant.components.websocket_api.http.connection] [281472337639552] 'ads_blocked_today'
Traceback (most recent call last):
  File "/usr/src/homeassistant/homeassistant/components/websocket_api/commands.py", line 185, in handle_call_service
    await hass.services.async_call(
  File "/usr/src/homeassistant/homeassistant/core.py", line 1495, in async_call
    task.result()
  File "/usr/src/homeassistant/homeassistant/core.py", line 1530, in _execute_service
    await handler.job.target(service_call)
  File "/usr/src/homeassistant/homeassistant/helpers/entity_component.py", line 213, in handle_service
    await self.hass.helpers.service.entity_service_call(
  File "/usr/src/homeassistant/homeassistant/helpers/service.py", line 667, in entity_service_call
    future.result()  # pop exception if have
  File "/usr/src/homeassistant/homeassistant/helpers/entity.py", line 863, in async_request_call
    await coro
  File "/usr/src/homeassistant/homeassistant/helpers/service.py", line 704, in _handle_entity_call
    await result
  File "/usr/src/homeassistant/homeassistant/components/pi_hole/switch.py", line 88, in async_turn_off
    await self.async_disable()
  File "/usr/src/homeassistant/homeassistant/components/pi_hole/switch.py", line 103, in async_disable
    await self.async_update()
  File "/usr/src/homeassistant/homeassistant/helpers/update_coordinator.py", line 336, in async_update
    await self.coordinator.async_request_refresh()
  File "/usr/src/homeassistant/homeassistant/helpers/update_coordinator.py", line 141, in async_request_refresh
    await self._debounced_refresh.async_call()
  File "/usr/src/homeassistant/homeassistant/helpers/debounce.py", line 78, in async_call
    await task
  File "/usr/src/homeassistant/homeassistant/helpers/update_coordinator.py", line 165, in async_refresh
    await self._async_refresh(log_failures=True)
  File "/usr/src/homeassistant/homeassistant/helpers/update_coordinator.py", line 265, in _async_refresh
    update_callback()
  File "/usr/src/homeassistant/homeassistant/helpers/update_coordinator.py", line 325, in _handle_coordinator_update
    self.async_write_ha_state()
  File "/usr/src/homeassistant/homeassistant/helpers/entity.py", line 486, in async_write_ha_state
    self._async_write_ha_state()
  File "/usr/src/homeassistant/homeassistant/helpers/entity.py", line 519, in _async_write_ha_state
    state = self._stringify_state()
  File "/usr/src/homeassistant/homeassistant/helpers/entity.py", line 492, in _stringify_state
    if (state := self.state) is None:
  File "/usr/src/homeassistant/homeassistant/components/sensor/__init__.py", line 273, in state
    value = self.native_value
  File "/usr/src/homeassistant/homeassistant/components/pi_hole/sensor.py", line 68, in native_value
    return round(self.api.data[self.entity_description.key], 2)
KeyError: 'ads_blocked_today'
2021-11-13 18:49:53 ERROR (MainThread) [homeassistant.components.websocket_api.http.connection] [281472337639552] 'ads_blocked_today'
Traceback (most recent call last):
  File "/usr/src/homeassistant/homeassistant/components/websocket_api/commands.py", line 185, in handle_call_service
    await hass.services.async_call(
  File "/usr/src/homeassistant/homeassistant/core.py", line 1495, in async_call
    task.result()
  File "/usr/src/homeassistant/homeassistant/core.py", line 1530, in _execute_service
    await handler.job.target(service_call)
  File "/usr/src/homeassistant/homeassistant/helpers/entity_component.py", line 213, in handle_service
    await self.hass.helpers.service.entity_service_call(
  File "/usr/src/homeassistant/homeassistant/helpers/service.py", line 667, in entity_service_call
    future.result()  # pop exception if have
  File "/usr/src/homeassistant/homeassistant/helpers/entity.py", line 863, in async_request_call
    await coro
  File "/usr/src/homeassistant/homeassistant/helpers/service.py", line 704, in _handle_entity_call
    await result
  File "/usr/src/homeassistant/homeassistant/components/pi_hole/switch.py", line 82, in async_turn_on
    await self.async_update()
  File "/usr/src/homeassistant/homeassistant/helpers/update_coordinator.py", line 336, in async_update
    await self.coordinator.async_request_refresh()
  File "/usr/src/homeassistant/homeassistant/helpers/update_coordinator.py", line 141, in async_request_refresh
    await self._debounced_refresh.async_call()
  File "/usr/src/homeassistant/homeassistant/helpers/debounce.py", line 78, in async_call
    await task
  File "/usr/src/homeassistant/homeassistant/helpers/update_coordinator.py", line 165, in async_refresh
    await self._async_refresh(log_failures=True)
  File "/usr/src/homeassistant/homeassistant/helpers/update_coordinator.py", line 265, in _async_refresh
    update_callback()
  File "/usr/src/homeassistant/homeassistant/helpers/update_coordinator.py", line 325, in _handle_coordinator_update
    self.async_write_ha_state()
  File "/usr/src/homeassistant/homeassistant/helpers/entity.py", line 486, in async_write_ha_state
    self._async_write_ha_state()
  File "/usr/src/homeassistant/homeassistant/helpers/entity.py", line 519, in _async_write_ha_state
    state = self._stringify_state()
  File "/usr/src/homeassistant/homeassistant/helpers/entity.py", line 492, in _stringify_state
    if (state := self.state) is None:
  File "/usr/src/homeassistant/homeassistant/components/sensor/__init__.py", line 273, in state
    value = self.native_value
  File "/usr/src/homeassistant/homeassistant/components/pi_hole/sensor.py", line 68, in native_value
    return round(self.api.data[self.entity_description.key], 2)
KeyError: 'ads_blocked_today'
2021-11-13 18:50:27 ERROR (SyncWorker_14) [homeassistant.components.influxdb] Cannot connect to InfluxDB due to '<urllib3.connection.HTTPConnection object at 0xffff4c550850>: Failed to establish a new connection: [Errno 111] Connection refused'. Please check that the provided connection details (host, port, etc.) are correct and that your InfluxDB server is running and accessible. Retrying in 60 seconds.
2021-11-13 18:50:38 ERROR (MainThread) [homeassistant.components.google_assistant.http] Request for https://homegraph.googleapis.com/v1/devices:reportStateAndNotification failed: 404
2021-11-13 18:51:27 ERROR (SyncWorker_9) [homeassistant.components.influxdb] Cannot connect to InfluxDB due to '<urllib3.connection.HTTPConnection object at 0xffff4c4c3a30>: Failed to establish a new connection: [Errno 111] Connection refused'. Please check that the provided connection details (host, port, etc.) are correct and that your InfluxDB server is running and accessible. Retrying in 60 seconds.
2021-11-13 18:52:27 ERROR (SyncWorker_11) [homeassistant.components.influxdb] Cannot connect to InfluxDB due to '<urllib3.connection.HTTPConnection object at 0xffff4a15e3d0>: Failed to establish a new connection: [Errno 111] Connection refused'. Please check that the provided connection details (host, port, etc.) are correct and that your InfluxDB server is running and accessible. Retrying in 60 seconds.
2021-11-13 18:52:27 ERROR (MainThread) [homeassistant.components.websocket_api.http.connection] [281472231771104] 'ads_blocked_today'
Traceback (most recent call last):
  File "/usr/src/homeassistant/homeassistant/components/websocket_api/commands.py", line 185, in handle_call_service
    await hass.services.async_call(
  File "/usr/src/homeassistant/homeassistant/core.py", line 1495, in async_call
    task.result()
  File "/usr/src/homeassistant/homeassistant/core.py", line 1530, in _execute_service
    await handler.job.target(service_call)
  File "/usr/src/homeassistant/homeassistant/helpers/entity_component.py", line 213, in handle_service
    await self.hass.helpers.service.entity_service_call(
  File "/usr/src/homeassistant/homeassistant/helpers/service.py", line 667, in entity_service_call
    future.result()  # pop exception if have
  File "/usr/src/homeassistant/homeassistant/helpers/entity.py", line 863, in async_request_call
    await coro
  File "/usr/src/homeassistant/homeassistant/helpers/service.py", line 704, in _handle_entity_call
    await result
  File "/usr/src/homeassistant/homeassistant/components/pi_hole/switch.py", line 82, in async_turn_on
    await self.async_update()
  File "/usr/src/homeassistant/homeassistant/helpers/update_coordinator.py", line 336, in async_update
    await self.coordinator.async_request_refresh()
  File "/usr/src/homeassistant/homeassistant/helpers/update_coordinator.py", line 141, in async_request_refresh
    await self._debounced_refresh.async_call()
  File "/usr/src/homeassistant/homeassistant/helpers/debounce.py", line 78, in async_call
    await task
  File "/usr/src/homeassistant/homeassistant/helpers/update_coordinator.py", line 165, in async_refresh
    await self._async_refresh(log_failures=True)
  File "/usr/src/homeassistant/homeassistant/helpers/update_coordinator.py", line 265, in _async_refresh
    update_callback()
  File "/usr/src/homeassistant/homeassistant/helpers/update_coordinator.py", line 325, in _handle_coordinator_update
    self.async_write_ha_state()
  File "/usr/src/homeassistant/homeassistant/helpers/entity.py", line 486, in async_write_ha_state
    self._async_write_ha_state()
  File "/usr/src/homeassistant/homeassistant/helpers/entity.py", line 519, in _async_write_ha_state
    state = self._stringify_state()
  File "/usr/src/homeassistant/homeassistant/helpers/entity.py", line 492, in _stringify_state
    if (state := self.state) is None:
  File "/usr/src/homeassistant/homeassistant/components/sensor/__init__.py", line 273, in state
    value = self.native_value
  File "/usr/src/homeassistant/homeassistant/components/pi_hole/sensor.py", line 68, in native_value
    return round(self.api.data[self.entity_description.key], 2)
KeyError: 'ads_blocked_today'
2021-11-13 18:53:27 ERROR (SyncWorker_4) [homeassistant.components.influxdb] Cannot connect to InfluxDB due to '<urllib3.connection.HTTPConnection object at 0xffff4d0ee760>: Failed to establish a new connection: [Errno 111] Connection refused'. Please check that the provided connection details (host, port, etc.) are correct and that your InfluxDB server is running and accessible. Retrying in 60 seconds.
2021-11-13 18:54:27 ERROR (SyncWorker_14) [homeassistant.components.influxdb] Cannot connect to InfluxDB due to '<urllib3.connection.HTTPConnection object at 0xffff4d0b7340>: Failed to establish a new connection: [Errno 111] Connection refused'. Please check that the provided connection details (host, port, etc.) are correct and that your InfluxDB server is running and accessible. Retrying in 60 seconds.
2021-11-13 18:54:27 ERROR (MainThread) [homeassistant.config] Invalid config for [automation]: expected str for dictionary value @ data['from']. Got None. (See ?, line ?). 
2021-11-13 18:54:27 ERROR (MainThread) [homeassistant.config] Invalid config for [automation]: required key not provided @ data['trigger'][1]['platform']. Got None. (See ?, line ?). 
2021-11-13 18:54:27 ERROR (MainThread) [homeassistant.config] Invalid config for [automation]: Unexpected value for condition: 'None'. Expected and, device, not, numeric_state, or, state, sun, template, time, trigger, zone @ data['condition'][0]. Got None. (See ?, line ?). 
2021-11-13 18:54:27 ERROR (MainThread) [homeassistant.config] Invalid config for [automation]: Unexpected value for condition: 'None'. Expected and, device, not, numeric_state, or, state, sun, template, time, trigger, zone @ data['condition'][0]. Got None. (See ?, line ?). 
2021-11-13 18:54:27 ERROR (MainThread) [homeassistant.config] Invalid config for [automation]: required key not provided @ data['action'][4]['domain']. Got None. (See ?, line ?). 
2021-11-13 18:54:28 ERROR (MainThread) [homeassistant.config] Invalid config for [automation]: must be a value between 0 and 59 for dictionary value @ data['minutes']. Got None. (See ?, line ?). 
2021-11-13 18:54:28 ERROR (MainThread) [homeassistant.config] Invalid config for [automation]: must be a value between 0 and 59 for dictionary value @ data['minutes']. Got None. (See ?, line ?). 
2021-11-13 18:54:39 ERROR (MainThread) [homeassistant.config] Invalid config for [automation]: expected str for dictionary value @ data['from']. Got None. (See ?, line ?). 
2021-11-13 18:54:39 ERROR (MainThread) [homeassistant.config] Invalid config for [automation]: required key not provided @ data['trigger'][1]['platform']. Got None. (See ?, line ?). 
2021-11-13 18:54:39 ERROR (MainThread) [homeassistant.config] Invalid config for [automation]: Unexpected value for condition: 'None'. Expected and, device, not, numeric_state, or, state, sun, template, time, trigger, zone @ data['condition'][0]. Got None. (See ?, line ?). 
2021-11-13 18:54:39 ERROR (MainThread) [homeassistant.config] Invalid config for [automation]: Unexpected value for condition: 'None'. Expected and, device, not, numeric_state, or, state, sun, template, time, trigger, zone @ data['condition'][0]. Got None. (See ?, line ?). 
2021-11-13 18:54:39 ERROR (MainThread) [homeassistant.config] Invalid config for [automation]: required key not provided @ data['action'][4]['domain']. Got None. (See ?, line ?). 
2021-11-13 18:54:40 ERROR (MainThread) [homeassistant.config] Invalid config for [automation]: must be a value between 0 and 59 for dictionary value @ data['minutes']. Got None. (See ?, line ?). 
2021-11-13 18:54:40 ERROR (MainThread) [homeassistant.config] Invalid config for [automation]: must be a value between 0 and 59 for dictionary value @ data['minutes']. Got None. (See ?, line ?). 
2021-11-13 18:54:41 ERROR (MainThread) [homeassistant.helpers.entity] Update for sensor.master_bedroom_tv_aan_vandaag fails
Traceback (most recent call last):
  File "/usr/src/homeassistant/homeassistant/helpers/entity.py", line 468, in async_update_ha_state
    await self.async_device_update()
  File "/usr/src/homeassistant/homeassistant/helpers/entity.py", line 658, in async_device_update
    raise exc
  File "/usr/src/homeassistant/homeassistant/components/history_stats/sensor.py", line 221, in async_update
    await self.hass.async_add_executor_job(
  File "/usr/local/lib/python3.9/concurrent/futures/thread.py", line 52, in run
    result = self.fn(*self.args, **self.kwargs)
  File "/usr/src/homeassistant/homeassistant/components/history_stats/sensor.py", line 227, in _update
    history_list = history.state_changes_during_period(
  File "/usr/src/homeassistant/homeassistant/components/recorder/history.py", line 147, in state_changes_during_period
    with session_scope(hass=hass) as session:
  File "/usr/local/lib/python3.9/contextlib.py", line 119, in __enter__
    return next(self.gen)
  File "/usr/src/homeassistant/homeassistant/components/recorder/util.py", line 73, in session_scope
    session = hass.data[DATA_INSTANCE].get_session()
TypeError: 'NoneType' object is not callable
2021-11-13 18:54:41 ERROR (MainThread) [homeassistant.helpers.entity] Update for sensor.veranda_speaker_aan_vandaag fails
Traceback (most recent call last):
  File "/usr/src/homeassistant/homeassistant/helpers/entity.py", line 468, in async_update_ha_state
    await self.async_device_update()
  File "/usr/src/homeassistant/homeassistant/helpers/entity.py", line 658, in async_device_update
    raise exc
  File "/usr/src/homeassistant/homeassistant/components/history_stats/sensor.py", line 221, in async_update
    await self.hass.async_add_executor_job(
  File "/usr/local/lib/python3.9/concurrent/futures/thread.py", line 52, in run
    result = self.fn(*self.args, **self.kwargs)
  File "/usr/src/homeassistant/homeassistant/components/history_stats/sensor.py", line 227, in _update
    history_list = history.state_changes_during_period(
  File "/usr/src/homeassistant/homeassistant/components/recorder/history.py", line 147, in state_changes_during_period
    with session_scope(hass=hass) as session:
  File "/usr/local/lib/python3.9/contextlib.py", line 119, in __enter__
    return next(self.gen)
  File "/usr/src/homeassistant/homeassistant/components/recorder/util.py", line 73, in session_scope
    session = hass.data[DATA_INSTANCE].get_session()
TypeError: 'NoneType' object is not callable
2021-11-13 18:54:43 WARNING (Thread-123) [homeassistant.util.executor] Thread[SyncWorker_1] is still running at shutdown: File "/usr/local/lib/python3.9/threading.py", line 930, in _bootstrap
    self._bootstrap_inner()
  File "/usr/local/lib/python3.9/threading.py", line 973, in _bootstrap_inner
    self.run()
  File "/usr/local/lib/python3.9/threading.py", line 910, in run
    self._target(*self._args, **self._kwargs)
  File "/usr/local/lib/python3.9/concurrent/futures/thread.py", line 77, in _worker
    work_item.run()
  File "/usr/local/lib/python3.9/concurrent/futures/thread.py", line 52, in run
    result = self.fn(*self.args, **self.kwargs)
  File "/usr/src/homeassistant/homeassistant/components/samsungtv/media_player.py", line 141, in update
    self._state = STATE_ON if self._bridge.is_on() else STATE_OFF
  File "/usr/src/homeassistant/homeassistant/components/samsungtv/bridge.py", line 124, in is_on
    return self._get_remote() is not None
  File "/usr/src/homeassistant/homeassistant/components/samsungtv/bridge.py", line 353, in _get_remote
    self._remote.open()
  File "/usr/local/lib/python3.9/site-packages/samsungtvws/remote.py", line 146, in open
    self.connection = websocket.create_connection(
  File "/usr/local/lib/python3.9/site-packages/websocket/_core.py", line 596, in create_connection
    websock.connect(url, **options)
  File "/usr/local/lib/python3.9/site-packages/websocket/_core.py", line 249, in connect
    self.sock, addrs = connect(url, self.sock_opt, proxy_info(**options),
  File "/usr/local/lib/python3.9/site-packages/websocket/_http.py", line 130, in connect
    sock = _open_socket(addrinfo_list, options.sockopt, options.timeout)
  File "/usr/local/lib/python3.9/site-packages/websocket/_http.py", line 185, in _open_socket
    sock.connect(address)
2021-11-13 18:54:44 ERROR (MainThread) [homeassistant] Error doing job: Future exception was never retrieved
Traceback (most recent call last):
  File "/usr/local/lib/python3.9/site-packages/websocket/_http.py", line 185, in _open_socket
    sock.connect(address)
socket.timeout: timed out

During handling of the above exception, another exception occurred:

Traceback (most recent call last):
  File "/usr/local/lib/python3.9/concurrent/futures/thread.py", line 52, in run
    result = self.fn(*self.args, **self.kwargs)
  File "/usr/src/homeassistant/homeassistant/components/samsungtv/media_player.py", line 141, in update
    self._state = STATE_ON if self._bridge.is_on() else STATE_OFF
  File "/usr/src/homeassistant/homeassistant/components/samsungtv/bridge.py", line 124, in is_on
    return self._get_remote() is not None
  File "/usr/src/homeassistant/homeassistant/components/samsungtv/bridge.py", line 353, in _get_remote
    self._remote.open()
  File "/usr/local/lib/python3.9/site-packages/samsungtvws/remote.py", line 146, in open
    self.connection = websocket.create_connection(
  File "/usr/local/lib/python3.9/site-packages/websocket/_core.py", line 596, in create_connection
    websock.connect(url, **options)
  File "/usr/local/lib/python3.9/site-packages/websocket/_core.py", line 249, in connect
    self.sock, addrs = connect(url, self.sock_opt, proxy_info(**options),
  File "/usr/local/lib/python3.9/site-packages/websocket/_http.py", line 130, in connect
    sock = _open_socket(addrinfo_list, options.sockopt, options.timeout)
  File "/usr/local/lib/python3.9/site-packages/websocket/_http.py", line 185, in _open_socket
    sock.connect(address)
SystemExit
