2022-03-22 09:51:58 WARNING (SyncWorker_0) [homeassistant.util.yaml.loader] YAML file /config/packages/arriving_home.yaml contains duplicate key "trigger". Check lines 144 and 145
2022-03-22 09:52:05 WARNING (SyncWorker_0) [homeassistant.loader] We found a custom integration average which has not been tested by Home Assistant. This component might cause stability problems, be sure to disable it if you experience issues with Home Assistant
2022-03-22 09:52:05 WARNING (SyncWorker_2) [homeassistant.loader] We found a custom integration xiaomi_miio_airpurifier which has not been tested by Home Assistant. This component might cause stability problems, be sure to disable it if you experience issues with Home Assistant
2022-03-22 09:52:05 WARNING (SyncWorker_1) [homeassistant.loader] We found a custom integration adaptive_lighting which has not been tested by Home Assistant. This component might cause stability problems, be sure to disable it if you experience issues with Home Assistant
2022-03-22 09:52:05 WARNING (SyncWorker_1) [homeassistant.loader] We found a custom integration powercalc which has not been tested by Home Assistant. This component might cause stability problems, be sure to disable it if you experience issues with Home Assistant
2022-03-22 09:52:05 WARNING (SyncWorker_0) [homeassistant.loader] We found a custom integration monitor_docker which has not been tested by Home Assistant. This component might cause stability problems, be sure to disable it if you experience issues with Home Assistant
2022-03-22 09:52:05 WARNING (SyncWorker_2) [homeassistant.loader] We found a custom integration audiconnect which has not been tested by Home Assistant. This component might cause stability problems, be sure to disable it if you experience issues with Home Assistant
2022-03-22 09:52:05 WARNING (SyncWorker_1) [homeassistant.loader] We found a custom integration hacs which has not been tested by Home Assistant. This component might cause stability problems, be sure to disable it if you experience issues with Home Assistant
2022-03-22 09:52:05 WARNING (SyncWorker_1) [homeassistant.loader] We found a custom integration shelly which has not been tested by Home Assistant. This component might cause stability problems, be sure to disable it if you experience issues with Home Assistant
2022-03-22 09:52:05 WARNING (SyncWorker_3) [homeassistant.loader] We found a custom integration tuya_v2 which has not been tested by Home Assistant. This component might cause stability problems, be sure to disable it if you experience issues with Home Assistant
2022-03-22 09:52:05 WARNING (SyncWorker_2) [homeassistant.loader] We found a custom integration localtuya which has not been tested by Home Assistant. This component might cause stability problems, be sure to disable it if you experience issues with Home Assistant
2022-03-22 09:52:05 WARNING (SyncWorker_1) [homeassistant.loader] We found a custom integration iphonedetect which has not been tested by Home Assistant. This component might cause stability problems, be sure to disable it if you experience issues with Home Assistant
2022-03-22 09:52:05 WARNING (SyncWorker_0) [homeassistant.loader] We found a custom integration xiaomi_miio_fan which has not been tested by Home Assistant. This component might cause stability problems, be sure to disable it if you experience issues with Home Assistant
2022-03-22 09:52:05 WARNING (SyncWorker_3) [homeassistant.loader] We found a custom integration huesyncbox which has not been tested by Home Assistant. This component might cause stability problems, be sure to disable it if you experience issues with Home Assistant
2022-03-22 09:52:05 WARNING (SyncWorker_6) [homeassistant.loader] We found a custom integration googlewifi which has not been tested by Home Assistant. This component might cause stability problems, be sure to disable it if you experience issues with Home Assistant
2022-03-22 09:52:05 WARNING (SyncWorker_0) [homeassistant.loader] We found a custom integration tgtg which has not been tested by Home Assistant. This component might cause stability problems, be sure to disable it if you experience issues with Home Assistant
2022-03-22 09:52:05 WARNING (SyncWorker_5) [homeassistant.loader] We found a custom integration thermal_comfort which has not been tested by Home Assistant. This component might cause stability problems, be sure to disable it if you experience issues with Home Assistant
2022-03-22 09:52:05 WARNING (SyncWorker_3) [homeassistant.loader] We found a custom integration buienalarm which has not been tested by Home Assistant. This component might cause stability problems, be sure to disable it if you experience issues with Home Assistant
2022-03-22 09:52:05 WARNING (SyncWorker_1) [homeassistant.loader] We found a custom integration xiaomi_miot which has not been tested by Home Assistant. This component might cause stability problems, be sure to disable it if you experience issues with Home Assistant
2022-03-22 09:52:05 WARNING (SyncWorker_4) [homeassistant.loader] We found a custom integration anniversaries which has not been tested by Home Assistant. This component might cause stability problems, be sure to disable it if you experience issues with Home Assistant
2022-03-22 09:52:05 WARNING (SyncWorker_2) [homeassistant.loader] We found a custom integration frigate which has not been tested by Home Assistant. This component might cause stability problems, be sure to disable it if you experience issues with Home Assistant
2022-03-22 09:52:05 WARNING (SyncWorker_5) [homeassistant.loader] We found a custom integration google_home which has not been tested by Home Assistant. This component might cause stability problems, be sure to disable it if you experience issues with Home Assistant
2022-03-22 09:52:05 WARNING (SyncWorker_0) [homeassistant.loader] We found a custom integration deepstack_face which has not been tested by Home Assistant. This component might cause stability problems, be sure to disable it if you experience issues with Home Assistant
2022-03-22 09:52:05 WARNING (SyncWorker_4) [homeassistant.loader] We found a custom integration xiaomi_miio_fan which has not been tested by Home Assistant. This component might cause stability problems, be sure to disable it if you experience issues with Home Assistant
2022-03-22 09:52:05 WARNING (SyncWorker_3) [homeassistant.loader] We found a custom integration ytube_music_player which has not been tested by Home Assistant. This component might cause stability problems, be sure to disable it if you experience issues with Home Assistant
2022-03-22 09:52:05 WARNING (SyncWorker_7) [homeassistant.loader] We found a custom integration scheduler which has not been tested by Home Assistant. This component might cause stability problems, be sure to disable it if you experience issues with Home Assistant
2022-03-22 09:52:05 WARNING (SyncWorker_1) [homeassistant.loader] We found a custom integration afvalbeheer which has not been tested by Home Assistant. This component might cause stability problems, be sure to disable it if you experience issues with Home Assistant
2022-03-22 09:52:05 WARNING (SyncWorker_2) [homeassistant.loader] We found a custom integration neerslag which has not been tested by Home Assistant. This component might cause stability problems, be sure to disable it if you experience issues with Home Assistant
2022-03-22 09:52:12 ERROR (SyncWorker_3) [pymodbus.client.sync] Connection to (192.168.xxx.yyy, 502) failed: [Errno -2] Name does not resolve
2022-03-22 09:52:20 ERROR (MainThread) [homeassistant.config] Invalid config for [automation]: template value should be a string for dictionary value @ data['action'][0]['data']. Got None. (See ?, line ?). 
2022-03-22 09:52:21 ERROR (MainThread) [homeassistant.config] Invalid config for [automation]: template value should be a string for dictionary value @ data['action'][0]['data']. Got None. (See ?, line ?). 
2022-03-22 09:52:21 ERROR (MainThread) [homeassistant.config] Invalid config for [automation]: invalid template (TemplateSyntaxError: unexpected '}', expected ')') for dictionary value @ data['condition'][3]['value_template']. Got None. (See ?, line ?). 
2022-03-22 09:52:21 ERROR (MainThread) [homeassistant.config] Invalid config for [automation]: invalid template (TemplateSyntaxError: unexpected '}', expected ')') for dictionary value @ data['condition'][3]['value_template']. Got None. (See ?, line ?). 
2022-03-22 09:52:23 WARNING (MainThread) [homeassistant.setup] Setup of timer is taking over 10 seconds.
2022-03-22 09:52:23 WARNING (MainThread) [homeassistant.setup] Setup of input_datetime is taking over 10 seconds.
2022-03-22 09:52:23 ERROR (MainThread) [hole] Can not load data from *hole: 192.168.86.101:8081
2022-03-22 09:52:23 WARNING (MainThread) [homeassistant.components.pi_hole] Failed to connect: Can not load data from *hole: 192.168.86.101:8081
2022-03-22 09:52:23 WARNING (MainThread) [homeassistant.config_entries] Config entry 'pihole' for pi_hole integration not ready yet: Can not load data from *hole: 192.168.86.101:8081; Retrying in background
2022-03-22 09:52:23 WARNING (MainThread) [homeassistant.setup] Setup of input_boolean is taking over 10 seconds.
2022-03-22 09:52:23 WARNING (MainThread) [homeassistant.setup] Setup of input_text is taking over 10 seconds.
2022-03-22 09:52:23 WARNING (MainThread) [homeassistant.setup] Setup of input_number is taking over 10 seconds.
2022-03-22 09:52:23 WARNING (MainThread) [homeassistant.components.scene] Setup of scene platform homeassistant is taking over 10 seconds.
2022-03-22 09:52:23 WARNING (MainThread) [homeassistant.setup] Setup of counter is taking over 10 seconds.
2022-03-22 09:52:24 WARNING (MainThread) [homeassistant.setup] Setup of zone is taking over 10 seconds.
2022-03-22 09:52:24 WARNING (MainThread) [homeassistant.setup] Setup of group is taking over 10 seconds.
2022-03-22 09:52:24 WARNING (MainThread) [homeassistant.setup] Setup of input_select is taking over 10 seconds.
2022-03-22 09:52:24 WARNING (MainThread) [homeassistant.setup] Setup of input_button is taking over 10 seconds.
2022-03-22 09:52:24 ERROR (MainThread) [custom_components.audiconnect.audi_connect_account] Login to Audi service failed, trying again in 10 seconds
2022-03-22 09:52:27 WARNING (MainThread) [homeassistant.components.alarm_control_panel] Setup of alarm_control_panel platform manual is taking over 10 seconds.
2022-03-22 09:52:27 WARNING (MainThread) [homeassistant.config_entries] Config entry '192.168.86.83' for synology_dsm integration not ready yet: ConnectionError = <urllib3.connection.HTTPSConnection object at 0xffff858eb6d0>: Failed to establish a new connection: [Errno 113] Host is unreachable; Retrying in background
2022-03-22 09:52:27 WARNING (MainThread) [homeassistant.config_entries] Config entry 'Home Assistant Website' for version integration not ready yet: Timeout of 10 seconds was reached while fetching version for haio; Retrying in background
2022-03-22 09:52:28 WARNING (MainThread) [homeassistant.config_entries] Config entry 'Fan 2' for xiaomi_miio integration not ready yet: Unable to discover the device 192.168.86.46; Retrying in background
2022-03-22 09:52:28 WARNING (MainThread) [homeassistant.config_entries] Config entry 'Fan 1' for xiaomi_miio integration not ready yet: Unable to discover the device 192.168.86.28; Retrying in background
2022-03-22 09:52:34 ERROR (MainThread) [custom_components.powercalc.model_discovery] light.amilya_plafond: Cannot autodiscover model, manufacturer or model unknown from device registry
2022-03-22 09:52:34 ERROR (MainThread) [custom_components.powercalc.sensors.power] Skipping sensor setup light.amilya_plafond: Cannot select a mode (LINEAR, FIXED or LUT, WLED), supply it in the config
2022-03-22 09:52:34 ERROR (MainThread) [custom_components.powercalc.model_discovery] light.amilya_staande_lamp: Cannot autodiscover model, manufacturer or model unknown from device registry
2022-03-22 09:52:34 ERROR (MainThread) [custom_components.powercalc.sensors.power] Skipping sensor setup light.amilya_staande_lamp: Cannot select a mode (LINEAR, FIXED or LUT, WLED), supply it in the config
2022-03-22 09:52:34 ERROR (MainThread) [custom_components.powercalc.sensors.power] Skipping sensor setup light.buiten: ('No lookup file found for mode', 'brightness')
2022-03-22 09:52:36 WARNING (MainThread) [homeassistant.components.integration.sensor] Could not restore last state: [<class 'decimal.ConversionSyntax'>]
2022-03-22 09:52:36 WARNING (MainThread) [homeassistant.components.integration.sensor] Could not restore last state: [<class 'decimal.ConversionSyntax'>]
2022-03-22 09:52:36 WARNING (MainThread) [homeassistant.components.integration.sensor] Could not restore last state: [<class 'decimal.ConversionSyntax'>]
2022-03-22 09:52:36 WARNING (MainThread) [homeassistant.components.integration.sensor] Could not restore last state: [<class 'decimal.ConversionSyntax'>]
2022-03-22 09:52:38 ERROR (SyncWorker_1) [pymodbus.client.sync] Connection to (192.168.xxx.yyy, 502) failed: [Errno -2] Name does not resolve
2022-03-22 09:52:38 ERROR (SyncWorker_1) [homeassistant.components.modbus.modbus] Pymodbus: laadpaal: Modbus Error: [Connection] Failed to connect[ModbusTcpClient(192.168.xxx.yyy:502)]
2022-03-22 09:52:38 ERROR (SyncWorker_4) [pymodbus.client.sync] Connection to (192.168.xxx.yyy, 502) failed: [Errno -2] Name does not resolve
2022-03-22 09:52:38 ERROR (SyncWorker_2) [pymodbus.client.sync] Connection to (192.168.xxx.yyy, 502) failed: [Errno -2] Name does not resolve
2022-03-22 09:52:38 ERROR (SyncWorker_5) [pymodbus.client.sync] Connection to (192.168.xxx.yyy, 502) failed: [Errno -2] Name does not resolve
2022-03-22 09:52:38 ERROR (SyncWorker_9) [pymodbus.client.sync] Connection to (192.168.xxx.yyy, 502) failed: [Errno -2] Name does not resolve
2022-03-22 09:52:38 ERROR (SyncWorker_1) [pymodbus.client.sync] Connection to (192.168.xxx.yyy, 502) failed: [Errno -2] Name does not resolve
2022-03-22 09:52:38 ERROR (SyncWorker_6) [pymodbus.client.sync] Connection to (192.168.xxx.yyy, 502) failed: [Errno -2] Name does not resolve
2022-03-22 09:52:38 ERROR (SyncWorker_1) [pymodbus.client.sync] Connection to (192.168.xxx.yyy, 502) failed: [Errno -2] Name does not resolve
2022-03-22 09:52:38 WARNING (MainThread) [homeassistant.components.sensor] Platform netatmo not ready yet: None; Retrying in background in 30 seconds
2022-03-22 09:52:39 WARNING (MainThread) [homeassistant.components.binary_sensor] Updating ping binary_sensor took longer than the scheduled update interval 0:00:05
2022-03-22 09:52:41 ERROR (MainThread) [homeassistant.components.sensor] scrape: Error on device update!
Traceback (most recent call last):
  File "/usr/src/homeassistant/homeassistant/helpers/entity_platform.py", line 431, in _async_add_entity
    await entity.async_device_update(warning=False)
  File "/usr/src/homeassistant/homeassistant/helpers/entity.py", line 737, in async_device_update
    await task
  File "/usr/src/homeassistant/homeassistant/components/scrape/sensor.py", line 183, in async_update
    await self._async_update_from_rest_data()
  File "/usr/src/homeassistant/homeassistant/components/scrape/sensor.py", line 195, in _async_update_from_rest_data
    value = await self.hass.async_add_executor_job(self._extract_value)
  File "/usr/local/lib/python3.9/concurrent/futures/thread.py", line 58, in run
    result = self.fn(*self.args, **self.kwargs)
  File "/usr/src/homeassistant/homeassistant/components/scrape/sensor.py", line 164, in _extract_value
    tag = raw_data.select(self._select)[self._index]
  File "/usr/local/lib/python3.9/site-packages/bs4/element.py", line 1949, in select
    results = soupsieve.select(selector, self, namespaces, limit, **kwargs)
  File "/usr/local/lib/python3.9/site-packages/soupsieve/__init__.py", line 144, in select
    return compile(select, namespaces, flags, **kwargs).select(tag, limit)
  File "/usr/local/lib/python3.9/site-packages/soupsieve/__init__.py", line 67, in compile
    return cp._cached_css_compile(pattern, ns, cs, flags)
  File "/usr/local/lib/python3.9/site-packages/soupsieve/css_parser.py", line 218, in _cached_css_compile
    CSSParser(
  File "/usr/local/lib/python3.9/site-packages/soupsieve/css_parser.py", line 1159, in process_selectors
    return self.parse_selectors(self.selector_iter(self.pattern), index, flags)
  File "/usr/local/lib/python3.9/site-packages/soupsieve/css_parser.py", line 985, in parse_selectors
    key, m = next(iselector)
  File "/usr/local/lib/python3.9/site-packages/soupsieve/css_parser.py", line 1152, in selector_iter
    raise SelectorSyntaxError(msg, self.pattern, index)
soupsieve.util.SelectorSyntaxError: Invalid character '<' position 0
  line 1:
<span _ngcontent-app-root-c173="">Offline</span>
^
2022-03-22 09:52:41 ERROR (SyncWorker_7) [pymodbus.client.sync] Connection to (192.168.xxx.yyy, 502) failed: [Errno -2] Name does not resolve
2022-03-22 09:52:43 WARNING (MainThread) [homeassistant.components.sensor] Setup of sensor platform scrape is taking over 10 seconds.
2022-03-22 09:52:43 WARNING (MainThread) [homeassistant.components.sensor] Setup of sensor platform scrape is taking over 10 seconds.
2022-03-22 09:52:43 WARNING (MainThread) [homeassistant.components.sensor] Setup of sensor platform scrape is taking over 10 seconds.
2022-03-22 09:52:46 ERROR (MainThread) [custom_components.audiconnect.audi_connect_account] Unable to obtain the vehicle longTerm tripdata of WAUZZZGE6MB019131: 'NoneType' object is not subscriptable
2022-03-22 09:52:46 ERROR (MainThread) [custom_components.audiconnect.audi_connect_account] support_preheater set to False: 502
2022-03-22 09:52:46 ERROR (MainThread) [homeassistant.components.sensor] Error adding entities for domain sensor with platform audiconnect
Traceback (most recent call last):
  File "/usr/src/homeassistant/homeassistant/helpers/entity_platform.py", line 382, in async_add_entities
    await asyncio.gather(*tasks)
  File "/usr/src/homeassistant/homeassistant/helpers/entity_platform.py", line 614, in _async_add_entity
    await entity.add_to_platform_finish()
  File "/usr/src/homeassistant/homeassistant/helpers/entity.py", line 801, in add_to_platform_finish
    self.async_write_ha_state()
  File "/usr/src/homeassistant/homeassistant/helpers/entity.py", line 553, in async_write_ha_state
    self._async_write_ha_state()
  File "/usr/src/homeassistant/homeassistant/helpers/entity.py", line 681, in _async_write_ha_state
    self.hass.states.async_set(
  File "/usr/src/homeassistant/homeassistant/core.py", line 1363, in async_set
    state = State(
  File "/usr/src/homeassistant/homeassistant/core.py", line 1049, in __init__
    raise InvalidStateError(
homeassistant.exceptions.InvalidStateError: Invalid state encountered for entity ID: sensor.audi_e_tron_sportback_shortterm_trip_data. State max length is 255 characters.
2022-03-22 09:52:46 ERROR (MainThread) [homeassistant.components.sensor] Error while setting up audiconnect platform for sensor
Traceback (most recent call last):
  File "/usr/src/homeassistant/homeassistant/helpers/entity_platform.py", line 257, in _async_setup_platform
    await asyncio.gather(*pending)
  File "/usr/src/homeassistant/homeassistant/helpers/entity_platform.py", line 382, in async_add_entities
    await asyncio.gather(*tasks)
  File "/usr/src/homeassistant/homeassistant/helpers/entity_platform.py", line 614, in _async_add_entity
    await entity.add_to_platform_finish()
  File "/usr/src/homeassistant/homeassistant/helpers/entity.py", line 801, in add_to_platform_finish
    self.async_write_ha_state()
  File "/usr/src/homeassistant/homeassistant/helpers/entity.py", line 553, in async_write_ha_state
    self._async_write_ha_state()
  File "/usr/src/homeassistant/homeassistant/helpers/entity.py", line 681, in _async_write_ha_state
    self.hass.states.async_set(
  File "/usr/src/homeassistant/homeassistant/core.py", line 1363, in async_set
    state = State(
  File "/usr/src/homeassistant/homeassistant/core.py", line 1049, in __init__
    raise InvalidStateError(
homeassistant.exceptions.InvalidStateError: Invalid state encountered for entity ID: sensor.audi_e_tron_sportback_shortterm_trip_data. State max length is 255 characters.
2022-03-22 09:52:46 ERROR (SyncWorker_0) [pymodbus.client.sync] Connection to (192.168.xxx.yyy, 502) failed: [Errno -2] Name does not resolve
2022-03-22 09:52:51 WARNING (SyncWorker_9) [homeassistant.components.waze_travel_time.sensor] Error on retrieving data: empty response
2022-03-22 09:52:52 ERROR (SyncWorker_1) [pymodbus.client.sync] Connection to (192.168.xxx.yyy, 502) failed: [Errno -2] Name does not resolve
2022-03-22 09:52:52 ERROR (SyncWorker_8) [pymodbus.client.sync] Connection to (192.168.xxx.yyy, 502) failed: [Errno -2] Name does not resolve
2022-03-22 09:53:00 ERROR (SyncWorker_4) [pymodbus.client.sync] Connection to (192.168.xxx.yyy, 502) failed: [Errno -2] Name does not resolve
2022-03-22 09:53:02 WARNING (MainThread) [homeassistant.components.binary_sensor] Updating ping binary_sensor took longer than the scheduled update interval 0:00:05
2022-03-22 09:53:03 ERROR (MainThread) [hole] Can not load data from *hole: 192.168.86.101:8081
2022-03-22 09:53:03 WARNING (MainThread) [homeassistant.components.pi_hole] Failed to connect: Can not load data from *hole: 192.168.86.101:8081
2022-03-22 09:53:03 ERROR (SyncWorker_2) [pymodbus.client.sync] Connection to (192.168.xxx.yyy, 502) failed: [Errno -2] Name does not resolve
2022-03-22 09:53:03 WARNING (MainThread) [homeassistant.helpers.entity] Update of binary_sensor.google_server is taking over 10 seconds
2022-03-22 09:53:04 WARNING (MainThread) [homeassistant.components.media_player] Updating samsungtv media_player took longer than the scheduled update interval 0:00:10
2022-03-22 09:53:04 WARNING (MainThread) [homeassistant.components.media_player] Updating huesyncbox media_player took longer than the scheduled update interval 0:00:02
2022-03-22 09:53:05 ERROR (SyncWorker_10) [pymodbus.client.sync] Connection to (192.168.xxx.yyy, 502) failed: [Errno -2] Name does not resolve
2022-03-22 09:53:06 WARNING (MainThread) [homeassistant.components.media_player] Updating huesyncbox media_player took longer than the scheduled update interval 0:00:02
2022-03-22 09:53:06 ERROR (SyncWorker_2) [pymodbus.client.sync] Connection to (192.168.xxx.yyy, 502) failed: [Errno -2] Name does not resolve
2022-03-22 09:53:13 WARNING (MainThread) [homeassistant.components.binary_sensor] Updating ping binary_sensor took longer than the scheduled update interval 0:00:05
2022-03-22 09:53:14 WARNING (MainThread) [homeassistant.components.binary_sensor] Updating ping binary_sensor took longer than the scheduled update interval 0:00:05
2022-03-22 09:53:14 ERROR (SyncWorker_4) [pymodbus.client.sync] Connection to (192.168.xxx.yyy, 502) failed: [Errno -2] Name does not resolve
2022-03-22 09:53:17 ERROR (SyncWorker_19) [pymodbus.client.sync] Connection to (192.168.xxx.yyy, 502) failed: [Errno -2] Name does not resolve
2022-03-22 09:53:17 WARNING (MainThread) [homeassistant.components.media_player] Updating huesyncbox media_player took longer than the scheduled update interval 0:00:02
2022-03-22 09:53:17 ERROR (SyncWorker_8) [pymodbus.client.sync] Connection to (192.168.xxx.yyy, 502) failed: [Errno -2] Name does not resolve
2022-03-22 09:53:17 ERROR (SyncWorker_3) [pymodbus.client.sync] Connection to (192.168.xxx.yyy, 502) failed: [Errno -2] Name does not resolve
2022-03-22 09:53:17 ERROR (SyncWorker_4) [pymodbus.client.sync] Connection to (192.168.xxx.yyy, 502) failed: [Errno -2] Name does not resolve
2022-03-22 09:53:17 ERROR (SyncWorker_6) [pymodbus.client.sync] Connection to (192.168.xxx.yyy, 502) failed: [Errno -2] Name does not resolve
2022-03-22 09:53:17 ERROR (SyncWorker_1) [pymodbus.client.sync] Connection to (192.168.xxx.yyy, 502) failed: [Errno -2] Name does not resolve
2022-03-22 09:53:18 ERROR (SyncWorker_20) [pymodbus.client.sync] Connection to (192.168.xxx.yyy, 502) failed: [Errno -2] Name does not resolve
2022-03-22 09:53:18 ERROR (SyncWorker_15) [pymodbus.client.sync] Connection to (192.168.xxx.yyy, 502) failed: [Errno -2] Name does not resolve
2022-03-22 09:53:18 ERROR (SyncWorker_13) [pymodbus.client.sync] Connection to (192.168.xxx.yyy, 502) failed: [Errno -2] Name does not resolve
2022-03-22 09:53:18 ERROR (SyncWorker_11) [pymodbus.client.sync] Connection to (192.168.xxx.yyy, 502) failed: [Errno -2] Name does not resolve
2022-03-22 09:53:18 ERROR (SyncWorker_14) [pymodbus.client.sync] Connection to (192.168.xxx.yyy, 502) failed: [Errno -2] Name does not resolve
2022-03-22 09:53:18 WARNING (MainThread) [homeassistant.components.binary_sensor] Updating ping binary_sensor took longer than the scheduled update interval 0:00:05
2022-03-22 09:53:18 ERROR (SyncWorker_18) [pymodbus.client.sync] Connection to (192.168.xxx.yyy, 502) failed: [Errno -2] Name does not resolve
2022-03-22 09:53:23 ERROR (SyncWorker_8) [pymodbus.client.sync] Connection to (192.168.xxx.yyy, 502) failed: [Errno -2] Name does not resolve
2022-03-22 09:53:28 ERROR (SyncWorker_6) [pymodbus.client.sync] Connection to (192.168.xxx.yyy, 502) failed: [Errno -2] Name does not resolve
2022-03-22 09:53:28 ERROR (SyncWorker_17) [pymodbus.client.sync] Connection to (192.168.xxx.yyy, 502) failed: [Errno -2] Name does not resolve
2022-03-22 09:53:28 ERROR (SyncWorker_9) [pymodbus.client.sync] Connection to (192.168.xxx.yyy, 502) failed: [Errno -2] Name does not resolve
2022-03-22 09:53:28 ERROR (SyncWorker_7) [pymodbus.client.sync] Connection to (192.168.xxx.yyy, 502) failed: [Errno -2] Name does not resolve
2022-03-22 09:53:28 ERROR (SyncWorker_10) [pymodbus.client.sync] Connection to (192.168.xxx.yyy, 502) failed: [Errno -2] Name does not resolve
2022-03-22 09:53:29 ERROR (SyncWorker_20) [pymodbus.client.sync] Connection to (192.168.xxx.yyy, 502) failed: [Errno -2] Name does not resolve
2022-03-22 09:53:29 ERROR (SyncWorker_15) [pymodbus.client.sync] Connection to (192.168.xxx.yyy, 502) failed: [Errno -2] Name does not resolve
2022-03-22 09:53:29 ERROR (SyncWorker_13) [pymodbus.client.sync] Connection to (192.168.xxx.yyy, 502) failed: [Errno -2] Name does not resolve
2022-03-22 09:53:34 ERROR (SyncWorker_17) [pymodbus.client.sync] Connection to (192.168.xxx.yyy, 502) failed: [Errno -2] Name does not resolve
2022-03-22 09:53:38 ERROR (SyncWorker_0) [pymodbus.client.sync] Connection to (192.168.xxx.yyy, 502) failed: [Errno -2] Name does not resolve
2022-03-22 09:53:44 ERROR (SyncWorker_18) [pymodbus.client.sync] Connection to (192.168.xxx.yyy, 502) failed: [Errno -2] Name does not resolve
2022-03-22 09:53:44 ERROR (SyncWorker_13) [pymodbus.client.sync] Connection to (192.168.xxx.yyy, 502) failed: [Errno -2] Name does not resolve
2022-03-22 09:53:44 ERROR (SyncWorker_2) [pymodbus.client.sync] Connection to (192.168.xxx.yyy, 502) failed: [Errno -2] Name does not resolve
2022-03-22 09:53:44 ERROR (SyncWorker_11) [pymodbus.client.sync] Connection to (192.168.xxx.yyy, 502) failed: [Errno -2] Name does not resolve
2022-03-22 09:53:44 ERROR (SyncWorker_11) [pymodbus.client.sync] Connection to (192.168.xxx.yyy, 502) failed: [Errno -2] Name does not resolve
2022-03-22 09:53:44 ERROR (SyncWorker_1) [pymodbus.client.sync] Connection to (192.168.xxx.yyy, 502) failed: [Errno -2] Name does not resolve
2022-03-22 09:53:44 ERROR (SyncWorker_10) [pymodbus.client.sync] Connection to (192.168.xxx.yyy, 502) failed: [Errno -2] Name does not resolve
2022-03-22 09:53:44 ERROR (SyncWorker_17) [pymodbus.client.sync] Connection to (192.168.xxx.yyy, 502) failed: [Errno -2] Name does not resolve
2022-03-22 09:53:49 ERROR (SyncWorker_15) [pymodbus.client.sync] Connection to (192.168.xxx.yyy, 502) failed: [Errno -2] Name does not resolve
2022-03-22 09:53:54 WARNING (MainThread) [homeassistant.components.binary_sensor] Updating ping binary_sensor took longer than the scheduled update interval 0:00:05
2022-03-22 09:53:54 ERROR (SyncWorker_8) [pymodbus.client.sync] Connection to (192.168.xxx.yyy, 502) failed: [Errno -2] Name does not resolve
2022-03-22 09:53:58 ERROR (SyncWorker_2) [pymodbus.client.sync] Connection to (192.168.xxx.yyy, 502) failed: [Errno -2] Name does not resolve
2022-03-22 09:53:58 ERROR (SyncWorker_22) [pymodbus.client.sync] Connection to (192.168.xxx.yyy, 502) failed: [Errno -2] Name does not resolve
2022-03-22 09:53:59 ERROR (SyncWorker_9) [pymodbus.client.sync] Connection to (192.168.xxx.yyy, 502) failed: [Errno -2] Name does not resolve
2022-03-22 09:53:59 ERROR (SyncWorker_7) [pymodbus.client.sync] Connection to (192.168.xxx.yyy, 502) failed: [Errno -2] Name does not resolve
2022-03-22 09:53:59 ERROR (SyncWorker_0) [pymodbus.client.sync] Connection to (192.168.xxx.yyy, 502) failed: [Errno -2] Name does not resolve
2022-03-22 09:53:59 ERROR (SyncWorker_21) [pymodbus.client.sync] Connection to (192.168.xxx.yyy, 502) failed: [Errno -2] Name does not resolve
2022-03-22 09:53:59 ERROR (SyncWorker_5) [pymodbus.client.sync] Connection to (192.168.xxx.yyy, 502) failed: [Errno -2] Name does not resolve
2022-03-22 09:53:59 ERROR (SyncWorker_15) [pymodbus.client.sync] Connection to (192.168.xxx.yyy, 502) failed: [Errno -2] Name does not resolve
2022-03-22 09:54:04 ERROR (SyncWorker_8) [pymodbus.client.sync] Connection to (192.168.xxx.yyy, 502) failed: [Errno -2] Name does not resolve
2022-03-22 09:54:09 ERROR (SyncWorker_13) [pymodbus.client.sync] Connection to (192.168.xxx.yyy, 502) failed: [Errno -2] Name does not resolve
2022-03-22 09:54:14 ERROR (SyncWorker_15) [pymodbus.client.sync] Connection to (192.168.xxx.yyy, 502) failed: [Errno -2] Name does not resolve
2022-03-22 09:54:14 ERROR (SyncWorker_24) [pymodbus.client.sync] Connection to (192.168.xxx.yyy, 502) failed: [Errno -2] Name does not resolve
2022-03-22 09:54:14 ERROR (SyncWorker_8) [pymodbus.client.sync] Connection to (192.168.xxx.yyy, 502) failed: [Errno -2] Name does not resolve
2022-03-22 09:54:14 ERROR (SyncWorker_14) [pymodbus.client.sync] Connection to (192.168.xxx.yyy, 502) failed: [Errno -2] Name does not resolve
2022-03-22 09:54:14 ERROR (SyncWorker_1) [pymodbus.client.sync] Connection to (192.168.xxx.yyy, 502) failed: [Errno -2] Name does not resolve
2022-03-22 09:54:14 ERROR (SyncWorker_7) [pymodbus.client.sync] Connection to (192.168.xxx.yyy, 502) failed: [Errno -2] Name does not resolve
2022-03-22 09:54:14 ERROR (SyncWorker_10) [pymodbus.client.sync] Connection to (192.168.xxx.yyy, 502) failed: [Errno -2] Name does not resolve
2022-03-22 09:54:14 ERROR (SyncWorker_12) [pymodbus.client.sync] Connection to (192.168.xxx.yyy, 502) failed: [Errno -2] Name does not resolve
2022-03-22 09:54:19 ERROR (SyncWorker_2) [pymodbus.client.sync] Connection to (192.168.xxx.yyy, 502) failed: [Errno -2] Name does not resolve
2022-03-22 09:54:24 ERROR (SyncWorker_22) [pymodbus.client.sync] Connection to (192.168.xxx.yyy, 502) failed: [Errno -2] Name does not resolve
2022-03-22 09:54:28 WARNING (MainThread) [homeassistant.helpers.template] Template warning: 'timestamp_custom' got invalid input 'n/a' when rendering template '{% if states('device_tracker.audi_e_tron_sportback_position') =="home" %} Auto staat thuis.

  {% if (states('input_number.car_smart_charging_target_percentage') | float(default=0)) < (states('sensor.audi_e_tron_sportback_state_of_charge') | float(default=0) ) %} 
  Er hoeft niet te worden geladen: laaddoel {{states('input_number.car_smart_charging_target_percentage') |round()}}% is al bereikt.

  {% else %}
 {% set target = states('input_number.car_smart_charging_target_percentage') | float(default=0) %}
 {% set soc = states('sensor.audi_e_tron_sportback_state_of_charge') | float(default=0) %}
 {% set nog_te_laden_procent = [target - soc, 0] | max %}
 {% set nog_te_laden_minuten = nog_te_laden_procent * 8.5 | round(2) %}

   Van **{{states('sensor.audi_e_tron_sportback_state_of_charge') | round() }}%** naar  **{{states('input_number.car_smart_charging_target_percentage') | round() }}%** =  **{{nog_te_laden_procent | round() }}%** laden = laadtijd **{{ (nog_te_laden_minuten | float(default=0) * 60) | timestamp_custom('%-Hu%M', false)}}**
  {% endif %}

{% else %} Auto staat niet thuis.
Resterende laadtijd: {{states('sensor.audi_e_tron_sportback_remaining_charge_time') | timestamp_custom('%Hu%M')}}
{% endif %}' but no default was specified. Currently 'timestamp_custom' will return 'n/a', however this template will fail to render in Home Assistant core 2022.1
2022-03-22 09:54:29 WARNING (MainThread) [homeassistant.helpers.template] Template warning: 'timestamp_custom' got invalid input 'n/a' when rendering template '{% if states('device_tracker.audi_e_tron_sportback_position') =="home" %} Auto staat thuis.

  {% if (states('input_number.car_smart_charging_target_percentage') | float(default=0)) < (states('sensor.audi_e_tron_sportback_state_of_charge') | float(default=0) ) %} 
  Er hoeft niet te worden geladen: laaddoel {{states('input_number.car_smart_charging_target_percentage') |round()}}% is al bereikt.

  {% else %}
 {% set target = states('input_number.car_smart_charging_target_percentage') | float(default=0) %}
 {% set soc = states('sensor.audi_e_tron_sportback_state_of_charge') | float(default=0) %}
 {% set nog_te_laden_procent = [target - soc, 0] | max %}
 {% set nog_te_laden_minuten = nog_te_laden_procent * 8.5 | round(2) %}

   Van **{{states('sensor.audi_e_tron_sportback_state_of_charge') | round() }}%** naar  **{{states('input_number.car_smart_charging_target_percentage') | round() }}%** =  **{{nog_te_laden_procent | round() }}%** laden = laadtijd **{{ (nog_te_laden_minuten | float(default=0) * 60) | timestamp_custom('%-Hu%M', false)}}**
  {% endif %}

{% else %} Auto staat niet thuis.
Resterende laadtijd: {{states('sensor.audi_e_tron_sportback_remaining_charge_time') | timestamp_custom('%Hu%M')}}
{% endif %}' but no default was specified. Currently 'timestamp_custom' will return 'n/a', however this template will fail to render in Home Assistant core 2022.1
2022-03-22 09:54:29 ERROR (SyncWorker_12) [pymodbus.client.sync] Connection to (192.168.xxx.yyy, 502) failed: [Errno -2] Name does not resolve
2022-03-22 09:54:29 ERROR (SyncWorker_21) [pymodbus.client.sync] Connection to (192.168.xxx.yyy, 502) failed: [Errno -2] Name does not resolve
2022-03-22 09:54:29 ERROR (SyncWorker_15) [pymodbus.client.sync] Connection to (192.168.xxx.yyy, 502) failed: [Errno -2] Name does not resolve
2022-03-22 09:54:29 ERROR (SyncWorker_14) [pymodbus.client.sync] Connection to (192.168.xxx.yyy, 502) failed: [Errno -2] Name does not resolve
2022-03-22 09:54:29 ERROR (SyncWorker_19) [pymodbus.client.sync] Connection to (192.168.xxx.yyy, 502) failed: [Errno -2] Name does not resolve
2022-03-22 09:54:29 ERROR (SyncWorker_20) [pymodbus.client.sync] Connection to (192.168.xxx.yyy, 502) failed: [Errno -2] Name does not resolve
2022-03-22 09:54:29 ERROR (SyncWorker_0) [pymodbus.client.sync] Connection to (192.168.xxx.yyy, 502) failed: [Errno -2] Name does not resolve
2022-03-22 09:54:29 ERROR (SyncWorker_10) [pymodbus.client.sync] Connection to (192.168.xxx.yyy, 502) failed: [Errno -2] Name does not resolve
2022-03-22 09:54:34 ERROR (SyncWorker_23) [pymodbus.client.sync] Connection to (192.168.xxx.yyy, 502) failed: [Errno -2] Name does not resolve
2022-03-22 09:54:39 ERROR (SyncWorker_21) [pymodbus.client.sync] Connection to (192.168.xxx.yyy, 502) failed: [Errno -2] Name does not resolve
2022-03-22 09:54:43 WARNING (SyncWorker_2) [homeassistant.util.yaml.loader] YAML file /config/packages/arriving_home.yaml contains duplicate key "trigger". Check lines 144 and 145
2022-03-22 09:54:44 ERROR (SyncWorker_1) [pymodbus.client.sync] Connection to (192.168.xxx.yyy, 502) failed: [Errno -2] Name does not resolve
2022-03-22 09:54:44 ERROR (SyncWorker_24) [pymodbus.client.sync] Connection to (192.168.xxx.yyy, 502) failed: [Errno -2] Name does not resolve
2022-03-22 09:54:44 ERROR (SyncWorker_11) [pymodbus.client.sync] Connection to (192.168.xxx.yyy, 502) failed: [Errno -2] Name does not resolve
2022-03-22 09:54:44 ERROR (SyncWorker_0) [pymodbus.client.sync] Connection to (192.168.xxx.yyy, 502) failed: [Errno -2] Name does not resolve
2022-03-22 09:54:44 ERROR (SyncWorker_19) [pymodbus.client.sync] Connection to (192.168.xxx.yyy, 502) failed: [Errno -2] Name does not resolve
2022-03-22 09:54:44 ERROR (SyncWorker_15) [pymodbus.client.sync] Connection to (192.168.xxx.yyy, 502) failed: [Errno -2] Name does not resolve
2022-03-22 09:54:44 ERROR (SyncWorker_16) [pymodbus.client.sync] Connection to (192.168.xxx.yyy, 502) failed: [Errno -2] Name does not resolve
2022-03-22 09:54:45 ERROR (SyncWorker_21) [pymodbus.client.sync] Connection to (192.168.xxx.yyy, 502) failed: [Errno -2] Name does not resolve
2022-03-22 09:54:47 ERROR (MainThread) [homeassistant.config] Invalid config for [automation]: template value should be a string for dictionary value @ data['action'][0]['data']. Got None. (See ?, line ?). 
2022-03-22 09:54:47 ERROR (MainThread) [homeassistant.config] Invalid config for [automation]: template value should be a string for dictionary value @ data['action'][0]['data']. Got None. (See ?, line ?). 
2022-03-22 09:54:47 ERROR (MainThread) [homeassistant.config] Invalid config for [automation]: invalid template (TemplateSyntaxError: unexpected '}', expected ')') for dictionary value @ data['condition'][3]['value_template']. Got None. (See ?, line ?). 
2022-03-22 09:54:47 ERROR (MainThread) [homeassistant.config] Invalid config for [automation]: invalid template (TemplateSyntaxError: unexpected '}', expected ')') for dictionary value @ data['condition'][3]['value_template']. Got None. (See ?, line ?). 
2022-03-22 09:54:49 ERROR (SyncWorker_24) [pymodbus.client.sync] Connection to (192.168.xxx.yyy, 502) failed: [Errno -2] Name does not resolve
2022-03-22 09:54:51 ERROR (MainThread) [homeassistant.util.logging] Exception in async_schedule_update_ha_state when dispatching 'audiconnect.updated': ()
Traceback (most recent call last):
  File "/usr/src/homeassistant/homeassistant/helpers/entity.py", line 712, in async_schedule_update_ha_state
    self.async_write_ha_state()
  File "/usr/src/homeassistant/homeassistant/helpers/entity.py", line 553, in async_write_ha_state
    self._async_write_ha_state()
  File "/usr/src/homeassistant/homeassistant/helpers/entity.py", line 681, in _async_write_ha_state
    self.hass.states.async_set(
  File "/usr/src/homeassistant/homeassistant/core.py", line 1363, in async_set
    state = State(
  File "/usr/src/homeassistant/homeassistant/core.py", line 1049, in __init__
    raise InvalidStateError(
homeassistant.exceptions.InvalidStateError: Invalid state encountered for entity ID: sensor.audi_e_tron_sportback_shortterm_trip_data. State max length is 255 characters.

2022-03-22 09:54:51 ERROR (MainThread) [homeassistant.util.logging] Exception in async_schedule_update_ha_state when dispatching 'audiconnect.updated': ()
Traceback (most recent call last):
  File "/usr/src/homeassistant/homeassistant/helpers/entity.py", line 712, in async_schedule_update_ha_state
    self.async_write_ha_state()
  File "/usr/src/homeassistant/homeassistant/helpers/entity.py", line 553, in async_write_ha_state
    self._async_write_ha_state()
  File "/usr/src/homeassistant/homeassistant/helpers/entity.py", line 681, in _async_write_ha_state
    self.hass.states.async_set(
  File "/usr/src/homeassistant/homeassistant/core.py", line 1363, in async_set
    state = State(
  File "/usr/src/homeassistant/homeassistant/core.py", line 1049, in __init__
    raise InvalidStateError(
homeassistant.exceptions.InvalidStateError: Invalid state encountered for entity ID: sensor.audi_e_tron_sportback_shortterm_trip_user_reset. State max length is 255 characters.

2022-03-22 09:54:51 WARNING (MainThread) [homeassistant.helpers.template] Template warning: 'timestamp_custom' got invalid input 'n/a' when rendering template '{% if states('device_tracker.audi_e_tron_sportback_position') =="home" %} Auto staat thuis.

  {% if (states('input_number.car_smart_charging_target_percentage') | float(default=0)) < (states('sensor.audi_e_tron_sportback_state_of_charge') | float(default=0) ) %} 
  Er hoeft niet te worden geladen: laaddoel {{states('input_number.car_smart_charging_target_percentage') |round()}}% is al bereikt.

  {% else %}
 {% set target = states('input_number.car_smart_charging_target_percentage') | float(default=0) %}
 {% set soc = states('sensor.audi_e_tron_sportback_state_of_charge') | float(default=0) %}
 {% set nog_te_laden_procent = [target - soc, 0] | max %}
 {% set nog_te_laden_minuten = nog_te_laden_procent * 8.5 | round(2) %}

   Van **{{states('sensor.audi_e_tron_sportback_state_of_charge') | round() }}%** naar  **{{states('input_number.car_smart_charging_target_percentage') | round() }}%** =  **{{nog_te_laden_procent | round() }}%** laden = laadtijd **{{ (nog_te_laden_minuten | float(default=0) * 60) | timestamp_custom('%-Hu%M', false)}}**
  {% endif %}

{% else %} Auto staat niet thuis.
Resterende laadtijd: {{states('sensor.audi_e_tron_sportback_remaining_charge_time') | timestamp_custom('%Hu%M')}}
{% endif %}' but no default was specified. Currently 'timestamp_custom' will return 'n/a', however this template will fail to render in Home Assistant core 2022.1
2022-03-22 09:54:54 ERROR (SyncWorker_21) [pymodbus.client.sync] Connection to (192.168.xxx.yyy, 502) failed: [Errno -2] Name does not resolve
2022-03-22 09:54:59 ERROR (SyncWorker_4) [pymodbus.client.sync] Connection to (192.168.xxx.yyy, 502) failed: [Errno -2] Name does not resolve
2022-03-22 09:54:59 ERROR (SyncWorker_3) [pymodbus.client.sync] Connection to (192.168.xxx.yyy, 502) failed: [Errno -2] Name does not resolve
2022-03-22 09:54:59 ERROR (SyncWorker_13) [pymodbus.client.sync] Connection to (192.168.xxx.yyy, 502) failed: [Errno -2] Name does not resolve
2022-03-22 09:54:59 ERROR (SyncWorker_1) [pymodbus.client.sync] Connection to (192.168.xxx.yyy, 502) failed: [Errno -2] Name does not resolve
2022-03-22 09:54:59 ERROR (SyncWorker_24) [pymodbus.client.sync] Connection to (192.168.xxx.yyy, 502) failed: [Errno -2] Name does not resolve
2022-03-22 09:54:59 ERROR (SyncWorker_11) [pymodbus.client.sync] Connection to (192.168.xxx.yyy, 502) failed: [Errno -2] Name does not resolve
2022-03-22 09:54:59 ERROR (SyncWorker_0) [pymodbus.client.sync] Connection to (192.168.xxx.yyy, 502) failed: [Errno -2] Name does not resolve
2022-03-22 09:54:59 ERROR (SyncWorker_19) [pymodbus.client.sync] Connection to (192.168.xxx.yyy, 502) failed: [Errno -2] Name does not resolve
2022-03-22 09:55:04 ERROR (SyncWorker_22) [pymodbus.client.sync] Connection to (192.168.xxx.yyy, 502) failed: [Errno -2] Name does not resolve
2022-03-22 09:55:09 ERROR (SyncWorker_11) [pymodbus.client.sync] Connection to (192.168.xxx.yyy, 502) failed: [Errno -2] Name does not resolve
2022-03-22 09:55:14 ERROR (SyncWorker_8) [pymodbus.client.sync] Connection to (192.168.xxx.yyy, 502) failed: [Errno -2] Name does not resolve
2022-03-22 09:55:14 ERROR (SyncWorker_15) [pymodbus.client.sync] Connection to (192.168.xxx.yyy, 502) failed: [Errno -2] Name does not resolve
2022-03-22 09:55:14 ERROR (SyncWorker_14) [pymodbus.client.sync] Connection to (192.168.xxx.yyy, 502) failed: [Errno -2] Name does not resolve
2022-03-22 09:55:14 ERROR (SyncWorker_16) [pymodbus.client.sync] Connection to (192.168.xxx.yyy, 502) failed: [Errno -2] Name does not resolve
2022-03-22 09:55:14 ERROR (SyncWorker_19) [pymodbus.client.sync] Connection to (192.168.xxx.yyy, 502) failed: [Errno -2] Name does not resolve
2022-03-22 09:55:14 ERROR (SyncWorker_24) [pymodbus.client.sync] Connection to (192.168.xxx.yyy, 502) failed: [Errno -2] Name does not resolve
2022-03-22 09:55:14 ERROR (SyncWorker_21) [pymodbus.client.sync] Connection to (192.168.xxx.yyy, 502) failed: [Errno -2] Name does not resolve
2022-03-22 09:55:14 ERROR (SyncWorker_21) [pymodbus.client.sync] Connection to (192.168.xxx.yyy, 502) failed: [Errno -2] Name does not resolve
2022-03-22 09:55:19 ERROR (SyncWorker_3) [pymodbus.client.sync] Connection to (192.168.xxx.yyy, 502) failed: [Errno -2] Name does not resolve
2022-03-22 09:55:24 ERROR (SyncWorker_15) [pymodbus.client.sync] Connection to (192.168.xxx.yyy, 502) failed: [Errno -2] Name does not resolve
2022-03-22 09:55:29 ERROR (SyncWorker_16) [pymodbus.client.sync] Connection to (192.168.xxx.yyy, 502) failed: [Errno -2] Name does not resolve
2022-03-22 09:55:29 ERROR (SyncWorker_19) [pymodbus.client.sync] Connection to (192.168.xxx.yyy, 502) failed: [Errno -2] Name does not resolve
2022-03-22 09:55:29 ERROR (SyncWorker_24) [pymodbus.client.sync] Connection to (192.168.xxx.yyy, 502) failed: [Errno -2] Name does not resolve
2022-03-22 09:55:29 ERROR (SyncWorker_10) [pymodbus.client.sync] Connection to (192.168.xxx.yyy, 502) failed: [Errno -2] Name does not resolve
2022-03-22 09:55:29 ERROR (SyncWorker_6) [pymodbus.client.sync] Connection to (192.168.xxx.yyy, 502) failed: [Errno -2] Name does not resolve
2022-03-22 09:55:29 ERROR (SyncWorker_3) [pymodbus.client.sync] Connection to (192.168.xxx.yyy, 502) failed: [Errno -2] Name does not resolve
2022-03-22 09:55:29 ERROR (SyncWorker_17) [pymodbus.client.sync] Connection to (192.168.xxx.yyy, 502) failed: [Errno -2] Name does not resolve
2022-03-22 09:55:29 ERROR (SyncWorker_11) [pymodbus.client.sync] Connection to (192.168.xxx.yyy, 502) failed: [Errno -2] Name does not resolve
2022-03-22 09:55:34 ERROR (SyncWorker_2) [pymodbus.client.sync] Connection to (192.168.xxx.yyy, 502) failed: [Errno -2] Name does not resolve
2022-03-22 09:55:39 ERROR (SyncWorker_25) [pymodbus.client.sync] Connection to (192.168.xxx.yyy, 502) failed: [Errno -2] Name does not resolve
2022-03-22 09:55:44 ERROR (SyncWorker_7) [pymodbus.client.sync] Connection to (192.168.xxx.yyy, 502) failed: [Errno -2] Name does not resolve
2022-03-22 09:55:44 ERROR (SyncWorker_8) [pymodbus.client.sync] Connection to (192.168.xxx.yyy, 502) failed: [Errno -2] Name does not resolve
2022-03-22 09:55:44 ERROR (SyncWorker_5) [pymodbus.client.sync] Connection to (192.168.xxx.yyy, 502) failed: [Errno -2] Name does not resolve
2022-03-22 09:55:44 ERROR (SyncWorker_3) [pymodbus.client.sync] Connection to (192.168.xxx.yyy, 502) failed: [Errno -2] Name does not resolve
2022-03-22 09:55:44 ERROR (SyncWorker_15) [pymodbus.client.sync] Connection to (192.168.xxx.yyy, 502) failed: [Errno -2] Name does not resolve
2022-03-22 09:55:44 ERROR (SyncWorker_11) [pymodbus.client.sync] Connection to (192.168.xxx.yyy, 502) failed: [Errno -2] Name does not resolve
2022-03-22 09:55:44 ERROR (SyncWorker_0) [pymodbus.client.sync] Connection to (192.168.xxx.yyy, 502) failed: [Errno -2] Name does not resolve
2022-03-22 09:55:44 ERROR (SyncWorker_24) [pymodbus.client.sync] Connection to (192.168.xxx.yyy, 502) failed: [Errno -2] Name does not resolve
2022-03-22 09:55:49 ERROR (SyncWorker_9) [pymodbus.client.sync] Connection to (192.168.xxx.yyy, 502) failed: [Errno -2] Name does not resolve
2022-03-22 09:55:54 ERROR (SyncWorker_14) [pymodbus.client.sync] Connection to (192.168.xxx.yyy, 502) failed: [Errno -2] Name does not resolve
2022-03-22 09:55:59 ERROR (SyncWorker_6) [pymodbus.client.sync] Connection to (192.168.xxx.yyy, 502) failed: [Errno -2] Name does not resolve
2022-03-22 09:55:59 ERROR (SyncWorker_20) [pymodbus.client.sync] Connection to (192.168.xxx.yyy, 502) failed: [Errno -2] Name does not resolve
2022-03-22 09:55:59 ERROR (SyncWorker_22) [pymodbus.client.sync] Connection to (192.168.xxx.yyy, 502) failed: [Errno -2] Name does not resolve
2022-03-22 09:55:59 ERROR (SyncWorker_21) [pymodbus.client.sync] Connection to (192.168.xxx.yyy, 502) failed: [Errno -2] Name does not resolve
2022-03-22 09:55:59 ERROR (SyncWorker_13) [pymodbus.client.sync] Connection to (192.168.xxx.yyy, 502) failed: [Errno -2] Name does not resolve
2022-03-22 09:55:59 ERROR (SyncWorker_19) [pymodbus.client.sync] Connection to (192.168.xxx.yyy, 502) failed: [Errno -2] Name does not resolve
2022-03-22 09:55:59 ERROR (SyncWorker_12) [pymodbus.client.sync] Connection to (192.168.xxx.yyy, 502) failed: [Errno -2] Name does not resolve
2022-03-22 09:55:59 ERROR (SyncWorker_1) [pymodbus.client.sync] Connection to (192.168.xxx.yyy, 502) failed: [Errno -2] Name does not resolve
2022-03-22 09:56:04 ERROR (SyncWorker_11) [pymodbus.client.sync] Connection to (192.168.xxx.yyy, 502) failed: [Errno -2] Name does not resolve
2022-03-22 09:56:09 ERROR (SyncWorker_23) [pymodbus.client.sync] Connection to (192.168.xxx.yyy, 502) failed: [Errno -2] Name does not resolve
2022-03-22 09:56:14 ERROR (SyncWorker_4) [pymodbus.client.sync] Connection to (192.168.xxx.yyy, 502) failed: [Errno -2] Name does not resolve
2022-03-22 09:56:14 ERROR (SyncWorker_5) [pymodbus.client.sync] Connection to (192.168.xxx.yyy, 502) failed: [Errno -2] Name does not resolve
2022-03-22 09:56:14 ERROR (SyncWorker_2) [pymodbus.client.sync] Connection to (192.168.xxx.yyy, 502) failed: [Errno -2] Name does not resolve
2022-03-22 09:56:14 ERROR (SyncWorker_12) [pymodbus.client.sync] Connection to (192.168.xxx.yyy, 502) failed: [Errno -2] Name does not resolve
2022-03-22 09:56:14 ERROR (SyncWorker_25) [pymodbus.client.sync] Connection to (192.168.xxx.yyy, 502) failed: [Errno -2] Name does not resolve
2022-03-22 09:56:14 ERROR (SyncWorker_0) [pymodbus.client.sync] Connection to (192.168.xxx.yyy, 502) failed: [Errno -2] Name does not resolve
2022-03-22 09:56:14 ERROR (SyncWorker_19) [pymodbus.client.sync] Connection to (192.168.xxx.yyy, 502) failed: [Errno -2] Name does not resolve
2022-03-22 09:56:14 ERROR (SyncWorker_24) [pymodbus.client.sync] Connection to (192.168.xxx.yyy, 502) failed: [Errno -2] Name does not resolve
2022-03-22 09:56:19 ERROR (SyncWorker_7) [pymodbus.client.sync] Connection to (192.168.xxx.yyy, 502) failed: [Errno -2] Name does not resolve
2022-03-22 09:56:24 ERROR (SyncWorker_18) [pymodbus.client.sync] Connection to (192.168.xxx.yyy, 502) failed: [Errno -2] Name does not resolve
2022-03-22 09:56:29 ERROR (SyncWorker_4) [pymodbus.client.sync] Connection to (192.168.xxx.yyy, 502) failed: [Errno -2] Name does not resolve
2022-03-22 09:56:29 ERROR (SyncWorker_5) [pymodbus.client.sync] Connection to (192.168.xxx.yyy, 502) failed: [Errno -2] Name does not resolve
2022-03-22 09:56:29 ERROR (SyncWorker_2) [pymodbus.client.sync] Connection to (192.168.xxx.yyy, 502) failed: [Errno -2] Name does not resolve
2022-03-22 09:56:29 ERROR (SyncWorker_12) [pymodbus.client.sync] Connection to (192.168.xxx.yyy, 502) failed: [Errno -2] Name does not resolve
2022-03-22 09:56:29 ERROR (SyncWorker_25) [pymodbus.client.sync] Connection to (192.168.xxx.yyy, 502) failed: [Errno -2] Name does not resolve
2022-03-22 09:56:29 ERROR (SyncWorker_0) [pymodbus.client.sync] Connection to (192.168.xxx.yyy, 502) failed: [Errno -2] Name does not resolve
2022-03-22 09:56:29 ERROR (SyncWorker_19) [pymodbus.client.sync] Connection to (192.168.xxx.yyy, 502) failed: [Errno -2] Name does not resolve
2022-03-22 09:56:29 ERROR (SyncWorker_24) [pymodbus.client.sync] Connection to (192.168.xxx.yyy, 502) failed: [Errno -2] Name does not resolve
2022-03-22 09:56:34 ERROR (SyncWorker_18) [pymodbus.client.sync] Connection to (192.168.xxx.yyy, 502) failed: [Errno -2] Name does not resolve
2022-03-22 09:56:39 ERROR (SyncWorker_9) [pymodbus.client.sync] Connection to (192.168.xxx.yyy, 502) failed: [Errno -2] Name does not resolve
2022-03-22 09:56:44 ERROR (SyncWorker_4) [pymodbus.client.sync] Connection to (192.168.xxx.yyy, 502) failed: [Errno -2] Name does not resolve
2022-03-22 09:56:44 ERROR (SyncWorker_6) [pymodbus.client.sync] Connection to (192.168.xxx.yyy, 502) failed: [Errno -2] Name does not resolve
2022-03-22 09:56:44 ERROR (SyncWorker_25) [pymodbus.client.sync] Connection to (192.168.xxx.yyy, 502) failed: [Errno -2] Name does not resolve
2022-03-22 09:56:44 ERROR (SyncWorker_16) [pymodbus.client.sync] Connection to (192.168.xxx.yyy, 502) failed: [Errno -2] Name does not resolve
2022-03-22 09:56:44 ERROR (SyncWorker_13) [pymodbus.client.sync] Connection to (192.168.xxx.yyy, 502) failed: [Errno -2] Name does not resolve
2022-03-22 09:56:44 ERROR (SyncWorker_19) [pymodbus.client.sync] Connection to (192.168.xxx.yyy, 502) failed: [Errno -2] Name does not resolve
2022-03-22 09:56:44 ERROR (SyncWorker_17) [pymodbus.client.sync] Connection to (192.168.xxx.yyy, 502) failed: [Errno -2] Name does not resolve
2022-03-22 09:56:44 ERROR (SyncWorker_11) [pymodbus.client.sync] Connection to (192.168.xxx.yyy, 502) failed: [Errno -2] Name does not resolve
2022-03-22 09:56:49 ERROR (SyncWorker_12) [pymodbus.client.sync] Connection to (192.168.xxx.yyy, 502) failed: [Errno -2] Name does not resolve
2022-03-22 09:56:54 ERROR (SyncWorker_17) [pymodbus.client.sync] Connection to (192.168.xxx.yyy, 502) failed: [Errno -2] Name does not resolve
2022-03-22 09:56:55 ERROR (MainThread) [homeassistant.util.logging] Exception in async_schedule_update_ha_state when dispatching 'audiconnect.updated': ()
Traceback (most recent call last):
  File "/usr/src/homeassistant/homeassistant/helpers/entity.py", line 712, in async_schedule_update_ha_state
    self.async_write_ha_state()
  File "/usr/src/homeassistant/homeassistant/helpers/entity.py", line 553, in async_write_ha_state
    self._async_write_ha_state()
  File "/usr/src/homeassistant/homeassistant/helpers/entity.py", line 681, in _async_write_ha_state
    self.hass.states.async_set(
  File "/usr/src/homeassistant/homeassistant/core.py", line 1363, in async_set
    state = State(
  File "/usr/src/homeassistant/homeassistant/core.py", line 1049, in __init__
    raise InvalidStateError(
homeassistant.exceptions.InvalidStateError: Invalid state encountered for entity ID: sensor.audi_e_tron_sportback_shortterm_trip_data. State max length is 255 characters.

2022-03-22 09:56:55 ERROR (MainThread) [homeassistant.util.logging] Exception in async_schedule_update_ha_state when dispatching 'audiconnect.updated': ()
Traceback (most recent call last):
  File "/usr/src/homeassistant/homeassistant/helpers/entity.py", line 712, in async_schedule_update_ha_state
    self.async_write_ha_state()
  File "/usr/src/homeassistant/homeassistant/helpers/entity.py", line 553, in async_write_ha_state
    self._async_write_ha_state()
  File "/usr/src/homeassistant/homeassistant/helpers/entity.py", line 681, in _async_write_ha_state
    self.hass.states.async_set(
  File "/usr/src/homeassistant/homeassistant/core.py", line 1363, in async_set
    state = State(
  File "/usr/src/homeassistant/homeassistant/core.py", line 1049, in __init__
    raise InvalidStateError(
homeassistant.exceptions.InvalidStateError: Invalid state encountered for entity ID: sensor.audi_e_tron_sportback_shortterm_trip_user_reset. State max length is 255 characters.

2022-03-22 09:56:55 WARNING (MainThread) [homeassistant.helpers.template] Template warning: 'timestamp_custom' got invalid input 'n/a' when rendering template '{% if states('device_tracker.audi_e_tron_sportback_position') =="home" %} Auto staat thuis.

  {% if (states('input_number.car_smart_charging_target_percentage') | float(default=0)) < (states('sensor.audi_e_tron_sportback_state_of_charge') | float(default=0) ) %} 
  Er hoeft niet te worden geladen: laaddoel {{states('input_number.car_smart_charging_target_percentage') |round()}}% is al bereikt.

  {% else %}
 {% set target = states('input_number.car_smart_charging_target_percentage') | float(default=0) %}
 {% set soc = states('sensor.audi_e_tron_sportback_state_of_charge') | float(default=0) %}
 {% set nog_te_laden_procent = [target - soc, 0] | max %}
 {% set nog_te_laden_minuten = nog_te_laden_procent * 8.5 | round(2) %}

   Van **{{states('sensor.audi_e_tron_sportback_state_of_charge') | round() }}%** naar  **{{states('input_number.car_smart_charging_target_percentage') | round() }}%** =  **{{nog_te_laden_procent | round() }}%** laden = laadtijd **{{ (nog_te_laden_minuten | float(default=0) * 60) | timestamp_custom('%-Hu%M', false)}}**
  {% endif %}

{% else %} Auto staat niet thuis.
Resterende laadtijd: {{states('sensor.audi_e_tron_sportback_remaining_charge_time') | timestamp_custom('%Hu%M')}}
{% endif %}' but no default was specified. Currently 'timestamp_custom' will return 'n/a', however this template will fail to render in Home Assistant core 2022.1
2022-03-22 09:56:59 ERROR (SyncWorker_10) [pymodbus.client.sync] Connection to (192.168.xxx.yyy, 502) failed: [Errno -2] Name does not resolve
2022-03-22 09:56:59 ERROR (SyncWorker_12) [pymodbus.client.sync] Connection to (192.168.xxx.yyy, 502) failed: [Errno -2] Name does not resolve
2022-03-22 09:56:59 ERROR (SyncWorker_3) [pymodbus.client.sync] Connection to (192.168.xxx.yyy, 502) failed: [Errno -2] Name does not resolve
2022-03-22 09:56:59 ERROR (SyncWorker_8) [pymodbus.client.sync] Connection to (192.168.xxx.yyy, 502) failed: [Errno -2] Name does not resolve
2022-03-22 09:56:59 ERROR (SyncWorker_2) [pymodbus.client.sync] Connection to (192.168.xxx.yyy, 502) failed: [Errno -2] Name does not resolve
2022-03-22 09:56:59 ERROR (SyncWorker_4) [pymodbus.client.sync] Connection to (192.168.xxx.yyy, 502) failed: [Errno -2] Name does not resolve
2022-03-22 09:56:59 ERROR (SyncWorker_6) [pymodbus.client.sync] Connection to (192.168.xxx.yyy, 502) failed: [Errno -2] Name does not resolve
2022-03-22 09:56:59 ERROR (SyncWorker_6) [pymodbus.client.sync] Connection to (192.168.xxx.yyy, 502) failed: [Errno -2] Name does not resolve
2022-03-22 09:57:04 ERROR (SyncWorker_18) [pymodbus.client.sync] Connection to (192.168.xxx.yyy, 502) failed: [Errno -2] Name does not resolve
2022-03-22 09:57:09 ERROR (SyncWorker_2) [pymodbus.client.sync] Connection to (192.168.xxx.yyy, 502) failed: [Errno -2] Name does not resolve
2022-03-22 09:57:14 ERROR (SyncWorker_11) [pymodbus.client.sync] Connection to (192.168.xxx.yyy, 502) failed: [Errno -2] Name does not resolve
2022-03-22 09:57:14 ERROR (SyncWorker_19) [pymodbus.client.sync] Connection to (192.168.xxx.yyy, 502) failed: [Errno -2] Name does not resolve
2022-03-22 09:57:14 ERROR (SyncWorker_0) [pymodbus.client.sync] Connection to (192.168.xxx.yyy, 502) failed: [Errno -2] Name does not resolve
2022-03-22 09:57:14 ERROR (SyncWorker_15) [pymodbus.client.sync] Connection to (192.168.xxx.yyy, 502) failed: [Errno -2] Name does not resolve
2022-03-22 09:57:14 ERROR (SyncWorker_20) [pymodbus.client.sync] Connection to (192.168.xxx.yyy, 502) failed: [Errno -2] Name does not resolve
2022-03-22 09:57:14 ERROR (SyncWorker_6) [pymodbus.client.sync] Connection to (192.168.xxx.yyy, 502) failed: [Errno -2] Name does not resolve
2022-03-22 09:57:14 ERROR (SyncWorker_25) [pymodbus.client.sync] Connection to (192.168.xxx.yyy, 502) failed: [Errno -2] Name does not resolve
2022-03-22 09:57:14 ERROR (SyncWorker_12) [pymodbus.client.sync] Connection to (192.168.xxx.yyy, 502) failed: [Errno -2] Name does not resolve
2022-03-22 09:57:19 ERROR (SyncWorker_3) [pymodbus.client.sync] Connection to (192.168.xxx.yyy, 502) failed: [Errno -2] Name does not resolve
2022-03-22 09:57:24 ERROR (SyncWorker_11) [pymodbus.client.sync] Connection to (192.168.xxx.yyy, 502) failed: [Errno -2] Name does not resolve
2022-03-22 09:57:29 ERROR (SyncWorker_6) [pymodbus.client.sync] Connection to (192.168.xxx.yyy, 502) failed: [Errno -2] Name does not resolve
2022-03-22 09:57:29 ERROR (SyncWorker_25) [pymodbus.client.sync] Connection to (192.168.xxx.yyy, 502) failed: [Errno -2] Name does not resolve
2022-03-22 09:57:29 ERROR (SyncWorker_25) [pymodbus.client.sync] Connection to (192.168.xxx.yyy, 502) failed: [Errno -2] Name does not resolve
2022-03-22 09:57:29 ERROR (SyncWorker_9) [pymodbus.client.sync] Connection to (192.168.xxx.yyy, 502) failed: [Errno -2] Name does not resolve
2022-03-22 09:57:29 ERROR (SyncWorker_14) [pymodbus.client.sync] Connection to (192.168.xxx.yyy, 502) failed: [Errno -2] Name does not resolve
2022-03-22 09:57:29 ERROR (SyncWorker_3) [pymodbus.client.sync] Connection to (192.168.xxx.yyy, 502) failed: [Errno -2] Name does not resolve
2022-03-22 09:57:29 ERROR (SyncWorker_4) [pymodbus.client.sync] Connection to (192.168.xxx.yyy, 502) failed: [Errno -2] Name does not resolve
2022-03-22 09:57:29 ERROR (SyncWorker_2) [pymodbus.client.sync] Connection to (192.168.xxx.yyy, 502) failed: [Errno -2] Name does not resolve
2022-03-22 09:57:34 ERROR (SyncWorker_0) [pymodbus.client.sync] Connection to (192.168.xxx.yyy, 502) failed: [Errno -2] Name does not resolve
2022-03-22 09:57:39 ERROR (SyncWorker_13) [pymodbus.client.sync] Connection to (192.168.xxx.yyy, 502) failed: [Errno -2] Name does not resolve
2022-03-22 09:57:44 ERROR (SyncWorker_3) [pymodbus.client.sync] Connection to (192.168.xxx.yyy, 502) failed: [Errno -2] Name does not resolve
2022-03-22 09:57:44 ERROR (SyncWorker_18) [pymodbus.client.sync] Connection to (192.168.xxx.yyy, 502) failed: [Errno -2] Name does not resolve
2022-03-22 09:57:44 ERROR (SyncWorker_18) [pymodbus.client.sync] Connection to (192.168.xxx.yyy, 502) failed: [Errno -2] Name does not resolve
2022-03-22 09:57:44 ERROR (SyncWorker_2) [pymodbus.client.sync] Connection to (192.168.xxx.yyy, 502) failed: [Errno -2] Name does not resolve
2022-03-22 09:57:44 ERROR (SyncWorker_14) [pymodbus.client.sync] Connection to (192.168.xxx.yyy, 502) failed: [Errno -2] Name does not resolve
2022-03-22 09:57:44 ERROR (SyncWorker_17) [pymodbus.client.sync] Connection to (192.168.xxx.yyy, 502) failed: [Errno -2] Name does not resolve
2022-03-22 09:57:44 ERROR (SyncWorker_27) [pymodbus.client.sync] Connection to (192.168.xxx.yyy, 502) failed: [Errno -2] Name does not resolve
2022-03-22 09:57:44 ERROR (SyncWorker_11) [pymodbus.client.sync] Connection to (192.168.xxx.yyy, 502) failed: [Errno -2] Name does not resolve
2022-03-22 09:57:49 ERROR (SyncWorker_26) [pymodbus.client.sync] Connection to (192.168.xxx.yyy, 502) failed: [Errno -2] Name does not resolve
2022-03-22 09:57:54 ERROR (SyncWorker_13) [pymodbus.client.sync] Connection to (192.168.xxx.yyy, 502) failed: [Errno -2] Name does not resolve
2022-03-22 09:57:59 ERROR (SyncWorker_0) [pymodbus.client.sync] Connection to (192.168.xxx.yyy, 502) failed: [Errno -2] Name does not resolve
2022-03-22 09:57:59 ERROR (SyncWorker_4) [pymodbus.client.sync] Connection to (192.168.xxx.yyy, 502) failed: [Errno -2] Name does not resolve
2022-03-22 09:57:59 ERROR (SyncWorker_5) [pymodbus.client.sync] Connection to (192.168.xxx.yyy, 502) failed: [Errno -2] Name does not resolve
2022-03-22 09:57:59 ERROR (SyncWorker_18) [pymodbus.client.sync] Connection to (192.168.xxx.yyy, 502) failed: [Errno -2] Name does not resolve
2022-03-22 09:57:59 ERROR (SyncWorker_2) [pymodbus.client.sync] Connection to (192.168.xxx.yyy, 502) failed: [Errno -2] Name does not resolve
2022-03-22 09:57:59 ERROR (SyncWorker_14) [pymodbus.client.sync] Connection to (192.168.xxx.yyy, 502) failed: [Errno -2] Name does not resolve
2022-03-22 09:57:59 ERROR (SyncWorker_17) [pymodbus.client.sync] Connection to (192.168.xxx.yyy, 502) failed: [Errno -2] Name does not resolve
2022-03-22 09:57:59 ERROR (SyncWorker_27) [pymodbus.client.sync] Connection to (192.168.xxx.yyy, 502) failed: [Errno -2] Name does not resolve
2022-03-22 09:58:04 ERROR (SyncWorker_19) [pymodbus.client.sync] Connection to (192.168.xxx.yyy, 502) failed: [Errno -2] Name does not resolve
2022-03-22 09:58:09 ERROR (SyncWorker_7) [pymodbus.client.sync] Connection to (192.168.xxx.yyy, 502) failed: [Errno -2] Name does not resolve
2022-03-22 09:58:14 ERROR (SyncWorker_26) [pymodbus.client.sync] Connection to (192.168.xxx.yyy, 502) failed: [Errno -2] Name does not resolve
2022-03-22 09:58:14 ERROR (SyncWorker_18) [pymodbus.client.sync] Connection to (192.168.xxx.yyy, 502) failed: [Errno -2] Name does not resolve
2022-03-22 09:58:14 ERROR (SyncWorker_23) [pymodbus.client.sync] Connection to (192.168.xxx.yyy, 502) failed: [Errno -2] Name does not resolve
2022-03-22 09:58:14 ERROR (SyncWorker_10) [pymodbus.client.sync] Connection to (192.168.xxx.yyy, 502) failed: [Errno -2] Name does not resolve
2022-03-22 09:58:14 ERROR (SyncWorker_9) [pymodbus.client.sync] Connection to (192.168.xxx.yyy, 502) failed: [Errno -2] Name does not resolve
2022-03-22 09:58:14 ERROR (SyncWorker_17) [pymodbus.client.sync] Connection to (192.168.xxx.yyy, 502) failed: [Errno -2] Name does not resolve
2022-03-22 09:58:14 ERROR (SyncWorker_8) [pymodbus.client.sync] Connection to (192.168.xxx.yyy, 502) failed: [Errno -2] Name does not resolve
2022-03-22 09:58:14 ERROR (SyncWorker_5) [pymodbus.client.sync] Connection to (192.168.xxx.yyy, 502) failed: [Errno -2] Name does not resolve
2022-03-22 09:58:19 ERROR (SyncWorker_6) [pymodbus.client.sync] Connection to (192.168.xxx.yyy, 502) failed: [Errno -2] Name does not resolve
2022-03-22 09:58:24 ERROR (SyncWorker_18) [pymodbus.client.sync] Connection to (192.168.xxx.yyy, 502) failed: [Errno -2] Name does not resolve
2022-03-22 09:58:29 ERROR (SyncWorker_10) [pymodbus.client.sync] Connection to (192.168.xxx.yyy, 502) failed: [Errno -2] Name does not resolve
2022-03-22 09:58:29 ERROR (SyncWorker_9) [pymodbus.client.sync] Connection to (192.168.xxx.yyy, 502) failed: [Errno -2] Name does not resolve
2022-03-22 09:58:29 ERROR (SyncWorker_17) [pymodbus.client.sync] Connection to (192.168.xxx.yyy, 502) failed: [Errno -2] Name does not resolve
2022-03-22 09:58:29 ERROR (SyncWorker_8) [pymodbus.client.sync] Connection to (192.168.xxx.yyy, 502) failed: [Errno -2] Name does not resolve
2022-03-22 09:58:29 ERROR (SyncWorker_5) [pymodbus.client.sync] Connection to (192.168.xxx.yyy, 502) failed: [Errno -2] Name does not resolve
2022-03-22 09:58:29 ERROR (SyncWorker_14) [pymodbus.client.sync] Connection to (192.168.xxx.yyy, 502) failed: [Errno -2] Name does not resolve
2022-03-22 09:58:29 ERROR (SyncWorker_14) [pymodbus.client.sync] Connection to (192.168.xxx.yyy, 502) failed: [Errno -2] Name does not resolve
2022-03-22 09:58:29 ERROR (SyncWorker_20) [pymodbus.client.sync] Connection to (192.168.xxx.yyy, 502) failed: [Errno -2] Name does not resolve
2022-03-22 09:58:34 ERROR (SyncWorker_25) [pymodbus.client.sync] Connection to (192.168.xxx.yyy, 502) failed: [Errno -2] Name does not resolve
2022-03-22 09:58:39 ERROR (SyncWorker_22) [pymodbus.client.sync] Connection to (192.168.xxx.yyy, 502) failed: [Errno -2] Name does not resolve
2022-03-22 09:58:44 ERROR (SyncWorker_21) [pymodbus.client.sync] Connection to (192.168.xxx.yyy, 502) failed: [Errno -2] Name does not resolve
2022-03-22 09:58:44 ERROR (SyncWorker_14) [pymodbus.client.sync] Connection to (192.168.xxx.yyy, 502) failed: [Errno -2] Name does not resolve
2022-03-22 09:58:44 ERROR (SyncWorker_11) [pymodbus.client.sync] Connection to (192.168.xxx.yyy, 502) failed: [Errno -2] Name does not resolve
2022-03-22 09:58:44 ERROR (SyncWorker_19) [pymodbus.client.sync] Connection to (192.168.xxx.yyy, 502) failed: [Errno -2] Name does not resolve
2022-03-22 09:58:44 ERROR (SyncWorker_5) [pymodbus.client.sync] Connection to (192.168.xxx.yyy, 502) failed: [Errno -2] Name does not resolve
2022-03-22 09:58:44 ERROR (SyncWorker_13) [pymodbus.client.sync] Connection to (192.168.xxx.yyy, 502) failed: [Errno -2] Name does not resolve
2022-03-22 09:58:44 ERROR (SyncWorker_24) [pymodbus.client.sync] Connection to (192.168.xxx.yyy, 502) failed: [Errno -2] Name does not resolve
2022-03-22 09:58:44 ERROR (SyncWorker_2) [pymodbus.client.sync] Connection to (192.168.xxx.yyy, 502) failed: [Errno -2] Name does not resolve
2022-03-22 09:58:49 ERROR (SyncWorker_1) [pymodbus.client.sync] Connection to (192.168.xxx.yyy, 502) failed: [Errno -2] Name does not resolve
2022-03-22 09:58:54 ERROR (SyncWorker_21) [pymodbus.client.sync] Connection to (192.168.xxx.yyy, 502) failed: [Errno -2] Name does not resolve
2022-03-22 09:58:58 ERROR (MainThread) [homeassistant.util.logging] Exception in async_schedule_update_ha_state when dispatching 'audiconnect.updated': ()
Traceback (most recent call last):
  File "/usr/src/homeassistant/homeassistant/helpers/entity.py", line 712, in async_schedule_update_ha_state
    self.async_write_ha_state()
  File "/usr/src/homeassistant/homeassistant/helpers/entity.py", line 553, in async_write_ha_state
    self._async_write_ha_state()
  File "/usr/src/homeassistant/homeassistant/helpers/entity.py", line 681, in _async_write_ha_state
    self.hass.states.async_set(
  File "/usr/src/homeassistant/homeassistant/core.py", line 1363, in async_set
    state = State(
  File "/usr/src/homeassistant/homeassistant/core.py", line 1049, in __init__
    raise InvalidStateError(
homeassistant.exceptions.InvalidStateError: Invalid state encountered for entity ID: sensor.audi_e_tron_sportback_shortterm_trip_data. State max length is 255 characters.

2022-03-22 09:58:58 ERROR (MainThread) [homeassistant.util.logging] Exception in async_schedule_update_ha_state when dispatching 'audiconnect.updated': ()
Traceback (most recent call last):
  File "/usr/src/homeassistant/homeassistant/helpers/entity.py", line 712, in async_schedule_update_ha_state
    self.async_write_ha_state()
  File "/usr/src/homeassistant/homeassistant/helpers/entity.py", line 553, in async_write_ha_state
    self._async_write_ha_state()
  File "/usr/src/homeassistant/homeassistant/helpers/entity.py", line 681, in _async_write_ha_state
    self.hass.states.async_set(
  File "/usr/src/homeassistant/homeassistant/core.py", line 1363, in async_set
    state = State(
  File "/usr/src/homeassistant/homeassistant/core.py", line 1049, in __init__
    raise InvalidStateError(
homeassistant.exceptions.InvalidStateError: Invalid state encountered for entity ID: sensor.audi_e_tron_sportback_shortterm_trip_user_reset. State max length is 255 characters.

2022-03-22 09:58:58 WARNING (MainThread) [homeassistant.helpers.template] Template warning: 'timestamp_custom' got invalid input 'n/a' when rendering template '{% if states('device_tracker.audi_e_tron_sportback_position') =="home" %} Auto staat thuis.

  {% if (states('input_number.car_smart_charging_target_percentage') | float(default=0)) < (states('sensor.audi_e_tron_sportback_state_of_charge') | float(default=0) ) %} 
  Er hoeft niet te worden geladen: laaddoel {{states('input_number.car_smart_charging_target_percentage') |round()}}% is al bereikt.

  {% else %}
 {% set target = states('input_number.car_smart_charging_target_percentage') | float(default=0) %}
 {% set soc = states('sensor.audi_e_tron_sportback_state_of_charge') | float(default=0) %}
 {% set nog_te_laden_procent = [target - soc, 0] | max %}
 {% set nog_te_laden_minuten = nog_te_laden_procent * 8.5 | round(2) %}

   Van **{{states('sensor.audi_e_tron_sportback_state_of_charge') | round() }}%** naar  **{{states('input_number.car_smart_charging_target_percentage') | round() }}%** =  **{{nog_te_laden_procent | round() }}%** laden = laadtijd **{{ (nog_te_laden_minuten | float(default=0) * 60) | timestamp_custom('%-Hu%M', false)}}**
  {% endif %}

{% else %} Auto staat niet thuis.
Resterende laadtijd: {{states('sensor.audi_e_tron_sportback_remaining_charge_time') | timestamp_custom('%Hu%M')}}
{% endif %}' but no default was specified. Currently 'timestamp_custom' will return 'n/a', however this template will fail to render in Home Assistant core 2022.1
2022-03-22 09:58:59 ERROR (SyncWorker_22) [pymodbus.client.sync] Connection to (192.168.xxx.yyy, 502) failed: [Errno -2] Name does not resolve
2022-03-22 09:58:59 ERROR (SyncWorker_1) [pymodbus.client.sync] Connection to (192.168.xxx.yyy, 502) failed: [Errno -2] Name does not resolve
2022-03-22 09:58:59 ERROR (SyncWorker_0) [pymodbus.client.sync] Connection to (192.168.xxx.yyy, 502) failed: [Errno -2] Name does not resolve
2022-03-22 09:58:59 ERROR (SyncWorker_3) [pymodbus.client.sync] Connection to (192.168.xxx.yyy, 502) failed: [Errno -2] Name does not resolve
2022-03-22 09:58:59 ERROR (SyncWorker_3) [pymodbus.client.sync] Connection to (192.168.xxx.yyy, 502) failed: [Errno -2] Name does not resolve
2022-03-22 09:58:59 ERROR (SyncWorker_6) [pymodbus.client.sync] Connection to (192.168.xxx.yyy, 502) failed: [Errno -2] Name does not resolve
2022-03-22 09:58:59 ERROR (SyncWorker_15) [pymodbus.client.sync] Connection to (192.168.xxx.yyy, 502) failed: [Errno -2] Name does not resolve
2022-03-22 09:58:59 ERROR (SyncWorker_10) [pymodbus.client.sync] Connection to (192.168.xxx.yyy, 502) failed: [Errno -2] Name does not resolve
2022-03-22 09:59:04 ERROR (SyncWorker_2) [pymodbus.client.sync] Connection to (192.168.xxx.yyy, 502) failed: [Errno -2] Name does not resolve
2022-03-22 09:59:09 ERROR (SyncWorker_26) [pymodbus.client.sync] Connection to (192.168.xxx.yyy, 502) failed: [Errno -2] Name does not resolve
2022-03-22 09:59:14 ERROR (SyncWorker_0) [pymodbus.client.sync] Connection to (192.168.xxx.yyy, 502) failed: [Errno -2] Name does not resolve
2022-03-22 09:59:14 ERROR (SyncWorker_14) [pymodbus.client.sync] Connection to (192.168.xxx.yyy, 502) failed: [Errno -2] Name does not resolve
2022-03-22 09:59:14 ERROR (SyncWorker_7) [pymodbus.client.sync] Connection to (192.168.xxx.yyy, 502) failed: [Errno -2] Name does not resolve
2022-03-22 09:59:14 ERROR (SyncWorker_27) [pymodbus.client.sync] Connection to (192.168.xxx.yyy, 502) failed: [Errno -2] Name does not resolve
2022-03-22 09:59:14 ERROR (SyncWorker_1) [pymodbus.client.sync] Connection to (192.168.xxx.yyy, 502) failed: [Errno -2] Name does not resolve
2022-03-22 09:59:14 ERROR (SyncWorker_5) [pymodbus.client.sync] Connection to (192.168.xxx.yyy, 502) failed: [Errno -2] Name does not resolve
2022-03-22 09:59:14 ERROR (SyncWorker_6) [pymodbus.client.sync] Connection to (192.168.xxx.yyy, 502) failed: [Errno -2] Name does not resolve
2022-03-22 09:59:14 ERROR (SyncWorker_6) [pymodbus.client.sync] Connection to (192.168.xxx.yyy, 502) failed: [Errno -2] Name does not resolve
2022-03-22 09:59:19 ERROR (SyncWorker_11) [pymodbus.client.sync] Connection to (192.168.xxx.yyy, 502) failed: [Errno -2] Name does not resolve
2022-03-22 09:59:24 ERROR (SyncWorker_17) [pymodbus.client.sync] Connection to (192.168.xxx.yyy, 502) failed: [Errno -2] Name does not resolve
2022-03-22 09:59:29 ERROR (SyncWorker_14) [pymodbus.client.sync] Connection to (192.168.xxx.yyy, 502) failed: [Errno -2] Name does not resolve
2022-03-22 09:59:29 ERROR (SyncWorker_13) [pymodbus.client.sync] Connection to (192.168.xxx.yyy, 502) failed: [Errno -2] Name does not resolve
2022-03-22 09:59:29 ERROR (SyncWorker_13) [pymodbus.client.sync] Connection to (192.168.xxx.yyy, 502) failed: [Errno -2] Name does not resolve
2022-03-22 09:59:29 ERROR (SyncWorker_27) [pymodbus.client.sync] Connection to (192.168.xxx.yyy, 502) failed: [Errno -2] Name does not resolve
2022-03-22 09:59:29 ERROR (SyncWorker_1) [pymodbus.client.sync] Connection to (192.168.xxx.yyy, 502) failed: [Errno -2] Name does not resolve
2022-03-22 09:59:29 ERROR (SyncWorker_5) [pymodbus.client.sync] Connection to (192.168.xxx.yyy, 502) failed: [Errno -2] Name does not resolve
2022-03-22 09:59:29 ERROR (SyncWorker_4) [pymodbus.client.sync] Connection to (192.168.xxx.yyy, 502) failed: [Errno -2] Name does not resolve
2022-03-22 09:59:29 ERROR (SyncWorker_18) [pymodbus.client.sync] Connection to (192.168.xxx.yyy, 502) failed: [Errno -2] Name does not resolve
2022-03-22 09:59:34 ERROR (SyncWorker_21) [pymodbus.client.sync] Connection to (192.168.xxx.yyy, 502) failed: [Errno -2] Name does not resolve
2022-03-22 09:59:39 ERROR (SyncWorker_20) [pymodbus.client.sync] Connection to (192.168.xxx.yyy, 502) failed: [Errno -2] Name does not resolve
2022-03-22 09:59:44 ERROR (SyncWorker_19) [pymodbus.client.sync] Connection to (192.168.xxx.yyy, 502) failed: [Errno -2] Name does not resolve
2022-03-22 09:59:44 ERROR (SyncWorker_24) [pymodbus.client.sync] Connection to (192.168.xxx.yyy, 502) failed: [Errno -2] Name does not resolve
2022-03-22 09:59:44 ERROR (SyncWorker_23) [pymodbus.client.sync] Connection to (192.168.xxx.yyy, 502) failed: [Errno -2] Name does not resolve
2022-03-22 09:59:44 ERROR (SyncWorker_7) [pymodbus.client.sync] Connection to (192.168.xxx.yyy, 502) failed: [Errno -2] Name does not resolve
2022-03-22 09:59:44 ERROR (SyncWorker_14) [pymodbus.client.sync] Connection to (192.168.xxx.yyy, 502) failed: [Errno -2] Name does not resolve
2022-03-22 09:59:44 ERROR (SyncWorker_16) [pymodbus.client.sync] Connection to (192.168.xxx.yyy, 502) failed: [Errno -2] Name does not resolve
2022-03-22 09:59:44 ERROR (SyncWorker_25) [pymodbus.client.sync] Connection to (192.168.xxx.yyy, 502) failed: [Errno -2] Name does not resolve
2022-03-22 09:59:44 ERROR (SyncWorker_10) [pymodbus.client.sync] Connection to (192.168.xxx.yyy, 502) failed: [Errno -2] Name does not resolve
2022-03-22 09:59:49 ERROR (SyncWorker_27) [pymodbus.client.sync] Connection to (192.168.xxx.yyy, 502) failed: [Errno -2] Name does not resolve
2022-03-22 09:59:54 ERROR (SyncWorker_9) [pymodbus.client.sync] Connection to (192.168.xxx.yyy, 502) failed: [Errno -2] Name does not resolve
2022-03-22 09:59:59 ERROR (SyncWorker_19) [pymodbus.client.sync] Connection to (192.168.xxx.yyy, 502) failed: [Errno -2] Name does not resolve
2022-03-22 09:59:59 ERROR (SyncWorker_19) [pymodbus.client.sync] Connection to (192.168.xxx.yyy, 502) failed: [Errno -2] Name does not resolve
2022-03-22 09:59:59 ERROR (SyncWorker_0) [pymodbus.client.sync] Connection to (192.168.xxx.yyy, 502) failed: [Errno -2] Name does not resolve
2022-03-22 09:59:59 ERROR (SyncWorker_1) [pymodbus.client.sync] Connection to (192.168.xxx.yyy, 502) failed: [Errno -2] Name does not resolve
2022-03-22 09:59:59 ERROR (SyncWorker_17) [pymodbus.client.sync] Connection to (192.168.xxx.yyy, 502) failed: [Errno -2] Name does not resolve
2022-03-22 09:59:59 ERROR (SyncWorker_26) [pymodbus.client.sync] Connection to (192.168.xxx.yyy, 502) failed: [Errno -2] Name does not resolve
2022-03-22 09:59:59 ERROR (SyncWorker_22) [pymodbus.client.sync] Connection to (192.168.xxx.yyy, 502) failed: [Errno -2] Name does not resolve
2022-03-22 09:59:59 ERROR (SyncWorker_11) [pymodbus.client.sync] Connection to (192.168.xxx.yyy, 502) failed: [Errno -2] Name does not resolve
2022-03-22 10:00:00 WARNING (MainThread) [homeassistant.components.xiaomi_miio.fan] 'auto'is not a valid preset mode
2022-03-22 10:00:04 ERROR (SyncWorker_19) [pymodbus.client.sync] Connection to (192.168.xxx.yyy, 502) failed: [Errno -2] Name does not resolve
2022-03-22 10:00:09 ERROR (SyncWorker_21) [pymodbus.client.sync] Connection to (192.168.xxx.yyy, 502) failed: [Errno -2] Name does not resolve
2022-03-22 10:00:14 ERROR (SyncWorker_3) [pymodbus.client.sync] Connection to (192.168.xxx.yyy, 502) failed: [Errno -2] Name does not resolve
2022-03-22 10:00:14 ERROR (SyncWorker_14) [pymodbus.client.sync] Connection to (192.168.xxx.yyy, 502) failed: [Errno -2] Name does not resolve
2022-03-22 10:00:14 ERROR (SyncWorker_27) [pymodbus.client.sync] Connection to (192.168.xxx.yyy, 502) failed: [Errno -2] Name does not resolve
2022-03-22 10:00:14 ERROR (SyncWorker_19) [pymodbus.client.sync] Connection to (192.168.xxx.yyy, 502) failed: [Errno -2] Name does not resolve
2022-03-22 10:00:14 ERROR (SyncWorker_15) [pymodbus.client.sync] Connection to (192.168.xxx.yyy, 502) failed: [Errno -2] Name does not resolve
2022-03-22 10:00:14 ERROR (SyncWorker_2) [pymodbus.client.sync] Connection to (192.168.xxx.yyy, 502) failed: [Errno -2] Name does not resolve
2022-03-22 10:00:14 ERROR (SyncWorker_10) [pymodbus.client.sync] Connection to (192.168.xxx.yyy, 502) failed: [Errno -2] Name does not resolve
2022-03-22 10:00:14 ERROR (SyncWorker_24) [pymodbus.client.sync] Connection to (192.168.xxx.yyy, 502) failed: [Errno -2] Name does not resolve
2022-03-22 10:00:19 ERROR (SyncWorker_6) [pymodbus.client.sync] Connection to (192.168.xxx.yyy, 502) failed: [Errno -2] Name does not resolve
2022-03-22 10:00:24 ERROR (SyncWorker_5) [pymodbus.client.sync] Connection to (192.168.xxx.yyy, 502) failed: [Errno -2] Name does not resolve
2022-03-22 10:00:29 ERROR (SyncWorker_3) [pymodbus.client.sync] Connection to (192.168.xxx.yyy, 502) failed: [Errno -2] Name does not resolve
2022-03-22 10:00:29 ERROR (SyncWorker_14) [pymodbus.client.sync] Connection to (192.168.xxx.yyy, 502) failed: [Errno -2] Name does not resolve
2022-03-22 10:00:29 ERROR (SyncWorker_27) [pymodbus.client.sync] Connection to (192.168.xxx.yyy, 502) failed: [Errno -2] Name does not resolve
2022-03-22 10:00:29 ERROR (SyncWorker_19) [pymodbus.client.sync] Connection to (192.168.xxx.yyy, 502) failed: [Errno -2] Name does not resolve
2022-03-22 10:00:29 ERROR (SyncWorker_15) [pymodbus.client.sync] Connection to (192.168.xxx.yyy, 502) failed: [Errno -2] Name does not resolve
2022-03-22 10:00:29 ERROR (SyncWorker_2) [pymodbus.client.sync] Connection to (192.168.xxx.yyy, 502) failed: [Errno -2] Name does not resolve
2022-03-22 10:00:29 ERROR (SyncWorker_10) [pymodbus.client.sync] Connection to (192.168.xxx.yyy, 502) failed: [Errno -2] Name does not resolve
2022-03-22 10:00:29 ERROR (SyncWorker_24) [pymodbus.client.sync] Connection to (192.168.xxx.yyy, 502) failed: [Errno -2] Name does not resolve
2022-03-22 10:00:34 ERROR (SyncWorker_21) [pymodbus.client.sync] Connection to (192.168.xxx.yyy, 502) failed: [Errno -2] Name does not resolve
2022-03-22 10:00:39 ERROR (SyncWorker_22) [pymodbus.client.sync] Connection to (192.168.xxx.yyy, 502) failed: [Errno -2] Name does not resolve
2022-03-22 10:00:44 ERROR (SyncWorker_5) [pymodbus.client.sync] Connection to (192.168.xxx.yyy, 502) failed: [Errno -2] Name does not resolve
2022-03-22 10:00:44 ERROR (SyncWorker_3) [pymodbus.client.sync] Connection to (192.168.xxx.yyy, 502) failed: [Errno -2] Name does not resolve
2022-03-22 10:00:44 ERROR (SyncWorker_16) [pymodbus.client.sync] Connection to (192.168.xxx.yyy, 502) failed: [Errno -2] Name does not resolve
2022-03-22 10:00:44 ERROR (SyncWorker_4) [pymodbus.client.sync] Connection to (192.168.xxx.yyy, 502) failed: [Errno -2] Name does not resolve
2022-03-22 10:00:44 ERROR (SyncWorker_17) [pymodbus.client.sync] Connection to (192.168.xxx.yyy, 502) failed: [Errno -2] Name does not resolve
2022-03-22 10:00:44 ERROR (SyncWorker_12) [pymodbus.client.sync] Connection to (192.168.xxx.yyy, 502) failed: [Errno -2] Name does not resolve
2022-03-22 10:00:44 ERROR (SyncWorker_24) [pymodbus.client.sync] Connection to (192.168.xxx.yyy, 502) failed: [Errno -2] Name does not resolve
2022-03-22 10:00:44 ERROR (SyncWorker_20) [pymodbus.client.sync] Connection to (192.168.xxx.yyy, 502) failed: [Errno -2] Name does not resolve
2022-03-22 10:00:49 ERROR (SyncWorker_19) [pymodbus.client.sync] Connection to (192.168.xxx.yyy, 502) failed: [Errno -2] Name does not resolve
2022-03-22 10:00:54 ERROR (SyncWorker_5) [pymodbus.client.sync] Connection to (192.168.xxx.yyy, 502) failed: [Errno -2] Name does not resolve
2022-03-22 10:00:59 ERROR (SyncWorker_17) [pymodbus.client.sync] Connection to (192.168.xxx.yyy, 502) failed: [Errno -2] Name does not resolve
2022-03-22 10:00:59 ERROR (SyncWorker_12) [pymodbus.client.sync] Connection to (192.168.xxx.yyy, 502) failed: [Errno -2] Name does not resolve
2022-03-22 10:00:59 ERROR (SyncWorker_24) [pymodbus.client.sync] Connection to (192.168.xxx.yyy, 502) failed: [Errno -2] Name does not resolve
2022-03-22 10:00:59 ERROR (SyncWorker_20) [pymodbus.client.sync] Connection to (192.168.xxx.yyy, 502) failed: [Errno -2] Name does not resolve
2022-03-22 10:00:59 ERROR (SyncWorker_27) [pymodbus.client.sync] Connection to (192.168.xxx.yyy, 502) failed: [Errno -2] Name does not resolve
2022-03-22 10:00:59 ERROR (SyncWorker_22) [pymodbus.client.sync] Connection to (192.168.xxx.yyy, 502) failed: [Errno -2] Name does not resolve
2022-03-22 10:00:59 ERROR (SyncWorker_11) [pymodbus.client.sync] Connection to (192.168.xxx.yyy, 502) failed: [Errno -2] Name does not resolve
2022-03-22 10:00:59 ERROR (SyncWorker_7) [pymodbus.client.sync] Connection to (192.168.xxx.yyy, 502) failed: [Errno -2] Name does not resolve
2022-03-22 10:01:04 ERROR (SyncWorker_12) [pymodbus.client.sync] Connection to (192.168.xxx.yyy, 502) failed: [Errno -2] Name does not resolve
2022-03-22 10:01:05 ERROR (MainThread) [homeassistant.util.logging] Exception in async_schedule_update_ha_state when dispatching 'audiconnect.updated': ()
Traceback (most recent call last):
  File "/usr/src/homeassistant/homeassistant/helpers/entity.py", line 712, in async_schedule_update_ha_state
    self.async_write_ha_state()
  File "/usr/src/homeassistant/homeassistant/helpers/entity.py", line 553, in async_write_ha_state
    self._async_write_ha_state()
  File "/usr/src/homeassistant/homeassistant/helpers/entity.py", line 681, in _async_write_ha_state
    self.hass.states.async_set(
  File "/usr/src/homeassistant/homeassistant/core.py", line 1363, in async_set
    state = State(
  File "/usr/src/homeassistant/homeassistant/core.py", line 1049, in __init__
    raise InvalidStateError(
homeassistant.exceptions.InvalidStateError: Invalid state encountered for entity ID: sensor.audi_e_tron_sportback_shortterm_trip_data. State max length is 255 characters.

2022-03-22 10:01:05 ERROR (MainThread) [homeassistant.util.logging] Exception in async_schedule_update_ha_state when dispatching 'audiconnect.updated': ()
Traceback (most recent call last):
  File "/usr/src/homeassistant/homeassistant/helpers/entity.py", line 712, in async_schedule_update_ha_state
    self.async_write_ha_state()
  File "/usr/src/homeassistant/homeassistant/helpers/entity.py", line 553, in async_write_ha_state
    self._async_write_ha_state()
  File "/usr/src/homeassistant/homeassistant/helpers/entity.py", line 681, in _async_write_ha_state
    self.hass.states.async_set(
  File "/usr/src/homeassistant/homeassistant/core.py", line 1363, in async_set
    state = State(
  File "/usr/src/homeassistant/homeassistant/core.py", line 1049, in __init__
    raise InvalidStateError(
homeassistant.exceptions.InvalidStateError: Invalid state encountered for entity ID: sensor.audi_e_tron_sportback_shortterm_trip_user_reset. State max length is 255 characters.

2022-03-22 10:01:05 WARNING (MainThread) [homeassistant.helpers.template] Template warning: 'timestamp_custom' got invalid input 'n/a' when rendering template '{% if states('device_tracker.audi_e_tron_sportback_position') =="home" %} Auto staat thuis.

  {% if (states('input_number.car_smart_charging_target_percentage') | float(default=0)) < (states('sensor.audi_e_tron_sportback_state_of_charge') | float(default=0) ) %} 
  Er hoeft niet te worden geladen: laaddoel {{states('input_number.car_smart_charging_target_percentage') |round()}}% is al bereikt.

  {% else %}
 {% set target = states('input_number.car_smart_charging_target_percentage') | float(default=0) %}
 {% set soc = states('sensor.audi_e_tron_sportback_state_of_charge') | float(default=0) %}
 {% set nog_te_laden_procent = [target - soc, 0] | max %}
 {% set nog_te_laden_minuten = nog_te_laden_procent * 8.5 | round(2) %}

   Van **{{states('sensor.audi_e_tron_sportback_state_of_charge') | round() }}%** naar  **{{states('input_number.car_smart_charging_target_percentage') | round() }}%** =  **{{nog_te_laden_procent | round() }}%** laden = laadtijd **{{ (nog_te_laden_minuten | float(default=0) * 60) | timestamp_custom('%-Hu%M', false)}}**
  {% endif %}

{% else %} Auto staat niet thuis.
Resterende laadtijd: {{states('sensor.audi_e_tron_sportback_remaining_charge_time') | timestamp_custom('%Hu%M')}}
{% endif %}' but no default was specified. Currently 'timestamp_custom' will return 'n/a', however this template will fail to render in Home Assistant core 2022.1
2022-03-22 10:01:09 ERROR (SyncWorker_18) [pymodbus.client.sync] Connection to (192.168.xxx.yyy, 502) failed: [Errno -2] Name does not resolve
2022-03-22 10:01:14 ERROR (SyncWorker_14) [pymodbus.client.sync] Connection to (192.168.xxx.yyy, 502) failed: [Errno -2] Name does not resolve
2022-03-22 10:01:14 ERROR (SyncWorker_13) [pymodbus.client.sync] Connection to (192.168.xxx.yyy, 502) failed: [Errno -2] Name does not resolve
2022-03-22 10:01:14 ERROR (SyncWorker_4) [pymodbus.client.sync] Connection to (192.168.xxx.yyy, 502) failed: [Errno -2] Name does not resolve
2022-03-22 10:01:14 ERROR (SyncWorker_23) [pymodbus.client.sync] Connection to (192.168.xxx.yyy, 502) failed: [Errno -2] Name does not resolve
2022-03-22 10:01:14 ERROR (SyncWorker_21) [pymodbus.client.sync] Connection to (192.168.xxx.yyy, 502) failed: [Errno -2] Name does not resolve
2022-03-22 10:01:14 ERROR (SyncWorker_12) [pymodbus.client.sync] Connection to (192.168.xxx.yyy, 502) failed: [Errno -2] Name does not resolve
2022-03-22 10:01:14 ERROR (SyncWorker_24) [pymodbus.client.sync] Connection to (192.168.xxx.yyy, 502) failed: [Errno -2] Name does not resolve
2022-03-22 10:01:14 ERROR (SyncWorker_27) [pymodbus.client.sync] Connection to (192.168.xxx.yyy, 502) failed: [Errno -2] Name does not resolve
2022-03-22 10:01:19 ERROR (SyncWorker_2) [pymodbus.client.sync] Connection to (192.168.xxx.yyy, 502) failed: [Errno -2] Name does not resolve
2022-03-22 10:01:24 ERROR (SyncWorker_15) [pymodbus.client.sync] Connection to (192.168.xxx.yyy, 502) failed: [Errno -2] Name does not resolve
2022-03-22 10:01:29 ERROR (SyncWorker_4) [pymodbus.client.sync] Connection to (192.168.xxx.yyy, 502) failed: [Errno -2] Name does not resolve
2022-03-22 10:01:29 ERROR (SyncWorker_23) [pymodbus.client.sync] Connection to (192.168.xxx.yyy, 502) failed: [Errno -2] Name does not resolve
2022-03-22 10:01:29 ERROR (SyncWorker_21) [pymodbus.client.sync] Connection to (192.168.xxx.yyy, 502) failed: [Errno -2] Name does not resolve
2022-03-22 10:01:29 ERROR (SyncWorker_12) [pymodbus.client.sync] Connection to (192.168.xxx.yyy, 502) failed: [Errno -2] Name does not resolve
2022-03-22 10:01:29 ERROR (SyncWorker_24) [pymodbus.client.sync] Connection to (192.168.xxx.yyy, 502) failed: [Errno -2] Name does not resolve
2022-03-22 10:01:29 ERROR (SyncWorker_24) [pymodbus.client.sync] Connection to (192.168.xxx.yyy, 502) failed: [Errno -2] Name does not resolve
2022-03-22 10:01:29 ERROR (SyncWorker_17) [pymodbus.client.sync] Connection to (192.168.xxx.yyy, 502) failed: [Errno -2] Name does not resolve
2022-03-22 10:01:29 ERROR (SyncWorker_7) [pymodbus.client.sync] Connection to (192.168.xxx.yyy, 502) failed: [Errno -2] Name does not resolve
2022-03-22 10:01:34 ERROR (SyncWorker_16) [pymodbus.client.sync] Connection to (192.168.xxx.yyy, 502) failed: [Errno -2] Name does not resolve
2022-03-22 10:01:39 ERROR (SyncWorker_12) [pymodbus.client.sync] Connection to (192.168.xxx.yyy, 502) failed: [Errno -2] Name does not resolve
2022-03-22 10:01:44 ERROR (SyncWorker_13) [pymodbus.client.sync] Connection to (192.168.xxx.yyy, 502) failed: [Errno -2] Name does not resolve
2022-03-22 10:01:44 ERROR (SyncWorker_8) [pymodbus.client.sync] Connection to (192.168.xxx.yyy, 502) failed: [Errno -2] Name does not resolve
2022-03-22 10:01:44 ERROR (SyncWorker_2) [pymodbus.client.sync] Connection to (192.168.xxx.yyy, 502) failed: [Errno -2] Name does not resolve
2022-03-22 10:01:44 ERROR (SyncWorker_17) [pymodbus.client.sync] Connection to (192.168.xxx.yyy, 502) failed: [Errno -2] Name does not resolve
2022-03-22 10:01:44 ERROR (SyncWorker_11) [pymodbus.client.sync] Connection to (192.168.xxx.yyy, 502) failed: [Errno -2] Name does not resolve
2022-03-22 10:01:44 ERROR (SyncWorker_25) [pymodbus.client.sync] Connection to (192.168.xxx.yyy, 502) failed: [Errno -2] Name does not resolve
2022-03-22 10:01:44 ERROR (SyncWorker_9) [pymodbus.client.sync] Connection to (192.168.xxx.yyy, 502) failed: [Errno -2] Name does not resolve
2022-03-22 10:01:44 ERROR (SyncWorker_20) [pymodbus.client.sync] Connection to (192.168.xxx.yyy, 502) failed: [Errno -2] Name does not resolve
2022-03-22 10:01:49 ERROR (SyncWorker_26) [pymodbus.client.sync] Connection to (192.168.xxx.yyy, 502) failed: [Errno -2] Name does not resolve
2022-03-22 10:01:54 ERROR (SyncWorker_16) [pymodbus.client.sync] Connection to (192.168.xxx.yyy, 502) failed: [Errno -2] Name does not resolve
2022-03-22 10:01:59 ERROR (SyncWorker_21) [pymodbus.client.sync] Connection to (192.168.xxx.yyy, 502) failed: [Errno -2] Name does not resolve
2022-03-22 10:01:59 ERROR (SyncWorker_15) [pymodbus.client.sync] Connection to (192.168.xxx.yyy, 502) failed: [Errno -2] Name does not resolve
2022-03-22 10:01:59 ERROR (SyncWorker_14) [pymodbus.client.sync] Connection to (192.168.xxx.yyy, 502) failed: [Errno -2] Name does not resolve
2022-03-22 10:01:59 ERROR (SyncWorker_19) [pymodbus.client.sync] Connection to (192.168.xxx.yyy, 502) failed: [Errno -2] Name does not resolve
2022-03-22 10:01:59 ERROR (SyncWorker_23) [pymodbus.client.sync] Connection to (192.168.xxx.yyy, 502) failed: [Errno -2] Name does not resolve
2022-03-22 10:01:59 ERROR (SyncWorker_1) [pymodbus.client.sync] Connection to (192.168.xxx.yyy, 502) failed: [Errno -2] Name does not resolve
2022-03-22 10:01:59 ERROR (SyncWorker_4) [pymodbus.client.sync] Connection to (192.168.xxx.yyy, 502) failed: [Errno -2] Name does not resolve
2022-03-22 10:01:59 ERROR (SyncWorker_22) [pymodbus.client.sync] Connection to (192.168.xxx.yyy, 502) failed: [Errno -2] Name does not resolve
2022-03-22 10:02:04 ERROR (SyncWorker_13) [pymodbus.client.sync] Connection to (192.168.xxx.yyy, 502) failed: [Errno -2] Name does not resolve
2022-03-22 10:02:09 ERROR (SyncWorker_5) [pymodbus.client.sync] Connection to (192.168.xxx.yyy, 502) failed: [Errno -2] Name does not resolve
2022-03-22 10:02:14 ERROR (SyncWorker_4) [pymodbus.client.sync] Connection to (192.168.xxx.yyy, 502) failed: [Errno -2] Name does not resolve
2022-03-22 10:02:14 ERROR (SyncWorker_19) [pymodbus.client.sync] Connection to (192.168.xxx.yyy, 502) failed: [Errno -2] Name does not resolve
2022-03-22 10:02:14 ERROR (SyncWorker_19) [pymodbus.client.sync] Connection to (192.168.xxx.yyy, 502) failed: [Errno -2] Name does not resolve
2022-03-22 10:02:14 ERROR (SyncWorker_8) [pymodbus.client.sync] Connection to (192.168.xxx.yyy, 502) failed: [Errno -2] Name does not resolve
2022-03-22 10:02:14 ERROR (SyncWorker_24) [pymodbus.client.sync] Connection to (192.168.xxx.yyy, 502) failed: [Errno -2] Name does not resolve
2022-03-22 10:02:14 ERROR (SyncWorker_12) [pymodbus.client.sync] Connection to (192.168.xxx.yyy, 502) failed: [Errno -2] Name does not resolve
2022-03-22 10:02:14 ERROR (SyncWorker_3) [pymodbus.client.sync] Connection to (192.168.xxx.yyy, 502) failed: [Errno -2] Name does not resolve
2022-03-22 10:02:14 ERROR (SyncWorker_10) [pymodbus.client.sync] Connection to (192.168.xxx.yyy, 502) failed: [Errno -2] Name does not resolve
2022-03-22 10:02:19 ERROR (SyncWorker_14) [pymodbus.client.sync] Connection to (192.168.xxx.yyy, 502) failed: [Errno -2] Name does not resolve
2022-03-22 10:02:24 ERROR (SyncWorker_4) [pymodbus.client.sync] Connection to (192.168.xxx.yyy, 502) failed: [Errno -2] Name does not resolve
2022-03-22 10:02:29 ERROR (SyncWorker_10) [pymodbus.client.sync] Connection to (192.168.xxx.yyy, 502) failed: [Errno -2] Name does not resolve
2022-03-22 10:02:29 ERROR (SyncWorker_9) [pymodbus.client.sync] Connection to (192.168.xxx.yyy, 502) failed: [Errno -2] Name does not resolve
2022-03-22 10:02:29 ERROR (SyncWorker_20) [pymodbus.client.sync] Connection to (192.168.xxx.yyy, 502) failed: [Errno -2] Name does not resolve
2022-03-22 10:02:29 ERROR (SyncWorker_7) [pymodbus.client.sync] Connection to (192.168.xxx.yyy, 502) failed: [Errno -2] Name does not resolve
2022-03-22 10:02:29 ERROR (SyncWorker_17) [pymodbus.client.sync] Connection to (192.168.xxx.yyy, 502) failed: [Errno -2] Name does not resolve
2022-03-22 10:02:29 ERROR (SyncWorker_5) [pymodbus.client.sync] Connection to (192.168.xxx.yyy, 502) failed: [Errno -2] Name does not resolve
2022-03-22 10:02:29 ERROR (SyncWorker_6) [pymodbus.client.sync] Connection to (192.168.xxx.yyy, 502) failed: [Errno -2] Name does not resolve
2022-03-22 10:02:29 ERROR (SyncWorker_4) [pymodbus.client.sync] Connection to (192.168.xxx.yyy, 502) failed: [Errno -2] Name does not resolve
2022-03-22 10:02:34 ERROR (SyncWorker_0) [pymodbus.client.sync] Connection to (192.168.xxx.yyy, 502) failed: [Errno -2] Name does not resolve
2022-03-22 10:02:35 WARNING (SyncWorker_10) [homeassistant.components.waze_travel_time.sensor] Error on retrieving data: empty response
2022-03-22 10:02:39 ERROR (SyncWorker_25) [pymodbus.client.sync] Connection to (192.168.xxx.yyy, 502) failed: [Errno -2] Name does not resolve
2022-03-22 10:02:44 ERROR (SyncWorker_6) [pymodbus.client.sync] Connection to (192.168.xxx.yyy, 502) failed: [Errno -2] Name does not resolve
2022-03-22 10:02:44 ERROR (SyncWorker_26) [pymodbus.client.sync] Connection to (192.168.xxx.yyy, 502) failed: [Errno -2] Name does not resolve
2022-03-22 10:02:44 ERROR (SyncWorker_11) [pymodbus.client.sync] Connection to (192.168.xxx.yyy, 502) failed: [Errno -2] Name does not resolve
2022-03-22 10:02:44 ERROR (SyncWorker_4) [pymodbus.client.sync] Connection to (192.168.xxx.yyy, 502) failed: [Errno -2] Name does not resolve
2022-03-22 10:02:44 ERROR (SyncWorker_23) [pymodbus.client.sync] Connection to (192.168.xxx.yyy, 502) failed: [Errno -2] Name does not resolve
2022-03-22 10:02:44 ERROR (SyncWorker_14) [pymodbus.client.sync] Connection to (192.168.xxx.yyy, 502) failed: [Errno -2] Name does not resolve
2022-03-22 10:02:44 ERROR (SyncWorker_13) [pymodbus.client.sync] Connection to (192.168.xxx.yyy, 502) failed: [Errno -2] Name does not resolve
2022-03-22 10:02:44 ERROR (SyncWorker_15) [pymodbus.client.sync] Connection to (192.168.xxx.yyy, 502) failed: [Errno -2] Name does not resolve
2022-03-22 10:02:49 ERROR (SyncWorker_17) [pymodbus.client.sync] Connection to (192.168.xxx.yyy, 502) failed: [Errno -2] Name does not resolve
2022-03-22 10:02:54 ERROR (SyncWorker_19) [pymodbus.client.sync] Connection to (192.168.xxx.yyy, 502) failed: [Errno -2] Name does not resolve
2022-03-22 10:02:59 ERROR (SyncWorker_2) [pymodbus.client.sync] Connection to (192.168.xxx.yyy, 502) failed: [Errno -2] Name does not resolve
2022-03-22 10:02:59 ERROR (SyncWorker_16) [pymodbus.client.sync] Connection to (192.168.xxx.yyy, 502) failed: [Errno -2] Name does not resolve
2022-03-22 10:02:59 ERROR (SyncWorker_0) [pymodbus.client.sync] Connection to (192.168.xxx.yyy, 502) failed: [Errno -2] Name does not resolve
2022-03-22 10:02:59 ERROR (SyncWorker_7) [pymodbus.client.sync] Connection to (192.168.xxx.yyy, 502) failed: [Errno -2] Name does not resolve
2022-03-22 10:02:59 ERROR (SyncWorker_15) [pymodbus.client.sync] Connection to (192.168.xxx.yyy, 502) failed: [Errno -2] Name does not resolve
2022-03-22 10:02:59 ERROR (SyncWorker_5) [pymodbus.client.sync] Connection to (192.168.xxx.yyy, 502) failed: [Errno -2] Name does not resolve
2022-03-22 10:02:59 ERROR (SyncWorker_25) [pymodbus.client.sync] Connection to (192.168.xxx.yyy, 502) failed: [Errno -2] Name does not resolve
2022-03-22 10:02:59 ERROR (SyncWorker_10) [pymodbus.client.sync] Connection to (192.168.xxx.yyy, 502) failed: [Errno -2] Name does not resolve
2022-03-22 10:03:00 WARNING (MainThread) [homeassistant.helpers.template] Template warning: 'timestamp_custom' got invalid input 'n/a' when rendering template '{% if states('device_tracker.audi_e_tron_sportback_position') =="home" %} Auto staat thuis.

  {% if (states('input_number.car_smart_charging_target_percentage') | float(default=0)) < (states('sensor.audi_e_tron_sportback_state_of_charge') | float(default=0) ) %} 
  Er hoeft niet te worden geladen: laaddoel {{states('input_number.car_smart_charging_target_percentage') |round()}}% is al bereikt.

  {% else %}
 {% set target = states('input_number.car_smart_charging_target_percentage') | float(default=0) %}
 {% set soc = states('sensor.audi_e_tron_sportback_state_of_charge') | float(default=0) %}
 {% set nog_te_laden_procent = [target - soc, 0] | max %}
 {% set nog_te_laden_minuten = nog_te_laden_procent * 8.5 | round(2) %}

   Van **{{states('sensor.audi_e_tron_sportback_state_of_charge') | round() }}%** naar  **{{states('input_number.car_smart_charging_target_percentage') | round() }}%** =  **{{nog_te_laden_procent | round() }}%** laden = laadtijd **{{ (nog_te_laden_minuten | float(default=0) * 60) | timestamp_custom('%-Hu%M', false)}}**
  {% endif %}

{% else %} Auto staat niet thuis.
Resterende laadtijd: {{states('sensor.audi_e_tron_sportback_remaining_charge_time') | timestamp_custom('%Hu%M')}}
{% endif %}' but no default was specified. Currently 'timestamp_custom' will return 'n/a', however this template will fail to render in Home Assistant core 2022.1
2022-03-22 10:03:00 WARNING (MainThread) [homeassistant.helpers.template] Template warning: 'timestamp_custom' got invalid input 'n/a' when rendering template '{% if states('device_tracker.audi_e_tron_sportback_position') =="home" %} Auto staat thuis.

  {% if (states('input_number.car_smart_charging_target_percentage') | float(default=0)) < (states('sensor.audi_e_tron_sportback_state_of_charge') | float(default=0) ) %} 
  Er hoeft niet te worden geladen: laaddoel {{states('input_number.car_smart_charging_target_percentage') |round()}}% is al bereikt.

  {% else %}
 {% set target = states('input_number.car_smart_charging_target_percentage') | float(default=0) %}
 {% set soc = states('sensor.audi_e_tron_sportback_state_of_charge') | float(default=0) %}
 {% set nog_te_laden_procent = [target - soc, 0] | max %}
 {% set nog_te_laden_minuten = nog_te_laden_procent * 8.5 | round(2) %}

   Van **{{states('sensor.audi_e_tron_sportback_state_of_charge') | round() }}%** naar  **{{states('input_number.car_smart_charging_target_percentage') | round() }}%** =  **{{nog_te_laden_procent | round() }}%** laden = laadtijd **{{ (nog_te_laden_minuten | float(default=0) * 60) | timestamp_custom('%-Hu%M', false)}}**
  {% endif %}

{% else %} Auto staat niet thuis.
Resterende laadtijd: {{states('sensor.audi_e_tron_sportback_remaining_charge_time') | timestamp_custom('%Hu%M')}}
{% endif %}' but no default was specified. Currently 'timestamp_custom' will return 'n/a', however this template will fail to render in Home Assistant core 2022.1
2022-03-22 10:03:04 ERROR (SyncWorker_14) [pymodbus.client.sync] Connection to (192.168.xxx.yyy, 502) failed: [Errno -2] Name does not resolve
2022-03-22 10:03:08 ERROR (MainThread) [homeassistant.util.logging] Exception in async_schedule_update_ha_state when dispatching 'audiconnect.updated': ()
Traceback (most recent call last):
  File "/usr/src/homeassistant/homeassistant/helpers/entity.py", line 712, in async_schedule_update_ha_state
    self.async_write_ha_state()
  File "/usr/src/homeassistant/homeassistant/helpers/entity.py", line 553, in async_write_ha_state
    self._async_write_ha_state()
  File "/usr/src/homeassistant/homeassistant/helpers/entity.py", line 681, in _async_write_ha_state
    self.hass.states.async_set(
  File "/usr/src/homeassistant/homeassistant/core.py", line 1363, in async_set
    state = State(
  File "/usr/src/homeassistant/homeassistant/core.py", line 1049, in __init__
    raise InvalidStateError(
homeassistant.exceptions.InvalidStateError: Invalid state encountered for entity ID: sensor.audi_e_tron_sportback_shortterm_trip_data. State max length is 255 characters.

2022-03-22 10:03:08 ERROR (MainThread) [homeassistant.util.logging] Exception in async_schedule_update_ha_state when dispatching 'audiconnect.updated': ()
Traceback (most recent call last):
  File "/usr/src/homeassistant/homeassistant/helpers/entity.py", line 712, in async_schedule_update_ha_state
    self.async_write_ha_state()
  File "/usr/src/homeassistant/homeassistant/helpers/entity.py", line 553, in async_write_ha_state
    self._async_write_ha_state()
  File "/usr/src/homeassistant/homeassistant/helpers/entity.py", line 681, in _async_write_ha_state
    self.hass.states.async_set(
  File "/usr/src/homeassistant/homeassistant/core.py", line 1363, in async_set
    state = State(
  File "/usr/src/homeassistant/homeassistant/core.py", line 1049, in __init__
    raise InvalidStateError(
homeassistant.exceptions.InvalidStateError: Invalid state encountered for entity ID: sensor.audi_e_tron_sportback_shortterm_trip_user_reset. State max length is 255 characters.

2022-03-22 10:03:08 WARNING (MainThread) [homeassistant.helpers.template] Template warning: 'timestamp_custom' got invalid input 'n/a' when rendering template '{% if states('device_tracker.audi_e_tron_sportback_position') =="home" %} Auto staat thuis.

  {% if (states('input_number.car_smart_charging_target_percentage') | float(default=0)) < (states('sensor.audi_e_tron_sportback_state_of_charge') | float(default=0) ) %} 
  Er hoeft niet te worden geladen: laaddoel {{states('input_number.car_smart_charging_target_percentage') |round()}}% is al bereikt.

  {% else %}
 {% set target = states('input_number.car_smart_charging_target_percentage') | float(default=0) %}
 {% set soc = states('sensor.audi_e_tron_sportback_state_of_charge') | float(default=0) %}
 {% set nog_te_laden_procent = [target - soc, 0] | max %}
 {% set nog_te_laden_minuten = nog_te_laden_procent * 8.5 | round(2) %}

   Van **{{states('sensor.audi_e_tron_sportback_state_of_charge') | round() }}%** naar  **{{states('input_number.car_smart_charging_target_percentage') | round() }}%** =  **{{nog_te_laden_procent | round() }}%** laden = laadtijd **{{ (nog_te_laden_minuten | float(default=0) * 60) | timestamp_custom('%-Hu%M', false)}}**
  {% endif %}

{% else %} Auto staat niet thuis.
Resterende laadtijd: {{states('sensor.audi_e_tron_sportback_remaining_charge_time') | timestamp_custom('%Hu%M')}}
{% endif %}' but no default was specified. Currently 'timestamp_custom' will return 'n/a', however this template will fail to render in Home Assistant core 2022.1
2022-03-22 10:03:09 ERROR (SyncWorker_27) [pymodbus.client.sync] Connection to (192.168.xxx.yyy, 502) failed: [Errno -2] Name does not resolve
2022-03-22 10:03:14 ERROR (SyncWorker_14) [pymodbus.client.sync] Connection to (192.168.xxx.yyy, 502) failed: [Errno -2] Name does not resolve
2022-03-22 10:03:14 ERROR (SyncWorker_16) [pymodbus.client.sync] Connection to (192.168.xxx.yyy, 502) failed: [Errno -2] Name does not resolve
2022-03-22 10:03:14 ERROR (SyncWorker_17) [pymodbus.client.sync] Connection to (192.168.xxx.yyy, 502) failed: [Errno -2] Name does not resolve
2022-03-22 10:03:14 ERROR (SyncWorker_26) [pymodbus.client.sync] Connection to (192.168.xxx.yyy, 502) failed: [Errno -2] Name does not resolve
2022-03-22 10:03:14 ERROR (SyncWorker_10) [pymodbus.client.sync] Connection to (192.168.xxx.yyy, 502) failed: [Errno -2] Name does not resolve
2022-03-22 10:03:14 ERROR (SyncWorker_22) [pymodbus.client.sync] Connection to (192.168.xxx.yyy, 502) failed: [Errno -2] Name does not resolve
2022-03-22 10:03:14 ERROR (SyncWorker_13) [pymodbus.client.sync] Connection to (192.168.xxx.yyy, 502) failed: [Errno -2] Name does not resolve
2022-03-22 10:03:14 ERROR (SyncWorker_4) [pymodbus.client.sync] Connection to (192.168.xxx.yyy, 502) failed: [Errno -2] Name does not resolve
2022-03-22 10:03:19 ERROR (SyncWorker_8) [pymodbus.client.sync] Connection to (192.168.xxx.yyy, 502) failed: [Errno -2] Name does not resolve
2022-03-22 10:03:24 ERROR (SyncWorker_9) [pymodbus.client.sync] Connection to (192.168.xxx.yyy, 502) failed: [Errno -2] Name does not resolve
2022-03-22 10:03:29 ERROR (SyncWorker_3) [pymodbus.client.sync] Connection to (192.168.xxx.yyy, 502) failed: [Errno -2] Name does not resolve
2022-03-22 10:03:29 ERROR (SyncWorker_0) [pymodbus.client.sync] Connection to (192.168.xxx.yyy, 502) failed: [Errno -2] Name does not resolve
2022-03-22 10:03:29 ERROR (SyncWorker_11) [pymodbus.client.sync] Connection to (192.168.xxx.yyy, 502) failed: [Errno -2] Name does not resolve
2022-03-22 10:03:29 ERROR (SyncWorker_4) [pymodbus.client.sync] Connection to (192.168.xxx.yyy, 502) failed: [Errno -2] Name does not resolve
2022-03-22 10:03:29 ERROR (SyncWorker_23) [pymodbus.client.sync] Connection to (192.168.xxx.yyy, 502) failed: [Errno -2] Name does not resolve
2022-03-22 10:03:29 ERROR (SyncWorker_12) [pymodbus.client.sync] Connection to (192.168.xxx.yyy, 502) failed: [Errno -2] Name does not resolve
2022-03-22 10:03:29 ERROR (SyncWorker_15) [pymodbus.client.sync] Connection to (192.168.xxx.yyy, 502) failed: [Errno -2] Name does not resolve
2022-03-22 10:03:29 ERROR (SyncWorker_20) [pymodbus.client.sync] Connection to (192.168.xxx.yyy, 502) failed: [Errno -2] Name does not resolve
2022-03-22 10:03:34 ERROR (SyncWorker_2) [pymodbus.client.sync] Connection to (192.168.xxx.yyy, 502) failed: [Errno -2] Name does not resolve
2022-03-22 10:03:39 ERROR (SyncWorker_21) [pymodbus.client.sync] Connection to (192.168.xxx.yyy, 502) failed: [Errno -2] Name does not resolve
2022-03-22 10:03:44 ERROR (SyncWorker_2) [pymodbus.client.sync] Connection to (192.168.xxx.yyy, 502) failed: [Errno -2] Name does not resolve
2022-03-22 10:03:44 ERROR (SyncWorker_14) [pymodbus.client.sync] Connection to (192.168.xxx.yyy, 502) failed: [Errno -2] Name does not resolve
2022-03-22 10:03:44 ERROR (SyncWorker_16) [pymodbus.client.sync] Connection to (192.168.xxx.yyy, 502) failed: [Errno -2] Name does not resolve
2022-03-22 10:03:44 ERROR (SyncWorker_1) [pymodbus.client.sync] Connection to (192.168.xxx.yyy, 502) failed: [Errno -2] Name does not resolve
2022-03-22 10:03:44 ERROR (SyncWorker_1) [pymodbus.client.sync] Connection to (192.168.xxx.yyy, 502) failed: [Errno -2] Name does not resolve
2022-03-22 10:03:44 ERROR (SyncWorker_0) [pymodbus.client.sync] Connection to (192.168.xxx.yyy, 502) failed: [Errno -2] Name does not resolve
2022-03-22 10:03:44 ERROR (SyncWorker_22) [pymodbus.client.sync] Connection to (192.168.xxx.yyy, 502) failed: [Errno -2] Name does not resolve
2022-03-22 10:03:44 ERROR (SyncWorker_5) [pymodbus.client.sync] Connection to (192.168.xxx.yyy, 502) failed: [Errno -2] Name does not resolve
2022-03-22 10:03:49 ERROR (SyncWorker_20) [pymodbus.client.sync] Connection to (192.168.xxx.yyy, 502) failed: [Errno -2] Name does not resolve
2022-03-22 10:03:54 ERROR (SyncWorker_7) [pymodbus.client.sync] Connection to (192.168.xxx.yyy, 502) failed: [Errno -2] Name does not resolve
2022-03-22 10:03:59 ERROR (SyncWorker_24) [pymodbus.client.sync] Connection to (192.168.xxx.yyy, 502) failed: [Errno -2] Name does not resolve
2022-03-22 10:03:59 ERROR (SyncWorker_10) [pymodbus.client.sync] Connection to (192.168.xxx.yyy, 502) failed: [Errno -2] Name does not resolve
2022-03-22 10:03:59 ERROR (SyncWorker_8) [pymodbus.client.sync] Connection to (192.168.xxx.yyy, 502) failed: [Errno -2] Name does not resolve
2022-03-22 10:03:59 ERROR (SyncWorker_1) [pymodbus.client.sync] Connection to (192.168.xxx.yyy, 502) failed: [Errno -2] Name does not resolve
2022-03-22 10:03:59 ERROR (SyncWorker_0) [pymodbus.client.sync] Connection to (192.168.xxx.yyy, 502) failed: [Errno -2] Name does not resolve
2022-03-22 10:03:59 ERROR (SyncWorker_22) [pymodbus.client.sync] Connection to (192.168.xxx.yyy, 502) failed: [Errno -2] Name does not resolve
2022-03-22 10:03:59 ERROR (SyncWorker_27) [pymodbus.client.sync] Connection to (192.168.xxx.yyy, 502) failed: [Errno -2] Name does not resolve
2022-03-22 10:03:59 ERROR (SyncWorker_13) [pymodbus.client.sync] Connection to (192.168.xxx.yyy, 502) failed: [Errno -2] Name does not resolve
2022-03-22 10:04:04 ERROR (SyncWorker_7) [pymodbus.client.sync] Connection to (192.168.xxx.yyy, 502) failed: [Errno -2] Name does not resolve
2022-03-22 10:04:09 ERROR (SyncWorker_6) [pymodbus.client.sync] Connection to (192.168.xxx.yyy, 502) failed: [Errno -2] Name does not resolve
2022-03-22 10:04:14 ERROR (SyncWorker_21) [pymodbus.client.sync] Connection to (192.168.xxx.yyy, 502) failed: [Errno -2] Name does not resolve
2022-03-22 10:04:14 ERROR (SyncWorker_26) [pymodbus.client.sync] Connection to (192.168.xxx.yyy, 502) failed: [Errno -2] Name does not resolve
2022-03-22 10:04:14 ERROR (SyncWorker_19) [pymodbus.client.sync] Connection to (192.168.xxx.yyy, 502) failed: [Errno -2] Name does not resolve
2022-03-22 10:04:14 ERROR (SyncWorker_7) [pymodbus.client.sync] Connection to (192.168.xxx.yyy, 502) failed: [Errno -2] Name does not resolve
2022-03-22 10:04:14 ERROR (SyncWorker_25) [pymodbus.client.sync] Connection to (192.168.xxx.yyy, 502) failed: [Errno -2] Name does not resolve
2022-03-22 10:04:14 ERROR (SyncWorker_3) [pymodbus.client.sync] Connection to (192.168.xxx.yyy, 502) failed: [Errno -2] Name does not resolve
2022-03-22 10:04:14 ERROR (SyncWorker_8) [pymodbus.client.sync] Connection to (192.168.xxx.yyy, 502) failed: [Errno -2] Name does not resolve
2022-03-22 10:04:14 ERROR (SyncWorker_0) [pymodbus.client.sync] Connection to (192.168.xxx.yyy, 502) failed: [Errno -2] Name does not resolve
2022-03-22 10:04:19 ERROR (SyncWorker_20) [pymodbus.client.sync] Connection to (192.168.xxx.yyy, 502) failed: [Errno -2] Name does not resolve
2022-03-22 10:04:24 ERROR (SyncWorker_26) [pymodbus.client.sync] Connection to (192.168.xxx.yyy, 502) failed: [Errno -2] Name does not resolve
2022-03-22 10:04:29 ERROR (SyncWorker_19) [pymodbus.client.sync] Connection to (192.168.xxx.yyy, 502) failed: [Errno -2] Name does not resolve
2022-03-22 10:04:29 ERROR (SyncWorker_7) [pymodbus.client.sync] Connection to (192.168.xxx.yyy, 502) failed: [Errno -2] Name does not resolve
2022-03-22 10:04:29 ERROR (SyncWorker_25) [pymodbus.client.sync] Connection to (192.168.xxx.yyy, 502) failed: [Errno -2] Name does not resolve
2022-03-22 10:04:29 ERROR (SyncWorker_3) [pymodbus.client.sync] Connection to (192.168.xxx.yyy, 502) failed: [Errno -2] Name does not resolve
2022-03-22 10:04:29 ERROR (SyncWorker_8) [pymodbus.client.sync] Connection to (192.168.xxx.yyy, 502) failed: [Errno -2] Name does not resolve
2022-03-22 10:04:29 ERROR (SyncWorker_2) [pymodbus.client.sync] Connection to (192.168.xxx.yyy, 502) failed: [Errno -2] Name does not resolve
2022-03-22 10:04:29 ERROR (SyncWorker_2) [pymodbus.client.sync] Connection to (192.168.xxx.yyy, 502) failed: [Errno -2] Name does not resolve
2022-03-22 10:04:29 ERROR (SyncWorker_23) [pymodbus.client.sync] Connection to (192.168.xxx.yyy, 502) failed: [Errno -2] Name does not resolve
2022-03-22 10:04:34 ERROR (SyncWorker_25) [pymodbus.client.sync] Connection to (192.168.xxx.yyy, 502) failed: [Errno -2] Name does not resolve
2022-03-22 10:04:39 ERROR (SyncWorker_18) [pymodbus.client.sync] Connection to (192.168.xxx.yyy, 502) failed: [Errno -2] Name does not resolve
2022-03-22 10:04:44 ERROR (SyncWorker_4) [pymodbus.client.sync] Connection to (192.168.xxx.yyy, 502) failed: [Errno -2] Name does not resolve
2022-03-22 10:04:44 ERROR (SyncWorker_16) [pymodbus.client.sync] Connection to (192.168.xxx.yyy, 502) failed: [Errno -2] Name does not resolve
2022-03-22 10:04:44 ERROR (SyncWorker_3) [pymodbus.client.sync] Connection to (192.168.xxx.yyy, 502) failed: [Errno -2] Name does not resolve
2022-03-22 10:04:44 ERROR (SyncWorker_27) [pymodbus.client.sync] Connection to (192.168.xxx.yyy, 502) failed: [Errno -2] Name does not resolve
2022-03-22 10:04:44 ERROR (SyncWorker_17) [pymodbus.client.sync] Connection to (192.168.xxx.yyy, 502) failed: [Errno -2] Name does not resolve
2022-03-22 10:04:44 ERROR (SyncWorker_12) [pymodbus.client.sync] Connection to (192.168.xxx.yyy, 502) failed: [Errno -2] Name does not resolve
2022-03-22 10:04:44 ERROR (SyncWorker_9) [pymodbus.client.sync] Connection to (192.168.xxx.yyy, 502) failed: [Errno -2] Name does not resolve
2022-03-22 10:04:44 ERROR (SyncWorker_26) [pymodbus.client.sync] Connection to (192.168.xxx.yyy, 502) failed: [Errno -2] Name does not resolve
2022-03-22 10:04:49 ERROR (SyncWorker_15) [pymodbus.client.sync] Connection to (192.168.xxx.yyy, 502) failed: [Errno -2] Name does not resolve
2022-03-22 10:04:54 ERROR (SyncWorker_27) [pymodbus.client.sync] Connection to (192.168.xxx.yyy, 502) failed: [Errno -2] Name does not resolve
2022-03-22 10:04:59 ERROR (SyncWorker_17) [pymodbus.client.sync] Connection to (192.168.xxx.yyy, 502) failed: [Errno -2] Name does not resolve
2022-03-22 10:04:59 ERROR (SyncWorker_12) [pymodbus.client.sync] Connection to (192.168.xxx.yyy, 502) failed: [Errno -2] Name does not resolve
2022-03-22 10:04:59 ERROR (SyncWorker_9) [pymodbus.client.sync] Connection to (192.168.xxx.yyy, 502) failed: [Errno -2] Name does not resolve
2022-03-22 10:04:59 ERROR (SyncWorker_24) [pymodbus.client.sync] Connection to (192.168.xxx.yyy, 502) failed: [Errno -2] Name does not resolve
2022-03-22 10:04:59 ERROR (SyncWorker_26) [pymodbus.client.sync] Connection to (192.168.xxx.yyy, 502) failed: [Errno -2] Name does not resolve
2022-03-22 10:04:59 ERROR (SyncWorker_2) [pymodbus.client.sync] Connection to (192.168.xxx.yyy, 502) failed: [Errno -2] Name does not resolve
2022-03-22 10:04:59 ERROR (SyncWorker_1) [pymodbus.client.sync] Connection to (192.168.xxx.yyy, 502) failed: [Errno -2] Name does not resolve
2022-03-22 10:04:59 ERROR (SyncWorker_13) [pymodbus.client.sync] Connection to (192.168.xxx.yyy, 502) failed: [Errno -2] Name does not resolve
2022-03-22 10:05:00 WARNING (MainThread) [homeassistant.components.xiaomi_miio.fan] 'auto'is not a valid preset mode
2022-03-22 10:05:04 ERROR (SyncWorker_19) [pymodbus.client.sync] Connection to (192.168.xxx.yyy, 502) failed: [Errno -2] Name does not resolve
2022-03-22 10:05:09 ERROR (SyncWorker_4) [pymodbus.client.sync] Connection to (192.168.xxx.yyy, 502) failed: [Errno -2] Name does not resolve
2022-03-22 10:05:12 ERROR (MainThread) [homeassistant.util.logging] Exception in async_schedule_update_ha_state when dispatching 'audiconnect.updated': ()
Traceback (most recent call last):
  File "/usr/src/homeassistant/homeassistant/helpers/entity.py", line 712, in async_schedule_update_ha_state
    self.async_write_ha_state()
  File "/usr/src/homeassistant/homeassistant/helpers/entity.py", line 553, in async_write_ha_state
    self._async_write_ha_state()
  File "/usr/src/homeassistant/homeassistant/helpers/entity.py", line 681, in _async_write_ha_state
    self.hass.states.async_set(
  File "/usr/src/homeassistant/homeassistant/core.py", line 1363, in async_set
    state = State(
  File "/usr/src/homeassistant/homeassistant/core.py", line 1049, in __init__
    raise InvalidStateError(
homeassistant.exceptions.InvalidStateError: Invalid state encountered for entity ID: sensor.audi_e_tron_sportback_shortterm_trip_data. State max length is 255 characters.

2022-03-22 10:05:12 ERROR (MainThread) [homeassistant.util.logging] Exception in async_schedule_update_ha_state when dispatching 'audiconnect.updated': ()
Traceback (most recent call last):
  File "/usr/src/homeassistant/homeassistant/helpers/entity.py", line 712, in async_schedule_update_ha_state
    self.async_write_ha_state()
  File "/usr/src/homeassistant/homeassistant/helpers/entity.py", line 553, in async_write_ha_state
    self._async_write_ha_state()
  File "/usr/src/homeassistant/homeassistant/helpers/entity.py", line 681, in _async_write_ha_state
    self.hass.states.async_set(
  File "/usr/src/homeassistant/homeassistant/core.py", line 1363, in async_set
    state = State(
  File "/usr/src/homeassistant/homeassistant/core.py", line 1049, in __init__
    raise InvalidStateError(
homeassistant.exceptions.InvalidStateError: Invalid state encountered for entity ID: sensor.audi_e_tron_sportback_shortterm_trip_user_reset. State max length is 255 characters.

2022-03-22 10:05:12 WARNING (MainThread) [homeassistant.helpers.template] Template warning: 'timestamp_custom' got invalid input 'n/a' when rendering template '{% if states('device_tracker.audi_e_tron_sportback_position') =="home" %} Auto staat thuis.

  {% if (states('input_number.car_smart_charging_target_percentage') | float(default=0)) < (states('sensor.audi_e_tron_sportback_state_of_charge') | float(default=0) ) %} 
  Er hoeft niet te worden geladen: laaddoel {{states('input_number.car_smart_charging_target_percentage') |round()}}% is al bereikt.

  {% else %}
 {% set target = states('input_number.car_smart_charging_target_percentage') | float(default=0) %}
 {% set soc = states('sensor.audi_e_tron_sportback_state_of_charge') | float(default=0) %}
 {% set nog_te_laden_procent = [target - soc, 0] | max %}
 {% set nog_te_laden_minuten = nog_te_laden_procent * 8.5 | round(2) %}

   Van **{{states('sensor.audi_e_tron_sportback_state_of_charge') | round() }}%** naar  **{{states('input_number.car_smart_charging_target_percentage') | round() }}%** =  **{{nog_te_laden_procent | round() }}%** laden = laadtijd **{{ (nog_te_laden_minuten | float(default=0) * 60) | timestamp_custom('%-Hu%M', false)}}**
  {% endif %}

{% else %} Auto staat niet thuis.
Resterende laadtijd: {{states('sensor.audi_e_tron_sportback_remaining_charge_time') | timestamp_custom('%Hu%M')}}
{% endif %}' but no default was specified. Currently 'timestamp_custom' will return 'n/a', however this template will fail to render in Home Assistant core 2022.1
2022-03-22 10:05:14 ERROR (SyncWorker_13) [pymodbus.client.sync] Connection to (192.168.xxx.yyy, 502) failed: [Errno -2] Name does not resolve
2022-03-22 10:05:14 ERROR (SyncWorker_3) [pymodbus.client.sync] Connection to (192.168.xxx.yyy, 502) failed: [Errno -2] Name does not resolve
2022-03-22 10:05:14 ERROR (SyncWorker_12) [pymodbus.client.sync] Connection to (192.168.xxx.yyy, 502) failed: [Errno -2] Name does not resolve
2022-03-22 10:05:14 ERROR (SyncWorker_18) [pymodbus.client.sync] Connection to (192.168.xxx.yyy, 502) failed: [Errno -2] Name does not resolve
2022-03-22 10:05:14 ERROR (SyncWorker_0) [pymodbus.client.sync] Connection to (192.168.xxx.yyy, 502) failed: [Errno -2] Name does not resolve
2022-03-22 10:05:14 ERROR (SyncWorker_27) [pymodbus.client.sync] Connection to (192.168.xxx.yyy, 502) failed: [Errno -2] Name does not resolve
2022-03-22 10:05:14 ERROR (SyncWorker_26) [pymodbus.client.sync] Connection to (192.168.xxx.yyy, 502) failed: [Errno -2] Name does not resolve
2022-03-22 10:05:14 ERROR (SyncWorker_1) [pymodbus.client.sync] Connection to (192.168.xxx.yyy, 502) failed: [Errno -2] Name does not resolve
2022-03-22 10:05:19 ERROR (SyncWorker_11) [pymodbus.client.sync] Connection to (192.168.xxx.yyy, 502) failed: [Errno -2] Name does not resolve
2022-03-22 10:05:24 ERROR (SyncWorker_13) [pymodbus.client.sync] Connection to (192.168.xxx.yyy, 502) failed: [Errno -2] Name does not resolve
2022-03-22 10:05:29 ERROR (SyncWorker_18) [pymodbus.client.sync] Connection to (192.168.xxx.yyy, 502) failed: [Errno -2] Name does not resolve
2022-03-22 10:05:29 ERROR (SyncWorker_0) [pymodbus.client.sync] Connection to (192.168.xxx.yyy, 502) failed: [Errno -2] Name does not resolve
2022-03-22 10:05:29 ERROR (SyncWorker_27) [pymodbus.client.sync] Connection to (192.168.xxx.yyy, 502) failed: [Errno -2] Name does not resolve
2022-03-22 10:05:29 ERROR (SyncWorker_26) [pymodbus.client.sync] Connection to (192.168.xxx.yyy, 502) failed: [Errno -2] Name does not resolve
2022-03-22 10:05:29 ERROR (SyncWorker_4) [pymodbus.client.sync] Connection to (192.168.xxx.yyy, 502) failed: [Errno -2] Name does not resolve
2022-03-22 10:05:29 ERROR (SyncWorker_17) [pymodbus.client.sync] Connection to (192.168.xxx.yyy, 502) failed: [Errno -2] Name does not resolve
2022-03-22 10:05:29 ERROR (SyncWorker_8) [pymodbus.client.sync] Connection to (192.168.xxx.yyy, 502) failed: [Errno -2] Name does not resolve
2022-03-22 10:05:29 ERROR (SyncWorker_14) [pymodbus.client.sync] Connection to (192.168.xxx.yyy, 502) failed: [Errno -2] Name does not resolve
2022-03-22 10:05:34 ERROR (SyncWorker_23) [pymodbus.client.sync] Connection to (192.168.xxx.yyy, 502) failed: [Errno -2] Name does not resolve
2022-03-22 10:05:39 ERROR (SyncWorker_24) [pymodbus.client.sync] Connection to (192.168.xxx.yyy, 502) failed: [Errno -2] Name does not resolve
2022-03-22 10:05:44 ERROR (SyncWorker_6) [pymodbus.client.sync] Connection to (192.168.xxx.yyy, 502) failed: [Errno -2] Name does not resolve
2022-03-22 10:05:44 ERROR (SyncWorker_27) [pymodbus.client.sync] Connection to (192.168.xxx.yyy, 502) failed: [Errno -2] Name does not resolve
2022-03-22 10:05:44 ERROR (SyncWorker_19) [pymodbus.client.sync] Connection to (192.168.xxx.yyy, 502) failed: [Errno -2] Name does not resolve
2022-03-22 10:05:44 ERROR (SyncWorker_23) [pymodbus.client.sync] Connection to (192.168.xxx.yyy, 502) failed: [Errno -2] Name does not resolve
2022-03-22 10:05:44 ERROR (SyncWorker_15) [pymodbus.client.sync] Connection to (192.168.xxx.yyy, 502) failed: [Errno -2] Name does not resolve
2022-03-22 10:05:44 ERROR (SyncWorker_10) [pymodbus.client.sync] Connection to (192.168.xxx.yyy, 502) failed: [Errno -2] Name does not resolve
2022-03-22 10:05:44 ERROR (SyncWorker_8) [pymodbus.client.sync] Connection to (192.168.xxx.yyy, 502) failed: [Errno -2] Name does not resolve
2022-03-22 10:05:44 ERROR (SyncWorker_1) [pymodbus.client.sync] Connection to (192.168.xxx.yyy, 502) failed: [Errno -2] Name does not resolve
2022-03-22 10:05:49 ERROR (SyncWorker_12) [pymodbus.client.sync] Connection to (192.168.xxx.yyy, 502) failed: [Errno -2] Name does not resolve
2022-03-22 10:05:54 ERROR (SyncWorker_0) [pymodbus.client.sync] Connection to (192.168.xxx.yyy, 502) failed: [Errno -2] Name does not resolve
2022-03-22 10:05:59 WARNING (MainThread) [homeassistant.components.modbus.modbus] modbus laadpaal communication closed
2022-03-22 10:05:59 ERROR (MainThread) [homeassistant.helpers.entity] Update for sensor.veranda_speaker_aan_vandaag fails
Traceback (most recent call last):
  File "/usr/src/homeassistant/homeassistant/helpers/entity.py", line 535, in async_update_ha_state
    await self.async_device_update()
  File "/usr/src/homeassistant/homeassistant/helpers/entity.py", line 744, in async_device_update
    raise exc
  File "/usr/src/homeassistant/homeassistant/components/history_stats/sensor.py", line 228, in async_update
    await self.hass.async_add_executor_job(
  File "/usr/local/lib/python3.9/concurrent/futures/thread.py", line 58, in run
    result = self.fn(*self.args, **self.kwargs)
  File "/usr/src/homeassistant/homeassistant/components/history_stats/sensor.py", line 234, in _update
    history_list = history.state_changes_during_period(
  File "/usr/src/homeassistant/homeassistant/components/recorder/history.py", line 143, in state_changes_during_period
    with session_scope(hass=hass) as session:
  File "/usr/local/lib/python3.9/contextlib.py", line 119, in __enter__
    return next(self.gen)
  File "/usr/src/homeassistant/homeassistant/components/recorder/util.py", line 76, in session_scope
    session = hass.data[DATA_INSTANCE].get_session()
TypeError: 'NoneType' object is not callable
2022-03-22 10:05:59 ERROR (MainThread) [homeassistant.helpers.entity] Update for sensor.chromebook_bart_madouce_aan_vandaag fails
Traceback (most recent call last):
  File "/usr/src/homeassistant/homeassistant/helpers/entity.py", line 535, in async_update_ha_state
    await self.async_device_update()
  File "/usr/src/homeassistant/homeassistant/helpers/entity.py", line 744, in async_device_update
    raise exc
  File "/usr/src/homeassistant/homeassistant/components/history_stats/sensor.py", line 228, in async_update
    await self.hass.async_add_executor_job(
  File "/usr/local/lib/python3.9/concurrent/futures/thread.py", line 58, in run
    result = self.fn(*self.args, **self.kwargs)
  File "/usr/src/homeassistant/homeassistant/components/history_stats/sensor.py", line 234, in _update
    history_list = history.state_changes_during_period(
  File "/usr/src/homeassistant/homeassistant/components/recorder/history.py", line 143, in state_changes_during_period
    with session_scope(hass=hass) as session:
  File "/usr/local/lib/python3.9/contextlib.py", line 119, in __enter__
    return next(self.gen)
  File "/usr/src/homeassistant/homeassistant/components/recorder/util.py", line 76, in session_scope
    session = hass.data[DATA_INSTANCE].get_session()
TypeError: 'NoneType' object is not callable
