2021-10-09 22:07:58 WARNING (SyncWorker_2) [homeassistant.loader] We found a custom integration audiconnect which has not been tested by Home Assistant. This component might cause stability problems, be sure to disable it if you experience issues with Home Assistant
2021-10-09 22:07:58 WARNING (SyncWorker_0) [homeassistant.loader] We found a custom integration xiaomi_miio_airpurifier which has not been tested by Home Assistant. This component might cause stability problems, be sure to disable it if you experience issues with Home Assistant
2021-10-09 22:07:58 WARNING (SyncWorker_1) [homeassistant.loader] We found a custom integration average which has not been tested by Home Assistant. This component might cause stability problems, be sure to disable it if you experience issues with Home Assistant
2021-10-09 22:07:58 WARNING (SyncWorker_4) [homeassistant.loader] We found a custom integration monitor_docker which has not been tested by Home Assistant. This component might cause stability problems, be sure to disable it if you experience issues with Home Assistant
2021-10-09 22:07:58 WARNING (SyncWorker_3) [homeassistant.loader] We found a custom integration powercalc which has not been tested by Home Assistant. This component might cause stability problems, be sure to disable it if you experience issues with Home Assistant
2021-10-09 22:07:58 WARNING (SyncWorker_5) [homeassistant.loader] We found a custom integration hacs which has not been tested by Home Assistant. This component might cause stability problems, be sure to disable it if you experience issues with Home Assistant
2021-10-09 22:07:58 WARNING (SyncWorker_0) [homeassistant.loader] We found a custom integration xiaomi_miio_fan which has not been tested by Home Assistant. This component might cause stability problems, be sure to disable it if you experience issues with Home Assistant
2021-10-09 22:07:58 WARNING (SyncWorker_7) [homeassistant.loader] We found a custom integration huesyncbox which has not been tested by Home Assistant. This component might cause stability problems, be sure to disable it if you experience issues with Home Assistant
2021-10-09 22:07:58 WARNING (SyncWorker_2) [homeassistant.loader] We found a custom integration localtuya which has not been tested by Home Assistant. This component might cause stability problems, be sure to disable it if you experience issues with Home Assistant
2021-10-09 22:07:58 WARNING (SyncWorker_6) [homeassistant.loader] We found a custom integration shelly which has not been tested by Home Assistant. This component might cause stability problems, be sure to disable it if you experience issues with Home Assistant
2021-10-09 22:07:58 WARNING (SyncWorker_1) [homeassistant.loader] We found a custom integration buienalarm which has not been tested by Home Assistant. This component might cause stability problems, be sure to disable it if you experience issues with Home Assistant
2021-10-09 22:07:58 WARNING (SyncWorker_8) [homeassistant.loader] We found a custom integration anniversaries which has not been tested by Home Assistant. This component might cause stability problems, be sure to disable it if you experience issues with Home Assistant
2021-10-09 22:07:58 WARNING (SyncWorker_5) [homeassistant.loader] We found a custom integration thermal_comfort which has not been tested by Home Assistant. This component might cause stability problems, be sure to disable it if you experience issues with Home Assistant
2021-10-09 22:07:58 WARNING (SyncWorker_3) [homeassistant.loader] We found a custom integration googlewifi which has not been tested by Home Assistant. This component might cause stability problems, be sure to disable it if you experience issues with Home Assistant
2021-10-09 22:07:58 WARNING (SyncWorker_9) [homeassistant.loader] We found a custom integration ytube_music_player which has not been tested by Home Assistant. This component might cause stability problems, be sure to disable it if you experience issues with Home Assistant
2021-10-09 22:07:58 WARNING (SyncWorker_4) [homeassistant.loader] We found a custom integration xiaomi_miot which has not been tested by Home Assistant. This component might cause stability problems, be sure to disable it if you experience issues with Home Assistant
2021-10-09 22:07:58 WARNING (SyncWorker_2) [homeassistant.loader] We found a custom integration google_home which has not been tested by Home Assistant. This component might cause stability problems, be sure to disable it if you experience issues with Home Assistant
2021-10-09 22:07:58 WARNING (SyncWorker_7) [homeassistant.loader] We found a custom integration deepstack_face which has not been tested by Home Assistant. This component might cause stability problems, be sure to disable it if you experience issues with Home Assistant
2021-10-09 22:07:58 WARNING (SyncWorker_1) [homeassistant.loader] We found a custom integration afvalbeheer which has not been tested by Home Assistant. This component might cause stability problems, be sure to disable it if you experience issues with Home Assistant
2021-10-09 22:08:06 ERROR (MainThread) [homeassistant.config] Invalid config for [automation]: required key not provided @ data['action'][4]['domain']. Got None. (See ?, line ?). 
2021-10-09 22:08:06 ERROR (MainThread) [homeassistant.config] Invalid config for [automation]: [title] is an invalid option for [automation]. Check: automation->action->1->title. (See ?, line ?). 
2021-10-09 22:08:06 ERROR (MainThread) [homeassistant.config] Invalid config for [automation]: must be a value between 0 and 59 for dictionary value @ data['minutes']. Got None. (See ?, line ?). 
2021-10-09 22:08:06 ERROR (MainThread) [homeassistant.config] Invalid config for [automation]: must be a value between 0 and 59 for dictionary value @ data['minutes']. Got None. (See ?, line ?). 
2021-10-09 22:08:11 WARNING (MainThread) [homeassistant.components.webhook] Received message for unregistered webhook 80adf825ef6b969ee3c95fc54091652f8a80fe790532f31c6bff63908742af08 from 192.168.86.26
2021-10-09 22:08:11 WARNING (MainThread) [homeassistant.components.fan] Platform xiaomi_miio_fan not ready yet: Unable to discover the device 192.168.86.28; Retrying in background in 30 seconds
2021-10-09 22:08:11 WARNING (MainThread) [homeassistant.components.fan] Platform xiaomi_miio_fan not ready yet: Unable to discover the device 192.168.86.29; Retrying in background in 30 seconds
2021-10-09 22:08:12 WARNING (MainThread) [homeassistant.setup] Setup of input_number is taking over 10 seconds.
2021-10-09 22:08:14 WARNING (MainThread) [homeassistant.config_entries] Config entry '192.168.86.83' for synology_dsm integration not ready yet: ConnectionError = <urllib3.connection.HTTPSConnection object at 0xffff72cb7340>: Failed to establish a new connection: [Errno 113] Host is unreachable; Retrying in background
2021-10-09 22:08:16 WARNING (MainThread) [homeassistant.components.light] Platform netatmo not ready yet: None; Retrying in background in 30 seconds
2021-10-09 22:08:16 WARNING (MainThread) [homeassistant.components.hue.light] Please check for software updates of the douche bulb in the Philips Hue App.
2021-10-09 22:08:16 WARNING (MainThread) [homeassistant.components.hue.light] Please check for software updates of the wasbak rechts bulb in the Philips Hue App.
2021-10-09 22:08:16 WARNING (MainThread) [homeassistant.components.hue.light] Please check for software updates of the bad bulb in the Philips Hue App.
2021-10-09 22:08:16 WARNING (MainThread) [homeassistant.components.hue.light] Please check for software updates of the Inkomhal bulb in the Philips Hue App.
2021-10-09 22:08:16 WARNING (MainThread) [homeassistant.components.hue.light] Please check for software updates of the Amilya plafond 2 bulb in the Philips Hue App.
2021-10-09 22:08:16 WARNING (MainThread) [homeassistant.components.hue.light] Please check for software updates of the Amilya plafond 1 bulb in the Philips Hue App.
2021-10-09 22:08:17 WARNING (MainThread) [homeassistant.components.select] Platform netatmo not ready yet: None; Retrying in background in 30 seconds
2021-10-09 22:08:17 WARNING (MainThread) [homeassistant.helpers.template] Template warning: 'float' got invalid input 'unknown' when rendering template '{% if states('sensor.temp_leuven24_wunderground') | float < 14 %}
   ideaal ❄
{% else %}
  ideaal
{% endif %}' but no default was specified. Currently 'float' will return '0', however this template will fail to render in Home Assistant core 2021.12
2021-10-09 22:08:17 WARNING (MainThread) [homeassistant.helpers.template] Template warning: 'float' got invalid input 'unknown' when rendering template '{% if states('sensor.temp_leuven24_wunderground') | float < 15 %}
   ideaal ❄
{% else %}
  ideaal
{% endif %}' but no default was specified. Currently 'float' will return '0', however this template will fail to render in Home Assistant core 2021.12
2021-10-09 22:08:17 WARNING (MainThread) [homeassistant.helpers.template] Template warning: 'float' got invalid input 'unknown' when rendering template '{% if states('sensor.temp_leuven24_wunderground') | float < 16 %}
   ideaal ❄
{% else %}
  ideaal
{% endif %}' but no default was specified. Currently 'float' will return '0', however this template will fail to render in Home Assistant core 2021.12
2021-10-09 22:08:17 WARNING (MainThread) [homeassistant.helpers.template] Template warning: 'float' got invalid input 'unknown' when rendering template '{% if states('sensor.temp_leuven24_wunderground') | float < 16 %}
   ideaal ❄
{% else %}
  ideaal
{% endif %}' but no default was specified. Currently 'float' will return '0', however this template will fail to render in Home Assistant core 2021.12
2021-10-09 22:08:17 WARNING (MainThread) [homeassistant.helpers.template] Template warning: 'float' got invalid input 'unknown' when rendering template '{% if states('sensor.temp_leuven24_wunderground') | float < 10 %}
   ideaal ❄
{% else %}
  ideaal
{% endif %}' but no default was specified. Currently 'float' will return '0', however this template will fail to render in Home Assistant core 2021.12
2021-10-09 22:08:17 WARNING (MainThread) [homeassistant.helpers.template] Template warning: 'float' got invalid input 'unknown' when rendering template '{% if states('sensor.temp_leuven24_wunderground') | float < 16 %}
   ideaal ❄
{% else %}
  ideaal
{% endif %}' but no default was specified. Currently 'float' will return '0', however this template will fail to render in Home Assistant core 2021.12
2021-10-09 22:08:17 WARNING (MainThread) [homeassistant.helpers.template] Template warning: 'float' got invalid input 'unknown' when rendering template '{% if states('sensor.temp_leuven24_wunderground') | float < 15 %}
   ideaal ❄
{% else %}
  ideaal
{% endif %}' but no default was specified. Currently 'float' will return '0', however this template will fail to render in Home Assistant core 2021.12
2021-10-09 22:08:17 WARNING (MainThread) [homeassistant.helpers.template] Template warning: 'float' got invalid input 'unknown' when rendering template '{% if states('sensor.temp_leuven24_wunderground') | float < 12 %}
   ideaal ❄
{% else %}
  ideaal
{% endif %}' but no default was specified. Currently 'float' will return '0', however this template will fail to render in Home Assistant core 2021.12
2021-10-09 22:08:17 WARNING (MainThread) [homeassistant.helpers.template] Template warning: 'float' got invalid input 'unknown' when rendering template '{% if states('sensor.temp_leuven24_wunderground') | float < 14 %}
   ideaal ❄
{% else %}
  ideaal
{% endif %}' but no default was specified. Currently 'float' will return '0', however this template will fail to render in Home Assistant core 2021.12
2021-10-09 22:08:17 WARNING (MainThread) [homeassistant.helpers.template] Template warning: 'float' got invalid input 'unknown' when rendering template '{% if states('sensor.temp_leuven24_wunderground') | float < 15 %}
   ideaal ❄
{% else %}
  ideaal
{% endif %}' but no default was specified. Currently 'float' will return '0', however this template will fail to render in Home Assistant core 2021.12
2021-10-09 22:08:17 WARNING (MainThread) [homeassistant.helpers.template] Template warning: 'float' got invalid input 'unknown' when rendering template '{% if states('sensor.temp_leuven24_wunderground') | float < 16 %}
   ideaal ❄
{% else %}
  ideaal
{% endif %}' but no default was specified. Currently 'float' will return '0', however this template will fail to render in Home Assistant core 2021.12
2021-10-09 22:08:17 WARNING (MainThread) [homeassistant.helpers.template] Template warning: 'float' got invalid input 'unknown' when rendering template '{% if states('sensor.temp_leuven24_wunderground') | float < 16 %}
   ideaal ❄
{% else %}
  ideaal
{% endif %}' but no default was specified. Currently 'float' will return '0', however this template will fail to render in Home Assistant core 2021.12
2021-10-09 22:08:17 WARNING (MainThread) [homeassistant.helpers.template] Template warning: 'float' got invalid input 'unknown' when rendering template '{% if states('sensor.temp_leuven24_wunderground') | float < 10 %}
   ideaal ❄
{% else %}
  ideaal
{% endif %}' but no default was specified. Currently 'float' will return '0', however this template will fail to render in Home Assistant core 2021.12
2021-10-09 22:08:17 WARNING (MainThread) [homeassistant.helpers.template] Template warning: 'float' got invalid input 'unknown' when rendering template '{% if states('sensor.temp_leuven24_wunderground') | float < 16 %}
   ideaal ❄
{% else %}
  ideaal
{% endif %}' but no default was specified. Currently 'float' will return '0', however this template will fail to render in Home Assistant core 2021.12
2021-10-09 22:08:17 WARNING (MainThread) [homeassistant.helpers.template] Template warning: 'float' got invalid input 'unknown' when rendering template '{% if states('sensor.temp_leuven24_wunderground') | float < 15 %}
   ideaal ❄
{% else %}
  ideaal
{% endif %}' but no default was specified. Currently 'float' will return '0', however this template will fail to render in Home Assistant core 2021.12
2021-10-09 22:08:17 WARNING (MainThread) [homeassistant.helpers.template] Template warning: 'float' got invalid input 'unknown' when rendering template '{% if states('sensor.temp_leuven24_wunderground') | float < 12 %}
   ideaal ❄
{% else %}
  ideaal
{% endif %}' but no default was specified. Currently 'float' will return '0', however this template will fail to render in Home Assistant core 2021.12
2021-10-09 22:08:18 WARNING (MainThread) [homeassistant.components.sensor] Platform netatmo not ready yet: None; Retrying in background in 30 seconds
2021-10-09 22:08:23 ERROR (MainThread) [homeassistant.components.sensor] scrape: Error on device update!
Traceback (most recent call last):
  File "/usr/src/homeassistant/homeassistant/helpers/entity_platform.py", line 431, in _async_add_entity
    await entity.async_device_update(warning=False)
  File "/usr/src/homeassistant/homeassistant/helpers/entity.py", line 618, in async_device_update
    await task
  File "/usr/src/homeassistant/homeassistant/components/scrape/sensor.py", line 139, in async_update
    await self._async_update_from_rest_data()
  File "/usr/src/homeassistant/homeassistant/components/scrape/sensor.py", line 152, in _async_update_from_rest_data
    value = await self.hass.async_add_executor_job(self._extract_value)
  File "/usr/local/lib/python3.9/concurrent/futures/thread.py", line 52, in run
    result = self.fn(*self.args, **self.kwargs)
  File "/usr/src/homeassistant/homeassistant/components/scrape/sensor.py", line 128, in _extract_value
    tag = raw_data.select(self._select)[self._index]
  File "/usr/local/lib/python3.9/site-packages/bs4/element.py", line 1949, in select
    results = soupsieve.select(selector, self, namespaces, limit, **kwargs)
  File "/usr/local/lib/python3.9/site-packages/soupsieve/__init__.py", line 98, in select
    return compile(select, namespaces, flags, **kwargs).select(tag, limit)
  File "/usr/local/lib/python3.9/site-packages/soupsieve/__init__.py", line 62, in compile
    return cp._cached_css_compile(pattern, namespaces, custom, flags)
  File "/usr/local/lib/python3.9/site-packages/soupsieve/css_parser.py", line 211, in _cached_css_compile
    CSSParser(pattern, custom=custom_selectors, flags=flags).process_selectors(),
  File "/usr/local/lib/python3.9/site-packages/soupsieve/css_parser.py", line 1058, in process_selectors
    return self.parse_selectors(self.selector_iter(self.pattern), index, flags)
  File "/usr/local/lib/python3.9/site-packages/soupsieve/css_parser.py", line 909, in parse_selectors
    key, m = next(iselector)
  File "/usr/local/lib/python3.9/site-packages/soupsieve/css_parser.py", line 1051, in selector_iter
    raise SelectorSyntaxError(msg, self.pattern, index)
soupsieve.util.SelectorSyntaxError: Invalid character '<' position 0
  line 1:
<span _ngcontent-app-root-c173="">Offline</span>
^
2021-10-09 22:08:24 ERROR (SyncWorker_8) [glocaltokens.client] [Device - Nest Wifi router(id=2f2a9d15-0ae2-4ffe-b6c1-2ef24c742b8a)] local_auth_token must follow the correct format
2021-10-09 22:08:24 ERROR (SyncWorker_8) [glocaltokens.client] [Device - Nest Wifi router(id=e1e5a8d5-d21f-444d-95a9-c76d78c9bc79)] local_auth_token must follow the correct format
2021-10-09 22:08:24 ERROR (SyncWorker_8) [glocaltokens.client] [Device - Nest Wifi router(id=ea3de37c-ca74-4689-8171-1681b2f4f924)] local_auth_token must follow the correct format
2021-10-09 22:08:25 WARNING (MainThread) [homeassistant.components.sensor] Setup of sensor platform scrape is taking over 10 seconds.
2021-10-09 22:08:25 WARNING (MainThread) [homeassistant.components.sensor] Setup of sensor platform scrape is taking over 10 seconds.
2021-10-09 22:08:25 WARNING (MainThread) [homeassistant.components.sensor] Setup of sensor platform scrape is taking over 10 seconds.
2021-10-09 22:08:25 WARNING (MainThread) [homeassistant.components.sensor] Setup of sensor platform scrape is taking over 10 seconds.
2021-10-09 22:08:25 WARNING (MainThread) [homeassistant.components.sensor] Setup of sensor platform scrape is taking over 10 seconds.
2021-10-09 22:08:25 ERROR (MainThread) [homeassistant.components.camera] Error while setting up netatmo platform for camera
Traceback (most recent call last):
  File "/usr/local/lib/python3.9/site-packages/aiohttp/connector.py", line 969, in _wrap_create_connection
    return await self._loop.create_connection(*args, **kwargs)  # type: ignore  # noqa
  File "/usr/local/lib/python3.9/asyncio/base_events.py", line 1056, in create_connection
    raise exceptions[0]
  File "/usr/local/lib/python3.9/asyncio/base_events.py", line 1041, in create_connection
    sock = await self._connect_sock(
  File "/usr/local/lib/python3.9/asyncio/base_events.py", line 955, in _connect_sock
    await self.sock_connect(sock, address)
  File "/usr/local/lib/python3.9/asyncio/selector_events.py", line 502, in sock_connect
    return await fut
  File "/usr/local/lib/python3.9/asyncio/selector_events.py", line 537, in _sock_connect_cb
    raise OSError(err, f'Connect call failed {address}')
OSError: [Errno 113] Connect call failed ('169.254.113.236', 80)

The above exception was the direct cause of the following exception:

Traceback (most recent call last):
  File "/usr/src/homeassistant/homeassistant/helpers/entity_platform.py", line 249, in _async_setup_platform
    await asyncio.shield(task)
  File "/usr/src/homeassistant/homeassistant/components/netatmo/camera.py", line 57, in async_setup_entry
    await data_handler.register_data_class(
  File "/usr/src/homeassistant/homeassistant/components/netatmo/data_handler.py", line 192, in register_data_class
    await self.async_fetch_data(data_class_entry)
  File "/usr/src/homeassistant/homeassistant/components/netatmo/data_handler.py", line 149, in async_fetch_data
    await self.data[data_class_entry].async_update()
  File "/usr/local/lib/python3.9/site-packages/pyatmo/camera.py", line 652, in async_update
    await self._async_update_all_camera_urls()
  File "/usr/local/lib/python3.9/site-packages/pyatmo/camera.py", line 662, in _async_update_all_camera_urls
    await self.async_update_camera_urls(camera_id)
  File "/usr/local/lib/python3.9/site-packages/pyatmo/camera.py", line 728, in async_update_camera_urls
    ] = await self._async_check_url(
  File "/usr/local/lib/python3.9/site-packages/pyatmo/camera.py", line 735, in _async_check_url
    resp = await self.auth.async_post_request(url=f"{url}/command/ping")
  File "/usr/local/lib/python3.9/site-packages/pyatmo/auth.py", line 339, in async_post_request
    async with self.websession.post(
  File "/usr/local/lib/python3.9/site-packages/aiohttp/client.py", line 1117, in __aenter__
    self._resp = await self._coro
  File "/usr/local/lib/python3.9/site-packages/aiohttp/client.py", line 520, in _request
    conn = await self._connector.connect(
  File "/usr/local/lib/python3.9/site-packages/aiohttp/connector.py", line 535, in connect
    proto = await self._create_connection(req, traces, timeout)
  File "/usr/local/lib/python3.9/site-packages/aiohttp/connector.py", line 892, in _create_connection
    _, proto = await self._create_direct_connection(req, traces, timeout)
  File "/usr/local/lib/python3.9/site-packages/aiohttp/connector.py", line 1051, in _create_direct_connection
    raise last_exc
  File "/usr/local/lib/python3.9/site-packages/aiohttp/connector.py", line 1020, in _create_direct_connection
    transp, proto = await self._wrap_create_connection(
  File "/usr/local/lib/python3.9/site-packages/aiohttp/connector.py", line 975, in _wrap_create_connection
    raise client_error(req.connection_key, exc) from exc
aiohttp.client_exceptions.ClientConnectorError: Cannot connect to host 169.254.113.236:80 ssl:default [Connect call failed ('169.254.113.236', 80)]
2021-10-09 22:08:25 WARNING (MainThread) [homeassistant.config_entries] Config entry 'OnHub' for upnp integration not ready yet; Retrying in background
2021-10-09 22:08:26 ERROR (MainThread) [homeassistant.config_entries] Error setting up entry bartland@gmail.com for audiconnect
Traceback (most recent call last):
  File "/usr/src/homeassistant/homeassistant/config_entries.py", line 304, in async_setup
    result = await component.async_setup_entry(hass, self)  # type: ignore
  File "/config/custom_components/audiconnect/__init__.py", line 106, in async_setup_entry
    return await data.update(utcnow())
  File "/config/custom_components/audiconnect/audi_account.py", line 162, in update
    if not await self.connection.update(None):
  File "/config/custom_components/audiconnect/audi_connect_account.py", line 105, in update
    vehicles_response = await self._audi_service.get_vehicle_information()
  File "/config/custom_components/audiconnect/audi_services.py", line 193, in get_vehicle_information
    data = await self._api.get(
  File "/config/custom_components/audiconnect/audi_api.py", line 72, in get
    r = await self.request(
  File "/config/custom_components/audiconnect/audi_api.py", line 55, in request
    raise ClientResponseError(
aiohttp.client_exceptions.ClientResponseError: 401, message='Unauthorized', url=URL('https://msg.audi.de/myaudi/vehicle-management/v2/vehicles')
2021-10-09 22:08:37 WARNING (MainThread) [homeassistant.helpers.template] Template warning: 'float' got invalid input 'unknown' when rendering template '{{ states('sensor.tv_living_on_today') | float * 0.085 | round(3) }}' but no default was specified. Currently 'float' will return '0', however this template will fail to render in Home Assistant core 2021.12
2021-10-09 22:08:37 WARNING (MainThread) [homeassistant.helpers.template] Template warning: 'float' got invalid input 'unknown' when rendering template '{{ states('sensor.tv_living_on_today') | float * 0.085 | round(3) }}' but no default was specified. Currently 'float' will return '0', however this template will fail to render in Home Assistant core 2021.12
2021-10-09 22:08:37 WARNING (MainThread) [homeassistant.helpers.template] Template warning: 'float' got invalid input 'unknown' when rendering template '{{ states('sensor.master_bedroom_TV_on_today') | float * 0.063 | round(3) }}' but no default was specified. Currently 'float' will return '0', however this template will fail to render in Home Assistant core 2021.12
2021-10-09 22:08:37 WARNING (MainThread) [homeassistant.helpers.template] Template warning: 'float' got invalid input 'unknown' when rendering template '{{ states('sensor.master_bedroom_TV_on_today') | float * 0.063 | round(3) }}' but no default was specified. Currently 'float' will return '0', however this template will fail to render in Home Assistant core 2021.12
2021-10-09 22:08:47 ERROR (MainThread) [homeassistant] Error doing job: Task exception was never retrieved
Traceback (most recent call last):
  File "/usr/src/homeassistant/homeassistant/components/netatmo/__init__.py", line 198, in register_webhook
    await hass.data[DOMAIN][entry.entry_id][AUTH].async_addwebhook(webhook_url)
  File "/usr/local/lib/python3.9/site-packages/pyatmo/auth.py", line 381, in async_addwebhook
    resp = await self.async_post_request(WEBHOOK_URL_ADD, {"url": webhook_url})
  File "/usr/local/lib/python3.9/site-packages/pyatmo/auth.py", line 339, in async_post_request
    async with self.websession.post(
  File "/usr/local/lib/python3.9/site-packages/aiohttp/client.py", line 1117, in __aenter__
    self._resp = await self._coro
  File "/usr/local/lib/python3.9/site-packages/aiohttp/client.py", line 619, in _request
    break
  File "/usr/local/lib/python3.9/site-packages/aiohttp/helpers.py", line 656, in __exit__
    raise asyncio.TimeoutError from None
asyncio.exceptions.TimeoutError
2021-10-09 22:08:47 WARNING (MainThread) [homeassistant.components.media_player] Updating huesyncbox media_player took longer than the scheduled update interval 0:00:02
2021-10-09 22:08:54 ERROR (MainThread) [homeassistant.components.hue.sensor_base] Timeout fetching sensor data
2021-10-09 22:08:54 ERROR (MainThread) [homeassistant.components.hue.sensor_base] Timeout fetching sensor data
2021-10-09 22:08:55 ERROR (MainThread) [homeassistant.components.google_assistant.http] Request for https://homegraph.googleapis.com/v1/devices:requestSync failed: 500
2021-10-09 22:09:08 ERROR (MainThread) [homeassistant.components.google_assistant.http] Request for https://homegraph.googleapis.com/v1/devices:reportStateAndNotification failed: 404
2021-10-09 22:18:26 ERROR (MainThread) [homeassistant] Error doing job: Task exception was never retrieved
Traceback (most recent call last):
  File "/config/custom_components/audiconnect/audi_account.py", line 162, in update
    if not await self.connection.update(None):
  File "/config/custom_components/audiconnect/audi_connect_account.py", line 105, in update
    vehicles_response = await self._audi_service.get_vehicle_information()
  File "/config/custom_components/audiconnect/audi_services.py", line 193, in get_vehicle_information
    data = await self._api.get(
  File "/config/custom_components/audiconnect/audi_api.py", line 72, in get
    r = await self.request(
  File "/config/custom_components/audiconnect/audi_api.py", line 55, in request
    raise ClientResponseError(
aiohttp.client_exceptions.ClientResponseError: 401, message='Unauthorized', url=URL('https://msg.audi.de/myaudi/vehicle-management/v2/vehicles')
2021-10-09 22:23:16 WARNING (SyncWorker_8) [buienalarm.pybuienalarm] Error fetching data safely: 503 Server Error: Service Unavailable for url: https://cdn-secure.buienalarm.nl/api/3.4/forecast.php?lat=50.878800118427755&lon=4.749415398691782&region=nl&unit=mm%2Fu
2021-10-09 22:27:32 ERROR (MainThread) [custom_components.googlewifi] Error fetching GoogleWifi data: Error connecting to GoogleWifi: 
2021-10-09 22:28:27 ERROR (MainThread) [homeassistant] Error doing job: Task exception was never retrieved
Traceback (most recent call last):
  File "/config/custom_components/audiconnect/audi_account.py", line 162, in update
    if not await self.connection.update(None):
  File "/config/custom_components/audiconnect/audi_connect_account.py", line 105, in update
    vehicles_response = await self._audi_service.get_vehicle_information()
  File "/config/custom_components/audiconnect/audi_services.py", line 193, in get_vehicle_information
    data = await self._api.get(
  File "/config/custom_components/audiconnect/audi_api.py", line 72, in get
    r = await self.request(
  File "/config/custom_components/audiconnect/audi_api.py", line 55, in request
    raise ClientResponseError(
aiohttp.client_exceptions.ClientResponseError: 401, message='Unauthorized', url=URL('https://msg.audi.de/myaudi/vehicle-management/v2/vehicles')
2021-10-09 22:28:52 ERROR (MainThread) [custom_components.googlewifi] Unexpected error fetching GoogleWifi data: 'operationState'
Traceback (most recent call last):
  File "/usr/src/homeassistant/homeassistant/helpers/update_coordinator.py", line 187, in _async_refresh
    self.data = await self._async_update_data()
  File "/config/custom_components/googlewifi/__init__.py", line 171, in _async_update_data
    system_data = await self.api.get_systems()
  File "/usr/local/lib/python3.9/site-packages/googlewifi/__init__.py", line 191, in get_systems
    return await self.structure_systems(response)
  File "/usr/local/lib/python3.9/site-packages/googlewifi/__init__.py", line 284, in structure_systems
    sensitive_info = await self.get_sensitive_info(system_id=this_system["id"], station_ids=station_ids)
  File "/usr/local/lib/python3.9/site-packages/googlewifi/__init__.py", line 616, in get_sensitive_info
    status = status["operationState"]
KeyError: 'operationState'
2021-10-09 22:36:15 ERROR (MainThread) [homeassistant.components.google_assistant.http] Request for https://homegraph.googleapis.com/v1/devices:reportStateAndNotification failed: 404
2021-10-09 22:38:27 ERROR (MainThread) [homeassistant] Error doing job: Task exception was never retrieved
Traceback (most recent call last):
  File "/config/custom_components/audiconnect/audi_account.py", line 162, in update
    if not await self.connection.update(None):
  File "/config/custom_components/audiconnect/audi_connect_account.py", line 105, in update
    vehicles_response = await self._audi_service.get_vehicle_information()
  File "/config/custom_components/audiconnect/audi_services.py", line 193, in get_vehicle_information
    data = await self._api.get(
  File "/config/custom_components/audiconnect/audi_api.py", line 72, in get
    r = await self.request(
  File "/config/custom_components/audiconnect/audi_api.py", line 55, in request
    raise ClientResponseError(
aiohttp.client_exceptions.ClientResponseError: 401, message='Unauthorized', url=URL('https://msg.audi.de/myaudi/vehicle-management/v2/vehicles')
2021-10-09 22:48:27 ERROR (MainThread) [homeassistant] Error doing job: Task exception was never retrieved
Traceback (most recent call last):
  File "/config/custom_components/audiconnect/audi_account.py", line 162, in update
    if not await self.connection.update(None):
  File "/config/custom_components/audiconnect/audi_connect_account.py", line 105, in update
    vehicles_response = await self._audi_service.get_vehicle_information()
  File "/config/custom_components/audiconnect/audi_services.py", line 193, in get_vehicle_information
    data = await self._api.get(
  File "/config/custom_components/audiconnect/audi_api.py", line 72, in get
    r = await self.request(
  File "/config/custom_components/audiconnect/audi_api.py", line 55, in request
    raise ClientResponseError(
aiohttp.client_exceptions.ClientResponseError: 401, message='Unauthorized', url=URL('https://msg.audi.de/myaudi/vehicle-management/v2/vehicles')
2021-10-09 22:53:16 WARNING (SyncWorker_2) [buienalarm.pybuienalarm] Error fetching data safely: 502 Server Error: Bad Gateway for url: https://cdn-secure.buienalarm.nl/api/3.4/forecast.php?lat=50.878800118427755&lon=4.749415398691782&region=nl&unit=mm%2Fu
2021-10-09 22:58:27 ERROR (MainThread) [homeassistant] Error doing job: Task exception was never retrieved
Traceback (most recent call last):
  File "/config/custom_components/audiconnect/audi_account.py", line 162, in update
    if not await self.connection.update(None):
  File "/config/custom_components/audiconnect/audi_connect_account.py", line 105, in update
    vehicles_response = await self._audi_service.get_vehicle_information()
  File "/config/custom_components/audiconnect/audi_services.py", line 193, in get_vehicle_information
    data = await self._api.get(
  File "/config/custom_components/audiconnect/audi_api.py", line 72, in get
    r = await self.request(
  File "/config/custom_components/audiconnect/audi_api.py", line 55, in request
    raise ClientResponseError(
aiohttp.client_exceptions.ClientResponseError: 401, message='Unauthorized', url=URL('https://msg.audi.de/myaudi/vehicle-management/v2/vehicles')
2021-10-09 23:04:09 WARNING (MainThread) [homeassistant.helpers.service] Unable to find referenced entities switch.3504547724a160162a33_3
2021-10-09 23:08:28 ERROR (MainThread) [homeassistant] Error doing job: Task exception was never retrieved
Traceback (most recent call last):
  File "/config/custom_components/audiconnect/audi_account.py", line 162, in update
    if not await self.connection.update(None):
  File "/config/custom_components/audiconnect/audi_connect_account.py", line 105, in update
    vehicles_response = await self._audi_service.get_vehicle_information()
  File "/config/custom_components/audiconnect/audi_services.py", line 193, in get_vehicle_information
    data = await self._api.get(
  File "/config/custom_components/audiconnect/audi_api.py", line 72, in get
    r = await self.request(
  File "/config/custom_components/audiconnect/audi_api.py", line 55, in request
    raise ClientResponseError(
aiohttp.client_exceptions.ClientResponseError: 401, message='Unauthorized', url=URL('https://msg.audi.de/myaudi/vehicle-management/v2/vehicles')
2021-10-09 23:18:28 ERROR (MainThread) [homeassistant] Error doing job: Task exception was never retrieved
Traceback (most recent call last):
  File "/config/custom_components/audiconnect/audi_account.py", line 162, in update
    if not await self.connection.update(None):
  File "/config/custom_components/audiconnect/audi_connect_account.py", line 105, in update
    vehicles_response = await self._audi_service.get_vehicle_information()
  File "/config/custom_components/audiconnect/audi_services.py", line 193, in get_vehicle_information
    data = await self._api.get(
  File "/config/custom_components/audiconnect/audi_api.py", line 72, in get
    r = await self.request(
  File "/config/custom_components/audiconnect/audi_api.py", line 55, in request
    raise ClientResponseError(
aiohttp.client_exceptions.ClientResponseError: 401, message='Unauthorized', url=URL('https://msg.audi.de/myaudi/vehicle-management/v2/vehicles')
2021-10-09 23:28:29 ERROR (MainThread) [homeassistant] Error doing job: Task exception was never retrieved
Traceback (most recent call last):
  File "/config/custom_components/audiconnect/audi_account.py", line 162, in update
    if not await self.connection.update(None):
  File "/config/custom_components/audiconnect/audi_connect_account.py", line 105, in update
    vehicles_response = await self._audi_service.get_vehicle_information()
  File "/config/custom_components/audiconnect/audi_services.py", line 193, in get_vehicle_information
    data = await self._api.get(
  File "/config/custom_components/audiconnect/audi_api.py", line 72, in get
    r = await self.request(
  File "/config/custom_components/audiconnect/audi_api.py", line 55, in request
    raise ClientResponseError(
aiohttp.client_exceptions.ClientResponseError: 401, message='Unauthorized', url=URL('https://msg.audi.de/myaudi/vehicle-management/v2/vehicles')
2021-10-09 23:38:29 ERROR (MainThread) [homeassistant] Error doing job: Task exception was never retrieved
Traceback (most recent call last):
  File "/config/custom_components/audiconnect/audi_account.py", line 162, in update
    if not await self.connection.update(None):
  File "/config/custom_components/audiconnect/audi_connect_account.py", line 105, in update
    vehicles_response = await self._audi_service.get_vehicle_information()
  File "/config/custom_components/audiconnect/audi_services.py", line 193, in get_vehicle_information
    data = await self._api.get(
  File "/config/custom_components/audiconnect/audi_api.py", line 72, in get
    r = await self.request(
  File "/config/custom_components/audiconnect/audi_api.py", line 55, in request
    raise ClientResponseError(
aiohttp.client_exceptions.ClientResponseError: 401, message='Unauthorized', url=URL('https://msg.audi.de/myaudi/vehicle-management/v2/vehicles')
2021-10-09 23:48:26 WARNING (SyncWorker_10) [buienalarm.pybuienalarm] Error fetching data safely: HTTPSConnectionPool(host='cdn-secure.buienalarm.nl', port=443): Read timed out. (read timeout=10.0)
2021-10-09 23:48:30 ERROR (MainThread) [homeassistant] Error doing job: Task exception was never retrieved
Traceback (most recent call last):
  File "/config/custom_components/audiconnect/audi_account.py", line 162, in update
    if not await self.connection.update(None):
  File "/config/custom_components/audiconnect/audi_connect_account.py", line 105, in update
    vehicles_response = await self._audi_service.get_vehicle_information()
  File "/config/custom_components/audiconnect/audi_services.py", line 193, in get_vehicle_information
    data = await self._api.get(
  File "/config/custom_components/audiconnect/audi_api.py", line 72, in get
    r = await self.request(
  File "/config/custom_components/audiconnect/audi_api.py", line 55, in request
    raise ClientResponseError(
aiohttp.client_exceptions.ClientResponseError: 401, message='Unauthorized', url=URL('https://msg.audi.de/myaudi/vehicle-management/v2/vehicles')
2021-10-09 23:49:15 WARNING (MainThread) [homeassistant.helpers.service] Unable to find referenced entities media_player.veranda_speaker_2
2021-10-09 23:49:25 WARNING (MainThread) [homeassistant.helpers.service] Unable to find referenced entities camera.netatmo_eikenbos_oprit
2021-10-09 23:58:30 ERROR (MainThread) [homeassistant] Error doing job: Task exception was never retrieved
Traceback (most recent call last):
  File "/config/custom_components/audiconnect/audi_account.py", line 162, in update
    if not await self.connection.update(None):
  File "/config/custom_components/audiconnect/audi_connect_account.py", line 105, in update
    vehicles_response = await self._audi_service.get_vehicle_information()
  File "/config/custom_components/audiconnect/audi_services.py", line 193, in get_vehicle_information
    data = await self._api.get(
  File "/config/custom_components/audiconnect/audi_api.py", line 72, in get
    r = await self.request(
  File "/config/custom_components/audiconnect/audi_api.py", line 55, in request
    raise ClientResponseError(
aiohttp.client_exceptions.ClientResponseError: 401, message='Unauthorized', url=URL('https://msg.audi.de/myaudi/vehicle-management/v2/vehicles')
2021-10-10 00:08:30 ERROR (MainThread) [homeassistant] Error doing job: Task exception was never retrieved
Traceback (most recent call last):
  File "/config/custom_components/audiconnect/audi_account.py", line 162, in update
    if not await self.connection.update(None):
  File "/config/custom_components/audiconnect/audi_connect_account.py", line 105, in update
    vehicles_response = await self._audi_service.get_vehicle_information()
  File "/config/custom_components/audiconnect/audi_services.py", line 193, in get_vehicle_information
    data = await self._api.get(
  File "/config/custom_components/audiconnect/audi_api.py", line 72, in get
    r = await self.request(
  File "/config/custom_components/audiconnect/audi_api.py", line 55, in request
    raise ClientResponseError(
aiohttp.client_exceptions.ClientResponseError: 401, message='Unauthorized', url=URL('https://msg.audi.de/myaudi/vehicle-management/v2/vehicles')
2021-10-10 00:10:34 WARNING (Thread-49) [pychromecast.socket_client] [(192.168.86.32):8009] Heartbeat timeout, resetting connection
2021-10-10 00:10:49 ERROR (Thread-49) [pychromecast.socket_client] [(192.168.86.32):8009] Failed to connect to service ServiceInfo(type='host', data=('192.168.86.32', 8009)), retrying in 5.0s
2021-10-10 00:18:08 WARNING (Thread-84) [pychromecast.socket_client] [badkamer speaker(192.168.86.35):8009] Heartbeat timeout, resetting connection
2021-10-10 00:18:30 ERROR (MainThread) [homeassistant] Error doing job: Task exception was never retrieved
Traceback (most recent call last):
  File "/config/custom_components/audiconnect/audi_account.py", line 162, in update
    if not await self.connection.update(None):
  File "/config/custom_components/audiconnect/audi_connect_account.py", line 105, in update
    vehicles_response = await self._audi_service.get_vehicle_information()
  File "/config/custom_components/audiconnect/audi_services.py", line 193, in get_vehicle_information
    data = await self._api.get(
  File "/config/custom_components/audiconnect/audi_api.py", line 72, in get
    r = await self.request(
  File "/config/custom_components/audiconnect/audi_api.py", line 55, in request
    raise ClientResponseError(
aiohttp.client_exceptions.ClientResponseError: 401, message='Unauthorized', url=URL('https://msg.audi.de/myaudi/vehicle-management/v2/vehicles')
2021-10-10 00:22:12 ERROR (MainThread) [custom_components.googlewifi] Unexpected error fetching GoogleWifi data: 'NoneType' object is not iterable
Traceback (most recent call last):
  File "/usr/src/homeassistant/homeassistant/helpers/update_coordinator.py", line 187, in _async_refresh
    self.data = await self._async_update_data()
  File "/config/custom_components/googlewifi/__init__.py", line 171, in _async_update_data
    system_data = await self.api.get_systems()
  File "/usr/local/lib/python3.9/site-packages/googlewifi/__init__.py", line 191, in get_systems
    return await self.structure_systems(response)
  File "/usr/local/lib/python3.9/site-packages/googlewifi/__init__.py", line 289, in structure_systems
    for this_station in system_metrics.get("stationMetrics"):
TypeError: 'NoneType' object is not iterable
2021-10-10 00:24:54 ERROR (SyncWorker_14) [glocaltokens.client] [Device - Nest Wifi router(id=2f2a9d15-0ae2-4ffe-b6c1-2ef24c742b8a)] local_auth_token must follow the correct format
2021-10-10 00:24:54 ERROR (SyncWorker_14) [glocaltokens.client] [Device - Nest Wifi router(id=e1e5a8d5-d21f-444d-95a9-c76d78c9bc79)] local_auth_token must follow the correct format
2021-10-10 00:24:54 ERROR (SyncWorker_14) [glocaltokens.client] [Device - Nest Wifi router(id=ea3de37c-ca74-4689-8171-1681b2f4f924)] local_auth_token must follow the correct format
2021-10-10 00:28:31 ERROR (MainThread) [homeassistant] Error doing job: Task exception was never retrieved
Traceback (most recent call last):
  File "/config/custom_components/audiconnect/audi_account.py", line 162, in update
    if not await self.connection.update(None):
  File "/config/custom_components/audiconnect/audi_connect_account.py", line 105, in update
    vehicles_response = await self._audi_service.get_vehicle_information()
  File "/config/custom_components/audiconnect/audi_services.py", line 193, in get_vehicle_information
    data = await self._api.get(
  File "/config/custom_components/audiconnect/audi_api.py", line 72, in get
    r = await self.request(
  File "/config/custom_components/audiconnect/audi_api.py", line 55, in request
    raise ClientResponseError(
aiohttp.client_exceptions.ClientResponseError: 401, message='Unauthorized', url=URL('https://msg.audi.de/myaudi/vehicle-management/v2/vehicles')
2021-10-10 00:38:31 ERROR (MainThread) [homeassistant] Error doing job: Task exception was never retrieved
Traceback (most recent call last):
  File "/config/custom_components/audiconnect/audi_account.py", line 162, in update
    if not await self.connection.update(None):
  File "/config/custom_components/audiconnect/audi_connect_account.py", line 105, in update
    vehicles_response = await self._audi_service.get_vehicle_information()
  File "/config/custom_components/audiconnect/audi_services.py", line 193, in get_vehicle_information
    data = await self._api.get(
  File "/config/custom_components/audiconnect/audi_api.py", line 72, in get
    r = await self.request(
  File "/config/custom_components/audiconnect/audi_api.py", line 55, in request
    raise ClientResponseError(
aiohttp.client_exceptions.ClientResponseError: 401, message='Unauthorized', url=URL('https://msg.audi.de/myaudi/vehicle-management/v2/vehicles')
2021-10-10 00:39:14 WARNING (Thread-80) [pychromecast.socket_client] [Master bedroom speaker(192.168.86.42):8009] Heartbeat timeout, resetting connection
2021-10-10 00:43:36 ERROR (SyncWorker_11) [glocaltokens.client] [Device - Nest Wifi router(id=2f2a9d15-0ae2-4ffe-b6c1-2ef24c742b8a)] local_auth_token must follow the correct format
2021-10-10 00:43:36 ERROR (SyncWorker_11) [glocaltokens.client] [Device - Nest Wifi router(id=e1e5a8d5-d21f-444d-95a9-c76d78c9bc79)] local_auth_token must follow the correct format
2021-10-10 00:43:36 ERROR (SyncWorker_11) [glocaltokens.client] [Device - Nest Wifi router(id=ea3de37c-ca74-4689-8171-1681b2f4f924)] local_auth_token must follow the correct format
2021-10-10 00:46:35 ERROR (MainThread) [custom_components.googlewifi] Error fetching GoogleWifi data: Error connecting to GoogleWifi: 
2021-10-10 00:48:31 ERROR (MainThread) [homeassistant] Error doing job: Task exception was never retrieved
Traceback (most recent call last):
  File "/config/custom_components/audiconnect/audi_account.py", line 162, in update
    if not await self.connection.update(None):
  File "/config/custom_components/audiconnect/audi_connect_account.py", line 105, in update
    vehicles_response = await self._audi_service.get_vehicle_information()
  File "/config/custom_components/audiconnect/audi_services.py", line 193, in get_vehicle_information
    data = await self._api.get(
  File "/config/custom_components/audiconnect/audi_api.py", line 72, in get
    r = await self.request(
  File "/config/custom_components/audiconnect/audi_api.py", line 55, in request
    raise ClientResponseError(
aiohttp.client_exceptions.ClientResponseError: 401, message='Unauthorized', url=URL('https://msg.audi.de/myaudi/vehicle-management/v2/vehicles')
2021-10-10 00:58:31 ERROR (MainThread) [homeassistant] Error doing job: Task exception was never retrieved
Traceback (most recent call last):
  File "/config/custom_components/audiconnect/audi_account.py", line 162, in update
    if not await self.connection.update(None):
  File "/config/custom_components/audiconnect/audi_connect_account.py", line 105, in update
    vehicles_response = await self._audi_service.get_vehicle_information()
  File "/config/custom_components/audiconnect/audi_services.py", line 193, in get_vehicle_information
    data = await self._api.get(
  File "/config/custom_components/audiconnect/audi_api.py", line 72, in get
    r = await self.request(
  File "/config/custom_components/audiconnect/audi_api.py", line 55, in request
    raise ClientResponseError(
aiohttp.client_exceptions.ClientResponseError: 401, message='Unauthorized', url=URL('https://msg.audi.de/myaudi/vehicle-management/v2/vehicles')
2021-10-10 01:02:30 ERROR (MainThread) [homeassistant.components.scrape.sensor] Unable to extract data from HTML for precip_rate_leuven24_wunderground
2021-10-10 01:04:23 ERROR (MainThread) [homeassistant.components.scrape.sensor] Unable to extract data from HTML for humidity_leuven24_wunderground
2021-10-10 01:04:24 ERROR (MainThread) [homeassistant.components.scrape.sensor] Unable to extract data from HTML for temp_leuven24_wunderground
2021-10-10 01:05:26 ERROR (MainThread) [homeassistant.components.scrape.sensor] Unable to extract data from HTML for precip_rate_leuven24_wunderground
2021-10-10 01:08:32 ERROR (MainThread) [homeassistant] Error doing job: Task exception was never retrieved
Traceback (most recent call last):
  File "/config/custom_components/audiconnect/audi_account.py", line 162, in update
    if not await self.connection.update(None):
  File "/config/custom_components/audiconnect/audi_connect_account.py", line 105, in update
    vehicles_response = await self._audi_service.get_vehicle_information()
  File "/config/custom_components/audiconnect/audi_services.py", line 193, in get_vehicle_information
    data = await self._api.get(
  File "/config/custom_components/audiconnect/audi_api.py", line 72, in get
    r = await self.request(
  File "/config/custom_components/audiconnect/audi_api.py", line 55, in request
    raise ClientResponseError(
aiohttp.client_exceptions.ClientResponseError: 401, message='Unauthorized', url=URL('https://msg.audi.de/myaudi/vehicle-management/v2/vehicles')
2021-10-10 01:18:32 ERROR (MainThread) [homeassistant] Error doing job: Task exception was never retrieved
Traceback (most recent call last):
  File "/config/custom_components/audiconnect/audi_account.py", line 162, in update
    if not await self.connection.update(None):
  File "/config/custom_components/audiconnect/audi_connect_account.py", line 105, in update
    vehicles_response = await self._audi_service.get_vehicle_information()
  File "/config/custom_components/audiconnect/audi_services.py", line 193, in get_vehicle_information
    data = await self._api.get(
  File "/config/custom_components/audiconnect/audi_api.py", line 72, in get
    r = await self.request(
  File "/config/custom_components/audiconnect/audi_api.py", line 55, in request
    raise ClientResponseError(
aiohttp.client_exceptions.ClientResponseError: 401, message='Unauthorized', url=URL('https://msg.audi.de/myaudi/vehicle-management/v2/vehicles')
2021-10-10 01:28:32 ERROR (MainThread) [homeassistant] Error doing job: Task exception was never retrieved
Traceback (most recent call last):
  File "/config/custom_components/audiconnect/audi_account.py", line 162, in update
    if not await self.connection.update(None):
  File "/config/custom_components/audiconnect/audi_connect_account.py", line 105, in update
    vehicles_response = await self._audi_service.get_vehicle_information()
  File "/config/custom_components/audiconnect/audi_services.py", line 193, in get_vehicle_information
    data = await self._api.get(
  File "/config/custom_components/audiconnect/audi_api.py", line 72, in get
    r = await self.request(
  File "/config/custom_components/audiconnect/audi_api.py", line 55, in request
    raise ClientResponseError(
aiohttp.client_exceptions.ClientResponseError: 401, message='Unauthorized', url=URL('https://msg.audi.de/myaudi/vehicle-management/v2/vehicles')
2021-10-10 01:38:32 ERROR (MainThread) [homeassistant] Error doing job: Task exception was never retrieved
Traceback (most recent call last):
  File "/config/custom_components/audiconnect/audi_account.py", line 162, in update
    if not await self.connection.update(None):
  File "/config/custom_components/audiconnect/audi_connect_account.py", line 105, in update
    vehicles_response = await self._audi_service.get_vehicle_information()
  File "/config/custom_components/audiconnect/audi_services.py", line 193, in get_vehicle_information
    data = await self._api.get(
  File "/config/custom_components/audiconnect/audi_api.py", line 72, in get
    r = await self.request(
  File "/config/custom_components/audiconnect/audi_api.py", line 55, in request
    raise ClientResponseError(
aiohttp.client_exceptions.ClientResponseError: 401, message='Unauthorized', url=URL('https://msg.audi.de/myaudi/vehicle-management/v2/vehicles')
2021-10-10 01:48:33 ERROR (MainThread) [homeassistant] Error doing job: Task exception was never retrieved
Traceback (most recent call last):
  File "/config/custom_components/audiconnect/audi_account.py", line 162, in update
    if not await self.connection.update(None):
  File "/config/custom_components/audiconnect/audi_connect_account.py", line 105, in update
    vehicles_response = await self._audi_service.get_vehicle_information()
  File "/config/custom_components/audiconnect/audi_services.py", line 193, in get_vehicle_information
    data = await self._api.get(
  File "/config/custom_components/audiconnect/audi_api.py", line 72, in get
    r = await self.request(
  File "/config/custom_components/audiconnect/audi_api.py", line 55, in request
    raise ClientResponseError(
aiohttp.client_exceptions.ClientResponseError: 401, message='Unauthorized', url=URL('https://msg.audi.de/myaudi/vehicle-management/v2/vehicles')
2021-10-10 01:58:33 ERROR (MainThread) [homeassistant] Error doing job: Task exception was never retrieved
Traceback (most recent call last):
  File "/config/custom_components/audiconnect/audi_account.py", line 162, in update
    if not await self.connection.update(None):
  File "/config/custom_components/audiconnect/audi_connect_account.py", line 105, in update
    vehicles_response = await self._audi_service.get_vehicle_information()
  File "/config/custom_components/audiconnect/audi_services.py", line 193, in get_vehicle_information
    data = await self._api.get(
  File "/config/custom_components/audiconnect/audi_api.py", line 72, in get
    r = await self.request(
  File "/config/custom_components/audiconnect/audi_api.py", line 55, in request
    raise ClientResponseError(
aiohttp.client_exceptions.ClientResponseError: 401, message='Unauthorized', url=URL('https://msg.audi.de/myaudi/vehicle-management/v2/vehicles')
2021-10-10 02:00:02 ERROR (MainThread) [homeassistant.components.google_assistant.http] Request for https://homegraph.googleapis.com/v1/devices:reportStateAndNotification failed: 404
2021-10-10 02:01:00 ERROR (MainThread) [homeassistant.components.google_assistant.http] Request for https://homegraph.googleapis.com/v1/devices:reportStateAndNotification failed: 404
2021-10-10 02:03:24 WARNING (Thread-82) [pychromecast.socket_client] [Alunya speaker(192.168.86.37):8009] Heartbeat timeout, resetting connection
2021-10-10 02:03:31 ERROR (Thread-82) [pychromecast.socket_client] [Alunya speaker(192.168.86.37):8009] Failed to connect to service ServiceInfo(type='host', data=('192.168.86.37', 8009)), retrying in 5.0s
2021-10-10 02:05:59 ERROR (MainThread) [custom_components.googlewifi] Unexpected error fetching GoogleWifi data: 'NoneType' object is not iterable
Traceback (most recent call last):
  File "/usr/src/homeassistant/homeassistant/helpers/update_coordinator.py", line 187, in _async_refresh
    self.data = await self._async_update_data()
  File "/config/custom_components/googlewifi/__init__.py", line 171, in _async_update_data
    system_data = await self.api.get_systems()
  File "/usr/local/lib/python3.9/site-packages/googlewifi/__init__.py", line 191, in get_systems
    return await self.structure_systems(response)
  File "/usr/local/lib/python3.9/site-packages/googlewifi/__init__.py", line 289, in structure_systems
    for this_station in system_metrics.get("stationMetrics"):
TypeError: 'NoneType' object is not iterable
2021-10-10 02:07:24 ERROR (SyncWorker_2) [glocaltokens.client] [Device - Nest Wifi router(id=2f2a9d15-0ae2-4ffe-b6c1-2ef24c742b8a)] local_auth_token must follow the correct format
2021-10-10 02:07:24 ERROR (SyncWorker_2) [glocaltokens.client] [Device - Nest Wifi router(id=e1e5a8d5-d21f-444d-95a9-c76d78c9bc79)] local_auth_token must follow the correct format
2021-10-10 02:07:24 ERROR (SyncWorker_2) [glocaltokens.client] [Device - Nest Wifi router(id=ea3de37c-ca74-4689-8171-1681b2f4f924)] local_auth_token must follow the correct format
2021-10-10 02:08:33 ERROR (MainThread) [homeassistant] Error doing job: Task exception was never retrieved
Traceback (most recent call last):
  File "/config/custom_components/audiconnect/audi_account.py", line 162, in update
    if not await self.connection.update(None):
  File "/config/custom_components/audiconnect/audi_connect_account.py", line 105, in update
    vehicles_response = await self._audi_service.get_vehicle_information()
  File "/config/custom_components/audiconnect/audi_services.py", line 193, in get_vehicle_information
    data = await self._api.get(
  File "/config/custom_components/audiconnect/audi_api.py", line 72, in get
    r = await self.request(
  File "/config/custom_components/audiconnect/audi_api.py", line 55, in request
    raise ClientResponseError(
aiohttp.client_exceptions.ClientResponseError: 401, message='Unauthorized', url=URL('https://msg.audi.de/myaudi/vehicle-management/v2/vehicles')
2021-10-10 02:18:33 ERROR (MainThread) [homeassistant] Error doing job: Task exception was never retrieved
Traceback (most recent call last):
  File "/config/custom_components/audiconnect/audi_account.py", line 162, in update
    if not await self.connection.update(None):
  File "/config/custom_components/audiconnect/audi_connect_account.py", line 105, in update
    vehicles_response = await self._audi_service.get_vehicle_information()
  File "/config/custom_components/audiconnect/audi_services.py", line 193, in get_vehicle_information
    data = await self._api.get(
  File "/config/custom_components/audiconnect/audi_api.py", line 72, in get
    r = await self.request(
  File "/config/custom_components/audiconnect/audi_api.py", line 55, in request
    raise ClientResponseError(
aiohttp.client_exceptions.ClientResponseError: 401, message='Unauthorized', url=URL('https://msg.audi.de/myaudi/vehicle-management/v2/vehicles')
2021-10-10 02:28:34 ERROR (MainThread) [homeassistant] Error doing job: Task exception was never retrieved
Traceback (most recent call last):
  File "/config/custom_components/audiconnect/audi_account.py", line 162, in update
    if not await self.connection.update(None):
  File "/config/custom_components/audiconnect/audi_connect_account.py", line 105, in update
    vehicles_response = await self._audi_service.get_vehicle_information()
  File "/config/custom_components/audiconnect/audi_services.py", line 193, in get_vehicle_information
    data = await self._api.get(
  File "/config/custom_components/audiconnect/audi_api.py", line 72, in get
    r = await self.request(
  File "/config/custom_components/audiconnect/audi_api.py", line 55, in request
    raise ClientResponseError(
aiohttp.client_exceptions.ClientResponseError: 401, message='Unauthorized', url=URL('https://msg.audi.de/myaudi/vehicle-management/v2/vehicles')
2021-10-10 02:38:29 ERROR (MainThread) [homeassistant.components.scrape.sensor] Unable to extract data from HTML for precip_rate_leuven24_wunderground
2021-10-10 02:38:30 ERROR (MainThread) [homeassistant.components.scrape.sensor] Unable to extract data from HTML for precip_total_leuven24_wunderground
2021-10-10 02:38:34 ERROR (MainThread) [homeassistant] Error doing job: Task exception was never retrieved
Traceback (most recent call last):
  File "/config/custom_components/audiconnect/audi_account.py", line 162, in update
    if not await self.connection.update(None):
  File "/config/custom_components/audiconnect/audi_connect_account.py", line 105, in update
    vehicles_response = await self._audi_service.get_vehicle_information()
  File "/config/custom_components/audiconnect/audi_services.py", line 193, in get_vehicle_information
    data = await self._api.get(
  File "/config/custom_components/audiconnect/audi_api.py", line 72, in get
    r = await self.request(
  File "/config/custom_components/audiconnect/audi_api.py", line 55, in request
    raise ClientResponseError(
aiohttp.client_exceptions.ClientResponseError: 401, message='Unauthorized', url=URL('https://msg.audi.de/myaudi/vehicle-management/v2/vehicles')
2021-10-10 02:40:24 ERROR (MainThread) [homeassistant.components.scrape.sensor] Unable to extract data from HTML for humidity_leuven24_wunderground
2021-10-10 02:40:24 ERROR (MainThread) [homeassistant.components.scrape.sensor] Unable to extract data from HTML for temp_leuven24_wunderground
2021-10-10 02:41:26 ERROR (MainThread) [homeassistant.components.scrape.sensor] Unable to extract data from HTML for precip_rate_leuven24_wunderground
2021-10-10 02:48:34 ERROR (MainThread) [homeassistant] Error doing job: Task exception was never retrieved
Traceback (most recent call last):
  File "/config/custom_components/audiconnect/audi_account.py", line 162, in update
    if not await self.connection.update(None):
  File "/config/custom_components/audiconnect/audi_connect_account.py", line 105, in update
    vehicles_response = await self._audi_service.get_vehicle_information()
  File "/config/custom_components/audiconnect/audi_services.py", line 193, in get_vehicle_information
    data = await self._api.get(
  File "/config/custom_components/audiconnect/audi_api.py", line 72, in get
    r = await self.request(
  File "/config/custom_components/audiconnect/audi_api.py", line 55, in request
    raise ClientResponseError(
aiohttp.client_exceptions.ClientResponseError: 401, message='Unauthorized', url=URL('https://msg.audi.de/myaudi/vehicle-management/v2/vehicles')
2021-10-10 02:51:12 ERROR (Thread-94) [pychromecast.socket_client] [Living speaker(192.168.86.244):8009] Error reading from socket.
2021-10-10 02:51:12 WARNING (Thread-94) [pychromecast.socket_client] [Living speaker(192.168.86.244):8009] Error communicating with socket, resetting connection
2021-10-10 02:51:12 ERROR (Thread-16) [pychromecast.socket_client] [Groep_living_veranda(192.168.86.244):32106] Error reading from socket.
2021-10-10 02:51:12 WARNING (Thread-16) [pychromecast.socket_client] [Groep_living_veranda(192.168.86.244):32106] Error communicating with socket, resetting connection
2021-10-10 02:51:12 ERROR (Thread-94) [pychromecast.socket_client] [Living speaker(192.168.86.244):8009] Failed to connect to service ServiceInfo(type='mdns', data='google-nest-hub-f462ed96d0e5940e88b752d709fcc230._googlecast._tcp.local.'), retrying in 5.0s
2021-10-10 02:51:12 ERROR (Thread-16) [pychromecast.socket_client] [Groep_living_veranda(192.168.86.244):32106] Failed to connect to service ServiceInfo(type='mdns', data='google-cast-group-90490c41565e4b21af61a4ecedd76c58._googlecast._tcp.local.'), retrying in 5.0s
2021-10-10 02:57:06 ERROR (SyncWorker_8) [glocaltokens.client] [Device - Nest Wifi router(id=2f2a9d15-0ae2-4ffe-b6c1-2ef24c742b8a)] local_auth_token must follow the correct format
2021-10-10 02:57:06 ERROR (SyncWorker_8) [glocaltokens.client] [Device - Nest Wifi router(id=e1e5a8d5-d21f-444d-95a9-c76d78c9bc79)] local_auth_token must follow the correct format
2021-10-10 02:57:06 ERROR (SyncWorker_8) [glocaltokens.client] [Device - Nest Wifi router(id=ea3de37c-ca74-4689-8171-1681b2f4f924)] local_auth_token must follow the correct format
2021-10-10 02:58:34 ERROR (MainThread) [homeassistant] Error doing job: Task exception was never retrieved
Traceback (most recent call last):
  File "/config/custom_components/audiconnect/audi_account.py", line 162, in update
    if not await self.connection.update(None):
  File "/config/custom_components/audiconnect/audi_connect_account.py", line 105, in update
    vehicles_response = await self._audi_service.get_vehicle_information()
  File "/config/custom_components/audiconnect/audi_services.py", line 193, in get_vehicle_information
    data = await self._api.get(
  File "/config/custom_components/audiconnect/audi_api.py", line 72, in get
    r = await self.request(
  File "/config/custom_components/audiconnect/audi_api.py", line 55, in request
    raise ClientResponseError(
aiohttp.client_exceptions.ClientResponseError: 401, message='Unauthorized', url=URL('https://msg.audi.de/myaudi/vehicle-management/v2/vehicles')
2021-10-10 03:08:34 ERROR (MainThread) [homeassistant] Error doing job: Task exception was never retrieved
Traceback (most recent call last):
  File "/config/custom_components/audiconnect/audi_account.py", line 162, in update
    if not await self.connection.update(None):
  File "/config/custom_components/audiconnect/audi_connect_account.py", line 105, in update
    vehicles_response = await self._audi_service.get_vehicle_information()
  File "/config/custom_components/audiconnect/audi_services.py", line 193, in get_vehicle_information
    data = await self._api.get(
  File "/config/custom_components/audiconnect/audi_api.py", line 72, in get
    r = await self.request(
  File "/config/custom_components/audiconnect/audi_api.py", line 55, in request
    raise ClientResponseError(
aiohttp.client_exceptions.ClientResponseError: 401, message='Unauthorized', url=URL('https://msg.audi.de/myaudi/vehicle-management/v2/vehicles')
2021-10-10 03:18:35 ERROR (MainThread) [homeassistant] Error doing job: Task exception was never retrieved
Traceback (most recent call last):
  File "/config/custom_components/audiconnect/audi_account.py", line 162, in update
    if not await self.connection.update(None):
  File "/config/custom_components/audiconnect/audi_connect_account.py", line 105, in update
    vehicles_response = await self._audi_service.get_vehicle_information()
  File "/config/custom_components/audiconnect/audi_services.py", line 193, in get_vehicle_information
    data = await self._api.get(
  File "/config/custom_components/audiconnect/audi_api.py", line 72, in get
    r = await self.request(
  File "/config/custom_components/audiconnect/audi_api.py", line 55, in request
    raise ClientResponseError(
aiohttp.client_exceptions.ClientResponseError: 401, message='Unauthorized', url=URL('https://msg.audi.de/myaudi/vehicle-management/v2/vehicles')
2021-10-10 03:28:36 ERROR (MainThread) [homeassistant] Error doing job: Task exception was never retrieved
Traceback (most recent call last):
  File "/config/custom_components/audiconnect/audi_account.py", line 162, in update
    if not await self.connection.update(None):
  File "/config/custom_components/audiconnect/audi_connect_account.py", line 105, in update
    vehicles_response = await self._audi_service.get_vehicle_information()
  File "/config/custom_components/audiconnect/audi_services.py", line 193, in get_vehicle_information
    data = await self._api.get(
  File "/config/custom_components/audiconnect/audi_api.py", line 72, in get
    r = await self.request(
  File "/config/custom_components/audiconnect/audi_api.py", line 55, in request
    raise ClientResponseError(
aiohttp.client_exceptions.ClientResponseError: 401, message='Unauthorized', url=URL('https://msg.audi.de/myaudi/vehicle-management/v2/vehicles')
2021-10-10 03:38:36 ERROR (MainThread) [homeassistant] Error doing job: Task exception was never retrieved
Traceback (most recent call last):
  File "/config/custom_components/audiconnect/audi_account.py", line 162, in update
    if not await self.connection.update(None):
  File "/config/custom_components/audiconnect/audi_connect_account.py", line 105, in update
    vehicles_response = await self._audi_service.get_vehicle_information()
  File "/config/custom_components/audiconnect/audi_services.py", line 193, in get_vehicle_information
    data = await self._api.get(
  File "/config/custom_components/audiconnect/audi_api.py", line 72, in get
    r = await self.request(
  File "/config/custom_components/audiconnect/audi_api.py", line 55, in request
    raise ClientResponseError(
aiohttp.client_exceptions.ClientResponseError: 401, message='Unauthorized', url=URL('https://msg.audi.de/myaudi/vehicle-management/v2/vehicles')
2021-10-10 03:38:39 WARNING (MainThread) [homeassistant.helpers.service] Unable to find referenced entities media_player.veranda_speaker_2
2021-10-10 03:38:49 WARNING (MainThread) [homeassistant.helpers.service] Unable to find referenced entities camera.netatmo_eikenbos_oprit
2021-10-10 03:48:37 ERROR (MainThread) [homeassistant] Error doing job: Task exception was never retrieved
Traceback (most recent call last):
  File "/config/custom_components/audiconnect/audi_account.py", line 162, in update
    if not await self.connection.update(None):
  File "/config/custom_components/audiconnect/audi_connect_account.py", line 105, in update
    vehicles_response = await self._audi_service.get_vehicle_information()
  File "/config/custom_components/audiconnect/audi_services.py", line 193, in get_vehicle_information
    data = await self._api.get(
  File "/config/custom_components/audiconnect/audi_api.py", line 72, in get
    r = await self.request(
  File "/config/custom_components/audiconnect/audi_api.py", line 55, in request
    raise ClientResponseError(
aiohttp.client_exceptions.ClientResponseError: 401, message='Unauthorized', url=URL('https://msg.audi.de/myaudi/vehicle-management/v2/vehicles')
2021-10-10 03:58:37 ERROR (MainThread) [homeassistant] Error doing job: Task exception was never retrieved
Traceback (most recent call last):
  File "/config/custom_components/audiconnect/audi_account.py", line 162, in update
    if not await self.connection.update(None):
  File "/config/custom_components/audiconnect/audi_connect_account.py", line 105, in update
    vehicles_response = await self._audi_service.get_vehicle_information()
  File "/config/custom_components/audiconnect/audi_services.py", line 193, in get_vehicle_information
    data = await self._api.get(
  File "/config/custom_components/audiconnect/audi_api.py", line 72, in get
    r = await self.request(
  File "/config/custom_components/audiconnect/audi_api.py", line 55, in request
    raise ClientResponseError(
aiohttp.client_exceptions.ClientResponseError: 401, message='Unauthorized', url=URL('https://msg.audi.de/myaudi/vehicle-management/v2/vehicles')
2021-10-10 04:05:18 WARNING (MainThread) [homeassistant.helpers.service] Unable to find referenced entities media_player.veranda_speaker_2
2021-10-10 04:05:28 WARNING (MainThread) [homeassistant.helpers.service] Unable to find referenced entities camera.netatmo_eikenbos_oprit
2021-10-10 04:08:37 ERROR (MainThread) [homeassistant] Error doing job: Task exception was never retrieved
Traceback (most recent call last):
  File "/config/custom_components/audiconnect/audi_account.py", line 162, in update
    if not await self.connection.update(None):
  File "/config/custom_components/audiconnect/audi_connect_account.py", line 105, in update
    vehicles_response = await self._audi_service.get_vehicle_information()
  File "/config/custom_components/audiconnect/audi_services.py", line 193, in get_vehicle_information
    data = await self._api.get(
  File "/config/custom_components/audiconnect/audi_api.py", line 72, in get
    r = await self.request(
  File "/config/custom_components/audiconnect/audi_api.py", line 55, in request
    raise ClientResponseError(
aiohttp.client_exceptions.ClientResponseError: 401, message='Unauthorized', url=URL('https://msg.audi.de/myaudi/vehicle-management/v2/vehicles')
2021-10-10 04:10:10 ERROR (MainThread) [custom_components.googlewifi] Error fetching GoogleWifi data: Error connecting to GoogleWifi: 
2021-10-10 04:14:36 WARNING (MainThread) [homeassistant.helpers.entity] Update of sensor.precip_rate_leuven24_wunderground is taking over 10 seconds
2021-10-10 04:18:38 ERROR (MainThread) [homeassistant] Error doing job: Task exception was never retrieved
Traceback (most recent call last):
  File "/config/custom_components/audiconnect/audi_account.py", line 162, in update
    if not await self.connection.update(None):
  File "/config/custom_components/audiconnect/audi_connect_account.py", line 105, in update
    vehicles_response = await self._audi_service.get_vehicle_information()
  File "/config/custom_components/audiconnect/audi_services.py", line 193, in get_vehicle_information
    data = await self._api.get(
  File "/config/custom_components/audiconnect/audi_api.py", line 72, in get
    r = await self.request(
  File "/config/custom_components/audiconnect/audi_api.py", line 55, in request
    raise ClientResponseError(
aiohttp.client_exceptions.ClientResponseError: 401, message='Unauthorized', url=URL('https://msg.audi.de/myaudi/vehicle-management/v2/vehicles')
2021-10-10 04:28:38 ERROR (MainThread) [homeassistant] Error doing job: Task exception was never retrieved
Traceback (most recent call last):
  File "/config/custom_components/audiconnect/audi_account.py", line 162, in update
    if not await self.connection.update(None):
  File "/config/custom_components/audiconnect/audi_connect_account.py", line 105, in update
    vehicles_response = await self._audi_service.get_vehicle_information()
  File "/config/custom_components/audiconnect/audi_services.py", line 193, in get_vehicle_information
    data = await self._api.get(
  File "/config/custom_components/audiconnect/audi_api.py", line 72, in get
    r = await self.request(
  File "/config/custom_components/audiconnect/audi_api.py", line 55, in request
    raise ClientResponseError(
aiohttp.client_exceptions.ClientResponseError: 401, message='Unauthorized', url=URL('https://msg.audi.de/myaudi/vehicle-management/v2/vehicles')
2021-10-10 04:38:38 ERROR (MainThread) [homeassistant] Error doing job: Task exception was never retrieved
Traceback (most recent call last):
  File "/config/custom_components/audiconnect/audi_account.py", line 162, in update
    if not await self.connection.update(None):
  File "/config/custom_components/audiconnect/audi_connect_account.py", line 105, in update
    vehicles_response = await self._audi_service.get_vehicle_information()
  File "/config/custom_components/audiconnect/audi_services.py", line 193, in get_vehicle_information
    data = await self._api.get(
  File "/config/custom_components/audiconnect/audi_api.py", line 72, in get
    r = await self.request(
  File "/config/custom_components/audiconnect/audi_api.py", line 55, in request
    raise ClientResponseError(
aiohttp.client_exceptions.ClientResponseError: 401, message='Unauthorized', url=URL('https://msg.audi.de/myaudi/vehicle-management/v2/vehicles')
2021-10-10 04:39:34 ERROR (MainThread) [custom_components.googlewifi] Unexpected error fetching GoogleWifi data: 'NoneType' object is not iterable
Traceback (most recent call last):
  File "/usr/src/homeassistant/homeassistant/helpers/update_coordinator.py", line 187, in _async_refresh
    self.data = await self._async_update_data()
  File "/config/custom_components/googlewifi/__init__.py", line 171, in _async_update_data
    system_data = await self.api.get_systems()
  File "/usr/local/lib/python3.9/site-packages/googlewifi/__init__.py", line 191, in get_systems
    return await self.structure_systems(response)
  File "/usr/local/lib/python3.9/site-packages/googlewifi/__init__.py", line 289, in structure_systems
    for this_station in system_metrics.get("stationMetrics"):
TypeError: 'NoneType' object is not iterable
2021-10-10 04:40:16 ERROR (MainThread) [homeassistant.components.google_assistant.http] Request for https://homegraph.googleapis.com/v1/devices:reportStateAndNotification failed: 404
2021-10-10 04:48:38 ERROR (MainThread) [homeassistant] Error doing job: Task exception was never retrieved
Traceback (most recent call last):
  File "/config/custom_components/audiconnect/audi_account.py", line 162, in update
    if not await self.connection.update(None):
  File "/config/custom_components/audiconnect/audi_connect_account.py", line 105, in update
    vehicles_response = await self._audi_service.get_vehicle_information()
  File "/config/custom_components/audiconnect/audi_services.py", line 193, in get_vehicle_information
    data = await self._api.get(
  File "/config/custom_components/audiconnect/audi_api.py", line 72, in get
    r = await self.request(
  File "/config/custom_components/audiconnect/audi_api.py", line 55, in request
    raise ClientResponseError(
aiohttp.client_exceptions.ClientResponseError: 401, message='Unauthorized', url=URL('https://msg.audi.de/myaudi/vehicle-management/v2/vehicles')
2021-10-10 04:58:38 ERROR (MainThread) [homeassistant] Error doing job: Task exception was never retrieved
Traceback (most recent call last):
  File "/config/custom_components/audiconnect/audi_account.py", line 162, in update
    if not await self.connection.update(None):
  File "/config/custom_components/audiconnect/audi_connect_account.py", line 105, in update
    vehicles_response = await self._audi_service.get_vehicle_information()
  File "/config/custom_components/audiconnect/audi_services.py", line 193, in get_vehicle_information
    data = await self._api.get(
  File "/config/custom_components/audiconnect/audi_api.py", line 72, in get
    r = await self.request(
  File "/config/custom_components/audiconnect/audi_api.py", line 55, in request
    raise ClientResponseError(
aiohttp.client_exceptions.ClientResponseError: 401, message='Unauthorized', url=URL('https://msg.audi.de/myaudi/vehicle-management/v2/vehicles')
2021-10-10 05:08:39 ERROR (MainThread) [homeassistant] Error doing job: Task exception was never retrieved
Traceback (most recent call last):
  File "/config/custom_components/audiconnect/audi_account.py", line 162, in update
    if not await self.connection.update(None):
  File "/config/custom_components/audiconnect/audi_connect_account.py", line 105, in update
    vehicles_response = await self._audi_service.get_vehicle_information()
  File "/config/custom_components/audiconnect/audi_services.py", line 193, in get_vehicle_information
    data = await self._api.get(
  File "/config/custom_components/audiconnect/audi_api.py", line 72, in get
    r = await self.request(
  File "/config/custom_components/audiconnect/audi_api.py", line 55, in request
    raise ClientResponseError(
aiohttp.client_exceptions.ClientResponseError: 401, message='Unauthorized', url=URL('https://msg.audi.de/myaudi/vehicle-management/v2/vehicles')
2021-10-10 05:14:30 WARNING (MainThread) [homeassistant.components.automation] Error evaluating condition in 'Regen en raam open = melding':
In 'condition':
  In 'state':
    In 'state' condition: unknown entity binary_sensor.kamer_amilya_window_sensor
2021-10-10 05:14:30 ERROR (MainThread) [homeassistant.components.automation.het_regent] het regent: Error executing script. Invalid data for call_service at pos 1: extra keys not allowed @ data['tag']
2021-10-10 05:14:30 ERROR (MainThread) [homeassistant.components.automation.het_regent] Error while executing automation automation.het_regent: extra keys not allowed @ data['tag']
2021-10-10 05:18:39 ERROR (MainThread) [homeassistant] Error doing job: Task exception was never retrieved
Traceback (most recent call last):
  File "/config/custom_components/audiconnect/audi_account.py", line 162, in update
    if not await self.connection.update(None):
  File "/config/custom_components/audiconnect/audi_connect_account.py", line 105, in update
    vehicles_response = await self._audi_service.get_vehicle_information()
  File "/config/custom_components/audiconnect/audi_services.py", line 193, in get_vehicle_information
    data = await self._api.get(
  File "/config/custom_components/audiconnect/audi_api.py", line 72, in get
    r = await self.request(
  File "/config/custom_components/audiconnect/audi_api.py", line 55, in request
    raise ClientResponseError(
aiohttp.client_exceptions.ClientResponseError: 401, message='Unauthorized', url=URL('https://msg.audi.de/myaudi/vehicle-management/v2/vehicles')
2021-10-10 05:28:39 ERROR (MainThread) [homeassistant] Error doing job: Task exception was never retrieved
Traceback (most recent call last):
  File "/config/custom_components/audiconnect/audi_account.py", line 162, in update
    if not await self.connection.update(None):
  File "/config/custom_components/audiconnect/audi_connect_account.py", line 105, in update
    vehicles_response = await self._audi_service.get_vehicle_information()
  File "/config/custom_components/audiconnect/audi_services.py", line 193, in get_vehicle_information
    data = await self._api.get(
  File "/config/custom_components/audiconnect/audi_api.py", line 72, in get
    r = await self.request(
  File "/config/custom_components/audiconnect/audi_api.py", line 55, in request
    raise ClientResponseError(
aiohttp.client_exceptions.ClientResponseError: 401, message='Unauthorized', url=URL('https://msg.audi.de/myaudi/vehicle-management/v2/vehicles')
2021-10-10 05:38:39 ERROR (MainThread) [homeassistant] Error doing job: Task exception was never retrieved
Traceback (most recent call last):
  File "/config/custom_components/audiconnect/audi_account.py", line 162, in update
    if not await self.connection.update(None):
  File "/config/custom_components/audiconnect/audi_connect_account.py", line 105, in update
    vehicles_response = await self._audi_service.get_vehicle_information()
  File "/config/custom_components/audiconnect/audi_services.py", line 193, in get_vehicle_information
    data = await self._api.get(
  File "/config/custom_components/audiconnect/audi_api.py", line 72, in get
    r = await self.request(
  File "/config/custom_components/audiconnect/audi_api.py", line 55, in request
    raise ClientResponseError(
aiohttp.client_exceptions.ClientResponseError: 401, message='Unauthorized', url=URL('https://msg.audi.de/myaudi/vehicle-management/v2/vehicles')
2021-10-10 05:48:40 ERROR (MainThread) [homeassistant] Error doing job: Task exception was never retrieved
Traceback (most recent call last):
  File "/config/custom_components/audiconnect/audi_account.py", line 162, in update
    if not await self.connection.update(None):
  File "/config/custom_components/audiconnect/audi_connect_account.py", line 105, in update
    vehicles_response = await self._audi_service.get_vehicle_information()
  File "/config/custom_components/audiconnect/audi_services.py", line 193, in get_vehicle_information
    data = await self._api.get(
  File "/config/custom_components/audiconnect/audi_api.py", line 72, in get
    r = await self.request(
  File "/config/custom_components/audiconnect/audi_api.py", line 55, in request
    raise ClientResponseError(
aiohttp.client_exceptions.ClientResponseError: 401, message='Unauthorized', url=URL('https://msg.audi.de/myaudi/vehicle-management/v2/vehicles')
2021-10-10 05:58:40 ERROR (MainThread) [homeassistant] Error doing job: Task exception was never retrieved
Traceback (most recent call last):
  File "/config/custom_components/audiconnect/audi_account.py", line 162, in update
    if not await self.connection.update(None):
  File "/config/custom_components/audiconnect/audi_connect_account.py", line 105, in update
    vehicles_response = await self._audi_service.get_vehicle_information()
  File "/config/custom_components/audiconnect/audi_services.py", line 193, in get_vehicle_information
    data = await self._api.get(
  File "/config/custom_components/audiconnect/audi_api.py", line 72, in get
    r = await self.request(
  File "/config/custom_components/audiconnect/audi_api.py", line 55, in request
    raise ClientResponseError(
aiohttp.client_exceptions.ClientResponseError: 401, message='Unauthorized', url=URL('https://msg.audi.de/myaudi/vehicle-management/v2/vehicles')
2021-10-10 06:08:40 ERROR (MainThread) [homeassistant] Error doing job: Task exception was never retrieved
Traceback (most recent call last):
  File "/config/custom_components/audiconnect/audi_account.py", line 162, in update
    if not await self.connection.update(None):
  File "/config/custom_components/audiconnect/audi_connect_account.py", line 105, in update
    vehicles_response = await self._audi_service.get_vehicle_information()
  File "/config/custom_components/audiconnect/audi_services.py", line 193, in get_vehicle_information
    data = await self._api.get(
  File "/config/custom_components/audiconnect/audi_api.py", line 72, in get
    r = await self.request(
  File "/config/custom_components/audiconnect/audi_api.py", line 55, in request
    raise ClientResponseError(
aiohttp.client_exceptions.ClientResponseError: 401, message='Unauthorized', url=URL('https://msg.audi.de/myaudi/vehicle-management/v2/vehicles')
2021-10-10 06:18:40 ERROR (MainThread) [homeassistant] Error doing job: Task exception was never retrieved
Traceback (most recent call last):
  File "/config/custom_components/audiconnect/audi_account.py", line 162, in update
    if not await self.connection.update(None):
  File "/config/custom_components/audiconnect/audi_connect_account.py", line 105, in update
    vehicles_response = await self._audi_service.get_vehicle_information()
  File "/config/custom_components/audiconnect/audi_services.py", line 193, in get_vehicle_information
    data = await self._api.get(
  File "/config/custom_components/audiconnect/audi_api.py", line 72, in get
    r = await self.request(
  File "/config/custom_components/audiconnect/audi_api.py", line 55, in request
    raise ClientResponseError(
aiohttp.client_exceptions.ClientResponseError: 401, message='Unauthorized', url=URL('https://msg.audi.de/myaudi/vehicle-management/v2/vehicles')
2021-10-10 06:28:41 ERROR (MainThread) [homeassistant] Error doing job: Task exception was never retrieved
Traceback (most recent call last):
  File "/config/custom_components/audiconnect/audi_account.py", line 162, in update
    if not await self.connection.update(None):
  File "/config/custom_components/audiconnect/audi_connect_account.py", line 105, in update
    vehicles_response = await self._audi_service.get_vehicle_information()
  File "/config/custom_components/audiconnect/audi_services.py", line 193, in get_vehicle_information
    data = await self._api.get(
  File "/config/custom_components/audiconnect/audi_api.py", line 72, in get
    r = await self.request(
  File "/config/custom_components/audiconnect/audi_api.py", line 55, in request
    raise ClientResponseError(
aiohttp.client_exceptions.ClientResponseError: 401, message='Unauthorized', url=URL('https://msg.audi.de/myaudi/vehicle-management/v2/vehicles')
2021-10-10 06:38:41 ERROR (MainThread) [homeassistant] Error doing job: Task exception was never retrieved
Traceback (most recent call last):
  File "/config/custom_components/audiconnect/audi_account.py", line 162, in update
    if not await self.connection.update(None):
  File "/config/custom_components/audiconnect/audi_connect_account.py", line 105, in update
    vehicles_response = await self._audi_service.get_vehicle_information()
  File "/config/custom_components/audiconnect/audi_services.py", line 193, in get_vehicle_information
    data = await self._api.get(
  File "/config/custom_components/audiconnect/audi_api.py", line 72, in get
    r = await self.request(
  File "/config/custom_components/audiconnect/audi_api.py", line 55, in request
    raise ClientResponseError(
aiohttp.client_exceptions.ClientResponseError: 401, message='Unauthorized', url=URL('https://msg.audi.de/myaudi/vehicle-management/v2/vehicles')
2021-10-10 06:48:41 ERROR (MainThread) [homeassistant] Error doing job: Task exception was never retrieved
Traceback (most recent call last):
  File "/config/custom_components/audiconnect/audi_account.py", line 162, in update
    if not await self.connection.update(None):
  File "/config/custom_components/audiconnect/audi_connect_account.py", line 105, in update
    vehicles_response = await self._audi_service.get_vehicle_information()
  File "/config/custom_components/audiconnect/audi_services.py", line 193, in get_vehicle_information
    data = await self._api.get(
  File "/config/custom_components/audiconnect/audi_api.py", line 72, in get
    r = await self.request(
  File "/config/custom_components/audiconnect/audi_api.py", line 55, in request
    raise ClientResponseError(
aiohttp.client_exceptions.ClientResponseError: 401, message='Unauthorized', url=URL('https://msg.audi.de/myaudi/vehicle-management/v2/vehicles')
2021-10-10 06:58:41 ERROR (MainThread) [homeassistant] Error doing job: Task exception was never retrieved
Traceback (most recent call last):
  File "/config/custom_components/audiconnect/audi_account.py", line 162, in update
    if not await self.connection.update(None):
  File "/config/custom_components/audiconnect/audi_connect_account.py", line 105, in update
    vehicles_response = await self._audi_service.get_vehicle_information()
  File "/config/custom_components/audiconnect/audi_services.py", line 193, in get_vehicle_information
    data = await self._api.get(
  File "/config/custom_components/audiconnect/audi_api.py", line 72, in get
    r = await self.request(
  File "/config/custom_components/audiconnect/audi_api.py", line 55, in request
    raise ClientResponseError(
aiohttp.client_exceptions.ClientResponseError: 401, message='Unauthorized', url=URL('https://msg.audi.de/myaudi/vehicle-management/v2/vehicles')
2021-10-10 07:08:08 WARNING (MainThread) [homeassistant.components.media_player] Updating huesyncbox media_player took longer than the scheduled update interval 0:00:02
2021-10-10 07:08:42 ERROR (MainThread) [homeassistant] Error doing job: Task exception was never retrieved
Traceback (most recent call last):
  File "/config/custom_components/audiconnect/audi_account.py", line 162, in update
    if not await self.connection.update(None):
  File "/config/custom_components/audiconnect/audi_connect_account.py", line 105, in update
    vehicles_response = await self._audi_service.get_vehicle_information()
  File "/config/custom_components/audiconnect/audi_services.py", line 193, in get_vehicle_information
    data = await self._api.get(
  File "/config/custom_components/audiconnect/audi_api.py", line 72, in get
    r = await self.request(
  File "/config/custom_components/audiconnect/audi_api.py", line 55, in request
    raise ClientResponseError(
aiohttp.client_exceptions.ClientResponseError: 401, message='Unauthorized', url=URL('https://msg.audi.de/myaudi/vehicle-management/v2/vehicles')
2021-10-10 07:18:42 ERROR (MainThread) [homeassistant] Error doing job: Task exception was never retrieved
Traceback (most recent call last):
  File "/config/custom_components/audiconnect/audi_account.py", line 162, in update
    if not await self.connection.update(None):
  File "/config/custom_components/audiconnect/audi_connect_account.py", line 105, in update
    vehicles_response = await self._audi_service.get_vehicle_information()
  File "/config/custom_components/audiconnect/audi_services.py", line 193, in get_vehicle_information
    data = await self._api.get(
  File "/config/custom_components/audiconnect/audi_api.py", line 72, in get
    r = await self.request(
  File "/config/custom_components/audiconnect/audi_api.py", line 55, in request
    raise ClientResponseError(
aiohttp.client_exceptions.ClientResponseError: 401, message='Unauthorized', url=URL('https://msg.audi.de/myaudi/vehicle-management/v2/vehicles')
2021-10-10 07:28:42 ERROR (MainThread) [homeassistant] Error doing job: Task exception was never retrieved
Traceback (most recent call last):
  File "/config/custom_components/audiconnect/audi_account.py", line 162, in update
    if not await self.connection.update(None):
  File "/config/custom_components/audiconnect/audi_connect_account.py", line 105, in update
    vehicles_response = await self._audi_service.get_vehicle_information()
  File "/config/custom_components/audiconnect/audi_services.py", line 193, in get_vehicle_information
    data = await self._api.get(
  File "/config/custom_components/audiconnect/audi_api.py", line 72, in get
    r = await self.request(
  File "/config/custom_components/audiconnect/audi_api.py", line 55, in request
    raise ClientResponseError(
aiohttp.client_exceptions.ClientResponseError: 401, message='Unauthorized', url=URL('https://msg.audi.de/myaudi/vehicle-management/v2/vehicles')
2021-10-10 07:38:42 ERROR (MainThread) [homeassistant] Error doing job: Task exception was never retrieved
Traceback (most recent call last):
  File "/config/custom_components/audiconnect/audi_account.py", line 162, in update
    if not await self.connection.update(None):
  File "/config/custom_components/audiconnect/audi_connect_account.py", line 105, in update
    vehicles_response = await self._audi_service.get_vehicle_information()
  File "/config/custom_components/audiconnect/audi_services.py", line 193, in get_vehicle_information
    data = await self._api.get(
  File "/config/custom_components/audiconnect/audi_api.py", line 72, in get
    r = await self.request(
  File "/config/custom_components/audiconnect/audi_api.py", line 55, in request
    raise ClientResponseError(
aiohttp.client_exceptions.ClientResponseError: 401, message='Unauthorized', url=URL('https://msg.audi.de/myaudi/vehicle-management/v2/vehicles')
2021-10-10 07:48:43 ERROR (MainThread) [homeassistant] Error doing job: Task exception was never retrieved
Traceback (most recent call last):
  File "/config/custom_components/audiconnect/audi_account.py", line 162, in update
    if not await self.connection.update(None):
  File "/config/custom_components/audiconnect/audi_connect_account.py", line 105, in update
    vehicles_response = await self._audi_service.get_vehicle_information()
  File "/config/custom_components/audiconnect/audi_services.py", line 193, in get_vehicle_information
    data = await self._api.get(
  File "/config/custom_components/audiconnect/audi_api.py", line 72, in get
    r = await self.request(
  File "/config/custom_components/audiconnect/audi_api.py", line 55, in request
    raise ClientResponseError(
aiohttp.client_exceptions.ClientResponseError: 401, message='Unauthorized', url=URL('https://msg.audi.de/myaudi/vehicle-management/v2/vehicles')
2021-10-10 07:58:44 ERROR (MainThread) [homeassistant] Error doing job: Task exception was never retrieved
Traceback (most recent call last):
  File "/config/custom_components/audiconnect/audi_account.py", line 162, in update
    if not await self.connection.update(None):
  File "/config/custom_components/audiconnect/audi_connect_account.py", line 105, in update
    vehicles_response = await self._audi_service.get_vehicle_information()
  File "/config/custom_components/audiconnect/audi_services.py", line 193, in get_vehicle_information
    data = await self._api.get(
  File "/config/custom_components/audiconnect/audi_api.py", line 72, in get
    r = await self.request(
  File "/config/custom_components/audiconnect/audi_api.py", line 55, in request
    raise ClientResponseError(
aiohttp.client_exceptions.ClientResponseError: 401, message='Unauthorized', url=URL('https://msg.audi.de/myaudi/vehicle-management/v2/vehicles')
2021-10-10 08:04:39 WARNING (MainThread) [homeassistant.helpers.service] Unable to find referenced entities media_player.veranda_speaker_2
2021-10-10 08:04:49 WARNING (MainThread) [homeassistant.helpers.service] Unable to find referenced entities camera.netatmo_eikenbos_oprit
2021-10-10 08:08:17 WARNING (MainThread) [homeassistant.helpers.service] Unable to find referenced entities media_player.veranda_speaker_2
2021-10-10 08:08:27 WARNING (MainThread) [homeassistant.helpers.service] Unable to find referenced entities camera.netatmo_eikenbos_oprit
2021-10-10 08:08:44 ERROR (MainThread) [homeassistant] Error doing job: Task exception was never retrieved
Traceback (most recent call last):
  File "/config/custom_components/audiconnect/audi_account.py", line 162, in update
    if not await self.connection.update(None):
  File "/config/custom_components/audiconnect/audi_connect_account.py", line 105, in update
    vehicles_response = await self._audi_service.get_vehicle_information()
  File "/config/custom_components/audiconnect/audi_services.py", line 193, in get_vehicle_information
    data = await self._api.get(
  File "/config/custom_components/audiconnect/audi_api.py", line 72, in get
    r = await self.request(
  File "/config/custom_components/audiconnect/audi_api.py", line 55, in request
    raise ClientResponseError(
aiohttp.client_exceptions.ClientResponseError: 401, message='Unauthorized', url=URL('https://msg.audi.de/myaudi/vehicle-management/v2/vehicles')
2021-10-10 08:18:44 ERROR (MainThread) [homeassistant] Error doing job: Task exception was never retrieved
Traceback (most recent call last):
  File "/config/custom_components/audiconnect/audi_account.py", line 162, in update
    if not await self.connection.update(None):
  File "/config/custom_components/audiconnect/audi_connect_account.py", line 105, in update
    vehicles_response = await self._audi_service.get_vehicle_information()
  File "/config/custom_components/audiconnect/audi_services.py", line 193, in get_vehicle_information
    data = await self._api.get(
  File "/config/custom_components/audiconnect/audi_api.py", line 72, in get
    r = await self.request(
  File "/config/custom_components/audiconnect/audi_api.py", line 55, in request
    raise ClientResponseError(
aiohttp.client_exceptions.ClientResponseError: 401, message='Unauthorized', url=URL('https://msg.audi.de/myaudi/vehicle-management/v2/vehicles')
2021-10-10 08:28:45 ERROR (MainThread) [homeassistant] Error doing job: Task exception was never retrieved
Traceback (most recent call last):
  File "/config/custom_components/audiconnect/audi_account.py", line 162, in update
    if not await self.connection.update(None):
  File "/config/custom_components/audiconnect/audi_connect_account.py", line 105, in update
    vehicles_response = await self._audi_service.get_vehicle_information()
  File "/config/custom_components/audiconnect/audi_services.py", line 193, in get_vehicle_information
    data = await self._api.get(
  File "/config/custom_components/audiconnect/audi_api.py", line 72, in get
    r = await self.request(
  File "/config/custom_components/audiconnect/audi_api.py", line 55, in request
    raise ClientResponseError(
aiohttp.client_exceptions.ClientResponseError: 401, message='Unauthorized', url=URL('https://msg.audi.de/myaudi/vehicle-management/v2/vehicles')
2021-10-10 08:38:46 ERROR (MainThread) [homeassistant] Error doing job: Task exception was never retrieved
Traceback (most recent call last):
  File "/config/custom_components/audiconnect/audi_account.py", line 162, in update
    if not await self.connection.update(None):
  File "/config/custom_components/audiconnect/audi_connect_account.py", line 105, in update
    vehicles_response = await self._audi_service.get_vehicle_information()
  File "/config/custom_components/audiconnect/audi_services.py", line 193, in get_vehicle_information
    data = await self._api.get(
  File "/config/custom_components/audiconnect/audi_api.py", line 72, in get
    r = await self.request(
  File "/config/custom_components/audiconnect/audi_api.py", line 55, in request
    raise ClientResponseError(
aiohttp.client_exceptions.ClientResponseError: 401, message='Unauthorized', url=URL('https://msg.audi.de/myaudi/vehicle-management/v2/vehicles')
2021-10-10 08:41:24 ERROR (MainThread) [homeassistant.components.google_assistant.http] Request for https://homegraph.googleapis.com/v1/devices:reportStateAndNotification failed: 404
2021-10-10 08:43:38 WARNING (SyncWorker_20) [buienalarm.pybuienalarm] Error fetching data safely: HTTPSConnectionPool(host='cdn-secure.buienalarm.nl', port=443): Read timed out. (read timeout=10.0)
2021-10-10 08:45:51 ERROR (MainThread) [homeassistant.components.google_assistant.http] Request for https://homegraph.googleapis.com/v1/devices:reportStateAndNotification failed: 404
2021-10-10 08:48:14 ERROR (MainThread) [custom_components.googlewifi] Error fetching GoogleWifi data: Error connecting to GoogleWifi: 
2021-10-10 08:48:46 ERROR (MainThread) [homeassistant.components.google_assistant.http] Request for https://homegraph.googleapis.com/v1/devices:reportStateAndNotification failed: 404
2021-10-10 08:48:46 ERROR (MainThread) [homeassistant] Error doing job: Task exception was never retrieved
Traceback (most recent call last):
  File "/config/custom_components/audiconnect/audi_account.py", line 162, in update
    if not await self.connection.update(None):
  File "/config/custom_components/audiconnect/audi_connect_account.py", line 105, in update
    vehicles_response = await self._audi_service.get_vehicle_information()
  File "/config/custom_components/audiconnect/audi_services.py", line 193, in get_vehicle_information
    data = await self._api.get(
  File "/config/custom_components/audiconnect/audi_api.py", line 72, in get
    r = await self.request(
  File "/config/custom_components/audiconnect/audi_api.py", line 55, in request
    raise ClientResponseError(
aiohttp.client_exceptions.ClientResponseError: 401, message='Unauthorized', url=URL('https://msg.audi.de/myaudi/vehicle-management/v2/vehicles')
2021-10-10 08:49:17 ERROR (MainThread) [homeassistant.components.google_assistant.http] Request for https://homegraph.googleapis.com/v1/devices:reportStateAndNotification failed: 404
2021-10-10 08:51:24 ERROR (MainThread) [homeassistant.components.google_assistant.http] Request for https://homegraph.googleapis.com/v1/devices:reportStateAndNotification failed: 404
2021-10-10 08:52:12 ERROR (MainThread) [homeassistant.components.google_assistant.http] Request for https://homegraph.googleapis.com/v1/devices:reportStateAndNotification failed: 404
2021-10-10 08:53:45 ERROR (MainThread) [homeassistant.components.google_assistant.http] Request for https://homegraph.googleapis.com/v1/devices:reportStateAndNotification failed: 404
2021-10-10 08:58:46 ERROR (MainThread) [homeassistant] Error doing job: Task exception was never retrieved
Traceback (most recent call last):
  File "/config/custom_components/audiconnect/audi_account.py", line 162, in update
    if not await self.connection.update(None):
  File "/config/custom_components/audiconnect/audi_connect_account.py", line 105, in update
    vehicles_response = await self._audi_service.get_vehicle_information()
  File "/config/custom_components/audiconnect/audi_services.py", line 193, in get_vehicle_information
    data = await self._api.get(
  File "/config/custom_components/audiconnect/audi_api.py", line 72, in get
    r = await self.request(
  File "/config/custom_components/audiconnect/audi_api.py", line 55, in request
    raise ClientResponseError(
aiohttp.client_exceptions.ClientResponseError: 401, message='Unauthorized', url=URL('https://msg.audi.de/myaudi/vehicle-management/v2/vehicles')
2021-10-10 08:59:12 ERROR (MainThread) [custom_components.googlewifi] Error fetching GoogleWifi data: Error connecting to GoogleWifi: 
2021-10-10 09:08:47 ERROR (MainThread) [homeassistant] Error doing job: Task exception was never retrieved
Traceback (most recent call last):
  File "/config/custom_components/audiconnect/audi_account.py", line 162, in update
    if not await self.connection.update(None):
  File "/config/custom_components/audiconnect/audi_connect_account.py", line 105, in update
    vehicles_response = await self._audi_service.get_vehicle_information()
  File "/config/custom_components/audiconnect/audi_services.py", line 193, in get_vehicle_information
    data = await self._api.get(
  File "/config/custom_components/audiconnect/audi_api.py", line 72, in get
    r = await self.request(
  File "/config/custom_components/audiconnect/audi_api.py", line 55, in request
    raise ClientResponseError(
aiohttp.client_exceptions.ClientResponseError: 401, message='Unauthorized', url=URL('https://msg.audi.de/myaudi/vehicle-management/v2/vehicles')
2021-10-10 09:18:47 ERROR (MainThread) [homeassistant] Error doing job: Task exception was never retrieved
Traceback (most recent call last):
  File "/config/custom_components/audiconnect/audi_account.py", line 162, in update
    if not await self.connection.update(None):
  File "/config/custom_components/audiconnect/audi_connect_account.py", line 105, in update
    vehicles_response = await self._audi_service.get_vehicle_information()
  File "/config/custom_components/audiconnect/audi_services.py", line 193, in get_vehicle_information
    data = await self._api.get(
  File "/config/custom_components/audiconnect/audi_api.py", line 72, in get
    r = await self.request(
  File "/config/custom_components/audiconnect/audi_api.py", line 55, in request
    raise ClientResponseError(
aiohttp.client_exceptions.ClientResponseError: 401, message='Unauthorized', url=URL('https://msg.audi.de/myaudi/vehicle-management/v2/vehicles')
2021-10-10 09:24:24 WARNING (MainThread) [homeassistant.helpers.template] Template warning: 'float' got invalid input 'unknown' when rendering template '{{ states('sensor.gram_badkamer_diff_outside') | float >= 1 }}' but no default was specified. Currently 'float' will return '0', however this template will fail to render in Home Assistant core 2021.12
2021-10-10 09:24:24 WARNING (MainThread) [homeassistant.helpers.template] Template warning: 'float' got invalid input 'unknown' when rendering template '{{ states('sensor.gram_badkamer_diff_outside') | float >= 1 }}' but no default was specified. Currently 'float' will return '0', however this template will fail to render in Home Assistant core 2021.12
2021-10-10 09:28:47 ERROR (MainThread) [homeassistant] Error doing job: Task exception was never retrieved
Traceback (most recent call last):
  File "/config/custom_components/audiconnect/audi_account.py", line 162, in update
    if not await self.connection.update(None):
  File "/config/custom_components/audiconnect/audi_connect_account.py", line 105, in update
    vehicles_response = await self._audi_service.get_vehicle_information()
  File "/config/custom_components/audiconnect/audi_services.py", line 193, in get_vehicle_information
    data = await self._api.get(
  File "/config/custom_components/audiconnect/audi_api.py", line 72, in get
    r = await self.request(
  File "/config/custom_components/audiconnect/audi_api.py", line 55, in request
    raise ClientResponseError(
aiohttp.client_exceptions.ClientResponseError: 401, message='Unauthorized', url=URL('https://msg.audi.de/myaudi/vehicle-management/v2/vehicles')
2021-10-10 09:32:24 WARNING (MainThread) [homeassistant.helpers.template] Template warning: 'float' got invalid input 'unknown' when rendering template '{{ states('sensor.gram_badkamer_diff_outside') | float >= 1 }}' but no default was specified. Currently 'float' will return '0', however this template will fail to render in Home Assistant core 2021.12
2021-10-10 09:32:24 WARNING (MainThread) [homeassistant.helpers.template] Template warning: 'float' got invalid input 'unknown' when rendering template '{{ states('sensor.gram_badkamer_diff_outside') | float >= 1 }}' but no default was specified. Currently 'float' will return '0', however this template will fail to render in Home Assistant core 2021.12
2021-10-10 09:32:24 WARNING (MainThread) [homeassistant.helpers.template] Template warning: 'float' got invalid input 'unknown' when rendering template '{{ states('sensor.gram_badkamer_diff_outside') | float >= 1 }}' but no default was specified. Currently 'float' will return '0', however this template will fail to render in Home Assistant core 2021.12
2021-10-10 09:33:16 WARNING (MainThread) [homeassistant.helpers.template] Template warning: 'float' got invalid input 'unknown' when rendering template '{{ states('sensor.gram_badkamer_diff_outside') | float >= 1 }}' but no default was specified. Currently 'float' will return '0', however this template will fail to render in Home Assistant core 2021.12
2021-10-10 09:36:24 WARNING (MainThread) [homeassistant.helpers.template] Template warning: 'float' got invalid input 'unknown' when rendering template '{{ states('sensor.gram_badkamer_diff_outside') | float >= 1 }}' but no default was specified. Currently 'float' will return '0', however this template will fail to render in Home Assistant core 2021.12
2021-10-10 09:36:24 WARNING (MainThread) [homeassistant.helpers.template] Template warning: 'float' got invalid input 'unknown' when rendering template '{{ states('sensor.gram_badkamer_diff_outside') | float >= 1 }}' but no default was specified. Currently 'float' will return '0', however this template will fail to render in Home Assistant core 2021.12
2021-10-10 09:36:24 WARNING (MainThread) [homeassistant.helpers.template] Template warning: 'float' got invalid input 'unknown' when rendering template '{{ states('sensor.gram_badkamer_diff_outside') | float >= 1 }}' but no default was specified. Currently 'float' will return '0', however this template will fail to render in Home Assistant core 2021.12
2021-10-10 09:38:48 ERROR (MainThread) [homeassistant] Error doing job: Task exception was never retrieved
Traceback (most recent call last):
  File "/config/custom_components/audiconnect/audi_account.py", line 162, in update
    if not await self.connection.update(None):
  File "/config/custom_components/audiconnect/audi_connect_account.py", line 105, in update
    vehicles_response = await self._audi_service.get_vehicle_information()
  File "/config/custom_components/audiconnect/audi_services.py", line 193, in get_vehicle_information
    data = await self._api.get(
  File "/config/custom_components/audiconnect/audi_api.py", line 72, in get
    r = await self.request(
  File "/config/custom_components/audiconnect/audi_api.py", line 55, in request
    raise ClientResponseError(
aiohttp.client_exceptions.ClientResponseError: 401, message='Unauthorized', url=URL('https://msg.audi.de/myaudi/vehicle-management/v2/vehicles')
2021-10-10 09:43:16 WARNING (MainThread) [homeassistant.helpers.template] Template warning: 'float' got invalid input 'unknown' when rendering template '{{ states('sensor.gram_badkamer_diff_outside') | float >= 1 }}' but no default was specified. Currently 'float' will return '0', however this template will fail to render in Home Assistant core 2021.12
2021-10-10 09:44:24 WARNING (MainThread) [homeassistant.helpers.template] Template warning: 'float' got invalid input 'unknown' when rendering template '{{ states('sensor.gram_badkamer_diff_outside') | float >= 1 }}' but no default was specified. Currently 'float' will return '0', however this template will fail to render in Home Assistant core 2021.12
2021-10-10 09:44:24 WARNING (MainThread) [homeassistant.helpers.template] Template warning: 'float' got invalid input 'unknown' when rendering template '{{ states('sensor.gram_badkamer_diff_outside') | float >= 1 }}' but no default was specified. Currently 'float' will return '0', however this template will fail to render in Home Assistant core 2021.12
2021-10-10 09:44:24 WARNING (MainThread) [homeassistant.helpers.template] Template warning: 'float' got invalid input 'unknown' when rendering template '{{ states('sensor.gram_badkamer_diff_outside') | float >= 1 }}' but no default was specified. Currently 'float' will return '0', however this template will fail to render in Home Assistant core 2021.12
2021-10-10 09:48:24 WARNING (MainThread) [homeassistant.helpers.template] Template warning: 'float' got invalid input 'unknown' when rendering template '{{ states('sensor.gram_badkamer_diff_outside') | float >= 1 }}' but no default was specified. Currently 'float' will return '0', however this template will fail to render in Home Assistant core 2021.12
2021-10-10 09:48:24 WARNING (MainThread) [homeassistant.helpers.template] Template warning: 'float' got invalid input 'unknown' when rendering template '{{ states('sensor.gram_badkamer_diff_outside') | float >= 1 }}' but no default was specified. Currently 'float' will return '0', however this template will fail to render in Home Assistant core 2021.12
2021-10-10 09:48:24 WARNING (MainThread) [homeassistant.helpers.template] Template warning: 'float' got invalid input 'unknown' when rendering template '{{ states('sensor.gram_badkamer_diff_outside') | float >= 1 }}' but no default was specified. Currently 'float' will return '0', however this template will fail to render in Home Assistant core 2021.12
2021-10-10 09:48:48 ERROR (MainThread) [homeassistant] Error doing job: Task exception was never retrieved
Traceback (most recent call last):
  File "/config/custom_components/audiconnect/audi_account.py", line 162, in update
    if not await self.connection.update(None):
  File "/config/custom_components/audiconnect/audi_connect_account.py", line 105, in update
    vehicles_response = await self._audi_service.get_vehicle_information()
  File "/config/custom_components/audiconnect/audi_services.py", line 193, in get_vehicle_information
    data = await self._api.get(
  File "/config/custom_components/audiconnect/audi_api.py", line 72, in get
    r = await self.request(
  File "/config/custom_components/audiconnect/audi_api.py", line 55, in request
    raise ClientResponseError(
aiohttp.client_exceptions.ClientResponseError: 401, message='Unauthorized', url=URL('https://msg.audi.de/myaudi/vehicle-management/v2/vehicles')
2021-10-10 09:58:48 ERROR (MainThread) [homeassistant] Error doing job: Task exception was never retrieved
Traceback (most recent call last):
  File "/config/custom_components/audiconnect/audi_account.py", line 162, in update
    if not await self.connection.update(None):
  File "/config/custom_components/audiconnect/audi_connect_account.py", line 105, in update
    vehicles_response = await self._audi_service.get_vehicle_information()
  File "/config/custom_components/audiconnect/audi_services.py", line 193, in get_vehicle_information
    data = await self._api.get(
  File "/config/custom_components/audiconnect/audi_api.py", line 72, in get
    r = await self.request(
  File "/config/custom_components/audiconnect/audi_api.py", line 55, in request
    raise ClientResponseError(
aiohttp.client_exceptions.ClientResponseError: 401, message='Unauthorized', url=URL('https://msg.audi.de/myaudi/vehicle-management/v2/vehicles')
2021-10-10 10:08:49 ERROR (MainThread) [homeassistant] Error doing job: Task exception was never retrieved
Traceback (most recent call last):
  File "/config/custom_components/audiconnect/audi_account.py", line 162, in update
    if not await self.connection.update(None):
  File "/config/custom_components/audiconnect/audi_connect_account.py", line 105, in update
    vehicles_response = await self._audi_service.get_vehicle_information()
  File "/config/custom_components/audiconnect/audi_services.py", line 193, in get_vehicle_information
    data = await self._api.get(
  File "/config/custom_components/audiconnect/audi_api.py", line 72, in get
    r = await self.request(
  File "/config/custom_components/audiconnect/audi_api.py", line 55, in request
    raise ClientResponseError(
aiohttp.client_exceptions.ClientResponseError: 401, message='Unauthorized', url=URL('https://msg.audi.de/myaudi/vehicle-management/v2/vehicles')
2021-10-10 10:17:06 WARNING (MainThread) [homeassistant.helpers.service] Unable to find referenced entities media_player.veranda_speaker_2
2021-10-10 10:17:16 WARNING (MainThread) [homeassistant.helpers.service] Unable to find referenced entities camera.netatmo_eikenbos_oprit
2021-10-10 10:18:49 ERROR (MainThread) [homeassistant] Error doing job: Task exception was never retrieved
Traceback (most recent call last):
  File "/config/custom_components/audiconnect/audi_account.py", line 162, in update
    if not await self.connection.update(None):
  File "/config/custom_components/audiconnect/audi_connect_account.py", line 105, in update
    vehicles_response = await self._audi_service.get_vehicle_information()
  File "/config/custom_components/audiconnect/audi_services.py", line 193, in get_vehicle_information
    data = await self._api.get(
  File "/config/custom_components/audiconnect/audi_api.py", line 72, in get
    r = await self.request(
  File "/config/custom_components/audiconnect/audi_api.py", line 55, in request
    raise ClientResponseError(
aiohttp.client_exceptions.ClientResponseError: 401, message='Unauthorized', url=URL('https://msg.audi.de/myaudi/vehicle-management/v2/vehicles')
2021-10-10 10:28:20 WARNING (Thread-94) [pychromecast.socket_client] [Living speaker(192.168.86.244):8009] Heartbeat timeout, resetting connection
2021-10-10 10:28:20 WARNING (Thread-16) [pychromecast.socket_client] [Groep_living_veranda(192.168.86.244):32106] Heartbeat timeout, resetting connection
2021-10-10 10:28:49 ERROR (MainThread) [homeassistant] Error doing job: Task exception was never retrieved
Traceback (most recent call last):
  File "/config/custom_components/audiconnect/audi_account.py", line 162, in update
    if not await self.connection.update(None):
  File "/config/custom_components/audiconnect/audi_connect_account.py", line 105, in update
    vehicles_response = await self._audi_service.get_vehicle_information()
  File "/config/custom_components/audiconnect/audi_services.py", line 193, in get_vehicle_information
    data = await self._api.get(
  File "/config/custom_components/audiconnect/audi_api.py", line 72, in get
    r = await self.request(
  File "/config/custom_components/audiconnect/audi_api.py", line 55, in request
    raise ClientResponseError(
aiohttp.client_exceptions.ClientResponseError: 401, message='Unauthorized', url=URL('https://msg.audi.de/myaudi/vehicle-management/v2/vehicles')
2021-10-10 10:28:50 ERROR (Thread-16) [pychromecast.socket_client] [Groep_living_veranda(192.168.86.244):32106] Failed to connect to service ServiceInfo(type='mdns', data='google-cast-group-90490c41565e4b21af61a4ecedd76c58._googlecast._tcp.local.'), retrying in 5.0s
2021-10-10 10:28:50 ERROR (Thread-94) [pychromecast.socket_client] [Living speaker(192.168.86.244):8009] Failed to connect to service ServiceInfo(type='mdns', data='google-nest-hub-f462ed96d0e5940e88b752d709fcc230._googlecast._tcp.local.'), retrying in 5.0s
2021-10-10 10:38:50 ERROR (MainThread) [homeassistant] Error doing job: Task exception was never retrieved
Traceback (most recent call last):
  File "/config/custom_components/audiconnect/audi_account.py", line 162, in update
    if not await self.connection.update(None):
  File "/config/custom_components/audiconnect/audi_connect_account.py", line 105, in update
    vehicles_response = await self._audi_service.get_vehicle_information()
  File "/config/custom_components/audiconnect/audi_services.py", line 193, in get_vehicle_information
    data = await self._api.get(
  File "/config/custom_components/audiconnect/audi_api.py", line 72, in get
    r = await self.request(
  File "/config/custom_components/audiconnect/audi_api.py", line 55, in request
    raise ClientResponseError(
aiohttp.client_exceptions.ClientResponseError: 401, message='Unauthorized', url=URL('https://msg.audi.de/myaudi/vehicle-management/v2/vehicles')
2021-10-10 10:48:24 ERROR (SyncWorker_31) [glocaltokens.client] [Device - Nest Wifi router(id=2f2a9d15-0ae2-4ffe-b6c1-2ef24c742b8a)] local_auth_token must follow the correct format
2021-10-10 10:48:24 ERROR (SyncWorker_31) [glocaltokens.client] [Device - Nest Wifi router(id=e1e5a8d5-d21f-444d-95a9-c76d78c9bc79)] local_auth_token must follow the correct format
2021-10-10 10:48:24 ERROR (SyncWorker_31) [glocaltokens.client] [Device - Nest Wifi router(id=ea3de37c-ca74-4689-8171-1681b2f4f924)] local_auth_token must follow the correct format
2021-10-10 10:48:50 ERROR (MainThread) [homeassistant] Error doing job: Task exception was never retrieved
Traceback (most recent call last):
  File "/config/custom_components/audiconnect/audi_account.py", line 162, in update
    if not await self.connection.update(None):
  File "/config/custom_components/audiconnect/audi_connect_account.py", line 105, in update
    vehicles_response = await self._audi_service.get_vehicle_information()
  File "/config/custom_components/audiconnect/audi_services.py", line 193, in get_vehicle_information
    data = await self._api.get(
  File "/config/custom_components/audiconnect/audi_api.py", line 72, in get
    r = await self.request(
  File "/config/custom_components/audiconnect/audi_api.py", line 55, in request
    raise ClientResponseError(
aiohttp.client_exceptions.ClientResponseError: 401, message='Unauthorized', url=URL('https://msg.audi.de/myaudi/vehicle-management/v2/vehicles')
2021-10-10 10:55:45 ERROR (SyncWorker_30) [homeassistant.util.yaml.loader] mapping values are not allowed here
  in "/config/packages/rain.yaml", line 16, column 12
2021-10-10 10:58:48 WARNING (SyncWorker_15) [buienalarm.pybuienalarm] Error fetching data safely: HTTPSConnectionPool(host='cdn-secure.buienalarm.nl', port=443): Read timed out. (read timeout=10.0)
2021-10-10 10:58:50 ERROR (MainThread) [homeassistant] Error doing job: Task exception was never retrieved
Traceback (most recent call last):
  File "/config/custom_components/audiconnect/audi_account.py", line 162, in update
    if not await self.connection.update(None):
  File "/config/custom_components/audiconnect/audi_connect_account.py", line 105, in update
    vehicles_response = await self._audi_service.get_vehicle_information()
  File "/config/custom_components/audiconnect/audi_services.py", line 193, in get_vehicle_information
    data = await self._api.get(
  File "/config/custom_components/audiconnect/audi_api.py", line 72, in get
    r = await self.request(
  File "/config/custom_components/audiconnect/audi_api.py", line 55, in request
    raise ClientResponseError(
aiohttp.client_exceptions.ClientResponseError: 401, message='Unauthorized', url=URL('https://msg.audi.de/myaudi/vehicle-management/v2/vehicles')
2021-10-10 11:02:06 ERROR (MainThread) [homeassistant.config] Invalid config for [automation]: required key not provided @ data['action'][4]['domain']. Got None. (See ?, line ?). 
2021-10-10 11:02:06 ERROR (MainThread) [homeassistant.config] Invalid config for [automation]: [title] is an invalid option for [automation]. Check: automation->action->1->title. (See ?, line ?). 
2021-10-10 11:02:06 ERROR (MainThread) [homeassistant.config] Invalid config for [automation]: must be a value between 0 and 59 for dictionary value @ data['minutes']. Got None. (See ?, line ?). 
2021-10-10 11:02:06 ERROR (MainThread) [homeassistant.config] Invalid config for [automation]: must be a value between 0 and 59 for dictionary value @ data['minutes']. Got None. (See ?, line ?). 
2021-10-10 11:02:14 ERROR (MainThread) [homeassistant.config] Invalid config for [automation]: required key not provided @ data['action'][4]['domain']. Got None. (See ?, line ?). 
2021-10-10 11:02:14 ERROR (MainThread) [homeassistant.config] Invalid config for [automation]: [title] is an invalid option for [automation]. Check: automation->action->1->title. (See ?, line ?). 
2021-10-10 11:02:14 ERROR (MainThread) [homeassistant.config] Invalid config for [automation]: must be a value between 0 and 59 for dictionary value @ data['minutes']. Got None. (See ?, line ?). 
2021-10-10 11:02:14 ERROR (MainThread) [homeassistant.config] Invalid config for [automation]: must be a value between 0 and 59 for dictionary value @ data['minutes']. Got None. (See ?, line ?). 
