2021-08-31 16:50:46 WARNING (SyncWorker_0) [homeassistant.util.yaml.loader] YAML file /config/packages/uv_index.yaml contains duplicate key "channel". Check lines 90 and 91
2021-08-31 16:50:46 WARNING (SyncWorker_0) [homeassistant.loader] We found a custom integration xiaomi_miio_airpurifier which has not been tested by Home Assistant. This component might cause stability problems, be sure to disable it if you experience issues with Home Assistant
2021-08-31 16:50:46 WARNING (SyncWorker_1) [homeassistant.loader] We found a custom integration average which has not been tested by Home Assistant. This component might cause stability problems, be sure to disable it if you experience issues with Home Assistant
2021-08-31 16:50:46 WARNING (SyncWorker_1) [homeassistant.loader] We found a custom integration powercalc which has not been tested by Home Assistant. This component might cause stability problems, be sure to disable it if you experience issues with Home Assistant
2021-08-31 16:50:46 WARNING (SyncWorker_1) [homeassistant.loader] We found a custom integration monitor_docker which has not been tested by Home Assistant. This component might cause stability problems, be sure to disable it if you experience issues with Home Assistant
2021-08-31 16:50:46 WARNING (SyncWorker_1) [homeassistant.loader] We found a custom integration hacs which has not been tested by Home Assistant. This component might cause stability problems, be sure to disable it if you experience issues with Home Assistant
2021-08-31 16:50:46 WARNING (SyncWorker_1) [homeassistant.loader] We found a custom integration localtuya which has not been tested by Home Assistant. This component might cause stability problems, be sure to disable it if you experience issues with Home Assistant
2021-08-31 16:50:46 WARNING (SyncWorker_2) [homeassistant.loader] We found a custom integration audiconnect which has not been tested by Home Assistant. This component might cause stability problems, be sure to disable it if you experience issues with Home Assistant
2021-08-31 16:50:46 WARNING (SyncWorker_0) [homeassistant.loader] We found a custom integration tuya_v2 which has not been tested by Home Assistant. This component might cause stability problems, be sure to disable it if you experience issues with Home Assistant
2021-08-31 16:50:46 WARNING (SyncWorker_1) [homeassistant.loader] We found a custom integration shelly which has not been tested by Home Assistant. This component might cause stability problems, be sure to disable it if you experience issues with Home Assistant
2021-08-31 16:50:46 WARNING (SyncWorker_3) [homeassistant.loader] We found a custom integration xiaomi_miio_fan which has not been tested by Home Assistant. This component might cause stability problems, be sure to disable it if you experience issues with Home Assistant
2021-08-31 16:50:46 WARNING (SyncWorker_0) [homeassistant.loader] We found a custom integration huesyncbox which has not been tested by Home Assistant. This component might cause stability problems, be sure to disable it if you experience issues with Home Assistant
2021-08-31 16:50:46 WARNING (SyncWorker_2) [homeassistant.loader] We found a custom integration buienalarm which has not been tested by Home Assistant. This component might cause stability problems, be sure to disable it if you experience issues with Home Assistant
2021-08-31 16:50:46 WARNING (SyncWorker_4) [homeassistant.loader] We found a custom integration xiaomi_miot which has not been tested by Home Assistant. This component might cause stability problems, be sure to disable it if you experience issues with Home Assistant
2021-08-31 16:50:46 WARNING (SyncWorker_5) [homeassistant.loader] We found a custom integration anniversaries which has not been tested by Home Assistant. This component might cause stability problems, be sure to disable it if you experience issues with Home Assistant
2021-08-31 16:50:46 WARNING (SyncWorker_6) [homeassistant.loader] We found a custom integration googlewifi which has not been tested by Home Assistant. This component might cause stability problems, be sure to disable it if you experience issues with Home Assistant
2021-08-31 16:50:46 WARNING (SyncWorker_1) [homeassistant.loader] We found a custom integration ytube_music_player which has not been tested by Home Assistant. This component might cause stability problems, be sure to disable it if you experience issues with Home Assistant
2021-08-31 16:50:46 WARNING (SyncWorker_7) [homeassistant.loader] We found a custom integration deepstack_face which has not been tested by Home Assistant. This component might cause stability problems, be sure to disable it if you experience issues with Home Assistant
2021-08-31 16:50:46 WARNING (SyncWorker_3) [homeassistant.loader] We found a custom integration google_home which has not been tested by Home Assistant. This component might cause stability problems, be sure to disable it if you experience issues with Home Assistant
2021-08-31 16:50:46 WARNING (SyncWorker_8) [homeassistant.loader] We found a custom integration afvalbeheer which has not been tested by Home Assistant. This component might cause stability problems, be sure to disable it if you experience issues with Home Assistant
2021-08-31 16:50:52 ERROR (MainThread) [homeassistant.config] Invalid config for [automation]: [title] is an invalid option for [automation]. Check: automation->action->1->title. (See ?, line ?). 
2021-08-31 16:50:52 ERROR (MainThread) [homeassistant.config] Invalid config for [automation]: invalid template (TemplateSyntaxError: expected token ',', got 'sensor') for dictionary value @ data['action'][0]['data']. Got None. (See ?, line ?). 
2021-08-31 16:50:52 ERROR (MainThread) [homeassistant.config] Invalid config for [automation]: invalid template (TemplateSyntaxError: expected token ',', got 'sensor') for dictionary value @ data['action'][0]['data']. Got None. (See ?, line ?). 
2021-08-31 16:50:52 ERROR (MainThread) [homeassistant.config] Invalid config for [automation]: invalid template (TemplateSyntaxError: expected token ',', got 'sensor') for dictionary value @ data['action'][0]['data']. Got None. (See ?, line ?). 
2021-08-31 16:50:52 ERROR (MainThread) [homeassistant.config] Invalid config for [automation]: required key not provided @ data['action'][4]['domain']. Got None. (See ?, line ?). 
2021-08-31 16:51:29 WARNING (MainThread) [homeassistant.components.webhook] Received message for unregistered webhook 8b8f82ade2e454d538c7b1b55e021814b7aa12b9fa3693773bc28dc044af0487 from 192.168.86.34
2021-08-31 16:51:38 WARNING (MainThread) [homeassistant.components.webhook] Received message for unregistered webhook 8b8f82ade2e454d538c7b1b55e021814b7aa12b9fa3693773bc28dc044af0487 from 192.168.86.34
2021-08-31 16:51:42 WARNING (MainThread) [homeassistant.components.webhook] Received message for unregistered webhook 8b8f82ade2e454d538c7b1b55e021814b7aa12b9fa3693773bc28dc044af0487 from 192.168.86.34
2021-08-31 16:51:43 WARNING (MainThread) [homeassistant.components.webhook] Received message for unregistered webhook 8b8f82ade2e454d538c7b1b55e021814b7aa12b9fa3693773bc28dc044af0487 from 192.168.86.34
2021-08-31 16:51:45 WARNING (MainThread) [homeassistant.components.webhook] Received message for unregistered webhook 8b8f82ade2e454d538c7b1b55e021814b7aa12b9fa3693773bc28dc044af0487 from 192.168.86.34
2021-08-31 16:51:50 WARNING (MainThread) [homeassistant.components.webhook] Received message for unregistered webhook 8b8f82ade2e454d538c7b1b55e021814b7aa12b9fa3693773bc28dc044af0487 from 192.168.86.34
2021-08-31 16:51:58 WARNING (MainThread) [homeassistant.components.webhook] Received message for unregistered webhook 8b8f82ade2e454d538c7b1b55e021814b7aa12b9fa3693773bc28dc044af0487 from 192.168.86.34
2021-08-31 16:52:00 WARNING (MainThread) [homeassistant.components.webhook] Received message for unregistered webhook 8b8f82ade2e454d538c7b1b55e021814b7aa12b9fa3693773bc28dc044af0487 from 192.168.86.34
2021-08-31 16:52:01 WARNING (MainThread) [homeassistant.bootstrap] Waiting on integrations to complete setup: tuya_v2, pi_hole
2021-08-31 16:52:35 WARNING (MainThread) [homeassistant.components.webhook] Received message for unregistered webhook 8b8f82ade2e454d538c7b1b55e021814b7aa12b9fa3693773bc28dc044af0487 from 192.168.86.34
2021-08-31 16:52:37 WARNING (MainThread) [homeassistant.components.webhook] Received message for unregistered webhook 8b8f82ade2e454d538c7b1b55e021814b7aa12b9fa3693773bc28dc044af0487 from 192.168.86.34
2021-08-31 16:52:44 WARNING (MainThread) [homeassistant.components.webhook] Received message for unregistered webhook 80adf825ef6b969ee3c95fc54091652f8a80fe790532f31c6bff63908742af08 from 192.168.86.26
2021-08-31 16:52:59 WARNING (MainThread) [homeassistant.components.webhook] Received message for unregistered webhook 8b8f82ade2e454d538c7b1b55e021814b7aa12b9fa3693773bc28dc044af0487 from 192.168.86.34
2021-08-31 16:53:02 WARNING (MainThread) [homeassistant.components.webhook] Received message for unregistered webhook 8b8f82ade2e454d538c7b1b55e021814b7aa12b9fa3693773bc28dc044af0487 from 192.168.86.34
2021-08-31 16:53:02 WARNING (MainThread) [homeassistant.components.webhook] Received message for unregistered webhook 8b8f82ade2e454d538c7b1b55e021814b7aa12b9fa3693773bc28dc044af0487 from 192.168.86.34
2021-08-31 16:53:18 WARNING (MainThread) [homeassistant.components.webhook] Received message for unregistered webhook 8b8f82ade2e454d538c7b1b55e021814b7aa12b9fa3693773bc28dc044af0487 from 192.168.86.34
2021-08-31 16:53:42 WARNING (MainThread) [homeassistant.bootstrap] Waiting on integrations to complete setup: hacs, buienradar, utility_meter
2021-08-31 16:54:41 WARNING (MainThread) [homeassistant.components.webhook] Received message for unregistered webhook 8b8f82ade2e454d538c7b1b55e021814b7aa12b9fa3693773bc28dc044af0487 from 192.168.86.34
2021-08-31 16:54:53 WARNING (MainThread) [homeassistant.components.buienradar.util] Unable to retrieve rain data from Buienradar(Msg: , status: None)
2021-08-31 16:54:59 WARNING (MainThread) [homeassistant.components.webhook] Received message for unregistered webhook 8b8f82ade2e454d538c7b1b55e021814b7aa12b9fa3693773bc28dc044af0487 from 192.168.86.34
2021-08-31 16:55:31 WARNING (MainThread) [homeassistant.bootstrap] Waiting on integrations to complete setup: nfandroidtv, anniversaries, ytube_music_player
2021-08-31 16:55:37 WARNING (MainThread) [homeassistant.config_entries] Config entry '192.168.86.83' for synology_dsm integration not ready yet: {'api': None, 'code': -1, 'reason': 'Unknown', 'details': 'ConnectionError = <urllib3.connection.HTTPSConnection object at 0xffff718d17c0>: Failed to establish a new connection: [Errno 113] Host is unreachable'}; Retrying in background
2021-08-31 16:55:37 WARNING (MainThread) [homeassistant.components.fan] Platform xiaomi_miio_fan not ready yet: Unable to discover the device 192.168.86.28; Retrying in background in 30 seconds
2021-08-31 16:55:37 WARNING (MainThread) [homeassistant.components.fan] Platform xiaomi_miio_fan not ready yet: Unable to discover the device 192.168.86.29; Retrying in background in 30 seconds
2021-08-31 16:55:38 WARNING (MainThread) [homeassistant.components.light] Platform netatmo not ready yet: None; Retrying in background in 30 seconds
2021-08-31 16:55:38 WARNING (MainThread) [homeassistant.components.select] Platform netatmo not ready yet: None; Retrying in background in 30 seconds
2021-08-31 16:55:39 WARNING (MainThread) [homeassistant.components.hue.light] Please check for software updates of the douche bulb in the Philips Hue App.
2021-08-31 16:55:39 WARNING (MainThread) [homeassistant.components.hue.light] Please check for software updates of the wasbak rechts bulb in the Philips Hue App.
2021-08-31 16:55:39 WARNING (MainThread) [homeassistant.components.hue.light] Please check for software updates of the bad bulb in the Philips Hue App.
2021-08-31 16:55:48 WARNING (MainThread) [homeassistant.setup] Setup of default_config is taking over 10 seconds.
2021-08-31 16:56:36 WARNING (MainThread) [homeassistant.bootstrap] Waiting on integrations to complete setup: default_config
2021-08-31 16:57:00 ERROR (SyncWorker_3) [glocaltokens.client] [Device - Nest Wifi router(id=2f2a9d15-0ae2-4ffe-b6c1-2ef24c742b8a)] local_auth_token must follow the correct format
2021-08-31 16:57:00 ERROR (SyncWorker_3) [glocaltokens.client] [Device - Nest Wifi router(id=e1e5a8d5-d21f-444d-95a9-c76d78c9bc79)] local_auth_token must follow the correct format
2021-08-31 16:57:00 ERROR (SyncWorker_3) [glocaltokens.client] [Device - Nest Wifi router(id=ea3de37c-ca74-4689-8171-1681b2f4f924)] local_auth_token must follow the correct format
2021-08-31 16:57:05 WARNING (MainThread) [homeassistant.config_entries] Config entry 'OnHub' for upnp integration not ready yet; Retrying in background
2021-08-31 16:57:30 ERROR (MainThread) [custom_components.powercalc.sensor] Skipping sensor setup light.amilya: Cannot select a mode (LINEAR, FIXED or LUT), supply it in the config
2021-08-31 16:57:30 ERROR (MainThread) [custom_components.powercalc.model_discovery] Cannot autodiscover model for 'light.badkamer', not found in the hue bridge api
2021-08-31 16:57:30 ERROR (MainThread) [custom_components.powercalc.sensor] Skipping sensor setup light.badkamer: Cannot select a mode (LINEAR, FIXED or LUT), supply it in the config
2021-08-31 16:57:30 ERROR (MainThread) [custom_components.powercalc.model_discovery] Cannot autodiscover model for 'light.buiten', not found in the hue bridge api
2021-08-31 16:57:30 ERROR (MainThread) [custom_components.powercalc.sensor] Skipping sensor setup light.buiten: Cannot select a mode (LINEAR, FIXED or LUT), supply it in the config
2021-08-31 16:57:30 ERROR (MainThread) [homeassistant.components.sensor] Error while setting up powercalc platform for sensor
Traceback (most recent call last):
  File "/usr/src/homeassistant/homeassistant/helpers/entity_platform.py", line 249, in _async_setup_platform
    await asyncio.shield(task)
  File "/config/custom_components/powercalc/sensor.py", line 174, in async_setup_platform
    power_sensor = await create_power_sensor(
  File "/config/custom_components/powercalc/sensor.py", line 235, in create_power_sensor
    await calculation_strategy.validate_config(source_entity)
  File "/config/custom_components/powercalc/strategy_lut.py", line 165, in validate_config
    supported_color_modes = source_entity.capabilities[
TypeError: list indices must be integers or slices, not str
2021-08-31 16:57:30 ERROR (MainThread) [homeassistant.components.sensor] Error while setting up powercalc platform for sensor
Traceback (most recent call last):
  File "/usr/src/homeassistant/homeassistant/helpers/entity_platform.py", line 249, in _async_setup_platform
    await asyncio.shield(task)
  File "/config/custom_components/powercalc/sensor.py", line 174, in async_setup_platform
    power_sensor = await create_power_sensor(
  File "/config/custom_components/powercalc/sensor.py", line 238, in create_power_sensor
    raise err
  File "/config/custom_components/powercalc/sensor.py", line 231, in create_power_sensor
    mode = select_calculation_mode(sensor_config, light_model)
  File "/config/custom_components/powercalc/sensor.py", line 333, in select_calculation_mode
    raise UnsupportedMode(
custom_components.powercalc.errors.UnsupportedMode: Cannot select a mode (LINEAR, FIXED or LUT), supply it in the config
2021-08-31 16:57:30 ERROR (MainThread) [homeassistant.components.sensor] Error while setting up powercalc platform for sensor
Traceback (most recent call last):
  File "/usr/src/homeassistant/homeassistant/helpers/entity_platform.py", line 249, in _async_setup_platform
    await asyncio.shield(task)
  File "/config/custom_components/powercalc/sensor.py", line 174, in async_setup_platform
    power_sensor = await create_power_sensor(
  File "/config/custom_components/powercalc/sensor.py", line 238, in create_power_sensor
    raise err
  File "/config/custom_components/powercalc/sensor.py", line 231, in create_power_sensor
    mode = select_calculation_mode(sensor_config, light_model)
  File "/config/custom_components/powercalc/sensor.py", line 333, in select_calculation_mode
    raise UnsupportedMode(
custom_components.powercalc.errors.UnsupportedMode: Cannot select a mode (LINEAR, FIXED or LUT), supply it in the config
2021-08-31 16:57:30 ERROR (MainThread) [homeassistant.components.sensor] Error while setting up powercalc platform for sensor
Traceback (most recent call last):
  File "/usr/src/homeassistant/homeassistant/helpers/entity_platform.py", line 249, in _async_setup_platform
    await asyncio.shield(task)
  File "/config/custom_components/powercalc/sensor.py", line 174, in async_setup_platform
    power_sensor = await create_power_sensor(
  File "/config/custom_components/powercalc/sensor.py", line 238, in create_power_sensor
    raise err
  File "/config/custom_components/powercalc/sensor.py", line 231, in create_power_sensor
    mode = select_calculation_mode(sensor_config, light_model)
  File "/config/custom_components/powercalc/sensor.py", line 333, in select_calculation_mode
    raise UnsupportedMode(
custom_components.powercalc.errors.UnsupportedMode: Cannot select a mode (LINEAR, FIXED or LUT), supply it in the config
2021-08-31 16:57:31 WARNING (SyncWorker_7) [buienalarm.pybuienalarm] Error fetching data safely: 502 Server Error: Bad Gateway for url: https://cdn-secure.buienalarm.nl/api/3.4/forecast.php?lat=50.878800118427755&lon=4.749415398691782&region=nl&unit=mm%2Fu
2021-08-31 16:57:31 WARNING (MainThread) [homeassistant.components.sensor] Platform netatmo not ready yet: None; Retrying in background in 30 seconds
2021-08-31 16:57:47 ERROR (MainThread) [homeassistant.components.google_assistant.http] Request for https://homegraph.googleapis.com/v1/devices:requestSync failed: 403
2021-08-31 17:03:15 ERROR (MainThread) [custom_components.googlewifi] Unexpected error fetching GoogleWifi data: 'NoneType' object is not iterable
Traceback (most recent call last):
  File "/usr/src/homeassistant/homeassistant/helpers/update_coordinator.py", line 187, in _async_refresh
    self.data = await self._async_update_data()
  File "/config/custom_components/googlewifi/__init__.py", line 171, in _async_update_data
    system_data = await self.api.get_systems()
  File "/usr/local/lib/python3.9/site-packages/googlewifi/__init__.py", line 191, in get_systems
    return await self.structure_systems(response)
  File "/usr/local/lib/python3.9/site-packages/googlewifi/__init__.py", line 289, in structure_systems
    for this_station in system_metrics.get("stationMetrics"):
TypeError: 'NoneType' object is not iterable
2021-08-31 17:05:43 ERROR (MainThread) [homeassistant.components.google_assistant.http] Request for https://homegraph.googleapis.com/v1/devices:reportStateAndNotification failed: 404
2021-08-31 17:24:59 ERROR (MainThread) [homeassistant.components.google_assistant.http] Request for https://homegraph.googleapis.com/v1/devices:reportStateAndNotification failed: 404
2021-08-31 17:26:51 ERROR (MainThread) [homeassistant.components.google_assistant.http] Request for https://homegraph.googleapis.com/v1/devices:reportStateAndNotification failed: 404
2021-08-31 17:27:48 WARNING (MainThread) [homeassistant.helpers.entity] Update of sensor.humidity_leuven24_wunderground is taking over 10 seconds
2021-08-31 17:27:48 ERROR (MainThread) [homeassistant.components.rest.data] Error fetching data: https://www.wunderground.com/dashboard/pws/ILEUVE24 failed with 
2021-08-31 17:27:48 ERROR (MainThread) [homeassistant.components.scrape.sensor] Unable to retrieve data for humidity_leuven24_wunderground
2021-08-31 17:29:54 ERROR (MainThread) [custom_components.googlewifi] Unexpected error fetching GoogleWifi data: 'traffic'
Traceback (most recent call last):
  File "/usr/src/homeassistant/homeassistant/helpers/update_coordinator.py", line 187, in _async_refresh
    self.data = await self._async_update_data()
  File "/config/custom_components/googlewifi/__init__.py", line 171, in _async_update_data
    system_data = await self.api.get_systems()
  File "/usr/local/lib/python3.9/site-packages/googlewifi/__init__.py", line 191, in get_systems
    return await self.structure_systems(response)
  File "/usr/local/lib/python3.9/site-packages/googlewifi/__init__.py", line 291, in structure_systems
    devices[this_station["station"]["id"]]["traffic"] = this_station["traffic"]
KeyError: 'traffic'
2021-08-31 17:31:17 ERROR (MainThread) [custom_components.googlewifi] Unexpected error fetching GoogleWifi data: 'traffic'
Traceback (most recent call last):
  File "/usr/src/homeassistant/homeassistant/helpers/update_coordinator.py", line 187, in _async_refresh
    self.data = await self._async_update_data()
  File "/config/custom_components/googlewifi/__init__.py", line 171, in _async_update_data
    system_data = await self.api.get_systems()
  File "/usr/local/lib/python3.9/site-packages/googlewifi/__init__.py", line 191, in get_systems
    return await self.structure_systems(response)
  File "/usr/local/lib/python3.9/site-packages/googlewifi/__init__.py", line 291, in structure_systems
    devices[this_station["station"]["id"]]["traffic"] = this_station["traffic"]
KeyError: 'traffic'
2021-08-31 17:32:10 ERROR (MainThread) [homeassistant.components.google_assistant.http] Request for https://homegraph.googleapis.com/v1/devices:reportStateAndNotification failed: 404
2021-08-31 17:32:36 ERROR (MainThread) [homeassistant.components.google_assistant.http] Request for https://homegraph.googleapis.com/v1/devices:reportStateAndNotification failed: 404
2021-08-31 17:37:34 ERROR (MainThread) [custom_components.googlewifi] Unexpected error fetching GoogleWifi data: 'traffic'
Traceback (most recent call last):
  File "/usr/src/homeassistant/homeassistant/helpers/update_coordinator.py", line 187, in _async_refresh
    self.data = await self._async_update_data()
  File "/config/custom_components/googlewifi/__init__.py", line 171, in _async_update_data
    system_data = await self.api.get_systems()
  File "/usr/local/lib/python3.9/site-packages/googlewifi/__init__.py", line 191, in get_systems
    return await self.structure_systems(response)
  File "/usr/local/lib/python3.9/site-packages/googlewifi/__init__.py", line 291, in structure_systems
    devices[this_station["station"]["id"]]["traffic"] = this_station["traffic"]
KeyError: 'traffic'
2021-08-31 17:38:17 ERROR (MainThread) [custom_components.googlewifi] Unexpected error fetching GoogleWifi data: 'traffic'
Traceback (most recent call last):
  File "/usr/src/homeassistant/homeassistant/helpers/update_coordinator.py", line 187, in _async_refresh
    self.data = await self._async_update_data()
  File "/config/custom_components/googlewifi/__init__.py", line 171, in _async_update_data
    system_data = await self.api.get_systems()
  File "/usr/local/lib/python3.9/site-packages/googlewifi/__init__.py", line 191, in get_systems
    return await self.structure_systems(response)
  File "/usr/local/lib/python3.9/site-packages/googlewifi/__init__.py", line 291, in structure_systems
    devices[this_station["station"]["id"]]["traffic"] = this_station["traffic"]
KeyError: 'traffic'
2021-08-31 17:39:09 ERROR (MainThread) [custom_components.googlewifi] Unexpected error fetching GoogleWifi data: 'NoneType' object is not iterable
Traceback (most recent call last):
  File "/usr/src/homeassistant/homeassistant/helpers/update_coordinator.py", line 187, in _async_refresh
    self.data = await self._async_update_data()
  File "/config/custom_components/googlewifi/__init__.py", line 171, in _async_update_data
    system_data = await self.api.get_systems()
  File "/usr/local/lib/python3.9/site-packages/googlewifi/__init__.py", line 191, in get_systems
    return await self.structure_systems(response)
  File "/usr/local/lib/python3.9/site-packages/googlewifi/__init__.py", line 289, in structure_systems
    for this_station in system_metrics.get("stationMetrics"):
TypeError: 'NoneType' object is not iterable
2021-08-31 17:39:52 ERROR (MainThread) [custom_components.googlewifi] Unexpected error fetching GoogleWifi data: 'traffic'
Traceback (most recent call last):
  File "/usr/src/homeassistant/homeassistant/helpers/update_coordinator.py", line 187, in _async_refresh
    self.data = await self._async_update_data()
  File "/config/custom_components/googlewifi/__init__.py", line 171, in _async_update_data
    system_data = await self.api.get_systems()
  File "/usr/local/lib/python3.9/site-packages/googlewifi/__init__.py", line 191, in get_systems
    return await self.structure_systems(response)
  File "/usr/local/lib/python3.9/site-packages/googlewifi/__init__.py", line 291, in structure_systems
    devices[this_station["station"]["id"]]["traffic"] = this_station["traffic"]
KeyError: 'traffic'
2021-08-31 17:40:34 ERROR (MainThread) [custom_components.googlewifi] Unexpected error fetching GoogleWifi data: 'traffic'
Traceback (most recent call last):
  File "/usr/src/homeassistant/homeassistant/helpers/update_coordinator.py", line 187, in _async_refresh
    self.data = await self._async_update_data()
  File "/config/custom_components/googlewifi/__init__.py", line 171, in _async_update_data
    system_data = await self.api.get_systems()
  File "/usr/local/lib/python3.9/site-packages/googlewifi/__init__.py", line 191, in get_systems
    return await self.structure_systems(response)
  File "/usr/local/lib/python3.9/site-packages/googlewifi/__init__.py", line 291, in structure_systems
    devices[this_station["station"]["id"]]["traffic"] = this_station["traffic"]
KeyError: 'traffic'
2021-08-31 18:06:47 ERROR (MainThread) [custom_components.googlewifi] Unexpected error fetching GoogleWifi data: 'traffic'
Traceback (most recent call last):
  File "/usr/src/homeassistant/homeassistant/helpers/update_coordinator.py", line 187, in _async_refresh
    self.data = await self._async_update_data()
  File "/config/custom_components/googlewifi/__init__.py", line 171, in _async_update_data
    system_data = await self.api.get_systems()
  File "/usr/local/lib/python3.9/site-packages/googlewifi/__init__.py", line 191, in get_systems
    return await self.structure_systems(response)
  File "/usr/local/lib/python3.9/site-packages/googlewifi/__init__.py", line 291, in structure_systems
    devices[this_station["station"]["id"]]["traffic"] = this_station["traffic"]
KeyError: 'traffic'
2021-08-31 18:07:29 ERROR (MainThread) [custom_components.googlewifi] Unexpected error fetching GoogleWifi data: 'traffic'
Traceback (most recent call last):
  File "/usr/src/homeassistant/homeassistant/helpers/update_coordinator.py", line 187, in _async_refresh
    self.data = await self._async_update_data()
  File "/config/custom_components/googlewifi/__init__.py", line 171, in _async_update_data
    system_data = await self.api.get_systems()
  File "/usr/local/lib/python3.9/site-packages/googlewifi/__init__.py", line 191, in get_systems
    return await self.structure_systems(response)
  File "/usr/local/lib/python3.9/site-packages/googlewifi/__init__.py", line 291, in structure_systems
    devices[this_station["station"]["id"]]["traffic"] = this_station["traffic"]
KeyError: 'traffic'
2021-08-31 18:17:03 ERROR (MainThread) [homeassistant.components.google_assistant.http] Request for https://homegraph.googleapis.com/v1/devices:reportStateAndNotification failed: 404
2021-08-31 18:22:17 ERROR (MainThread) [homeassistant.components.google_assistant.http] Request for https://homegraph.googleapis.com/v1/devices:reportStateAndNotification failed: 404
2021-08-31 18:35:04 ERROR (MainThread) [homeassistant.components.google_assistant.http] Request for https://homegraph.googleapis.com/v1/devices:reportStateAndNotification failed: 404
2021-08-31 18:39:59 ERROR (MainThread) [custom_components.googlewifi] Unexpected error fetching GoogleWifi data: 'NoneType' object is not iterable
Traceback (most recent call last):
  File "/usr/src/homeassistant/homeassistant/helpers/update_coordinator.py", line 187, in _async_refresh
    self.data = await self._async_update_data()
  File "/config/custom_components/googlewifi/__init__.py", line 171, in _async_update_data
    system_data = await self.api.get_systems()
  File "/usr/local/lib/python3.9/site-packages/googlewifi/__init__.py", line 191, in get_systems
    return await self.structure_systems(response)
  File "/usr/local/lib/python3.9/site-packages/googlewifi/__init__.py", line 289, in structure_systems
    for this_station in system_metrics.get("stationMetrics"):
TypeError: 'NoneType' object is not iterable
2021-08-31 18:50:01 ERROR (MainThread) [homeassistant.components.google_assistant.http] Request for https://homegraph.googleapis.com/v1/devices:reportStateAndNotification failed: 404
2021-08-31 18:54:22 ERROR (MainThread) [homeassistant.components.google_assistant.http] Request for https://homegraph.googleapis.com/v1/devices:reportStateAndNotification failed: 404
2021-08-31 18:58:18 ERROR (MainThread) [homeassistant.components.google_assistant.http] Request for https://homegraph.googleapis.com/v1/devices:reportStateAndNotification failed: 404
2021-08-31 19:05:45 ERROR (MainThread) [custom_components.googlewifi] Error fetching GoogleWifi data: Error connecting to GoogleWifi: 
2021-08-31 19:12:26 ERROR (MainThread) [homeassistant.components.google_assistant.http] Request for https://homegraph.googleapis.com/v1/devices:reportStateAndNotification failed: 404
2021-08-31 19:17:41 WARNING (SyncWorker_2) [buienalarm.pybuienalarm] Error fetching data safely: HTTPSConnectionPool(host='cdn-secure.buienalarm.nl', port=443): Read timed out. (read timeout=10.0)
2021-08-31 19:36:09 ERROR (MainThread) [homeassistant.components.google_assistant.http] Request for https://homegraph.googleapis.com/v1/devices:reportStateAndNotification failed: 404
2021-08-31 19:39:34 ERROR (MainThread) [custom_components.googlewifi] Error fetching GoogleWifi data: Error connecting to GoogleWifi: 
2021-08-31 19:40:09 ERROR (MainThread) [homeassistant.components.google_assistant.http] Request for https://homegraph.googleapis.com/v1/devices:reportStateAndNotification failed: 404
2021-08-31 19:44:29 ERROR (MainThread) [homeassistant.components.google_assistant.http] Request for https://homegraph.googleapis.com/v1/devices:reportStateAndNotification failed: 404
2021-08-31 19:48:32 ERROR (MainThread) [homeassistant.components.google_assistant.http] Request for https://homegraph.googleapis.com/v1/devices:reportStateAndNotification failed: 404
2021-08-31 19:52:12 ERROR (MainThread) [custom_components.googlewifi] Unexpected error fetching GoogleWifi data: 'NoneType' object is not iterable
Traceback (most recent call last):
  File "/usr/src/homeassistant/homeassistant/helpers/update_coordinator.py", line 187, in _async_refresh
    self.data = await self._async_update_data()
  File "/config/custom_components/googlewifi/__init__.py", line 171, in _async_update_data
    system_data = await self.api.get_systems()
  File "/usr/local/lib/python3.9/site-packages/googlewifi/__init__.py", line 191, in get_systems
    return await self.structure_systems(response)
  File "/usr/local/lib/python3.9/site-packages/googlewifi/__init__.py", line 289, in structure_systems
    for this_station in system_metrics.get("stationMetrics"):
TypeError: 'NoneType' object is not iterable
2021-08-31 19:57:37 ERROR (MainThread) [homeassistant.components.google_assistant.http] Request for https://homegraph.googleapis.com/v1/devices:reportStateAndNotification failed: 404
2021-08-31 20:11:33 ERROR (MainThread) [custom_components.googlewifi] Unexpected error fetching GoogleWifi data: 'traffic'
Traceback (most recent call last):
  File "/usr/src/homeassistant/homeassistant/helpers/update_coordinator.py", line 187, in _async_refresh
    self.data = await self._async_update_data()
  File "/config/custom_components/googlewifi/__init__.py", line 171, in _async_update_data
    system_data = await self.api.get_systems()
  File "/usr/local/lib/python3.9/site-packages/googlewifi/__init__.py", line 191, in get_systems
    return await self.structure_systems(response)
  File "/usr/local/lib/python3.9/site-packages/googlewifi/__init__.py", line 291, in structure_systems
    devices[this_station["station"]["id"]]["traffic"] = this_station["traffic"]
KeyError: 'traffic'
2021-08-31 20:26:18 ERROR (MainThread) [homeassistant.components.google_assistant.http] Request for https://homegraph.googleapis.com/v1/devices:reportStateAndNotification failed: 404
2021-08-31 20:34:43 ERROR (MainThread) [homeassistant.components.google_assistant.http] Request for https://homegraph.googleapis.com/v1/devices:reportStateAndNotification failed: 404
2021-08-31 20:47:47 ERROR (MainThread) [homeassistant.components.google_assistant.http] Request for https://homegraph.googleapis.com/v1/devices:reportStateAndNotification failed: 404
2021-08-31 21:23:57 ERROR (MainThread) [homeassistant.components.google_assistant.http] Request for https://homegraph.googleapis.com/v1/devices:reportStateAndNotification failed: 404
2021-08-31 21:33:12 ERROR (MainThread) [custom_components.googlewifi] Unexpected error fetching GoogleWifi data: 'traffic'
Traceback (most recent call last):
  File "/usr/src/homeassistant/homeassistant/helpers/update_coordinator.py", line 187, in _async_refresh
    self.data = await self._async_update_data()
  File "/config/custom_components/googlewifi/__init__.py", line 171, in _async_update_data
    system_data = await self.api.get_systems()
  File "/usr/local/lib/python3.9/site-packages/googlewifi/__init__.py", line 191, in get_systems
    return await self.structure_systems(response)
  File "/usr/local/lib/python3.9/site-packages/googlewifi/__init__.py", line 291, in structure_systems
    devices[this_station["station"]["id"]]["traffic"] = this_station["traffic"]
KeyError: 'traffic'
2021-08-31 21:34:35 ERROR (MainThread) [custom_components.googlewifi] Unexpected error fetching GoogleWifi data: 'traffic'
Traceback (most recent call last):
  File "/usr/src/homeassistant/homeassistant/helpers/update_coordinator.py", line 187, in _async_refresh
    self.data = await self._async_update_data()
  File "/config/custom_components/googlewifi/__init__.py", line 171, in _async_update_data
    system_data = await self.api.get_systems()
  File "/usr/local/lib/python3.9/site-packages/googlewifi/__init__.py", line 191, in get_systems
    return await self.structure_systems(response)
  File "/usr/local/lib/python3.9/site-packages/googlewifi/__init__.py", line 291, in structure_systems
    devices[this_station["station"]["id"]]["traffic"] = this_station["traffic"]
KeyError: 'traffic'
2021-08-31 21:40:14 ERROR (MainThread) [custom_components.googlewifi] Unexpected error fetching GoogleWifi data: 'NoneType' object is not iterable
Traceback (most recent call last):
  File "/usr/src/homeassistant/homeassistant/helpers/update_coordinator.py", line 187, in _async_refresh
    self.data = await self._async_update_data()
  File "/config/custom_components/googlewifi/__init__.py", line 171, in _async_update_data
    system_data = await self.api.get_systems()
  File "/usr/local/lib/python3.9/site-packages/googlewifi/__init__.py", line 191, in get_systems
    return await self.structure_systems(response)
  File "/usr/local/lib/python3.9/site-packages/googlewifi/__init__.py", line 289, in structure_systems
    for this_station in system_metrics.get("stationMetrics"):
TypeError: 'NoneType' object is not iterable
2021-08-31 21:54:45 WARNING (MainThread) [homeassistant.helpers.entity] Update of sensor.precip_rate_leuven24_wunderground is taking over 10 seconds
2021-08-31 21:54:46 ERROR (MainThread) [homeassistant.components.rest.data] Error fetching data: https://www.wunderground.com/dashboard/pws/ILEUVE24 failed with 
2021-08-31 21:54:46 ERROR (MainThread) [homeassistant.components.scrape.sensor] Unable to retrieve data for precip_rate_leuven24_wunderground
2021-08-31 21:54:54 ERROR (MainThread) [custom_components.googlewifi] Unexpected error fetching GoogleWifi data: 'traffic'
Traceback (most recent call last):
  File "/usr/src/homeassistant/homeassistant/helpers/update_coordinator.py", line 187, in _async_refresh
    self.data = await self._async_update_data()
  File "/config/custom_components/googlewifi/__init__.py", line 171, in _async_update_data
    system_data = await self.api.get_systems()
  File "/usr/local/lib/python3.9/site-packages/googlewifi/__init__.py", line 191, in get_systems
    return await self.structure_systems(response)
  File "/usr/local/lib/python3.9/site-packages/googlewifi/__init__.py", line 291, in structure_systems
    devices[this_station["station"]["id"]]["traffic"] = this_station["traffic"]
KeyError: 'traffic'
2021-08-31 21:55:35 ERROR (MainThread) [custom_components.googlewifi] Unexpected error fetching GoogleWifi data: 'traffic'
Traceback (most recent call last):
  File "/usr/src/homeassistant/homeassistant/helpers/update_coordinator.py", line 187, in _async_refresh
    self.data = await self._async_update_data()
  File "/config/custom_components/googlewifi/__init__.py", line 171, in _async_update_data
    system_data = await self.api.get_systems()
  File "/usr/local/lib/python3.9/site-packages/googlewifi/__init__.py", line 191, in get_systems
    return await self.structure_systems(response)
  File "/usr/local/lib/python3.9/site-packages/googlewifi/__init__.py", line 291, in structure_systems
    devices[this_station["station"]["id"]]["traffic"] = this_station["traffic"]
KeyError: 'traffic'
2021-08-31 21:56:17 ERROR (MainThread) [custom_components.googlewifi] Unexpected error fetching GoogleWifi data: 'traffic'
Traceback (most recent call last):
  File "/usr/src/homeassistant/homeassistant/helpers/update_coordinator.py", line 187, in _async_refresh
    self.data = await self._async_update_data()
  File "/config/custom_components/googlewifi/__init__.py", line 171, in _async_update_data
    system_data = await self.api.get_systems()
  File "/usr/local/lib/python3.9/site-packages/googlewifi/__init__.py", line 191, in get_systems
    return await self.structure_systems(response)
  File "/usr/local/lib/python3.9/site-packages/googlewifi/__init__.py", line 291, in structure_systems
    devices[this_station["station"]["id"]]["traffic"] = this_station["traffic"]
KeyError: 'traffic'
2021-08-31 21:57:01 ERROR (MainThread) [custom_components.googlewifi] Unexpected error fetching GoogleWifi data: 'traffic'
Traceback (most recent call last):
  File "/usr/src/homeassistant/homeassistant/helpers/update_coordinator.py", line 187, in _async_refresh
    self.data = await self._async_update_data()
  File "/config/custom_components/googlewifi/__init__.py", line 171, in _async_update_data
    system_data = await self.api.get_systems()
  File "/usr/local/lib/python3.9/site-packages/googlewifi/__init__.py", line 191, in get_systems
    return await self.structure_systems(response)
  File "/usr/local/lib/python3.9/site-packages/googlewifi/__init__.py", line 291, in structure_systems
    devices[this_station["station"]["id"]]["traffic"] = this_station["traffic"]
KeyError: 'traffic'
2021-08-31 21:57:43 ERROR (MainThread) [custom_components.googlewifi] Unexpected error fetching GoogleWifi data: 'traffic'
Traceback (most recent call last):
  File "/usr/src/homeassistant/homeassistant/helpers/update_coordinator.py", line 187, in _async_refresh
    self.data = await self._async_update_data()
  File "/config/custom_components/googlewifi/__init__.py", line 171, in _async_update_data
    system_data = await self.api.get_systems()
  File "/usr/local/lib/python3.9/site-packages/googlewifi/__init__.py", line 191, in get_systems
    return await self.structure_systems(response)
  File "/usr/local/lib/python3.9/site-packages/googlewifi/__init__.py", line 291, in structure_systems
    devices[this_station["station"]["id"]]["traffic"] = this_station["traffic"]
KeyError: 'traffic'
2021-08-31 21:58:24 ERROR (MainThread) [custom_components.googlewifi] Unexpected error fetching GoogleWifi data: 'traffic'
Traceback (most recent call last):
  File "/usr/src/homeassistant/homeassistant/helpers/update_coordinator.py", line 187, in _async_refresh
    self.data = await self._async_update_data()
  File "/config/custom_components/googlewifi/__init__.py", line 171, in _async_update_data
    system_data = await self.api.get_systems()
  File "/usr/local/lib/python3.9/site-packages/googlewifi/__init__.py", line 191, in get_systems
    return await self.structure_systems(response)
  File "/usr/local/lib/python3.9/site-packages/googlewifi/__init__.py", line 291, in structure_systems
    devices[this_station["station"]["id"]]["traffic"] = this_station["traffic"]
KeyError: 'traffic'
2021-08-31 21:59:05 ERROR (MainThread) [custom_components.googlewifi] Unexpected error fetching GoogleWifi data: 'traffic'
Traceback (most recent call last):
  File "/usr/src/homeassistant/homeassistant/helpers/update_coordinator.py", line 187, in _async_refresh
    self.data = await self._async_update_data()
  File "/config/custom_components/googlewifi/__init__.py", line 171, in _async_update_data
    system_data = await self.api.get_systems()
  File "/usr/local/lib/python3.9/site-packages/googlewifi/__init__.py", line 191, in get_systems
    return await self.structure_systems(response)
  File "/usr/local/lib/python3.9/site-packages/googlewifi/__init__.py", line 291, in structure_systems
    devices[this_station["station"]["id"]]["traffic"] = this_station["traffic"]
KeyError: 'traffic'
2021-08-31 22:06:51 ERROR (MainThread) [custom_components.googlewifi] Unexpected error fetching GoogleWifi data: 'NoneType' object is not iterable
Traceback (most recent call last):
  File "/usr/src/homeassistant/homeassistant/helpers/update_coordinator.py", line 187, in _async_refresh
    self.data = await self._async_update_data()
  File "/config/custom_components/googlewifi/__init__.py", line 171, in _async_update_data
    system_data = await self.api.get_systems()
  File "/usr/local/lib/python3.9/site-packages/googlewifi/__init__.py", line 191, in get_systems
    return await self.structure_systems(response)
  File "/usr/local/lib/python3.9/site-packages/googlewifi/__init__.py", line 289, in structure_systems
    for this_station in system_metrics.get("stationMetrics"):
TypeError: 'NoneType' object is not iterable
2021-08-31 22:09:28 ERROR (MainThread) [homeassistant.components.google_assistant.http] Request for https://homegraph.googleapis.com/v1/devices:reportStateAndNotification failed: 404
2021-08-31 22:14:54 ERROR (MainThread) [homeassistant.components.google_assistant.http] Request for https://homegraph.googleapis.com/v1/devices:reportStateAndNotification failed: 404
2021-08-31 22:22:27 ERROR (MainThread) [homeassistant.components.google_assistant.http] Request for https://homegraph.googleapis.com/v1/devices:reportStateAndNotification failed: 404
2021-08-31 22:25:50 ERROR (MainThread) [custom_components.googlewifi] Unexpected error fetching GoogleWifi data: 'traffic'
Traceback (most recent call last):
  File "/usr/src/homeassistant/homeassistant/helpers/update_coordinator.py", line 187, in _async_refresh
    self.data = await self._async_update_data()
  File "/config/custom_components/googlewifi/__init__.py", line 171, in _async_update_data
    system_data = await self.api.get_systems()
  File "/usr/local/lib/python3.9/site-packages/googlewifi/__init__.py", line 191, in get_systems
    return await self.structure_systems(response)
  File "/usr/local/lib/python3.9/site-packages/googlewifi/__init__.py", line 291, in structure_systems
    devices[this_station["station"]["id"]]["traffic"] = this_station["traffic"]
KeyError: 'traffic'
2021-08-31 22:28:13 ERROR (MainThread) [homeassistant.components.google_assistant.http] Request for https://homegraph.googleapis.com/v1/devices:reportStateAndNotification failed: 404
2021-08-31 23:04:17 ERROR (MainThread) [homeassistant.components.google_assistant.http] Request for https://homegraph.googleapis.com/v1/devices:reportStateAndNotification failed: 404
2021-08-31 23:46:55 ERROR (MainThread) [homeassistant.components.google_assistant.http] Request for https://homegraph.googleapis.com/v1/devices:reportStateAndNotification failed: 404
2021-08-31 23:48:46 ERROR (MainThread) [homeassistant] Error doing job: Task exception was never retrieved
Traceback (most recent call last):
  File "/usr/src/homeassistant/homeassistant/components/discovery/__init__.py", line 194, in scan_devices
    results = await hass.async_add_executor_job(
  File "/usr/local/lib/python3.9/concurrent/futures/thread.py", line 52, in run
    result = self.fn(*self.args, **self.kwargs)
  File "/usr/src/homeassistant/homeassistant/components/discovery/__init__.py", line 226, in _discover
    for service in netdisco.get_info(disc):
  File "/usr/local/lib/python3.9/site-packages/netdisco/discovery.py", line 108, in get_info
    return self.discoverables[dis].get_info()
  File "/usr/local/lib/python3.9/site-packages/netdisco/discoverables/__init__.py", line 28, in get_info
    return [self.info_from_entry(entry) for entry in self.get_entries()]
  File "/usr/local/lib/python3.9/site-packages/netdisco/discoverables/__init__.py", line 28, in <listcomp>
    return [self.info_from_entry(entry) for entry in self.get_entries()]
  File "/usr/local/lib/python3.9/site-packages/netdisco/discoverables/__init__.py", line 129, in info_from_entry
    ATTR_HOST: str(ipaddress.ip_address(entry.addresses[0])),
IndexError: list index out of range
2021-08-31 23:55:12 ERROR (MainThread) [homeassistant.components.google_assistant.http] Request for https://homegraph.googleapis.com/v1/devices:reportStateAndNotification failed: 404
2021-09-01 00:02:45 ERROR (MainThread) [homeassistant.components.google_assistant.http] Request for https://homegraph.googleapis.com/v1/devices:reportStateAndNotification failed: 404
2021-09-01 00:17:01 WARNING (Thread-10) [pychromecast.socket_client] [Veranda TV(192.168.86.24):8009] Heartbeat timeout, resetting connection
2021-09-01 00:17:16 ERROR (Thread-10) [pychromecast.socket_client] [Veranda TV(192.168.86.24):8009] Failed to connect to service ServiceInfo(type='host', data=('192.168.86.24', 8009)), retrying in 5.0s
2021-09-01 00:17:20 ERROR (MainThread) [custom_components.googlewifi] Unexpected error fetching GoogleWifi data: 'traffic'
Traceback (most recent call last):
  File "/usr/src/homeassistant/homeassistant/helpers/update_coordinator.py", line 187, in _async_refresh
    self.data = await self._async_update_data()
  File "/config/custom_components/googlewifi/__init__.py", line 171, in _async_update_data
    system_data = await self.api.get_systems()
  File "/usr/local/lib/python3.9/site-packages/googlewifi/__init__.py", line 191, in get_systems
    return await self.structure_systems(response)
  File "/usr/local/lib/python3.9/site-packages/googlewifi/__init__.py", line 291, in structure_systems
    devices[this_station["station"]["id"]]["traffic"] = this_station["traffic"]
KeyError: 'traffic'
2021-09-01 00:41:40 ERROR (MainThread) [custom_components.googlewifi] Unexpected error fetching GoogleWifi data: 'NoneType' object is not iterable
Traceback (most recent call last):
  File "/usr/src/homeassistant/homeassistant/helpers/update_coordinator.py", line 187, in _async_refresh
    self.data = await self._async_update_data()
  File "/config/custom_components/googlewifi/__init__.py", line 171, in _async_update_data
    system_data = await self.api.get_systems()
  File "/usr/local/lib/python3.9/site-packages/googlewifi/__init__.py", line 191, in get_systems
    return await self.structure_systems(response)
  File "/usr/local/lib/python3.9/site-packages/googlewifi/__init__.py", line 289, in structure_systems
    for this_station in system_metrics.get("stationMetrics"):
TypeError: 'NoneType' object is not iterable
2021-09-01 00:42:51 WARNING (SyncWorker_8) [buienalarm.pybuienalarm] Error fetching data safely: HTTPSConnectionPool(host='cdn-secure.buienalarm.nl', port=443): Read timed out. (read timeout=10.0)
2021-09-01 00:45:19 ERROR (MainThread) [homeassistant.components.google_assistant.http] Request for https://homegraph.googleapis.com/v1/devices:reportStateAndNotification failed: 404
2021-09-01 00:57:23 WARNING (Thread-17) [pychromecast.socket_client] [badkamer speaker(192.168.86.35):8009] Heartbeat timeout, resetting connection
2021-09-01 00:57:33 ERROR (Thread-17) [pychromecast.socket_client] [badkamer speaker(192.168.86.35):8009] Failed to connect to service ServiceInfo(type='host', data=('192.168.86.35', 8009)), retrying in 5.0s
2021-09-01 00:58:45 ERROR (MainThread) [homeassistant.components.google_assistant.http] Request for https://homegraph.googleapis.com/v1/devices:reportStateAndNotification failed: 404
2021-09-01 01:03:44 ERROR (SyncWorker_1) [glocaltokens.client] [Device - Nest Wifi router(id=2f2a9d15-0ae2-4ffe-b6c1-2ef24c742b8a)] local_auth_token must follow the correct format
2021-09-01 01:03:44 ERROR (SyncWorker_1) [glocaltokens.client] [Device - Nest Wifi router(id=e1e5a8d5-d21f-444d-95a9-c76d78c9bc79)] local_auth_token must follow the correct format
2021-09-01 01:03:44 ERROR (SyncWorker_1) [glocaltokens.client] [Device - Nest Wifi router(id=ea3de37c-ca74-4689-8171-1681b2f4f924)] local_auth_token must follow the correct format
2021-09-01 01:05:52 WARNING (Thread-16) [pychromecast.socket_client] [Living Chromecast(192.168.86.32):8009] Heartbeat timeout, resetting connection
2021-09-01 01:06:08 ERROR (Thread-16) [pychromecast.socket_client] [Living Chromecast(192.168.86.32):8009] Failed to connect to service ServiceInfo(type='host', data=('192.168.86.32', 8009)), retrying in 5.0s
2021-09-01 01:26:29 WARNING (Thread-13) [pychromecast.socket_client] [Alunya speaker(192.168.86.37):8009] Heartbeat timeout, resetting connection
2021-09-01 01:26:36 ERROR (Thread-13) [pychromecast.socket_client] [Alunya speaker(192.168.86.37):8009] Failed to connect to service ServiceInfo(type='host', data=('192.168.86.37', 8009)), retrying in 5.0s
2021-09-01 01:27:15 ERROR (MainThread) [homeassistant.components.google_assistant.http] Request for https://homegraph.googleapis.com/v1/devices:reportStateAndNotification failed: 404
2021-09-01 01:31:43 ERROR (SyncWorker_9) [glocaltokens.client] [Device - Nest Wifi router(id=2f2a9d15-0ae2-4ffe-b6c1-2ef24c742b8a)] local_auth_token must follow the correct format
2021-09-01 01:31:43 ERROR (SyncWorker_9) [glocaltokens.client] [Device - Nest Wifi router(id=e1e5a8d5-d21f-444d-95a9-c76d78c9bc79)] local_auth_token must follow the correct format
2021-09-01 01:31:43 ERROR (SyncWorker_9) [glocaltokens.client] [Device - Nest Wifi router(id=ea3de37c-ca74-4689-8171-1681b2f4f924)] local_auth_token must follow the correct format
2021-09-01 01:35:28 ERROR (MainThread) [homeassistant.components.google_assistant.http] Request for https://homegraph.googleapis.com/v1/devices:reportStateAndNotification failed: 404
2021-09-01 01:35:40 ERROR (MainThread) [homeassistant.components.google_assistant.http] Request for https://homegraph.googleapis.com/v1/devices:reportStateAndNotification failed: 404
2021-09-01 02:15:21 WARNING (Thread-11) [pychromecast.socket_client] [Master bedroom speaker(192.168.86.42):8009] Heartbeat timeout, resetting connection
2021-09-01 02:17:24 ERROR (MainThread) [homeassistant.components.google_assistant.http] Request for https://homegraph.googleapis.com/v1/devices:reportStateAndNotification failed: 404
2021-09-01 02:21:18 ERROR (SyncWorker_1) [glocaltokens.client] [Device - Nest Wifi router(id=2f2a9d15-0ae2-4ffe-b6c1-2ef24c742b8a)] local_auth_token must follow the correct format
2021-09-01 02:21:18 ERROR (SyncWorker_1) [glocaltokens.client] [Device - Nest Wifi router(id=e1e5a8d5-d21f-444d-95a9-c76d78c9bc79)] local_auth_token must follow the correct format
2021-09-01 02:21:18 ERROR (SyncWorker_1) [glocaltokens.client] [Device - Nest Wifi router(id=ea3de37c-ca74-4689-8171-1681b2f4f924)] local_auth_token must follow the correct format
2021-09-01 02:33:17 ERROR (MainThread) [homeassistant.components.google_assistant.http] Request for https://homegraph.googleapis.com/v1/devices:reportStateAndNotification failed: 404
2021-09-01 03:07:32 ERROR (MainThread) [homeassistant.components.google_assistant.http] Request for https://homegraph.googleapis.com/v1/devices:reportStateAndNotification failed: 404
2021-09-01 03:08:44 ERROR (MainThread) [custom_components.googlewifi] Unexpected error fetching GoogleWifi data: 'operationState'
Traceback (most recent call last):
  File "/usr/src/homeassistant/homeassistant/helpers/update_coordinator.py", line 187, in _async_refresh
    self.data = await self._async_update_data()
  File "/config/custom_components/googlewifi/__init__.py", line 171, in _async_update_data
    system_data = await self.api.get_systems()
  File "/usr/local/lib/python3.9/site-packages/googlewifi/__init__.py", line 191, in get_systems
    return await self.structure_systems(response)
  File "/usr/local/lib/python3.9/site-packages/googlewifi/__init__.py", line 284, in structure_systems
    sensitive_info = await self.get_sensitive_info(system_id=this_system["id"], station_ids=station_ids)
  File "/usr/local/lib/python3.9/site-packages/googlewifi/__init__.py", line 616, in get_sensitive_info
    status = status["operationState"]
KeyError: 'operationState'
2021-09-01 03:23:27 ERROR (MainThread) [homeassistant.components.google_assistant.http] Request for https://homegraph.googleapis.com/v1/devices:reportStateAndNotification failed: 404
2021-09-01 03:57:44 ERROR (MainThread) [homeassistant.components.google_assistant.http] Request for https://homegraph.googleapis.com/v1/devices:reportStateAndNotification failed: 404
2021-09-01 04:00:00 WARNING (MainThread) [homeassistant.components.automation] Error evaluating condition in '🔌's morgens Bart S10+ nog bijladen':
In 'condition':
  In 'numeric_state':
    In 'numeric_state' condition: unknown entity sensor.bart_s10_batterijniveau
2021-09-01 04:56:22 ERROR (MainThread) [homeassistant.components.google_assistant.http] Request for https://homegraph.googleapis.com/v1/devices:reportStateAndNotification failed: 404
2021-09-01 05:22:24 ERROR (MainThread) [homeassistant.components.google_assistant.http] Request for https://homegraph.googleapis.com/v1/devices:reportStateAndNotification failed: 404
2021-09-01 06:12:31 ERROR (MainThread) [homeassistant.components.google_assistant.http] Request for https://homegraph.googleapis.com/v1/devices:reportStateAndNotification failed: 404
2021-09-01 06:38:01 ERROR (MainThread) [custom_components.googlewifi] Error fetching GoogleWifi data: Error connecting to GoogleWifi: 
2021-09-01 06:42:13 ERROR (MainThread) [custom_components.googlewifi] Unexpected error fetching GoogleWifi data: 'traffic'
Traceback (most recent call last):
  File "/usr/src/homeassistant/homeassistant/helpers/update_coordinator.py", line 187, in _async_refresh
    self.data = await self._async_update_data()
  File "/config/custom_components/googlewifi/__init__.py", line 171, in _async_update_data
    system_data = await self.api.get_systems()
  File "/usr/local/lib/python3.9/site-packages/googlewifi/__init__.py", line 191, in get_systems
    return await self.structure_systems(response)
  File "/usr/local/lib/python3.9/site-packages/googlewifi/__init__.py", line 291, in structure_systems
    devices[this_station["station"]["id"]]["traffic"] = this_station["traffic"]
KeyError: 'traffic'
2021-09-01 06:52:46 ERROR (MainThread) [custom_components.googlewifi] Unexpected error fetching GoogleWifi data: 'traffic'
Traceback (most recent call last):
  File "/usr/src/homeassistant/homeassistant/helpers/update_coordinator.py", line 187, in _async_refresh
    self.data = await self._async_update_data()
  File "/config/custom_components/googlewifi/__init__.py", line 171, in _async_update_data
    system_data = await self.api.get_systems()
  File "/usr/local/lib/python3.9/site-packages/googlewifi/__init__.py", line 191, in get_systems
    return await self.structure_systems(response)
  File "/usr/local/lib/python3.9/site-packages/googlewifi/__init__.py", line 291, in structure_systems
    devices[this_station["station"]["id"]]["traffic"] = this_station["traffic"]
KeyError: 'traffic'
2021-09-01 06:53:28 ERROR (MainThread) [custom_components.googlewifi] Unexpected error fetching GoogleWifi data: 'traffic'
Traceback (most recent call last):
  File "/usr/src/homeassistant/homeassistant/helpers/update_coordinator.py", line 187, in _async_refresh
    self.data = await self._async_update_data()
  File "/config/custom_components/googlewifi/__init__.py", line 171, in _async_update_data
    system_data = await self.api.get_systems()
  File "/usr/local/lib/python3.9/site-packages/googlewifi/__init__.py", line 191, in get_systems
    return await self.structure_systems(response)
  File "/usr/local/lib/python3.9/site-packages/googlewifi/__init__.py", line 291, in structure_systems
    devices[this_station["station"]["id"]]["traffic"] = this_station["traffic"]
KeyError: 'traffic'
2021-09-01 06:54:09 ERROR (MainThread) [custom_components.googlewifi] Unexpected error fetching GoogleWifi data: 'traffic'
Traceback (most recent call last):
  File "/usr/src/homeassistant/homeassistant/helpers/update_coordinator.py", line 187, in _async_refresh
    self.data = await self._async_update_data()
  File "/config/custom_components/googlewifi/__init__.py", line 171, in _async_update_data
    system_data = await self.api.get_systems()
  File "/usr/local/lib/python3.9/site-packages/googlewifi/__init__.py", line 191, in get_systems
    return await self.structure_systems(response)
  File "/usr/local/lib/python3.9/site-packages/googlewifi/__init__.py", line 291, in structure_systems
    devices[this_station["station"]["id"]]["traffic"] = this_station["traffic"]
KeyError: 'traffic'
2021-09-01 06:54:51 ERROR (MainThread) [custom_components.googlewifi] Unexpected error fetching GoogleWifi data: 'traffic'
Traceback (most recent call last):
  File "/usr/src/homeassistant/homeassistant/helpers/update_coordinator.py", line 187, in _async_refresh
    self.data = await self._async_update_data()
  File "/config/custom_components/googlewifi/__init__.py", line 171, in _async_update_data
    system_data = await self.api.get_systems()
  File "/usr/local/lib/python3.9/site-packages/googlewifi/__init__.py", line 191, in get_systems
    return await self.structure_systems(response)
  File "/usr/local/lib/python3.9/site-packages/googlewifi/__init__.py", line 291, in structure_systems
    devices[this_station["station"]["id"]]["traffic"] = this_station["traffic"]
KeyError: 'traffic'
2021-09-01 06:55:32 ERROR (MainThread) [custom_components.googlewifi] Unexpected error fetching GoogleWifi data: 'traffic'
Traceback (most recent call last):
  File "/usr/src/homeassistant/homeassistant/helpers/update_coordinator.py", line 187, in _async_refresh
    self.data = await self._async_update_data()
  File "/config/custom_components/googlewifi/__init__.py", line 171, in _async_update_data
    system_data = await self.api.get_systems()
  File "/usr/local/lib/python3.9/site-packages/googlewifi/__init__.py", line 191, in get_systems
    return await self.structure_systems(response)
  File "/usr/local/lib/python3.9/site-packages/googlewifi/__init__.py", line 291, in structure_systems
    devices[this_station["station"]["id"]]["traffic"] = this_station["traffic"]
KeyError: 'traffic'
2021-09-01 07:07:02 ERROR (MainThread) [custom_components.googlewifi] Unexpected error fetching GoogleWifi data: 'operationState'
Traceback (most recent call last):
  File "/usr/src/homeassistant/homeassistant/helpers/update_coordinator.py", line 187, in _async_refresh
    self.data = await self._async_update_data()
  File "/config/custom_components/googlewifi/__init__.py", line 171, in _async_update_data
    system_data = await self.api.get_systems()
  File "/usr/local/lib/python3.9/site-packages/googlewifi/__init__.py", line 191, in get_systems
    return await self.structure_systems(response)
  File "/usr/local/lib/python3.9/site-packages/googlewifi/__init__.py", line 284, in structure_systems
    sensitive_info = await self.get_sensitive_info(system_id=this_system["id"], station_ids=station_ids)
  File "/usr/local/lib/python3.9/site-packages/googlewifi/__init__.py", line 616, in get_sensitive_info
    status = status["operationState"]
KeyError: 'operationState'
2021-09-01 07:11:02 ERROR (MainThread) [custom_components.googlewifi] Unexpected error fetching GoogleWifi data: 'traffic'
Traceback (most recent call last):
  File "/usr/src/homeassistant/homeassistant/helpers/update_coordinator.py", line 187, in _async_refresh
    self.data = await self._async_update_data()
  File "/config/custom_components/googlewifi/__init__.py", line 171, in _async_update_data
    system_data = await self.api.get_systems()
  File "/usr/local/lib/python3.9/site-packages/googlewifi/__init__.py", line 191, in get_systems
    return await self.structure_systems(response)
  File "/usr/local/lib/python3.9/site-packages/googlewifi/__init__.py", line 291, in structure_systems
    devices[this_station["station"]["id"]]["traffic"] = this_station["traffic"]
KeyError: 'traffic'
2021-09-01 07:12:29 ERROR (MainThread) [custom_components.googlewifi] Unexpected error fetching GoogleWifi data: 'traffic'
Traceback (most recent call last):
  File "/usr/src/homeassistant/homeassistant/helpers/update_coordinator.py", line 187, in _async_refresh
    self.data = await self._async_update_data()
  File "/config/custom_components/googlewifi/__init__.py", line 171, in _async_update_data
    system_data = await self.api.get_systems()
  File "/usr/local/lib/python3.9/site-packages/googlewifi/__init__.py", line 191, in get_systems
    return await self.structure_systems(response)
  File "/usr/local/lib/python3.9/site-packages/googlewifi/__init__.py", line 291, in structure_systems
    devices[this_station["station"]["id"]]["traffic"] = this_station["traffic"]
KeyError: 'traffic'
2021-09-01 07:16:07 ERROR (MainThread) [custom_components.googlewifi] Unexpected error fetching GoogleWifi data: 'traffic'
Traceback (most recent call last):
  File "/usr/src/homeassistant/homeassistant/helpers/update_coordinator.py", line 187, in _async_refresh
    self.data = await self._async_update_data()
  File "/config/custom_components/googlewifi/__init__.py", line 171, in _async_update_data
    system_data = await self.api.get_systems()
  File "/usr/local/lib/python3.9/site-packages/googlewifi/__init__.py", line 191, in get_systems
    return await self.structure_systems(response)
  File "/usr/local/lib/python3.9/site-packages/googlewifi/__init__.py", line 291, in structure_systems
    devices[this_station["station"]["id"]]["traffic"] = this_station["traffic"]
KeyError: 'traffic'
2021-09-01 07:16:50 ERROR (MainThread) [custom_components.googlewifi] Unexpected error fetching GoogleWifi data: 'traffic'
Traceback (most recent call last):
  File "/usr/src/homeassistant/homeassistant/helpers/update_coordinator.py", line 187, in _async_refresh
    self.data = await self._async_update_data()
  File "/config/custom_components/googlewifi/__init__.py", line 171, in _async_update_data
    system_data = await self.api.get_systems()
  File "/usr/local/lib/python3.9/site-packages/googlewifi/__init__.py", line 191, in get_systems
    return await self.structure_systems(response)
  File "/usr/local/lib/python3.9/site-packages/googlewifi/__init__.py", line 291, in structure_systems
    devices[this_station["station"]["id"]]["traffic"] = this_station["traffic"]
KeyError: 'traffic'
2021-09-01 07:17:31 ERROR (MainThread) [custom_components.googlewifi] Unexpected error fetching GoogleWifi data: 'traffic'
Traceback (most recent call last):
  File "/usr/src/homeassistant/homeassistant/helpers/update_coordinator.py", line 187, in _async_refresh
    self.data = await self._async_update_data()
  File "/config/custom_components/googlewifi/__init__.py", line 171, in _async_update_data
    system_data = await self.api.get_systems()
  File "/usr/local/lib/python3.9/site-packages/googlewifi/__init__.py", line 191, in get_systems
    return await self.structure_systems(response)
  File "/usr/local/lib/python3.9/site-packages/googlewifi/__init__.py", line 291, in structure_systems
    devices[this_station["station"]["id"]]["traffic"] = this_station["traffic"]
KeyError: 'traffic'
2021-09-01 07:18:13 ERROR (MainThread) [custom_components.googlewifi] Unexpected error fetching GoogleWifi data: 'traffic'
Traceback (most recent call last):
  File "/usr/src/homeassistant/homeassistant/helpers/update_coordinator.py", line 187, in _async_refresh
    self.data = await self._async_update_data()
  File "/config/custom_components/googlewifi/__init__.py", line 171, in _async_update_data
    system_data = await self.api.get_systems()
  File "/usr/local/lib/python3.9/site-packages/googlewifi/__init__.py", line 191, in get_systems
    return await self.structure_systems(response)
  File "/usr/local/lib/python3.9/site-packages/googlewifi/__init__.py", line 291, in structure_systems
    devices[this_station["station"]["id"]]["traffic"] = this_station["traffic"]
KeyError: 'traffic'
2021-09-01 07:18:55 ERROR (MainThread) [custom_components.googlewifi] Unexpected error fetching GoogleWifi data: 'traffic'
Traceback (most recent call last):
  File "/usr/src/homeassistant/homeassistant/helpers/update_coordinator.py", line 187, in _async_refresh
    self.data = await self._async_update_data()
  File "/config/custom_components/googlewifi/__init__.py", line 171, in _async_update_data
    system_data = await self.api.get_systems()
  File "/usr/local/lib/python3.9/site-packages/googlewifi/__init__.py", line 191, in get_systems
    return await self.structure_systems(response)
  File "/usr/local/lib/python3.9/site-packages/googlewifi/__init__.py", line 291, in structure_systems
    devices[this_station["station"]["id"]]["traffic"] = this_station["traffic"]
KeyError: 'traffic'
2021-09-01 07:34:14 ERROR (MainThread) [homeassistant.components.google_assistant.http] Request for https://homegraph.googleapis.com/v1/devices:reportStateAndNotification failed: 404
2021-09-01 07:37:06 ERROR (MainThread) [custom_components.googlewifi] Unexpected error fetching GoogleWifi data: 'traffic'
Traceback (most recent call last):
  File "/usr/src/homeassistant/homeassistant/helpers/update_coordinator.py", line 187, in _async_refresh
    self.data = await self._async_update_data()
  File "/config/custom_components/googlewifi/__init__.py", line 171, in _async_update_data
    system_data = await self.api.get_systems()
  File "/usr/local/lib/python3.9/site-packages/googlewifi/__init__.py", line 191, in get_systems
    return await self.structure_systems(response)
  File "/usr/local/lib/python3.9/site-packages/googlewifi/__init__.py", line 291, in structure_systems
    devices[this_station["station"]["id"]]["traffic"] = this_station["traffic"]
KeyError: 'traffic'
2021-09-01 07:39:53 ERROR (MainThread) [custom_components.googlewifi] Unexpected error fetching GoogleWifi data: 'traffic'
Traceback (most recent call last):
  File "/usr/src/homeassistant/homeassistant/helpers/update_coordinator.py", line 187, in _async_refresh
    self.data = await self._async_update_data()
  File "/config/custom_components/googlewifi/__init__.py", line 171, in _async_update_data
    system_data = await self.api.get_systems()
  File "/usr/local/lib/python3.9/site-packages/googlewifi/__init__.py", line 191, in get_systems
    return await self.structure_systems(response)
  File "/usr/local/lib/python3.9/site-packages/googlewifi/__init__.py", line 291, in structure_systems
    devices[this_station["station"]["id"]]["traffic"] = this_station["traffic"]
KeyError: 'traffic'
2021-09-01 07:40:34 ERROR (MainThread) [custom_components.googlewifi] Unexpected error fetching GoogleWifi data: 'traffic'
Traceback (most recent call last):
  File "/usr/src/homeassistant/homeassistant/helpers/update_coordinator.py", line 187, in _async_refresh
    self.data = await self._async_update_data()
  File "/config/custom_components/googlewifi/__init__.py", line 171, in _async_update_data
    system_data = await self.api.get_systems()
  File "/usr/local/lib/python3.9/site-packages/googlewifi/__init__.py", line 191, in get_systems
    return await self.structure_systems(response)
  File "/usr/local/lib/python3.9/site-packages/googlewifi/__init__.py", line 291, in structure_systems
    devices[this_station["station"]["id"]]["traffic"] = this_station["traffic"]
KeyError: 'traffic'
2021-09-01 07:41:15 ERROR (MainThread) [custom_components.googlewifi] Unexpected error fetching GoogleWifi data: 'traffic'
Traceback (most recent call last):
  File "/usr/src/homeassistant/homeassistant/helpers/update_coordinator.py", line 187, in _async_refresh
    self.data = await self._async_update_data()
  File "/config/custom_components/googlewifi/__init__.py", line 171, in _async_update_data
    system_data = await self.api.get_systems()
  File "/usr/local/lib/python3.9/site-packages/googlewifi/__init__.py", line 191, in get_systems
    return await self.structure_systems(response)
  File "/usr/local/lib/python3.9/site-packages/googlewifi/__init__.py", line 291, in structure_systems
    devices[this_station["station"]["id"]]["traffic"] = this_station["traffic"]
KeyError: 'traffic'
2021-09-01 08:08:26 ERROR (MainThread) [homeassistant.components.google_assistant.http] Request for https://homegraph.googleapis.com/v1/devices:reportStateAndNotification failed: 404
2021-09-01 08:17:16 ERROR (MainThread) [homeassistant.components.google_assistant.http] Request for https://homegraph.googleapis.com/v1/devices:reportStateAndNotification failed: 404
2021-09-01 08:24:27 ERROR (MainThread) [homeassistant.components.google_assistant.http] Request for https://homegraph.googleapis.com/v1/devices:reportStateAndNotification failed: 404
2021-09-01 08:38:12 ERROR (MainThread) [custom_components.googlewifi] Unexpected error fetching GoogleWifi data: 'traffic'
Traceback (most recent call last):
  File "/usr/src/homeassistant/homeassistant/helpers/update_coordinator.py", line 187, in _async_refresh
    self.data = await self._async_update_data()
  File "/config/custom_components/googlewifi/__init__.py", line 171, in _async_update_data
    system_data = await self.api.get_systems()
  File "/usr/local/lib/python3.9/site-packages/googlewifi/__init__.py", line 191, in get_systems
    return await self.structure_systems(response)
  File "/usr/local/lib/python3.9/site-packages/googlewifi/__init__.py", line 291, in structure_systems
    devices[this_station["station"]["id"]]["traffic"] = this_station["traffic"]
KeyError: 'traffic'
2021-09-01 08:41:43 ERROR (MainThread) [custom_components.googlewifi] Unexpected error fetching GoogleWifi data: 'traffic'
Traceback (most recent call last):
  File "/usr/src/homeassistant/homeassistant/helpers/update_coordinator.py", line 187, in _async_refresh
    self.data = await self._async_update_data()
  File "/config/custom_components/googlewifi/__init__.py", line 171, in _async_update_data
    system_data = await self.api.get_systems()
  File "/usr/local/lib/python3.9/site-packages/googlewifi/__init__.py", line 191, in get_systems
    return await self.structure_systems(response)
  File "/usr/local/lib/python3.9/site-packages/googlewifi/__init__.py", line 291, in structure_systems
    devices[this_station["station"]["id"]]["traffic"] = this_station["traffic"]
KeyError: 'traffic'
2021-09-01 08:42:25 ERROR (MainThread) [custom_components.googlewifi] Unexpected error fetching GoogleWifi data: 'traffic'
Traceback (most recent call last):
  File "/usr/src/homeassistant/homeassistant/helpers/update_coordinator.py", line 187, in _async_refresh
    self.data = await self._async_update_data()
  File "/config/custom_components/googlewifi/__init__.py", line 171, in _async_update_data
    system_data = await self.api.get_systems()
  File "/usr/local/lib/python3.9/site-packages/googlewifi/__init__.py", line 191, in get_systems
    return await self.structure_systems(response)
  File "/usr/local/lib/python3.9/site-packages/googlewifi/__init__.py", line 291, in structure_systems
    devices[this_station["station"]["id"]]["traffic"] = this_station["traffic"]
KeyError: 'traffic'
2021-09-01 08:43:07 ERROR (MainThread) [custom_components.googlewifi] Unexpected error fetching GoogleWifi data: 'traffic'
Traceback (most recent call last):
  File "/usr/src/homeassistant/homeassistant/helpers/update_coordinator.py", line 187, in _async_refresh
    self.data = await self._async_update_data()
  File "/config/custom_components/googlewifi/__init__.py", line 171, in _async_update_data
    system_data = await self.api.get_systems()
  File "/usr/local/lib/python3.9/site-packages/googlewifi/__init__.py", line 191, in get_systems
    return await self.structure_systems(response)
  File "/usr/local/lib/python3.9/site-packages/googlewifi/__init__.py", line 291, in structure_systems
    devices[this_station["station"]["id"]]["traffic"] = this_station["traffic"]
KeyError: 'traffic'
2021-09-01 08:51:46 WARNING (MainThread) [homeassistant.helpers.entity] Update of sensor.precip_rate_leuven24_wunderground is taking over 10 seconds
2021-09-01 08:51:46 ERROR (MainThread) [homeassistant.components.rest.data] Error fetching data: https://www.wunderground.com/dashboard/pws/ILEUVE24 failed with 
2021-09-01 08:51:46 ERROR (MainThread) [homeassistant.components.scrape.sensor] Unable to retrieve data for precip_rate_leuven24_wunderground
2021-09-01 09:02:24 ERROR (Thread-185) [pychromecast.socket_client] [Veranda speaker(192.168.86.48):8009] Failed to connect to service ServiceInfo(type='mdns', data='Nest-Audio-a9cba80c94f36e72acca1e3ab6c66816._googlecast._tcp.local.'), retrying in 5.0s
2021-09-01 09:07:28 ERROR (MainThread) [homeassistant.components.google_assistant.http] Request for https://homegraph.googleapis.com/v1/devices:reportStateAndNotification failed: 404
2021-09-01 09:17:53 WARNING (Thread-13) [pychromecast.socket_client] [Alunya speaker(192.168.86.37):8009] Heartbeat timeout, resetting connection
2021-09-01 09:18:11 ERROR (Thread-13) [pychromecast.socket_client] [Alunya speaker(192.168.86.37):8009] Failed to connect to service ServiceInfo(type='mdns', data='Google-Home-Mini-692970e69a700dfe8ff62a183e919f63._googlecast._tcp.local.'), retrying in 5.0s
2021-09-01 09:31:58 ERROR (MainThread) [custom_components.googlewifi] Unexpected error fetching GoogleWifi data: 'NoneType' object is not iterable
Traceback (most recent call last):
  File "/usr/src/homeassistant/homeassistant/helpers/update_coordinator.py", line 187, in _async_refresh
    self.data = await self._async_update_data()
  File "/config/custom_components/googlewifi/__init__.py", line 171, in _async_update_data
    system_data = await self.api.get_systems()
  File "/usr/local/lib/python3.9/site-packages/googlewifi/__init__.py", line 191, in get_systems
    return await self.structure_systems(response)
  File "/usr/local/lib/python3.9/site-packages/googlewifi/__init__.py", line 289, in structure_systems
    for this_station in system_metrics.get("stationMetrics"):
TypeError: 'NoneType' object is not iterable
2021-09-01 09:44:43 ERROR (MainThread) [custom_components.googlewifi] Unexpected error fetching GoogleWifi data: 'traffic'
Traceback (most recent call last):
  File "/usr/src/homeassistant/homeassistant/helpers/update_coordinator.py", line 187, in _async_refresh
    self.data = await self._async_update_data()
  File "/config/custom_components/googlewifi/__init__.py", line 171, in _async_update_data
    system_data = await self.api.get_systems()
  File "/usr/local/lib/python3.9/site-packages/googlewifi/__init__.py", line 191, in get_systems
    return await self.structure_systems(response)
  File "/usr/local/lib/python3.9/site-packages/googlewifi/__init__.py", line 291, in structure_systems
    devices[this_station["station"]["id"]]["traffic"] = this_station["traffic"]
KeyError: 'traffic'
2021-09-01 09:45:25 ERROR (MainThread) [custom_components.googlewifi] Unexpected error fetching GoogleWifi data: 'traffic'
Traceback (most recent call last):
  File "/usr/src/homeassistant/homeassistant/helpers/update_coordinator.py", line 187, in _async_refresh
    self.data = await self._async_update_data()
  File "/config/custom_components/googlewifi/__init__.py", line 171, in _async_update_data
    system_data = await self.api.get_systems()
  File "/usr/local/lib/python3.9/site-packages/googlewifi/__init__.py", line 191, in get_systems
    return await self.structure_systems(response)
  File "/usr/local/lib/python3.9/site-packages/googlewifi/__init__.py", line 291, in structure_systems
    devices[this_station["station"]["id"]]["traffic"] = this_station["traffic"]
KeyError: 'traffic'
2021-09-01 09:46:07 ERROR (MainThread) [custom_components.googlewifi] Unexpected error fetching GoogleWifi data: 'traffic'
Traceback (most recent call last):
  File "/usr/src/homeassistant/homeassistant/helpers/update_coordinator.py", line 187, in _async_refresh
    self.data = await self._async_update_data()
  File "/config/custom_components/googlewifi/__init__.py", line 171, in _async_update_data
    system_data = await self.api.get_systems()
  File "/usr/local/lib/python3.9/site-packages/googlewifi/__init__.py", line 191, in get_systems
    return await self.structure_systems(response)
  File "/usr/local/lib/python3.9/site-packages/googlewifi/__init__.py", line 291, in structure_systems
    devices[this_station["station"]["id"]]["traffic"] = this_station["traffic"]
KeyError: 'traffic'
2021-09-01 09:48:45 ERROR (MainThread) [homeassistant.components.google_assistant.http] Request for https://homegraph.googleapis.com/v1/devices:reportStateAndNotification failed: 404
2021-09-01 09:50:44 ERROR (MainThread) [custom_components.audiconnect.audi_connect_account] Unable to update the vehicle position of WAUZZZGE6MB019131: 204, message='No Content', url=URL('https://fal-3a.prd.eu.dp.vwg-connect.com/fs-car/bs/cf/v1/Audi/BE/vehicles/WAUZZZGE6MB019131/position')
2021-09-01 09:56:51 ERROR (MainThread) [homeassistant.components.google_assistant.http] Request for https://homegraph.googleapis.com/v1/devices:reportStateAndNotification failed: 404
2021-09-01 10:18:13 ERROR (MainThread) [custom_components.googlewifi] Unexpected error fetching GoogleWifi data: 'traffic'
Traceback (most recent call last):
  File "/usr/src/homeassistant/homeassistant/helpers/update_coordinator.py", line 187, in _async_refresh
    self.data = await self._async_update_data()
  File "/config/custom_components/googlewifi/__init__.py", line 171, in _async_update_data
    system_data = await self.api.get_systems()
  File "/usr/local/lib/python3.9/site-packages/googlewifi/__init__.py", line 191, in get_systems
    return await self.structure_systems(response)
  File "/usr/local/lib/python3.9/site-packages/googlewifi/__init__.py", line 291, in structure_systems
    devices[this_station["station"]["id"]]["traffic"] = this_station["traffic"]
KeyError: 'traffic'
2021-09-01 10:32:46 ERROR (MainThread) [homeassistant.components.google_assistant.http] Request for https://homegraph.googleapis.com/v1/devices:reportStateAndNotification failed: 404
2021-09-01 10:38:54 ERROR (MainThread) [homeassistant.components.google_assistant.http] Request for https://homegraph.googleapis.com/v1/devices:reportStateAndNotification failed: 404
2021-09-01 10:43:56 ERROR (MainThread) [custom_components.googlewifi] Unexpected error fetching GoogleWifi data: 'NoneType' object is not iterable
Traceback (most recent call last):
  File "/usr/src/homeassistant/homeassistant/helpers/update_coordinator.py", line 187, in _async_refresh
    self.data = await self._async_update_data()
  File "/config/custom_components/googlewifi/__init__.py", line 171, in _async_update_data
    system_data = await self.api.get_systems()
  File "/usr/local/lib/python3.9/site-packages/googlewifi/__init__.py", line 191, in get_systems
    return await self.structure_systems(response)
  File "/usr/local/lib/python3.9/site-packages/googlewifi/__init__.py", line 289, in structure_systems
    for this_station in system_metrics.get("stationMetrics"):
TypeError: 'NoneType' object is not iterable
2021-09-01 10:44:44 ERROR (MainThread) [custom_components.googlewifi] Unexpected error fetching GoogleWifi data: 'NoneType' object is not iterable
Traceback (most recent call last):
  File "/usr/src/homeassistant/homeassistant/helpers/update_coordinator.py", line 187, in _async_refresh
    self.data = await self._async_update_data()
  File "/config/custom_components/googlewifi/__init__.py", line 171, in _async_update_data
    system_data = await self.api.get_systems()
  File "/usr/local/lib/python3.9/site-packages/googlewifi/__init__.py", line 191, in get_systems
    return await self.structure_systems(response)
  File "/usr/local/lib/python3.9/site-packages/googlewifi/__init__.py", line 289, in structure_systems
    for this_station in system_metrics.get("stationMetrics"):
TypeError: 'NoneType' object is not iterable
2021-09-01 10:47:52 WARNING (SyncWorker_7) [buienalarm.pybuienalarm] Error fetching data safely: 502 Server Error: Bad Gateway for url: https://cdn-secure.buienalarm.nl/api/3.4/forecast.php?lat=50.878800118427755&lon=4.749415398691782&region=nl&unit=mm%2Fu
2021-09-01 11:00:57 ERROR (MainThread) [homeassistant.components.google_assistant.http] Request for https://homegraph.googleapis.com/v1/devices:reportStateAndNotification failed: 404
2021-09-01 11:07:52 WARNING (SyncWorker_1) [buienalarm.pybuienalarm] Error fetching data safely: 502 Server Error: Bad Gateway for url: https://cdn-secure.buienalarm.nl/api/3.4/forecast.php?lat=50.878800118427755&lon=4.749415398691782&region=nl&unit=mm%2Fu
2021-09-01 11:13:16 ERROR (MainThread) [custom_components.googlewifi] Unexpected error fetching GoogleWifi data: 'traffic'
Traceback (most recent call last):
  File "/usr/src/homeassistant/homeassistant/helpers/update_coordinator.py", line 187, in _async_refresh
    self.data = await self._async_update_data()
  File "/config/custom_components/googlewifi/__init__.py", line 171, in _async_update_data
    system_data = await self.api.get_systems()
  File "/usr/local/lib/python3.9/site-packages/googlewifi/__init__.py", line 191, in get_systems
    return await self.structure_systems(response)
  File "/usr/local/lib/python3.9/site-packages/googlewifi/__init__.py", line 291, in structure_systems
    devices[this_station["station"]["id"]]["traffic"] = this_station["traffic"]
KeyError: 'traffic'
2021-09-01 11:14:00 ERROR (MainThread) [custom_components.googlewifi] Unexpected error fetching GoogleWifi data: 'traffic'
Traceback (most recent call last):
  File "/usr/src/homeassistant/homeassistant/helpers/update_coordinator.py", line 187, in _async_refresh
    self.data = await self._async_update_data()
  File "/config/custom_components/googlewifi/__init__.py", line 171, in _async_update_data
    system_data = await self.api.get_systems()
  File "/usr/local/lib/python3.9/site-packages/googlewifi/__init__.py", line 191, in get_systems
    return await self.structure_systems(response)
  File "/usr/local/lib/python3.9/site-packages/googlewifi/__init__.py", line 291, in structure_systems
    devices[this_station["station"]["id"]]["traffic"] = this_station["traffic"]
KeyError: 'traffic'
2021-09-01 11:14:42 ERROR (MainThread) [custom_components.googlewifi] Unexpected error fetching GoogleWifi data: 'traffic'
Traceback (most recent call last):
  File "/usr/src/homeassistant/homeassistant/helpers/update_coordinator.py", line 187, in _async_refresh
    self.data = await self._async_update_data()
  File "/config/custom_components/googlewifi/__init__.py", line 171, in _async_update_data
    system_data = await self.api.get_systems()
  File "/usr/local/lib/python3.9/site-packages/googlewifi/__init__.py", line 191, in get_systems
    return await self.structure_systems(response)
  File "/usr/local/lib/python3.9/site-packages/googlewifi/__init__.py", line 291, in structure_systems
    devices[this_station["station"]["id"]]["traffic"] = this_station["traffic"]
KeyError: 'traffic'
2021-09-01 11:15:26 ERROR (MainThread) [custom_components.googlewifi] Unexpected error fetching GoogleWifi data: 'traffic'
Traceback (most recent call last):
  File "/usr/src/homeassistant/homeassistant/helpers/update_coordinator.py", line 187, in _async_refresh
    self.data = await self._async_update_data()
  File "/config/custom_components/googlewifi/__init__.py", line 171, in _async_update_data
    system_data = await self.api.get_systems()
  File "/usr/local/lib/python3.9/site-packages/googlewifi/__init__.py", line 191, in get_systems
    return await self.structure_systems(response)
  File "/usr/local/lib/python3.9/site-packages/googlewifi/__init__.py", line 291, in structure_systems
    devices[this_station["station"]["id"]]["traffic"] = this_station["traffic"]
KeyError: 'traffic'
2021-09-01 11:16:09 ERROR (MainThread) [custom_components.googlewifi] Unexpected error fetching GoogleWifi data: 'traffic'
Traceback (most recent call last):
  File "/usr/src/homeassistant/homeassistant/helpers/update_coordinator.py", line 187, in _async_refresh
    self.data = await self._async_update_data()
  File "/config/custom_components/googlewifi/__init__.py", line 171, in _async_update_data
    system_data = await self.api.get_systems()
  File "/usr/local/lib/python3.9/site-packages/googlewifi/__init__.py", line 191, in get_systems
    return await self.structure_systems(response)
  File "/usr/local/lib/python3.9/site-packages/googlewifi/__init__.py", line 291, in structure_systems
    devices[this_station["station"]["id"]]["traffic"] = this_station["traffic"]
KeyError: 'traffic'
2021-09-01 11:22:28 ERROR (MainThread) [homeassistant.components.google_assistant.http] Request for https://homegraph.googleapis.com/v1/devices:reportStateAndNotification failed: 404
2021-09-01 11:27:30 ERROR (MainThread) [custom_components.googlewifi] Error fetching GoogleWifi data: Error connecting to GoogleWifi: 
2021-09-01 11:27:52 WARNING (SyncWorker_7) [buienalarm.pybuienalarm] Error fetching data safely: 502 Server Error: Bad Gateway for url: https://cdn-secure.buienalarm.nl/api/3.4/forecast.php?lat=50.878800118427755&lon=4.749415398691782&region=nl&unit=mm%2Fu
2021-09-01 11:36:59 ERROR (MainThread) [homeassistant.components.google_assistant.http] Request for https://homegraph.googleapis.com/v1/devices:reportStateAndNotification failed: 404
2021-09-01 11:41:35 ERROR (MainThread) [custom_components.audiconnect.audi_connect_account] Login to Audi service failed, trying again in 10 seconds
2021-09-01 11:42:55 ERROR (MainThread) [custom_components.googlewifi] Unexpected error fetching GoogleWifi data: 'NoneType' object is not iterable
Traceback (most recent call last):
  File "/usr/src/homeassistant/homeassistant/helpers/update_coordinator.py", line 187, in _async_refresh
    self.data = await self._async_update_data()
  File "/config/custom_components/googlewifi/__init__.py", line 171, in _async_update_data
    system_data = await self.api.get_systems()
  File "/usr/local/lib/python3.9/site-packages/googlewifi/__init__.py", line 191, in get_systems
    return await self.structure_systems(response)
  File "/usr/local/lib/python3.9/site-packages/googlewifi/__init__.py", line 289, in structure_systems
    for this_station in system_metrics.get("stationMetrics"):
TypeError: 'NoneType' object is not iterable
2021-09-01 11:47:52 WARNING (SyncWorker_7) [buienalarm.pybuienalarm] Error fetching data safely: 502 Server Error: Bad Gateway for url: https://cdn-secure.buienalarm.nl/api/3.4/forecast.php?lat=50.878800118427755&lon=4.749415398691782&region=nl&unit=mm%2Fu
2021-09-01 11:51:07 ERROR (MainThread) [homeassistant.components.google_assistant.http] Request for https://homegraph.googleapis.com/v1/devices:reportStateAndNotification failed: 404
2021-09-01 11:52:07 ERROR (MainThread) [custom_components.audiconnect.audi_connect_account] Login to Audi service failed, trying again in 10 seconds
2021-09-01 11:52:19 ERROR (MainThread) [custom_components.googlewifi] Unexpected error fetching GoogleWifi data: 'traffic'
Traceback (most recent call last):
  File "/usr/src/homeassistant/homeassistant/helpers/update_coordinator.py", line 187, in _async_refresh
    self.data = await self._async_update_data()
  File "/config/custom_components/googlewifi/__init__.py", line 171, in _async_update_data
    system_data = await self.api.get_systems()
  File "/usr/local/lib/python3.9/site-packages/googlewifi/__init__.py", line 191, in get_systems
    return await self.structure_systems(response)
  File "/usr/local/lib/python3.9/site-packages/googlewifi/__init__.py", line 291, in structure_systems
    devices[this_station["station"]["id"]]["traffic"] = this_station["traffic"]
KeyError: 'traffic'
2021-09-01 11:52:34 ERROR (MainThread) [custom_components.audiconnect.audi_connect_account] Login to Audi service failed, trying again in 10 seconds
2021-09-01 11:52:55 ERROR (MainThread) [custom_components.audiconnect.audi_connect_account] Login to Audi service failed: Timeout error
2021-09-01 11:58:41 ERROR (MainThread) [custom_components.googlewifi] Unexpected error fetching GoogleWifi data: 'traffic'
Traceback (most recent call last):
  File "/usr/src/homeassistant/homeassistant/helpers/update_coordinator.py", line 187, in _async_refresh
    self.data = await self._async_update_data()
  File "/config/custom_components/googlewifi/__init__.py", line 171, in _async_update_data
    system_data = await self.api.get_systems()
  File "/usr/local/lib/python3.9/site-packages/googlewifi/__init__.py", line 191, in get_systems
    return await self.structure_systems(response)
  File "/usr/local/lib/python3.9/site-packages/googlewifi/__init__.py", line 291, in structure_systems
    devices[this_station["station"]["id"]]["traffic"] = this_station["traffic"]
KeyError: 'traffic'
2021-09-01 12:03:05 ERROR (MainThread) [custom_components.audiconnect.audi_connect_account] Login to Audi service failed, trying again in 10 seconds
2021-09-01 12:03:29 ERROR (MainThread) [custom_components.audiconnect.audi_connect_account] Login to Audi service failed, trying again in 10 seconds
2021-09-01 12:07:52 WARNING (SyncWorker_9) [buienalarm.pybuienalarm] Error fetching data safely: 502 Server Error: Bad Gateway for url: https://cdn-secure.buienalarm.nl/api/3.4/forecast.php?lat=50.878800118427755&lon=4.749415398691782&region=nl&unit=mm%2Fu
2021-09-01 12:12:39 ERROR (MainThread) [homeassistant.components.google_assistant.http] Request for https://homegraph.googleapis.com/v1/devices:reportStateAndNotification failed: 404
2021-09-01 12:13:57 ERROR (MainThread) [custom_components.audiconnect.audi_connect_account] Login to Audi service failed, trying again in 10 seconds
2021-09-01 12:14:17 ERROR (MainThread) [custom_components.audiconnect.audi_connect_account] Login to Audi service failed, trying again in 10 seconds
2021-09-01 12:14:27 ERROR (MainThread) [custom_components.audiconnect.audi_connect_account] Login to Audi service failed: 503, message='Service Unavailable', url=URL('https://app-api.live-my.audi.com/myaudiappidk/v1/openid-configuration')
2021-09-01 12:22:29 ERROR (MainThread) [custom_components.googlewifi] Unexpected error fetching GoogleWifi data: 'traffic'
Traceback (most recent call last):
  File "/usr/src/homeassistant/homeassistant/helpers/update_coordinator.py", line 187, in _async_refresh
    self.data = await self._async_update_data()
  File "/config/custom_components/googlewifi/__init__.py", line 171, in _async_update_data
    system_data = await self.api.get_systems()
  File "/usr/local/lib/python3.9/site-packages/googlewifi/__init__.py", line 191, in get_systems
    return await self.structure_systems(response)
  File "/usr/local/lib/python3.9/site-packages/googlewifi/__init__.py", line 291, in structure_systems
    devices[this_station["station"]["id"]]["traffic"] = this_station["traffic"]
KeyError: 'traffic'
2021-09-01 12:27:08 ERROR (MainThread) [homeassistant.components.google_assistant.http] Request for https://homegraph.googleapis.com/v1/devices:reportStateAndNotification failed: 404
2021-09-01 12:27:52 WARNING (SyncWorker_0) [buienalarm.pybuienalarm] Error fetching data safely: 502 Server Error: Bad Gateway for url: https://cdn-secure.buienalarm.nl/api/3.4/forecast.php?lat=50.878800118427755&lon=4.749415398691782&region=nl&unit=mm%2Fu
2021-09-01 12:51:04 ERROR (MainThread) [custom_components.googlewifi] Unexpected error fetching GoogleWifi data: 'NoneType' object is not iterable
Traceback (most recent call last):
  File "/usr/src/homeassistant/homeassistant/helpers/update_coordinator.py", line 187, in _async_refresh
    self.data = await self._async_update_data()
  File "/config/custom_components/googlewifi/__init__.py", line 171, in _async_update_data
    system_data = await self.api.get_systems()
  File "/usr/local/lib/python3.9/site-packages/googlewifi/__init__.py", line 191, in get_systems
    return await self.structure_systems(response)
  File "/usr/local/lib/python3.9/site-packages/googlewifi/__init__.py", line 289, in structure_systems
    for this_station in system_metrics.get("stationMetrics"):
TypeError: 'NoneType' object is not iterable
2021-09-01 13:00:21 ERROR (MainThread) [custom_components.googlewifi] Unexpected error fetching GoogleWifi data: 'traffic'
Traceback (most recent call last):
  File "/usr/src/homeassistant/homeassistant/helpers/update_coordinator.py", line 187, in _async_refresh
    self.data = await self._async_update_data()
  File "/config/custom_components/googlewifi/__init__.py", line 171, in _async_update_data
    system_data = await self.api.get_systems()
  File "/usr/local/lib/python3.9/site-packages/googlewifi/__init__.py", line 191, in get_systems
    return await self.structure_systems(response)
  File "/usr/local/lib/python3.9/site-packages/googlewifi/__init__.py", line 291, in structure_systems
    devices[this_station["station"]["id"]]["traffic"] = this_station["traffic"]
KeyError: 'traffic'
2021-09-01 13:01:05 ERROR (MainThread) [custom_components.googlewifi] Unexpected error fetching GoogleWifi data: 'traffic'
Traceback (most recent call last):
  File "/usr/src/homeassistant/homeassistant/helpers/update_coordinator.py", line 187, in _async_refresh
    self.data = await self._async_update_data()
  File "/config/custom_components/googlewifi/__init__.py", line 171, in _async_update_data
    system_data = await self.api.get_systems()
  File "/usr/local/lib/python3.9/site-packages/googlewifi/__init__.py", line 191, in get_systems
    return await self.structure_systems(response)
  File "/usr/local/lib/python3.9/site-packages/googlewifi/__init__.py", line 291, in structure_systems
    devices[this_station["station"]["id"]]["traffic"] = this_station["traffic"]
KeyError: 'traffic'
2021-09-01 13:01:48 ERROR (MainThread) [custom_components.googlewifi] Unexpected error fetching GoogleWifi data: 'traffic'
Traceback (most recent call last):
  File "/usr/src/homeassistant/homeassistant/helpers/update_coordinator.py", line 187, in _async_refresh
    self.data = await self._async_update_data()
  File "/config/custom_components/googlewifi/__init__.py", line 171, in _async_update_data
    system_data = await self.api.get_systems()
  File "/usr/local/lib/python3.9/site-packages/googlewifi/__init__.py", line 191, in get_systems
    return await self.structure_systems(response)
  File "/usr/local/lib/python3.9/site-packages/googlewifi/__init__.py", line 291, in structure_systems
    devices[this_station["station"]["id"]]["traffic"] = this_station["traffic"]
KeyError: 'traffic'
2021-09-01 13:02:32 ERROR (MainThread) [custom_components.googlewifi] Unexpected error fetching GoogleWifi data: 'traffic'
Traceback (most recent call last):
  File "/usr/src/homeassistant/homeassistant/helpers/update_coordinator.py", line 187, in _async_refresh
    self.data = await self._async_update_data()
  File "/config/custom_components/googlewifi/__init__.py", line 171, in _async_update_data
    system_data = await self.api.get_systems()
  File "/usr/local/lib/python3.9/site-packages/googlewifi/__init__.py", line 191, in get_systems
    return await self.structure_systems(response)
  File "/usr/local/lib/python3.9/site-packages/googlewifi/__init__.py", line 291, in structure_systems
    devices[this_station["station"]["id"]]["traffic"] = this_station["traffic"]
KeyError: 'traffic'
2021-09-01 13:02:49 ERROR (MainThread) [homeassistant.components.google_assistant.http] Request for https://homegraph.googleapis.com/v1/devices:reportStateAndNotification failed: 404
2021-09-01 13:03:17 ERROR (MainThread) [custom_components.googlewifi] Unexpected error fetching GoogleWifi data: 'traffic'
Traceback (most recent call last):
  File "/usr/src/homeassistant/homeassistant/helpers/update_coordinator.py", line 187, in _async_refresh
    self.data = await self._async_update_data()
  File "/config/custom_components/googlewifi/__init__.py", line 171, in _async_update_data
    system_data = await self.api.get_systems()
  File "/usr/local/lib/python3.9/site-packages/googlewifi/__init__.py", line 191, in get_systems
    return await self.structure_systems(response)
  File "/usr/local/lib/python3.9/site-packages/googlewifi/__init__.py", line 291, in structure_systems
    devices[this_station["station"]["id"]]["traffic"] = this_station["traffic"]
KeyError: 'traffic'
2021-09-01 13:05:25 ERROR (MainThread) [custom_components.googlewifi] Unexpected error fetching GoogleWifi data: 'traffic'
Traceback (most recent call last):
  File "/usr/src/homeassistant/homeassistant/helpers/update_coordinator.py", line 187, in _async_refresh
    self.data = await self._async_update_data()
  File "/config/custom_components/googlewifi/__init__.py", line 171, in _async_update_data
    system_data = await self.api.get_systems()
  File "/usr/local/lib/python3.9/site-packages/googlewifi/__init__.py", line 191, in get_systems
    return await self.structure_systems(response)
  File "/usr/local/lib/python3.9/site-packages/googlewifi/__init__.py", line 291, in structure_systems
    devices[this_station["station"]["id"]]["traffic"] = this_station["traffic"]
KeyError: 'traffic'
2021-09-01 13:07:52 WARNING (SyncWorker_7) [buienalarm.pybuienalarm] Error fetching data safely: 502 Server Error: Bad Gateway for url: https://cdn-secure.buienalarm.nl/api/3.4/forecast.php?lat=50.878800118427755&lon=4.749415398691782&region=nl&unit=mm%2Fu
2021-09-01 13:14:59 ERROR (MainThread) [custom_components.audiconnect.audi_connect_account] Login to Audi service failed, trying again in 10 seconds
2021-09-01 13:17:19 ERROR (MainThread) [homeassistant.components.google_assistant.http] Request for https://homegraph.googleapis.com/v1/devices:reportStateAndNotification failed: 404
2021-09-01 13:17:25 ERROR (MainThread) [homeassistant.components.google_assistant.http] Request for https://homegraph.googleapis.com/v1/devices:reportStateAndNotification failed: 404
2021-09-01 13:22:45 ERROR (MainThread) [custom_components.googlewifi] Unexpected error fetching GoogleWifi data: 'traffic'
Traceback (most recent call last):
  File "/usr/src/homeassistant/homeassistant/helpers/update_coordinator.py", line 187, in _async_refresh
    self.data = await self._async_update_data()
  File "/config/custom_components/googlewifi/__init__.py", line 171, in _async_update_data
    system_data = await self.api.get_systems()
  File "/usr/local/lib/python3.9/site-packages/googlewifi/__init__.py", line 191, in get_systems
    return await self.structure_systems(response)
  File "/usr/local/lib/python3.9/site-packages/googlewifi/__init__.py", line 291, in structure_systems
    devices[this_station["station"]["id"]]["traffic"] = this_station["traffic"]
KeyError: 'traffic'
2021-09-01 13:27:52 WARNING (SyncWorker_8) [buienalarm.pybuienalarm] Error fetching data safely: 502 Server Error: Bad Gateway for url: https://cdn-secure.buienalarm.nl/api/3.4/forecast.php?lat=50.878800118427755&lon=4.749415398691782&region=nl&unit=mm%2Fu
2021-09-01 13:31:31 ERROR (MainThread) [homeassistant.components.google_assistant.http] Request for https://homegraph.googleapis.com/v1/devices:reportStateAndNotification failed: 404
2021-09-01 13:37:19 ERROR (MainThread) [custom_components.googlewifi] Error fetching GoogleWifi data: Error connecting to GoogleWifi: 
2021-09-01 13:47:52 WARNING (SyncWorker_10) [buienalarm.pybuienalarm] Error fetching data safely: 502 Server Error: Bad Gateway for url: https://cdn-secure.buienalarm.nl/api/3.4/forecast.php?lat=50.878800118427755&lon=4.749415398691782&region=nl&unit=mm%2Fu
2021-09-01 14:07:30 ERROR (MainThread) [homeassistant.components.google_assistant.http] Request for https://homegraph.googleapis.com/v1/devices:reportStateAndNotification failed: 404
2021-09-01 14:07:52 WARNING (SyncWorker_5) [buienalarm.pybuienalarm] Error fetching data safely: 502 Server Error: Bad Gateway for url: https://cdn-secure.buienalarm.nl/api/3.4/forecast.php?lat=50.878800118427755&lon=4.749415398691782&region=nl&unit=mm%2Fu
2021-09-01 14:08:32 ERROR (MainThread) [homeassistant.components.google_assistant.http] Request for https://homegraph.googleapis.com/v1/devices:reportStateAndNotification failed: 404
2021-09-01 14:21:44 ERROR (MainThread) [homeassistant.components.google_assistant.http] Request for https://homegraph.googleapis.com/v1/devices:reportStateAndNotification failed: 404
2021-09-01 14:27:16 ERROR (MainThread) [custom_components.googlewifi] Unexpected error fetching GoogleWifi data: 'traffic'
Traceback (most recent call last):
  File "/usr/src/homeassistant/homeassistant/helpers/update_coordinator.py", line 187, in _async_refresh
    self.data = await self._async_update_data()
  File "/config/custom_components/googlewifi/__init__.py", line 171, in _async_update_data
    system_data = await self.api.get_systems()
  File "/usr/local/lib/python3.9/site-packages/googlewifi/__init__.py", line 191, in get_systems
    return await self.structure_systems(response)
  File "/usr/local/lib/python3.9/site-packages/googlewifi/__init__.py", line 291, in structure_systems
    devices[this_station["station"]["id"]]["traffic"] = this_station["traffic"]
KeyError: 'traffic'
2021-09-01 14:27:52 WARNING (SyncWorker_11) [buienalarm.pybuienalarm] Error fetching data safely: 502 Server Error: Bad Gateway for url: https://cdn-secure.buienalarm.nl/api/3.4/forecast.php?lat=50.878800118427755&lon=4.749415398691782&region=nl&unit=mm%2Fu
2021-09-01 14:47:52 WARNING (SyncWorker_6) [buienalarm.pybuienalarm] Error fetching data safely: 502 Server Error: Bad Gateway for url: https://cdn-secure.buienalarm.nl/api/3.4/forecast.php?lat=50.878800118427755&lon=4.749415398691782&region=nl&unit=mm%2Fu
2021-09-01 14:58:41 ERROR (MainThread) [homeassistant.components.google_assistant.http] Request for https://homegraph.googleapis.com/v1/devices:reportStateAndNotification failed: 404
2021-09-01 15:07:52 WARNING (SyncWorker_2) [buienalarm.pybuienalarm] Error fetching data safely: 502 Server Error: Bad Gateway for url: https://cdn-secure.buienalarm.nl/api/3.4/forecast.php?lat=50.878800118427755&lon=4.749415398691782&region=nl&unit=mm%2Fu
2021-09-01 15:21:05 WARNING (SyncWorker_8) [homeassistant.util.yaml.loader] YAML file /config/packages/uv_index.yaml contains duplicate key "channel". Check lines 90 and 91
2021-09-01 15:21:05 ERROR (MainThread) [homeassistant.config] Invalid config for [automation]: [title] is an invalid option for [automation]. Check: automation->action->1->title. (See ?, line ?). 
2021-09-01 15:21:06 ERROR (MainThread) [homeassistant.config] Invalid config for [automation]: invalid template (TemplateSyntaxError: expected token ',', got 'sensor') for dictionary value @ data['action'][0]['data']. Got None. (See ?, line ?). 
2021-09-01 15:21:06 ERROR (MainThread) [homeassistant.config] Invalid config for [automation]: invalid template (TemplateSyntaxError: expected token ',', got 'sensor') for dictionary value @ data['action'][0]['data']. Got None. (See ?, line ?). 
2021-09-01 15:21:06 ERROR (MainThread) [homeassistant.config] Invalid config for [automation]: invalid template (TemplateSyntaxError: expected token ',', got 'sensor') for dictionary value @ data['action'][0]['data']. Got None. (See ?, line ?). 
2021-09-01 15:21:06 ERROR (MainThread) [homeassistant.config] Invalid config for [automation]: required key not provided @ data['action'][4]['domain']. Got None. (See ?, line ?). 
2021-09-01 15:21:10 WARNING (SyncWorker_1) [homeassistant.util.yaml.loader] YAML file /config/packages/uv_index.yaml contains duplicate key "channel". Check lines 90 and 91
2021-09-01 15:21:10 ERROR (MainThread) [homeassistant.config] Invalid config for [automation]: [title] is an invalid option for [automation]. Check: automation->action->1->title. (See ?, line ?). 
2021-09-01 15:21:10 ERROR (MainThread) [homeassistant.config] Invalid config for [automation]: invalid template (TemplateSyntaxError: expected token ',', got 'sensor') for dictionary value @ data['action'][0]['data']. Got None. (See ?, line ?). 
2021-09-01 15:21:10 ERROR (MainThread) [homeassistant.config] Invalid config for [automation]: invalid template (TemplateSyntaxError: expected token ',', got 'sensor') for dictionary value @ data['action'][0]['data']. Got None. (See ?, line ?). 
2021-09-01 15:21:10 ERROR (MainThread) [homeassistant.config] Invalid config for [automation]: invalid template (TemplateSyntaxError: expected token ',', got 'sensor') for dictionary value @ data['action'][0]['data']. Got None. (See ?, line ?). 
2021-09-01 15:21:10 ERROR (MainThread) [homeassistant.config] Invalid config for [automation]: required key not provided @ data['action'][4]['domain']. Got None. (See ?, line ?). 
2021-09-01 15:27:52 WARNING (SyncWorker_5) [buienalarm.pybuienalarm] Error fetching data safely: 502 Server Error: Bad Gateway for url: https://cdn-secure.buienalarm.nl/api/3.4/forecast.php?lat=50.878800118427755&lon=4.749415398691782&region=nl&unit=mm%2Fu
2021-09-01 15:31:53 ERROR (MainThread) [custom_components.googlewifi] Unexpected error fetching GoogleWifi data: 'traffic'
Traceback (most recent call last):
  File "/usr/src/homeassistant/homeassistant/helpers/update_coordinator.py", line 187, in _async_refresh
    self.data = await self._async_update_data()
  File "/config/custom_components/googlewifi/__init__.py", line 171, in _async_update_data
    system_data = await self.api.get_systems()
  File "/usr/local/lib/python3.9/site-packages/googlewifi/__init__.py", line 191, in get_systems
    return await self.structure_systems(response)
  File "/usr/local/lib/python3.9/site-packages/googlewifi/__init__.py", line 291, in structure_systems
    devices[this_station["station"]["id"]]["traffic"] = this_station["traffic"]
KeyError: 'traffic'
2021-09-01 15:32:34 ERROR (MainThread) [custom_components.googlewifi] Unexpected error fetching GoogleWifi data: 'traffic'
Traceback (most recent call last):
  File "/usr/src/homeassistant/homeassistant/helpers/update_coordinator.py", line 187, in _async_refresh
    self.data = await self._async_update_data()
  File "/config/custom_components/googlewifi/__init__.py", line 171, in _async_update_data
    system_data = await self.api.get_systems()
  File "/usr/local/lib/python3.9/site-packages/googlewifi/__init__.py", line 191, in get_systems
    return await self.structure_systems(response)
  File "/usr/local/lib/python3.9/site-packages/googlewifi/__init__.py", line 291, in structure_systems
    devices[this_station["station"]["id"]]["traffic"] = this_station["traffic"]
KeyError: 'traffic'
2021-09-01 15:33:23 ERROR (MainThread) [homeassistant.components.google_assistant.http] Request for https://homegraph.googleapis.com/v1/devices:reportStateAndNotification failed: 404
2021-09-01 15:33:45 ERROR (MainThread) [custom_components.googlewifi] Unexpected error fetching GoogleWifi data: 'traffic'
Traceback (most recent call last):
  File "/usr/src/homeassistant/homeassistant/helpers/update_coordinator.py", line 187, in _async_refresh
    self.data = await self._async_update_data()
  File "/config/custom_components/googlewifi/__init__.py", line 171, in _async_update_data
    system_data = await self.api.get_systems()
  File "/usr/local/lib/python3.9/site-packages/googlewifi/__init__.py", line 191, in get_systems
    return await self.structure_systems(response)
  File "/usr/local/lib/python3.9/site-packages/googlewifi/__init__.py", line 291, in structure_systems
    devices[this_station["station"]["id"]]["traffic"] = this_station["traffic"]
KeyError: 'traffic'
2021-09-01 15:34:28 ERROR (MainThread) [custom_components.googlewifi] Unexpected error fetching GoogleWifi data: 'traffic'
Traceback (most recent call last):
  File "/usr/src/homeassistant/homeassistant/helpers/update_coordinator.py", line 187, in _async_refresh
    self.data = await self._async_update_data()
  File "/config/custom_components/googlewifi/__init__.py", line 171, in _async_update_data
    system_data = await self.api.get_systems()
  File "/usr/local/lib/python3.9/site-packages/googlewifi/__init__.py", line 191, in get_systems
    return await self.structure_systems(response)
  File "/usr/local/lib/python3.9/site-packages/googlewifi/__init__.py", line 291, in structure_systems
    devices[this_station["station"]["id"]]["traffic"] = this_station["traffic"]
KeyError: 'traffic'
2021-09-01 15:35:11 ERROR (MainThread) [custom_components.googlewifi] Unexpected error fetching GoogleWifi data: 'traffic'
Traceback (most recent call last):
  File "/usr/src/homeassistant/homeassistant/helpers/update_coordinator.py", line 187, in _async_refresh
    self.data = await self._async_update_data()
  File "/config/custom_components/googlewifi/__init__.py", line 171, in _async_update_data
    system_data = await self.api.get_systems()
  File "/usr/local/lib/python3.9/site-packages/googlewifi/__init__.py", line 191, in get_systems
    return await self.structure_systems(response)
  File "/usr/local/lib/python3.9/site-packages/googlewifi/__init__.py", line 291, in structure_systems
    devices[this_station["station"]["id"]]["traffic"] = this_station["traffic"]
KeyError: 'traffic'
2021-09-01 15:36:25 ERROR (MainThread) [custom_components.audiconnect.audi_connect_account] Login to Audi service failed, trying again in 10 seconds
2021-09-01 15:36:45 ERROR (MainThread) [custom_components.audiconnect.audi_connect_account] Login to Audi service failed, trying again in 10 seconds
2021-09-01 15:37:05 ERROR (MainThread) [custom_components.audiconnect.audi_connect_account] Login to Audi service failed: Timeout error
2021-09-01 15:43:56 ERROR (MainThread) [custom_components.googlewifi] Unexpected error fetching GoogleWifi data: 'NoneType' object is not iterable
Traceback (most recent call last):
  File "/usr/src/homeassistant/homeassistant/helpers/update_coordinator.py", line 187, in _async_refresh
    self.data = await self._async_update_data()
  File "/config/custom_components/googlewifi/__init__.py", line 171, in _async_update_data
    system_data = await self.api.get_systems()
  File "/usr/local/lib/python3.9/site-packages/googlewifi/__init__.py", line 191, in get_systems
    return await self.structure_systems(response)
  File "/usr/local/lib/python3.9/site-packages/googlewifi/__init__.py", line 289, in structure_systems
    for this_station in system_metrics.get("stationMetrics"):
TypeError: 'NoneType' object is not iterable
2021-09-01 15:47:52 WARNING (SyncWorker_7) [buienalarm.pybuienalarm] Error fetching data safely: 502 Server Error: Bad Gateway for url: https://cdn-secure.buienalarm.nl/api/3.4/forecast.php?lat=50.878800118427755&lon=4.749415398691782&region=nl&unit=mm%2Fu
2021-09-01 16:02:05 ERROR (MainThread) [homeassistant.components.google_assistant.http] Request for https://homegraph.googleapis.com/v1/devices:reportStateAndNotification failed: 404
2021-09-01 16:07:52 WARNING (SyncWorker_6) [buienalarm.pybuienalarm] Error fetching data safely: 502 Server Error: Bad Gateway for url: https://cdn-secure.buienalarm.nl/api/3.4/forecast.php?lat=50.878800118427755&lon=4.749415398691782&region=nl&unit=mm%2Fu
2021-09-01 16:18:43 ERROR (MainThread) [custom_components.googlewifi] Unexpected error fetching GoogleWifi data: 'traffic'
Traceback (most recent call last):
  File "/usr/src/homeassistant/homeassistant/helpers/update_coordinator.py", line 187, in _async_refresh
    self.data = await self._async_update_data()
  File "/config/custom_components/googlewifi/__init__.py", line 171, in _async_update_data
    system_data = await self.api.get_systems()
  File "/usr/local/lib/python3.9/site-packages/googlewifi/__init__.py", line 191, in get_systems
    return await self.structure_systems(response)
  File "/usr/local/lib/python3.9/site-packages/googlewifi/__init__.py", line 291, in structure_systems
    devices[this_station["station"]["id"]]["traffic"] = this_station["traffic"]
KeyError: 'traffic'
2021-09-01 16:19:24 ERROR (MainThread) [custom_components.googlewifi] Unexpected error fetching GoogleWifi data: 'traffic'
Traceback (most recent call last):
  File "/usr/src/homeassistant/homeassistant/helpers/update_coordinator.py", line 187, in _async_refresh
    self.data = await self._async_update_data()
  File "/config/custom_components/googlewifi/__init__.py", line 171, in _async_update_data
    system_data = await self.api.get_systems()
  File "/usr/local/lib/python3.9/site-packages/googlewifi/__init__.py", line 191, in get_systems
    return await self.structure_systems(response)
  File "/usr/local/lib/python3.9/site-packages/googlewifi/__init__.py", line 291, in structure_systems
    devices[this_station["station"]["id"]]["traffic"] = this_station["traffic"]
KeyError: 'traffic'
2021-09-01 16:20:06 ERROR (MainThread) [custom_components.googlewifi] Unexpected error fetching GoogleWifi data: 'traffic'
Traceback (most recent call last):
  File "/usr/src/homeassistant/homeassistant/helpers/update_coordinator.py", line 187, in _async_refresh
    self.data = await self._async_update_data()
  File "/config/custom_components/googlewifi/__init__.py", line 171, in _async_update_data
    system_data = await self.api.get_systems()
  File "/usr/local/lib/python3.9/site-packages/googlewifi/__init__.py", line 191, in get_systems
    return await self.structure_systems(response)
  File "/usr/local/lib/python3.9/site-packages/googlewifi/__init__.py", line 291, in structure_systems
    devices[this_station["station"]["id"]]["traffic"] = this_station["traffic"]
KeyError: 'traffic'
2021-09-01 16:23:32 ERROR (MainThread) [homeassistant.components.google_assistant.http] Request for https://homegraph.googleapis.com/v1/devices:reportStateAndNotification failed: 404
2021-09-01 16:27:52 WARNING (SyncWorker_6) [buienalarm.pybuienalarm] Error fetching data safely: 502 Server Error: Bad Gateway for url: https://cdn-secure.buienalarm.nl/api/3.4/forecast.php?lat=50.878800118427755&lon=4.749415398691782&region=nl&unit=mm%2Fu
2021-09-01 16:47:52 WARNING (SyncWorker_1) [buienalarm.pybuienalarm] Error fetching data safely: 502 Server Error: Bad Gateway for url: https://cdn-secure.buienalarm.nl/api/3.4/forecast.php?lat=50.878800118427755&lon=4.749415398691782&region=nl&unit=mm%2Fu
2021-09-01 16:50:14 ERROR (MainThread) [custom_components.googlewifi] Error fetching GoogleWifi data: Error connecting to GoogleWifi: 
2021-09-01 16:59:51 ERROR (MainThread) [custom_components.afvalbeheer.sensor] Error occurred while fetching data: ConnectionError(MaxRetryError("HTTPSConnectionPool(host='recycleapp.be', port=443): Max retries exceeded with url: /api/app/v1/access-token (Caused by NewConnectionError('<urllib3.connection.HTTPSConnection object at 0xffff5ada3b50>: Failed to establish a new connection: [Errno 110] Operation timed out'))"))
2021-09-01 17:07:35 ERROR (MainThread) [custom_components.audiconnect.audi_connect_account] Login to Audi service failed, trying again in 10 seconds
2021-09-01 17:07:52 WARNING (SyncWorker_0) [buienalarm.pybuienalarm] Error fetching data safely: 502 Server Error: Bad Gateway for url: https://cdn-secure.buienalarm.nl/api/3.4/forecast.php?lat=50.878800118427755&lon=4.749415398691782&region=nl&unit=mm%2Fu
2021-09-01 17:13:46 ERROR (MainThread) [homeassistant.components.google_assistant.http] Request for https://homegraph.googleapis.com/v1/devices:reportStateAndNotification failed: 404
2021-09-01 17:27:52 WARNING (SyncWorker_10) [buienalarm.pybuienalarm] Error fetching data safely: 502 Server Error: Bad Gateway for url: https://cdn-secure.buienalarm.nl/api/3.4/forecast.php?lat=50.878800118427755&lon=4.749415398691782&region=nl&unit=mm%2Fu
2021-09-01 17:35:36 ERROR (MainThread) [custom_components.googlewifi] Unexpected error fetching GoogleWifi data: 'traffic'
Traceback (most recent call last):
  File "/usr/src/homeassistant/homeassistant/helpers/update_coordinator.py", line 187, in _async_refresh
    self.data = await self._async_update_data()
  File "/config/custom_components/googlewifi/__init__.py", line 171, in _async_update_data
    system_data = await self.api.get_systems()
  File "/usr/local/lib/python3.9/site-packages/googlewifi/__init__.py", line 191, in get_systems
    return await self.structure_systems(response)
  File "/usr/local/lib/python3.9/site-packages/googlewifi/__init__.py", line 291, in structure_systems
    devices[this_station["station"]["id"]]["traffic"] = this_station["traffic"]
KeyError: 'traffic'
2021-09-01 17:45:44 ERROR (SyncWorker_2) [homeassistant.util.yaml.loader] while scanning a simple key
  in "/config/groups.yaml", line 32, column 1
could not find expected ':'
  in "/config/groups.yaml", line 33, column 7
2021-09-01 17:45:44 ERROR (MainThread) [homeassistant.components.group] while scanning a simple key
  in "/config/groups.yaml", line 32, column 1
could not find expected ':'
  in "/config/groups.yaml", line 33, column 7
2021-09-01 17:46:18 ERROR (SyncWorker_11) [homeassistant.util.yaml.loader] while scanning a simple key
  in "/config/groups.yaml", line 32, column 1
could not find expected ':'
  in "/config/groups.yaml", line 33, column 7
2021-09-01 17:46:35 ERROR (SyncWorker_10) [homeassistant.util.yaml.loader] while parsing a block mapping
  in "/config/groups.yaml", line 33, column 3
expected <block end>, but found '-'
  in "/config/groups.yaml", line 34, column 3
2021-09-01 17:46:59 WARNING (SyncWorker_8) [homeassistant.util.yaml.loader] YAML file /config/packages/uv_index.yaml contains duplicate key "channel". Check lines 90 and 91
2021-09-01 17:46:59 ERROR (MainThread) [homeassistant.config] Invalid config for [automation]: [title] is an invalid option for [automation]. Check: automation->action->1->title. (See ?, line ?). 
2021-09-01 17:46:59 ERROR (MainThread) [homeassistant.config] Invalid config for [automation]: invalid template (TemplateSyntaxError: expected token ',', got 'sensor') for dictionary value @ data['action'][0]['data']. Got None. (See ?, line ?). 
2021-09-01 17:46:59 ERROR (MainThread) [homeassistant.config] Invalid config for [automation]: invalid template (TemplateSyntaxError: expected token ',', got 'sensor') for dictionary value @ data['action'][0]['data']. Got None. (See ?, line ?). 
2021-09-01 17:46:59 ERROR (MainThread) [homeassistant.config] Invalid config for [automation]: invalid template (TemplateSyntaxError: expected token ',', got 'sensor') for dictionary value @ data['action'][0]['data']. Got None. (See ?, line ?). 
2021-09-01 17:46:59 ERROR (MainThread) [homeassistant.config] Invalid config for [automation]: required key not provided @ data['action'][4]['domain']. Got None. (See ?, line ?). 
2021-09-01 17:47:04 WARNING (SyncWorker_3) [homeassistant.util.yaml.loader] YAML file /config/packages/uv_index.yaml contains duplicate key "channel". Check lines 90 and 91
2021-09-01 17:47:06 WARNING (SyncWorker_5) [homeassistant.util.yaml.loader] YAML file /config/packages/uv_index.yaml contains duplicate key "channel". Check lines 90 and 91
2021-09-01 17:47:52 WARNING (SyncWorker_3) [buienalarm.pybuienalarm] Error fetching data safely: 502 Server Error: Bad Gateway for url: https://cdn-secure.buienalarm.nl/api/3.4/forecast.php?lat=50.878800118427755&lon=4.749415398691782&region=nl&unit=mm%2Fu
2021-09-01 17:53:50 WARNING (SyncWorker_0) [homeassistant.util.yaml.loader] YAML file /config/packages/uv_index.yaml contains duplicate key "channel". Check lines 90 and 91
2021-09-01 17:53:50 ERROR (MainThread) [homeassistant.config] Invalid config for [automation]: [title] is an invalid option for [automation]. Check: automation->action->1->title. (See ?, line ?). 
2021-09-01 17:53:50 ERROR (MainThread) [homeassistant.config] Invalid config for [automation]: invalid template (TemplateSyntaxError: expected token ',', got 'sensor') for dictionary value @ data['action'][0]['data']. Got None. (See ?, line ?). 
2021-09-01 17:53:50 ERROR (MainThread) [homeassistant.config] Invalid config for [automation]: invalid template (TemplateSyntaxError: expected token ',', got 'sensor') for dictionary value @ data['action'][0]['data']. Got None. (See ?, line ?). 
2021-09-01 17:53:50 ERROR (MainThread) [homeassistant.config] Invalid config for [automation]: invalid template (TemplateSyntaxError: expected token ',', got 'sensor') for dictionary value @ data['action'][0]['data']. Got None. (See ?, line ?). 
2021-09-01 17:53:50 ERROR (MainThread) [homeassistant.config] Invalid config for [automation]: required key not provided @ data['action'][4]['domain']. Got None. (See ?, line ?). 
2021-09-01 18:01:18 ERROR (Thread-12) [pychromecast.socket_client] [Living speaker(192.168.86.244):8009] Error reading from socket.
2021-09-01 18:01:18 WARNING (Thread-12) [pychromecast.socket_client] [Living speaker(192.168.86.244):8009] Error communicating with socket, resetting connection
2021-09-01 18:01:20 ERROR (Thread-12) [pychromecast.socket_client] [Living speaker(192.168.86.244):8009] Failed to connect to service ServiceInfo(type='mdns', data='google-nest-hub-f462ed96d0e5940e88b752d709fcc230._googlecast._tcp.local.'), retrying in 5.0s
2021-09-01 18:01:48 WARNING (SyncWorker_7) [homeassistant.util.yaml.loader] YAML file /config/packages/uv_index.yaml contains duplicate key "channel". Check lines 90 and 91
2021-09-01 18:01:48 ERROR (MainThread) [homeassistant.config] Invalid config for [automation]: [title] is an invalid option for [automation]. Check: automation->action->1->title. (See ?, line ?). 
2021-09-01 18:01:48 ERROR (MainThread) [homeassistant.config] Invalid config for [automation]: invalid template (TemplateSyntaxError: expected token ',', got 'sensor') for dictionary value @ data['action'][0]['data']. Got None. (See ?, line ?). 
2021-09-01 18:01:48 ERROR (MainThread) [homeassistant.config] Invalid config for [automation]: invalid template (TemplateSyntaxError: expected token ',', got 'sensor') for dictionary value @ data['action'][0]['data']. Got None. (See ?, line ?). 
2021-09-01 18:01:48 ERROR (MainThread) [homeassistant.config] Invalid config for [automation]: invalid template (TemplateSyntaxError: expected token ',', got 'sensor') for dictionary value @ data['action'][0]['data']. Got None. (See ?, line ?). 
2021-09-01 18:01:48 ERROR (MainThread) [homeassistant.config] Invalid config for [automation]: required key not provided @ data['action'][4]['domain']. Got None. (See ?, line ?). 
2021-09-01 18:01:53 WARNING (SyncWorker_5) [homeassistant.util.yaml.loader] YAML file /config/packages/uv_index.yaml contains duplicate key "channel". Check lines 90 and 91
2021-09-01 18:01:55 WARNING (SyncWorker_6) [homeassistant.util.yaml.loader] YAML file /config/packages/uv_index.yaml contains duplicate key "channel". Check lines 90 and 91
2021-09-01 18:01:58 WARNING (SyncWorker_4) [homeassistant.util.yaml.loader] YAML file /config/packages/uv_index.yaml contains duplicate key "channel". Check lines 90 and 91
2021-09-01 18:01:58 ERROR (MainThread) [homeassistant.config] Invalid config for [automation]: [title] is an invalid option for [automation]. Check: automation->action->1->title. (See ?, line ?). 
2021-09-01 18:01:58 ERROR (MainThread) [homeassistant.config] Invalid config for [automation]: invalid template (TemplateSyntaxError: expected token ',', got 'sensor') for dictionary value @ data['action'][0]['data']. Got None. (See ?, line ?). 
2021-09-01 18:01:58 ERROR (MainThread) [homeassistant.config] Invalid config for [automation]: invalid template (TemplateSyntaxError: expected token ',', got 'sensor') for dictionary value @ data['action'][0]['data']. Got None. (See ?, line ?). 
2021-09-01 18:01:58 ERROR (MainThread) [homeassistant.config] Invalid config for [automation]: invalid template (TemplateSyntaxError: expected token ',', got 'sensor') for dictionary value @ data['action'][0]['data']. Got None. (See ?, line ?). 
2021-09-01 18:01:58 ERROR (MainThread) [homeassistant.config] Invalid config for [automation]: required key not provided @ data['action'][4]['domain']. Got None. (See ?, line ?). 
2021-09-01 18:07:52 WARNING (SyncWorker_7) [buienalarm.pybuienalarm] Error fetching data safely: 502 Server Error: Bad Gateway for url: https://cdn-secure.buienalarm.nl/api/3.4/forecast.php?lat=50.878800118427755&lon=4.749415398691782&region=nl&unit=mm%2Fu
2021-09-01 18:10:51 WARNING (SyncWorker_11) [homeassistant.util.yaml.loader] YAML file /config/packages/uv_index.yaml contains duplicate key "channel". Check lines 90 and 91
2021-09-01 18:10:51 ERROR (MainThread) [homeassistant.config] Invalid config for [automation]: [title] is an invalid option for [automation]. Check: automation->action->1->title. (See ?, line ?). 
2021-09-01 18:10:51 ERROR (MainThread) [homeassistant.config] Invalid config for [automation]: invalid template (TemplateSyntaxError: Unexpected end of template. Jinja was looking for the following tags: 'elif' or 'else' or 'endif'. The innermost block that needs to be closed is 'if'.) for dictionary value @ data['action'][3]['data']. Got None. (See ?, line ?). 
2021-09-01 18:10:51 ERROR (MainThread) [homeassistant.config] Invalid config for [automation]: invalid template (TemplateSyntaxError: expected token ',', got 'sensor') for dictionary value @ data['action'][0]['data']. Got None. (See ?, line ?). 
2021-09-01 18:10:51 ERROR (MainThread) [homeassistant.config] Invalid config for [automation]: invalid template (TemplateSyntaxError: expected token ',', got 'sensor') for dictionary value @ data['action'][0]['data']. Got None. (See ?, line ?). 
2021-09-01 18:10:51 ERROR (MainThread) [homeassistant.config] Invalid config for [automation]: invalid template (TemplateSyntaxError: expected token ',', got 'sensor') for dictionary value @ data['action'][0]['data']. Got None. (See ?, line ?). 
2021-09-01 18:10:51 ERROR (MainThread) [homeassistant.config] Invalid config for [automation]: required key not provided @ data['action'][4]['domain']. Got None. (See ?, line ?). 
2021-09-01 18:11:00 WARNING (SyncWorker_3) [homeassistant.util.yaml.loader] YAML file /config/packages/uv_index.yaml contains duplicate key "channel". Check lines 90 and 91
2021-09-01 18:11:01 ERROR (MainThread) [homeassistant.config] Invalid config for [automation]: [title] is an invalid option for [automation]. Check: automation->action->1->title. (See ?, line ?). 
2021-09-01 18:11:01 ERROR (MainThread) [homeassistant.config] Invalid config for [automation]: invalid template (TemplateSyntaxError: Unexpected end of template. Jinja was looking for the following tags: 'elif' or 'else' or 'endif'. The innermost block that needs to be closed is 'if'.) for dictionary value @ data['action'][3]['data']. Got None. (See ?, line ?). 
2021-09-01 18:11:01 ERROR (MainThread) [homeassistant.config] Invalid config for [automation]: invalid template (TemplateSyntaxError: expected token ',', got 'sensor') for dictionary value @ data['action'][0]['data']. Got None. (See ?, line ?). 
2021-09-01 18:11:01 ERROR (MainThread) [homeassistant.config] Invalid config for [automation]: invalid template (TemplateSyntaxError: expected token ',', got 'sensor') for dictionary value @ data['action'][0]['data']. Got None. (See ?, line ?). 
2021-09-01 18:11:01 ERROR (MainThread) [homeassistant.config] Invalid config for [automation]: invalid template (TemplateSyntaxError: expected token ',', got 'sensor') for dictionary value @ data['action'][0]['data']. Got None. (See ?, line ?). 
2021-09-01 18:11:01 ERROR (MainThread) [homeassistant.config] Invalid config for [automation]: required key not provided @ data['action'][4]['domain']. Got None. (See ?, line ?). 
2021-09-01 18:18:28 ERROR (MainThread) [homeassistant.components.google_assistant.http] Request for https://homegraph.googleapis.com/v1/devices:reportStateAndNotification failed: 404
2021-09-01 18:27:52 WARNING (SyncWorker_5) [buienalarm.pybuienalarm] Error fetching data safely: 502 Server Error: Bad Gateway for url: https://cdn-secure.buienalarm.nl/api/3.4/forecast.php?lat=50.878800118427755&lon=4.749415398691782&region=nl&unit=mm%2Fu
2021-09-01 18:28:33 ERROR (MainThread) [custom_components.hacs] PTST/O365-HomeAssistant - Repository is archived.
2021-09-01 18:32:42 ERROR (MainThread) [homeassistant.components.google_assistant.http] Request for https://homegraph.googleapis.com/v1/devices:reportStateAndNotification failed: 404
2021-09-01 18:40:00 ERROR (MainThread) [custom_components.googlewifi] Unexpected error fetching GoogleWifi data: 'traffic'
Traceback (most recent call last):
  File "/usr/src/homeassistant/homeassistant/helpers/update_coordinator.py", line 187, in _async_refresh
    self.data = await self._async_update_data()
  File "/config/custom_components/googlewifi/__init__.py", line 171, in _async_update_data
    system_data = await self.api.get_systems()
  File "/usr/local/lib/python3.9/site-packages/googlewifi/__init__.py", line 191, in get_systems
    return await self.structure_systems(response)
  File "/usr/local/lib/python3.9/site-packages/googlewifi/__init__.py", line 291, in structure_systems
    devices[this_station["station"]["id"]]["traffic"] = this_station["traffic"]
KeyError: 'traffic'
2021-09-01 18:40:41 ERROR (MainThread) [custom_components.googlewifi] Unexpected error fetching GoogleWifi data: 'traffic'
Traceback (most recent call last):
  File "/usr/src/homeassistant/homeassistant/helpers/update_coordinator.py", line 187, in _async_refresh
    self.data = await self._async_update_data()
  File "/config/custom_components/googlewifi/__init__.py", line 171, in _async_update_data
    system_data = await self.api.get_systems()
  File "/usr/local/lib/python3.9/site-packages/googlewifi/__init__.py", line 191, in get_systems
    return await self.structure_systems(response)
  File "/usr/local/lib/python3.9/site-packages/googlewifi/__init__.py", line 291, in structure_systems
    devices[this_station["station"]["id"]]["traffic"] = this_station["traffic"]
KeyError: 'traffic'
2021-09-01 18:41:22 ERROR (MainThread) [custom_components.googlewifi] Unexpected error fetching GoogleWifi data: 'traffic'
Traceback (most recent call last):
  File "/usr/src/homeassistant/homeassistant/helpers/update_coordinator.py", line 187, in _async_refresh
    self.data = await self._async_update_data()
  File "/config/custom_components/googlewifi/__init__.py", line 171, in _async_update_data
    system_data = await self.api.get_systems()
  File "/usr/local/lib/python3.9/site-packages/googlewifi/__init__.py", line 191, in get_systems
    return await self.structure_systems(response)
  File "/usr/local/lib/python3.9/site-packages/googlewifi/__init__.py", line 291, in structure_systems
    devices[this_station["station"]["id"]]["traffic"] = this_station["traffic"]
KeyError: 'traffic'
2021-09-01 18:47:52 WARNING (SyncWorker_7) [buienalarm.pybuienalarm] Error fetching data safely: 502 Server Error: Bad Gateway for url: https://cdn-secure.buienalarm.nl/api/3.4/forecast.php?lat=50.878800118427755&lon=4.749415398691782&region=nl&unit=mm%2Fu
2021-09-01 18:53:05 WARNING (SyncWorker_2) [homeassistant.util.yaml.loader] YAML file /config/packages/uv_index.yaml contains duplicate key "channel". Check lines 90 and 91
2021-09-01 18:53:05 ERROR (MainThread) [homeassistant.config] Invalid config for [automation]: [title] is an invalid option for [automation]. Check: automation->action->1->title. (See ?, line ?). 
2021-09-01 18:53:05 ERROR (MainThread) [homeassistant.config] Invalid config for [automation]: invalid template (TemplateSyntaxError: Unexpected end of template. Jinja was looking for the following tags: 'elif' or 'else' or 'endif'. The innermost block that needs to be closed is 'if'.) for dictionary value @ data['action'][3]['data']. Got None. (See ?, line ?). 
2021-09-01 18:53:05 ERROR (MainThread) [homeassistant.config] Invalid config for [automation]: invalid template (TemplateSyntaxError: expected token ',', got 'sensor') for dictionary value @ data['action'][0]['data']. Got None. (See ?, line ?). 
2021-09-01 18:53:05 ERROR (MainThread) [homeassistant.config] Invalid config for [automation]: invalid template (TemplateSyntaxError: expected token ',', got 'sensor') for dictionary value @ data['action'][0]['data']. Got None. (See ?, line ?). 
2021-09-01 18:53:05 ERROR (MainThread) [homeassistant.config] Invalid config for [automation]: invalid template (TemplateSyntaxError: expected token ',', got 'sensor') for dictionary value @ data['action'][0]['data']. Got None. (See ?, line ?). 
2021-09-01 18:53:05 ERROR (MainThread) [homeassistant.config] Invalid config for [automation]: required key not provided @ data['action'][4]['domain']. Got None. (See ?, line ?). 
