2021-09-24 15:37:27 WARNING (SyncWorker_1) [homeassistant.loader] We found a custom integration xiaomi_miio_airpurifier which has not been tested by Home Assistant. This component might cause stability problems, be sure to disable it if you experience issues with Home Assistant
2021-09-24 15:37:27 WARNING (SyncWorker_2) [homeassistant.loader] We found a custom integration audiconnect which has not been tested by Home Assistant. This component might cause stability problems, be sure to disable it if you experience issues with Home Assistant
2021-09-24 15:37:27 WARNING (SyncWorker_0) [homeassistant.loader] We found a custom integration average which has not been tested by Home Assistant. This component might cause stability problems, be sure to disable it if you experience issues with Home Assistant
2021-09-24 15:37:27 WARNING (SyncWorker_3) [homeassistant.loader] We found a custom integration powercalc which has not been tested by Home Assistant. This component might cause stability problems, be sure to disable it if you experience issues with Home Assistant
2021-09-24 15:37:27 WARNING (SyncWorker_4) [homeassistant.loader] We found a custom integration monitor_docker which has not been tested by Home Assistant. This component might cause stability problems, be sure to disable it if you experience issues with Home Assistant
2021-09-24 15:37:27 WARNING (SyncWorker_1) [homeassistant.loader] We found a custom integration localtuya which has not been tested by Home Assistant. This component might cause stability problems, be sure to disable it if you experience issues with Home Assistant
2021-09-24 15:37:27 WARNING (SyncWorker_2) [homeassistant.loader] We found a custom integration shelly which has not been tested by Home Assistant. This component might cause stability problems, be sure to disable it if you experience issues with Home Assistant
2021-09-24 15:37:27 WARNING (SyncWorker_5) [homeassistant.loader] We found a custom integration hacs which has not been tested by Home Assistant. This component might cause stability problems, be sure to disable it if you experience issues with Home Assistant
2021-09-24 15:37:27 WARNING (SyncWorker_1) [homeassistant.loader] We found a custom integration buienalarm which has not been tested by Home Assistant. This component might cause stability problems, be sure to disable it if you experience issues with Home Assistant
2021-09-24 15:37:27 WARNING (SyncWorker_3) [homeassistant.loader] We found a custom integration xiaomi_miot which has not been tested by Home Assistant. This component might cause stability problems, be sure to disable it if you experience issues with Home Assistant
2021-09-24 15:37:27 WARNING (SyncWorker_8) [homeassistant.loader] We found a custom integration huesyncbox which has not been tested by Home Assistant. This component might cause stability problems, be sure to disable it if you experience issues with Home Assistant
2021-09-24 15:37:27 WARNING (SyncWorker_9) [homeassistant.loader] We found a custom integration anniversaries which has not been tested by Home Assistant. This component might cause stability problems, be sure to disable it if you experience issues with Home Assistant
2021-09-24 15:37:27 WARNING (SyncWorker_7) [homeassistant.loader] We found a custom integration xiaomi_miio_fan which has not been tested by Home Assistant. This component might cause stability problems, be sure to disable it if you experience issues with Home Assistant
2021-09-24 15:37:27 WARNING (SyncWorker_6) [homeassistant.loader] We found a custom integration deepstack_face which has not been tested by Home Assistant. This component might cause stability problems, be sure to disable it if you experience issues with Home Assistant
2021-09-24 15:37:27 WARNING (SyncWorker_5) [homeassistant.loader] We found a custom integration googlewifi which has not been tested by Home Assistant. This component might cause stability problems, be sure to disable it if you experience issues with Home Assistant
2021-09-24 15:37:27 WARNING (SyncWorker_2) [homeassistant.loader] We found a custom integration thermal_comfort which has not been tested by Home Assistant. This component might cause stability problems, be sure to disable it if you experience issues with Home Assistant
2021-09-24 15:37:27 WARNING (SyncWorker_10) [homeassistant.loader] We found a custom integration google_home which has not been tested by Home Assistant. This component might cause stability problems, be sure to disable it if you experience issues with Home Assistant
2021-09-24 15:37:27 WARNING (SyncWorker_0) [homeassistant.loader] We found a custom integration tuya_v2 which has not been tested by Home Assistant. This component might cause stability problems, be sure to disable it if you experience issues with Home Assistant
2021-09-24 15:37:27 WARNING (SyncWorker_3) [homeassistant.loader] We found a custom integration ytube_music_player which has not been tested by Home Assistant. This component might cause stability problems, be sure to disable it if you experience issues with Home Assistant
2021-09-24 15:37:27 WARNING (SyncWorker_4) [homeassistant.loader] We found a custom integration afvalbeheer which has not been tested by Home Assistant. This component might cause stability problems, be sure to disable it if you experience issues with Home Assistant
2021-09-24 15:37:38 ERROR (MainThread) [homeassistant.config] Invalid config for [automation]: required key not provided @ data['action'][4]['domain']. Got None. (See ?, line ?). 
2021-09-24 15:37:39 ERROR (MainThread) [homeassistant.config] Invalid config for [automation]: [title] is an invalid option for [automation]. Check: automation->action->1->title. (See ?, line ?). 
2021-09-24 15:37:39 ERROR (MainThread) [homeassistant.config] Invalid config for [automation]: must be a value between 0 and 59 for dictionary value @ data['minutes']. Got None. (See ?, line ?). 
2021-09-24 15:37:39 ERROR (MainThread) [homeassistant.config] Invalid config for [automation]: must be a value between 0 and 59 for dictionary value @ data['minutes']. Got None. (See ?, line ?). 
2021-09-24 15:37:44 WARNING (MainThread) [homeassistant.components.fan] Platform xiaomi_miio_fan not ready yet: Unable to discover the device 192.168.86.28; Retrying in background in 30 seconds
2021-09-24 15:37:44 WARNING (MainThread) [homeassistant.components.fan] Platform xiaomi_miio_fan not ready yet: Unable to discover the device 192.168.86.29; Retrying in background in 30 seconds
2021-09-24 15:37:47 WARNING (MainThread) [homeassistant.config_entries] Config entry '192.168.86.83' for synology_dsm integration not ready yet: {'api': None, 'code': -1, 'reason': 'Unknown', 'details': 'ConnectionError = <urllib3.connection.HTTPSConnection object at 0xffff84ada040>: Failed to establish a new connection: [Errno 113] Host is unreachable'}; Retrying in background
2021-09-24 15:37:47 ERROR (MainThread) [homeassistant.components.automation] Platform automation does not generate unique IDs. ID 1632427763962 already exists - ignoring automation.verwarming_aan_en_raam_open_verwarming_uit
2021-09-24 15:37:47 ERROR (MainThread) [homeassistant.components.automation] Platform automation does not generate unique IDs. ID 1632427763962 already exists - ignoring automation.verwarming_aan_en_raam_open_verwarming_uit
2021-09-24 15:37:48 WARNING (MainThread) [homeassistant.components.light] Platform netatmo not ready yet: None; Retrying in background in 30 seconds
2021-09-24 15:37:48 WARNING (MainThread) [homeassistant.components.select] Platform netatmo not ready yet: None; Retrying in background in 30 seconds
2021-09-24 15:37:49 WARNING (MainThread) [homeassistant.components.hue.light] Please check for software updates of the douche bulb in the Philips Hue App.
2021-09-24 15:37:49 WARNING (MainThread) [homeassistant.components.hue.light] Please check for software updates of the wasbak rechts bulb in the Philips Hue App.
2021-09-24 15:37:49 WARNING (MainThread) [homeassistant.components.hue.light] Please check for software updates of the bad bulb in the Philips Hue App.
2021-09-24 15:37:50 ERROR (MainThread) [custom_components.powercalc.sensor] Skipping sensor setup light.amilya: Cannot select a mode (LINEAR, FIXED or LUT), supply it in the config
2021-09-24 15:37:50 ERROR (MainThread) [custom_components.powercalc.model_discovery] Cannot autodiscover model for 'light.badkamer', not found in the hue bridge api
2021-09-24 15:37:50 ERROR (MainThread) [custom_components.powercalc.sensor] Skipping sensor setup light.badkamer: Cannot select a mode (LINEAR, FIXED or LUT), supply it in the config
2021-09-24 15:37:50 ERROR (MainThread) [custom_components.powercalc.model_discovery] Cannot autodiscover model for 'light.buiten', not found in the hue bridge api
2021-09-24 15:37:50 ERROR (MainThread) [custom_components.powercalc.sensor] Skipping sensor setup light.buiten: Cannot select a mode (LINEAR, FIXED or LUT), supply it in the config
2021-09-24 15:37:50 ERROR (MainThread) [homeassistant.components.sensor] Error while setting up powercalc platform for sensor
Traceback (most recent call last):
  File "/usr/src/homeassistant/homeassistant/helpers/entity_platform.py", line 249, in _async_setup_platform
    await asyncio.shield(task)
  File "/config/custom_components/powercalc/sensor.py", line 198, in async_setup_platform
    entities.extend(await create_individual_sensors(hass, merged_sensor_config))
  File "/config/custom_components/powercalc/sensor.py", line 241, in create_individual_sensors
    power_sensor = await create_power_sensor(
  File "/config/custom_components/powercalc/sensor.py", line 359, in create_power_sensor
    await calculation_strategy.validate_config(source_entity)
  File "/config/custom_components/powercalc/strategy_lut.py", line 214, in validate_config
    supported_color_modes = source_entity.capabilities[
TypeError: list indices must be integers or slices, not str
2021-09-24 15:37:53 WARNING (MainThread) [homeassistant.components.sensor] Platform netatmo not ready yet: None; Retrying in background in 30 seconds
2021-09-24 15:37:54 ERROR (SyncWorker_6) [glocaltokens.client] [Device - Nest Wifi router(id=2f2a9d15-0ae2-4ffe-b6c1-2ef24c742b8a)] local_auth_token must follow the correct format
2021-09-24 15:37:54 ERROR (SyncWorker_6) [glocaltokens.client] [Device - Nest Wifi router(id=e1e5a8d5-d21f-444d-95a9-c76d78c9bc79)] local_auth_token must follow the correct format
2021-09-24 15:37:54 ERROR (SyncWorker_6) [glocaltokens.client] [Device - Nest Wifi router(id=ea3de37c-ca74-4689-8171-1681b2f4f924)] local_auth_token must follow the correct format
2021-09-24 15:37:56 ERROR (MainThread) [homeassistant.components.sensor] scrape: Error on device update!
Traceback (most recent call last):
  File "/usr/src/homeassistant/homeassistant/helpers/entity_platform.py", line 431, in _async_add_entity
    await entity.async_device_update(warning=False)
  File "/usr/src/homeassistant/homeassistant/helpers/entity.py", line 633, in async_device_update
    await task
  File "/usr/src/homeassistant/homeassistant/components/scrape/sensor.py", line 139, in async_update
    await self._async_update_from_rest_data()
  File "/usr/src/homeassistant/homeassistant/components/scrape/sensor.py", line 152, in _async_update_from_rest_data
    value = await self.hass.async_add_executor_job(self._extract_value)
  File "/usr/local/lib/python3.9/concurrent/futures/thread.py", line 52, in run
    result = self.fn(*self.args, **self.kwargs)
  File "/usr/src/homeassistant/homeassistant/components/scrape/sensor.py", line 128, in _extract_value
    tag = raw_data.select(self._select)[self._index]
  File "/usr/local/lib/python3.9/site-packages/bs4/element.py", line 1869, in select
    results = soupsieve.select(selector, self, namespaces, limit, **kwargs)
  File "/usr/local/lib/python3.9/site-packages/soupsieve/__init__.py", line 98, in select
    return compile(select, namespaces, flags, **kwargs).select(tag, limit)
  File "/usr/local/lib/python3.9/site-packages/soupsieve/__init__.py", line 62, in compile
    return cp._cached_css_compile(pattern, namespaces, custom, flags)
  File "/usr/local/lib/python3.9/site-packages/soupsieve/css_parser.py", line 211, in _cached_css_compile
    CSSParser(pattern, custom=custom_selectors, flags=flags).process_selectors(),
  File "/usr/local/lib/python3.9/site-packages/soupsieve/css_parser.py", line 1058, in process_selectors
    return self.parse_selectors(self.selector_iter(self.pattern), index, flags)
  File "/usr/local/lib/python3.9/site-packages/soupsieve/css_parser.py", line 909, in parse_selectors
    key, m = next(iselector)
  File "/usr/local/lib/python3.9/site-packages/soupsieve/css_parser.py", line 1051, in selector_iter
    raise SelectorSyntaxError(msg, self.pattern, index)
soupsieve.util.SelectorSyntaxError: Invalid character '<' position 0
  line 1:
<span _ngcontent-app-root-c173="">Offline</span>
^
2021-09-24 15:37:57 WARNING (MainThread) [homeassistant.config_entries] Config entry 'OnHub' for upnp integration not ready yet; Retrying in background
2021-09-24 15:37:59 WARNING (MainThread) [homeassistant.components.sensor] Setup of sensor platform scrape is taking over 10 seconds.
2021-09-24 15:37:59 WARNING (MainThread) [homeassistant.components.sensor] Setup of sensor platform scrape is taking over 10 seconds.
2021-09-24 15:37:59 WARNING (MainThread) [homeassistant.components.sensor] Setup of sensor platform scrape is taking over 10 seconds.
2021-09-24 15:37:59 WARNING (MainThread) [homeassistant.components.sensor] Setup of sensor platform scrape is taking over 10 seconds.
2021-09-24 15:38:00 ERROR (MainThread) [custom_components.audiconnect.audi_connect_account] Unable to update the vehicle position of WAUZZZGE6MB019131: 204, message='No Content', url=URL('https://fal-3a.prd.eu.dp.vwg-connect.com/fs-car/bs/cf/v1/Audi/BE/vehicles/WAUZZZGE6MB019131/position')
2021-09-24 15:38:21 WARNING (MainThread) [homeassistant.components.media_player] Updating huesyncbox media_player took longer than the scheduled update interval 0:00:02
2021-09-24 15:38:21 ERROR (MainThread) [homeassistant] Error doing job: Task exception was never retrieved
Traceback (most recent call last):
  File "/usr/src/homeassistant/homeassistant/components/netatmo/__init__.py", line 198, in register_webhook
    await hass.data[DOMAIN][entry.entry_id][AUTH].async_addwebhook(webhook_url)
  File "/usr/local/lib/python3.9/site-packages/pyatmo/auth.py", line 351, in async_addwebhook
    resp = await self.async_post_request(WEBHOOK_URL_ADD, {"url": webhook_url})
  File "/usr/local/lib/python3.9/site-packages/pyatmo/auth.py", line 306, in async_post_request
    async with self.websession.post(
  File "/usr/local/lib/python3.9/site-packages/aiohttp/client.py", line 1117, in __aenter__
    self._resp = await self._coro
  File "/usr/local/lib/python3.9/site-packages/aiohttp/client.py", line 544, in _request
    await resp.start(conn)
  File "/usr/local/lib/python3.9/site-packages/aiohttp/client_reqrep.py", line 905, in start
    self._continue = None
  File "/usr/local/lib/python3.9/site-packages/aiohttp/helpers.py", line 656, in __exit__
    raise asyncio.TimeoutError from None
asyncio.exceptions.TimeoutError
2021-09-24 15:38:32 WARNING (MainThread) [homeassistant.components.fan] Setup of fan platform xiaomi_miio_fan is taking over 10 seconds.
2021-09-24 15:38:32 WARNING (MainThread) [homeassistant.components.fan] Setup of fan platform xiaomi_miio_fan is taking over 10 seconds.
2021-09-24 15:38:32 ERROR (MainThread) [homeassistant.components.hue.sensor_base] Timeout fetching sensor data
2021-09-24 15:38:32 ERROR (MainThread) [homeassistant.components.mobile_app.notify] Timeout sending notification to https://mobile-apps.home-assistant.io/api/sendPush/android/v1
2021-09-24 15:47:06 ERROR (MainThread) [homeassistant.components.scrape.sensor] Unable to extract data from HTML for precip_rate_leuven24_wunderground
2021-09-24 15:48:00 ERROR (MainThread) [homeassistant.components.scrape.sensor] Unable to extract data from HTML for uvindex_leuven24_wunderground
2021-09-24 15:48:00 ERROR (MainThread) [homeassistant.components.scrape.sensor] Unable to extract data from HTML for precip_total_leuven24_wunderground
2021-09-24 15:49:57 ERROR (MainThread) [homeassistant.components.scrape.sensor] Unable to extract data from HTML for temp_leuven24_wunderground
2021-09-24 15:49:57 ERROR (MainThread) [homeassistant.components.scrape.sensor] Unable to extract data from HTML for humidity_leuven24_wunderground
2021-09-24 15:49:59 ERROR (MainThread) [homeassistant.components.scrape.sensor] Unable to extract data from HTML for precip_rate_leuven24_wunderground
2021-09-24 15:53:58 WARNING (MainThread) [homeassistant.components.automation.ramen_check_living_room_sluiten_2] 🪟 ramen -  check living room (sluiten): Already running
2021-09-24 15:53:58 WARNING (MainThread) [homeassistant.components.automation.ramen_check_veranda_sluiten_2] 🪟 ramen -  check veranda (sluiten): Already running
2021-09-24 15:53:58 WARNING (MainThread) [homeassistant.components.automation.ramen_check_berging_sluiten_2] 🪟 ramen -  check berging (sluiten): Already running
2021-09-24 15:53:58 WARNING (MainThread) [homeassistant.components.automation.ramen_check_master_bedroom_sluiten_2] 🪟 ramen -  check master bedroom (sluiten): Already running
2021-09-24 16:02:01 WARNING (MainThread) [homeassistant.components.automation.ramen_check_master_bedroom_sluiten_2] 🪟 ramen -  check master bedroom (sluiten): Already running
2021-09-24 16:02:01 WARNING (MainThread) [homeassistant.components.automation.ramen_check_kamer_amilya_open] 🪟 ramen -  Check kamer Amilya (open): Already running
2021-09-24 16:26:01 WARNING (MainThread) [homeassistant.components.automation.ramen_check_berging_sluiten_2] 🪟 ramen -  check berging (sluiten): Already running
2021-09-24 16:26:01 WARNING (MainThread) [homeassistant.components.automation.ramen_check_master_bedroom_sluiten_2] 🪟 ramen -  check master bedroom (sluiten): Already running
2021-09-24 16:26:01 WARNING (MainThread) [homeassistant.components.automation.ramen_check_kamer_amilya_open] 🪟 ramen -  Check kamer Amilya (open): Already running
2021-09-24 16:26:01 WARNING (MainThread) [homeassistant.components.automation.ramen_check_badkamer_open] 🪟 ramen -  Check badkamer (open): Already running
2021-09-24 16:26:01 WARNING (MainThread) [homeassistant.components.automation.ramen_check_kamer_alunya_open_2] 🪟 ramen -  Check kamer Alunya (open): Already running
2021-09-24 16:26:56 ERROR (MainThread) [homeassistant.config] Invalid config for [automation]: required key not provided @ data['action'][4]['domain']. Got None. (See ?, line ?). 
2021-09-24 16:26:56 ERROR (MainThread) [homeassistant.config] Invalid config for [automation]: [title] is an invalid option for [automation]. Check: automation->action->1->title. (See ?, line ?). 
2021-09-24 16:26:56 ERROR (MainThread) [homeassistant.config] Invalid config for [automation]: must be a value between 0 and 59 for dictionary value @ data['minutes']. Got None. (See ?, line ?). 
2021-09-24 16:26:56 ERROR (MainThread) [homeassistant.config] Invalid config for [automation]: must be a value between 0 and 59 for dictionary value @ data['minutes']. Got None. (See ?, line ?). 
2021-09-24 16:27:03 ERROR (MainThread) [homeassistant.config] Invalid config for [automation]: required key not provided @ data['action'][4]['domain']. Got None. (See ?, line ?). 
2021-09-24 16:27:03 ERROR (MainThread) [homeassistant.config] Invalid config for [automation]: [title] is an invalid option for [automation]. Check: automation->action->1->title. (See ?, line ?). 
2021-09-24 16:27:03 ERROR (MainThread) [homeassistant.config] Invalid config for [automation]: must be a value between 0 and 59 for dictionary value @ data['minutes']. Got None. (See ?, line ?). 
2021-09-24 16:27:03 ERROR (MainThread) [homeassistant.config] Invalid config for [automation]: must be a value between 0 and 59 for dictionary value @ data['minutes']. Got None. (See ?, line ?). 
2021-09-24 16:27:03 ERROR (MainThread) [homeassistant.helpers.entity] Update for sensor.master_bedroom_tv_on_today fails
Traceback (most recent call last):
  File "/usr/src/homeassistant/homeassistant/helpers/entity.py", line 446, in async_update_ha_state
    await self.async_device_update()
  File "/usr/src/homeassistant/homeassistant/helpers/entity.py", line 641, in async_device_update
    raise exc
  File "/usr/src/homeassistant/homeassistant/components/history_stats/sensor.py", line 221, in async_update
    await self.hass.async_add_executor_job(
  File "/usr/local/lib/python3.9/concurrent/futures/thread.py", line 52, in run
    result = self.fn(*self.args, **self.kwargs)
  File "/usr/src/homeassistant/homeassistant/components/history_stats/sensor.py", line 227, in _update
    history_list = history.state_changes_during_period(
  File "/usr/src/homeassistant/homeassistant/components/recorder/history.py", line 142, in state_changes_during_period
    with session_scope(hass=hass) as session:
  File "/usr/local/lib/python3.9/contextlib.py", line 119, in __enter__
    return next(self.gen)
  File "/usr/src/homeassistant/homeassistant/components/recorder/util.py", line 59, in session_scope
    session = hass.data[DATA_INSTANCE].get_session()
TypeError: 'NoneType' object is not callable
2021-09-24 16:27:05 WARNING (Thread-143) [homeassistant.util.executor] Thread[SyncWorker_2] is still running at shutdown: File "/usr/local/lib/python3.9/threading.py", line 930, in _bootstrap
    self._bootstrap_inner()
  File "/usr/local/lib/python3.9/threading.py", line 973, in _bootstrap_inner
    self.run()
  File "/usr/local/lib/python3.9/threading.py", line 910, in run
    self._target(*self._args, **self._kwargs)
  File "/usr/local/lib/python3.9/concurrent/futures/thread.py", line 77, in _worker
    work_item.run()
  File "/usr/local/lib/python3.9/concurrent/futures/thread.py", line 52, in run
    result = self.fn(*self.args, **self.kwargs)
  File "/usr/src/homeassistant/homeassistant/components/samsungtv/media_player.py", line 124, in update
    self._state = STATE_ON if self._bridge.is_on() else STATE_OFF
  File "/usr/src/homeassistant/homeassistant/components/samsungtv/bridge.py", line 112, in is_on
    return self._get_remote() is not None
  File "/usr/src/homeassistant/homeassistant/components/samsungtv/bridge.py", line 338, in _get_remote
    self._remote.open()
  File "/usr/local/lib/python3.9/site-packages/samsungtvws/remote.py", line 146, in open
    self.connection = websocket.create_connection(
  File "/usr/local/lib/python3.9/site-packages/websocket/_core.py", line 596, in create_connection
    websock.connect(url, **options)
  File "/usr/local/lib/python3.9/site-packages/websocket/_core.py", line 249, in connect
    self.sock, addrs = connect(url, self.sock_opt, proxy_info(**options),
  File "/usr/local/lib/python3.9/site-packages/websocket/_http.py", line 130, in connect
    sock = _open_socket(addrinfo_list, options.sockopt, options.timeout)
  File "/usr/local/lib/python3.9/site-packages/websocket/_http.py", line 185, in _open_socket
    sock.connect(address)
2021-09-24 16:27:06 WARNING (Thread-143) [homeassistant.util.executor] Thread[SyncWorker_2] is still running at shutdown: File "/usr/local/lib/python3.9/threading.py", line 930, in _bootstrap
    self._bootstrap_inner()
  File "/usr/local/lib/python3.9/threading.py", line 973, in _bootstrap_inner
    self.run()
  File "/usr/local/lib/python3.9/threading.py", line 910, in run
    self._target(*self._args, **self._kwargs)
  File "/usr/local/lib/python3.9/concurrent/futures/thread.py", line 77, in _worker
    work_item.run()
  File "/usr/local/lib/python3.9/concurrent/futures/thread.py", line 52, in run
    result = self.fn(*self.args, **self.kwargs)
  File "/usr/src/homeassistant/homeassistant/components/samsungtv/media_player.py", line 124, in update
    self._state = STATE_ON if self._bridge.is_on() else STATE_OFF
  File "/usr/src/homeassistant/homeassistant/components/samsungtv/bridge.py", line 112, in is_on
    return self._get_remote() is not None
  File "/usr/src/homeassistant/homeassistant/components/samsungtv/bridge.py", line 338, in _get_remote
    self._remote.open()
  File "/usr/local/lib/python3.9/site-packages/samsungtvws/remote.py", line 146, in open
    self.connection = websocket.create_connection(
  File "/usr/local/lib/python3.9/site-packages/websocket/_core.py", line 596, in create_connection
    websock.connect(url, **options)
  File "/usr/local/lib/python3.9/site-packages/websocket/_core.py", line 249, in connect
    self.sock, addrs = connect(url, self.sock_opt, proxy_info(**options),
  File "/usr/local/lib/python3.9/site-packages/websocket/_http.py", line 130, in connect
    sock = _open_socket(addrinfo_list, options.sockopt, options.timeout)
  File "/usr/local/lib/python3.9/site-packages/websocket/_http.py", line 185, in _open_socket
    sock.connect(address)
2021-09-24 16:27:07 ERROR (MainThread) [homeassistant.components.hue.sensor_base] Unexpected error fetching sensor data: Session is closed
Traceback (most recent call last):
  File "/usr/src/homeassistant/homeassistant/helpers/update_coordinator.py", line 187, in _async_refresh
    self.data = await self._async_update_data()
  File "/usr/src/homeassistant/homeassistant/helpers/update_coordinator.py", line 147, in _async_update_data
    return await self.update_method()
  File "/usr/src/homeassistant/homeassistant/components/hue/sensor_base.py", line 65, in async_update_data
    return await self.bridge.async_request_call(
  File "/usr/src/homeassistant/homeassistant/components/hue/bridge.py", line 138, in async_request_call
    return await task()
  File "/usr/local/lib/python3.9/site-packages/aiohue/api.py", line 14, in update
    raw = await self._request("get", self._path)
  File "/usr/local/lib/python3.9/site-packages/aiohue/bridge.py", line 114, in request
    async with self.websession.request(
  File "/usr/local/lib/python3.9/site-packages/aiohttp/client.py", line 1117, in __aenter__
    self._resp = await self._coro
  File "/usr/local/lib/python3.9/site-packages/aiohttp/client.py", line 381, in _request
    raise RuntimeError("Session is closed")
RuntimeError: Session is closed
2021-09-24 16:27:07 ERROR (MainThread) [homeassistant.components.hue.sensor_base] Unexpected error fetching sensor data: Session is closed
Traceback (most recent call last):
  File "/usr/src/homeassistant/homeassistant/helpers/update_coordinator.py", line 187, in _async_refresh
    self.data = await self._async_update_data()
  File "/usr/src/homeassistant/homeassistant/helpers/update_coordinator.py", line 147, in _async_update_data
    return await self.update_method()
  File "/usr/src/homeassistant/homeassistant/components/hue/sensor_base.py", line 65, in async_update_data
    return await self.bridge.async_request_call(
  File "/usr/src/homeassistant/homeassistant/components/hue/bridge.py", line 138, in async_request_call
    return await task()
  File "/usr/local/lib/python3.9/site-packages/aiohue/api.py", line 14, in update
    raw = await self._request("get", self._path)
  File "/usr/local/lib/python3.9/site-packages/aiohue/bridge.py", line 114, in request
    async with self.websession.request(
  File "/usr/local/lib/python3.9/site-packages/aiohttp/client.py", line 1117, in __aenter__
    self._resp = await self._coro
  File "/usr/local/lib/python3.9/site-packages/aiohttp/client.py", line 381, in _request
    raise RuntimeError("Session is closed")
RuntimeError: Session is closed
2021-09-24 16:27:07 ERROR (MainThread) [homeassistant.components.hue.light] Unexpected error fetching light data: Session is closed
Traceback (most recent call last):
  File "/usr/src/homeassistant/homeassistant/helpers/update_coordinator.py", line 187, in _async_refresh
    self.data = await self._async_update_data()
  File "/usr/src/homeassistant/homeassistant/helpers/update_coordinator.py", line 147, in _async_update_data
    return await self.update_method()
  File "/usr/src/homeassistant/homeassistant/components/hue/light.py", line 228, in async_safe_fetch
    return await bridge.async_request_call(fetch_method)
  File "/usr/src/homeassistant/homeassistant/components/hue/bridge.py", line 138, in async_request_call
    return await task()
  File "/usr/local/lib/python3.9/site-packages/aiohue/api.py", line 14, in update
    raw = await self._request("get", self._path)
  File "/usr/local/lib/python3.9/site-packages/aiohue/bridge.py", line 114, in request
    async with self.websession.request(
  File "/usr/local/lib/python3.9/site-packages/aiohttp/client.py", line 1117, in __aenter__
    self._resp = await self._coro
  File "/usr/local/lib/python3.9/site-packages/aiohttp/client.py", line 381, in _request
    raise RuntimeError("Session is closed")
RuntimeError: Session is closed
2021-09-24 16:27:07 ERROR (MainThread) [homeassistant.helpers.entity] Update for sensor.veranda_light_on_today fails
Traceback (most recent call last):
  File "/usr/src/homeassistant/homeassistant/helpers/entity.py", line 446, in async_update_ha_state
    await self.async_device_update()
  File "/usr/src/homeassistant/homeassistant/helpers/entity.py", line 641, in async_device_update
    raise exc
  File "/usr/src/homeassistant/homeassistant/components/history_stats/sensor.py", line 221, in async_update
    await self.hass.async_add_executor_job(
  File "/usr/src/homeassistant/homeassistant/core.py", line 405, in async_add_executor_job
    task = self.loop.run_in_executor(None, target, *args)
  File "/usr/local/lib/python3.9/asyncio/base_events.py", line 807, in run_in_executor
    self._check_default_executor()
  File "/usr/local/lib/python3.9/asyncio/base_events.py", line 514, in _check_default_executor
    raise RuntimeError('Executor shutdown has been called')
RuntimeError: Executor shutdown has been called
2021-09-24 16:27:07 ERROR (MainThread) [homeassistant] Error doing job: Future exception was never retrieved
Traceback (most recent call last):
  File "/usr/local/lib/python3.9/site-packages/websocket/_http.py", line 185, in _open_socket
    sock.connect(address)
socket.timeout: timed out

During handling of the above exception, another exception occurred:

Traceback (most recent call last):
  File "/usr/local/lib/python3.9/concurrent/futures/thread.py", line 52, in run
    result = self.fn(*self.args, **self.kwargs)
  File "/usr/src/homeassistant/homeassistant/components/samsungtv/media_player.py", line 124, in update
    self._state = STATE_ON if self._bridge.is_on() else STATE_OFF
  File "/usr/src/homeassistant/homeassistant/components/samsungtv/bridge.py", line 112, in is_on
    return self._get_remote() is not None
  File "/usr/src/homeassistant/homeassistant/components/samsungtv/bridge.py", line 338, in _get_remote
    self._remote.open()
  File "/usr/local/lib/python3.9/site-packages/samsungtvws/remote.py", line 146, in open
    self.connection = websocket.create_connection(
  File "/usr/local/lib/python3.9/site-packages/websocket/_core.py", line 596, in create_connection
    websock.connect(url, **options)
  File "/usr/local/lib/python3.9/site-packages/websocket/_core.py", line 249, in connect
    self.sock, addrs = connect(url, self.sock_opt, proxy_info(**options),
  File "/usr/local/lib/python3.9/site-packages/websocket/_http.py", line 130, in connect
    sock = _open_socket(addrinfo_list, options.sockopt, options.timeout)
  File "/usr/local/lib/python3.9/site-packages/websocket/_http.py", line 185, in _open_socket
    sock.connect(address)
SystemExit
