2021-10-03 07:20:36 WARNING (SyncWorker_0) [homeassistant.loader] We found a custom integration average which has not been tested by Home Assistant. This component might cause stability problems, be sure to disable it if you experience issues with Home Assistant
2021-10-03 07:20:36 WARNING (SyncWorker_0) [homeassistant.loader] We found a custom integration hacs which has not been tested by Home Assistant. This component might cause stability problems, be sure to disable it if you experience issues with Home Assistant
2021-10-03 07:20:36 WARNING (SyncWorker_2) [homeassistant.loader] We found a custom integration xiaomi_miio_airpurifier which has not been tested by Home Assistant. This component might cause stability problems, be sure to disable it if you experience issues with Home Assistant
2021-10-03 07:20:36 WARNING (SyncWorker_3) [homeassistant.loader] We found a custom integration audiconnect which has not been tested by Home Assistant. This component might cause stability problems, be sure to disable it if you experience issues with Home Assistant
2021-10-03 07:20:36 WARNING (SyncWorker_0) [homeassistant.loader] We found a custom integration localtuya which has not been tested by Home Assistant. This component might cause stability problems, be sure to disable it if you experience issues with Home Assistant
2021-10-03 07:20:36 WARNING (SyncWorker_4) [homeassistant.loader] We found a custom integration monitor_docker which has not been tested by Home Assistant. This component might cause stability problems, be sure to disable it if you experience issues with Home Assistant
2021-10-03 07:20:36 WARNING (SyncWorker_1) [homeassistant.loader] We found a custom integration powercalc which has not been tested by Home Assistant. This component might cause stability problems, be sure to disable it if you experience issues with Home Assistant
2021-10-03 07:20:36 WARNING (SyncWorker_2) [homeassistant.loader] We found a custom integration xiaomi_miio_fan which has not been tested by Home Assistant. This component might cause stability problems, be sure to disable it if you experience issues with Home Assistant
2021-10-03 07:20:36 WARNING (SyncWorker_6) [homeassistant.loader] We found a custom integration shelly which has not been tested by Home Assistant. This component might cause stability problems, be sure to disable it if you experience issues with Home Assistant
2021-10-03 07:20:36 WARNING (SyncWorker_3) [homeassistant.loader] We found a custom integration tuya_v2 which has not been tested by Home Assistant. This component might cause stability problems, be sure to disable it if you experience issues with Home Assistant
2021-10-03 07:20:36 WARNING (SyncWorker_5) [homeassistant.loader] We found a custom integration buienalarm which has not been tested by Home Assistant. This component might cause stability problems, be sure to disable it if you experience issues with Home Assistant
2021-10-03 07:20:36 WARNING (SyncWorker_8) [homeassistant.loader] We found a custom integration thermal_comfort which has not been tested by Home Assistant. This component might cause stability problems, be sure to disable it if you experience issues with Home Assistant
2021-10-03 07:20:36 WARNING (SyncWorker_4) [homeassistant.loader] We found a custom integration xiaomi_miot which has not been tested by Home Assistant. This component might cause stability problems, be sure to disable it if you experience issues with Home Assistant
2021-10-03 07:20:36 WARNING (SyncWorker_1) [homeassistant.loader] We found a custom integration deepstack_face which has not been tested by Home Assistant. This component might cause stability problems, be sure to disable it if you experience issues with Home Assistant
2021-10-03 07:20:36 WARNING (SyncWorker_0) [homeassistant.loader] We found a custom integration anniversaries which has not been tested by Home Assistant. This component might cause stability problems, be sure to disable it if you experience issues with Home Assistant
2021-10-03 07:20:36 WARNING (SyncWorker_3) [homeassistant.loader] We found a custom integration afvalbeheer which has not been tested by Home Assistant. This component might cause stability problems, be sure to disable it if you experience issues with Home Assistant
2021-10-03 07:20:36 WARNING (SyncWorker_7) [homeassistant.loader] We found a custom integration huesyncbox which has not been tested by Home Assistant. This component might cause stability problems, be sure to disable it if you experience issues with Home Assistant
2021-10-03 07:20:36 WARNING (SyncWorker_5) [homeassistant.loader] We found a custom integration google_home which has not been tested by Home Assistant. This component might cause stability problems, be sure to disable it if you experience issues with Home Assistant
2021-10-03 07:20:36 WARNING (SyncWorker_2) [homeassistant.loader] We found a custom integration ytube_music_player which has not been tested by Home Assistant. This component might cause stability problems, be sure to disable it if you experience issues with Home Assistant
2021-10-03 07:20:36 WARNING (SyncWorker_9) [homeassistant.loader] We found a custom integration googlewifi which has not been tested by Home Assistant. This component might cause stability problems, be sure to disable it if you experience issues with Home Assistant
2021-10-03 07:20:44 ERROR (SyncWorker_2) [homeassistant.components.influxdb] Cannot connect to InfluxDB due to '<urllib3.connection.HTTPConnection object at 0xffff98e0d970>: Failed to establish a new connection: [Errno 111] Connection refused'. Please check that the provided connection details (host, port, etc.) are correct and that your InfluxDB server is running and accessible. Retrying in 60 seconds.
2021-10-03 07:20:50 ERROR (MainThread) [homeassistant.config] Invalid config for [automation]: required key not provided @ data['action'][4]['domain']. Got None. (See ?, line ?). 
2021-10-03 07:20:50 ERROR (MainThread) [homeassistant.config] Invalid config for [automation]: [title] is an invalid option for [automation]. Check: automation->action->1->title. (See ?, line ?). 
2021-10-03 07:20:50 ERROR (MainThread) [homeassistant.config] Invalid config for [automation]: must be a value between 0 and 59 for dictionary value @ data['minutes']. Got None. (See ?, line ?). 
2021-10-03 07:20:50 ERROR (MainThread) [homeassistant.config] Invalid config for [automation]: must be a value between 0 and 59 for dictionary value @ data['minutes']. Got None. (See ?, line ?). 
2021-10-03 07:20:55 WARNING (MainThread) [homeassistant.setup] Setup of input_boolean is taking over 10 seconds.
2021-10-03 07:20:56 WARNING (MainThread) [homeassistant.components.fan] Platform xiaomi_miio_fan not ready yet: Unable to discover the device 192.168.86.29; Retrying in background in 30 seconds
2021-10-03 07:20:56 WARNING (MainThread) [homeassistant.components.fan] Platform xiaomi_miio_fan not ready yet: Unable to discover the device 192.168.86.28; Retrying in background in 30 seconds
2021-10-03 07:20:56 WARNING (MainThread) [homeassistant.setup] Setup of counter is taking over 10 seconds.
2021-10-03 07:20:56 WARNING (MainThread) [homeassistant.setup] Setup of input_text is taking over 10 seconds.
2021-10-03 07:20:56 WARNING (MainThread) [homeassistant.setup] Setup of input_select is taking over 10 seconds.
2021-10-03 07:20:56 WARNING (MainThread) [homeassistant.setup] Setup of input_number is taking over 10 seconds.
2021-10-03 07:20:59 WARNING (MainThread) [homeassistant.config_entries] Config entry '192.168.86.83' for synology_dsm integration not ready yet: {'api': None, 'code': -1, 'reason': 'Unknown', 'details': 'ConnectionError = <urllib3.connection.HTTPSConnection object at 0xffff8cdb40a0>: Failed to establish a new connection: [Errno 113] Host is unreachable'}; Retrying in background
2021-10-03 07:21:00 ERROR (MainThread) [homeassistant.components.automation] Platform automation does not generate unique IDs. ID 1632427763962 already exists - ignoring automation.verwarming_aan_en_raam_open_verwarming_uit
2021-10-03 07:21:01 WARNING (MainThread) [homeassistant.components.light] Platform netatmo not ready yet: None; Retrying in background in 30 seconds
2021-10-03 07:21:01 WARNING (MainThread) [homeassistant.components.select] Platform netatmo not ready yet: None; Retrying in background in 30 seconds
2021-10-03 07:21:04 WARNING (MainThread) [homeassistant.components.sensor] Platform netatmo not ready yet: None; Retrying in background in 30 seconds
2021-10-03 07:21:05 ERROR (SyncWorker_8) [glocaltokens.client] [Device - Nest Wifi router(id=2f2a9d15-0ae2-4ffe-b6c1-2ef24c742b8a)] local_auth_token must follow the correct format
2021-10-03 07:21:05 ERROR (SyncWorker_8) [glocaltokens.client] [Device - Nest Wifi router(id=e1e5a8d5-d21f-444d-95a9-c76d78c9bc79)] local_auth_token must follow the correct format
2021-10-03 07:21:05 ERROR (SyncWorker_8) [glocaltokens.client] [Device - Nest Wifi router(id=ea3de37c-ca74-4689-8171-1681b2f4f924)] local_auth_token must follow the correct format
2021-10-03 07:21:09 ERROR (MainThread) [homeassistant.components.sensor] scrape: Error on device update!
Traceback (most recent call last):
  File "/usr/src/homeassistant/homeassistant/helpers/entity_platform.py", line 431, in _async_add_entity
    await entity.async_device_update(warning=False)
  File "/usr/src/homeassistant/homeassistant/helpers/entity.py", line 633, in async_device_update
    await task
  File "/usr/src/homeassistant/homeassistant/components/scrape/sensor.py", line 139, in async_update
    await self._async_update_from_rest_data()
  File "/usr/src/homeassistant/homeassistant/components/scrape/sensor.py", line 152, in _async_update_from_rest_data
    value = await self.hass.async_add_executor_job(self._extract_value)
  File "/usr/local/lib/python3.9/concurrent/futures/thread.py", line 52, in run
    result = self.fn(*self.args, **self.kwargs)
  File "/usr/src/homeassistant/homeassistant/components/scrape/sensor.py", line 128, in _extract_value
    tag = raw_data.select(self._select)[self._index]
  File "/usr/local/lib/python3.9/site-packages/bs4/element.py", line 1869, in select
    results = soupsieve.select(selector, self, namespaces, limit, **kwargs)
  File "/usr/local/lib/python3.9/site-packages/soupsieve/__init__.py", line 98, in select
    return compile(select, namespaces, flags, **kwargs).select(tag, limit)
  File "/usr/local/lib/python3.9/site-packages/soupsieve/__init__.py", line 62, in compile
    return cp._cached_css_compile(pattern, namespaces, custom, flags)
  File "/usr/local/lib/python3.9/site-packages/soupsieve/css_parser.py", line 211, in _cached_css_compile
    CSSParser(pattern, custom=custom_selectors, flags=flags).process_selectors(),
  File "/usr/local/lib/python3.9/site-packages/soupsieve/css_parser.py", line 1058, in process_selectors
    return self.parse_selectors(self.selector_iter(self.pattern), index, flags)
  File "/usr/local/lib/python3.9/site-packages/soupsieve/css_parser.py", line 909, in parse_selectors
    key, m = next(iselector)
  File "/usr/local/lib/python3.9/site-packages/soupsieve/css_parser.py", line 1051, in selector_iter
    raise SelectorSyntaxError(msg, self.pattern, index)
soupsieve.util.SelectorSyntaxError: Invalid character '<' position 0
  line 1:
<span _ngcontent-app-root-c173="">Offline</span>
^
2021-10-03 07:21:11 WARNING (MainThread) [homeassistant.components.sensor] Setup of sensor platform buienalarm is taking over 10 seconds.
2021-10-03 07:21:11 WARNING (MainThread) [homeassistant.components.sensor] Setup of sensor platform scrape is taking over 10 seconds.
2021-10-03 07:21:11 WARNING (MainThread) [homeassistant.components.sensor] Setup of sensor platform scrape is taking over 10 seconds.
2021-10-03 07:21:11 WARNING (MainThread) [homeassistant.components.sensor] Setup of sensor platform scrape is taking over 10 seconds.
2021-10-03 07:21:11 WARNING (MainThread) [homeassistant.components.sensor] Setup of sensor platform scrape is taking over 10 seconds.
2021-10-03 07:21:11 WARNING (MainThread) [homeassistant.components.media_player] Updating huesyncbox media_player took longer than the scheduled update interval 0:00:02
2021-10-03 07:21:11 WARNING (SyncWorker_6) [buienalarm.pybuienalarm] Error fetching data safely: HTTPSConnectionPool(host='cdn-secure.buienalarm.nl', port=443): Read timed out. (read timeout=10.0)
2021-10-03 07:21:11 WARNING (MainThread) [homeassistant.config_entries] Config entry 'OnHub' for upnp integration not ready yet; Retrying in background
2021-10-03 07:21:32 WARNING (MainThread) [homeassistant.components.media_player] Updating huesyncbox media_player took longer than the scheduled update interval 0:00:02
2021-10-03 07:21:43 WARNING (MainThread) [homeassistant.components.fan] Setup of fan platform xiaomi_miio_fan is taking over 10 seconds.
2021-10-03 07:21:43 WARNING (MainThread) [homeassistant.components.fan] Setup of fan platform xiaomi_miio_fan is taking over 10 seconds.
2021-10-03 07:21:43 ERROR (MainThread) [homeassistant.components.hue.light] Timeout fetching light data
2021-10-03 07:21:43 ERROR (MainThread) [homeassistant.components.mobile_app.notify] Timeout sending notification to https://mobile-apps.home-assistant.io/api/sendPush/android/v1
2021-10-03 07:21:44 ERROR (MainThread) [homeassistant.components.google_assistant.http] Request for https://homegraph.googleapis.com/v1/devices:requestSync failed: 500
2021-10-03 07:21:51 ERROR (MainThread) [homeassistant.components.google_assistant.http] Request for https://homegraph.googleapis.com/v1/devices:reportStateAndNotification failed: 404
2021-10-03 07:26:22 WARNING (SyncWorker_10) [buienalarm.pybuienalarm] Error fetching data safely: HTTPSConnectionPool(host='cdn-secure.buienalarm.nl', port=443): Read timed out. (read timeout=10.0)
2021-10-03 07:31:32 WARNING (SyncWorker_3) [buienalarm.pybuienalarm] Error fetching data safely: HTTPSConnectionPool(host='cdn-secure.buienalarm.nl', port=443): Read timed out. (read timeout=10.0)
2021-10-03 07:32:34 ERROR (MainThread) [homeassistant.config] Invalid config for [automation]: required key not provided @ data['action'][4]['domain']. Got None. (See ?, line ?). 
2021-10-03 07:32:34 ERROR (MainThread) [homeassistant.config] Invalid config for [automation]: [title] is an invalid option for [automation]. Check: automation->action->1->title. (See ?, line ?). 
2021-10-03 07:32:34 ERROR (MainThread) [homeassistant.config] Invalid config for [automation]: must be a value between 0 and 59 for dictionary value @ data['minutes']. Got None. (See ?, line ?). 
2021-10-03 07:32:34 ERROR (MainThread) [homeassistant.config] Invalid config for [automation]: must be a value between 0 and 59 for dictionary value @ data['minutes']. Got None. (See ?, line ?). 
2021-10-03 07:32:41 ERROR (MainThread) [homeassistant.config] Invalid config for [automation]: required key not provided @ data['action'][4]['domain']. Got None. (See ?, line ?). 
2021-10-03 07:32:42 ERROR (MainThread) [homeassistant.config] Invalid config for [automation]: [title] is an invalid option for [automation]. Check: automation->action->1->title. (See ?, line ?). 
2021-10-03 07:32:42 ERROR (MainThread) [homeassistant.config] Invalid config for [automation]: must be a value between 0 and 59 for dictionary value @ data['minutes']. Got None. (See ?, line ?). 
2021-10-03 07:32:42 ERROR (MainThread) [homeassistant.config] Invalid config for [automation]: must be a value between 0 and 59 for dictionary value @ data['minutes']. Got None. (See ?, line ?). 
2021-10-03 07:32:42 ERROR (MainThread) [homeassistant.helpers.entity] Update for sensor.master_bedroom_tv_on_today fails
Traceback (most recent call last):
  File "/usr/src/homeassistant/homeassistant/helpers/entity.py", line 446, in async_update_ha_state
    await self.async_device_update()
  File "/usr/src/homeassistant/homeassistant/helpers/entity.py", line 641, in async_device_update
    raise exc
  File "/usr/src/homeassistant/homeassistant/components/history_stats/sensor.py", line 221, in async_update
    await self.hass.async_add_executor_job(
  File "/usr/local/lib/python3.9/concurrent/futures/thread.py", line 52, in run
    result = self.fn(*self.args, **self.kwargs)
  File "/usr/src/homeassistant/homeassistant/components/history_stats/sensor.py", line 227, in _update
    history_list = history.state_changes_during_period(
  File "/usr/src/homeassistant/homeassistant/components/recorder/history.py", line 142, in state_changes_during_period
    with session_scope(hass=hass) as session:
  File "/usr/local/lib/python3.9/contextlib.py", line 119, in __enter__
    return next(self.gen)
  File "/usr/src/homeassistant/homeassistant/components/recorder/util.py", line 59, in session_scope
    session = hass.data[DATA_INSTANCE].get_session()
TypeError: 'NoneType' object is not callable
