2021-11-08 08:43:38 WARNING (SyncWorker_0) [homeassistant.loader] We found a custom integration average which has not been tested by Home Assistant. This component might cause stability problems, be sure to disable it if you experience issues with Home Assistant
2021-11-08 08:43:38 WARNING (SyncWorker_3) [homeassistant.loader] We found a custom integration audiconnect which has not been tested by Home Assistant. This component might cause stability problems, be sure to disable it if you experience issues with Home Assistant
2021-11-08 08:43:38 WARNING (SyncWorker_2) [homeassistant.loader] We found a custom integration xiaomi_miio_airpurifier which has not been tested by Home Assistant. This component might cause stability problems, be sure to disable it if you experience issues with Home Assistant
2021-11-08 08:43:38 WARNING (SyncWorker_1) [homeassistant.loader] We found a custom integration adaptive_lighting which has not been tested by Home Assistant. This component might cause stability problems, be sure to disable it if you experience issues with Home Assistant
2021-11-08 08:43:38 WARNING (SyncWorker_0) [homeassistant.loader] We found a custom integration hacs which has not been tested by Home Assistant. This component might cause stability problems, be sure to disable it if you experience issues with Home Assistant
2021-11-08 08:43:38 WARNING (SyncWorker_4) [homeassistant.loader] We found a custom integration powercalc which has not been tested by Home Assistant. This component might cause stability problems, be sure to disable it if you experience issues with Home Assistant
2021-11-08 08:43:38 WARNING (SyncWorker_5) [homeassistant.loader] We found a custom integration monitor_docker which has not been tested by Home Assistant. This component might cause stability problems, be sure to disable it if you experience issues with Home Assistant
2021-11-08 08:43:38 WARNING (SyncWorker_7) [homeassistant.loader] We found a custom integration shelly which has not been tested by Home Assistant. This component might cause stability problems, be sure to disable it if you experience issues with Home Assistant
2021-11-08 08:43:38 WARNING (SyncWorker_1) [homeassistant.loader] We found a custom integration localtuya which has not been tested by Home Assistant. This component might cause stability problems, be sure to disable it if you experience issues with Home Assistant
2021-11-08 08:43:38 WARNING (SyncWorker_3) [homeassistant.loader] We found a custom integration tuya_v2 which has not been tested by Home Assistant. This component might cause stability problems, be sure to disable it if you experience issues with Home Assistant
2021-11-08 08:43:38 WARNING (SyncWorker_9) [homeassistant.loader] We found a custom integration thermal_comfort which has not been tested by Home Assistant. This component might cause stability problems, be sure to disable it if you experience issues with Home Assistant
2021-11-08 08:43:38 WARNING (SyncWorker_5) [homeassistant.loader] We found a custom integration xiaomi_miot which has not been tested by Home Assistant. This component might cause stability problems, be sure to disable it if you experience issues with Home Assistant
2021-11-08 08:43:38 WARNING (SyncWorker_6) [homeassistant.loader] We found a custom integration xiaomi_miio_fan which has not been tested by Home Assistant. This component might cause stability problems, be sure to disable it if you experience issues with Home Assistant
2021-11-08 08:43:38 WARNING (SyncWorker_8) [homeassistant.loader] We found a custom integration huesyncbox which has not been tested by Home Assistant. This component might cause stability problems, be sure to disable it if you experience issues with Home Assistant
2021-11-08 08:43:38 WARNING (SyncWorker_0) [homeassistant.loader] We found a custom integration buienalarm which has not been tested by Home Assistant. This component might cause stability problems, be sure to disable it if you experience issues with Home Assistant
2021-11-08 08:43:38 WARNING (SyncWorker_2) [homeassistant.loader] We found a custom integration frigate which has not been tested by Home Assistant. This component might cause stability problems, be sure to disable it if you experience issues with Home Assistant
2021-11-08 08:43:38 WARNING (SyncWorker_4) [homeassistant.loader] We found a custom integration googlewifi which has not been tested by Home Assistant. This component might cause stability problems, be sure to disable it if you experience issues with Home Assistant
2021-11-08 08:43:38 WARNING (SyncWorker_6) [homeassistant.loader] We found a custom integration ytube_music_player which has not been tested by Home Assistant. This component might cause stability problems, be sure to disable it if you experience issues with Home Assistant
2021-11-08 08:43:38 WARNING (SyncWorker_5) [homeassistant.loader] We found a custom integration anniversaries which has not been tested by Home Assistant. This component might cause stability problems, be sure to disable it if you experience issues with Home Assistant
2021-11-08 08:43:38 WARNING (SyncWorker_0) [homeassistant.loader] We found a custom integration afvalbeheer which has not been tested by Home Assistant. This component might cause stability problems, be sure to disable it if you experience issues with Home Assistant
2021-11-08 08:43:38 WARNING (SyncWorker_9) [homeassistant.loader] We found a custom integration deepstack_face which has not been tested by Home Assistant. This component might cause stability problems, be sure to disable it if you experience issues with Home Assistant
2021-11-08 08:43:38 WARNING (SyncWorker_11) [homeassistant.loader] We found a custom integration google_home which has not been tested by Home Assistant. This component might cause stability problems, be sure to disable it if you experience issues with Home Assistant
2021-11-08 08:43:46 ERROR (SyncWorker_6) [homeassistant.components.influxdb] InfluxDB bucket is not accessible due to '(401)
Reason: Unauthorized
HTTP response headers: HTTPHeaderDict({'Content-Type': 'application/json; charset=utf-8', 'X-Influxdb-Build': 'OSS', 'X-Influxdb-Version': '2.1.0', 'X-Platform-Error-Code': 'unauthorized', 'Date': 'Mon, 08 Nov 2021 08:43:46 GMT', 'Content-Length': '55'})
HTTP response body: {"code":"unauthorized","message":"unauthorized access"}
'. Please check that the bucket, org and token are correct and that the token has the correct permissions set. Retrying in 60 seconds.
2021-11-08 08:43:46 WARNING (MainThread) [homeassistant.helpers.frame] Detected integration that called async_timeout.timeout with loop keyword argument. The loop keyword argument is deprecated and calls will fail after Home Assistant 2022.2. Please report issue for pi_hole using this method at homeassistant/components/pi_hole/__init__.py, line 111: await api.get_data()
2021-11-08 08:43:47 ERROR (MainThread) [homeassistant.config] Invalid config for [automation]: expected str for dictionary value @ data['from']. Got None. (See ?, line ?). 
2021-11-08 08:43:47 ERROR (MainThread) [homeassistant.config] Invalid config for [automation]: required key not provided @ data['action'][4]['domain']. Got None. (See ?, line ?). 
2021-11-08 08:43:47 ERROR (MainThread) [homeassistant.config] Invalid config for [automation]: must be a value between 0 and 59 for dictionary value @ data['minutes']. Got None. (See ?, line ?). 
2021-11-08 08:43:47 ERROR (MainThread) [homeassistant.config] Invalid config for [automation]: must be a value between 0 and 59 for dictionary value @ data['minutes']. Got None. (See ?, line ?). 
2021-11-08 08:43:49 WARNING (MainThread) [homeassistant.helpers.frame] Detected integration that called async_timeout.timeout with loop keyword argument. The loop keyword argument is deprecated and calls will fail after Home Assistant 2022.2. Please report issue for pi_hole using this method at homeassistant/components/pi_hole/__init__.py, line 119: await api.get_data()
2021-11-08 08:44:46 ERROR (SyncWorker_8) [homeassistant.components.influxdb] InfluxDB bucket is not accessible due to '(401)
Reason: Unauthorized
HTTP response headers: HTTPHeaderDict({'Content-Type': 'application/json; charset=utf-8', 'X-Influxdb-Build': 'OSS', 'X-Influxdb-Version': '2.1.0', 'X-Platform-Error-Code': 'unauthorized', 'Date': 'Mon, 08 Nov 2021 08:44:46 GMT', 'Content-Length': '55'})
HTTP response body: {"code":"unauthorized","message":"unauthorized access"}
'. Please check that the bucket, org and token are correct and that the token has the correct permissions set. Retrying in 60 seconds.
2021-11-08 08:44:47 ERROR (MainThread) [homeassistant.components.google_assistant.http] Request for https://homegraph.googleapis.com/v1/devices:reportStateAndNotification failed: 404
2021-11-08 08:45:44 WARNING (MainThread) [homeassistant.components.webhook] Received message for unregistered webhook 80adf825ef6b969ee3c95fc54091652f8a80fe790532f31c6bff63908742af08 from 192.168.86.26
2021-11-08 08:45:45 WARNING (MainThread) [homeassistant.components.webhook] Received message for unregistered webhook 80adf825ef6b969ee3c95fc54091652f8a80fe790532f31c6bff63908742af08 from 192.168.86.26
2021-11-08 08:45:46 ERROR (SyncWorker_8) [homeassistant.components.influxdb] InfluxDB bucket is not accessible due to '(401)
Reason: Unauthorized
HTTP response headers: HTTPHeaderDict({'Content-Type': 'application/json; charset=utf-8', 'X-Influxdb-Build': 'OSS', 'X-Influxdb-Version': '2.1.0', 'X-Platform-Error-Code': 'unauthorized', 'Date': 'Mon, 08 Nov 2021 08:45:46 GMT', 'Content-Length': '55'})
HTTP response body: {"code":"unauthorized","message":"unauthorized access"}
'. Please check that the bucket, org and token are correct and that the token has the correct permissions set. Retrying in 60 seconds.
2021-11-08 08:45:53 WARNING (MainThread) [homeassistant.bootstrap] Waiting on integrations to complete setup: hacs
2021-11-08 08:45:53 WARNING (MainThread) [homeassistant.components.webhook] Received message for unregistered webhook 8b8f82ade2e454d538c7b1b55e021814b7aa12b9fa3693773bc28dc044af0487 from 192.168.86.34
2021-11-08 08:46:35 WARNING (MainThread) [homeassistant.components.webhook] Received message for unregistered webhook 8b8f82ade2e454d538c7b1b55e021814b7aa12b9fa3693773bc28dc044af0487 from 192.168.86.34
2021-11-08 08:46:46 ERROR (SyncWorker_0) [homeassistant.components.influxdb] InfluxDB bucket is not accessible due to '(401)
Reason: Unauthorized
HTTP response headers: HTTPHeaderDict({'Content-Type': 'application/json; charset=utf-8', 'X-Influxdb-Build': 'OSS', 'X-Influxdb-Version': '2.1.0', 'X-Platform-Error-Code': 'unauthorized', 'Date': 'Mon, 08 Nov 2021 08:46:46 GMT', 'Content-Length': '55'})
HTTP response body: {"code":"unauthorized","message":"unauthorized access"}
'. Please check that the bucket, org and token are correct and that the token has the correct permissions set. Retrying in 60 seconds.
2021-11-08 08:47:18 WARNING (MainThread) [homeassistant.bootstrap] Waiting on integrations to complete setup: anniversaries, nfandroidtv
2021-11-08 08:47:46 ERROR (SyncWorker_7) [homeassistant.components.influxdb] InfluxDB bucket is not accessible due to '(401)
Reason: Unauthorized
HTTP response headers: HTTPHeaderDict({'Content-Type': 'application/json; charset=utf-8', 'X-Influxdb-Build': 'OSS', 'X-Influxdb-Version': '2.1.0', 'X-Platform-Error-Code': 'unauthorized', 'Date': 'Mon, 08 Nov 2021 08:47:46 GMT', 'Content-Length': '55'})
HTTP response body: {"code":"unauthorized","message":"unauthorized access"}
'. Please check that the bucket, org and token are correct and that the token has the correct permissions set. Retrying in 60 seconds.
2021-11-08 08:48:40 WARNING (MainThread) [homeassistant.bootstrap] Waiting on integrations to complete setup: co2signal
2021-11-08 08:48:47 ERROR (SyncWorker_2) [homeassistant.components.influxdb] InfluxDB bucket is not accessible due to '(401)
Reason: Unauthorized
HTTP response headers: HTTPHeaderDict({'Content-Type': 'application/json; charset=utf-8', 'X-Influxdb-Build': 'OSS', 'X-Influxdb-Version': '2.1.0', 'X-Platform-Error-Code': 'unauthorized', 'Date': 'Mon, 08 Nov 2021 08:48:47 GMT', 'Content-Length': '55'})
HTTP response body: {"code":"unauthorized","message":"unauthorized access"}
'. Please check that the bucket, org and token are correct and that the token has the correct permissions set. Retrying in 60 seconds.
2021-11-08 08:48:48 WARNING (MainThread) [homeassistant.config_entries] Config entry '192.168.86.83' for synology_dsm integration not ready yet: ConnectionError = <urllib3.connection.HTTPSConnection object at 0xffffa49b0d90>: Failed to establish a new connection: [Errno 113] Host is unreachable; Retrying in background
2021-11-08 08:48:49 WARNING (MainThread) [homeassistant.helpers.frame] Detected integration that called async_timeout.timeout with loop keyword argument. The loop keyword argument is deprecated and calls will fail after Home Assistant 2022.2. Please report issue for pi_hole using this method at homeassistant/components/pi_hole/__init__.py, line 119: await api.get_data()
2021-11-08 08:48:50 WARNING (MainThread) [homeassistant.components.fan] Platform xiaomi_miio_fan not ready yet: Unable to discover the device 192.168.86.28; Retrying in background in 30 seconds
2021-11-08 08:48:50 WARNING (MainThread) [homeassistant.components.fan] Platform xiaomi_miio_fan not ready yet: Unable to discover the device 192.168.86.29; Retrying in background in 30 seconds
2021-11-08 08:48:50 WARNING (MainThread) [homeassistant.components.light] Platform netatmo not ready yet: None; Retrying in background in 30 seconds
2021-11-08 08:48:50 WARNING (MainThread) [homeassistant.components.select] Platform netatmo not ready yet: None; Retrying in background in 30 seconds
2021-11-08 08:48:50 WARNING (MainThread) [homeassistant.components.hue.light] Please check for software updates of the douche bulb in the Philips Hue App.
2021-11-08 08:48:50 WARNING (MainThread) [homeassistant.components.hue.light] Please check for software updates of the wasbak rechts bulb in the Philips Hue App.
2021-11-08 08:48:54 ERROR (MainThread) [homeassistant.components.camera] Error while setting up netatmo platform for camera
Traceback (most recent call last):
  File "/usr/local/lib/python3.9/site-packages/aiohttp/connector.py", line 985, in _wrap_create_connection
    return await self._loop.create_connection(*args, **kwargs)  # type: ignore[return-value]  # noqa
  File "/usr/local/lib/python3.9/asyncio/base_events.py", line 1056, in create_connection
    raise exceptions[0]
  File "/usr/local/lib/python3.9/asyncio/base_events.py", line 1041, in create_connection
    sock = await self._connect_sock(
  File "/usr/local/lib/python3.9/asyncio/base_events.py", line 955, in _connect_sock
    await self.sock_connect(sock, address)
  File "/usr/local/lib/python3.9/asyncio/selector_events.py", line 502, in sock_connect
    return await fut
  File "/usr/local/lib/python3.9/asyncio/selector_events.py", line 537, in _sock_connect_cb
    raise OSError(err, f'Connect call failed {address}')
OSError: [Errno 113] Connect call failed ('169.254.215.165', 80)

The above exception was the direct cause of the following exception:

Traceback (most recent call last):
  File "/usr/src/homeassistant/homeassistant/helpers/entity_platform.py", line 249, in _async_setup_platform
    await asyncio.shield(task)
  File "/usr/src/homeassistant/homeassistant/components/netatmo/camera.py", line 58, in async_setup_entry
    await data_handler.register_data_class(
  File "/usr/src/homeassistant/homeassistant/components/netatmo/data_handler.py", line 187, in register_data_class
    await self.async_fetch_data(data_class_entry)
  File "/usr/src/homeassistant/homeassistant/components/netatmo/data_handler.py", line 144, in async_fetch_data
    await self.data[data_class_entry].async_update()
  File "/usr/local/lib/python3.9/site-packages/pyatmo/camera.py", line 652, in async_update
    await self._async_update_all_camera_urls()
  File "/usr/local/lib/python3.9/site-packages/pyatmo/camera.py", line 662, in _async_update_all_camera_urls
    await self.async_update_camera_urls(camera_id)
  File "/usr/local/lib/python3.9/site-packages/pyatmo/camera.py", line 728, in async_update_camera_urls
    ] = await self._async_check_url(
  File "/usr/local/lib/python3.9/site-packages/pyatmo/camera.py", line 735, in _async_check_url
    resp = await self.auth.async_post_request(url=f"{url}/command/ping")
  File "/usr/local/lib/python3.9/site-packages/pyatmo/auth.py", line 339, in async_post_request
    async with self.websession.post(
  File "/usr/local/lib/python3.9/site-packages/aiohttp/client.py", line 1140, in __aenter__
    self._resp = await self._coro
  File "/usr/local/lib/python3.9/site-packages/aiohttp/client.py", line 535, in _request
    conn = await self._connector.connect(
  File "/usr/local/lib/python3.9/site-packages/aiohttp/connector.py", line 543, in connect
    proto = await self._create_connection(req, traces, timeout)
  File "/usr/local/lib/python3.9/site-packages/aiohttp/connector.py", line 906, in _create_connection
    _, proto = await self._create_direct_connection(req, traces, timeout)
  File "/usr/local/lib/python3.9/site-packages/aiohttp/connector.py", line 1205, in _create_direct_connection
    raise last_exc
  File "/usr/local/lib/python3.9/site-packages/aiohttp/connector.py", line 1174, in _create_direct_connection
    transp, proto = await self._wrap_create_connection(
  File "/usr/local/lib/python3.9/site-packages/aiohttp/connector.py", line 991, in _wrap_create_connection
    raise client_error(req.connection_key, exc) from exc
aiohttp.client_exceptions.ClientConnectorError: Cannot connect to host 169.254.215.165:80 ssl:default [Connect call failed ('169.254.215.165', 80)]
2021-11-08 08:49:00 WARNING (MainThread) [homeassistant.setup] Setup of default_config is taking over 10 seconds.
2021-11-08 08:49:29 WARNING (MainThread) [homeassistant.components.binary_sensor] Updating ping binary_sensor took longer than the scheduled update interval 0:00:05
2021-11-08 08:49:44 WARNING (MainThread) [homeassistant.bootstrap] Setup timed out for stage 2 - moving forward
2021-11-08 08:49:47 WARNING (MainThread) [homeassistant.bootstrap] Waiting on integrations to complete setup: default_config
2021-11-08 08:49:47 ERROR (SyncWorker_7) [homeassistant.components.influxdb] InfluxDB bucket is not accessible due to '(401)
Reason: Unauthorized
HTTP response headers: HTTPHeaderDict({'Content-Type': 'application/json; charset=utf-8', 'X-Influxdb-Build': 'OSS', 'X-Influxdb-Version': '2.1.0', 'X-Platform-Error-Code': 'unauthorized', 'Date': 'Mon, 08 Nov 2021 08:49:47 GMT', 'Content-Length': '55'})
HTTP response body: {"code":"unauthorized","message":"unauthorized access"}
'. Please check that the bucket, org and token are correct and that the token has the correct permissions set. Retrying in 60 seconds.
2021-11-08 08:49:54 WARNING (MainThread) [homeassistant.components.binary_sensor] Updating ping binary_sensor took longer than the scheduled update interval 0:00:05
2021-11-08 08:50:22 WARNING (MainThread) [homeassistant.helpers.frame] Detected integration that called async_timeout.timeout with loop keyword argument. The loop keyword argument is deprecated and calls will fail after Home Assistant 2022.2. Please report issue to the custom component author for hacs using this method at custom_components/hacs/helpers/functions/download.py, line 43: with async_timeout.timeout(60, loop=hacs.hass.loop):
2021-11-08 08:50:22 WARNING (MainThread) [homeassistant.helpers.frame] Detected integration that called async_timeout.timeout with loop keyword argument. The loop keyword argument is deprecated and calls will fail after Home Assistant 2022.2. Please report issue to the custom component author for hacs using this method at custom_components/hacs/helpers/functions/download.py, line 43: with async_timeout.timeout(60, loop=hacs.hass.loop):
2021-11-08 08:50:30 WARNING (MainThread) [homeassistant.config_entries] Config entry 'OnHub' for upnp integration not ready yet; Retrying in background
2021-11-08 08:50:47 ERROR (SyncWorker_3) [homeassistant.components.influxdb] InfluxDB bucket is not accessible due to '(401)
Reason: Unauthorized
HTTP response headers: HTTPHeaderDict({'Content-Type': 'application/json; charset=utf-8', 'X-Influxdb-Build': 'OSS', 'X-Influxdb-Version': '2.1.0', 'X-Platform-Error-Code': 'unauthorized', 'Date': 'Mon, 08 Nov 2021 08:50:47 GMT', 'Content-Length': '55'})
HTTP response body: {"code":"unauthorized","message":"unauthorized access"}
'. Please check that the bucket, org and token are correct and that the token has the correct permissions set. Retrying in 60 seconds.
2021-11-08 08:51:00 WARNING (MainThread) [homeassistant.bootstrap] Waiting on integrations to complete setup: sensor.version, sensor.command_line, sensor.command_line_2, sensor.thermal_comfort, sensor.template, sensor.history_stats, sensor.afvalbeheer, sensor.buienalarm, sensor.time_date, sensor.min_max, sensor.scrape, sensor.scrape_2, sensor.scrape_3, sensor.scrape_4, sensor.scrape_5, sensor.scrape_6, sensor.scrape_7, sensor.systemmonitor, sensor.command_line_3, sensor.integration, sensor.filesize, sensor.buienradar, sensor.speedtestdotnet, sensor.pi_hole, sensor.hacs, sensor.co2signal, sensor.mobile_app, sensor.mobile_app_2, sensor.mobile_app_3, sensor.mobile_app_4, sensor.brother, sensor.tado, sensor.deconz, sensor.ipp, sensor.hue, sensor.netatmo, sensor.hue_2, sensor.tuya, sensor.audiconnect, sensor.googlewifi, sensor.google_home, sensor.powercalc, sensor.powercalc_2, sensor.powercalc_3, sensor.powercalc_4, sensor.powercalc_5, sensor.powercalc_6, sensor.powercalc_7, sensor.powercalc_8, sensor.powercalc_9, sensor.powercalc_10, sensor.powercalc_11, sensor.energy, sensor.template_2, sensor.utility_meter, sensor.utility_meter_2, sensor.anniversaries, sensor.anniversaries_2, sensor.anniversaries_3, sensor.anniversaries_4, sensor.anniversaries_5
2021-11-08 08:51:01 ERROR (MainThread) [custom_components.powercalc.sensors.power] Skipping sensor setup light.buiten: ('No lookup file found for mode', 'brightness')
2021-11-08 08:51:01 WARNING (MainThread) [homeassistant.helpers.frame] Detected integration that called async_timeout.timeout with loop keyword argument. The loop keyword argument is deprecated and calls will fail after Home Assistant 2022.2. Please report issue for pi_hole using this method at homeassistant/components/pi_hole/__init__.py, line 119: await api.get_data()
2021-11-08 08:51:03 WARNING (MainThread) [homeassistant.components.sensor] Platform netatmo not ready yet: None; Retrying in background in 30 seconds
2021-11-08 08:51:07 WARNING (MainThread) [homeassistant.components.binary_sensor] Updating ping binary_sensor took longer than the scheduled update interval 0:00:05
2021-11-08 08:51:07 ERROR (MainThread) [homeassistant.components.sensor] scrape: Error on device update!
Traceback (most recent call last):
  File "/usr/src/homeassistant/homeassistant/helpers/entity_platform.py", line 431, in _async_add_entity
    await entity.async_device_update(warning=False)
  File "/usr/src/homeassistant/homeassistant/helpers/entity.py", line 645, in async_device_update
    await task
  File "/usr/src/homeassistant/homeassistant/components/scrape/sensor.py", line 166, in async_update
    await self._async_update_from_rest_data()
  File "/usr/src/homeassistant/homeassistant/components/scrape/sensor.py", line 179, in _async_update_from_rest_data
    value = await self.hass.async_add_executor_job(self._extract_value)
  File "/usr/local/lib/python3.9/concurrent/futures/thread.py", line 52, in run
    result = self.fn(*self.args, **self.kwargs)
  File "/usr/src/homeassistant/homeassistant/components/scrape/sensor.py", line 155, in _extract_value
    tag = raw_data.select(self._select)[self._index]
  File "/usr/local/lib/python3.9/site-packages/bs4/element.py", line 1949, in select
    results = soupsieve.select(selector, self, namespaces, limit, **kwargs)
  File "/usr/local/lib/python3.9/site-packages/soupsieve/__init__.py", line 144, in select
    return compile(select, namespaces, flags, **kwargs).select(tag, limit)
  File "/usr/local/lib/python3.9/site-packages/soupsieve/__init__.py", line 67, in compile
    return cp._cached_css_compile(pattern, ns, cs, flags)
  File "/usr/local/lib/python3.9/site-packages/soupsieve/css_parser.py", line 218, in _cached_css_compile
    CSSParser(
  File "/usr/local/lib/python3.9/site-packages/soupsieve/css_parser.py", line 1159, in process_selectors
    return self.parse_selectors(self.selector_iter(self.pattern), index, flags)
  File "/usr/local/lib/python3.9/site-packages/soupsieve/css_parser.py", line 985, in parse_selectors
    key, m = next(iselector)
  File "/usr/local/lib/python3.9/site-packages/soupsieve/css_parser.py", line 1152, in selector_iter
    raise SelectorSyntaxError(msg, self.pattern, index)
soupsieve.util.SelectorSyntaxError: Invalid character '<' position 0
  line 1:
<span _ngcontent-app-root-c173="">Offline</span>
^
2021-11-08 08:51:38 WARNING (MainThread) [homeassistant.components.media_player] Updating huesyncbox media_player took longer than the scheduled update interval 0:00:02
2021-11-08 08:51:38 ERROR (MainThread) [homeassistant] Error doing job: Task exception was never retrieved
Traceback (most recent call last):
  File "/usr/src/homeassistant/homeassistant/components/netatmo/__init__.py", line 220, in register_webhook
    await hass.data[DOMAIN][entry.entry_id][AUTH].async_addwebhook(webhook_url)
  File "/usr/local/lib/python3.9/site-packages/pyatmo/auth.py", line 381, in async_addwebhook
    resp = await self.async_post_request(WEBHOOK_URL_ADD, {"url": webhook_url})
  File "/usr/local/lib/python3.9/site-packages/pyatmo/auth.py", line 339, in async_post_request
    async with self.websession.post(
  File "/usr/local/lib/python3.9/site-packages/aiohttp/client.py", line 1140, in __aenter__
    self._resp = await self._coro
  File "/usr/local/lib/python3.9/site-packages/aiohttp/client.py", line 634, in _request
    break
  File "/usr/local/lib/python3.9/site-packages/aiohttp/helpers.py", line 718, in __exit__
    raise asyncio.TimeoutError from None
asyncio.exceptions.TimeoutError
2021-11-08 08:51:38 WARNING (MainThread) [homeassistant.components.binary_sensor] Updating ping binary_sensor took longer than the scheduled update interval 0:00:05
2021-11-08 08:51:41 ERROR (MainThread) [homeassistant.components.google_assistant.http] Request for https://homegraph.googleapis.com/v1/devices:requestSync failed: 500
2021-11-08 08:51:43 WARNING (MainThread) [homeassistant.helpers.entity] Update of binary_sensor.google_server is taking over 10 seconds
2021-11-08 08:51:43 WARNING (MainThread) [homeassistant.components.binary_sensor] Updating ping binary_sensor took longer than the scheduled update interval 0:00:05
2021-11-08 08:51:53 ERROR (SyncWorker_14) [homeassistant.components.influxdb] InfluxDB bucket is not accessible due to '(401)
Reason: Unauthorized
HTTP response headers: HTTPHeaderDict({'Content-Type': 'application/json; charset=utf-8', 'X-Influxdb-Build': 'OSS', 'X-Influxdb-Version': '2.1.0', 'X-Platform-Error-Code': 'unauthorized', 'Date': 'Mon, 08 Nov 2021 08:51:53 GMT', 'Content-Length': '55'})
HTTP response body: {"code":"unauthorized","message":"unauthorized access"}
'. Please check that the bucket, org and token are correct and that the token has the correct permissions set. Retrying in 60 seconds.
2021-11-08 08:51:54 WARNING (MainThread) [homeassistant.components.binary_sensor] Updating ping binary_sensor took longer than the scheduled update interval 0:00:05
2021-11-08 08:51:54 ERROR (MainThread) [custom_components.ytube_music_player.media_player] async_update_selects failed
2021-11-08 08:52:03 WARNING (MainThread) [homeassistant.components.binary_sensor] Updating ping binary_sensor took longer than the scheduled update interval 0:00:05
2021-11-08 08:52:13 WARNING (MainThread) [homeassistant.components.binary_sensor] Updating ping binary_sensor took longer than the scheduled update interval 0:00:05
2021-11-08 08:52:28 WARNING (MainThread) [homeassistant.components.binary_sensor] Updating ping binary_sensor took longer than the scheduled update interval 0:00:05
2021-11-08 08:52:54 ERROR (SyncWorker_3) [homeassistant.components.influxdb] InfluxDB bucket is not accessible due to '(401)
Reason: Unauthorized
HTTP response headers: HTTPHeaderDict({'Content-Type': 'application/json; charset=utf-8', 'X-Influxdb-Build': 'OSS', 'X-Influxdb-Version': '2.1.0', 'X-Platform-Error-Code': 'unauthorized', 'Date': 'Mon, 08 Nov 2021 08:52:54 GMT', 'Content-Length': '55'})
HTTP response body: {"code":"unauthorized","message":"unauthorized access"}
'. Please check that the bucket, org and token are correct and that the token has the correct permissions set. Retrying in 60 seconds.
2021-11-08 08:53:49 ERROR (MainThread) [homeassistant.components.google_assistant.http] Request for https://homegraph.googleapis.com/v1/devices:reportStateAndNotification failed: 404
2021-11-08 08:53:54 ERROR (SyncWorker_6) [homeassistant.components.influxdb] InfluxDB bucket is not accessible due to '(401)
Reason: Unauthorized
HTTP response headers: HTTPHeaderDict({'Content-Type': 'application/json; charset=utf-8', 'X-Influxdb-Build': 'OSS', 'X-Influxdb-Version': '2.1.0', 'X-Platform-Error-Code': 'unauthorized', 'Date': 'Mon, 08 Nov 2021 08:53:54 GMT', 'Content-Length': '55'})
HTTP response body: {"code":"unauthorized","message":"unauthorized access"}
'. Please check that the bucket, org and token are correct and that the token has the correct permissions set. Retrying in 60 seconds.
2021-11-08 08:54:54 ERROR (SyncWorker_11) [homeassistant.components.influxdb] InfluxDB bucket is not accessible due to '(401)
Reason: Unauthorized
HTTP response headers: HTTPHeaderDict({'Content-Type': 'application/json; charset=utf-8', 'X-Influxdb-Build': 'OSS', 'X-Influxdb-Version': '2.1.0', 'X-Platform-Error-Code': 'unauthorized', 'Date': 'Mon, 08 Nov 2021 08:54:54 GMT', 'Content-Length': '55'})
HTTP response body: {"code":"unauthorized","message":"unauthorized access"}
'. Please check that the bucket, org and token are correct and that the token has the correct permissions set. Retrying in 60 seconds.
2021-11-08 08:55:30 ERROR (MainThread) [homeassistant.components.google_assistant.http] Request for https://homegraph.googleapis.com/v1/devices:reportStateAndNotification failed: 404
2021-11-08 08:55:54 ERROR (SyncWorker_12) [homeassistant.components.influxdb] InfluxDB bucket is not accessible due to '(401)
Reason: Unauthorized
HTTP response headers: HTTPHeaderDict({'Content-Type': 'application/json; charset=utf-8', 'X-Influxdb-Build': 'OSS', 'X-Influxdb-Version': '2.1.0', 'X-Platform-Error-Code': 'unauthorized', 'Date': 'Mon, 08 Nov 2021 08:55:54 GMT', 'Content-Length': '55'})
HTTP response body: {"code":"unauthorized","message":"unauthorized access"}
'. Please check that the bucket, org and token are correct and that the token has the correct permissions set. Retrying in 60 seconds.
2021-11-08 08:56:02 WARNING (MainThread) [homeassistant.helpers.frame] Detected integration that called async_timeout.timeout with loop keyword argument. The loop keyword argument is deprecated and calls will fail after Home Assistant 2022.2. Please report issue for pi_hole using this method at homeassistant/components/pi_hole/__init__.py, line 119: await api.get_data()
2021-11-08 08:56:54 ERROR (SyncWorker_5) [homeassistant.components.influxdb] InfluxDB bucket is not accessible due to '(401)
Reason: Unauthorized
HTTP response headers: HTTPHeaderDict({'Content-Type': 'application/json; charset=utf-8', 'X-Influxdb-Build': 'OSS', 'X-Influxdb-Version': '2.1.0', 'X-Platform-Error-Code': 'unauthorized', 'Date': 'Mon, 08 Nov 2021 08:56:54 GMT', 'Content-Length': '55'})
HTTP response body: {"code":"unauthorized","message":"unauthorized access"}
'. Please check that the bucket, org and token are correct and that the token has the correct permissions set. Retrying in 60 seconds.
2021-11-08 08:57:54 ERROR (SyncWorker_0) [homeassistant.components.influxdb] InfluxDB bucket is not accessible due to '(401)
Reason: Unauthorized
HTTP response headers: HTTPHeaderDict({'Content-Type': 'application/json; charset=utf-8', 'X-Influxdb-Build': 'OSS', 'X-Influxdb-Version': '2.1.0', 'X-Platform-Error-Code': 'unauthorized', 'Date': 'Mon, 08 Nov 2021 08:57:54 GMT', 'Content-Length': '55'})
HTTP response body: {"code":"unauthorized","message":"unauthorized access"}
'. Please check that the bucket, org and token are correct and that the token has the correct permissions set. Retrying in 60 seconds.
2021-11-08 08:58:24 WARNING (MainThread) [homeassistant.components.binary_sensor] Updating ping binary_sensor took longer than the scheduled update interval 0:00:05
2021-11-08 08:58:54 ERROR (SyncWorker_4) [homeassistant.components.influxdb] InfluxDB bucket is not accessible due to '(401)
Reason: Unauthorized
HTTP response headers: HTTPHeaderDict({'Content-Type': 'application/json; charset=utf-8', 'X-Influxdb-Build': 'OSS', 'X-Influxdb-Version': '2.1.0', 'X-Platform-Error-Code': 'unauthorized', 'Date': 'Mon, 08 Nov 2021 08:58:54 GMT', 'Content-Length': '55'})
HTTP response body: {"code":"unauthorized","message":"unauthorized access"}
'. Please check that the bucket, org and token are correct and that the token has the correct permissions set. Retrying in 60 seconds.
2021-11-08 08:59:09 WARNING (MainThread) [homeassistant.components.binary_sensor] Updating ping binary_sensor took longer than the scheduled update interval 0:00:05
2021-11-08 08:59:54 ERROR (SyncWorker_11) [homeassistant.components.influxdb] InfluxDB bucket is not accessible due to '(401)
Reason: Unauthorized
HTTP response headers: HTTPHeaderDict({'Content-Type': 'application/json; charset=utf-8', 'X-Influxdb-Build': 'OSS', 'X-Influxdb-Version': '2.1.0', 'X-Platform-Error-Code': 'unauthorized', 'Date': 'Mon, 08 Nov 2021 08:59:54 GMT', 'Content-Length': '55'})
HTTP response body: {"code":"unauthorized","message":"unauthorized access"}
'. Please check that the bucket, org and token are correct and that the token has the correct permissions set. Retrying in 60 seconds.
2021-11-08 09:00:54 ERROR (SyncWorker_3) [homeassistant.components.influxdb] InfluxDB bucket is not accessible due to '(401)
Reason: Unauthorized
HTTP response headers: HTTPHeaderDict({'Content-Type': 'application/json; charset=utf-8', 'X-Influxdb-Build': 'OSS', 'X-Influxdb-Version': '2.1.0', 'X-Platform-Error-Code': 'unauthorized', 'Date': 'Mon, 08 Nov 2021 09:00:54 GMT', 'Content-Length': '55'})
HTTP response body: {"code":"unauthorized","message":"unauthorized access"}
'. Please check that the bucket, org and token are correct and that the token has the correct permissions set. Retrying in 60 seconds.
2021-11-08 09:01:02 WARNING (MainThread) [homeassistant.helpers.frame] Detected integration that called async_timeout.timeout with loop keyword argument. The loop keyword argument is deprecated and calls will fail after Home Assistant 2022.2. Please report issue for pi_hole using this method at homeassistant/components/pi_hole/__init__.py, line 119: await api.get_data()
2021-11-08 09:01:54 ERROR (SyncWorker_8) [homeassistant.components.influxdb] InfluxDB bucket is not accessible due to '(401)
Reason: Unauthorized
HTTP response headers: HTTPHeaderDict({'Content-Type': 'application/json; charset=utf-8', 'X-Influxdb-Build': 'OSS', 'X-Influxdb-Version': '2.1.0', 'X-Platform-Error-Code': 'unauthorized', 'Date': 'Mon, 08 Nov 2021 09:01:54 GMT', 'Content-Length': '55'})
HTTP response body: {"code":"unauthorized","message":"unauthorized access"}
'. Please check that the bucket, org and token are correct and that the token has the correct permissions set. Retrying in 60 seconds.
2021-11-08 09:02:43 ERROR (MainThread) [homeassistant.config] Invalid config for [automation]: expected str for dictionary value @ data['from']. Got None. (See ?, line ?). 
2021-11-08 09:02:43 ERROR (MainThread) [homeassistant.config] Invalid config for [automation]: required key not provided @ data['action'][4]['domain']. Got None. (See ?, line ?). 
2021-11-08 09:02:43 ERROR (MainThread) [homeassistant.config] Invalid config for [automation]: must be a value between 0 and 59 for dictionary value @ data['minutes']. Got None. (See ?, line ?). 
2021-11-08 09:02:43 ERROR (MainThread) [homeassistant.config] Invalid config for [automation]: must be a value between 0 and 59 for dictionary value @ data['minutes']. Got None. (See ?, line ?). 
2021-11-08 09:02:44 ERROR (MainThread) [homeassistant.helpers.entity] Update for sensor.master_bedroom_tv_on_today fails
Traceback (most recent call last):
  File "/usr/src/homeassistant/homeassistant/helpers/entity.py", line 462, in async_update_ha_state
    await self.async_device_update()
  File "/usr/src/homeassistant/homeassistant/helpers/entity.py", line 652, in async_device_update
    raise exc
  File "/usr/src/homeassistant/homeassistant/components/history_stats/sensor.py", line 221, in async_update
    await self.hass.async_add_executor_job(
  File "/usr/local/lib/python3.9/concurrent/futures/thread.py", line 52, in run
    result = self.fn(*self.args, **self.kwargs)
  File "/usr/src/homeassistant/homeassistant/components/history_stats/sensor.py", line 227, in _update
    history_list = history.state_changes_during_period(
  File "/usr/src/homeassistant/homeassistant/components/recorder/history.py", line 147, in state_changes_during_period
    with session_scope(hass=hass) as session:
  File "/usr/local/lib/python3.9/contextlib.py", line 119, in __enter__
    return next(self.gen)
  File "/usr/src/homeassistant/homeassistant/components/recorder/util.py", line 73, in session_scope
    session = hass.data[DATA_INSTANCE].get_session()
TypeError: 'NoneType' object is not callable
2021-11-08 09:02:44 ERROR (MainThread) [homeassistant.helpers.entity] Update for sensor.veranda_speaker_on_today fails
Traceback (most recent call last):
  File "/usr/src/homeassistant/homeassistant/helpers/entity.py", line 462, in async_update_ha_state
    await self.async_device_update()
  File "/usr/src/homeassistant/homeassistant/helpers/entity.py", line 652, in async_device_update
    raise exc
  File "/usr/src/homeassistant/homeassistant/components/history_stats/sensor.py", line 221, in async_update
    await self.hass.async_add_executor_job(
  File "/usr/local/lib/python3.9/concurrent/futures/thread.py", line 52, in run
    result = self.fn(*self.args, **self.kwargs)
  File "/usr/src/homeassistant/homeassistant/components/history_stats/sensor.py", line 227, in _update
    history_list = history.state_changes_during_period(
  File "/usr/src/homeassistant/homeassistant/components/recorder/history.py", line 147, in state_changes_during_period
    with session_scope(hass=hass) as session:
  File "/usr/local/lib/python3.9/contextlib.py", line 119, in __enter__
    return next(self.gen)
  File "/usr/src/homeassistant/homeassistant/components/recorder/util.py", line 73, in session_scope
    session = hass.data[DATA_INSTANCE].get_session()
TypeError: 'NoneType' object is not callable
