2022-08-10 12:02:44.448 WARNING (SyncWorker_0) [homeassistant.util.yaml.loader] YAML file /config/packages/humidity_windows_close_prepare_notifications.yaml contains duplicate key "id". Check lines 310 and 357
2022-08-10 12:02:44.448 WARNING (SyncWorker_0) [homeassistant.util.yaml.loader] YAML file /config/packages/humidity_windows_close_prepare_notifications.yaml contains duplicate key "description". Check lines 311 and 358
2022-08-10 12:02:44.449 WARNING (SyncWorker_0) [homeassistant.util.yaml.loader] YAML file /config/packages/humidity_windows_close_prepare_notifications.yaml contains duplicate key "trigger". Check lines 312 and 359
2022-08-10 12:02:44.450 WARNING (SyncWorker_0) [homeassistant.util.yaml.loader] YAML file /config/packages/humidity_windows_close_prepare_notifications.yaml contains duplicate key "condition". Check lines 315 and 367
2022-08-10 12:02:44.450 WARNING (SyncWorker_0) [homeassistant.util.yaml.loader] YAML file /config/packages/humidity_windows_close_prepare_notifications.yaml contains duplicate key "action". Check lines 325 and 371
2022-08-10 12:02:44.450 WARNING (SyncWorker_0) [homeassistant.util.yaml.loader] YAML file /config/packages/humidity_windows_close_prepare_notifications.yaml contains duplicate key "mode". Check lines 354 and 382
2022-08-10 12:02:44.621 WARNING (SyncWorker_0) [homeassistant.util.yaml.loader] YAML file /config/packages/humidity_windows_open_prepare_notifications.yaml contains duplicate key "id". Check lines 359 and 380
2022-08-10 12:02:44.621 WARNING (SyncWorker_0) [homeassistant.util.yaml.loader] YAML file /config/packages/humidity_windows_open_prepare_notifications.yaml contains duplicate key "description". Check lines 360 and 381
2022-08-10 12:02:44.621 WARNING (SyncWorker_0) [homeassistant.util.yaml.loader] YAML file /config/packages/humidity_windows_open_prepare_notifications.yaml contains duplicate key "trigger". Check lines 361 and 382
2022-08-10 12:02:44.621 WARNING (SyncWorker_0) [homeassistant.util.yaml.loader] YAML file /config/packages/humidity_windows_open_prepare_notifications.yaml contains duplicate key "condition". Check lines 365 and 390
2022-08-10 12:02:44.622 WARNING (SyncWorker_0) [homeassistant.util.yaml.loader] YAML file /config/packages/humidity_windows_open_prepare_notifications.yaml contains duplicate key "action". Check lines 372 and 394
2022-08-10 12:02:44.622 WARNING (SyncWorker_0) [homeassistant.util.yaml.loader] YAML file /config/packages/humidity_windows_open_prepare_notifications.yaml contains duplicate key "mode". Check lines 377 and 405
2022-08-10 12:02:44.905 WARNING (SyncWorker_0) [homeassistant.util.yaml.loader] YAML file /config/packages/temperature_fan.yaml contains duplicate key "id". Check lines 29 and 41
2022-08-10 12:02:44.905 WARNING (SyncWorker_0) [homeassistant.util.yaml.loader] YAML file /config/packages/temperature_fan.yaml contains duplicate key "description". Check lines 30 and 42
2022-08-10 12:02:44.906 WARNING (SyncWorker_0) [homeassistant.util.yaml.loader] YAML file /config/packages/temperature_fan.yaml contains duplicate key "trigger". Check lines 31 and 43
2022-08-10 12:02:44.906 WARNING (SyncWorker_0) [homeassistant.util.yaml.loader] YAML file /config/packages/temperature_fan.yaml contains duplicate key "condition". Check lines 34 and 46
2022-08-10 12:02:44.906 WARNING (SyncWorker_0) [homeassistant.util.yaml.loader] YAML file /config/packages/temperature_fan.yaml contains duplicate key "action". Check lines 35 and 50
2022-08-10 12:02:44.926 WARNING (SyncWorker_0) [homeassistant.util.yaml.loader] YAML file /config/packages/temperature_windows.yaml contains duplicate key "id". Check lines 43 and 79
2022-08-10 12:02:44.926 WARNING (SyncWorker_0) [homeassistant.util.yaml.loader] YAML file /config/packages/temperature_windows.yaml contains duplicate key "description". Check lines 44 and 80
2022-08-10 12:02:44.927 WARNING (SyncWorker_0) [homeassistant.util.yaml.loader] YAML file /config/packages/temperature_windows.yaml contains duplicate key "trigger". Check lines 45 and 81
2022-08-10 12:02:44.927 WARNING (SyncWorker_0) [homeassistant.util.yaml.loader] YAML file /config/packages/temperature_windows.yaml contains duplicate key "condition". Check lines 48 and 84
2022-08-10 12:02:44.927 WARNING (SyncWorker_0) [homeassistant.util.yaml.loader] YAML file /config/packages/temperature_windows.yaml contains duplicate key "action". Check lines 62 and 85
2022-08-10 12:02:44.927 WARNING (SyncWorker_0) [homeassistant.util.yaml.loader] YAML file /config/packages/temperature_windows.yaml contains duplicate key "mode". Check lines 76 and 89
2022-08-10 12:02:45.341 WARNING (SyncWorker_0) [homeassistant.loader] We found a custom integration average which has not been tested by Home Assistant. This component might cause stability problems, be sure to disable it if you experience issues with Home Assistant
2022-08-10 12:02:45.346 WARNING (SyncWorker_0) [homeassistant.loader] We found a custom integration adaptive_lighting which has not been tested by Home Assistant. This component might cause stability problems, be sure to disable it if you experience issues with Home Assistant
2022-08-10 12:02:45.351 WARNING (SyncWorker_0) [homeassistant.loader] We found a custom integration samsungtv_custom which has not been tested by Home Assistant. This component might cause stability problems, be sure to disable it if you experience issues with Home Assistant
2022-08-10 12:02:45.352 ERROR (SyncWorker_0) [homeassistant.loader] The custom integration 'samsungtv_custom' does not have a version key in the manifest file and was blocked from loading. See https://developers.home-assistant.io/blog/2021/01/29/custom-integration-changes#versions for more details
2022-08-10 12:02:45.355 WARNING (SyncWorker_0) [homeassistant.loader] We found a custom integration xiaomi_miio_airpurifier which has not been tested by Home Assistant. This component might cause stability problems, be sure to disable it if you experience issues with Home Assistant
2022-08-10 12:02:45.360 WARNING (SyncWorker_0) [homeassistant.loader] We found a custom integration audiconnect which has not been tested by Home Assistant. This component might cause stability problems, be sure to disable it if you experience issues with Home Assistant
2022-08-10 12:02:45.364 WARNING (SyncWorker_0) [homeassistant.loader] We found a custom integration powercalc which has not been tested by Home Assistant. This component might cause stability problems, be sure to disable it if you experience issues with Home Assistant
2022-08-10 12:02:45.367 WARNING (SyncWorker_0) [homeassistant.loader] We found a custom integration monitor_docker which has not been tested by Home Assistant. This component might cause stability problems, be sure to disable it if you experience issues with Home Assistant
2022-08-10 12:02:45.370 WARNING (SyncWorker_0) [homeassistant.loader] We found a custom integration alphaess which has not been tested by Home Assistant. This component might cause stability problems, be sure to disable it if you experience issues with Home Assistant
2022-08-10 12:02:45.375 WARNING (SyncWorker_0) [homeassistant.loader] We found a custom integration hacs which has not been tested by Home Assistant. This component might cause stability problems, be sure to disable it if you experience issues with Home Assistant
2022-08-10 12:02:45.378 WARNING (SyncWorker_0) [homeassistant.loader] We found a custom integration nuki_ng which has not been tested by Home Assistant. This component might cause stability problems, be sure to disable it if you experience issues with Home Assistant
2022-08-10 12:02:45.381 WARNING (SyncWorker_0) [homeassistant.loader] We found a custom integration localtuya which has not been tested by Home Assistant. This component might cause stability problems, be sure to disable it if you experience issues with Home Assistant
2022-08-10 12:02:45.384 WARNING (SyncWorker_0) [homeassistant.loader] We found a custom integration xiaomi_miio_fan which has not been tested by Home Assistant. This component might cause stability problems, be sure to disable it if you experience issues with Home Assistant
2022-08-10 12:02:45.387 WARNING (SyncWorker_0) [homeassistant.loader] We found a custom integration webrtc which has not been tested by Home Assistant. This component might cause stability problems, be sure to disable it if you experience issues with Home Assistant
2022-08-10 12:02:45.391 WARNING (SyncWorker_0) [homeassistant.loader] We found a custom integration tuya_v2 which has not been tested by Home Assistant. This component might cause stability problems, be sure to disable it if you experience issues with Home Assistant
2022-08-10 12:02:45.395 WARNING (SyncWorker_0) [homeassistant.loader] We found a custom integration pyscript which has not been tested by Home Assistant. This component might cause stability problems, be sure to disable it if you experience issues with Home Assistant
2022-08-10 12:02:45.399 WARNING (SyncWorker_0) [homeassistant.loader] We found a custom integration battery_sim which has not been tested by Home Assistant. This component might cause stability problems, be sure to disable it if you experience issues with Home Assistant
2022-08-10 12:02:45.402 WARNING (SyncWorker_0) [homeassistant.loader] We found a custom integration nordpool which has not been tested by Home Assistant. This component might cause stability problems, be sure to disable it if you experience issues with Home Assistant
2022-08-10 12:02:45.406 WARNING (SyncWorker_0) [homeassistant.loader] We found a custom integration iphonedetect which has not been tested by Home Assistant. This component might cause stability problems, be sure to disable it if you experience issues with Home Assistant
2022-08-10 12:02:45.409 WARNING (SyncWorker_0) [homeassistant.loader] We found a custom integration huesyncbox which has not been tested by Home Assistant. This component might cause stability problems, be sure to disable it if you experience issues with Home Assistant
2022-08-10 12:02:45.412 WARNING (SyncWorker_0) [homeassistant.loader] We found a custom integration buienalarm which has not been tested by Home Assistant. This component might cause stability problems, be sure to disable it if you experience issues with Home Assistant
2022-08-10 12:02:45.416 WARNING (SyncWorker_0) [homeassistant.loader] We found a custom integration solaredge_modbus which has not been tested by Home Assistant. This component might cause stability problems, be sure to disable it if you experience issues with Home Assistant
2022-08-10 12:02:45.421 WARNING (SyncWorker_0) [homeassistant.loader] We found a custom integration multiscrape which has not been tested by Home Assistant. This component might cause stability problems, be sure to disable it if you experience issues with Home Assistant
2022-08-10 12:02:45.423 WARNING (SyncWorker_0) [homeassistant.loader] We found a custom integration sql_json which has not been tested by Home Assistant. This component might cause stability problems, be sure to disable it if you experience issues with Home Assistant
2022-08-10 12:02:45.426 WARNING (SyncWorker_0) [homeassistant.loader] We found a custom integration thermal_comfort which has not been tested by Home Assistant. This component might cause stability problems, be sure to disable it if you experience issues with Home Assistant
2022-08-10 12:02:45.428 WARNING (SyncWorker_0) [homeassistant.loader] We found a custom integration xiaomi_miot which has not been tested by Home Assistant. This component might cause stability problems, be sure to disable it if you experience issues with Home Assistant
2022-08-10 12:02:45.430 WARNING (SyncWorker_0) [homeassistant.loader] We found a custom integration googlewifi which has not been tested by Home Assistant. This component might cause stability problems, be sure to disable it if you experience issues with Home Assistant
2022-08-10 12:02:45.433 WARNING (SyncWorker_0) [homeassistant.loader] We found a custom integration anniversaries which has not been tested by Home Assistant. This component might cause stability problems, be sure to disable it if you experience issues with Home Assistant
2022-08-10 12:02:45.435 WARNING (SyncWorker_0) [homeassistant.loader] We found a custom integration tgtg which has not been tested by Home Assistant. This component might cause stability problems, be sure to disable it if you experience issues with Home Assistant
2022-08-10 12:02:45.437 WARNING (SyncWorker_0) [homeassistant.loader] We found a custom integration watchman which has not been tested by Home Assistant. This component might cause stability problems, be sure to disable it if you experience issues with Home Assistant
2022-08-10 12:02:45.441 WARNING (SyncWorker_0) [homeassistant.loader] We found a custom integration xiaomi_miio_fan which has not been tested by Home Assistant. This component might cause stability problems, be sure to disable it if you experience issues with Home Assistant
2022-08-10 12:02:45.446 WARNING (SyncWorker_0) [homeassistant.loader] We found a custom integration neerslag which has not been tested by Home Assistant. This component might cause stability problems, be sure to disable it if you experience issues with Home Assistant
2022-08-10 12:02:45.449 WARNING (SyncWorker_0) [homeassistant.loader] We found a custom integration ytube_music_player which has not been tested by Home Assistant. This component might cause stability problems, be sure to disable it if you experience issues with Home Assistant
2022-08-10 12:02:45.451 WARNING (SyncWorker_0) [homeassistant.loader] We found a custom integration dwains_dashboard which has not been tested by Home Assistant. This component might cause stability problems, be sure to disable it if you experience issues with Home Assistant
2022-08-10 12:02:45.454 WARNING (SyncWorker_0) [homeassistant.loader] We found a custom integration google_home which has not been tested by Home Assistant. This component might cause stability problems, be sure to disable it if you experience issues with Home Assistant
2022-08-10 12:02:45.456 WARNING (SyncWorker_0) [homeassistant.loader] We found a custom integration afvalbeheer which has not been tested by Home Assistant. This component might cause stability problems, be sure to disable it if you experience issues with Home Assistant
2022-08-10 12:02:50.316 WARNING (Recorder) [homeassistant.components.recorder.util] The system could not validate that the sqlite3 database at //config/home-assistant_v2.db was shutdown cleanly
2022-08-10 12:02:50.480 WARNING (Recorder) [homeassistant.components.recorder.util] Ended unfinished session (id=2195 from 2022-08-10 11:58:51.858441)
2022-08-10 12:02:54.187 ERROR (MainThread) [homeassistant.config] Invalid config for [automation]: template value should be a string for dictionary value @ data['action'][0]['data']. Got None. (See ?, line ?). 
2022-08-10 12:02:55.642 ERROR (MainThread) [homeassistant.config] Invalid config for [automation]: invalid template (TemplateSyntaxError: unexpected ')') for dictionary value @ data['variables']['reason']. Got None. (See ?, line ?). 
2022-08-10 12:03:09.339 WARNING (MainThread) [homeassistant.components.media_player] Setup of media_player platform dlna_dmr is taking over 10 seconds.
2022-08-10 12:03:09.800 WARNING (MainThread) [homeassistant.config_entries] Config entry 'shellyem3-BCFF4DFD1DBB' for shelly integration not ready yet: Timeout during device setup; Retrying in background
2022-08-10 12:03:18.876 WARNING (MainThread) [homeassistant.config_entries] Config entry 'DCP-L8410CDW E77432H9J432100' for brother integration not ready yet; Retrying in background
2022-08-10 12:03:33.743 WARNING (MainThread) [homeassistant.helpers.template] Template variable warning: 'None' has no attribute 'last_changed' when rendering 'sinds {{ as_timestamp(states[config.entity].last_changed) | timestamp_custom('%H:%M', True) }} - {{ (as_timestamp(now()) - as_timestamp(states[config.entity].last_changed)) | timestamp_custom('%H:%M', False) }} geleden'
2022-08-10 12:03:33.761 WARNING (MainThread) [homeassistant.helpers.template] Template variable warning: 'None' has no attribute 'last_changed' when rendering 'sinds {{ as_timestamp(states[config.entity].last_changed) | timestamp_custom('%H:%M', True) }} - {{ (as_timestamp(now()) - as_timestamp(states[config.entity].last_changed)) | timestamp_custom('%H:%M', False) }} geleden'
2022-08-10 12:03:33.770 WARNING (MainThread) [homeassistant.helpers.template] Template variable warning: 'None' has no attribute 'last_changed' when rendering 'sinds {{ as_timestamp(states[config.entity].last_changed) | timestamp_custom('%H:%M', True) }} - {{ (as_timestamp(now()) - as_timestamp(states[config.entity].last_changed)) | timestamp_custom('%H:%M', False) }} geleden'
2022-08-10 12:03:33.773 WARNING (MainThread) [homeassistant.helpers.template] Template variable warning: 'None' has no attribute 'last_changed' when rendering 'sinds {{ as_timestamp(states[config.entity].last_changed) | timestamp_custom('%H:%M', True) }} - {{ (as_timestamp(now()) - as_timestamp(states[config.entity].last_changed)) | timestamp_custom('%H:%M', False) }} geleden'
2022-08-10 12:03:33.789 WARNING (MainThread) [homeassistant.helpers.template] Template variable warning: 'None' has no attribute 'last_changed' when rendering 'sinds {{ as_timestamp(states[config.entity].last_changed) | timestamp_custom('%H:%M', True) }} - {{ (as_timestamp(now()) - as_timestamp(states[config.entity].last_changed)) | timestamp_custom('%H:%M', False) }} geleden'
2022-08-10 12:03:33.792 WARNING (MainThread) [homeassistant.helpers.template] Template variable warning: 'None' has no attribute 'last_changed' when rendering 'sinds {{ as_timestamp(states[config.entity].last_changed) | timestamp_custom('%H:%M', True) }} - {{ (as_timestamp(now()) - as_timestamp(states[config.entity].last_changed)) | timestamp_custom('%H:%M', False) }} geleden'
2022-08-10 12:03:33.817 WARNING (MainThread) [homeassistant.helpers.template] Template variable warning: 'None' has no attribute 'last_changed' when rendering 'sinds {{ as_timestamp(states[config.entity].last_changed) | timestamp_custom('%H:%M', True) }} - {{ (as_timestamp(now()) - as_timestamp(states[config.entity].last_changed)) | timestamp_custom('%H:%M', False) }} geleden'
2022-08-10 12:03:33.819 WARNING (MainThread) [homeassistant.helpers.template] Template variable warning: 'None' has no attribute 'last_changed' when rendering 'sinds {{ as_timestamp(states[config.entity].last_changed) | timestamp_custom('%H:%M', True) }} - {{ (as_timestamp(now()) - as_timestamp(states[config.entity].last_changed)) | timestamp_custom('%H:%M', False) }} geleden'
2022-08-10 12:03:33.832 WARNING (MainThread) [homeassistant.helpers.template] Template variable warning: 'None' has no attribute 'last_changed' when rendering 'sinds {{ as_timestamp(states[config.entity].last_changed) | timestamp_custom('%H:%M', True) }} - {{ (as_timestamp(now()) - as_timestamp(states[config.entity].last_changed)) | timestamp_custom('%H:%M', False) }} geleden'
2022-08-10 12:03:33.834 WARNING (MainThread) [homeassistant.helpers.template] Template variable warning: 'None' has no attribute 'last_changed' when rendering 'sinds {{ as_timestamp(states[config.entity].last_changed) | timestamp_custom('%H:%M', True) }} - {{ (as_timestamp(now()) - as_timestamp(states[config.entity].last_changed)) | timestamp_custom('%H:%M', False) }} geleden'
2022-08-10 12:03:33.850 WARNING (MainThread) [homeassistant.helpers.template] Template variable warning: 'None' has no attribute 'last_changed' when rendering 'sinds {{ as_timestamp(states[config.entity].last_changed) | timestamp_custom('%H:%M', True) }} - {{ (as_timestamp(now()) - as_timestamp(states[config.entity].last_changed)) | timestamp_custom('%H:%M', False) }} geleden'
2022-08-10 12:03:33.853 WARNING (MainThread) [homeassistant.helpers.template] Template variable warning: 'None' has no attribute 'last_changed' when rendering 'sinds {{ as_timestamp(states[config.entity].last_changed) | timestamp_custom('%H:%M', True) }} - {{ (as_timestamp(now()) - as_timestamp(states[config.entity].last_changed)) | timestamp_custom('%H:%M', False) }} geleden'
2022-08-10 12:03:33.878 WARNING (MainThread) [homeassistant.helpers.template] Template variable warning: 'None' has no attribute 'last_changed' when rendering 'sinds {{ as_timestamp(states[config.entity].last_changed) | timestamp_custom('%H:%M', True) }} - {{ (as_timestamp(now()) - as_timestamp(states[config.entity].last_changed)) | timestamp_custom('%H:%M', False) }} geleden'
2022-08-10 12:03:33.880 WARNING (MainThread) [homeassistant.helpers.template] Template variable warning: 'None' has no attribute 'last_changed' when rendering 'sinds {{ as_timestamp(states[config.entity].last_changed) | timestamp_custom('%H:%M', True) }} - {{ (as_timestamp(now()) - as_timestamp(states[config.entity].last_changed)) | timestamp_custom('%H:%M', False) }} geleden'
2022-08-10 12:03:33.895 WARNING (MainThread) [homeassistant.helpers.template] Template variable warning: 'None' has no attribute 'last_changed' when rendering 'sinds {{ as_timestamp(states[config.entity].last_changed) | timestamp_custom('%H:%M', True) }} - {{ (as_timestamp(now()) - as_timestamp(states[config.entity].last_changed)) | timestamp_custom('%H:%M', False) }} geleden'
2022-08-10 12:03:33.897 WARNING (MainThread) [homeassistant.helpers.template] Template variable warning: 'None' has no attribute 'last_changed' when rendering 'sinds {{ as_timestamp(states[config.entity].last_changed) | timestamp_custom('%H:%M', True) }} - {{ (as_timestamp(now()) - as_timestamp(states[config.entity].last_changed)) | timestamp_custom('%H:%M', False) }} geleden'
2022-08-10 12:03:33.909 WARNING (MainThread) [homeassistant.helpers.template] Template variable warning: 'None' has no attribute 'last_changed' when rendering 'sinds {{ as_timestamp(states[config.entity].last_changed) | timestamp_custom('%H:%M', True) }} - {{ (as_timestamp(now()) - as_timestamp(states[config.entity].last_changed)) | timestamp_custom('%H:%M', False) }} geleden'
2022-08-10 12:03:33.912 WARNING (MainThread) [homeassistant.helpers.template] Template variable warning: 'None' has no attribute 'last_changed' when rendering 'sinds {{ as_timestamp(states[config.entity].last_changed) | timestamp_custom('%H:%M', True) }} - {{ (as_timestamp(now()) - as_timestamp(states[config.entity].last_changed)) | timestamp_custom('%H:%M', False) }} geleden'
2022-08-10 12:03:33.937 WARNING (MainThread) [homeassistant.helpers.template] Template variable warning: 'None' has no attribute 'last_changed' when rendering 'sinds {{ as_timestamp(states[config.entity].last_changed) | timestamp_custom('%H:%M', True) }} - {{ (as_timestamp(now()) - as_timestamp(states[config.entity].last_changed)) | timestamp_custom('%H:%M', False) }} geleden'
2022-08-10 12:03:33.939 WARNING (MainThread) [homeassistant.helpers.template] Template variable warning: 'None' has no attribute 'last_changed' when rendering 'sinds {{ as_timestamp(states[config.entity].last_changed) | timestamp_custom('%H:%M', True) }} - {{ (as_timestamp(now()) - as_timestamp(states[config.entity].last_changed)) | timestamp_custom('%H:%M', False) }} geleden'
2022-08-10 12:03:33.952 WARNING (MainThread) [homeassistant.helpers.template] Template variable warning: 'None' has no attribute 'last_changed' when rendering 'sinds {{ as_timestamp(states[config.entity].last_changed) | timestamp_custom('%H:%M', True) }} - {{ (as_timestamp(now()) - as_timestamp(states[config.entity].last_changed)) | timestamp_custom('%H:%M', False) }} geleden'
2022-08-10 12:03:33.955 WARNING (MainThread) [homeassistant.helpers.template] Template variable warning: 'None' has no attribute 'last_changed' when rendering 'sinds {{ as_timestamp(states[config.entity].last_changed) | timestamp_custom('%H:%M', True) }} - {{ (as_timestamp(now()) - as_timestamp(states[config.entity].last_changed)) | timestamp_custom('%H:%M', False) }} geleden'
2022-08-10 12:03:55.347 WARNING (MainThread) [homeassistant.bootstrap] Waiting on integrations to complete setup: filesize, waze_travel_time, hacs, forecast_solar
2022-08-10 12:04:42.019 WARNING (MainThread) [homeassistant.config_entries] Config entry '192.168.86.83' for synology_dsm integration not ready yet: ConnectionError = <urllib3.connection.HTTPSConnection object at 0xffff8d968a60>: Failed to establish a new connection: [Errno 113] Host is unreachable; Retrying in background
2022-08-10 12:04:42.722 WARNING (MainThread) [homeassistant.config_entries] Config entry 'Brother DCP-L8410CDW series' for ipp integration not ready yet: Invalid response from API: Error occurred while communicating with IPP server.; Retrying in background
2022-08-10 12:04:45.459 ERROR (MainThread) [custom_components.audiconnect.audi_connect_account] Unable to obtain the vehicle longTerm tripdata of WAUZZZGE6MB019131: 'NoneType' object is not subscriptable
2022-08-10 12:04:45.880 ERROR (MainThread) [custom_components.audiconnect.audi_connect_account] support_preheater set to False: 502
2022-08-10 12:05:10.788 WARNING (MainThread) [homeassistant.bootstrap] Waiting on integrations to complete setup: filesize, waze_travel_time, hacs, forecast_solar, version
2022-08-10 12:06:15.600 WARNING (MainThread) [homeassistant.bootstrap] Waiting on integrations to complete setup: filesize, waze_travel_time, hacs, forecast_solar, version, openweathermap, utility_meter, tado, zha, pi_hole, rpi_power
2022-08-10 12:07:05.167 WARNING (MainThread) [homeassistant.config_entries] Config entry 'OnHub' for upnp integration not ready yet: Device not discovered: uuid:4a9b8e62-0dbb-42e8-905b-502b922db167::urn:schemas-upnp-org:device:InternetGatewayDevice:2; Retrying in background
2022-08-10 12:07:05.173 WARNING (MainThread) [homeassistant.config_entries] Config entry 'OnHub' for upnp integration not ready yet: Device not discovered: uuid:fb1f181f-db6e-4c9e-bdff-03ddf72e7062::urn:schemas-upnp-org:device:InternetGatewayDevice:2; Retrying in background
2022-08-10 12:07:05.176 WARNING (MainThread) [homeassistant.config_entries] Config entry 'OnHub' for upnp integration not ready yet: Device not discovered: uuid:fb1f181f-db6e-4c9e-bdff-03ddf72e7062::urn:schemas-upnp-org:device:InternetGatewayDevice:2; Retrying in background
2022-08-10 12:07:17.124 WARNING (MainThread) [homeassistant.bootstrap] Waiting on integrations to complete setup: filesize, waze_travel_time, hacs, forecast_solar, version, openweathermap, utility_meter, tado, zha, pi_hole, rpi_power, speedtestdotnet, plex, hue, buienradar
2022-08-10 12:07:31.213 WARNING (MainThread) [homeassistant.config_entries] Config entry 'Fan 2' for xiaomi_miio integration not ready yet: Unable to discover the device 192.168.86.22; Retrying in background
2022-08-10 12:07:31.218 WARNING (MainThread) [homeassistant.config_entries] Config entry 'Mi Air' for xiaomi_miio integration not ready yet: Unable to discover the device 192.168.86.26; Retrying in background
2022-08-10 12:07:31.222 WARNING (MainThread) [homeassistant.config_entries] Config entry 'Fan 1' for xiaomi_miio integration not ready yet: Unable to discover the device 192.168.86.26; Retrying in background
2022-08-10 12:07:52.396 WARNING (MainThread) [homeassistant.components.tts] TTS base_url option is deprecated. Configure internal/external URL instead
2022-08-10 12:07:53.322 ERROR (MainThread) [homeassistant.components.automation] Platform automation does not generate unique IDs. ID ce55bb82-1faf-4867-84ee-e0bf45b5b4cc already exists - ignoring automation.ramen_sluit_raam_master_bedroom_clear_notification_bart_en_madouce
2022-08-10 12:07:53.343 ERROR (MainThread) [homeassistant.components.automation] Platform automation does not generate unique IDs. ID 55bd62eb-9d04-44a0-b008-6ccb53531c29 already exists - ignoring automation.ramen_open_raam_master_bedroom_clear_notification_bart_en_madouce
2022-08-10 12:07:53.372 ERROR (MainThread) [homeassistant.components.automation] Platform automation does not generate unique IDs. ID 695898c2-c66e-4d93-9598-ff3337f00e05 already exists - ignoring automation.buiten_kouder_geworden_dan_in_master_bedroom_melding
2022-08-10 12:08:22.001 WARNING (MainThread) [custom_components.thermal_comfort.sensor] Legacy YAML configuration support will be removed in 2.0. You should update to the new yaml format: https://github.com/dolezsa/thermal_comfort/blob/master/documentation/yaml.md
2022-08-10 12:08:22.241 ERROR (MainThread) [custom_components.powercalc.sensors.power] light.buiten: Error setting up calculation strategy: No lookup file found for mode: brightness
2022-08-10 12:08:22.654 WARNING (MainThread) [homeassistant.components.sensor] Platform netatmo not ready yet: None; Retrying in background in 30 seconds
2022-08-10 12:08:22.659 WARNING (MainThread) [homeassistant.helpers.frame] Detected code that uses str for device registry entry_type. This is deprecated and will stop working in Home Assistant 2022.3, it should be updated to use DeviceEntryType instead. Please report this issue.
Stack (most recent call last):
  File "/usr/local/lib/python3.10/runpy.py", line 196, in _run_module_as_main
    return _run_code(code, main_globals, None,
  File "/usr/local/lib/python3.10/runpy.py", line 86, in _run_code
    exec(code, run_globals)
  File "/usr/src/homeassistant/homeassistant/__main__.py", line 203, in <module>
    sys.exit(main())
  File "/usr/src/homeassistant/homeassistant/__main__.py", line 191, in main
    exit_code = runner.run(runtime_conf)
  File "/usr/src/homeassistant/homeassistant/runner.py", line 119, in run
    return loop.run_until_complete(setup_and_run_hass(runtime_config))
  File "/usr/local/lib/python3.10/asyncio/base_events.py", line 633, in run_until_complete
    self.run_forever()
  File "/usr/local/lib/python3.10/asyncio/base_events.py", line 600, in run_forever
    self._run_once()
  File "/usr/local/lib/python3.10/asyncio/base_events.py", line 1896, in _run_once
    handle._run()
  File "/usr/local/lib/python3.10/asyncio/events.py", line 80, in _run
    self._context.run(self._callback, *self._args)
  File "/usr/src/homeassistant/homeassistant/helpers/entity_platform.py", line 538, in _async_add_entity
    device = device_registry.async_get_or_create(**processed_dev_info)  # type: ignore[arg-type]
  File "/usr/src/homeassistant/homeassistant/helpers/device_registry.py", line 371, in async_get_or_create
    report(  # type: ignore[unreachable]
  File "/usr/src/homeassistant/homeassistant/helpers/frame.py", line 74, in report
    _LOGGER.warning(msg, stack_info=True)
2022-08-10 12:08:22.664 WARNING (MainThread) [homeassistant.helpers.frame] Detected code that uses str for device registry entry_type. This is deprecated and will stop working in Home Assistant 2022.3, it should be updated to use DeviceEntryType instead. Please report this issue.
Stack (most recent call last):
  File "/usr/local/lib/python3.10/runpy.py", line 196, in _run_module_as_main
    return _run_code(code, main_globals, None,
  File "/usr/local/lib/python3.10/runpy.py", line 86, in _run_code
    exec(code, run_globals)
  File "/usr/src/homeassistant/homeassistant/__main__.py", line 203, in <module>
    sys.exit(main())
  File "/usr/src/homeassistant/homeassistant/__main__.py", line 191, in main
    exit_code = runner.run(runtime_conf)
  File "/usr/src/homeassistant/homeassistant/runner.py", line 119, in run
    return loop.run_until_complete(setup_and_run_hass(runtime_config))
  File "/usr/local/lib/python3.10/asyncio/base_events.py", line 633, in run_until_complete
    self.run_forever()
  File "/usr/local/lib/python3.10/asyncio/base_events.py", line 600, in run_forever
    self._run_once()
  File "/usr/local/lib/python3.10/asyncio/base_events.py", line 1896, in _run_once
    handle._run()
  File "/usr/local/lib/python3.10/asyncio/events.py", line 80, in _run
    self._context.run(self._callback, *self._args)
  File "/usr/src/homeassistant/homeassistant/helpers/entity_platform.py", line 538, in _async_add_entity
    device = device_registry.async_get_or_create(**processed_dev_info)  # type: ignore[arg-type]
  File "/usr/src/homeassistant/homeassistant/helpers/device_registry.py", line 371, in async_get_or_create
    report(  # type: ignore[unreachable]
  File "/usr/src/homeassistant/homeassistant/helpers/frame.py", line 74, in report
    _LOGGER.warning(msg, stack_info=True)
2022-08-10 12:08:22.670 WARNING (MainThread) [homeassistant.helpers.frame] Detected code that uses str for device registry entry_type. This is deprecated and will stop working in Home Assistant 2022.3, it should be updated to use DeviceEntryType instead. Please report this issue.
Stack (most recent call last):
  File "/usr/local/lib/python3.10/runpy.py", line 196, in _run_module_as_main
    return _run_code(code, main_globals, None,
  File "/usr/local/lib/python3.10/runpy.py", line 86, in _run_code
    exec(code, run_globals)
  File "/usr/src/homeassistant/homeassistant/__main__.py", line 203, in <module>
    sys.exit(main())
  File "/usr/src/homeassistant/homeassistant/__main__.py", line 191, in main
    exit_code = runner.run(runtime_conf)
  File "/usr/src/homeassistant/homeassistant/runner.py", line 119, in run
    return loop.run_until_complete(setup_and_run_hass(runtime_config))
  File "/usr/local/lib/python3.10/asyncio/base_events.py", line 633, in run_until_complete
    self.run_forever()
  File "/usr/local/lib/python3.10/asyncio/base_events.py", line 600, in run_forever
    self._run_once()
  File "/usr/local/lib/python3.10/asyncio/base_events.py", line 1896, in _run_once
    handle._run()
  File "/usr/local/lib/python3.10/asyncio/events.py", line 80, in _run
    self._context.run(self._callback, *self._args)
  File "/usr/src/homeassistant/homeassistant/helpers/entity_platform.py", line 538, in _async_add_entity
    device = device_registry.async_get_or_create(**processed_dev_info)  # type: ignore[arg-type]
  File "/usr/src/homeassistant/homeassistant/helpers/device_registry.py", line 371, in async_get_or_create
    report(  # type: ignore[unreachable]
  File "/usr/src/homeassistant/homeassistant/helpers/frame.py", line 74, in report
    _LOGGER.warning(msg, stack_info=True)
2022-08-10 12:08:22.674 WARNING (MainThread) [homeassistant.helpers.frame] Detected code that uses str for device registry entry_type. This is deprecated and will stop working in Home Assistant 2022.3, it should be updated to use DeviceEntryType instead. Please report this issue.
Stack (most recent call last):
  File "/usr/local/lib/python3.10/runpy.py", line 196, in _run_module_as_main
    return _run_code(code, main_globals, None,
  File "/usr/local/lib/python3.10/runpy.py", line 86, in _run_code
    exec(code, run_globals)
  File "/usr/src/homeassistant/homeassistant/__main__.py", line 203, in <module>
    sys.exit(main())
  File "/usr/src/homeassistant/homeassistant/__main__.py", line 191, in main
    exit_code = runner.run(runtime_conf)
  File "/usr/src/homeassistant/homeassistant/runner.py", line 119, in run
    return loop.run_until_complete(setup_and_run_hass(runtime_config))
  File "/usr/local/lib/python3.10/asyncio/base_events.py", line 633, in run_until_complete
    self.run_forever()
  File "/usr/local/lib/python3.10/asyncio/base_events.py", line 600, in run_forever
    self._run_once()
  File "/usr/local/lib/python3.10/asyncio/base_events.py", line 1896, in _run_once
    handle._run()
  File "/usr/local/lib/python3.10/asyncio/events.py", line 80, in _run
    self._context.run(self._callback, *self._args)
  File "/usr/src/homeassistant/homeassistant/helpers/entity_platform.py", line 538, in _async_add_entity
    device = device_registry.async_get_or_create(**processed_dev_info)  # type: ignore[arg-type]
  File "/usr/src/homeassistant/homeassistant/helpers/device_registry.py", line 371, in async_get_or_create
    report(  # type: ignore[unreachable]
  File "/usr/src/homeassistant/homeassistant/helpers/frame.py", line 74, in report
    _LOGGER.warning(msg, stack_info=True)
2022-08-10 12:08:22.680 WARNING (MainThread) [homeassistant.helpers.frame] Detected code that uses str for device registry entry_type. This is deprecated and will stop working in Home Assistant 2022.3, it should be updated to use DeviceEntryType instead. Please report this issue.
Stack (most recent call last):
  File "/usr/local/lib/python3.10/runpy.py", line 196, in _run_module_as_main
    return _run_code(code, main_globals, None,
  File "/usr/local/lib/python3.10/runpy.py", line 86, in _run_code
    exec(code, run_globals)
  File "/usr/src/homeassistant/homeassistant/__main__.py", line 203, in <module>
    sys.exit(main())
  File "/usr/src/homeassistant/homeassistant/__main__.py", line 191, in main
    exit_code = runner.run(runtime_conf)
  File "/usr/src/homeassistant/homeassistant/runner.py", line 119, in run
    return loop.run_until_complete(setup_and_run_hass(runtime_config))
  File "/usr/local/lib/python3.10/asyncio/base_events.py", line 633, in run_until_complete
    self.run_forever()
  File "/usr/local/lib/python3.10/asyncio/base_events.py", line 600, in run_forever
    self._run_once()
  File "/usr/local/lib/python3.10/asyncio/base_events.py", line 1896, in _run_once
    handle._run()
  File "/usr/local/lib/python3.10/asyncio/events.py", line 80, in _run
    self._context.run(self._callback, *self._args)
  File "/usr/src/homeassistant/homeassistant/helpers/entity_platform.py", line 538, in _async_add_entity
    device = device_registry.async_get_or_create(**processed_dev_info)  # type: ignore[arg-type]
  File "/usr/src/homeassistant/homeassistant/helpers/device_registry.py", line 371, in async_get_or_create
    report(  # type: ignore[unreachable]
  File "/usr/src/homeassistant/homeassistant/helpers/frame.py", line 74, in report
    _LOGGER.warning(msg, stack_info=True)
2022-08-10 12:08:22.687 WARNING (MainThread) [homeassistant.helpers.frame] Detected code that uses str for device registry entry_type. This is deprecated and will stop working in Home Assistant 2022.3, it should be updated to use DeviceEntryType instead. Please report this issue.
Stack (most recent call last):
  File "/usr/local/lib/python3.10/runpy.py", line 196, in _run_module_as_main
    return _run_code(code, main_globals, None,
  File "/usr/local/lib/python3.10/runpy.py", line 86, in _run_code
    exec(code, run_globals)
  File "/usr/src/homeassistant/homeassistant/__main__.py", line 203, in <module>
    sys.exit(main())
  File "/usr/src/homeassistant/homeassistant/__main__.py", line 191, in main
    exit_code = runner.run(runtime_conf)
  File "/usr/src/homeassistant/homeassistant/runner.py", line 119, in run
    return loop.run_until_complete(setup_and_run_hass(runtime_config))
  File "/usr/local/lib/python3.10/asyncio/base_events.py", line 633, in run_until_complete
    self.run_forever()
  File "/usr/local/lib/python3.10/asyncio/base_events.py", line 600, in run_forever
    self._run_once()
  File "/usr/local/lib/python3.10/asyncio/base_events.py", line 1896, in _run_once
    handle._run()
  File "/usr/local/lib/python3.10/asyncio/events.py", line 80, in _run
    self._context.run(self._callback, *self._args)
  File "/usr/src/homeassistant/homeassistant/helpers/entity_platform.py", line 538, in _async_add_entity
    device = device_registry.async_get_or_create(**processed_dev_info)  # type: ignore[arg-type]
  File "/usr/src/homeassistant/homeassistant/helpers/device_registry.py", line 371, in async_get_or_create
    report(  # type: ignore[unreachable]
  File "/usr/src/homeassistant/homeassistant/helpers/frame.py", line 74, in report
    _LOGGER.warning(msg, stack_info=True)
2022-08-10 12:08:22.694 WARNING (MainThread) [homeassistant.helpers.frame] Detected code that uses str for device registry entry_type. This is deprecated and will stop working in Home Assistant 2022.3, it should be updated to use DeviceEntryType instead. Please report this issue.
Stack (most recent call last):
  File "/usr/local/lib/python3.10/runpy.py", line 196, in _run_module_as_main
    return _run_code(code, main_globals, None,
  File "/usr/local/lib/python3.10/runpy.py", line 86, in _run_code
    exec(code, run_globals)
  File "/usr/src/homeassistant/homeassistant/__main__.py", line 203, in <module>
    sys.exit(main())
  File "/usr/src/homeassistant/homeassistant/__main__.py", line 191, in main
    exit_code = runner.run(runtime_conf)
  File "/usr/src/homeassistant/homeassistant/runner.py", line 119, in run
    return loop.run_until_complete(setup_and_run_hass(runtime_config))
  File "/usr/local/lib/python3.10/asyncio/base_events.py", line 633, in run_until_complete
    self.run_forever()
  File "/usr/local/lib/python3.10/asyncio/base_events.py", line 600, in run_forever
    self._run_once()
  File "/usr/local/lib/python3.10/asyncio/base_events.py", line 1896, in _run_once
    handle._run()
  File "/usr/local/lib/python3.10/asyncio/events.py", line 80, in _run
    self._context.run(self._callback, *self._args)
  File "/usr/src/homeassistant/homeassistant/helpers/entity_platform.py", line 538, in _async_add_entity
    device = device_registry.async_get_or_create(**processed_dev_info)  # type: ignore[arg-type]
  File "/usr/src/homeassistant/homeassistant/helpers/device_registry.py", line 371, in async_get_or_create
    report(  # type: ignore[unreachable]
  File "/usr/src/homeassistant/homeassistant/helpers/frame.py", line 74, in report
    _LOGGER.warning(msg, stack_info=True)
2022-08-10 12:08:22.702 WARNING (MainThread) [homeassistant.helpers.frame] Detected code that uses str for device registry entry_type. This is deprecated and will stop working in Home Assistant 2022.3, it should be updated to use DeviceEntryType instead. Please report this issue.
Stack (most recent call last):
  File "/usr/local/lib/python3.10/runpy.py", line 196, in _run_module_as_main
    return _run_code(code, main_globals, None,
  File "/usr/local/lib/python3.10/runpy.py", line 86, in _run_code
    exec(code, run_globals)
  File "/usr/src/homeassistant/homeassistant/__main__.py", line 203, in <module>
    sys.exit(main())
  File "/usr/src/homeassistant/homeassistant/__main__.py", line 191, in main
    exit_code = runner.run(runtime_conf)
  File "/usr/src/homeassistant/homeassistant/runner.py", line 119, in run
    return loop.run_until_complete(setup_and_run_hass(runtime_config))
  File "/usr/local/lib/python3.10/asyncio/base_events.py", line 633, in run_until_complete
    self.run_forever()
  File "/usr/local/lib/python3.10/asyncio/base_events.py", line 600, in run_forever
    self._run_once()
  File "/usr/local/lib/python3.10/asyncio/base_events.py", line 1896, in _run_once
    handle._run()
  File "/usr/local/lib/python3.10/asyncio/events.py", line 80, in _run
    self._context.run(self._callback, *self._args)
  File "/usr/src/homeassistant/homeassistant/helpers/entity_platform.py", line 538, in _async_add_entity
    device = device_registry.async_get_or_create(**processed_dev_info)  # type: ignore[arg-type]
  File "/usr/src/homeassistant/homeassistant/helpers/device_registry.py", line 371, in async_get_or_create
    report(  # type: ignore[unreachable]
  File "/usr/src/homeassistant/homeassistant/helpers/frame.py", line 74, in report
    _LOGGER.warning(msg, stack_info=True)
2022-08-10 12:08:22.708 WARNING (MainThread) [homeassistant.helpers.frame] Detected code that uses str for device registry entry_type. This is deprecated and will stop working in Home Assistant 2022.3, it should be updated to use DeviceEntryType instead. Please report this issue.
Stack (most recent call last):
  File "/usr/local/lib/python3.10/runpy.py", line 196, in _run_module_as_main
    return _run_code(code, main_globals, None,
  File "/usr/local/lib/python3.10/runpy.py", line 86, in _run_code
    exec(code, run_globals)
  File "/usr/src/homeassistant/homeassistant/__main__.py", line 203, in <module>
    sys.exit(main())
  File "/usr/src/homeassistant/homeassistant/__main__.py", line 191, in main
    exit_code = runner.run(runtime_conf)
  File "/usr/src/homeassistant/homeassistant/runner.py", line 119, in run
    return loop.run_until_complete(setup_and_run_hass(runtime_config))
  File "/usr/local/lib/python3.10/asyncio/base_events.py", line 633, in run_until_complete
    self.run_forever()
  File "/usr/local/lib/python3.10/asyncio/base_events.py", line 600, in run_forever
    self._run_once()
  File "/usr/local/lib/python3.10/asyncio/base_events.py", line 1896, in _run_once
    handle._run()
  File "/usr/local/lib/python3.10/asyncio/events.py", line 80, in _run
    self._context.run(self._callback, *self._args)
  File "/usr/src/homeassistant/homeassistant/helpers/entity_platform.py", line 538, in _async_add_entity
    device = device_registry.async_get_or_create(**processed_dev_info)  # type: ignore[arg-type]
  File "/usr/src/homeassistant/homeassistant/helpers/device_registry.py", line 371, in async_get_or_create
    report(  # type: ignore[unreachable]
  File "/usr/src/homeassistant/homeassistant/helpers/frame.py", line 74, in report
    _LOGGER.warning(msg, stack_info=True)
2022-08-10 12:08:22.713 WARNING (MainThread) [homeassistant.helpers.frame] Detected code that uses str for device registry entry_type. This is deprecated and will stop working in Home Assistant 2022.3, it should be updated to use DeviceEntryType instead. Please report this issue.
Stack (most recent call last):
  File "/usr/local/lib/python3.10/runpy.py", line 196, in _run_module_as_main
    return _run_code(code, main_globals, None,
  File "/usr/local/lib/python3.10/runpy.py", line 86, in _run_code
    exec(code, run_globals)
  File "/usr/src/homeassistant/homeassistant/__main__.py", line 203, in <module>
    sys.exit(main())
  File "/usr/src/homeassistant/homeassistant/__main__.py", line 191, in main
    exit_code = runner.run(runtime_conf)
  File "/usr/src/homeassistant/homeassistant/runner.py", line 119, in run
    return loop.run_until_complete(setup_and_run_hass(runtime_config))
  File "/usr/local/lib/python3.10/asyncio/base_events.py", line 633, in run_until_complete
    self.run_forever()
  File "/usr/local/lib/python3.10/asyncio/base_events.py", line 600, in run_forever
    self._run_once()
  File "/usr/local/lib/python3.10/asyncio/base_events.py", line 1896, in _run_once
    handle._run()
  File "/usr/local/lib/python3.10/asyncio/events.py", line 80, in _run
    self._context.run(self._callback, *self._args)
  File "/usr/src/homeassistant/homeassistant/helpers/entity_platform.py", line 538, in _async_add_entity
    device = device_registry.async_get_or_create(**processed_dev_info)  # type: ignore[arg-type]
  File "/usr/src/homeassistant/homeassistant/helpers/device_registry.py", line 371, in async_get_or_create
    report(  # type: ignore[unreachable]
  File "/usr/src/homeassistant/homeassistant/helpers/frame.py", line 74, in report
    _LOGGER.warning(msg, stack_info=True)
2022-08-10 12:08:22.724 WARNING (MainThread) [homeassistant.helpers.frame] Detected code that uses str for device registry entry_type. This is deprecated and will stop working in Home Assistant 2022.3, it should be updated to use DeviceEntryType instead. Please report this issue.
Stack (most recent call last):
  File "/usr/local/lib/python3.10/runpy.py", line 196, in _run_module_as_main
    return _run_code(code, main_globals, None,
  File "/usr/local/lib/python3.10/runpy.py", line 86, in _run_code
    exec(code, run_globals)
  File "/usr/src/homeassistant/homeassistant/__main__.py", line 203, in <module>
    sys.exit(main())
  File "/usr/src/homeassistant/homeassistant/__main__.py", line 191, in main
    exit_code = runner.run(runtime_conf)
  File "/usr/src/homeassistant/homeassistant/runner.py", line 119, in run
    return loop.run_until_complete(setup_and_run_hass(runtime_config))
  File "/usr/local/lib/python3.10/asyncio/base_events.py", line 633, in run_until_complete
    self.run_forever()
  File "/usr/local/lib/python3.10/asyncio/base_events.py", line 600, in run_forever
    self._run_once()
  File "/usr/local/lib/python3.10/asyncio/base_events.py", line 1896, in _run_once
    handle._run()
  File "/usr/local/lib/python3.10/asyncio/events.py", line 80, in _run
    self._context.run(self._callback, *self._args)
  File "/usr/src/homeassistant/homeassistant/helpers/entity_platform.py", line 538, in _async_add_entity
    device = device_registry.async_get_or_create(**processed_dev_info)  # type: ignore[arg-type]
  File "/usr/src/homeassistant/homeassistant/helpers/device_registry.py", line 371, in async_get_or_create
    report(  # type: ignore[unreachable]
  File "/usr/src/homeassistant/homeassistant/helpers/frame.py", line 74, in report
    _LOGGER.warning(msg, stack_info=True)
2022-08-10 12:08:23.278 ERROR (MainThread) [homeassistant.components.sensor] Error adding entities for domain sensor with platform audiconnect
Traceback (most recent call last):
  File "/usr/src/homeassistant/homeassistant/helpers/entity_platform.py", line 428, in async_add_entities
    await asyncio.gather(*tasks)
  File "/usr/src/homeassistant/homeassistant/helpers/entity_platform.py", line 673, in _async_add_entity
    await entity.add_to_platform_finish()
  File "/usr/src/homeassistant/homeassistant/helpers/entity.py", line 776, in add_to_platform_finish
    self.async_write_ha_state()
  File "/usr/src/homeassistant/homeassistant/helpers/entity.py", line 532, in async_write_ha_state
    self._async_write_ha_state()
  File "/usr/src/homeassistant/homeassistant/helpers/entity.py", line 646, in _async_write_ha_state
    self.hass.states.async_set(
  File "/usr/src/homeassistant/homeassistant/core.py", line 1438, in async_set
    state = State(
  File "/usr/src/homeassistant/homeassistant/core.py", line 1099, in __init__
    raise InvalidStateError(
homeassistant.exceptions.InvalidStateError: Invalid state encountered for entity ID: sensor.audi_e_tron_sportback_shortterm_trip_user_reset. State max length is 255 characters.
2022-08-10 12:08:23.650 WARNING (MainThread) [homeassistant.bootstrap] Waiting on integrations to complete setup: filesize, waze_travel_time, hacs, forecast_solar, version, openweathermap, utility_meter, tado, zha, pi_hole, speedtestdotnet, plex, hue, buienradar, mobile_app, netatmo, tuya, sensor.command_line, sensor.tgtg, sensor.nmbs_2, sensor.history_stats, sensor.buienalarm, sensor.scrape, sensor.scrape_2, sensor.scrape_3, sensor.scrape_4, sensor.scrape_5, sensor.scrape_6, sensor.scrape_7, sensor.systemmonitor, sensor.command_line_3, sensor.integration, sensor.dwains_dashboard, sensor.filesize, sensor.waze_travel_time, sensor.waze_travel_time_2, sensor.waze_travel_time_3, sensor.nuki_ng, sensor.forecast_solar, sensor.forecast_solar_2, sensor.hacs, sensor.version, sensor.audiconnect, sensor.nordpool, sensor.openweathermap, sensor.utility_meter, sensor.utility_meter_2, sensor.utility_meter_3, sensor.utility_meter_4, sensor.utility_meter_5, sensor.utility_meter_6, sensor.pi_hole, sensor.tado, sensor.speedtestdotnet, sensor.buienradar, sensor.plex, sensor.hue, sensor.hue_2, sensor.googlewifi, sensor.google_home, sensor.mobile_app, sensor.mobile_app_2, sensor.mobile_app_3, sensor.mobile_app_4, sensor.mobile_app_5, sensor.mobile_app_6, sensor.tuya, sensor.alphaess, sensor.thermal_comfort, sensor.powercalc, sensor.battery_sim, sensor.energy, sensor.anniversaries, sensor.utility_meter_7, sensor.modbus
2022-08-10 12:08:23.704 ERROR (MainThread) [homeassistant.components.sensor] Error while setting up audiconnect platform for sensor
Traceback (most recent call last):
  File "/usr/src/homeassistant/homeassistant/helpers/entity_platform.py", line 289, in _async_setup_platform
    await asyncio.gather(*pending)
  File "/usr/src/homeassistant/homeassistant/helpers/entity_platform.py", line 428, in async_add_entities
    await asyncio.gather(*tasks)
  File "/usr/src/homeassistant/homeassistant/helpers/entity_platform.py", line 673, in _async_add_entity
    await entity.add_to_platform_finish()
  File "/usr/src/homeassistant/homeassistant/helpers/entity.py", line 776, in add_to_platform_finish
    self.async_write_ha_state()
  File "/usr/src/homeassistant/homeassistant/helpers/entity.py", line 532, in async_write_ha_state
    self._async_write_ha_state()
  File "/usr/src/homeassistant/homeassistant/helpers/entity.py", line 646, in _async_write_ha_state
    self.hass.states.async_set(
  File "/usr/src/homeassistant/homeassistant/core.py", line 1438, in async_set
    state = State(
  File "/usr/src/homeassistant/homeassistant/core.py", line 1099, in __init__
    raise InvalidStateError(
homeassistant.exceptions.InvalidStateError: Invalid state encountered for entity ID: sensor.audi_e_tron_sportback_shortterm_trip_user_reset. State max length is 255 characters.
2022-08-10 12:08:23.797 WARNING (MainThread) [homeassistant.components.integration.sensor] sensor.wasbak_rechts_energy could not restore last state unknown: [<class 'decimal.ConversionSyntax'>]
2022-08-10 12:08:23.820 WARNING (MainThread) [homeassistant.components.integration.sensor] sensor.douche_energy_2 could not restore last state unknown: [<class 'decimal.ConversionSyntax'>]
2022-08-10 12:08:23.822 WARNING (MainThread) [homeassistant.components.integration.sensor] sensor.bad_energy could not restore last state unknown: [<class 'decimal.ConversionSyntax'>]
2022-08-10 12:08:24.170 WARNING (MainThread) [homeassistant.components.integration.sensor] sensor.inkomhal_energy could not restore last state unknown: [<class 'decimal.ConversionSyntax'>]
2022-08-10 12:08:24.681 WARNING (MainThread) [homeassistant.components.binary_sensor] Updating ping binary_sensor took longer than the scheduled update interval 0:00:05
2022-08-10 12:08:25.431 ERROR (SyncWorker_6) [homeassistant.components.modbus.modbus] Pymodbus: charger: Modbus Error: [Connection] ModbusTcpClient(192.168.1.2:502): Connection unexpectedly closed 0.000150 seconds into read of 8 bytes without response from unit before it closed connection
2022-08-10 12:08:30.176 WARNING (MainThread) [homeassistant.components.sensor] Setup of sensor platform scrape is taking over 10 seconds.
2022-08-10 12:08:30.195 WARNING (MainThread) [homeassistant.components.sensor] Setup of sensor platform scrape is taking over 10 seconds.
2022-08-10 12:08:30.205 WARNING (MainThread) [homeassistant.components.sensor] Setup of sensor platform scrape is taking over 10 seconds.
2022-08-10 12:08:30.210 WARNING (MainThread) [homeassistant.components.sensor] Setup of sensor platform scrape is taking over 10 seconds.
2022-08-10 12:08:30.227 WARNING (MainThread) [homeassistant.components.sensor] Setup of sensor platform scrape is taking over 10 seconds.
2022-08-10 12:08:30.245 WARNING (MainThread) [homeassistant.components.sensor] Setup of sensor platform scrape is taking over 10 seconds.
2022-08-10 12:08:30.581 ERROR (MainThread) [homeassistant.components.sensor] scrape: Error on device update!
Traceback (most recent call last):
  File "/usr/src/homeassistant/homeassistant/helpers/entity_platform.py", line 477, in _async_add_entity
    await entity.async_device_update(warning=False)
  File "/usr/src/homeassistant/homeassistant/helpers/entity.py", line 702, in async_device_update
    await task
  File "/usr/src/homeassistant/homeassistant/components/scrape/sensor.py", line 186, in async_update
    await self._async_update_from_rest_data()
  File "/usr/src/homeassistant/homeassistant/components/scrape/sensor.py", line 198, in _async_update_from_rest_data
    value = await self.hass.async_add_executor_job(self._extract_value)
  File "/usr/local/lib/python3.10/concurrent/futures/thread.py", line 58, in run
    result = self.fn(*self.args, **self.kwargs)
  File "/usr/src/homeassistant/homeassistant/components/scrape/sensor.py", line 167, in _extract_value
    tag = raw_data.select(self._select)[self._index]
  File "/usr/local/lib/python3.10/site-packages/bs4/element.py", line 1973, in select
    results = soupsieve.select(selector, self, namespaces, limit, **kwargs)
  File "/usr/local/lib/python3.10/site-packages/soupsieve/__init__.py", line 144, in select
    return compile(select, namespaces, flags, **kwargs).select(tag, limit)
  File "/usr/local/lib/python3.10/site-packages/soupsieve/__init__.py", line 67, in compile
    return cp._cached_css_compile(pattern, ns, cs, flags)
  File "/usr/local/lib/python3.10/site-packages/soupsieve/css_parser.py", line 222, in _cached_css_compile
    ).process_selectors(),
  File "/usr/local/lib/python3.10/site-packages/soupsieve/css_parser.py", line 1159, in process_selectors
    return self.parse_selectors(self.selector_iter(self.pattern), index, flags)
  File "/usr/local/lib/python3.10/site-packages/soupsieve/css_parser.py", line 985, in parse_selectors
    key, m = next(iselector)
  File "/usr/local/lib/python3.10/site-packages/soupsieve/css_parser.py", line 1152, in selector_iter
    raise SelectorSyntaxError(msg, self.pattern, index)
soupsieve.util.SelectorSyntaxError: Invalid character '<' position 0
  line 1:
<span _ngcontent-app-root-c173="">Offline</span>
^
2022-08-10 12:08:51.377 WARNING (MainThread) [homeassistant.helpers.template] Template variable warning: 'outdoor' is undefined when rendering '{{outdoor}} < {{indoor}}'
2022-08-10 12:08:51.437 WARNING (MainThread) [homeassistant.helpers.template] Template variable warning: 'indoor' is undefined when rendering '{{outdoor}} < {{indoor}}'
2022-08-10 12:08:51.449 WARNING (MainThread) [homeassistant.helpers.template] Template variable warning: 'outdoor' is undefined when rendering '{{outdoor}} < {{indoor}}'
2022-08-10 12:08:51.482 WARNING (MainThread) [homeassistant.helpers.template] Template variable warning: 'indoor' is undefined when rendering '{{outdoor}} < {{indoor}}'
2022-08-10 12:08:51.503 WARNING (MainThread) [homeassistant.helpers.template] Template variable warning: 'outdoor' is undefined when rendering '{{outdoor}} < {{indoor}}'
2022-08-10 12:08:51.526 WARNING (MainThread) [homeassistant.helpers.template] Template variable warning: 'indoor' is undefined when rendering '{{outdoor}} < {{indoor}}'
2022-08-10 12:08:51.534 WARNING (MainThread) [homeassistant.helpers.template] Template variable warning: 'outdoor' is undefined when rendering '{{outdoor}} < {{indoor}}'
2022-08-10 12:08:51.545 WARNING (MainThread) [homeassistant.helpers.template] Template variable warning: 'indoor' is undefined when rendering '{{outdoor}} < {{indoor}}'
2022-08-10 12:08:51.570 WARNING (MainThread) [homeassistant.helpers.template] Template variable warning: 'outdoor' is undefined when rendering '{{outdoor}} < {{indoor}}'
2022-08-10 12:08:51.593 WARNING (MainThread) [homeassistant.helpers.template] Template variable warning: 'indoor' is undefined when rendering '{{outdoor}} < {{indoor}}'
2022-08-10 12:08:51.601 WARNING (MainThread) [homeassistant.helpers.template] Template variable warning: 'outdoor' is undefined when rendering '{{outdoor}} < {{indoor}}'
2022-08-10 12:08:51.620 WARNING (MainThread) [homeassistant.helpers.template] Template variable warning: 'indoor' is undefined when rendering '{{outdoor}} < {{indoor}}'
2022-08-10 12:08:51.630 WARNING (MainThread) [homeassistant.helpers.template] Template variable warning: 'outdoor' is undefined when rendering '{{outdoor}} < {{indoor}}'
2022-08-10 12:08:51.653 WARNING (MainThread) [homeassistant.helpers.template] Template variable warning: 'indoor' is undefined when rendering '{{outdoor}} < {{indoor}}'
2022-08-10 12:08:51.706 WARNING (MainThread) [homeassistant.helpers.template] Template variable warning: 'outdoor' is undefined when rendering '{{outdoor}} < {{indoor}}'
2022-08-10 12:08:51.727 WARNING (MainThread) [homeassistant.helpers.template] Template variable warning: 'indoor' is undefined when rendering '{{outdoor}} < {{indoor}}'
2022-08-10 12:08:51.754 WARNING (MainThread) [homeassistant.helpers.template] Template variable warning: 'outdoor' is undefined when rendering '{{outdoor}} < {{indoor}}'
2022-08-10 12:08:51.773 WARNING (MainThread) [homeassistant.helpers.template] Template variable warning: 'indoor' is undefined when rendering '{{outdoor}} < {{indoor}}'
2022-08-10 12:08:51.785 WARNING (MainThread) [homeassistant.helpers.template] Template variable warning: 'outdoor' is undefined when rendering '{{outdoor}} < {{indoor}}'
2022-08-10 12:08:51.807 WARNING (MainThread) [homeassistant.helpers.template] Template variable warning: 'indoor' is undefined when rendering '{{outdoor}} < {{indoor}}'
2022-08-10 12:08:56.794 WARNING (MainThread) [homeassistant.components.binary_sensor] Updating ping binary_sensor took longer than the scheduled update interval 0:00:05
2022-08-10 12:09:00.302 WARNING (Thread-57) [matplotlib.font_manager] Matplotlib is building the font cache; this may take a moment.
2022-08-10 12:09:08.146 WARNING (MainThread) [homeassistant.components.binary_sensor] Updating ping binary_sensor took longer than the scheduled update interval 0:00:05
2022-08-10 12:09:08.172 WARNING (MainThread) [homeassistant.helpers.entity] Update of binary_sensor.google_server is taking over 10 seconds
2022-08-10 12:09:15.843 WARNING (MainThread) [homeassistant.components.binary_sensor] Updating ping binary_sensor took longer than the scheduled update interval 0:00:05
2022-08-10 12:09:36.444 WARNING (MainThread) [homeassistant.components.binary_sensor] Updating ping binary_sensor took longer than the scheduled update interval 0:00:05
2022-08-10 12:09:51.446 WARNING (MainThread) [homeassistant.components.binary_sensor] Updating ping binary_sensor took longer than the scheduled update interval 0:00:05
2022-08-10 12:10:00.022 WARNING (MainThread) [homeassistant.helpers.service] Unable to find referenced entities fan.mi_air or it is/they are currently not available
2022-08-10 12:10:10.532 WARNING (Recorder) [homeassistant.components.sensor.recorder] The unit of sensor.openweathermap_visibility (m) does not match the unit of already compiled statistics (km). Generation of long term statistics will be suppressed unless the unit changes back to km. Go to https://my.home-assistant.io/redirect/developer_statistics to fix this
2022-08-10 12:10:10.555 WARNING (Recorder) [homeassistant.components.sensor.recorder] The unit of sensor.car_charge_solar_energy_daily (kWh) does not match the unit of already compiled statistics (None). Generation of long term statistics will be suppressed unless the unit changes back to None. Go to https://my.home-assistant.io/redirect/developer_statistics to fix this
2022-08-10 12:10:10.556 WARNING (Recorder) [homeassistant.components.sensor.recorder] The unit of sensor.car_charge_grid_energy_daily (kWh) does not match the unit of already compiled statistics (None). Generation of long term statistics will be suppressed unless the unit changes back to None. Go to https://my.home-assistant.io/redirect/developer_statistics to fix this
2022-08-10 12:14:49.290 ERROR (MainThread) [aiohttp.server] Error handling request
Traceback (most recent call last):
  File "/usr/local/lib/python3.10/site-packages/aiohttp/web_protocol.py", line 334, in data_received
    messages, upgraded, tail = self._request_parser.feed_data(data)
  File "aiohttp/_http_parser.pyx", line 551, in aiohttp._http_parser.HttpParser.feed_data
aiohttp.http_exceptions.BadStatusLine: 400, message="Bad status line 'Invalid method encountered'"
2022-08-10 12:14:49.884 ERROR (MainThread) [homeassistant.util.logging] Exception in async_schedule_update_ha_state when dispatching 'audiconnect.updated': ()
Traceback (most recent call last):
  File "/usr/src/homeassistant/homeassistant/helpers/entity.py", line 677, in async_schedule_update_ha_state
    self.async_write_ha_state()
  File "/usr/src/homeassistant/homeassistant/helpers/entity.py", line 532, in async_write_ha_state
    self._async_write_ha_state()
  File "/usr/src/homeassistant/homeassistant/helpers/entity.py", line 646, in _async_write_ha_state
    self.hass.states.async_set(
  File "/usr/src/homeassistant/homeassistant/core.py", line 1438, in async_set
    state = State(
  File "/usr/src/homeassistant/homeassistant/core.py", line 1099, in __init__
    raise InvalidStateError(
homeassistant.exceptions.InvalidStateError: Invalid state encountered for entity ID: sensor.audi_e_tron_sportback_shortterm_trip_user_reset. State max length is 255 characters.

2022-08-10 12:14:49.891 ERROR (MainThread) [homeassistant.util.logging] Exception in async_schedule_update_ha_state when dispatching 'audiconnect.updated': ()
Traceback (most recent call last):
  File "/usr/src/homeassistant/homeassistant/helpers/entity.py", line 677, in async_schedule_update_ha_state
    self.async_write_ha_state()
  File "/usr/src/homeassistant/homeassistant/helpers/entity.py", line 532, in async_write_ha_state
    self._async_write_ha_state()
  File "/usr/src/homeassistant/homeassistant/helpers/entity.py", line 646, in _async_write_ha_state
    self.hass.states.async_set(
  File "/usr/src/homeassistant/homeassistant/core.py", line 1438, in async_set
    state = State(
  File "/usr/src/homeassistant/homeassistant/core.py", line 1099, in __init__
    raise InvalidStateError(
homeassistant.exceptions.InvalidStateError: Invalid state encountered for entity ID: sensor.audi_e_tron_sportback_shortterm_trip_data. State max length is 255 characters.

2022-08-10 12:15:00.047 WARNING (MainThread) [homeassistant.helpers.service] Unable to find referenced entities fan.mi_air or it is/they are currently not available
2022-08-10 12:15:00.056 WARNING (MainThread) [homeassistant.helpers.script] Error in 'condition' evaluation:
In 'zone' condition: error matching person.bart with zone.home: entity person.bart has no 'latitude' attribute
2022-08-10 12:15:00.082 WARNING (MainThread) [homeassistant.helpers.template] Template variable warning: 'reason' is undefined when rendering '{{reason}}<br>{{message}}'
2022-08-10 12:15:00.086 WARNING (MainThread) [homeassistant.helpers.template] Template variable warning: 'uri' is undefined when rendering '{{uri}}'
2022-08-10 12:20:00.021 WARNING (MainThread) [homeassistant.helpers.service] Unable to find referenced entities fan.mi_air or it is/they are currently not available
2022-08-10 12:23:26.624 WARNING (MainThread) [homeassistant.components.binary_sensor] Updating ping binary_sensor took longer than the scheduled update interval 0:00:05
2022-08-10 12:24:53.924 ERROR (MainThread) [homeassistant.util.logging] Exception in async_schedule_update_ha_state when dispatching 'audiconnect.updated': ()
Traceback (most recent call last):
  File "/usr/src/homeassistant/homeassistant/helpers/entity.py", line 677, in async_schedule_update_ha_state
    self.async_write_ha_state()
  File "/usr/src/homeassistant/homeassistant/helpers/entity.py", line 532, in async_write_ha_state
    self._async_write_ha_state()
  File "/usr/src/homeassistant/homeassistant/helpers/entity.py", line 646, in _async_write_ha_state
    self.hass.states.async_set(
  File "/usr/src/homeassistant/homeassistant/core.py", line 1438, in async_set
    state = State(
  File "/usr/src/homeassistant/homeassistant/core.py", line 1099, in __init__
    raise InvalidStateError(
homeassistant.exceptions.InvalidStateError: Invalid state encountered for entity ID: sensor.audi_e_tron_sportback_shortterm_trip_user_reset. State max length is 255 characters.

2022-08-10 12:24:53.953 ERROR (MainThread) [homeassistant.util.logging] Exception in async_schedule_update_ha_state when dispatching 'audiconnect.updated': ()
Traceback (most recent call last):
  File "/usr/src/homeassistant/homeassistant/helpers/entity.py", line 677, in async_schedule_update_ha_state
    self.async_write_ha_state()
  File "/usr/src/homeassistant/homeassistant/helpers/entity.py", line 532, in async_write_ha_state
    self._async_write_ha_state()
  File "/usr/src/homeassistant/homeassistant/helpers/entity.py", line 646, in _async_write_ha_state
    self.hass.states.async_set(
  File "/usr/src/homeassistant/homeassistant/core.py", line 1438, in async_set
    state = State(
  File "/usr/src/homeassistant/homeassistant/core.py", line 1099, in __init__
    raise InvalidStateError(
homeassistant.exceptions.InvalidStateError: Invalid state encountered for entity ID: sensor.audi_e_tron_sportback_shortterm_trip_data. State max length is 255 characters.

2022-08-10 12:25:00.015 WARNING (MainThread) [homeassistant.helpers.service] Unable to find referenced entities fan.mi_air or it is/they are currently not available
2022-08-10 12:28:23.429 WARNING (SyncWorker_5) [homeassistant.components.waze_travel_time.sensor] Error on retrieving data: empty response
2022-08-10 12:30:00.040 WARNING (MainThread) [homeassistant.helpers.service] Unable to find referenced entities fan.mi_air or it is/they are currently not available
2022-08-10 12:34:57.994 ERROR (MainThread) [homeassistant.util.logging] Exception in async_schedule_update_ha_state when dispatching 'audiconnect.updated': ()
Traceback (most recent call last):
  File "/usr/src/homeassistant/homeassistant/helpers/entity.py", line 677, in async_schedule_update_ha_state
    self.async_write_ha_state()
  File "/usr/src/homeassistant/homeassistant/helpers/entity.py", line 532, in async_write_ha_state
    self._async_write_ha_state()
  File "/usr/src/homeassistant/homeassistant/helpers/entity.py", line 646, in _async_write_ha_state
    self.hass.states.async_set(
  File "/usr/src/homeassistant/homeassistant/core.py", line 1438, in async_set
    state = State(
  File "/usr/src/homeassistant/homeassistant/core.py", line 1099, in __init__
    raise InvalidStateError(
homeassistant.exceptions.InvalidStateError: Invalid state encountered for entity ID: sensor.audi_e_tron_sportback_shortterm_trip_user_reset. State max length is 255 characters.

2022-08-10 12:34:58.004 ERROR (MainThread) [homeassistant.util.logging] Exception in async_schedule_update_ha_state when dispatching 'audiconnect.updated': ()
Traceback (most recent call last):
  File "/usr/src/homeassistant/homeassistant/helpers/entity.py", line 677, in async_schedule_update_ha_state
    self.async_write_ha_state()
  File "/usr/src/homeassistant/homeassistant/helpers/entity.py", line 532, in async_write_ha_state
    self._async_write_ha_state()
  File "/usr/src/homeassistant/homeassistant/helpers/entity.py", line 646, in _async_write_ha_state
    self.hass.states.async_set(
  File "/usr/src/homeassistant/homeassistant/core.py", line 1438, in async_set
    state = State(
  File "/usr/src/homeassistant/homeassistant/core.py", line 1099, in __init__
    raise InvalidStateError(
homeassistant.exceptions.InvalidStateError: Invalid state encountered for entity ID: sensor.audi_e_tron_sportback_shortterm_trip_data. State max length is 255 characters.

2022-08-10 12:35:00.019 WARNING (MainThread) [homeassistant.helpers.service] Unable to find referenced entities fan.mi_air or it is/they are currently not available
2022-08-10 12:40:00.031 WARNING (MainThread) [homeassistant.helpers.service] Unable to find referenced entities fan.mi_air or it is/they are currently not available
2022-08-10 12:45:00.039 WARNING (MainThread) [homeassistant.helpers.service] Unable to find referenced entities fan.mi_air or it is/they are currently not available
2022-08-10 12:45:02.046 ERROR (MainThread) [homeassistant.util.logging] Exception in async_schedule_update_ha_state when dispatching 'audiconnect.updated': ()
Traceback (most recent call last):
  File "/usr/src/homeassistant/homeassistant/helpers/entity.py", line 677, in async_schedule_update_ha_state
    self.async_write_ha_state()
  File "/usr/src/homeassistant/homeassistant/helpers/entity.py", line 532, in async_write_ha_state
    self._async_write_ha_state()
  File "/usr/src/homeassistant/homeassistant/helpers/entity.py", line 646, in _async_write_ha_state
    self.hass.states.async_set(
  File "/usr/src/homeassistant/homeassistant/core.py", line 1438, in async_set
    state = State(
  File "/usr/src/homeassistant/homeassistant/core.py", line 1099, in __init__
    raise InvalidStateError(
homeassistant.exceptions.InvalidStateError: Invalid state encountered for entity ID: sensor.audi_e_tron_sportback_shortterm_trip_user_reset. State max length is 255 characters.

2022-08-10 12:45:02.061 ERROR (MainThread) [homeassistant.util.logging] Exception in async_schedule_update_ha_state when dispatching 'audiconnect.updated': ()
Traceback (most recent call last):
  File "/usr/src/homeassistant/homeassistant/helpers/entity.py", line 677, in async_schedule_update_ha_state
    self.async_write_ha_state()
  File "/usr/src/homeassistant/homeassistant/helpers/entity.py", line 532, in async_write_ha_state
    self._async_write_ha_state()
  File "/usr/src/homeassistant/homeassistant/helpers/entity.py", line 646, in _async_write_ha_state
    self.hass.states.async_set(
  File "/usr/src/homeassistant/homeassistant/core.py", line 1438, in async_set
    state = State(
  File "/usr/src/homeassistant/homeassistant/core.py", line 1099, in __init__
    raise InvalidStateError(
homeassistant.exceptions.InvalidStateError: Invalid state encountered for entity ID: sensor.audi_e_tron_sportback_shortterm_trip_data. State max length is 255 characters.

2022-08-10 12:48:23.439 WARNING (SyncWorker_1) [homeassistant.components.waze_travel_time.sensor] Error on retrieving data: empty response
2022-08-10 12:50:00.020 WARNING (MainThread) [homeassistant.helpers.service] Unable to find referenced entities fan.mi_air or it is/they are currently not available
2022-08-10 12:50:10.285 WARNING (Recorder) [homeassistant.components.sensor.recorder] Entity sensor.alb001021090363_solar_to_load from integration alphaess has state class total_increasing, but its state is not strictly increasing. Triggered by state 1.43 (1.44) with last_updated set to 2022-08-10T12:48:06.590257+00:00. Please report it to the custom integration author.
2022-08-10 12:55:00.016 WARNING (MainThread) [homeassistant.helpers.service] Unable to find referenced entities fan.mi_air or it is/they are currently not available
2022-08-10 12:55:05.799 ERROR (MainThread) [homeassistant.util.logging] Exception in async_schedule_update_ha_state when dispatching 'audiconnect.updated': ()
Traceback (most recent call last):
  File "/usr/src/homeassistant/homeassistant/helpers/entity.py", line 677, in async_schedule_update_ha_state
    self.async_write_ha_state()
  File "/usr/src/homeassistant/homeassistant/helpers/entity.py", line 532, in async_write_ha_state
    self._async_write_ha_state()
  File "/usr/src/homeassistant/homeassistant/helpers/entity.py", line 646, in _async_write_ha_state
    self.hass.states.async_set(
  File "/usr/src/homeassistant/homeassistant/core.py", line 1438, in async_set
    state = State(
  File "/usr/src/homeassistant/homeassistant/core.py", line 1099, in __init__
    raise InvalidStateError(
homeassistant.exceptions.InvalidStateError: Invalid state encountered for entity ID: sensor.audi_e_tron_sportback_shortterm_trip_user_reset. State max length is 255 characters.

2022-08-10 12:55:05.811 ERROR (MainThread) [homeassistant.util.logging] Exception in async_schedule_update_ha_state when dispatching 'audiconnect.updated': ()
Traceback (most recent call last):
  File "/usr/src/homeassistant/homeassistant/helpers/entity.py", line 677, in async_schedule_update_ha_state
    self.async_write_ha_state()
  File "/usr/src/homeassistant/homeassistant/helpers/entity.py", line 532, in async_write_ha_state
    self._async_write_ha_state()
  File "/usr/src/homeassistant/homeassistant/helpers/entity.py", line 646, in _async_write_ha_state
    self.hass.states.async_set(
  File "/usr/src/homeassistant/homeassistant/core.py", line 1438, in async_set
    state = State(
  File "/usr/src/homeassistant/homeassistant/core.py", line 1099, in __init__
    raise InvalidStateError(
homeassistant.exceptions.InvalidStateError: Invalid state encountered for entity ID: sensor.audi_e_tron_sportback_shortterm_trip_data. State max length is 255 characters.

2022-08-10 12:58:27.064 WARNING (MainThread) [homeassistant.components.binary_sensor] Updating ping binary_sensor took longer than the scheduled update interval 0:00:05
2022-08-10 13:00:00.060 WARNING (MainThread) [homeassistant.helpers.service] Unable to find referenced entities fan.mi_air or it is/they are currently not available
2022-08-10 13:00:02.083 WARNING (MainThread) [homeassistant.components.binary_sensor] Updating ping binary_sensor took longer than the scheduled update interval 0:00:05
2022-08-10 13:05:00.018 WARNING (MainThread) [homeassistant.helpers.service] Unable to find referenced entities fan.mi_air or it is/they are currently not available
2022-08-10 13:05:10.578 ERROR (MainThread) [homeassistant.util.logging] Exception in async_schedule_update_ha_state when dispatching 'audiconnect.updated': ()
Traceback (most recent call last):
  File "/usr/src/homeassistant/homeassistant/helpers/entity.py", line 677, in async_schedule_update_ha_state
    self.async_write_ha_state()
  File "/usr/src/homeassistant/homeassistant/helpers/entity.py", line 532, in async_write_ha_state
    self._async_write_ha_state()
  File "/usr/src/homeassistant/homeassistant/helpers/entity.py", line 646, in _async_write_ha_state
    self.hass.states.async_set(
  File "/usr/src/homeassistant/homeassistant/core.py", line 1438, in async_set
    state = State(
  File "/usr/src/homeassistant/homeassistant/core.py", line 1099, in __init__
    raise InvalidStateError(
homeassistant.exceptions.InvalidStateError: Invalid state encountered for entity ID: sensor.audi_e_tron_sportback_shortterm_trip_user_reset. State max length is 255 characters.

2022-08-10 13:05:10.585 ERROR (MainThread) [homeassistant.util.logging] Exception in async_schedule_update_ha_state when dispatching 'audiconnect.updated': ()
Traceback (most recent call last):
  File "/usr/src/homeassistant/homeassistant/helpers/entity.py", line 677, in async_schedule_update_ha_state
    self.async_write_ha_state()
  File "/usr/src/homeassistant/homeassistant/helpers/entity.py", line 532, in async_write_ha_state
    self._async_write_ha_state()
  File "/usr/src/homeassistant/homeassistant/helpers/entity.py", line 646, in _async_write_ha_state
    self.hass.states.async_set(
  File "/usr/src/homeassistant/homeassistant/core.py", line 1438, in async_set
    state = State(
  File "/usr/src/homeassistant/homeassistant/core.py", line 1099, in __init__
    raise InvalidStateError(
homeassistant.exceptions.InvalidStateError: Invalid state encountered for entity ID: sensor.audi_e_tron_sportback_shortterm_trip_data. State max length is 255 characters.

2022-08-10 13:09:27.343 WARNING (MainThread) [homeassistant.components.binary_sensor] Updating ping binary_sensor took longer than the scheduled update interval 0:00:05
2022-08-10 13:09:37.233 WARNING (MainThread) [homeassistant.components.binary_sensor] Updating ping binary_sensor took longer than the scheduled update interval 0:00:05
2022-08-10 13:10:00.020 WARNING (MainThread) [homeassistant.helpers.service] Unable to find referenced entities fan.mi_air or it is/they are currently not available
2022-08-10 13:15:00.043 WARNING (MainThread) [homeassistant.helpers.service] Unable to find referenced entities fan.mi_air or it is/they are currently not available
2022-08-10 13:15:14.305 ERROR (MainThread) [homeassistant.util.logging] Exception in async_schedule_update_ha_state when dispatching 'audiconnect.updated': ()
Traceback (most recent call last):
  File "/usr/src/homeassistant/homeassistant/helpers/entity.py", line 677, in async_schedule_update_ha_state
    self.async_write_ha_state()
  File "/usr/src/homeassistant/homeassistant/helpers/entity.py", line 532, in async_write_ha_state
    self._async_write_ha_state()
  File "/usr/src/homeassistant/homeassistant/helpers/entity.py", line 646, in _async_write_ha_state
    self.hass.states.async_set(
  File "/usr/src/homeassistant/homeassistant/core.py", line 1438, in async_set
    state = State(
  File "/usr/src/homeassistant/homeassistant/core.py", line 1099, in __init__
    raise InvalidStateError(
homeassistant.exceptions.InvalidStateError: Invalid state encountered for entity ID: sensor.audi_e_tron_sportback_shortterm_trip_user_reset. State max length is 255 characters.

2022-08-10 13:15:14.312 ERROR (MainThread) [homeassistant.util.logging] Exception in async_schedule_update_ha_state when dispatching 'audiconnect.updated': ()
Traceback (most recent call last):
  File "/usr/src/homeassistant/homeassistant/helpers/entity.py", line 677, in async_schedule_update_ha_state
    self.async_write_ha_state()
  File "/usr/src/homeassistant/homeassistant/helpers/entity.py", line 532, in async_write_ha_state
    self._async_write_ha_state()
  File "/usr/src/homeassistant/homeassistant/helpers/entity.py", line 646, in _async_write_ha_state
    self.hass.states.async_set(
  File "/usr/src/homeassistant/homeassistant/core.py", line 1438, in async_set
    state = State(
  File "/usr/src/homeassistant/homeassistant/core.py", line 1099, in __init__
    raise InvalidStateError(
homeassistant.exceptions.InvalidStateError: Invalid state encountered for entity ID: sensor.audi_e_tron_sportback_shortterm_trip_data. State max length is 255 characters.

2022-08-10 13:20:00.072 WARNING (MainThread) [homeassistant.helpers.service] Unable to find referenced entities fan.mi_air or it is/they are currently not available
2022-08-10 13:23:23.816 WARNING (SyncWorker_0) [homeassistant.components.waze_travel_time.sensor] Error on retrieving data: empty response
2022-08-10 13:25:00.022 WARNING (MainThread) [homeassistant.helpers.service] Unable to find referenced entities fan.mi_air or it is/they are currently not available
2022-08-10 13:25:18.529 ERROR (MainThread) [homeassistant.util.logging] Exception in async_schedule_update_ha_state when dispatching 'audiconnect.updated': ()
Traceback (most recent call last):
  File "/usr/src/homeassistant/homeassistant/helpers/entity.py", line 677, in async_schedule_update_ha_state
    self.async_write_ha_state()
  File "/usr/src/homeassistant/homeassistant/helpers/entity.py", line 532, in async_write_ha_state
    self._async_write_ha_state()
  File "/usr/src/homeassistant/homeassistant/helpers/entity.py", line 646, in _async_write_ha_state
    self.hass.states.async_set(
  File "/usr/src/homeassistant/homeassistant/core.py", line 1438, in async_set
    state = State(
  File "/usr/src/homeassistant/homeassistant/core.py", line 1099, in __init__
    raise InvalidStateError(
homeassistant.exceptions.InvalidStateError: Invalid state encountered for entity ID: sensor.audi_e_tron_sportback_shortterm_trip_user_reset. State max length is 255 characters.

2022-08-10 13:25:18.536 ERROR (MainThread) [homeassistant.util.logging] Exception in async_schedule_update_ha_state when dispatching 'audiconnect.updated': ()
Traceback (most recent call last):
  File "/usr/src/homeassistant/homeassistant/helpers/entity.py", line 677, in async_schedule_update_ha_state
    self.async_write_ha_state()
  File "/usr/src/homeassistant/homeassistant/helpers/entity.py", line 532, in async_write_ha_state
    self._async_write_ha_state()
  File "/usr/src/homeassistant/homeassistant/helpers/entity.py", line 646, in _async_write_ha_state
    self.hass.states.async_set(
  File "/usr/src/homeassistant/homeassistant/core.py", line 1438, in async_set
    state = State(
  File "/usr/src/homeassistant/homeassistant/core.py", line 1099, in __init__
    raise InvalidStateError(
homeassistant.exceptions.InvalidStateError: Invalid state encountered for entity ID: sensor.audi_e_tron_sportback_shortterm_trip_data. State max length is 255 characters.

2022-08-10 13:30:00.074 WARNING (MainThread) [homeassistant.helpers.service] Unable to find referenced entities fan.mi_air or it is/they are currently not available
2022-08-10 13:35:00.018 WARNING (MainThread) [homeassistant.helpers.service] Unable to find referenced entities fan.mi_air or it is/they are currently not available
2022-08-10 13:35:23.274 ERROR (MainThread) [homeassistant.util.logging] Exception in async_schedule_update_ha_state when dispatching 'audiconnect.updated': ()
Traceback (most recent call last):
  File "/usr/src/homeassistant/homeassistant/helpers/entity.py", line 677, in async_schedule_update_ha_state
    self.async_write_ha_state()
  File "/usr/src/homeassistant/homeassistant/helpers/entity.py", line 532, in async_write_ha_state
    self._async_write_ha_state()
  File "/usr/src/homeassistant/homeassistant/helpers/entity.py", line 646, in _async_write_ha_state
    self.hass.states.async_set(
  File "/usr/src/homeassistant/homeassistant/core.py", line 1438, in async_set
    state = State(
  File "/usr/src/homeassistant/homeassistant/core.py", line 1099, in __init__
    raise InvalidStateError(
homeassistant.exceptions.InvalidStateError: Invalid state encountered for entity ID: sensor.audi_e_tron_sportback_shortterm_trip_user_reset. State max length is 255 characters.

2022-08-10 13:35:23.281 ERROR (MainThread) [homeassistant.util.logging] Exception in async_schedule_update_ha_state when dispatching 'audiconnect.updated': ()
Traceback (most recent call last):
  File "/usr/src/homeassistant/homeassistant/helpers/entity.py", line 677, in async_schedule_update_ha_state
    self.async_write_ha_state()
  File "/usr/src/homeassistant/homeassistant/helpers/entity.py", line 532, in async_write_ha_state
    self._async_write_ha_state()
  File "/usr/src/homeassistant/homeassistant/helpers/entity.py", line 646, in _async_write_ha_state
    self.hass.states.async_set(
  File "/usr/src/homeassistant/homeassistant/core.py", line 1438, in async_set
    state = State(
  File "/usr/src/homeassistant/homeassistant/core.py", line 1099, in __init__
    raise InvalidStateError(
homeassistant.exceptions.InvalidStateError: Invalid state encountered for entity ID: sensor.audi_e_tron_sportback_shortterm_trip_data. State max length is 255 characters.

2022-08-10 13:38:23.903 WARNING (SyncWorker_12) [homeassistant.components.waze_travel_time.sensor] Error on retrieving data: empty response
2022-08-10 13:40:00.030 WARNING (MainThread) [homeassistant.helpers.service] Unable to find referenced entities fan.mi_air or it is/they are currently not available
2022-08-10 13:45:00.038 WARNING (MainThread) [homeassistant.helpers.service] Unable to find referenced entities fan.mi_air or it is/they are currently not available
2022-08-10 13:45:27.207 ERROR (MainThread) [homeassistant.util.logging] Exception in async_schedule_update_ha_state when dispatching 'audiconnect.updated': ()
Traceback (most recent call last):
  File "/usr/src/homeassistant/homeassistant/helpers/entity.py", line 677, in async_schedule_update_ha_state
    self.async_write_ha_state()
  File "/usr/src/homeassistant/homeassistant/helpers/entity.py", line 532, in async_write_ha_state
    self._async_write_ha_state()
  File "/usr/src/homeassistant/homeassistant/helpers/entity.py", line 646, in _async_write_ha_state
    self.hass.states.async_set(
  File "/usr/src/homeassistant/homeassistant/core.py", line 1438, in async_set
    state = State(
  File "/usr/src/homeassistant/homeassistant/core.py", line 1099, in __init__
    raise InvalidStateError(
homeassistant.exceptions.InvalidStateError: Invalid state encountered for entity ID: sensor.audi_e_tron_sportback_shortterm_trip_user_reset. State max length is 255 characters.

2022-08-10 13:45:27.221 ERROR (MainThread) [homeassistant.util.logging] Exception in async_schedule_update_ha_state when dispatching 'audiconnect.updated': ()
Traceback (most recent call last):
  File "/usr/src/homeassistant/homeassistant/helpers/entity.py", line 677, in async_schedule_update_ha_state
    self.async_write_ha_state()
  File "/usr/src/homeassistant/homeassistant/helpers/entity.py", line 532, in async_write_ha_state
    self._async_write_ha_state()
  File "/usr/src/homeassistant/homeassistant/helpers/entity.py", line 646, in _async_write_ha_state
    self.hass.states.async_set(
  File "/usr/src/homeassistant/homeassistant/core.py", line 1438, in async_set
    state = State(
  File "/usr/src/homeassistant/homeassistant/core.py", line 1099, in __init__
    raise InvalidStateError(
homeassistant.exceptions.InvalidStateError: Invalid state encountered for entity ID: sensor.audi_e_tron_sportback_shortterm_trip_data. State max length is 255 characters.

2022-08-10 13:48:23.869 WARNING (SyncWorker_5) [homeassistant.components.waze_travel_time.sensor] Error on retrieving data: empty response
2022-08-10 13:48:33.932 WARNING (MainThread) [homeassistant.components.binary_sensor] Updating ping binary_sensor took longer than the scheduled update interval 0:00:05
2022-08-10 13:50:00.023 WARNING (MainThread) [homeassistant.helpers.service] Unable to find referenced entities fan.mi_air or it is/they are currently not available
2022-08-10 13:55:00.019 WARNING (MainThread) [homeassistant.helpers.service] Unable to find referenced entities fan.mi_air or it is/they are currently not available
2022-08-10 13:55:31.128 ERROR (MainThread) [homeassistant.util.logging] Exception in async_schedule_update_ha_state when dispatching 'audiconnect.updated': ()
Traceback (most recent call last):
  File "/usr/src/homeassistant/homeassistant/helpers/entity.py", line 677, in async_schedule_update_ha_state
    self.async_write_ha_state()
  File "/usr/src/homeassistant/homeassistant/helpers/entity.py", line 532, in async_write_ha_state
    self._async_write_ha_state()
  File "/usr/src/homeassistant/homeassistant/helpers/entity.py", line 646, in _async_write_ha_state
    self.hass.states.async_set(
  File "/usr/src/homeassistant/homeassistant/core.py", line 1438, in async_set
    state = State(
  File "/usr/src/homeassistant/homeassistant/core.py", line 1099, in __init__
    raise InvalidStateError(
homeassistant.exceptions.InvalidStateError: Invalid state encountered for entity ID: sensor.audi_e_tron_sportback_shortterm_trip_user_reset. State max length is 255 characters.

2022-08-10 13:55:31.138 ERROR (MainThread) [homeassistant.util.logging] Exception in async_schedule_update_ha_state when dispatching 'audiconnect.updated': ()
Traceback (most recent call last):
  File "/usr/src/homeassistant/homeassistant/helpers/entity.py", line 677, in async_schedule_update_ha_state
    self.async_write_ha_state()
  File "/usr/src/homeassistant/homeassistant/helpers/entity.py", line 532, in async_write_ha_state
    self._async_write_ha_state()
  File "/usr/src/homeassistant/homeassistant/helpers/entity.py", line 646, in _async_write_ha_state
    self.hass.states.async_set(
  File "/usr/src/homeassistant/homeassistant/core.py", line 1438, in async_set
    state = State(
  File "/usr/src/homeassistant/homeassistant/core.py", line 1099, in __init__
    raise InvalidStateError(
homeassistant.exceptions.InvalidStateError: Invalid state encountered for entity ID: sensor.audi_e_tron_sportback_shortterm_trip_data. State max length is 255 characters.

2022-08-10 14:00:00.064 WARNING (MainThread) [homeassistant.helpers.service] Unable to find referenced entities fan.mi_air or it is/they are currently not available
2022-08-10 14:05:00.014 WARNING (MainThread) [homeassistant.helpers.service] Unable to find referenced entities fan.mi_air or it is/they are currently not available
2022-08-10 14:05:34.897 ERROR (MainThread) [homeassistant.util.logging] Exception in async_schedule_update_ha_state when dispatching 'audiconnect.updated': ()
Traceback (most recent call last):
  File "/usr/src/homeassistant/homeassistant/helpers/entity.py", line 677, in async_schedule_update_ha_state
    self.async_write_ha_state()
  File "/usr/src/homeassistant/homeassistant/helpers/entity.py", line 532, in async_write_ha_state
    self._async_write_ha_state()
  File "/usr/src/homeassistant/homeassistant/helpers/entity.py", line 646, in _async_write_ha_state
    self.hass.states.async_set(
  File "/usr/src/homeassistant/homeassistant/core.py", line 1438, in async_set
    state = State(
  File "/usr/src/homeassistant/homeassistant/core.py", line 1099, in __init__
    raise InvalidStateError(
homeassistant.exceptions.InvalidStateError: Invalid state encountered for entity ID: sensor.audi_e_tron_sportback_shortterm_trip_user_reset. State max length is 255 characters.

2022-08-10 14:05:34.905 ERROR (MainThread) [homeassistant.util.logging] Exception in async_schedule_update_ha_state when dispatching 'audiconnect.updated': ()
Traceback (most recent call last):
  File "/usr/src/homeassistant/homeassistant/helpers/entity.py", line 677, in async_schedule_update_ha_state
    self.async_write_ha_state()
  File "/usr/src/homeassistant/homeassistant/helpers/entity.py", line 532, in async_write_ha_state
    self._async_write_ha_state()
  File "/usr/src/homeassistant/homeassistant/helpers/entity.py", line 646, in _async_write_ha_state
    self.hass.states.async_set(
  File "/usr/src/homeassistant/homeassistant/core.py", line 1438, in async_set
    state = State(
  File "/usr/src/homeassistant/homeassistant/core.py", line 1099, in __init__
    raise InvalidStateError(
homeassistant.exceptions.InvalidStateError: Invalid state encountered for entity ID: sensor.audi_e_tron_sportback_shortterm_trip_data. State max length is 255 characters.

2022-08-10 14:10:00.020 WARNING (MainThread) [homeassistant.helpers.service] Unable to find referenced entities fan.mi_air or it is/they are currently not available
2022-08-10 14:14:05.866 ERROR (MainThread) [aiohttp.server] Error handling request
Traceback (most recent call last):
  File "/usr/local/lib/python3.10/site-packages/aiohttp/web_protocol.py", line 334, in data_received
    messages, upgraded, tail = self._request_parser.feed_data(data)
  File "aiohttp/_http_parser.pyx", line 551, in aiohttp._http_parser.HttpParser.feed_data
aiohttp.http_exceptions.BadStatusLine: 400, message="Bad status line 'Invalid method encountered'"
2022-08-10 14:15:00.048 WARNING (MainThread) [homeassistant.helpers.service] Unable to find referenced entities fan.mi_air or it is/they are currently not available
2022-08-10 14:15:38.859 ERROR (MainThread) [homeassistant.util.logging] Exception in async_schedule_update_ha_state when dispatching 'audiconnect.updated': ()
Traceback (most recent call last):
  File "/usr/src/homeassistant/homeassistant/helpers/entity.py", line 677, in async_schedule_update_ha_state
    self.async_write_ha_state()
  File "/usr/src/homeassistant/homeassistant/helpers/entity.py", line 532, in async_write_ha_state
    self._async_write_ha_state()
  File "/usr/src/homeassistant/homeassistant/helpers/entity.py", line 646, in _async_write_ha_state
    self.hass.states.async_set(
  File "/usr/src/homeassistant/homeassistant/core.py", line 1438, in async_set
    state = State(
  File "/usr/src/homeassistant/homeassistant/core.py", line 1099, in __init__
    raise InvalidStateError(
homeassistant.exceptions.InvalidStateError: Invalid state encountered for entity ID: sensor.audi_e_tron_sportback_shortterm_trip_user_reset. State max length is 255 characters.

2022-08-10 14:15:38.867 ERROR (MainThread) [homeassistant.util.logging] Exception in async_schedule_update_ha_state when dispatching 'audiconnect.updated': ()
Traceback (most recent call last):
  File "/usr/src/homeassistant/homeassistant/helpers/entity.py", line 677, in async_schedule_update_ha_state
    self.async_write_ha_state()
  File "/usr/src/homeassistant/homeassistant/helpers/entity.py", line 532, in async_write_ha_state
    self._async_write_ha_state()
  File "/usr/src/homeassistant/homeassistant/helpers/entity.py", line 646, in _async_write_ha_state
    self.hass.states.async_set(
  File "/usr/src/homeassistant/homeassistant/core.py", line 1438, in async_set
    state = State(
  File "/usr/src/homeassistant/homeassistant/core.py", line 1099, in __init__
    raise InvalidStateError(
homeassistant.exceptions.InvalidStateError: Invalid state encountered for entity ID: sensor.audi_e_tron_sportback_shortterm_trip_data. State max length is 255 characters.

2022-08-10 14:18:23.841 WARNING (SyncWorker_2) [homeassistant.components.waze_travel_time.sensor] Error on retrieving data: empty response
2022-08-10 14:18:23.853 WARNING (SyncWorker_9) [homeassistant.components.waze_travel_time.sensor] Error on retrieving data: empty response
2022-08-10 14:20:00.018 WARNING (MainThread) [homeassistant.helpers.service] Unable to find referenced entities fan.mi_air or it is/they are currently not available
2022-08-10 14:20:35.867 WARNING (MainThread) [homeassistant.components.binary_sensor] Updating ping binary_sensor took longer than the scheduled update interval 0:00:05
2022-08-10 14:23:33.749 WARNING (MainThread) [homeassistant.helpers.entity] Update of sensor.waze_travel_time_toyota_evere_huis is taking over 10 seconds
2022-08-10 14:25:00.019 WARNING (MainThread) [homeassistant.helpers.service] Unable to find referenced entities fan.mi_air or it is/they are currently not available
2022-08-10 14:25:42.699 ERROR (MainThread) [homeassistant.util.logging] Exception in async_schedule_update_ha_state when dispatching 'audiconnect.updated': ()
Traceback (most recent call last):
  File "/usr/src/homeassistant/homeassistant/helpers/entity.py", line 677, in async_schedule_update_ha_state
    self.async_write_ha_state()
  File "/usr/src/homeassistant/homeassistant/helpers/entity.py", line 532, in async_write_ha_state
    self._async_write_ha_state()
  File "/usr/src/homeassistant/homeassistant/helpers/entity.py", line 646, in _async_write_ha_state
    self.hass.states.async_set(
  File "/usr/src/homeassistant/homeassistant/core.py", line 1438, in async_set
    state = State(
  File "/usr/src/homeassistant/homeassistant/core.py", line 1099, in __init__
    raise InvalidStateError(
homeassistant.exceptions.InvalidStateError: Invalid state encountered for entity ID: sensor.audi_e_tron_sportback_shortterm_trip_user_reset. State max length is 255 characters.

2022-08-10 14:25:42.706 ERROR (MainThread) [homeassistant.util.logging] Exception in async_schedule_update_ha_state when dispatching 'audiconnect.updated': ()
Traceback (most recent call last):
  File "/usr/src/homeassistant/homeassistant/helpers/entity.py", line 677, in async_schedule_update_ha_state
    self.async_write_ha_state()
  File "/usr/src/homeassistant/homeassistant/helpers/entity.py", line 532, in async_write_ha_state
    self._async_write_ha_state()
  File "/usr/src/homeassistant/homeassistant/helpers/entity.py", line 646, in _async_write_ha_state
    self.hass.states.async_set(
  File "/usr/src/homeassistant/homeassistant/core.py", line 1438, in async_set
    state = State(
  File "/usr/src/homeassistant/homeassistant/core.py", line 1099, in __init__
    raise InvalidStateError(
homeassistant.exceptions.InvalidStateError: Invalid state encountered for entity ID: sensor.audi_e_tron_sportback_shortterm_trip_data. State max length is 255 characters.

2022-08-10 14:28:23.921 WARNING (SyncWorker_6) [homeassistant.components.waze_travel_time.sensor] Error on retrieving data: empty response
2022-08-10 14:30:00.044 WARNING (MainThread) [homeassistant.helpers.service] Unable to find referenced entities fan.mi_air or it is/they are currently not available
2022-08-10 14:35:00.016 WARNING (MainThread) [homeassistant.helpers.service] Unable to find referenced entities fan.mi_air or it is/they are currently not available
2022-08-10 14:35:46.486 ERROR (MainThread) [homeassistant.util.logging] Exception in async_schedule_update_ha_state when dispatching 'audiconnect.updated': ()
Traceback (most recent call last):
  File "/usr/src/homeassistant/homeassistant/helpers/entity.py", line 677, in async_schedule_update_ha_state
    self.async_write_ha_state()
  File "/usr/src/homeassistant/homeassistant/helpers/entity.py", line 532, in async_write_ha_state
    self._async_write_ha_state()
  File "/usr/src/homeassistant/homeassistant/helpers/entity.py", line 646, in _async_write_ha_state
    self.hass.states.async_set(
  File "/usr/src/homeassistant/homeassistant/core.py", line 1438, in async_set
    state = State(
  File "/usr/src/homeassistant/homeassistant/core.py", line 1099, in __init__
    raise InvalidStateError(
homeassistant.exceptions.InvalidStateError: Invalid state encountered for entity ID: sensor.audi_e_tron_sportback_shortterm_trip_user_reset. State max length is 255 characters.

2022-08-10 14:35:46.494 ERROR (MainThread) [homeassistant.util.logging] Exception in async_schedule_update_ha_state when dispatching 'audiconnect.updated': ()
Traceback (most recent call last):
  File "/usr/src/homeassistant/homeassistant/helpers/entity.py", line 677, in async_schedule_update_ha_state
    self.async_write_ha_state()
  File "/usr/src/homeassistant/homeassistant/helpers/entity.py", line 532, in async_write_ha_state
    self._async_write_ha_state()
  File "/usr/src/homeassistant/homeassistant/helpers/entity.py", line 646, in _async_write_ha_state
    self.hass.states.async_set(
  File "/usr/src/homeassistant/homeassistant/core.py", line 1438, in async_set
    state = State(
  File "/usr/src/homeassistant/homeassistant/core.py", line 1099, in __init__
    raise InvalidStateError(
homeassistant.exceptions.InvalidStateError: Invalid state encountered for entity ID: sensor.audi_e_tron_sportback_shortterm_trip_data. State max length is 255 characters.

2022-08-10 14:39:26.093 WARNING (MainThread) [homeassistant.components.binary_sensor] Updating ping binary_sensor took longer than the scheduled update interval 0:00:05
2022-08-10 14:40:00.023 WARNING (MainThread) [homeassistant.helpers.service] Unable to find referenced entities fan.mi_air or it is/they are currently not available
2022-08-10 14:45:00.055 WARNING (MainThread) [homeassistant.helpers.service] Unable to find referenced entities fan.mi_air or it is/they are currently not available
2022-08-10 14:45:50.350 ERROR (MainThread) [homeassistant.util.logging] Exception in async_schedule_update_ha_state when dispatching 'audiconnect.updated': ()
Traceback (most recent call last):
  File "/usr/src/homeassistant/homeassistant/helpers/entity.py", line 677, in async_schedule_update_ha_state
    self.async_write_ha_state()
  File "/usr/src/homeassistant/homeassistant/helpers/entity.py", line 532, in async_write_ha_state
    self._async_write_ha_state()
  File "/usr/src/homeassistant/homeassistant/helpers/entity.py", line 646, in _async_write_ha_state
    self.hass.states.async_set(
  File "/usr/src/homeassistant/homeassistant/core.py", line 1438, in async_set
    state = State(
  File "/usr/src/homeassistant/homeassistant/core.py", line 1099, in __init__
    raise InvalidStateError(
homeassistant.exceptions.InvalidStateError: Invalid state encountered for entity ID: sensor.audi_e_tron_sportback_shortterm_trip_user_reset. State max length is 255 characters.

2022-08-10 14:45:50.360 ERROR (MainThread) [homeassistant.util.logging] Exception in async_schedule_update_ha_state when dispatching 'audiconnect.updated': ()
Traceback (most recent call last):
  File "/usr/src/homeassistant/homeassistant/helpers/entity.py", line 677, in async_schedule_update_ha_state
    self.async_write_ha_state()
  File "/usr/src/homeassistant/homeassistant/helpers/entity.py", line 532, in async_write_ha_state
    self._async_write_ha_state()
  File "/usr/src/homeassistant/homeassistant/helpers/entity.py", line 646, in _async_write_ha_state
    self.hass.states.async_set(
  File "/usr/src/homeassistant/homeassistant/core.py", line 1438, in async_set
    state = State(
  File "/usr/src/homeassistant/homeassistant/core.py", line 1099, in __init__
    raise InvalidStateError(
homeassistant.exceptions.InvalidStateError: Invalid state encountered for entity ID: sensor.audi_e_tron_sportback_shortterm_trip_data. State max length is 255 characters.

2022-08-10 14:50:00.020 WARNING (MainThread) [homeassistant.helpers.service] Unable to find referenced entities fan.mi_air or it is/they are currently not available
2022-08-10 14:50:35.965 WARNING (SyncWorker_0) [homeassistant.components.scrape.sensor] Index 'None' not found in sensor.precip_rate_leuven24_wunderground
2022-08-10 14:52:30.860 WARNING (SyncWorker_11) [homeassistant.components.scrape.sensor] Index 'None' not found in sensor.temp_leuven24_wunderground
2022-08-10 14:52:31.212 WARNING (SyncWorker_4) [homeassistant.components.scrape.sensor] Index 'None' not found in sensor.humidity_leuven24_wunderground
2022-08-10 14:53:32.436 WARNING (SyncWorker_12) [homeassistant.components.scrape.sensor] Index 'None' not found in sensor.precip_rate_leuven24_wunderground
2022-08-10 14:55:00.027 WARNING (MainThread) [homeassistant.helpers.service] Unable to find referenced entities fan.mi_air or it is/they are currently not available
2022-08-10 14:55:54.308 ERROR (MainThread) [homeassistant.util.logging] Exception in async_schedule_update_ha_state when dispatching 'audiconnect.updated': ()
Traceback (most recent call last):
  File "/usr/src/homeassistant/homeassistant/helpers/entity.py", line 677, in async_schedule_update_ha_state
    self.async_write_ha_state()
  File "/usr/src/homeassistant/homeassistant/helpers/entity.py", line 532, in async_write_ha_state
    self._async_write_ha_state()
  File "/usr/src/homeassistant/homeassistant/helpers/entity.py", line 646, in _async_write_ha_state
    self.hass.states.async_set(
  File "/usr/src/homeassistant/homeassistant/core.py", line 1438, in async_set
    state = State(
  File "/usr/src/homeassistant/homeassistant/core.py", line 1099, in __init__
    raise InvalidStateError(
homeassistant.exceptions.InvalidStateError: Invalid state encountered for entity ID: sensor.audi_e_tron_sportback_shortterm_trip_user_reset. State max length is 255 characters.

2022-08-10 14:55:54.316 ERROR (MainThread) [homeassistant.util.logging] Exception in async_schedule_update_ha_state when dispatching 'audiconnect.updated': ()
Traceback (most recent call last):
  File "/usr/src/homeassistant/homeassistant/helpers/entity.py", line 677, in async_schedule_update_ha_state
    self.async_write_ha_state()
  File "/usr/src/homeassistant/homeassistant/helpers/entity.py", line 532, in async_write_ha_state
    self._async_write_ha_state()
  File "/usr/src/homeassistant/homeassistant/helpers/entity.py", line 646, in _async_write_ha_state
    self.hass.states.async_set(
  File "/usr/src/homeassistant/homeassistant/core.py", line 1438, in async_set
    state = State(
  File "/usr/src/homeassistant/homeassistant/core.py", line 1099, in __init__
    raise InvalidStateError(
homeassistant.exceptions.InvalidStateError: Invalid state encountered for entity ID: sensor.audi_e_tron_sportback_shortterm_trip_data. State max length is 255 characters.

2022-08-10 14:56:34.297 WARNING (SyncWorker_13) [homeassistant.components.scrape.sensor] Index 'None' not found in sensor.temp_leuven24_wunderground
2022-08-10 14:56:34.330 WARNING (SyncWorker_5) [homeassistant.components.scrape.sensor] Index 'None' not found in sensor.humidity_leuven24_wunderground
2022-08-10 14:56:36.830 WARNING (MainThread) [homeassistant.components.binary_sensor] Updating ping binary_sensor took longer than the scheduled update interval 0:00:05
2022-08-10 14:56:37.176 WARNING (SyncWorker_11) [homeassistant.components.scrape.sensor] Index 'None' not found in sensor.precip_rate_leuven24_wunderground
2022-08-10 14:58:32.687 WARNING (SyncWorker_6) [homeassistant.components.scrape.sensor] Index 'None' not found in sensor.precip_total_leuven24_wunderground
2022-08-10 14:58:32.724 WARNING (SyncWorker_1) [homeassistant.components.scrape.sensor] Index 'None' not found in sensor.uvindex_leuven24_wunderground
2022-08-10 14:59:32.474 WARNING (SyncWorker_11) [homeassistant.components.scrape.sensor] Index 'None' not found in sensor.precip_rate_leuven24_wunderground
2022-08-10 14:59:54.482 ERROR (MainThread) [custom_components.googlewifi] Unexpected error fetching GoogleWifi data: 'operationState'
Traceback (most recent call last):
  File "/usr/src/homeassistant/homeassistant/helpers/update_coordinator.py", line 205, in _async_refresh
    self.data = await self._async_update_data()
  File "/config/custom_components/googlewifi/__init__.py", line 171, in _async_update_data
    system_data = await self.api.get_systems()
  File "/usr/local/lib/python3.10/site-packages/googlewifi/__init__.py", line 191, in get_systems
    return await self.structure_systems(response)
  File "/usr/local/lib/python3.10/site-packages/googlewifi/__init__.py", line 284, in structure_systems
    sensitive_info = await self.get_sensitive_info(system_id=this_system["id"], station_ids=station_ids)
  File "/usr/local/lib/python3.10/site-packages/googlewifi/__init__.py", line 617, in get_sensitive_info
    status = status["operationState"]
KeyError: 'operationState'
2022-08-10 15:00:00.100 WARNING (MainThread) [homeassistant.helpers.service] Unable to find referenced entities fan.mi_air or it is/they are currently not available
2022-08-10 15:00:00.147 WARNING (MainThread) [homeassistant.helpers.template] Template variable warning: 'reason' is undefined when rendering '{{reason}}<br>{{message}}'
2022-08-10 15:00:00.157 WARNING (MainThread) [homeassistant.helpers.template] Template variable warning: 'action_window_pause' is undefined when rendering '{{action_window_pause}}'
2022-08-10 15:00:00.171 WARNING (MainThread) [homeassistant.helpers.template] Template variable warning: 'uri' is undefined when rendering '{{uri}}'
2022-08-10 15:00:00.204 WARNING (MainThread) [homeassistant.helpers.template] Template variable warning: 'reason' is undefined when rendering '{{reason}}<br>{{message}}'
2022-08-10 15:00:00.210 WARNING (MainThread) [homeassistant.helpers.template] Template variable warning: 'action_window_pause' is undefined when rendering '{{action_window_pause}}'
2022-08-10 15:00:00.213 WARNING (MainThread) [homeassistant.helpers.template] Template variable warning: 'uri' is undefined when rendering '{{uri}}'
2022-08-10 15:00:30.868 WARNING (SyncWorker_4) [homeassistant.components.scrape.sensor] Index 'None' not found in sensor.temp_leuven24_wunderground
2022-08-10 15:00:30.910 WARNING (SyncWorker_1) [homeassistant.components.scrape.sensor] Index 'None' not found in sensor.humidity_leuven24_wunderground
2022-08-10 15:05:00.015 WARNING (MainThread) [homeassistant.helpers.service] Unable to find referenced entities fan.mi_air or it is/they are currently not available
2022-08-10 15:05:58.303 ERROR (MainThread) [homeassistant.util.logging] Exception in async_schedule_update_ha_state when dispatching 'audiconnect.updated': ()
Traceback (most recent call last):
  File "/usr/src/homeassistant/homeassistant/helpers/entity.py", line 677, in async_schedule_update_ha_state
    self.async_write_ha_state()
  File "/usr/src/homeassistant/homeassistant/helpers/entity.py", line 532, in async_write_ha_state
    self._async_write_ha_state()
  File "/usr/src/homeassistant/homeassistant/helpers/entity.py", line 646, in _async_write_ha_state
    self.hass.states.async_set(
  File "/usr/src/homeassistant/homeassistant/core.py", line 1438, in async_set
    state = State(
  File "/usr/src/homeassistant/homeassistant/core.py", line 1099, in __init__
    raise InvalidStateError(
homeassistant.exceptions.InvalidStateError: Invalid state encountered for entity ID: sensor.audi_e_tron_sportback_shortterm_trip_user_reset. State max length is 255 characters.

2022-08-10 15:05:58.314 ERROR (MainThread) [homeassistant.util.logging] Exception in async_schedule_update_ha_state when dispatching 'audiconnect.updated': ()
Traceback (most recent call last):
  File "/usr/src/homeassistant/homeassistant/helpers/entity.py", line 677, in async_schedule_update_ha_state
    self.async_write_ha_state()
  File "/usr/src/homeassistant/homeassistant/helpers/entity.py", line 532, in async_write_ha_state
    self._async_write_ha_state()
  File "/usr/src/homeassistant/homeassistant/helpers/entity.py", line 646, in _async_write_ha_state
    self.hass.states.async_set(
  File "/usr/src/homeassistant/homeassistant/core.py", line 1438, in async_set
    state = State(
  File "/usr/src/homeassistant/homeassistant/core.py", line 1099, in __init__
    raise InvalidStateError(
homeassistant.exceptions.InvalidStateError: Invalid state encountered for entity ID: sensor.audi_e_tron_sportback_shortterm_trip_data. State max length is 255 characters.

2022-08-10 15:10:00.040 WARNING (MainThread) [homeassistant.helpers.service] Unable to find referenced entities fan.mi_air or it is/they are currently not available
2022-08-10 15:15:00.040 WARNING (MainThread) [homeassistant.helpers.service] Unable to find referenced entities fan.mi_air or it is/they are currently not available
2022-08-10 15:16:02.368 ERROR (MainThread) [homeassistant.util.logging] Exception in async_schedule_update_ha_state when dispatching 'audiconnect.updated': ()
Traceback (most recent call last):
  File "/usr/src/homeassistant/homeassistant/helpers/entity.py", line 677, in async_schedule_update_ha_state
    self.async_write_ha_state()
  File "/usr/src/homeassistant/homeassistant/helpers/entity.py", line 532, in async_write_ha_state
    self._async_write_ha_state()
  File "/usr/src/homeassistant/homeassistant/helpers/entity.py", line 646, in _async_write_ha_state
    self.hass.states.async_set(
  File "/usr/src/homeassistant/homeassistant/core.py", line 1438, in async_set
    state = State(
  File "/usr/src/homeassistant/homeassistant/core.py", line 1099, in __init__
    raise InvalidStateError(
homeassistant.exceptions.InvalidStateError: Invalid state encountered for entity ID: sensor.audi_e_tron_sportback_shortterm_trip_user_reset. State max length is 255 characters.

2022-08-10 15:16:02.388 ERROR (MainThread) [homeassistant.util.logging] Exception in async_schedule_update_ha_state when dispatching 'audiconnect.updated': ()
Traceback (most recent call last):
  File "/usr/src/homeassistant/homeassistant/helpers/entity.py", line 677, in async_schedule_update_ha_state
    self.async_write_ha_state()
  File "/usr/src/homeassistant/homeassistant/helpers/entity.py", line 532, in async_write_ha_state
    self._async_write_ha_state()
  File "/usr/src/homeassistant/homeassistant/helpers/entity.py", line 646, in _async_write_ha_state
    self.hass.states.async_set(
  File "/usr/src/homeassistant/homeassistant/core.py", line 1438, in async_set
    state = State(
  File "/usr/src/homeassistant/homeassistant/core.py", line 1099, in __init__
    raise InvalidStateError(
homeassistant.exceptions.InvalidStateError: Invalid state encountered for entity ID: sensor.audi_e_tron_sportback_shortterm_trip_data. State max length is 255 characters.

2022-08-10 15:18:23.923 WARNING (SyncWorker_0) [homeassistant.components.waze_travel_time.sensor] Error on retrieving data: empty response
2022-08-10 15:20:00.022 WARNING (MainThread) [homeassistant.helpers.service] Unable to find referenced entities fan.mi_air or it is/they are currently not available
2022-08-10 15:25:00.018 WARNING (MainThread) [homeassistant.helpers.service] Unable to find referenced entities fan.mi_air or it is/they are currently not available
2022-08-10 15:25:10.295 WARNING (Recorder) [homeassistant.components.sensor.recorder] Entity sensor.alb001021090363_total_load from integration alphaess has state class total_increasing, but its state is not strictly increasing. Triggered by state 12.93 (13.0) with last_updated set to 2022-08-10T15:22:50.582647+00:00. Please report it to the custom integration author.
2022-08-10 15:26:06.218 ERROR (MainThread) [homeassistant.util.logging] Exception in async_schedule_update_ha_state when dispatching 'audiconnect.updated': ()
Traceback (most recent call last):
  File "/usr/src/homeassistant/homeassistant/helpers/entity.py", line 677, in async_schedule_update_ha_state
    self.async_write_ha_state()
  File "/usr/src/homeassistant/homeassistant/helpers/entity.py", line 532, in async_write_ha_state
    self._async_write_ha_state()
  File "/usr/src/homeassistant/homeassistant/helpers/entity.py", line 646, in _async_write_ha_state
    self.hass.states.async_set(
  File "/usr/src/homeassistant/homeassistant/core.py", line 1438, in async_set
    state = State(
  File "/usr/src/homeassistant/homeassistant/core.py", line 1099, in __init__
    raise InvalidStateError(
homeassistant.exceptions.InvalidStateError: Invalid state encountered for entity ID: sensor.audi_e_tron_sportback_shortterm_trip_user_reset. State max length is 255 characters.

2022-08-10 15:26:06.226 ERROR (MainThread) [homeassistant.util.logging] Exception in async_schedule_update_ha_state when dispatching 'audiconnect.updated': ()
Traceback (most recent call last):
  File "/usr/src/homeassistant/homeassistant/helpers/entity.py", line 677, in async_schedule_update_ha_state
    self.async_write_ha_state()
  File "/usr/src/homeassistant/homeassistant/helpers/entity.py", line 532, in async_write_ha_state
    self._async_write_ha_state()
  File "/usr/src/homeassistant/homeassistant/helpers/entity.py", line 646, in _async_write_ha_state
    self.hass.states.async_set(
  File "/usr/src/homeassistant/homeassistant/core.py", line 1438, in async_set
    state = State(
  File "/usr/src/homeassistant/homeassistant/core.py", line 1099, in __init__
    raise InvalidStateError(
homeassistant.exceptions.InvalidStateError: Invalid state encountered for entity ID: sensor.audi_e_tron_sportback_shortterm_trip_data. State max length is 255 characters.

2022-08-10 15:30:00.039 WARNING (MainThread) [homeassistant.helpers.service] Unable to find referenced entities fan.mi_air or it is/they are currently not available
2022-08-10 15:35:00.019 WARNING (MainThread) [homeassistant.helpers.service] Unable to find referenced entities fan.mi_air or it is/they are currently not available
2022-08-10 15:36:09.785 ERROR (MainThread) [homeassistant.util.logging] Exception in async_schedule_update_ha_state when dispatching 'audiconnect.updated': ()
Traceback (most recent call last):
  File "/usr/src/homeassistant/homeassistant/helpers/entity.py", line 677, in async_schedule_update_ha_state
    self.async_write_ha_state()
  File "/usr/src/homeassistant/homeassistant/helpers/entity.py", line 532, in async_write_ha_state
    self._async_write_ha_state()
  File "/usr/src/homeassistant/homeassistant/helpers/entity.py", line 646, in _async_write_ha_state
    self.hass.states.async_set(
  File "/usr/src/homeassistant/homeassistant/core.py", line 1438, in async_set
    state = State(
  File "/usr/src/homeassistant/homeassistant/core.py", line 1099, in __init__
    raise InvalidStateError(
homeassistant.exceptions.InvalidStateError: Invalid state encountered for entity ID: sensor.audi_e_tron_sportback_shortterm_trip_user_reset. State max length is 255 characters.

2022-08-10 15:36:09.794 ERROR (MainThread) [homeassistant.util.logging] Exception in async_schedule_update_ha_state when dispatching 'audiconnect.updated': ()
Traceback (most recent call last):
  File "/usr/src/homeassistant/homeassistant/helpers/entity.py", line 677, in async_schedule_update_ha_state
    self.async_write_ha_state()
  File "/usr/src/homeassistant/homeassistant/helpers/entity.py", line 532, in async_write_ha_state
    self._async_write_ha_state()
  File "/usr/src/homeassistant/homeassistant/helpers/entity.py", line 646, in _async_write_ha_state
    self.hass.states.async_set(
  File "/usr/src/homeassistant/homeassistant/core.py", line 1438, in async_set
    state = State(
  File "/usr/src/homeassistant/homeassistant/core.py", line 1099, in __init__
    raise InvalidStateError(
homeassistant.exceptions.InvalidStateError: Invalid state encountered for entity ID: sensor.audi_e_tron_sportback_shortterm_trip_data. State max length is 255 characters.

2022-08-10 15:38:23.935 WARNING (SyncWorker_3) [homeassistant.components.waze_travel_time.sensor] Error on retrieving data: empty response
2022-08-10 15:38:44.317 WARNING (Thread-18) [pychromecast.socket_client] [badkamer speaker(192.168.86.170):8009] Heartbeat timeout, resetting connection
2022-08-10 15:39:14.357 ERROR (Thread-18) [pychromecast.socket_client] [badkamer speaker(192.168.86.170):8009] Failed to connect to service ServiceInfo(type='host', data=('192.168.86.170', 8009)), retrying in 5.0s
2022-08-10 15:40:00.019 WARNING (MainThread) [homeassistant.helpers.service] Unable to find referenced entities fan.mi_air or it is/they are currently not available
2022-08-10 15:45:00.047 WARNING (MainThread) [homeassistant.helpers.service] Unable to find referenced entities fan.mi_air or it is/they are currently not available
2022-08-10 15:46:13.673 ERROR (MainThread) [homeassistant.util.logging] Exception in async_schedule_update_ha_state when dispatching 'audiconnect.updated': ()
Traceback (most recent call last):
  File "/usr/src/homeassistant/homeassistant/helpers/entity.py", line 677, in async_schedule_update_ha_state
    self.async_write_ha_state()
  File "/usr/src/homeassistant/homeassistant/helpers/entity.py", line 532, in async_write_ha_state
    self._async_write_ha_state()
  File "/usr/src/homeassistant/homeassistant/helpers/entity.py", line 646, in _async_write_ha_state
    self.hass.states.async_set(
  File "/usr/src/homeassistant/homeassistant/core.py", line 1438, in async_set
    state = State(
  File "/usr/src/homeassistant/homeassistant/core.py", line 1099, in __init__
    raise InvalidStateError(
homeassistant.exceptions.InvalidStateError: Invalid state encountered for entity ID: sensor.audi_e_tron_sportback_shortterm_trip_user_reset. State max length is 255 characters.

2022-08-10 15:46:13.681 ERROR (MainThread) [homeassistant.util.logging] Exception in async_schedule_update_ha_state when dispatching 'audiconnect.updated': ()
Traceback (most recent call last):
  File "/usr/src/homeassistant/homeassistant/helpers/entity.py", line 677, in async_schedule_update_ha_state
    self.async_write_ha_state()
  File "/usr/src/homeassistant/homeassistant/helpers/entity.py", line 532, in async_write_ha_state
    self._async_write_ha_state()
  File "/usr/src/homeassistant/homeassistant/helpers/entity.py", line 646, in _async_write_ha_state
    self.hass.states.async_set(
  File "/usr/src/homeassistant/homeassistant/core.py", line 1438, in async_set
    state = State(
  File "/usr/src/homeassistant/homeassistant/core.py", line 1099, in __init__
    raise InvalidStateError(
homeassistant.exceptions.InvalidStateError: Invalid state encountered for entity ID: sensor.audi_e_tron_sportback_shortterm_trip_data. State max length is 255 characters.

2022-08-10 15:50:00.020 WARNING (MainThread) [homeassistant.helpers.service] Unable to find referenced entities fan.mi_air or it is/they are currently not available
2022-08-10 15:55:00.017 WARNING (MainThread) [homeassistant.helpers.service] Unable to find referenced entities fan.mi_air or it is/they are currently not available
2022-08-10 15:56:17.874 ERROR (MainThread) [homeassistant.util.logging] Exception in async_schedule_update_ha_state when dispatching 'audiconnect.updated': ()
Traceback (most recent call last):
  File "/usr/src/homeassistant/homeassistant/helpers/entity.py", line 677, in async_schedule_update_ha_state
    self.async_write_ha_state()
  File "/usr/src/homeassistant/homeassistant/helpers/entity.py", line 532, in async_write_ha_state
    self._async_write_ha_state()
  File "/usr/src/homeassistant/homeassistant/helpers/entity.py", line 646, in _async_write_ha_state
    self.hass.states.async_set(
  File "/usr/src/homeassistant/homeassistant/core.py", line 1438, in async_set
    state = State(
  File "/usr/src/homeassistant/homeassistant/core.py", line 1099, in __init__
    raise InvalidStateError(
homeassistant.exceptions.InvalidStateError: Invalid state encountered for entity ID: sensor.audi_e_tron_sportback_shortterm_trip_user_reset. State max length is 255 characters.

2022-08-10 15:56:17.884 ERROR (MainThread) [homeassistant.util.logging] Exception in async_schedule_update_ha_state when dispatching 'audiconnect.updated': ()
Traceback (most recent call last):
  File "/usr/src/homeassistant/homeassistant/helpers/entity.py", line 677, in async_schedule_update_ha_state
    self.async_write_ha_state()
  File "/usr/src/homeassistant/homeassistant/helpers/entity.py", line 532, in async_write_ha_state
    self._async_write_ha_state()
  File "/usr/src/homeassistant/homeassistant/helpers/entity.py", line 646, in _async_write_ha_state
    self.hass.states.async_set(
  File "/usr/src/homeassistant/homeassistant/core.py", line 1438, in async_set
    state = State(
  File "/usr/src/homeassistant/homeassistant/core.py", line 1099, in __init__
    raise InvalidStateError(
homeassistant.exceptions.InvalidStateError: Invalid state encountered for entity ID: sensor.audi_e_tron_sportback_shortterm_trip_data. State max length is 255 characters.

2022-08-10 16:00:00.065 WARNING (MainThread) [homeassistant.helpers.service] Unable to find referenced entities fan.mi_air or it is/they are currently not available
2022-08-10 16:05:00.035 WARNING (MainThread) [homeassistant.helpers.service] Unable to find referenced entities fan.mi_air or it is/they are currently not available
2022-08-10 16:06:21.696 ERROR (MainThread) [homeassistant.util.logging] Exception in async_schedule_update_ha_state when dispatching 'audiconnect.updated': ()
Traceback (most recent call last):
  File "/usr/src/homeassistant/homeassistant/helpers/entity.py", line 677, in async_schedule_update_ha_state
    self.async_write_ha_state()
  File "/usr/src/homeassistant/homeassistant/helpers/entity.py", line 532, in async_write_ha_state
    self._async_write_ha_state()
  File "/usr/src/homeassistant/homeassistant/helpers/entity.py", line 646, in _async_write_ha_state
    self.hass.states.async_set(
  File "/usr/src/homeassistant/homeassistant/core.py", line 1438, in async_set
    state = State(
  File "/usr/src/homeassistant/homeassistant/core.py", line 1099, in __init__
    raise InvalidStateError(
homeassistant.exceptions.InvalidStateError: Invalid state encountered for entity ID: sensor.audi_e_tron_sportback_shortterm_trip_user_reset. State max length is 255 characters.

2022-08-10 16:06:21.703 ERROR (MainThread) [homeassistant.util.logging] Exception in async_schedule_update_ha_state when dispatching 'audiconnect.updated': ()
Traceback (most recent call last):
  File "/usr/src/homeassistant/homeassistant/helpers/entity.py", line 677, in async_schedule_update_ha_state
    self.async_write_ha_state()
  File "/usr/src/homeassistant/homeassistant/helpers/entity.py", line 532, in async_write_ha_state
    self._async_write_ha_state()
  File "/usr/src/homeassistant/homeassistant/helpers/entity.py", line 646, in _async_write_ha_state
    self.hass.states.async_set(
  File "/usr/src/homeassistant/homeassistant/core.py", line 1438, in async_set
    state = State(
  File "/usr/src/homeassistant/homeassistant/core.py", line 1099, in __init__
    raise InvalidStateError(
homeassistant.exceptions.InvalidStateError: Invalid state encountered for entity ID: sensor.audi_e_tron_sportback_shortterm_trip_data. State max length is 255 characters.

2022-08-10 16:08:33.759 WARNING (SyncWorker_2) [homeassistant.components.scrape.sensor] Index 'None' not found in sensor.humidity_leuven24_wunderground
2022-08-10 16:08:34.604 WARNING (SyncWorker_11) [homeassistant.components.scrape.sensor] Index 'None' not found in sensor.temp_leuven24_wunderground
2022-08-10 16:08:35.820 WARNING (SyncWorker_8) [homeassistant.components.scrape.sensor] Index 'None' not found in sensor.uvindex_leuven24_wunderground
2022-08-10 16:08:35.893 WARNING (SyncWorker_7) [homeassistant.components.scrape.sensor] Index 'None' not found in sensor.precip_rate_leuven24_wunderground
2022-08-10 16:08:36.137 WARNING (SyncWorker_12) [homeassistant.components.scrape.sensor] Index 'None' not found in sensor.precip_total_leuven24_wunderground
2022-08-10 16:10:00.018 WARNING (MainThread) [homeassistant.helpers.service] Unable to find referenced entities fan.mi_air or it is/they are currently not available
2022-08-10 16:10:45.504 WARNING (MainThread) [homeassistant.components.binary_sensor] Updating ping binary_sensor took longer than the scheduled update interval 0:00:05
2022-08-10 16:11:32.474 WARNING (SyncWorker_1) [homeassistant.components.scrape.sensor] Index 'None' not found in sensor.precip_rate_leuven24_wunderground
2022-08-10 16:12:30.901 WARNING (SyncWorker_13) [homeassistant.components.scrape.sensor] Index 'None' not found in sensor.temp_leuven24_wunderground
2022-08-10 16:12:30.934 WARNING (SyncWorker_2) [homeassistant.components.scrape.sensor] Index 'None' not found in sensor.humidity_leuven24_wunderground
2022-08-10 16:14:35.838 WARNING (SyncWorker_13) [homeassistant.components.scrape.sensor] Index 'None' not found in sensor.precip_rate_leuven24_wunderground
2022-08-10 16:15:00.053 WARNING (MainThread) [homeassistant.helpers.service] Unable to find referenced entities fan.mi_air or it is/they are currently not available
2022-08-10 16:16:25.346 ERROR (MainThread) [homeassistant.util.logging] Exception in async_schedule_update_ha_state when dispatching 'audiconnect.updated': ()
Traceback (most recent call last):
  File "/usr/src/homeassistant/homeassistant/helpers/entity.py", line 677, in async_schedule_update_ha_state
    self.async_write_ha_state()
  File "/usr/src/homeassistant/homeassistant/helpers/entity.py", line 532, in async_write_ha_state
    self._async_write_ha_state()
  File "/usr/src/homeassistant/homeassistant/helpers/entity.py", line 646, in _async_write_ha_state
    self.hass.states.async_set(
  File "/usr/src/homeassistant/homeassistant/core.py", line 1438, in async_set
    state = State(
  File "/usr/src/homeassistant/homeassistant/core.py", line 1099, in __init__
    raise InvalidStateError(
homeassistant.exceptions.InvalidStateError: Invalid state encountered for entity ID: sensor.audi_e_tron_sportback_shortterm_trip_user_reset. State max length is 255 characters.

2022-08-10 16:16:25.354 ERROR (MainThread) [homeassistant.util.logging] Exception in async_schedule_update_ha_state when dispatching 'audiconnect.updated': ()
Traceback (most recent call last):
  File "/usr/src/homeassistant/homeassistant/helpers/entity.py", line 677, in async_schedule_update_ha_state
    self.async_write_ha_state()
  File "/usr/src/homeassistant/homeassistant/helpers/entity.py", line 532, in async_write_ha_state
    self._async_write_ha_state()
  File "/usr/src/homeassistant/homeassistant/helpers/entity.py", line 646, in _async_write_ha_state
    self.hass.states.async_set(
  File "/usr/src/homeassistant/homeassistant/core.py", line 1438, in async_set
    state = State(
  File "/usr/src/homeassistant/homeassistant/core.py", line 1099, in __init__
    raise InvalidStateError(
homeassistant.exceptions.InvalidStateError: Invalid state encountered for entity ID: sensor.audi_e_tron_sportback_shortterm_trip_data. State max length is 255 characters.

2022-08-10 16:16:30.937 WARNING (SyncWorker_9) [homeassistant.components.scrape.sensor] Index 'None' not found in sensor.humidity_leuven24_wunderground
2022-08-10 16:16:30.971 WARNING (SyncWorker_7) [homeassistant.components.scrape.sensor] Index 'None' not found in sensor.temp_leuven24_wunderground
2022-08-10 16:17:32.520 WARNING (SyncWorker_11) [homeassistant.components.scrape.sensor] Index 'None' not found in sensor.precip_rate_leuven24_wunderground
2022-08-10 16:18:32.729 WARNING (SyncWorker_12) [homeassistant.components.scrape.sensor] Index 'None' not found in sensor.uvindex_leuven24_wunderground
2022-08-10 16:18:32.771 WARNING (SyncWorker_13) [homeassistant.components.scrape.sensor] Index 'None' not found in sensor.precip_total_leuven24_wunderground
2022-08-10 16:20:00.018 WARNING (MainThread) [homeassistant.helpers.service] Unable to find referenced entities fan.mi_air or it is/they are currently not available
2022-08-10 16:25:00.016 WARNING (MainThread) [homeassistant.helpers.service] Unable to find referenced entities fan.mi_air or it is/they are currently not available
2022-08-10 16:26:29.435 ERROR (MainThread) [homeassistant.util.logging] Exception in async_schedule_update_ha_state when dispatching 'audiconnect.updated': ()
Traceback (most recent call last):
  File "/usr/src/homeassistant/homeassistant/helpers/entity.py", line 677, in async_schedule_update_ha_state
    self.async_write_ha_state()
  File "/usr/src/homeassistant/homeassistant/helpers/entity.py", line 532, in async_write_ha_state
    self._async_write_ha_state()
  File "/usr/src/homeassistant/homeassistant/helpers/entity.py", line 646, in _async_write_ha_state
    self.hass.states.async_set(
  File "/usr/src/homeassistant/homeassistant/core.py", line 1438, in async_set
    state = State(
  File "/usr/src/homeassistant/homeassistant/core.py", line 1099, in __init__
    raise InvalidStateError(
homeassistant.exceptions.InvalidStateError: Invalid state encountered for entity ID: sensor.audi_e_tron_sportback_shortterm_trip_user_reset. State max length is 255 characters.

2022-08-10 16:26:29.444 ERROR (MainThread) [homeassistant.util.logging] Exception in async_schedule_update_ha_state when dispatching 'audiconnect.updated': ()
Traceback (most recent call last):
  File "/usr/src/homeassistant/homeassistant/helpers/entity.py", line 677, in async_schedule_update_ha_state
    self.async_write_ha_state()
  File "/usr/src/homeassistant/homeassistant/helpers/entity.py", line 532, in async_write_ha_state
    self._async_write_ha_state()
  File "/usr/src/homeassistant/homeassistant/helpers/entity.py", line 646, in _async_write_ha_state
    self.hass.states.async_set(
  File "/usr/src/homeassistant/homeassistant/core.py", line 1438, in async_set
    state = State(
  File "/usr/src/homeassistant/homeassistant/core.py", line 1099, in __init__
    raise InvalidStateError(
homeassistant.exceptions.InvalidStateError: Invalid state encountered for entity ID: sensor.audi_e_tron_sportback_shortterm_trip_data. State max length is 255 characters.

2022-08-10 16:30:00.038 WARNING (MainThread) [homeassistant.helpers.service] Unable to find referenced entities fan.mi_air or it is/they are currently not available
2022-08-10 16:35:00.018 WARNING (MainThread) [homeassistant.helpers.service] Unable to find referenced entities fan.mi_air or it is/they are currently not available
2022-08-10 16:36:33.603 ERROR (MainThread) [homeassistant.util.logging] Exception in async_schedule_update_ha_state when dispatching 'audiconnect.updated': ()
Traceback (most recent call last):
  File "/usr/src/homeassistant/homeassistant/helpers/entity.py", line 677, in async_schedule_update_ha_state
    self.async_write_ha_state()
  File "/usr/src/homeassistant/homeassistant/helpers/entity.py", line 532, in async_write_ha_state
    self._async_write_ha_state()
  File "/usr/src/homeassistant/homeassistant/helpers/entity.py", line 646, in _async_write_ha_state
    self.hass.states.async_set(
  File "/usr/src/homeassistant/homeassistant/core.py", line 1438, in async_set
    state = State(
  File "/usr/src/homeassistant/homeassistant/core.py", line 1099, in __init__
    raise InvalidStateError(
homeassistant.exceptions.InvalidStateError: Invalid state encountered for entity ID: sensor.audi_e_tron_sportback_shortterm_trip_user_reset. State max length is 255 characters.

2022-08-10 16:36:33.610 ERROR (MainThread) [homeassistant.util.logging] Exception in async_schedule_update_ha_state when dispatching 'audiconnect.updated': ()
Traceback (most recent call last):
  File "/usr/src/homeassistant/homeassistant/helpers/entity.py", line 677, in async_schedule_update_ha_state
    self.async_write_ha_state()
  File "/usr/src/homeassistant/homeassistant/helpers/entity.py", line 532, in async_write_ha_state
    self._async_write_ha_state()
  File "/usr/src/homeassistant/homeassistant/helpers/entity.py", line 646, in _async_write_ha_state
    self.hass.states.async_set(
  File "/usr/src/homeassistant/homeassistant/core.py", line 1438, in async_set
    state = State(
  File "/usr/src/homeassistant/homeassistant/core.py", line 1099, in __init__
    raise InvalidStateError(
homeassistant.exceptions.InvalidStateError: Invalid state encountered for entity ID: sensor.audi_e_tron_sportback_shortterm_trip_data. State max length is 255 characters.

2022-08-10 16:38:25.173 WARNING (SyncWorker_0) [homeassistant.components.waze_travel_time.sensor] Error on retrieving data: empty response
2022-08-10 16:40:00.026 WARNING (MainThread) [homeassistant.helpers.service] Unable to find referenced entities fan.mi_air or it is/they are currently not available
2022-08-10 16:43:25.154 WARNING (SyncWorker_10) [homeassistant.components.waze_travel_time.sensor] Error on retrieving data: empty response
2022-08-10 16:45:00.054 WARNING (MainThread) [homeassistant.helpers.service] Unable to find referenced entities fan.mi_air or it is/they are currently not available
2022-08-10 16:46:37.526 ERROR (MainThread) [homeassistant.util.logging] Exception in async_schedule_update_ha_state when dispatching 'audiconnect.updated': ()
Traceback (most recent call last):
  File "/usr/src/homeassistant/homeassistant/helpers/entity.py", line 677, in async_schedule_update_ha_state
    self.async_write_ha_state()
  File "/usr/src/homeassistant/homeassistant/helpers/entity.py", line 532, in async_write_ha_state
    self._async_write_ha_state()
  File "/usr/src/homeassistant/homeassistant/helpers/entity.py", line 646, in _async_write_ha_state
    self.hass.states.async_set(
  File "/usr/src/homeassistant/homeassistant/core.py", line 1438, in async_set
    state = State(
  File "/usr/src/homeassistant/homeassistant/core.py", line 1099, in __init__
    raise InvalidStateError(
homeassistant.exceptions.InvalidStateError: Invalid state encountered for entity ID: sensor.audi_e_tron_sportback_shortterm_trip_user_reset. State max length is 255 characters.

2022-08-10 16:46:37.534 ERROR (MainThread) [homeassistant.util.logging] Exception in async_schedule_update_ha_state when dispatching 'audiconnect.updated': ()
Traceback (most recent call last):
  File "/usr/src/homeassistant/homeassistant/helpers/entity.py", line 677, in async_schedule_update_ha_state
    self.async_write_ha_state()
  File "/usr/src/homeassistant/homeassistant/helpers/entity.py", line 532, in async_write_ha_state
    self._async_write_ha_state()
  File "/usr/src/homeassistant/homeassistant/helpers/entity.py", line 646, in _async_write_ha_state
    self.hass.states.async_set(
  File "/usr/src/homeassistant/homeassistant/core.py", line 1438, in async_set
    state = State(
  File "/usr/src/homeassistant/homeassistant/core.py", line 1099, in __init__
    raise InvalidStateError(
homeassistant.exceptions.InvalidStateError: Invalid state encountered for entity ID: sensor.audi_e_tron_sportback_shortterm_trip_data. State max length is 255 characters.

2022-08-10 16:48:25.430 WARNING (SyncWorker_8) [homeassistant.components.waze_travel_time.sensor] Error on retrieving data: empty response
2022-08-10 16:49:02.430 WARNING (MainThread) [homeassistant.components.binary_sensor] Updating ping binary_sensor took longer than the scheduled update interval 0:00:05
2022-08-10 16:50:00.023 WARNING (MainThread) [homeassistant.helpers.service] Unable to find referenced entities fan.mi_air or it is/they are currently not available
2022-08-10 16:53:07.478 WARNING (MainThread) [homeassistant.components.binary_sensor] Updating ping binary_sensor took longer than the scheduled update interval 0:00:05
2022-08-10 16:53:25.519 WARNING (SyncWorker_8) [homeassistant.components.waze_travel_time.sensor] Error on retrieving data: empty response
2022-08-10 16:55:00.027 WARNING (MainThread) [homeassistant.helpers.service] Unable to find referenced entities fan.mi_air or it is/they are currently not available
2022-08-10 16:56:32.522 WARNING (MainThread) [homeassistant.components.binary_sensor] Updating ping binary_sensor took longer than the scheduled update interval 0:00:05
2022-08-10 16:56:39.792 ERROR (MainThread) [custom_components.audiconnect.audi_connect_account] Login to Audi service failed, trying again in 10 seconds
2022-08-10 16:56:52.813 ERROR (MainThread) [homeassistant.util.logging] Exception in async_schedule_update_ha_state when dispatching 'audiconnect.updated': ()
Traceback (most recent call last):
  File "/usr/src/homeassistant/homeassistant/helpers/entity.py", line 677, in async_schedule_update_ha_state
    self.async_write_ha_state()
  File "/usr/src/homeassistant/homeassistant/helpers/entity.py", line 532, in async_write_ha_state
    self._async_write_ha_state()
  File "/usr/src/homeassistant/homeassistant/helpers/entity.py", line 646, in _async_write_ha_state
    self.hass.states.async_set(
  File "/usr/src/homeassistant/homeassistant/core.py", line 1438, in async_set
    state = State(
  File "/usr/src/homeassistant/homeassistant/core.py", line 1099, in __init__
    raise InvalidStateError(
homeassistant.exceptions.InvalidStateError: Invalid state encountered for entity ID: sensor.audi_e_tron_sportback_shortterm_trip_user_reset. State max length is 255 characters.

2022-08-10 16:56:52.822 ERROR (MainThread) [homeassistant.util.logging] Exception in async_schedule_update_ha_state when dispatching 'audiconnect.updated': ()
Traceback (most recent call last):
  File "/usr/src/homeassistant/homeassistant/helpers/entity.py", line 677, in async_schedule_update_ha_state
    self.async_write_ha_state()
  File "/usr/src/homeassistant/homeassistant/helpers/entity.py", line 532, in async_write_ha_state
    self._async_write_ha_state()
  File "/usr/src/homeassistant/homeassistant/helpers/entity.py", line 646, in _async_write_ha_state
    self.hass.states.async_set(
  File "/usr/src/homeassistant/homeassistant/core.py", line 1438, in async_set
    state = State(
  File "/usr/src/homeassistant/homeassistant/core.py", line 1099, in __init__
    raise InvalidStateError(
homeassistant.exceptions.InvalidStateError: Invalid state encountered for entity ID: sensor.audi_e_tron_sportback_shortterm_trip_data. State max length is 255 characters.

2022-08-10 16:57:37.537 WARNING (MainThread) [homeassistant.components.binary_sensor] Updating ping binary_sensor took longer than the scheduled update interval 0:00:05
2022-08-10 17:00:00.069 WARNING (MainThread) [homeassistant.helpers.service] Unable to find referenced entities fan.mi_air or it is/they are currently not available
2022-08-10 17:00:42.574 WARNING (MainThread) [homeassistant.components.binary_sensor] Updating ping binary_sensor took longer than the scheduled update interval 0:00:05
2022-08-10 17:03:22.365 ERROR (MainThread) [custom_components.audiconnect.util] Unable to lock wauzzzge6mb019131: Cannot lock vehicle, operation timed out
2022-08-10 17:05:00.027 WARNING (MainThread) [homeassistant.helpers.service] Unable to find referenced entities fan.mi_air or it is/they are currently not available
2022-08-10 17:06:42.062 WARNING (MainThread) [haffmpeg.tools] Timeout reading image.
2022-08-10 17:06:52.350 WARNING (MainThread) [haffmpeg.tools] Timeout reading image.
2022-08-10 17:06:53.968 ERROR (MainThread) [homeassistant.util.logging] Exception in async_schedule_update_ha_state when dispatching 'audiconnect.updated': ()
Traceback (most recent call last):
  File "/usr/src/homeassistant/homeassistant/helpers/entity.py", line 677, in async_schedule_update_ha_state
    self.async_write_ha_state()
  File "/usr/src/homeassistant/homeassistant/helpers/entity.py", line 532, in async_write_ha_state
    self._async_write_ha_state()
  File "/usr/src/homeassistant/homeassistant/helpers/entity.py", line 646, in _async_write_ha_state
    self.hass.states.async_set(
  File "/usr/src/homeassistant/homeassistant/core.py", line 1438, in async_set
    state = State(
  File "/usr/src/homeassistant/homeassistant/core.py", line 1099, in __init__
    raise InvalidStateError(
homeassistant.exceptions.InvalidStateError: Invalid state encountered for entity ID: sensor.audi_e_tron_sportback_shortterm_trip_user_reset. State max length is 255 characters.

2022-08-10 17:06:53.975 ERROR (MainThread) [homeassistant.util.logging] Exception in async_schedule_update_ha_state when dispatching 'audiconnect.updated': ()
Traceback (most recent call last):
  File "/usr/src/homeassistant/homeassistant/helpers/entity.py", line 677, in async_schedule_update_ha_state
    self.async_write_ha_state()
  File "/usr/src/homeassistant/homeassistant/helpers/entity.py", line 532, in async_write_ha_state
    self._async_write_ha_state()
  File "/usr/src/homeassistant/homeassistant/helpers/entity.py", line 646, in _async_write_ha_state
    self.hass.states.async_set(
  File "/usr/src/homeassistant/homeassistant/core.py", line 1438, in async_set
    state = State(
  File "/usr/src/homeassistant/homeassistant/core.py", line 1099, in __init__
    raise InvalidStateError(
homeassistant.exceptions.InvalidStateError: Invalid state encountered for entity ID: sensor.audi_e_tron_sportback_shortterm_trip_data. State max length is 255 characters.

2022-08-10 17:07:02.462 WARNING (MainThread) [haffmpeg.tools] Timeout reading image.
2022-08-10 17:07:14.914 WARNING (MainThread) [haffmpeg.tools] Timeout reading image.
2022-08-10 17:07:26.606 WARNING (MainThread) [haffmpeg.tools] Timeout reading image.
2022-08-10 17:07:36.590 WARNING (MainThread) [haffmpeg.tools] Timeout reading image.
2022-08-10 17:07:46.658 WARNING (MainThread) [haffmpeg.tools] Timeout reading image.
2022-08-10 17:07:56.846 WARNING (MainThread) [haffmpeg.tools] Timeout reading image.
2022-08-10 17:08:08.010 WARNING (MainThread) [haffmpeg.tools] Timeout reading image.
2022-08-10 17:08:18.027 WARNING (MainThread) [haffmpeg.tools] Timeout reading image.
2022-08-10 17:08:28.380 WARNING (MainThread) [haffmpeg.tools] Timeout reading image.
2022-08-10 17:08:37.675 WARNING (MainThread) [homeassistant.components.binary_sensor] Updating ping binary_sensor took longer than the scheduled update interval 0:00:05
2022-08-10 17:08:43.565 WARNING (MainThread) [haffmpeg.tools] Timeout reading image.
2022-08-10 17:09:09.623 WARNING (MainThread) [haffmpeg.tools] Timeout reading image.
2022-08-10 17:09:21.121 WARNING (MainThread) [haffmpeg.tools] Timeout reading image.
2022-08-10 17:09:33.377 WARNING (MainThread) [haffmpeg.tools] Timeout reading image.
2022-08-10 17:09:43.590 WARNING (MainThread) [haffmpeg.tools] Timeout reading image.
2022-08-10 17:09:57.450 WARNING (MainThread) [haffmpeg.tools] Timeout reading image.
2022-08-10 17:10:00.042 WARNING (MainThread) [homeassistant.helpers.service] Unable to find referenced entities fan.mi_air or it is/they are currently not available
2022-08-10 17:10:25.878 WARNING (MainThread) [haffmpeg.tools] Timeout reading image.
2022-08-10 17:10:35.726 WARNING (MainThread) [haffmpeg.tools] Timeout reading image.
2022-08-10 17:10:45.731 WARNING (MainThread) [haffmpeg.tools] Timeout reading image.
2022-08-10 17:10:57.718 WARNING (MainThread) [homeassistant.components.binary_sensor] Updating ping binary_sensor took longer than the scheduled update interval 0:00:05
2022-08-10 17:11:05.779 WARNING (MainThread) [haffmpeg.tools] Timeout reading image.
2022-08-10 17:11:07.721 WARNING (MainThread) [homeassistant.components.binary_sensor] Updating ping binary_sensor took longer than the scheduled update interval 0:00:05
2022-08-10 17:11:15.788 WARNING (MainThread) [haffmpeg.tools] Timeout reading image.
2022-08-10 17:11:26.654 WARNING (MainThread) [haffmpeg.tools] Timeout reading image.
2022-08-10 17:11:39.520 WARNING (MainThread) [haffmpeg.tools] Timeout reading image.
2022-08-10 17:15:00.059 WARNING (MainThread) [homeassistant.helpers.service] Unable to find referenced entities fan.mi_air or it is/they are currently not available
2022-08-10 17:16:57.835 ERROR (MainThread) [homeassistant.util.logging] Exception in async_schedule_update_ha_state when dispatching 'audiconnect.updated': ()
Traceback (most recent call last):
  File "/usr/src/homeassistant/homeassistant/helpers/entity.py", line 677, in async_schedule_update_ha_state
    self.async_write_ha_state()
  File "/usr/src/homeassistant/homeassistant/helpers/entity.py", line 532, in async_write_ha_state
    self._async_write_ha_state()
  File "/usr/src/homeassistant/homeassistant/helpers/entity.py", line 646, in _async_write_ha_state
    self.hass.states.async_set(
  File "/usr/src/homeassistant/homeassistant/core.py", line 1438, in async_set
    state = State(
  File "/usr/src/homeassistant/homeassistant/core.py", line 1099, in __init__
    raise InvalidStateError(
homeassistant.exceptions.InvalidStateError: Invalid state encountered for entity ID: sensor.audi_e_tron_sportback_shortterm_trip_user_reset. State max length is 255 characters.

2022-08-10 17:16:57.842 ERROR (MainThread) [homeassistant.util.logging] Exception in async_schedule_update_ha_state when dispatching 'audiconnect.updated': ()
Traceback (most recent call last):
  File "/usr/src/homeassistant/homeassistant/helpers/entity.py", line 677, in async_schedule_update_ha_state
    self.async_write_ha_state()
  File "/usr/src/homeassistant/homeassistant/helpers/entity.py", line 532, in async_write_ha_state
    self._async_write_ha_state()
  File "/usr/src/homeassistant/homeassistant/helpers/entity.py", line 646, in _async_write_ha_state
    self.hass.states.async_set(
  File "/usr/src/homeassistant/homeassistant/core.py", line 1438, in async_set
    state = State(
  File "/usr/src/homeassistant/homeassistant/core.py", line 1099, in __init__
    raise InvalidStateError(
homeassistant.exceptions.InvalidStateError: Invalid state encountered for entity ID: sensor.audi_e_tron_sportback_shortterm_trip_data. State max length is 255 characters.

2022-08-10 17:20:00.034 WARNING (MainThread) [homeassistant.helpers.service] Unable to find referenced entities fan.mi_air or it is/they are currently not available
2022-08-10 17:24:32.892 WARNING (MainThread) [homeassistant.components.binary_sensor] Updating ping binary_sensor took longer than the scheduled update interval 0:00:05
2022-08-10 17:25:00.019 WARNING (MainThread) [homeassistant.helpers.service] Unable to find referenced entities fan.mi_air or it is/they are currently not available
2022-08-10 17:27:01.692 ERROR (MainThread) [homeassistant.util.logging] Exception in async_schedule_update_ha_state when dispatching 'audiconnect.updated': ()
Traceback (most recent call last):
  File "/usr/src/homeassistant/homeassistant/helpers/entity.py", line 677, in async_schedule_update_ha_state
    self.async_write_ha_state()
  File "/usr/src/homeassistant/homeassistant/helpers/entity.py", line 532, in async_write_ha_state
    self._async_write_ha_state()
  File "/usr/src/homeassistant/homeassistant/helpers/entity.py", line 646, in _async_write_ha_state
    self.hass.states.async_set(
  File "/usr/src/homeassistant/homeassistant/core.py", line 1438, in async_set
    state = State(
  File "/usr/src/homeassistant/homeassistant/core.py", line 1099, in __init__
    raise InvalidStateError(
homeassistant.exceptions.InvalidStateError: Invalid state encountered for entity ID: sensor.audi_e_tron_sportback_shortterm_trip_user_reset. State max length is 255 characters.

2022-08-10 17:27:01.700 ERROR (MainThread) [homeassistant.util.logging] Exception in async_schedule_update_ha_state when dispatching 'audiconnect.updated': ()
Traceback (most recent call last):
  File "/usr/src/homeassistant/homeassistant/helpers/entity.py", line 677, in async_schedule_update_ha_state
    self.async_write_ha_state()
  File "/usr/src/homeassistant/homeassistant/helpers/entity.py", line 532, in async_write_ha_state
    self._async_write_ha_state()
  File "/usr/src/homeassistant/homeassistant/helpers/entity.py", line 646, in _async_write_ha_state
    self.hass.states.async_set(
  File "/usr/src/homeassistant/homeassistant/core.py", line 1438, in async_set
    state = State(
  File "/usr/src/homeassistant/homeassistant/core.py", line 1099, in __init__
    raise InvalidStateError(
homeassistant.exceptions.InvalidStateError: Invalid state encountered for entity ID: sensor.audi_e_tron_sportback_shortterm_trip_data. State max length is 255 characters.

2022-08-10 17:28:25.165 WARNING (SyncWorker_9) [homeassistant.components.waze_travel_time.sensor] Error on retrieving data: empty response
2022-08-10 17:30:00.058 WARNING (MainThread) [homeassistant.helpers.service] Unable to find referenced entities fan.mi_air or it is/they are currently not available
2022-08-10 17:35:00.045 WARNING (MainThread) [homeassistant.helpers.service] Unable to find referenced entities fan.mi_air or it is/they are currently not available
2022-08-10 17:37:05.476 ERROR (MainThread) [homeassistant.util.logging] Exception in async_schedule_update_ha_state when dispatching 'audiconnect.updated': ()
Traceback (most recent call last):
  File "/usr/src/homeassistant/homeassistant/helpers/entity.py", line 677, in async_schedule_update_ha_state
    self.async_write_ha_state()
  File "/usr/src/homeassistant/homeassistant/helpers/entity.py", line 532, in async_write_ha_state
    self._async_write_ha_state()
  File "/usr/src/homeassistant/homeassistant/helpers/entity.py", line 646, in _async_write_ha_state
    self.hass.states.async_set(
  File "/usr/src/homeassistant/homeassistant/core.py", line 1438, in async_set
    state = State(
  File "/usr/src/homeassistant/homeassistant/core.py", line 1099, in __init__
    raise InvalidStateError(
homeassistant.exceptions.InvalidStateError: Invalid state encountered for entity ID: sensor.audi_e_tron_sportback_shortterm_trip_user_reset. State max length is 255 characters.

2022-08-10 17:37:05.490 ERROR (MainThread) [homeassistant.util.logging] Exception in async_schedule_update_ha_state when dispatching 'audiconnect.updated': ()
Traceback (most recent call last):
  File "/usr/src/homeassistant/homeassistant/helpers/entity.py", line 677, in async_schedule_update_ha_state
    self.async_write_ha_state()
  File "/usr/src/homeassistant/homeassistant/helpers/entity.py", line 532, in async_write_ha_state
    self._async_write_ha_state()
  File "/usr/src/homeassistant/homeassistant/helpers/entity.py", line 646, in _async_write_ha_state
    self.hass.states.async_set(
  File "/usr/src/homeassistant/homeassistant/core.py", line 1438, in async_set
    state = State(
  File "/usr/src/homeassistant/homeassistant/core.py", line 1099, in __init__
    raise InvalidStateError(
homeassistant.exceptions.InvalidStateError: Invalid state encountered for entity ID: sensor.audi_e_tron_sportback_shortterm_trip_data. State max length is 255 characters.

2022-08-10 17:40:00.036 WARNING (MainThread) [homeassistant.helpers.service] Unable to find referenced entities fan.mi_air or it is/they are currently not available
2022-08-10 17:40:33.155 WARNING (MainThread) [homeassistant.components.binary_sensor] Updating ping binary_sensor took longer than the scheduled update interval 0:00:05
2022-08-10 17:43:25.185 WARNING (SyncWorker_2) [homeassistant.components.waze_travel_time.sensor] Error on retrieving data: empty response
2022-08-10 17:45:00.044 WARNING (MainThread) [homeassistant.helpers.service] Unable to find referenced entities fan.mi_air or it is/they are currently not available
2022-08-10 17:47:09.199 ERROR (MainThread) [homeassistant.util.logging] Exception in async_schedule_update_ha_state when dispatching 'audiconnect.updated': ()
Traceback (most recent call last):
  File "/usr/src/homeassistant/homeassistant/helpers/entity.py", line 677, in async_schedule_update_ha_state
    self.async_write_ha_state()
  File "/usr/src/homeassistant/homeassistant/helpers/entity.py", line 532, in async_write_ha_state
    self._async_write_ha_state()
  File "/usr/src/homeassistant/homeassistant/helpers/entity.py", line 646, in _async_write_ha_state
    self.hass.states.async_set(
  File "/usr/src/homeassistant/homeassistant/core.py", line 1438, in async_set
    state = State(
  File "/usr/src/homeassistant/homeassistant/core.py", line 1099, in __init__
    raise InvalidStateError(
homeassistant.exceptions.InvalidStateError: Invalid state encountered for entity ID: sensor.audi_e_tron_sportback_shortterm_trip_user_reset. State max length is 255 characters.

2022-08-10 17:47:09.209 ERROR (MainThread) [homeassistant.util.logging] Exception in async_schedule_update_ha_state when dispatching 'audiconnect.updated': ()
Traceback (most recent call last):
  File "/usr/src/homeassistant/homeassistant/helpers/entity.py", line 677, in async_schedule_update_ha_state
    self.async_write_ha_state()
  File "/usr/src/homeassistant/homeassistant/helpers/entity.py", line 532, in async_write_ha_state
    self._async_write_ha_state()
  File "/usr/src/homeassistant/homeassistant/helpers/entity.py", line 646, in _async_write_ha_state
    self.hass.states.async_set(
  File "/usr/src/homeassistant/homeassistant/core.py", line 1438, in async_set
    state = State(
  File "/usr/src/homeassistant/homeassistant/core.py", line 1099, in __init__
    raise InvalidStateError(
homeassistant.exceptions.InvalidStateError: Invalid state encountered for entity ID: sensor.audi_e_tron_sportback_shortterm_trip_data. State max length is 255 characters.

2022-08-10 17:50:00.019 WARNING (MainThread) [homeassistant.helpers.service] Unable to find referenced entities fan.mi_air or it is/they are currently not available
2022-08-10 17:50:40.336 WARNING (MainThread) [homeassistant.components.modbus.modbus] modbus charger communication closed
2022-08-10 17:50:45.639 ERROR (MainThread) [homeassistant] Error doing job: Task exception was never retrieved
Traceback (most recent call last):
  File "/usr/local/lib/python3.10/site-packages/aiohttp/connector.py", line 1154, in _create_direct_connection
    hosts = await asyncio.shield(host_resolved)
  File "/usr/local/lib/python3.10/site-packages/aiohttp/connector.py", line 880, in _resolve_host
    addrs = await self._resolver.resolve(host, port, family=self._family)
  File "/usr/local/lib/python3.10/site-packages/aiohttp/resolver.py", line 33, in resolve
    infos = await self._loop.getaddrinfo(
  File "/usr/local/lib/python3.10/asyncio/base_events.py", line 860, in getaddrinfo
    return await self.run_in_executor(
  File "/usr/local/lib/python3.10/concurrent/futures/thread.py", line 58, in run
    result = self.fn(*self.args, **self.kwargs)
  File "/usr/local/lib/python3.10/socket.py", line 955, in getaddrinfo
    for res in _socket.getaddrinfo(host, port, family, type, proto, flags):
socket.gaierror: [Errno -3] Try again

The above exception was the direct cause of the following exception:

Traceback (most recent call last):
  File "/usr/src/homeassistant/homeassistant/components/netatmo/__init__.py", line 171, in unregister_webhook
    await hass.data[DOMAIN][entry.entry_id][AUTH].async_dropwebhook()
  File "/usr/local/lib/python3.10/site-packages/pyatmo/auth.py", line 382, in async_dropwebhook
    resp = await self.async_post_request(
  File "/usr/local/lib/python3.10/site-packages/pyatmo/auth.py", line 335, in async_post_request
    async with self.websession.post(
  File "/usr/local/lib/python3.10/site-packages/aiohttp/client.py", line 1138, in __aenter__
    self._resp = await self._coro
  File "/usr/local/lib/python3.10/site-packages/aiohttp/client.py", line 535, in _request
    conn = await self._connector.connect(
  File "/usr/local/lib/python3.10/site-packages/aiohttp/connector.py", line 542, in connect
    proto = await self._create_connection(req, traces, timeout)
  File "/usr/local/lib/python3.10/site-packages/aiohttp/connector.py", line 907, in _create_connection
    _, proto = await self._create_direct_connection(req, traces, timeout)
  File "/usr/local/lib/python3.10/site-packages/aiohttp/connector.py", line 1166, in _create_direct_connection
    raise ClientConnectorError(req.connection_key, exc) from exc
aiohttp.client_exceptions.ClientConnectorError: Cannot connect to host api.netatmo.com:443 ssl:default [Try again]
2022-08-10 17:50:45.745 ERROR (MainThread) [homeassistant.components.mobile_app.notify] Error sending notification to https://mobile-apps.home-assistant.io/api/sendPush/android/v1: ClientConnectorError(ConnectionKey(host='mobile-apps.home-assistant.io', port=443, is_ssl=True, ssl=None, proxy=None, proxy_auth=None, proxy_headers_hash=-5418713189934101905), gaierror(-3, 'Try again'))
