2021-10-07 06:57:44 WARNING (SyncWorker_4) [homeassistant.loader] We found a custom integration monitor_docker which has not been tested by Home Assistant. This component might cause stability problems, be sure to disable it if you experience issues with Home Assistant
2021-10-07 06:57:44 WARNING (SyncWorker_2) [homeassistant.loader] We found a custom integration audiconnect which has not been tested by Home Assistant. This component might cause stability problems, be sure to disable it if you experience issues with Home Assistant
2021-10-07 06:57:44 WARNING (SyncWorker_1) [homeassistant.loader] We found a custom integration xiaomi_miio_airpurifier which has not been tested by Home Assistant. This component might cause stability problems, be sure to disable it if you experience issues with Home Assistant
2021-10-07 06:57:44 WARNING (SyncWorker_0) [homeassistant.loader] We found a custom integration average which has not been tested by Home Assistant. This component might cause stability problems, be sure to disable it if you experience issues with Home Assistant
2021-10-07 06:57:44 WARNING (SyncWorker_5) [homeassistant.loader] We found a custom integration hacs which has not been tested by Home Assistant. This component might cause stability problems, be sure to disable it if you experience issues with Home Assistant
2021-10-07 06:57:44 WARNING (SyncWorker_3) [homeassistant.loader] We found a custom integration powercalc which has not been tested by Home Assistant. This component might cause stability problems, be sure to disable it if you experience issues with Home Assistant
2021-10-07 06:57:44 WARNING (SyncWorker_4) [homeassistant.loader] We found a custom integration xiaomi_miio_fan which has not been tested by Home Assistant. This component might cause stability problems, be sure to disable it if you experience issues with Home Assistant
2021-10-07 06:57:44 WARNING (SyncWorker_0) [homeassistant.loader] We found a custom integration tuya_v2 which has not been tested by Home Assistant. This component might cause stability problems, be sure to disable it if you experience issues with Home Assistant
2021-10-07 06:57:44 WARNING (SyncWorker_5) [homeassistant.loader] We found a custom integration huesyncbox which has not been tested by Home Assistant. This component might cause stability problems, be sure to disable it if you experience issues with Home Assistant
2021-10-07 06:57:44 WARNING (SyncWorker_3) [homeassistant.loader] We found a custom integration buienalarm which has not been tested by Home Assistant. This component might cause stability problems, be sure to disable it if you experience issues with Home Assistant
2021-10-07 06:57:44 WARNING (SyncWorker_6) [homeassistant.loader] We found a custom integration localtuya which has not been tested by Home Assistant. This component might cause stability problems, be sure to disable it if you experience issues with Home Assistant
2021-10-07 06:57:44 WARNING (SyncWorker_5) [homeassistant.loader] We found a custom integration anniversaries which has not been tested by Home Assistant. This component might cause stability problems, be sure to disable it if you experience issues with Home Assistant
2021-10-07 06:57:44 WARNING (SyncWorker_8) [homeassistant.loader] We found a custom integration shelly which has not been tested by Home Assistant. This component might cause stability problems, be sure to disable it if you experience issues with Home Assistant
2021-10-07 06:57:44 WARNING (SyncWorker_10) [homeassistant.loader] We found a custom integration googlewifi which has not been tested by Home Assistant. This component might cause stability problems, be sure to disable it if you experience issues with Home Assistant
2021-10-07 06:57:44 WARNING (SyncWorker_7) [homeassistant.loader] We found a custom integration thermal_comfort which has not been tested by Home Assistant. This component might cause stability problems, be sure to disable it if you experience issues with Home Assistant
2021-10-07 06:57:44 WARNING (SyncWorker_9) [homeassistant.loader] We found a custom integration xiaomi_miot which has not been tested by Home Assistant. This component might cause stability problems, be sure to disable it if you experience issues with Home Assistant
2021-10-07 06:57:45 WARNING (SyncWorker_1) [homeassistant.loader] We found a custom integration deepstack_face which has not been tested by Home Assistant. This component might cause stability problems, be sure to disable it if you experience issues with Home Assistant
2021-10-07 06:57:45 WARNING (SyncWorker_4) [homeassistant.loader] We found a custom integration afvalbeheer which has not been tested by Home Assistant. This component might cause stability problems, be sure to disable it if you experience issues with Home Assistant
2021-10-07 06:57:45 WARNING (SyncWorker_0) [homeassistant.loader] We found a custom integration ytube_music_player which has not been tested by Home Assistant. This component might cause stability problems, be sure to disable it if you experience issues with Home Assistant
2021-10-07 06:57:45 WARNING (SyncWorker_2) [homeassistant.loader] We found a custom integration google_home which has not been tested by Home Assistant. This component might cause stability problems, be sure to disable it if you experience issues with Home Assistant
2021-10-07 06:57:54 ERROR (MainThread) [homeassistant.config] Invalid config for [automation]: required key not provided @ data['action'][4]['domain']. Got None. (See ?, line ?). 
2021-10-07 06:57:54 ERROR (MainThread) [homeassistant.config] Invalid config for [automation]: [title] is an invalid option for [automation]. Check: automation->action->1->title. (See ?, line ?). 
2021-10-07 06:57:54 ERROR (MainThread) [homeassistant.config] Invalid config for [automation]: must be a value between 0 and 59 for dictionary value @ data['minutes']. Got None. (See ?, line ?). 
2021-10-07 06:57:54 ERROR (MainThread) [homeassistant.config] Invalid config for [automation]: must be a value between 0 and 59 for dictionary value @ data['minutes']. Got None. (See ?, line ?). 
2021-10-07 06:57:55 ERROR (MainThread) [homeassistant.config] Invalid config for [automation]: invalid template (TemplateSyntaxError: unexpected '}', expected ')') for dictionary value @ data['action'][0]['data_template']. Got None. (See ?, line ?). 
2021-10-07 06:57:55 ERROR (MainThread) [homeassistant.config] Invalid config for [automation]: invalid template (TemplateSyntaxError: unexpected '}', expected ')') for dictionary value @ data['action'][0]['data_template']. Got None. (See ?, line ?). 
2021-10-07 06:57:55 ERROR (MainThread) [homeassistant.config] Invalid config for [automation]: invalid template (TemplateSyntaxError: unexpected '}', expected ')') for dictionary value @ data['action'][0]['data_template']. Got None. (See ?, line ?). 
2021-10-07 06:57:55 ERROR (MainThread) [homeassistant.config] Invalid config for [automation]: invalid template (TemplateSyntaxError: unexpected '}', expected ')') for dictionary value @ data['action'][0]['data_template']. Got None. (See ?, line ?). 
2021-10-07 06:57:55 ERROR (MainThread) [homeassistant.config] Invalid config for [automation]: invalid template (TemplateSyntaxError: unexpected '}', expected ')') for dictionary value @ data['action'][0]['data_template']. Got None. (See ?, line ?). 
2021-10-07 06:57:55 ERROR (MainThread) [homeassistant.config] Invalid config for [automation]: invalid template (TemplateSyntaxError: unexpected '}', expected ')') for dictionary value @ data['action'][0]['data_template']. Got None. (See ?, line ?). 
2021-10-07 06:57:55 ERROR (MainThread) [homeassistant.config] Invalid config for [automation]: invalid template (TemplateSyntaxError: unexpected '}', expected ')') for dictionary value @ data['action'][0]['data_template']. Got None. (See ?, line ?). 
2021-10-07 06:57:59 WARNING (MainThread) [homeassistant.setup] Setup of input_boolean is taking over 10 seconds.
2021-10-07 06:57:59 WARNING (MainThread) [homeassistant.setup] Setup of input_select is taking over 10 seconds.
2021-10-07 06:57:59 WARNING (MainThread) [homeassistant.setup] Setup of zone is taking over 10 seconds.
2021-10-07 06:57:59 WARNING (MainThread) [homeassistant.components.fan] Platform xiaomi_miio_fan not ready yet: Unable to discover the device 192.168.86.28; Retrying in background in 30 seconds
2021-10-07 06:57:59 WARNING (MainThread) [homeassistant.components.fan] Platform xiaomi_miio_fan not ready yet: Unable to discover the device 192.168.86.29; Retrying in background in 30 seconds
2021-10-07 06:58:02 WARNING (MainThread) [homeassistant.config_entries] Config entry '192.168.86.83' for synology_dsm integration not ready yet: {'api': None, 'code': -1, 'reason': 'Unknown', 'details': 'ConnectionError = <urllib3.connection.HTTPSConnection object at 0xffff9194b0a0>: Failed to establish a new connection: [Errno 113] Host is unreachable'}; Retrying in background
2021-10-07 06:58:04 WARNING (MainThread) [homeassistant.components.light] Platform netatmo not ready yet: None; Retrying in background in 30 seconds
2021-10-07 06:58:04 WARNING (MainThread) [homeassistant.components.select] Platform netatmo not ready yet: None; Retrying in background in 30 seconds
2021-10-07 06:58:04 WARNING (MainThread) [homeassistant.components.hue.light] Please check for software updates of the douche bulb in the Philips Hue App.
2021-10-07 06:58:04 WARNING (MainThread) [homeassistant.components.hue.light] Please check for software updates of the wasbak rechts bulb in the Philips Hue App.
2021-10-07 06:58:04 WARNING (MainThread) [homeassistant.components.hue.light] Please check for software updates of the bad bulb in the Philips Hue App.
2021-10-07 06:58:04 WARNING (MainThread) [homeassistant.components.hue.light] Please check for software updates of the Amilya plafond 2 bulb in the Philips Hue App.
2021-10-07 06:58:04 WARNING (MainThread) [homeassistant.components.hue.light] Please check for software updates of the Amilya plafond 1 bulb in the Philips Hue App.
2021-10-07 06:58:05 WARNING (MainThread) [homeassistant.components.sensor] Platform netatmo not ready yet: None; Retrying in background in 30 seconds
2021-10-07 06:58:07 ERROR (MainThread) [homeassistant.components.sensor] scrape: Error on device update!
Traceback (most recent call last):
  File "/usr/src/homeassistant/homeassistant/helpers/entity_platform.py", line 431, in _async_add_entity
    await entity.async_device_update(warning=False)
  File "/usr/src/homeassistant/homeassistant/helpers/entity.py", line 633, in async_device_update
    await task
  File "/usr/src/homeassistant/homeassistant/components/scrape/sensor.py", line 139, in async_update
    await self._async_update_from_rest_data()
  File "/usr/src/homeassistant/homeassistant/components/scrape/sensor.py", line 152, in _async_update_from_rest_data
    value = await self.hass.async_add_executor_job(self._extract_value)
  File "/usr/local/lib/python3.9/concurrent/futures/thread.py", line 52, in run
    result = self.fn(*self.args, **self.kwargs)
  File "/usr/src/homeassistant/homeassistant/components/scrape/sensor.py", line 128, in _extract_value
    tag = raw_data.select(self._select)[self._index]
  File "/usr/local/lib/python3.9/site-packages/bs4/element.py", line 1869, in select
    results = soupsieve.select(selector, self, namespaces, limit, **kwargs)
  File "/usr/local/lib/python3.9/site-packages/soupsieve/__init__.py", line 98, in select
    return compile(select, namespaces, flags, **kwargs).select(tag, limit)
  File "/usr/local/lib/python3.9/site-packages/soupsieve/__init__.py", line 62, in compile
    return cp._cached_css_compile(pattern, namespaces, custom, flags)
  File "/usr/local/lib/python3.9/site-packages/soupsieve/css_parser.py", line 211, in _cached_css_compile
    CSSParser(pattern, custom=custom_selectors, flags=flags).process_selectors(),
  File "/usr/local/lib/python3.9/site-packages/soupsieve/css_parser.py", line 1058, in process_selectors
    return self.parse_selectors(self.selector_iter(self.pattern), index, flags)
  File "/usr/local/lib/python3.9/site-packages/soupsieve/css_parser.py", line 909, in parse_selectors
    key, m = next(iselector)
  File "/usr/local/lib/python3.9/site-packages/soupsieve/css_parser.py", line 1051, in selector_iter
    raise SelectorSyntaxError(msg, self.pattern, index)
soupsieve.util.SelectorSyntaxError: Invalid character '<' position 0
  line 1:
<span _ngcontent-app-root-c173="">Offline</span>
^
2021-10-07 06:58:08 ERROR (SyncWorker_8) [glocaltokens.client] [Device - Nest Wifi router(id=2f2a9d15-0ae2-4ffe-b6c1-2ef24c742b8a)] local_auth_token must follow the correct format
2021-10-07 06:58:08 ERROR (SyncWorker_8) [glocaltokens.client] [Device - Nest Wifi router(id=e1e5a8d5-d21f-444d-95a9-c76d78c9bc79)] local_auth_token must follow the correct format
2021-10-07 06:58:08 ERROR (SyncWorker_8) [glocaltokens.client] [Device - Nest Wifi router(id=ea3de37c-ca74-4689-8171-1681b2f4f924)] local_auth_token must follow the correct format
2021-10-07 06:58:11 ERROR (MainThread) [homeassistant.components.camera] Error while setting up netatmo platform for camera
Traceback (most recent call last):
  File "/usr/local/lib/python3.9/site-packages/aiohttp/connector.py", line 969, in _wrap_create_connection
    return await self._loop.create_connection(*args, **kwargs)  # type: ignore  # noqa
  File "/usr/local/lib/python3.9/asyncio/base_events.py", line 1056, in create_connection
    raise exceptions[0]
  File "/usr/local/lib/python3.9/asyncio/base_events.py", line 1041, in create_connection
    sock = await self._connect_sock(
  File "/usr/local/lib/python3.9/asyncio/base_events.py", line 955, in _connect_sock
    await self.sock_connect(sock, address)
  File "/usr/local/lib/python3.9/asyncio/selector_events.py", line 502, in sock_connect
    return await fut
  File "/usr/local/lib/python3.9/asyncio/selector_events.py", line 537, in _sock_connect_cb
    raise OSError(err, f'Connect call failed {address}')
OSError: [Errno 113] Connect call failed ('169.254.113.236', 80)

The above exception was the direct cause of the following exception:

Traceback (most recent call last):
  File "/usr/src/homeassistant/homeassistant/helpers/entity_platform.py", line 249, in _async_setup_platform
    await asyncio.shield(task)
  File "/usr/src/homeassistant/homeassistant/components/netatmo/camera.py", line 62, in async_setup_entry
    await data_handler.register_data_class(
  File "/usr/src/homeassistant/homeassistant/components/netatmo/data_handler.py", line 192, in register_data_class
    await self.async_fetch_data(data_class_entry)
  File "/usr/src/homeassistant/homeassistant/components/netatmo/data_handler.py", line 149, in async_fetch_data
    await self.data[data_class_entry].async_update()
  File "/usr/local/lib/python3.9/site-packages/pyatmo/camera.py", line 607, in async_update
    await self._async_update_all_camera_urls()
  File "/usr/local/lib/python3.9/site-packages/pyatmo/camera.py", line 617, in _async_update_all_camera_urls
    await self.async_update_camera_urls(camera_id)
  File "/usr/local/lib/python3.9/site-packages/pyatmo/camera.py", line 696, in async_update_camera_urls
    self.cameras[home_id][camera_id]["local_url"] = await async_check_url(
  File "/usr/local/lib/python3.9/site-packages/pyatmo/camera.py", line 682, in async_check_url
    resp = await self.auth.async_post_request(url=f"{url}/command/ping")
  File "/usr/local/lib/python3.9/site-packages/pyatmo/auth.py", line 306, in async_post_request
    async with self.websession.post(
  File "/usr/local/lib/python3.9/site-packages/aiohttp/client.py", line 1117, in __aenter__
    self._resp = await self._coro
  File "/usr/local/lib/python3.9/site-packages/aiohttp/client.py", line 520, in _request
    conn = await self._connector.connect(
  File "/usr/local/lib/python3.9/site-packages/aiohttp/connector.py", line 535, in connect
    proto = await self._create_connection(req, traces, timeout)
  File "/usr/local/lib/python3.9/site-packages/aiohttp/connector.py", line 892, in _create_connection
    _, proto = await self._create_direct_connection(req, traces, timeout)
  File "/usr/local/lib/python3.9/site-packages/aiohttp/connector.py", line 1051, in _create_direct_connection
    raise last_exc
  File "/usr/local/lib/python3.9/site-packages/aiohttp/connector.py", line 1020, in _create_direct_connection
    transp, proto = await self._wrap_create_connection(
  File "/usr/local/lib/python3.9/site-packages/aiohttp/connector.py", line 975, in _wrap_create_connection
    raise client_error(req.connection_key, exc) from exc
aiohttp.client_exceptions.ClientConnectorError: Cannot connect to host 169.254.113.236:80 ssl:default [Connect call failed ('169.254.113.236', 80)]
2021-10-07 06:58:12 WARNING (MainThread) [homeassistant.config_entries] Config entry 'OnHub' for upnp integration not ready yet; Retrying in background
2021-10-07 06:58:13 WARNING (MainThread) [homeassistant.components.sensor] Setup of sensor platform buienalarm is taking over 10 seconds.
2021-10-07 06:58:14 WARNING (SyncWorker_6) [buienalarm.pybuienalarm] Error fetching data safely: HTTPSConnectionPool(host='cdn-secure.buienalarm.nl', port=443): Read timed out. (read timeout=10.0)
2021-10-07 06:58:45 WARNING (MainThread) [homeassistant.components.media_player] Updating huesyncbox media_player took longer than the scheduled update interval 0:00:02
2021-10-07 06:58:54 WARNING (MainThread) [homeassistant.components.fan] Setup of fan platform xiaomi_miio_fan is taking over 10 seconds.
2021-10-07 06:58:54 WARNING (MainThread) [homeassistant.components.fan] Setup of fan platform xiaomi_miio_fan is taking over 10 seconds.
2021-10-07 06:58:55 ERROR (MainThread) [homeassistant.components.google_assistant.http] Request for https://homegraph.googleapis.com/v1/devices:requestSync failed: 500
2021-10-07 06:58:56 ERROR (MainThread) [homeassistant.components.google_assistant.http] Request for https://homegraph.googleapis.com/v1/devices:reportStateAndNotification failed: 404
2021-10-07 07:03:24 WARNING (SyncWorker_10) [buienalarm.pybuienalarm] Error fetching data safely: HTTPSConnectionPool(host='cdn-secure.buienalarm.nl', port=443): Read timed out. (read timeout=10.0)
2021-10-07 07:08:34 WARNING (SyncWorker_9) [buienalarm.pybuienalarm] Error fetching data safely: HTTPSConnectionPool(host='cdn-secure.buienalarm.nl', port=443): Read timed out. (read timeout=10.0)
2021-10-07 07:13:44 WARNING (SyncWorker_12) [buienalarm.pybuienalarm] Error fetching data safely: HTTPSConnectionPool(host='cdn-secure.buienalarm.nl', port=443): Read timed out. (read timeout=10.0)
2021-10-07 07:15:59 WARNING (MainThread) [homeassistant.helpers.service] Unable to find referenced entities media_player.veranda_speaker_2
2021-10-07 07:16:09 WARNING (MainThread) [homeassistant.helpers.service] Unable to find referenced entities camera.netatmo_eikenbos_oprit
2021-10-07 07:18:54 WARNING (SyncWorker_1) [buienalarm.pybuienalarm] Error fetching data safely: HTTPSConnectionPool(host='cdn-secure.buienalarm.nl', port=443): Read timed out. (read timeout=10.0)
2021-10-07 07:24:04 WARNING (SyncWorker_5) [buienalarm.pybuienalarm] Error fetching data safely: HTTPSConnectionPool(host='cdn-secure.buienalarm.nl', port=443): Read timed out. (read timeout=10.0)
2021-10-07 07:29:14 WARNING (SyncWorker_10) [buienalarm.pybuienalarm] Error fetching data safely: HTTPSConnectionPool(host='cdn-secure.buienalarm.nl', port=443): Read timed out. (read timeout=10.0)
2021-10-07 07:34:24 WARNING (SyncWorker_12) [buienalarm.pybuienalarm] Error fetching data safely: HTTPSConnectionPool(host='cdn-secure.buienalarm.nl', port=443): Read timed out. (read timeout=10.0)
2021-10-07 07:39:34 WARNING (SyncWorker_12) [buienalarm.pybuienalarm] Error fetching data safely: HTTPSConnectionPool(host='cdn-secure.buienalarm.nl', port=443): Read timed out. (read timeout=10.0)
2021-10-07 07:44:44 WARNING (SyncWorker_17) [buienalarm.pybuienalarm] Error fetching data safely: HTTPSConnectionPool(host='cdn-secure.buienalarm.nl', port=443): Read timed out. (read timeout=10.0)
2021-10-07 07:49:54 WARNING (SyncWorker_7) [buienalarm.pybuienalarm] Error fetching data safely: HTTPSConnectionPool(host='cdn-secure.buienalarm.nl', port=443): Read timed out. (read timeout=10.0)
2021-10-07 07:55:04 WARNING (SyncWorker_6) [buienalarm.pybuienalarm] Error fetching data safely: HTTPSConnectionPool(host='cdn-secure.buienalarm.nl', port=443): Read timed out. (read timeout=10.0)
2021-10-07 08:00:14 WARNING (SyncWorker_12) [buienalarm.pybuienalarm] Error fetching data safely: HTTPSConnectionPool(host='cdn-secure.buienalarm.nl', port=443): Read timed out. (read timeout=10.0)
2021-10-07 08:16:42 ERROR (MainThread) [custom_components.googlewifi] Error fetching GoogleWifi data: Error connecting to GoogleWifi: 
2021-10-07 08:18:46 WARNING (MainThread) [homeassistant.helpers.service] Unable to find referenced entities media_player.veranda_speaker_2
2021-10-07 08:18:56 WARNING (MainThread) [homeassistant.helpers.service] Unable to find referenced entities camera.netatmo_eikenbos_oprit
2021-10-07 08:28:37 ERROR (MainThread) [custom_components.audiconnect.audi_connect_account] Unable to update the vehicle position of WAUZZZGE6MB019131: 204, message='No Content', url=URL('https://fal-3a.prd.eu.dp.vwg-connect.com/fs-car/bs/cf/v1/Audi/BE/vehicles/WAUZZZGE6MB019131/position')
2021-10-07 08:37:57 ERROR (MainThread) [custom_components.googlewifi] Unexpected error fetching GoogleWifi data: 'NoneType' object is not iterable
Traceback (most recent call last):
  File "/usr/src/homeassistant/homeassistant/helpers/update_coordinator.py", line 187, in _async_refresh
    self.data = await self._async_update_data()
  File "/config/custom_components/googlewifi/__init__.py", line 171, in _async_update_data
    system_data = await self.api.get_systems()
  File "/usr/local/lib/python3.9/site-packages/googlewifi/__init__.py", line 191, in get_systems
    return await self.structure_systems(response)
  File "/usr/local/lib/python3.9/site-packages/googlewifi/__init__.py", line 289, in structure_systems
    for this_station in system_metrics.get("stationMetrics"):
TypeError: 'NoneType' object is not iterable
2021-10-07 09:20:48 ERROR (MainThread) [custom_components.googlewifi] Unexpected error fetching GoogleWifi data: 'NoneType' object is not iterable
Traceback (most recent call last):
  File "/usr/src/homeassistant/homeassistant/helpers/update_coordinator.py", line 187, in _async_refresh
    self.data = await self._async_update_data()
  File "/config/custom_components/googlewifi/__init__.py", line 171, in _async_update_data
    system_data = await self.api.get_systems()
  File "/usr/local/lib/python3.9/site-packages/googlewifi/__init__.py", line 191, in get_systems
    return await self.structure_systems(response)
  File "/usr/local/lib/python3.9/site-packages/googlewifi/__init__.py", line 289, in structure_systems
    for this_station in system_metrics.get("stationMetrics"):
TypeError: 'NoneType' object is not iterable
2021-10-07 09:26:22 ERROR (MainThread) [custom_components.googlewifi] Error fetching GoogleWifi data: Error connecting to GoogleWifi: 
2021-10-07 09:45:13 ERROR (MainThread) [custom_components.googlewifi] Unexpected error fetching GoogleWifi data: 'NoneType' object is not iterable
Traceback (most recent call last):
  File "/usr/src/homeassistant/homeassistant/helpers/update_coordinator.py", line 187, in _async_refresh
    self.data = await self._async_update_data()
  File "/config/custom_components/googlewifi/__init__.py", line 171, in _async_update_data
    system_data = await self.api.get_systems()
  File "/usr/local/lib/python3.9/site-packages/googlewifi/__init__.py", line 191, in get_systems
    return await self.structure_systems(response)
  File "/usr/local/lib/python3.9/site-packages/googlewifi/__init__.py", line 289, in structure_systems
    for this_station in system_metrics.get("stationMetrics"):
TypeError: 'NoneType' object is not iterable
2021-10-07 09:56:52 ERROR (MainThread) [custom_components.googlewifi] Error fetching GoogleWifi data: Error connecting to GoogleWifi: 
2021-10-07 10:37:25 ERROR (MainThread) [custom_components.googlewifi] Error fetching GoogleWifi data: Error connecting to GoogleWifi: 
2021-10-07 10:40:47 ERROR (MainThread) [custom_components.googlewifi] Unexpected error fetching GoogleWifi data: 'NoneType' object is not iterable
Traceback (most recent call last):
  File "/usr/src/homeassistant/homeassistant/helpers/update_coordinator.py", line 187, in _async_refresh
    self.data = await self._async_update_data()
  File "/config/custom_components/googlewifi/__init__.py", line 171, in _async_update_data
    system_data = await self.api.get_systems()
  File "/usr/local/lib/python3.9/site-packages/googlewifi/__init__.py", line 191, in get_systems
    return await self.structure_systems(response)
  File "/usr/local/lib/python3.9/site-packages/googlewifi/__init__.py", line 289, in structure_systems
    for this_station in system_metrics.get("stationMetrics"):
TypeError: 'NoneType' object is not iterable
2021-10-07 10:58:06 ERROR (MainThread) [custom_components.googlewifi] Error fetching GoogleWifi data: Error connecting to GoogleWifi: 
2021-10-07 11:00:13 ERROR (MainThread) [homeassistant.components.speedtestdotnet] Error fetching speedtestdotnet data: Unable to connect to servers to test latency.
2021-10-07 11:04:54 ERROR (MainThread) [custom_components.googlewifi] Error fetching GoogleWifi data: Error connecting to GoogleWifi: 
2021-10-07 11:23:10 ERROR (MainThread) [custom_components.googlewifi] Unexpected error fetching GoogleWifi data: 'NoneType' object is not iterable
Traceback (most recent call last):
  File "/usr/src/homeassistant/homeassistant/helpers/update_coordinator.py", line 187, in _async_refresh
    self.data = await self._async_update_data()
  File "/config/custom_components/googlewifi/__init__.py", line 171, in _async_update_data
    system_data = await self.api.get_systems()
  File "/usr/local/lib/python3.9/site-packages/googlewifi/__init__.py", line 191, in get_systems
    return await self.structure_systems(response)
  File "/usr/local/lib/python3.9/site-packages/googlewifi/__init__.py", line 289, in structure_systems
    for this_station in system_metrics.get("stationMetrics"):
TypeError: 'NoneType' object is not iterable
2021-10-07 11:50:10 WARNING (MainThread) [homeassistant.helpers.entity] Update of fan.xiaomi_air_purifier_3h is taking over 10 seconds
2021-10-07 12:07:44 ERROR (MainThread) [custom_components.googlewifi] Error fetching GoogleWifi data: Error connecting to GoogleWifi: 
2021-10-07 12:16:33 WARNING (MainThread) [homeassistant.helpers.service] Unable to find referenced entities media_player.veranda_speaker_2
2021-10-07 12:16:43 WARNING (MainThread) [homeassistant.helpers.service] Unable to find referenced entities camera.netatmo_eikenbos_oprit
2021-10-07 12:18:50 WARNING (MainThread) [homeassistant.helpers.service] Unable to find referenced entities media_player.veranda_speaker_2
2021-10-07 12:19:00 WARNING (MainThread) [homeassistant.helpers.service] Unable to find referenced entities camera.netatmo_eikenbos_oprit
2021-10-07 12:45:04 ERROR (Thread-2) [root] Uncaught thread exception
Traceback (most recent call last):
  File "/usr/local/lib/python3.9/threading.py", line 973, in _bootstrap_inner
    self.run()
  File "/usr/local/lib/python3.9/threading.py", line 910, in run
    self._target(*self._args, **self._kwargs)
  File "/usr/local/lib/python3.9/logging/handlers.py", line 1518, in _monitor
    self.handle(record)
  File "/usr/local/lib/python3.9/logging/handlers.py", line 1499, in handle
    handler.handle(record)
  File "/usr/local/lib/python3.9/logging/__init__.py", line 952, in handle
    self.emit(record)
  File "/usr/src/homeassistant/homeassistant/components/system_log/__init__.py", line 192, in emit
    entry = LogEntry(record, stack, _figure_out_source(record, stack, self.hass))
  File "/usr/src/homeassistant/homeassistant/components/system_log/__init__.py", line 99, in __init__
    self.message = deque([record.getMessage()], maxlen=5)
  File "/usr/local/lib/python3.9/logging/__init__.py", line 367, in getMessage
    msg = msg % self.args
TypeError: not all arguments converted during string formatting
2021-10-07 13:07:59 ERROR (MainThread) [custom_components.googlewifi] Error fetching GoogleWifi data: Error connecting to GoogleWifi: 
2021-10-07 13:10:44 ERROR (MainThread) [custom_components.audiconnect.util] Unable to update vehicle data of WAUZZZGE6MB019131: Timeout error
2021-10-07 13:25:23 ERROR (MainThread) [custom_components.googlewifi] Unexpected error fetching GoogleWifi data: 'operationState'
Traceback (most recent call last):
  File "/usr/src/homeassistant/homeassistant/helpers/update_coordinator.py", line 187, in _async_refresh
    self.data = await self._async_update_data()
  File "/config/custom_components/googlewifi/__init__.py", line 171, in _async_update_data
    system_data = await self.api.get_systems()
  File "/usr/local/lib/python3.9/site-packages/googlewifi/__init__.py", line 191, in get_systems
    return await self.structure_systems(response)
  File "/usr/local/lib/python3.9/site-packages/googlewifi/__init__.py", line 284, in structure_systems
    sensitive_info = await self.get_sensitive_info(system_id=this_system["id"], station_ids=station_ids)
  File "/usr/local/lib/python3.9/site-packages/googlewifi/__init__.py", line 616, in get_sensitive_info
    status = status["operationState"]
KeyError: 'operationState'
2021-10-07 13:34:20 WARNING (MainThread) [homeassistant.helpers.entity] Update of sensor.precip_rate_leuven24_wunderground is taking over 10 seconds
2021-10-07 13:34:20 ERROR (MainThread) [homeassistant.components.rest.data] Error fetching data: https://www.wunderground.com/dashboard/pws/ILEUVE24 failed with 
2021-10-07 13:34:20 ERROR (MainThread) [homeassistant.components.scrape.sensor] Unable to retrieve data for precip_rate_leuven24_wunderground
2021-10-07 13:36:57 WARNING (MainThread) [homeassistant.helpers.service] Unable to find referenced entities media_player.veranda_speaker_2
2021-10-07 13:37:07 WARNING (MainThread) [homeassistant.helpers.service] Unable to find referenced entities camera.netatmo_eikenbos_oprit
2021-10-07 14:43:47 WARNING (MainThread) [homeassistant.helpers.service] Unable to find referenced entities media_player.veranda_speaker_2
2021-10-07 14:43:57 WARNING (MainThread) [homeassistant.helpers.service] Unable to find referenced entities camera.netatmo_eikenbos_oprit
2021-10-07 14:51:04 WARNING (MainThread) [homeassistant.helpers.service] Unable to find referenced entities media_player.veranda_speaker_2
2021-10-07 14:51:14 WARNING (MainThread) [homeassistant.helpers.service] Unable to find referenced entities camera.netatmo_eikenbos_oprit
2021-10-07 14:53:14 WARNING (MainThread) [homeassistant.helpers.service] Unable to find referenced entities media_player.veranda_speaker_2
2021-10-07 14:53:24 WARNING (MainThread) [homeassistant.helpers.service] Unable to find referenced entities camera.netatmo_eikenbos_oprit
2021-10-07 15:33:27 ERROR (MainThread) [custom_components.googlewifi] Error fetching GoogleWifi data: Error connecting to GoogleWifi: 
2021-10-07 15:44:37 WARNING (MainThread) [homeassistant.helpers.service] Unable to find referenced entities media_player.veranda_speaker_2
2021-10-07 15:44:47 WARNING (MainThread) [homeassistant.helpers.service] Unable to find referenced entities camera.netatmo_eikenbos_oprit
2021-10-07 15:47:06 WARNING (MainThread) [homeassistant.helpers.service] Unable to find referenced entities media_player.veranda_speaker_2
2021-10-07 15:47:16 WARNING (MainThread) [homeassistant.helpers.service] Unable to find referenced entities camera.netatmo_eikenbos_oprit
2021-10-07 15:53:33 WARNING (MainThread) [homeassistant.helpers.service] Unable to find referenced entities media_player.veranda_speaker_2
2021-10-07 15:53:43 WARNING (MainThread) [homeassistant.helpers.service] Unable to find referenced entities camera.netatmo_eikenbos_oprit
2021-10-07 15:55:57 WARNING (MainThread) [homeassistant.helpers.service] Unable to find referenced entities media_player.veranda_speaker_2
2021-10-07 15:56:07 WARNING (MainThread) [homeassistant.helpers.service] Unable to find referenced entities camera.netatmo_eikenbos_oprit
2021-10-07 15:58:42 WARNING (MainThread) [homeassistant.helpers.service] Unable to find referenced entities media_player.veranda_speaker_2
2021-10-07 15:58:52 WARNING (MainThread) [homeassistant.helpers.service] Unable to find referenced entities camera.netatmo_eikenbos_oprit
2021-10-07 16:30:46 WARNING (MainThread) [homeassistant.helpers.service] Unable to find referenced entities media_player.veranda_speaker_2
2021-10-07 16:30:56 WARNING (MainThread) [homeassistant.helpers.service] Unable to find referenced entities camera.netatmo_eikenbos_oprit
2021-10-07 16:45:26 WARNING (SyncWorker_7) [buienalarm.pybuienalarm] Error fetching data safely: HTTPSConnectionPool(host='cdn-secure.buienalarm.nl', port=443): Read timed out. (read timeout=10.0)
2021-10-07 16:47:55 ERROR (MainThread) [custom_components.googlewifi] Unexpected error fetching GoogleWifi data: 'NoneType' object is not iterable
Traceback (most recent call last):
  File "/usr/src/homeassistant/homeassistant/helpers/update_coordinator.py", line 187, in _async_refresh
    self.data = await self._async_update_data()
  File "/config/custom_components/googlewifi/__init__.py", line 171, in _async_update_data
    system_data = await self.api.get_systems()
  File "/usr/local/lib/python3.9/site-packages/googlewifi/__init__.py", line 191, in get_systems
    return await self.structure_systems(response)
  File "/usr/local/lib/python3.9/site-packages/googlewifi/__init__.py", line 289, in structure_systems
    for this_station in system_metrics.get("stationMetrics"):
TypeError: 'NoneType' object is not iterable
2021-10-07 17:25:14 ERROR (MainThread) [homeassistant.config] Invalid config for [automation]: required key not provided @ data['action'][4]['domain']. Got None. (See ?, line ?). 
2021-10-07 17:25:15 ERROR (MainThread) [homeassistant.config] Invalid config for [automation]: [title] is an invalid option for [automation]. Check: automation->action->1->title. (See ?, line ?). 
2021-10-07 17:25:15 ERROR (MainThread) [homeassistant.config] Invalid config for [automation]: must be a value between 0 and 59 for dictionary value @ data['minutes']. Got None. (See ?, line ?). 
2021-10-07 17:25:15 ERROR (MainThread) [homeassistant.config] Invalid config for [automation]: must be a value between 0 and 59 for dictionary value @ data['minutes']. Got None. (See ?, line ?). 
2021-10-07 17:25:15 ERROR (MainThread) [homeassistant.config] Invalid config for [automation]: invalid template (TemplateSyntaxError: unexpected '}', expected ')') for dictionary value @ data['action'][0]['data_template']. Got None. (See ?, line ?). 
2021-10-07 17:25:15 ERROR (MainThread) [homeassistant.config] Invalid config for [automation]: invalid template (TemplateSyntaxError: unexpected '}', expected ')') for dictionary value @ data['action'][0]['data_template']. Got None. (See ?, line ?). 
2021-10-07 17:25:15 ERROR (MainThread) [homeassistant.config] Invalid config for [automation]: invalid template (TemplateSyntaxError: unexpected '}', expected ')') for dictionary value @ data['action'][0]['data_template']. Got None. (See ?, line ?). 
2021-10-07 17:25:15 ERROR (MainThread) [homeassistant.config] Invalid config for [automation]: invalid template (TemplateSyntaxError: unexpected '}', expected ')') for dictionary value @ data['action'][0]['data_template']. Got None. (See ?, line ?). 
2021-10-07 17:25:15 ERROR (MainThread) [homeassistant.config] Invalid config for [automation]: invalid template (TemplateSyntaxError: unexpected '}', expected ')') for dictionary value @ data['action'][0]['data_template']. Got None. (See ?, line ?). 
2021-10-07 17:25:15 ERROR (MainThread) [homeassistant.config] Invalid config for [automation]: invalid template (TemplateSyntaxError: unexpected '}', expected ')') for dictionary value @ data['action'][0]['data_template']. Got None. (See ?, line ?). 
2021-10-07 17:25:15 ERROR (MainThread) [homeassistant.config] Invalid config for [automation]: invalid template (TemplateSyntaxError: unexpected '}', expected ')') for dictionary value @ data['action'][0]['data_template']. Got None. (See ?, line ?). 
2021-10-07 17:25:22 ERROR (MainThread) [homeassistant.config] Invalid config for [automation]: required key not provided @ data['action'][4]['domain']. Got None. (See ?, line ?). 
2021-10-07 17:25:22 ERROR (MainThread) [homeassistant.config] Invalid config for [automation]: [title] is an invalid option for [automation]. Check: automation->action->1->title. (See ?, line ?). 
2021-10-07 17:25:22 ERROR (MainThread) [homeassistant.config] Invalid config for [automation]: must be a value between 0 and 59 for dictionary value @ data['minutes']. Got None. (See ?, line ?). 
2021-10-07 17:25:22 ERROR (MainThread) [homeassistant.config] Invalid config for [automation]: must be a value between 0 and 59 for dictionary value @ data['minutes']. Got None. (See ?, line ?). 
2021-10-07 17:25:22 ERROR (MainThread) [homeassistant.config] Invalid config for [automation]: invalid template (TemplateSyntaxError: unexpected '}', expected ')') for dictionary value @ data['action'][0]['data_template']. Got None. (See ?, line ?). 
2021-10-07 17:25:22 ERROR (MainThread) [homeassistant.config] Invalid config for [automation]: invalid template (TemplateSyntaxError: unexpected '}', expected ')') for dictionary value @ data['action'][0]['data_template']. Got None. (See ?, line ?). 
2021-10-07 17:25:22 ERROR (MainThread) [homeassistant.config] Invalid config for [automation]: invalid template (TemplateSyntaxError: unexpected '}', expected ')') for dictionary value @ data['action'][0]['data_template']. Got None. (See ?, line ?). 
2021-10-07 17:25:22 ERROR (MainThread) [homeassistant.config] Invalid config for [automation]: invalid template (TemplateSyntaxError: unexpected '}', expected ')') for dictionary value @ data['action'][0]['data_template']. Got None. (See ?, line ?). 
2021-10-07 17:25:22 ERROR (MainThread) [homeassistant.config] Invalid config for [automation]: invalid template (TemplateSyntaxError: unexpected '}', expected ')') for dictionary value @ data['action'][0]['data_template']. Got None. (See ?, line ?). 
2021-10-07 17:25:22 ERROR (MainThread) [homeassistant.config] Invalid config for [automation]: invalid template (TemplateSyntaxError: unexpected '}', expected ')') for dictionary value @ data['action'][0]['data_template']. Got None. (See ?, line ?). 
2021-10-07 17:25:22 ERROR (MainThread) [homeassistant.config] Invalid config for [automation]: invalid template (TemplateSyntaxError: unexpected '}', expected ')') for dictionary value @ data['action'][0]['data_template']. Got None. (See ?, line ?). 
