2021-10-05 08:48:17 WARNING (SyncWorker_0) [homeassistant.loader] We found a custom integration xiaomi_miio_airpurifier which has not been tested by Home Assistant. This component might cause stability problems, be sure to disable it if you experience issues with Home Assistant
2021-10-05 08:48:17 WARNING (SyncWorker_3) [homeassistant.loader] We found a custom integration powercalc which has not been tested by Home Assistant. This component might cause stability problems, be sure to disable it if you experience issues with Home Assistant
2021-10-05 08:48:17 WARNING (SyncWorker_5) [homeassistant.loader] We found a custom integration hacs which has not been tested by Home Assistant. This component might cause stability problems, be sure to disable it if you experience issues with Home Assistant
2021-10-05 08:48:17 WARNING (SyncWorker_1) [homeassistant.loader] We found a custom integration average which has not been tested by Home Assistant. This component might cause stability problems, be sure to disable it if you experience issues with Home Assistant
2021-10-05 08:48:17 WARNING (SyncWorker_2) [homeassistant.loader] We found a custom integration audiconnect which has not been tested by Home Assistant. This component might cause stability problems, be sure to disable it if you experience issues with Home Assistant
2021-10-05 08:48:17 WARNING (SyncWorker_7) [homeassistant.loader] We found a custom integration xiaomi_miio_fan which has not been tested by Home Assistant. This component might cause stability problems, be sure to disable it if you experience issues with Home Assistant
2021-10-05 08:48:17 WARNING (SyncWorker_6) [homeassistant.loader] We found a custom integration localtuya which has not been tested by Home Assistant. This component might cause stability problems, be sure to disable it if you experience issues with Home Assistant
2021-10-05 08:48:17 WARNING (SyncWorker_0) [homeassistant.loader] We found a custom integration tuya_v2 which has not been tested by Home Assistant. This component might cause stability problems, be sure to disable it if you experience issues with Home Assistant
2021-10-05 08:48:17 WARNING (SyncWorker_4) [homeassistant.loader] We found a custom integration monitor_docker which has not been tested by Home Assistant. This component might cause stability problems, be sure to disable it if you experience issues with Home Assistant
2021-10-05 08:48:17 WARNING (SyncWorker_5) [homeassistant.loader] We found a custom integration shelly which has not been tested by Home Assistant. This component might cause stability problems, be sure to disable it if you experience issues with Home Assistant
2021-10-05 08:48:17 WARNING (SyncWorker_9) [homeassistant.loader] We found a custom integration huesyncbox which has not been tested by Home Assistant. This component might cause stability problems, be sure to disable it if you experience issues with Home Assistant
2021-10-05 08:48:17 WARNING (SyncWorker_3) [homeassistant.loader] We found a custom integration deepstack_face which has not been tested by Home Assistant. This component might cause stability problems, be sure to disable it if you experience issues with Home Assistant
2021-10-05 08:48:17 WARNING (SyncWorker_7) [homeassistant.loader] We found a custom integration buienalarm which has not been tested by Home Assistant. This component might cause stability problems, be sure to disable it if you experience issues with Home Assistant
2021-10-05 08:48:17 WARNING (SyncWorker_4) [homeassistant.loader] We found a custom integration ytube_music_player which has not been tested by Home Assistant. This component might cause stability problems, be sure to disable it if you experience issues with Home Assistant
2021-10-05 08:48:17 WARNING (SyncWorker_0) [homeassistant.loader] We found a custom integration googlewifi which has not been tested by Home Assistant. This component might cause stability problems, be sure to disable it if you experience issues with Home Assistant
2021-10-05 08:48:17 WARNING (SyncWorker_10) [homeassistant.loader] We found a custom integration xiaomi_miot which has not been tested by Home Assistant. This component might cause stability problems, be sure to disable it if you experience issues with Home Assistant
2021-10-05 08:48:17 WARNING (SyncWorker_6) [homeassistant.loader] We found a custom integration thermal_comfort which has not been tested by Home Assistant. This component might cause stability problems, be sure to disable it if you experience issues with Home Assistant
2021-10-05 08:48:17 WARNING (SyncWorker_5) [homeassistant.loader] We found a custom integration google_home which has not been tested by Home Assistant. This component might cause stability problems, be sure to disable it if you experience issues with Home Assistant
2021-10-05 08:48:17 WARNING (SyncWorker_9) [homeassistant.loader] We found a custom integration afvalbeheer which has not been tested by Home Assistant. This component might cause stability problems, be sure to disable it if you experience issues with Home Assistant
2021-10-05 08:48:17 WARNING (SyncWorker_11) [homeassistant.loader] We found a custom integration anniversaries which has not been tested by Home Assistant. This component might cause stability problems, be sure to disable it if you experience issues with Home Assistant
2021-10-05 08:48:27 ERROR (MainThread) [homeassistant.config] Invalid config for [automation]: required key not provided @ data['action'][4]['domain']. Got None. (See ?, line ?). 
2021-10-05 08:48:27 ERROR (MainThread) [homeassistant.config] Invalid config for [automation]: [title] is an invalid option for [automation]. Check: automation->action->1->title. (See ?, line ?). 
2021-10-05 08:48:27 ERROR (MainThread) [homeassistant.config] Invalid config for [automation]: must be a value between 0 and 59 for dictionary value @ data['minutes']. Got None. (See ?, line ?). 
2021-10-05 08:48:27 ERROR (MainThread) [homeassistant.config] Invalid config for [automation]: must be a value between 0 and 59 for dictionary value @ data['minutes']. Got None. (See ?, line ?). 
2021-10-05 08:48:30 WARNING (MainThread) [homeassistant.config_entries] Config entry 'GoogleTV' for nfandroidtv integration not ready yet: Failed to connect; Retrying in background
2021-10-05 08:48:32 WARNING (MainThread) [homeassistant.setup] Setup of input_select is taking over 10 seconds.
2021-10-05 08:48:32 WARNING (MainThread) [homeassistant.components.fan] Platform xiaomi_miio_fan not ready yet: Unable to discover the device 192.168.86.29; Retrying in background in 30 seconds
2021-10-05 08:48:32 WARNING (MainThread) [homeassistant.components.fan] Platform xiaomi_miio_fan not ready yet: Unable to discover the device 192.168.86.28; Retrying in background in 30 seconds
2021-10-05 08:48:33 WARNING (MainThread) [homeassistant.setup] Setup of input_number is taking over 10 seconds.
2021-10-05 08:48:35 WARNING (MainThread) [homeassistant.config_entries] Config entry '192.168.86.83' for synology_dsm integration not ready yet: {'api': None, 'code': -1, 'reason': 'Unknown', 'details': 'ConnectionError = <urllib3.connection.HTTPSConnection object at 0xffff9854fd00>: Failed to establish a new connection: [Errno 113] Host is unreachable'}; Retrying in background
2021-10-05 08:48:36 WARNING (MainThread) [homeassistant.components.light] Platform netatmo not ready yet: None; Retrying in background in 30 seconds
2021-10-05 08:48:36 WARNING (MainThread) [homeassistant.components.select] Platform netatmo not ready yet: None; Retrying in background in 30 seconds
2021-10-05 08:48:38 WARNING (MainThread) [homeassistant.components.hue.light] Please check for software updates of the wasbak rechts bulb in the Philips Hue App.
2021-10-05 08:48:38 WARNING (MainThread) [homeassistant.components.hue.light] Please check for software updates of the bad bulb in the Philips Hue App.
2021-10-05 08:48:39 WARNING (MainThread) [homeassistant.components.sensor] Platform netatmo not ready yet: None; Retrying in background in 30 seconds
2021-10-05 08:48:40 ERROR (SyncWorker_5) [glocaltokens.client] [Device - Nest Wifi router(id=2f2a9d15-0ae2-4ffe-b6c1-2ef24c742b8a)] local_auth_token must follow the correct format
2021-10-05 08:48:40 ERROR (SyncWorker_5) [glocaltokens.client] [Device - Nest Wifi router(id=e1e5a8d5-d21f-444d-95a9-c76d78c9bc79)] local_auth_token must follow the correct format
2021-10-05 08:48:40 ERROR (SyncWorker_5) [glocaltokens.client] [Device - Nest Wifi router(id=ea3de37c-ca74-4689-8171-1681b2f4f924)] local_auth_token must follow the correct format
2021-10-05 08:48:40 ERROR (MainThread) [homeassistant.components.sensor] scrape: Error on device update!
Traceback (most recent call last):
  File "/usr/src/homeassistant/homeassistant/helpers/entity_platform.py", line 431, in _async_add_entity
    await entity.async_device_update(warning=False)
  File "/usr/src/homeassistant/homeassistant/helpers/entity.py", line 633, in async_device_update
    await task
  File "/usr/src/homeassistant/homeassistant/components/scrape/sensor.py", line 139, in async_update
    await self._async_update_from_rest_data()
  File "/usr/src/homeassistant/homeassistant/components/scrape/sensor.py", line 152, in _async_update_from_rest_data
    value = await self.hass.async_add_executor_job(self._extract_value)
  File "/usr/local/lib/python3.9/concurrent/futures/thread.py", line 52, in run
    result = self.fn(*self.args, **self.kwargs)
  File "/usr/src/homeassistant/homeassistant/components/scrape/sensor.py", line 128, in _extract_value
    tag = raw_data.select(self._select)[self._index]
  File "/usr/local/lib/python3.9/site-packages/bs4/element.py", line 1869, in select
    results = soupsieve.select(selector, self, namespaces, limit, **kwargs)
  File "/usr/local/lib/python3.9/site-packages/soupsieve/__init__.py", line 98, in select
    return compile(select, namespaces, flags, **kwargs).select(tag, limit)
  File "/usr/local/lib/python3.9/site-packages/soupsieve/__init__.py", line 62, in compile
    return cp._cached_css_compile(pattern, namespaces, custom, flags)
  File "/usr/local/lib/python3.9/site-packages/soupsieve/css_parser.py", line 211, in _cached_css_compile
    CSSParser(pattern, custom=custom_selectors, flags=flags).process_selectors(),
  File "/usr/local/lib/python3.9/site-packages/soupsieve/css_parser.py", line 1058, in process_selectors
    return self.parse_selectors(self.selector_iter(self.pattern), index, flags)
  File "/usr/local/lib/python3.9/site-packages/soupsieve/css_parser.py", line 909, in parse_selectors
    key, m = next(iselector)
  File "/usr/local/lib/python3.9/site-packages/soupsieve/css_parser.py", line 1051, in selector_iter
    raise SelectorSyntaxError(msg, self.pattern, index)
soupsieve.util.SelectorSyntaxError: Invalid character '<' position 0
  line 1:
<span _ngcontent-app-root-c173="">Offline</span>
^
2021-10-05 08:48:44 ERROR (MainThread) [homeassistant.components.camera] Error while setting up netatmo platform for camera
Traceback (most recent call last):
  File "/usr/local/lib/python3.9/site-packages/aiohttp/connector.py", line 969, in _wrap_create_connection
    return await self._loop.create_connection(*args, **kwargs)  # type: ignore  # noqa
  File "/usr/local/lib/python3.9/asyncio/base_events.py", line 1056, in create_connection
    raise exceptions[0]
  File "/usr/local/lib/python3.9/asyncio/base_events.py", line 1041, in create_connection
    sock = await self._connect_sock(
  File "/usr/local/lib/python3.9/asyncio/base_events.py", line 955, in _connect_sock
    await self.sock_connect(sock, address)
  File "/usr/local/lib/python3.9/asyncio/selector_events.py", line 502, in sock_connect
    return await fut
  File "/usr/local/lib/python3.9/asyncio/selector_events.py", line 537, in _sock_connect_cb
    raise OSError(err, f'Connect call failed {address}')
OSError: [Errno 113] Connect call failed ('169.254.56.16', 80)

The above exception was the direct cause of the following exception:

Traceback (most recent call last):
  File "/usr/src/homeassistant/homeassistant/helpers/entity_platform.py", line 249, in _async_setup_platform
    await asyncio.shield(task)
  File "/usr/src/homeassistant/homeassistant/components/netatmo/camera.py", line 62, in async_setup_entry
    await data_handler.register_data_class(
  File "/usr/src/homeassistant/homeassistant/components/netatmo/data_handler.py", line 192, in register_data_class
    await self.async_fetch_data(data_class_entry)
  File "/usr/src/homeassistant/homeassistant/components/netatmo/data_handler.py", line 149, in async_fetch_data
    await self.data[data_class_entry].async_update()
  File "/usr/local/lib/python3.9/site-packages/pyatmo/camera.py", line 607, in async_update
    await self._async_update_all_camera_urls()
  File "/usr/local/lib/python3.9/site-packages/pyatmo/camera.py", line 617, in _async_update_all_camera_urls
    await self.async_update_camera_urls(camera_id)
  File "/usr/local/lib/python3.9/site-packages/pyatmo/camera.py", line 696, in async_update_camera_urls
    self.cameras[home_id][camera_id]["local_url"] = await async_check_url(
  File "/usr/local/lib/python3.9/site-packages/pyatmo/camera.py", line 682, in async_check_url
    resp = await self.auth.async_post_request(url=f"{url}/command/ping")
  File "/usr/local/lib/python3.9/site-packages/pyatmo/auth.py", line 306, in async_post_request
    async with self.websession.post(
  File "/usr/local/lib/python3.9/site-packages/aiohttp/client.py", line 1117, in __aenter__
    self._resp = await self._coro
  File "/usr/local/lib/python3.9/site-packages/aiohttp/client.py", line 520, in _request
    conn = await self._connector.connect(
  File "/usr/local/lib/python3.9/site-packages/aiohttp/connector.py", line 535, in connect
    proto = await self._create_connection(req, traces, timeout)
  File "/usr/local/lib/python3.9/site-packages/aiohttp/connector.py", line 892, in _create_connection
    _, proto = await self._create_direct_connection(req, traces, timeout)
  File "/usr/local/lib/python3.9/site-packages/aiohttp/connector.py", line 1051, in _create_direct_connection
    raise last_exc
  File "/usr/local/lib/python3.9/site-packages/aiohttp/connector.py", line 1020, in _create_direct_connection
    transp, proto = await self._wrap_create_connection(
  File "/usr/local/lib/python3.9/site-packages/aiohttp/connector.py", line 975, in _wrap_create_connection
    raise client_error(req.connection_key, exc) from exc
aiohttp.client_exceptions.ClientConnectorError: Cannot connect to host 169.254.56.16:80 ssl:default [Connect call failed ('169.254.56.16', 80)]
2021-10-05 08:48:44 WARNING (MainThread) [homeassistant.config_entries] Config entry 'OnHub' for upnp integration not ready yet; Retrying in background
2021-10-05 08:49:00 WARNING (MainThread) [homeassistant.components.fan] Setup of fan platform xiaomi_miio_fan is taking over 10 seconds.
2021-10-05 08:49:00 WARNING (MainThread) [homeassistant.components.fan] Setup of fan platform xiaomi_miio_fan is taking over 10 seconds.
2021-10-05 08:49:00 ERROR (MainThread) [homeassistant.components.google_assistant.http] Request for https://homegraph.googleapis.com/v1/devices:requestSync failed: 500
2021-10-05 08:49:29 ERROR (MainThread) [homeassistant.components.google_assistant.http] Request for https://homegraph.googleapis.com/v1/devices:reportStateAndNotification failed: 404
2021-10-05 08:50:56 WARNING (MainThread) [homeassistant.components.media_player] Updating huesyncbox media_player took longer than the scheduled update interval 0:00:02
2021-10-05 08:50:58 WARNING (MainThread) [homeassistant.components.media_player] Updating huesyncbox media_player took longer than the scheduled update interval 0:00:02
2021-10-05 08:51:02 WARNING (MainThread) [homeassistant.components.media_player] Updating huesyncbox media_player took longer than the scheduled update interval 0:00:02
2021-10-05 08:51:04 WARNING (MainThread) [homeassistant.components.media_player] Updating huesyncbox media_player took longer than the scheduled update interval 0:00:02
2021-10-05 08:51:08 WARNING (MainThread) [homeassistant.components.media_player] Updating huesyncbox media_player took longer than the scheduled update interval 0:00:02
2021-10-05 08:51:10 WARNING (MainThread) [homeassistant.components.media_player] Updating huesyncbox media_player took longer than the scheduled update interval 0:00:02
2021-10-05 08:51:14 WARNING (MainThread) [homeassistant.components.media_player] Updating huesyncbox media_player took longer than the scheduled update interval 0:00:02
2021-10-05 08:51:16 WARNING (MainThread) [homeassistant.components.media_player] Updating huesyncbox media_player took longer than the scheduled update interval 0:00:02
2021-10-05 08:51:20 WARNING (MainThread) [homeassistant.components.media_player] Updating huesyncbox media_player took longer than the scheduled update interval 0:00:02
2021-10-05 09:00:03 ERROR (MainThread) [homeassistant.components.mobile_app.notify] Error sending notification to https://mobile-apps.home-assistant.io/api/sendPush/android/v1: ContentTypeError(RequestInfo(url=URL('https://mobile-apps.home-assistant.io/api/sendPush/android/v1'), method='POST', headers=<CIMultiDictProxy('Host': 'mobile-apps.home-assistant.io', 'User-Agent': 'HomeAssistant/2021.9.7 aiohttp/3.7.4.post0 Python/3.9', 'Accept': '*/*', 'Accept-Encoding': 'gzip, deflate', 'Content-Length': '740', 'Content-Type': 'application/json')>, real_url=URL('https://mobile-apps.home-assistant.io/api/sendPush/android/v1')), (), message='Attempt to decode JSON with unexpected mimetype: text/html; charset=utf-8', headers=<CIMultiDictProxy('Connection': 'keep-alive', 'Content-Length': '323', 'Content-Type': 'text/html; charset=UTF-8', 'Server': 'Google Frontend', 'Accept-Ranges': 'bytes', 'Date': 'Tue, 05 Oct 2021 09:00:03 GMT', 'X-Served-By': 'cache-ams21027-AMS', 'X-Cache': 'MISS', 'X-Cache-Hits': '0', 'X-Timer': 'S1633424400.223250,VS0,VE3280', 'Vary': 'x-fh-requested-host, accept-encoding')>)
2021-10-05 09:27:02 WARNING (MainThread) [homeassistant.helpers.service] Unable to find referenced entities media_player.veranda_speaker_2
2021-10-05 09:27:12 WARNING (MainThread) [homeassistant.helpers.service] Unable to find referenced entities camera.netatmo_eikenbos_oprit
2021-10-05 09:28:09 ERROR (Thread-18) [pychromecast.socket_client] [Groep_living_veranda(192.168.86.244):32106] Error reading from socket.
2021-10-05 09:28:09 WARNING (Thread-18) [pychromecast.socket_client] [Groep_living_veranda(192.168.86.244):32106] Error communicating with socket, resetting connection
2021-10-05 09:28:09 ERROR (Thread-17) [pychromecast.socket_client] [Living speaker(192.168.86.244):8009] Error reading from socket.
2021-10-05 09:28:09 WARNING (Thread-17) [pychromecast.socket_client] [Living speaker(192.168.86.244):8009] Error communicating with socket, resetting connection
2021-10-05 09:28:09 ERROR (Thread-18) [pychromecast.socket_client] [Groep_living_veranda(192.168.86.244):32106] Failed to connect to service ServiceInfo(type='host', data=('192.168.86.244', 32106)), retrying in 5.0s
2021-10-05 09:28:09 ERROR (Thread-17) [pychromecast.socket_client] [Living speaker(192.168.86.244):8009] Failed to connect to service ServiceInfo(type='host', data=('192.168.86.244', 8009)), retrying in 5.0s
2021-10-05 09:32:10 ERROR (SyncWorker_16) [glocaltokens.client] [Device - Nest Wifi router(id=2f2a9d15-0ae2-4ffe-b6c1-2ef24c742b8a)] local_auth_token must follow the correct format
2021-10-05 09:32:10 ERROR (SyncWorker_16) [glocaltokens.client] [Device - Nest Wifi router(id=e1e5a8d5-d21f-444d-95a9-c76d78c9bc79)] local_auth_token must follow the correct format
2021-10-05 09:32:10 ERROR (SyncWorker_16) [glocaltokens.client] [Device - Nest Wifi router(id=ea3de37c-ca74-4689-8171-1681b2f4f924)] local_auth_token must follow the correct format
2021-10-05 09:33:39 WARNING (SyncWorker_5) [pynuki] Call failed: <Response [200]>
2021-10-05 09:33:39 ERROR (MainThread) [homeassistant.components.nuki] Unexpected error fetching nuki devices data: Failed to update data for Nuki device 604932253
Traceback (most recent call last):
  File "/usr/src/homeassistant/homeassistant/helpers/update_coordinator.py", line 187, in _async_refresh
    self.data = await self._async_update_data()
  File "/usr/src/homeassistant/homeassistant/helpers/update_coordinator.py", line 147, in _async_update_data
    return await self.update_method()
  File "/usr/src/homeassistant/homeassistant/components/nuki/__init__.py", line 106, in async_update_data
    await hass.async_add_executor_job(_update_devices, locks + openers)
  File "/usr/local/lib/python3.9/concurrent/futures/thread.py", line 52, in run
    result = self.fn(*self.args, **self.kwargs)
  File "/usr/src/homeassistant/homeassistant/components/nuki/__init__.py", line 45, in _update_devices
    device.update(level)
  File "/usr/local/lib/python3.9/site-packages/pynuki/device.py", line 81, in update
    raise NukiUpdateException(
pynuki.exceptions.NukiUpdateException: Failed to update data for Nuki device 604932253
2021-10-05 09:36:10 WARNING (SyncWorker_12) [pynuki] Call failed: <Response [200]>
2021-10-05 09:36:10 ERROR (MainThread) [homeassistant.components.nuki] Unexpected error fetching nuki devices data: Failed to update data for Nuki device 604932253
Traceback (most recent call last):
  File "/usr/src/homeassistant/homeassistant/helpers/update_coordinator.py", line 187, in _async_refresh
    self.data = await self._async_update_data()
  File "/usr/src/homeassistant/homeassistant/helpers/update_coordinator.py", line 147, in _async_update_data
    return await self.update_method()
  File "/usr/src/homeassistant/homeassistant/components/nuki/__init__.py", line 106, in async_update_data
    await hass.async_add_executor_job(_update_devices, locks + openers)
  File "/usr/local/lib/python3.9/concurrent/futures/thread.py", line 52, in run
    result = self.fn(*self.args, **self.kwargs)
  File "/usr/src/homeassistant/homeassistant/components/nuki/__init__.py", line 45, in _update_devices
    device.update(level)
  File "/usr/local/lib/python3.9/site-packages/pynuki/device.py", line 81, in update
    raise NukiUpdateException(
pynuki.exceptions.NukiUpdateException: Failed to update data for Nuki device 604932253
2021-10-05 09:36:25 WARNING (MainThread) [homeassistant.helpers.service] Unable to find referenced entities media_player.veranda_speaker_2
2021-10-05 09:36:35 WARNING (MainThread) [homeassistant.helpers.service] Unable to find referenced entities camera.netatmo_eikenbos_oprit
2021-10-05 09:39:11 WARNING (SyncWorker_6) [pynuki] Call failed: <Response [200]>
2021-10-05 09:39:11 ERROR (MainThread) [homeassistant.components.nuki] Unexpected error fetching nuki devices data: Failed to update data for Nuki device 604932253
Traceback (most recent call last):
  File "/usr/src/homeassistant/homeassistant/helpers/update_coordinator.py", line 187, in _async_refresh
    self.data = await self._async_update_data()
  File "/usr/src/homeassistant/homeassistant/helpers/update_coordinator.py", line 147, in _async_update_data
    return await self.update_method()
  File "/usr/src/homeassistant/homeassistant/components/nuki/__init__.py", line 106, in async_update_data
    await hass.async_add_executor_job(_update_devices, locks + openers)
  File "/usr/local/lib/python3.9/concurrent/futures/thread.py", line 52, in run
    result = self.fn(*self.args, **self.kwargs)
  File "/usr/src/homeassistant/homeassistant/components/nuki/__init__.py", line 45, in _update_devices
    device.update(level)
  File "/usr/local/lib/python3.9/site-packages/pynuki/device.py", line 81, in update
    raise NukiUpdateException(
pynuki.exceptions.NukiUpdateException: Failed to update data for Nuki device 604932253
2021-10-05 09:40:11 WARNING (SyncWorker_0) [pynuki] Call failed: <Response [200]>
2021-10-05 09:40:11 ERROR (MainThread) [homeassistant.components.nuki] Unexpected error fetching nuki devices data: Failed to update data for Nuki device 604932253
Traceback (most recent call last):
  File "/usr/src/homeassistant/homeassistant/helpers/update_coordinator.py", line 187, in _async_refresh
    self.data = await self._async_update_data()
  File "/usr/src/homeassistant/homeassistant/helpers/update_coordinator.py", line 147, in _async_update_data
    return await self.update_method()
  File "/usr/src/homeassistant/homeassistant/components/nuki/__init__.py", line 106, in async_update_data
    await hass.async_add_executor_job(_update_devices, locks + openers)
  File "/usr/local/lib/python3.9/concurrent/futures/thread.py", line 52, in run
    result = self.fn(*self.args, **self.kwargs)
  File "/usr/src/homeassistant/homeassistant/components/nuki/__init__.py", line 45, in _update_devices
    device.update(level)
  File "/usr/local/lib/python3.9/site-packages/pynuki/device.py", line 81, in update
    raise NukiUpdateException(
pynuki.exceptions.NukiUpdateException: Failed to update data for Nuki device 604932253
2021-10-05 09:45:15 ERROR (Thread-124) [pychromecast.socket_client] [Master Bedroom TV(192.168.86.40):8009] Error reading from socket.
2021-10-05 09:45:15 WARNING (Thread-124) [pychromecast.socket_client] [Master Bedroom TV(192.168.86.40):8009] Error communicating with socket, resetting connection
2021-10-05 09:48:13 WARNING (SyncWorker_10) [pynuki] Call failed: <Response [200]>
2021-10-05 09:48:13 ERROR (MainThread) [homeassistant.components.nuki] Unexpected error fetching nuki devices data: Failed to update data for Nuki device 604932253
Traceback (most recent call last):
  File "/usr/src/homeassistant/homeassistant/helpers/update_coordinator.py", line 187, in _async_refresh
    self.data = await self._async_update_data()
  File "/usr/src/homeassistant/homeassistant/helpers/update_coordinator.py", line 147, in _async_update_data
    return await self.update_method()
  File "/usr/src/homeassistant/homeassistant/components/nuki/__init__.py", line 106, in async_update_data
    await hass.async_add_executor_job(_update_devices, locks + openers)
  File "/usr/local/lib/python3.9/concurrent/futures/thread.py", line 52, in run
    result = self.fn(*self.args, **self.kwargs)
  File "/usr/src/homeassistant/homeassistant/components/nuki/__init__.py", line 45, in _update_devices
    device.update(level)
  File "/usr/local/lib/python3.9/site-packages/pynuki/device.py", line 81, in update
    raise NukiUpdateException(
pynuki.exceptions.NukiUpdateException: Failed to update data for Nuki device 604932253
2021-10-05 09:49:13 WARNING (SyncWorker_8) [pynuki] Call failed: <Response [200]>
2021-10-05 09:49:13 ERROR (MainThread) [homeassistant.components.nuki] Unexpected error fetching nuki devices data: Failed to update data for Nuki device 604932253
Traceback (most recent call last):
  File "/usr/src/homeassistant/homeassistant/helpers/update_coordinator.py", line 187, in _async_refresh
    self.data = await self._async_update_data()
  File "/usr/src/homeassistant/homeassistant/helpers/update_coordinator.py", line 147, in _async_update_data
    return await self.update_method()
  File "/usr/src/homeassistant/homeassistant/components/nuki/__init__.py", line 106, in async_update_data
    await hass.async_add_executor_job(_update_devices, locks + openers)
  File "/usr/local/lib/python3.9/concurrent/futures/thread.py", line 52, in run
    result = self.fn(*self.args, **self.kwargs)
  File "/usr/src/homeassistant/homeassistant/components/nuki/__init__.py", line 45, in _update_devices
    device.update(level)
  File "/usr/local/lib/python3.9/site-packages/pynuki/device.py", line 81, in update
    raise NukiUpdateException(
pynuki.exceptions.NukiUpdateException: Failed to update data for Nuki device 604932253
2021-10-05 09:52:43 WARNING (SyncWorker_5) [pynuki] Call failed: <Response [200]>
2021-10-05 09:52:43 ERROR (MainThread) [homeassistant.components.nuki] Unexpected error fetching nuki devices data: Failed to update data for Nuki device 604932253
Traceback (most recent call last):
  File "/usr/src/homeassistant/homeassistant/helpers/update_coordinator.py", line 187, in _async_refresh
    self.data = await self._async_update_data()
  File "/usr/src/homeassistant/homeassistant/helpers/update_coordinator.py", line 147, in _async_update_data
    return await self.update_method()
  File "/usr/src/homeassistant/homeassistant/components/nuki/__init__.py", line 106, in async_update_data
    await hass.async_add_executor_job(_update_devices, locks + openers)
  File "/usr/local/lib/python3.9/concurrent/futures/thread.py", line 52, in run
    result = self.fn(*self.args, **self.kwargs)
  File "/usr/src/homeassistant/homeassistant/components/nuki/__init__.py", line 45, in _update_devices
    device.update(level)
  File "/usr/local/lib/python3.9/site-packages/pynuki/device.py", line 81, in update
    raise NukiUpdateException(
pynuki.exceptions.NukiUpdateException: Failed to update data for Nuki device 604932253
2021-10-05 09:53:13 WARNING (SyncWorker_18) [pynuki] Call failed: <Response [200]>
2021-10-05 09:53:13 ERROR (MainThread) [homeassistant.components.nuki] Unexpected error fetching nuki devices data: Failed to update data for Nuki device 604932253
Traceback (most recent call last):
  File "/usr/src/homeassistant/homeassistant/helpers/update_coordinator.py", line 187, in _async_refresh
    self.data = await self._async_update_data()
  File "/usr/src/homeassistant/homeassistant/helpers/update_coordinator.py", line 147, in _async_update_data
    return await self.update_method()
  File "/usr/src/homeassistant/homeassistant/components/nuki/__init__.py", line 106, in async_update_data
    await hass.async_add_executor_job(_update_devices, locks + openers)
  File "/usr/local/lib/python3.9/concurrent/futures/thread.py", line 52, in run
    result = self.fn(*self.args, **self.kwargs)
  File "/usr/src/homeassistant/homeassistant/components/nuki/__init__.py", line 45, in _update_devices
    device.update(level)
  File "/usr/local/lib/python3.9/site-packages/pynuki/device.py", line 81, in update
    raise NukiUpdateException(
pynuki.exceptions.NukiUpdateException: Failed to update data for Nuki device 604932253
2021-10-05 09:53:43 WARNING (SyncWorker_8) [pynuki] Call failed: <Response [200]>
2021-10-05 09:53:43 ERROR (MainThread) [homeassistant.components.nuki] Unexpected error fetching nuki devices data: Failed to update data for Nuki device 604932253
Traceback (most recent call last):
  File "/usr/src/homeassistant/homeassistant/helpers/update_coordinator.py", line 187, in _async_refresh
    self.data = await self._async_update_data()
  File "/usr/src/homeassistant/homeassistant/helpers/update_coordinator.py", line 147, in _async_update_data
    return await self.update_method()
  File "/usr/src/homeassistant/homeassistant/components/nuki/__init__.py", line 106, in async_update_data
    await hass.async_add_executor_job(_update_devices, locks + openers)
  File "/usr/local/lib/python3.9/concurrent/futures/thread.py", line 52, in run
    result = self.fn(*self.args, **self.kwargs)
  File "/usr/src/homeassistant/homeassistant/components/nuki/__init__.py", line 45, in _update_devices
    device.update(level)
  File "/usr/local/lib/python3.9/site-packages/pynuki/device.py", line 81, in update
    raise NukiUpdateException(
pynuki.exceptions.NukiUpdateException: Failed to update data for Nuki device 604932253
2021-10-05 09:54:13 WARNING (SyncWorker_6) [pynuki] Call failed: <Response [200]>
2021-10-05 09:54:13 ERROR (MainThread) [homeassistant.components.nuki] Unexpected error fetching nuki devices data: Failed to update data for Nuki device 604932253
Traceback (most recent call last):
  File "/usr/src/homeassistant/homeassistant/helpers/update_coordinator.py", line 187, in _async_refresh
    self.data = await self._async_update_data()
  File "/usr/src/homeassistant/homeassistant/helpers/update_coordinator.py", line 147, in _async_update_data
    return await self.update_method()
  File "/usr/src/homeassistant/homeassistant/components/nuki/__init__.py", line 106, in async_update_data
    await hass.async_add_executor_job(_update_devices, locks + openers)
  File "/usr/local/lib/python3.9/concurrent/futures/thread.py", line 52, in run
    result = self.fn(*self.args, **self.kwargs)
  File "/usr/src/homeassistant/homeassistant/components/nuki/__init__.py", line 45, in _update_devices
    device.update(level)
  File "/usr/local/lib/python3.9/site-packages/pynuki/device.py", line 81, in update
    raise NukiUpdateException(
pynuki.exceptions.NukiUpdateException: Failed to update data for Nuki device 604932253
2021-10-05 09:54:43 WARNING (SyncWorker_16) [pynuki] Call failed: <Response [200]>
2021-10-05 09:54:43 ERROR (MainThread) [homeassistant.components.nuki] Unexpected error fetching nuki devices data: Failed to update data for Nuki device 604932253
Traceback (most recent call last):
  File "/usr/src/homeassistant/homeassistant/helpers/update_coordinator.py", line 187, in _async_refresh
    self.data = await self._async_update_data()
  File "/usr/src/homeassistant/homeassistant/helpers/update_coordinator.py", line 147, in _async_update_data
    return await self.update_method()
  File "/usr/src/homeassistant/homeassistant/components/nuki/__init__.py", line 106, in async_update_data
    await hass.async_add_executor_job(_update_devices, locks + openers)
  File "/usr/local/lib/python3.9/concurrent/futures/thread.py", line 52, in run
    result = self.fn(*self.args, **self.kwargs)
  File "/usr/src/homeassistant/homeassistant/components/nuki/__init__.py", line 45, in _update_devices
    device.update(level)
  File "/usr/local/lib/python3.9/site-packages/pynuki/device.py", line 81, in update
    raise NukiUpdateException(
pynuki.exceptions.NukiUpdateException: Failed to update data for Nuki device 604932253
2021-10-05 09:56:13 WARNING (SyncWorker_15) [pynuki] Call failed: <Response [200]>
2021-10-05 09:56:13 ERROR (MainThread) [homeassistant.components.nuki] Unexpected error fetching nuki devices data: Failed to update data for Nuki device 604932253
Traceback (most recent call last):
  File "/usr/src/homeassistant/homeassistant/helpers/update_coordinator.py", line 187, in _async_refresh
    self.data = await self._async_update_data()
  File "/usr/src/homeassistant/homeassistant/helpers/update_coordinator.py", line 147, in _async_update_data
    return await self.update_method()
  File "/usr/src/homeassistant/homeassistant/components/nuki/__init__.py", line 106, in async_update_data
    await hass.async_add_executor_job(_update_devices, locks + openers)
  File "/usr/local/lib/python3.9/concurrent/futures/thread.py", line 52, in run
    result = self.fn(*self.args, **self.kwargs)
  File "/usr/src/homeassistant/homeassistant/components/nuki/__init__.py", line 45, in _update_devices
    device.update(level)
  File "/usr/local/lib/python3.9/site-packages/pynuki/device.py", line 81, in update
    raise NukiUpdateException(
pynuki.exceptions.NukiUpdateException: Failed to update data for Nuki device 604932253
2021-10-05 09:59:46 WARNING (SyncWorker_0) [pynuki] Call failed: <Response [200]>
2021-10-05 09:59:46 ERROR (MainThread) [homeassistant.components.nuki] Unexpected error fetching nuki devices data: Failed to update data for Nuki device 604932253
Traceback (most recent call last):
  File "/usr/src/homeassistant/homeassistant/helpers/update_coordinator.py", line 187, in _async_refresh
    self.data = await self._async_update_data()
  File "/usr/src/homeassistant/homeassistant/helpers/update_coordinator.py", line 147, in _async_update_data
    return await self.update_method()
  File "/usr/src/homeassistant/homeassistant/components/nuki/__init__.py", line 106, in async_update_data
    await hass.async_add_executor_job(_update_devices, locks + openers)
  File "/usr/local/lib/python3.9/concurrent/futures/thread.py", line 52, in run
    result = self.fn(*self.args, **self.kwargs)
  File "/usr/src/homeassistant/homeassistant/components/nuki/__init__.py", line 45, in _update_devices
    device.update(level)
  File "/usr/local/lib/python3.9/site-packages/pynuki/device.py", line 81, in update
    raise NukiUpdateException(
pynuki.exceptions.NukiUpdateException: Failed to update data for Nuki device 604932253
2021-10-05 10:00:16 WARNING (SyncWorker_6) [pynuki] Call failed: <Response [200]>
2021-10-05 10:00:16 ERROR (MainThread) [homeassistant.components.nuki] Unexpected error fetching nuki devices data: Failed to update data for Nuki device 604932253
Traceback (most recent call last):
  File "/usr/src/homeassistant/homeassistant/helpers/update_coordinator.py", line 187, in _async_refresh
    self.data = await self._async_update_data()
  File "/usr/src/homeassistant/homeassistant/helpers/update_coordinator.py", line 147, in _async_update_data
    return await self.update_method()
  File "/usr/src/homeassistant/homeassistant/components/nuki/__init__.py", line 106, in async_update_data
    await hass.async_add_executor_job(_update_devices, locks + openers)
  File "/usr/local/lib/python3.9/concurrent/futures/thread.py", line 52, in run
    result = self.fn(*self.args, **self.kwargs)
  File "/usr/src/homeassistant/homeassistant/components/nuki/__init__.py", line 45, in _update_devices
    device.update(level)
  File "/usr/local/lib/python3.9/site-packages/pynuki/device.py", line 81, in update
    raise NukiUpdateException(
pynuki.exceptions.NukiUpdateException: Failed to update data for Nuki device 604932253
2021-10-05 10:02:51 WARNING (SyncWorker_14) [pynuki] Call failed: <Response [200]>
2021-10-05 10:02:52 ERROR (MainThread) [homeassistant.components.nuki] Unexpected error fetching nuki devices data: Failed to update data for Nuki device 604932253
Traceback (most recent call last):
  File "/usr/src/homeassistant/homeassistant/helpers/update_coordinator.py", line 187, in _async_refresh
    self.data = await self._async_update_data()
  File "/usr/src/homeassistant/homeassistant/helpers/update_coordinator.py", line 147, in _async_update_data
    return await self.update_method()
  File "/usr/src/homeassistant/homeassistant/components/nuki/__init__.py", line 106, in async_update_data
    await hass.async_add_executor_job(_update_devices, locks + openers)
  File "/usr/local/lib/python3.9/concurrent/futures/thread.py", line 52, in run
    result = self.fn(*self.args, **self.kwargs)
  File "/usr/src/homeassistant/homeassistant/components/nuki/__init__.py", line 45, in _update_devices
    device.update(level)
  File "/usr/local/lib/python3.9/site-packages/pynuki/device.py", line 81, in update
    raise NukiUpdateException(
pynuki.exceptions.NukiUpdateException: Failed to update data for Nuki device 604932253
2021-10-05 10:06:55 WARNING (SyncWorker_16) [pynuki] Call failed: <Response [200]>
2021-10-05 10:06:55 ERROR (MainThread) [homeassistant.components.nuki] Unexpected error fetching nuki devices data: Failed to update data for Nuki device 604932253
Traceback (most recent call last):
  File "/usr/src/homeassistant/homeassistant/helpers/update_coordinator.py", line 187, in _async_refresh
    self.data = await self._async_update_data()
  File "/usr/src/homeassistant/homeassistant/helpers/update_coordinator.py", line 147, in _async_update_data
    return await self.update_method()
  File "/usr/src/homeassistant/homeassistant/components/nuki/__init__.py", line 106, in async_update_data
    await hass.async_add_executor_job(_update_devices, locks + openers)
  File "/usr/local/lib/python3.9/concurrent/futures/thread.py", line 52, in run
    result = self.fn(*self.args, **self.kwargs)
  File "/usr/src/homeassistant/homeassistant/components/nuki/__init__.py", line 45, in _update_devices
    device.update(level)
  File "/usr/local/lib/python3.9/site-packages/pynuki/device.py", line 81, in update
    raise NukiUpdateException(
pynuki.exceptions.NukiUpdateException: Failed to update data for Nuki device 604932253
2021-10-05 10:09:30 WARNING (SyncWorker_14) [pynuki] Call failed: <Response [200]>
2021-10-05 10:09:30 ERROR (MainThread) [homeassistant.components.nuki] Unexpected error fetching nuki devices data: Failed to update data for Nuki device 604932253
Traceback (most recent call last):
  File "/usr/src/homeassistant/homeassistant/helpers/update_coordinator.py", line 187, in _async_refresh
    self.data = await self._async_update_data()
  File "/usr/src/homeassistant/homeassistant/helpers/update_coordinator.py", line 147, in _async_update_data
    return await self.update_method()
  File "/usr/src/homeassistant/homeassistant/components/nuki/__init__.py", line 106, in async_update_data
    await hass.async_add_executor_job(_update_devices, locks + openers)
  File "/usr/local/lib/python3.9/concurrent/futures/thread.py", line 52, in run
    result = self.fn(*self.args, **self.kwargs)
  File "/usr/src/homeassistant/homeassistant/components/nuki/__init__.py", line 45, in _update_devices
    device.update(level)
  File "/usr/local/lib/python3.9/site-packages/pynuki/device.py", line 81, in update
    raise NukiUpdateException(
pynuki.exceptions.NukiUpdateException: Failed to update data for Nuki device 604932253
2021-10-05 10:11:00 WARNING (SyncWorker_16) [pynuki] Call failed: <Response [200]>
2021-10-05 10:11:00 ERROR (MainThread) [homeassistant.components.nuki] Unexpected error fetching nuki devices data: Failed to update data for Nuki device 604932253
Traceback (most recent call last):
  File "/usr/src/homeassistant/homeassistant/helpers/update_coordinator.py", line 187, in _async_refresh
    self.data = await self._async_update_data()
  File "/usr/src/homeassistant/homeassistant/helpers/update_coordinator.py", line 147, in _async_update_data
    return await self.update_method()
  File "/usr/src/homeassistant/homeassistant/components/nuki/__init__.py", line 106, in async_update_data
    await hass.async_add_executor_job(_update_devices, locks + openers)
  File "/usr/local/lib/python3.9/concurrent/futures/thread.py", line 52, in run
    result = self.fn(*self.args, **self.kwargs)
  File "/usr/src/homeassistant/homeassistant/components/nuki/__init__.py", line 45, in _update_devices
    device.update(level)
  File "/usr/local/lib/python3.9/site-packages/pynuki/device.py", line 81, in update
    raise NukiUpdateException(
pynuki.exceptions.NukiUpdateException: Failed to update data for Nuki device 604932253
2021-10-05 10:12:33 WARNING (SyncWorker_13) [pynuki] Call failed: <Response [200]>
2021-10-05 10:12:33 ERROR (MainThread) [homeassistant.components.nuki] Unexpected error fetching nuki devices data: Failed to update data for Nuki device 604932253
Traceback (most recent call last):
  File "/usr/src/homeassistant/homeassistant/helpers/update_coordinator.py", line 187, in _async_refresh
    self.data = await self._async_update_data()
  File "/usr/src/homeassistant/homeassistant/helpers/update_coordinator.py", line 147, in _async_update_data
    return await self.update_method()
  File "/usr/src/homeassistant/homeassistant/components/nuki/__init__.py", line 106, in async_update_data
    await hass.async_add_executor_job(_update_devices, locks + openers)
  File "/usr/local/lib/python3.9/concurrent/futures/thread.py", line 52, in run
    result = self.fn(*self.args, **self.kwargs)
  File "/usr/src/homeassistant/homeassistant/components/nuki/__init__.py", line 45, in _update_devices
    device.update(level)
  File "/usr/local/lib/python3.9/site-packages/pynuki/device.py", line 81, in update
    raise NukiUpdateException(
pynuki.exceptions.NukiUpdateException: Failed to update data for Nuki device 604932253
2021-10-05 10:13:35 WARNING (SyncWorker_10) [pynuki] Call failed: <Response [200]>
2021-10-05 10:13:35 ERROR (MainThread) [homeassistant.components.nuki] Unexpected error fetching nuki devices data: Failed to update data for Nuki device 604932253
Traceback (most recent call last):
  File "/usr/src/homeassistant/homeassistant/helpers/update_coordinator.py", line 187, in _async_refresh
    self.data = await self._async_update_data()
  File "/usr/src/homeassistant/homeassistant/helpers/update_coordinator.py", line 147, in _async_update_data
    return await self.update_method()
  File "/usr/src/homeassistant/homeassistant/components/nuki/__init__.py", line 106, in async_update_data
    await hass.async_add_executor_job(_update_devices, locks + openers)
  File "/usr/local/lib/python3.9/concurrent/futures/thread.py", line 52, in run
    result = self.fn(*self.args, **self.kwargs)
  File "/usr/src/homeassistant/homeassistant/components/nuki/__init__.py", line 45, in _update_devices
    device.update(level)
  File "/usr/local/lib/python3.9/site-packages/pynuki/device.py", line 81, in update
    raise NukiUpdateException(
pynuki.exceptions.NukiUpdateException: Failed to update data for Nuki device 604932253
2021-10-05 10:17:07 WARNING (SyncWorker_3) [pynuki] Call failed: <Response [200]>
2021-10-05 10:17:07 ERROR (MainThread) [homeassistant.components.nuki] Unexpected error fetching nuki devices data: Failed to update data for Nuki device 604932253
Traceback (most recent call last):
  File "/usr/src/homeassistant/homeassistant/helpers/update_coordinator.py", line 187, in _async_refresh
    self.data = await self._async_update_data()
  File "/usr/src/homeassistant/homeassistant/helpers/update_coordinator.py", line 147, in _async_update_data
    return await self.update_method()
  File "/usr/src/homeassistant/homeassistant/components/nuki/__init__.py", line 106, in async_update_data
    await hass.async_add_executor_job(_update_devices, locks + openers)
  File "/usr/local/lib/python3.9/concurrent/futures/thread.py", line 52, in run
    result = self.fn(*self.args, **self.kwargs)
  File "/usr/src/homeassistant/homeassistant/components/nuki/__init__.py", line 45, in _update_devices
    device.update(level)
  File "/usr/local/lib/python3.9/site-packages/pynuki/device.py", line 81, in update
    raise NukiUpdateException(
pynuki.exceptions.NukiUpdateException: Failed to update data for Nuki device 604932253
2021-10-05 10:19:11 WARNING (SyncWorker_14) [pynuki] Call failed: <Response [200]>
2021-10-05 10:19:11 ERROR (MainThread) [homeassistant.components.nuki] Unexpected error fetching nuki devices data: Failed to update data for Nuki device 604932253
Traceback (most recent call last):
  File "/usr/src/homeassistant/homeassistant/helpers/update_coordinator.py", line 187, in _async_refresh
    self.data = await self._async_update_data()
  File "/usr/src/homeassistant/homeassistant/helpers/update_coordinator.py", line 147, in _async_update_data
    return await self.update_method()
  File "/usr/src/homeassistant/homeassistant/components/nuki/__init__.py", line 106, in async_update_data
    await hass.async_add_executor_job(_update_devices, locks + openers)
  File "/usr/local/lib/python3.9/concurrent/futures/thread.py", line 52, in run
    result = self.fn(*self.args, **self.kwargs)
  File "/usr/src/homeassistant/homeassistant/components/nuki/__init__.py", line 45, in _update_devices
    device.update(level)
  File "/usr/local/lib/python3.9/site-packages/pynuki/device.py", line 81, in update
    raise NukiUpdateException(
pynuki.exceptions.NukiUpdateException: Failed to update data for Nuki device 604932253
2021-10-05 10:28:48 WARNING (SyncWorker_3) [buienalarm.pybuienalarm] Error fetching data safely: HTTPSConnectionPool(host='cdn-secure.buienalarm.nl', port=443): Read timed out. (read timeout=10.0)
2021-10-05 10:34:31 WARNING (SyncWorker_13) [pynuki] Call failed: <Response [200]>
2021-10-05 10:34:31 ERROR (MainThread) [homeassistant.components.nuki] Unexpected error fetching nuki devices data: Failed to update data for Nuki device 604932253
Traceback (most recent call last):
  File "/usr/src/homeassistant/homeassistant/helpers/update_coordinator.py", line 187, in _async_refresh
    self.data = await self._async_update_data()
  File "/usr/src/homeassistant/homeassistant/helpers/update_coordinator.py", line 147, in _async_update_data
    return await self.update_method()
  File "/usr/src/homeassistant/homeassistant/components/nuki/__init__.py", line 106, in async_update_data
    await hass.async_add_executor_job(_update_devices, locks + openers)
  File "/usr/local/lib/python3.9/concurrent/futures/thread.py", line 52, in run
    result = self.fn(*self.args, **self.kwargs)
  File "/usr/src/homeassistant/homeassistant/components/nuki/__init__.py", line 45, in _update_devices
    device.update(level)
  File "/usr/local/lib/python3.9/site-packages/pynuki/device.py", line 81, in update
    raise NukiUpdateException(
pynuki.exceptions.NukiUpdateException: Failed to update data for Nuki device 604932253
2021-10-05 10:36:35 WARNING (SyncWorker_5) [pynuki] Call failed: <Response [200]>
2021-10-05 10:36:35 ERROR (MainThread) [homeassistant.components.nuki] Unexpected error fetching nuki devices data: Failed to update data for Nuki device 604932253
Traceback (most recent call last):
  File "/usr/src/homeassistant/homeassistant/helpers/update_coordinator.py", line 187, in _async_refresh
    self.data = await self._async_update_data()
  File "/usr/src/homeassistant/homeassistant/helpers/update_coordinator.py", line 147, in _async_update_data
    return await self.update_method()
  File "/usr/src/homeassistant/homeassistant/components/nuki/__init__.py", line 106, in async_update_data
    await hass.async_add_executor_job(_update_devices, locks + openers)
  File "/usr/local/lib/python3.9/concurrent/futures/thread.py", line 52, in run
    result = self.fn(*self.args, **self.kwargs)
  File "/usr/src/homeassistant/homeassistant/components/nuki/__init__.py", line 45, in _update_devices
    device.update(level)
  File "/usr/local/lib/python3.9/site-packages/pynuki/device.py", line 81, in update
    raise NukiUpdateException(
pynuki.exceptions.NukiUpdateException: Failed to update data for Nuki device 604932253
2021-10-05 10:38:05 WARNING (SyncWorker_12) [pynuki] Call failed: <Response [200]>
2021-10-05 10:38:05 ERROR (MainThread) [homeassistant.components.nuki] Unexpected error fetching nuki devices data: Failed to update data for Nuki device 604932253
Traceback (most recent call last):
  File "/usr/src/homeassistant/homeassistant/helpers/update_coordinator.py", line 187, in _async_refresh
    self.data = await self._async_update_data()
  File "/usr/src/homeassistant/homeassistant/helpers/update_coordinator.py", line 147, in _async_update_data
    return await self.update_method()
  File "/usr/src/homeassistant/homeassistant/components/nuki/__init__.py", line 106, in async_update_data
    await hass.async_add_executor_job(_update_devices, locks + openers)
  File "/usr/local/lib/python3.9/concurrent/futures/thread.py", line 52, in run
    result = self.fn(*self.args, **self.kwargs)
  File "/usr/src/homeassistant/homeassistant/components/nuki/__init__.py", line 45, in _update_devices
    device.update(level)
  File "/usr/local/lib/python3.9/site-packages/pynuki/device.py", line 81, in update
    raise NukiUpdateException(
pynuki.exceptions.NukiUpdateException: Failed to update data for Nuki device 604932253
2021-10-05 10:39:36 WARNING (SyncWorker_9) [pynuki] Call failed: <Response [200]>
2021-10-05 10:39:36 ERROR (MainThread) [homeassistant.components.nuki] Unexpected error fetching nuki devices data: Failed to update data for Nuki device 604932253
Traceback (most recent call last):
  File "/usr/src/homeassistant/homeassistant/helpers/update_coordinator.py", line 187, in _async_refresh
    self.data = await self._async_update_data()
  File "/usr/src/homeassistant/homeassistant/helpers/update_coordinator.py", line 147, in _async_update_data
    return await self.update_method()
  File "/usr/src/homeassistant/homeassistant/components/nuki/__init__.py", line 106, in async_update_data
    await hass.async_add_executor_job(_update_devices, locks + openers)
  File "/usr/local/lib/python3.9/concurrent/futures/thread.py", line 52, in run
    result = self.fn(*self.args, **self.kwargs)
  File "/usr/src/homeassistant/homeassistant/components/nuki/__init__.py", line 45, in _update_devices
    device.update(level)
  File "/usr/local/lib/python3.9/site-packages/pynuki/device.py", line 81, in update
    raise NukiUpdateException(
pynuki.exceptions.NukiUpdateException: Failed to update data for Nuki device 604932253
2021-10-05 10:43:48 WARNING (SyncWorker_6) [buienalarm.pybuienalarm] Error fetching data safely: 502 Server Error: Bad Gateway for url: https://cdn-secure.buienalarm.nl/api/3.4/forecast.php?lat=50.878800118427755&lon=4.749415398691782&region=nl&unit=mm%2Fu
2021-10-05 10:45:00 WARNING (MainThread) [homeassistant.components.automation] Error evaluating condition in '🪟 ramen - sluit raam Amilya (Bart en Madouce)':
In 'condition' (item 2 of 2):
  In 'or' (item 2 of 2):
    In 'state':
      In 'state' condition: unknown entity input_boolean.kamer_amylia_window_pause
2021-10-05 10:47:49 WARNING (SyncWorker_18) [pynuki] Call failed: <Response [200]>
2021-10-05 10:47:49 ERROR (MainThread) [homeassistant.components.nuki] Unexpected error fetching nuki devices data: Failed to update data for Nuki device 604932253
Traceback (most recent call last):
  File "/usr/src/homeassistant/homeassistant/helpers/update_coordinator.py", line 187, in _async_refresh
    self.data = await self._async_update_data()
  File "/usr/src/homeassistant/homeassistant/helpers/update_coordinator.py", line 147, in _async_update_data
    return await self.update_method()
  File "/usr/src/homeassistant/homeassistant/components/nuki/__init__.py", line 106, in async_update_data
    await hass.async_add_executor_job(_update_devices, locks + openers)
  File "/usr/local/lib/python3.9/concurrent/futures/thread.py", line 52, in run
    result = self.fn(*self.args, **self.kwargs)
  File "/usr/src/homeassistant/homeassistant/components/nuki/__init__.py", line 45, in _update_devices
    device.update(level)
  File "/usr/local/lib/python3.9/site-packages/pynuki/device.py", line 81, in update
    raise NukiUpdateException(
pynuki.exceptions.NukiUpdateException: Failed to update data for Nuki device 604932253
2021-10-05 10:49:53 WARNING (SyncWorker_16) [pynuki] Call failed: <Response [200]>
2021-10-05 10:49:53 ERROR (MainThread) [homeassistant.components.nuki] Unexpected error fetching nuki devices data: Failed to update data for Nuki device 604932253
Traceback (most recent call last):
  File "/usr/src/homeassistant/homeassistant/helpers/update_coordinator.py", line 187, in _async_refresh
    self.data = await self._async_update_data()
  File "/usr/src/homeassistant/homeassistant/helpers/update_coordinator.py", line 147, in _async_update_data
    return await self.update_method()
  File "/usr/src/homeassistant/homeassistant/components/nuki/__init__.py", line 106, in async_update_data
    await hass.async_add_executor_job(_update_devices, locks + openers)
  File "/usr/local/lib/python3.9/concurrent/futures/thread.py", line 52, in run
    result = self.fn(*self.args, **self.kwargs)
  File "/usr/src/homeassistant/homeassistant/components/nuki/__init__.py", line 45, in _update_devices
    device.update(level)
  File "/usr/local/lib/python3.9/site-packages/pynuki/device.py", line 81, in update
    raise NukiUpdateException(
pynuki.exceptions.NukiUpdateException: Failed to update data for Nuki device 604932253
2021-10-05 10:50:56 WARNING (SyncWorker_5) [pynuki] Call failed: <Response [200]>
2021-10-05 10:50:56 ERROR (MainThread) [homeassistant.components.nuki] Unexpected error fetching nuki devices data: Failed to update data for Nuki device 604932253
Traceback (most recent call last):
  File "/usr/src/homeassistant/homeassistant/helpers/update_coordinator.py", line 187, in _async_refresh
    self.data = await self._async_update_data()
  File "/usr/src/homeassistant/homeassistant/helpers/update_coordinator.py", line 147, in _async_update_data
    return await self.update_method()
  File "/usr/src/homeassistant/homeassistant/components/nuki/__init__.py", line 106, in async_update_data
    await hass.async_add_executor_job(_update_devices, locks + openers)
  File "/usr/local/lib/python3.9/concurrent/futures/thread.py", line 52, in run
    result = self.fn(*self.args, **self.kwargs)
  File "/usr/src/homeassistant/homeassistant/components/nuki/__init__.py", line 45, in _update_devices
    device.update(level)
  File "/usr/local/lib/python3.9/site-packages/pynuki/device.py", line 81, in update
    raise NukiUpdateException(
pynuki.exceptions.NukiUpdateException: Failed to update data for Nuki device 604932253
2021-10-05 10:57:46 WARNING (MainThread) [homeassistant.components.automation] Error evaluating condition in 'Regen en raam open = melding':
In 'condition':
  In 'state':
    In 'state' condition: unknown entity binary_sensor.kamer_amilya_window_sensor
2021-10-05 10:57:46 ERROR (MainThread) [homeassistant.components.automation.het_regent] het regent: Error executing script. Invalid data for call_service at pos 1: extra keys not allowed @ data['tag']
2021-10-05 10:57:46 ERROR (MainThread) [homeassistant.components.automation.het_regent] Error while executing automation automation.het_regent: extra keys not allowed @ data['tag']
2021-10-05 10:58:38 WARNING (SyncWorker_11) [pynuki] Call failed: <Response [200]>
2021-10-05 10:58:39 ERROR (MainThread) [homeassistant.components.nuki] Unexpected error fetching nuki devices data: Failed to update data for Nuki device 604932253
Traceback (most recent call last):
  File "/usr/src/homeassistant/homeassistant/helpers/update_coordinator.py", line 187, in _async_refresh
    self.data = await self._async_update_data()
  File "/usr/src/homeassistant/homeassistant/helpers/update_coordinator.py", line 147, in _async_update_data
    return await self.update_method()
  File "/usr/src/homeassistant/homeassistant/components/nuki/__init__.py", line 106, in async_update_data
    await hass.async_add_executor_job(_update_devices, locks + openers)
  File "/usr/local/lib/python3.9/concurrent/futures/thread.py", line 52, in run
    result = self.fn(*self.args, **self.kwargs)
  File "/usr/src/homeassistant/homeassistant/components/nuki/__init__.py", line 45, in _update_devices
    device.update(level)
  File "/usr/local/lib/python3.9/site-packages/pynuki/device.py", line 81, in update
    raise NukiUpdateException(
pynuki.exceptions.NukiUpdateException: Failed to update data for Nuki device 604932253
2021-10-05 10:59:40 WARNING (SyncWorker_17) [pynuki] Call failed: <Response [200]>
2021-10-05 10:59:40 ERROR (MainThread) [homeassistant.components.nuki] Unexpected error fetching nuki devices data: Failed to update data for Nuki device 604932253
Traceback (most recent call last):
  File "/usr/src/homeassistant/homeassistant/helpers/update_coordinator.py", line 187, in _async_refresh
    self.data = await self._async_update_data()
  File "/usr/src/homeassistant/homeassistant/helpers/update_coordinator.py", line 147, in _async_update_data
    return await self.update_method()
  File "/usr/src/homeassistant/homeassistant/components/nuki/__init__.py", line 106, in async_update_data
    await hass.async_add_executor_job(_update_devices, locks + openers)
  File "/usr/local/lib/python3.9/concurrent/futures/thread.py", line 52, in run
    result = self.fn(*self.args, **self.kwargs)
  File "/usr/src/homeassistant/homeassistant/components/nuki/__init__.py", line 45, in _update_devices
    device.update(level)
  File "/usr/local/lib/python3.9/site-packages/pynuki/device.py", line 81, in update
    raise NukiUpdateException(
pynuki.exceptions.NukiUpdateException: Failed to update data for Nuki device 604932253
2021-10-05 11:00:00 WARNING (MainThread) [homeassistant.components.automation] Error evaluating condition in '🪟 ramen - sluit raam Amilya (Bart en Madouce)':
In 'condition' (item 2 of 2):
  In 'or' (item 2 of 2):
    In 'state':
      In 'state' condition: unknown entity input_boolean.kamer_amylia_window_pause
2021-10-05 11:00:11 WARNING (SyncWorker_11) [pynuki] Call failed: <Response [200]>
2021-10-05 11:00:11 ERROR (MainThread) [homeassistant.components.nuki] Unexpected error fetching nuki devices data: Failed to update data for Nuki device 604932253
Traceback (most recent call last):
  File "/usr/src/homeassistant/homeassistant/helpers/update_coordinator.py", line 187, in _async_refresh
    self.data = await self._async_update_data()
  File "/usr/src/homeassistant/homeassistant/helpers/update_coordinator.py", line 147, in _async_update_data
    return await self.update_method()
  File "/usr/src/homeassistant/homeassistant/components/nuki/__init__.py", line 106, in async_update_data
    await hass.async_add_executor_job(_update_devices, locks + openers)
  File "/usr/local/lib/python3.9/concurrent/futures/thread.py", line 52, in run
    result = self.fn(*self.args, **self.kwargs)
  File "/usr/src/homeassistant/homeassistant/components/nuki/__init__.py", line 45, in _update_devices
    device.update(level)
  File "/usr/local/lib/python3.9/site-packages/pynuki/device.py", line 81, in update
    raise NukiUpdateException(
pynuki.exceptions.NukiUpdateException: Failed to update data for Nuki device 604932253
2021-10-05 11:00:41 WARNING (SyncWorker_0) [pynuki] Call failed: <Response [200]>
2021-10-05 11:00:41 ERROR (MainThread) [homeassistant.components.nuki] Unexpected error fetching nuki devices data: Failed to update data for Nuki device 604932253
Traceback (most recent call last):
  File "/usr/src/homeassistant/homeassistant/helpers/update_coordinator.py", line 187, in _async_refresh
    self.data = await self._async_update_data()
  File "/usr/src/homeassistant/homeassistant/helpers/update_coordinator.py", line 147, in _async_update_data
    return await self.update_method()
  File "/usr/src/homeassistant/homeassistant/components/nuki/__init__.py", line 106, in async_update_data
    await hass.async_add_executor_job(_update_devices, locks + openers)
  File "/usr/local/lib/python3.9/concurrent/futures/thread.py", line 52, in run
    result = self.fn(*self.args, **self.kwargs)
  File "/usr/src/homeassistant/homeassistant/components/nuki/__init__.py", line 45, in _update_devices
    device.update(level)
  File "/usr/local/lib/python3.9/site-packages/pynuki/device.py", line 81, in update
    raise NukiUpdateException(
pynuki.exceptions.NukiUpdateException: Failed to update data for Nuki device 604932253
2021-10-05 11:01:11 WARNING (SyncWorker_17) [pynuki] Call failed: <Response [200]>
2021-10-05 11:01:11 ERROR (MainThread) [homeassistant.components.nuki] Unexpected error fetching nuki devices data: Failed to update data for Nuki device 604932253
Traceback (most recent call last):
  File "/usr/src/homeassistant/homeassistant/helpers/update_coordinator.py", line 187, in _async_refresh
    self.data = await self._async_update_data()
  File "/usr/src/homeassistant/homeassistant/helpers/update_coordinator.py", line 147, in _async_update_data
    return await self.update_method()
  File "/usr/src/homeassistant/homeassistant/components/nuki/__init__.py", line 106, in async_update_data
    await hass.async_add_executor_job(_update_devices, locks + openers)
  File "/usr/local/lib/python3.9/concurrent/futures/thread.py", line 52, in run
    result = self.fn(*self.args, **self.kwargs)
  File "/usr/src/homeassistant/homeassistant/components/nuki/__init__.py", line 45, in _update_devices
    device.update(level)
  File "/usr/local/lib/python3.9/site-packages/pynuki/device.py", line 81, in update
    raise NukiUpdateException(
pynuki.exceptions.NukiUpdateException: Failed to update data for Nuki device 604932253
2021-10-05 11:03:47 WARNING (SyncWorker_15) [pynuki] Call failed: <Response [200]>
2021-10-05 11:03:47 ERROR (MainThread) [homeassistant.components.nuki] Unexpected error fetching nuki devices data: Failed to update data for Nuki device 604932253
Traceback (most recent call last):
  File "/usr/src/homeassistant/homeassistant/helpers/update_coordinator.py", line 187, in _async_refresh
    self.data = await self._async_update_data()
  File "/usr/src/homeassistant/homeassistant/helpers/update_coordinator.py", line 147, in _async_update_data
    return await self.update_method()
  File "/usr/src/homeassistant/homeassistant/components/nuki/__init__.py", line 106, in async_update_data
    await hass.async_add_executor_job(_update_devices, locks + openers)
  File "/usr/local/lib/python3.9/concurrent/futures/thread.py", line 52, in run
    result = self.fn(*self.args, **self.kwargs)
  File "/usr/src/homeassistant/homeassistant/components/nuki/__init__.py", line 45, in _update_devices
    device.update(level)
  File "/usr/local/lib/python3.9/site-packages/pynuki/device.py", line 81, in update
    raise NukiUpdateException(
pynuki.exceptions.NukiUpdateException: Failed to update data for Nuki device 604932253
2021-10-05 11:04:47 WARNING (SyncWorker_2) [pynuki] Call failed: <Response [200]>
2021-10-05 11:04:47 ERROR (MainThread) [homeassistant.components.nuki] Unexpected error fetching nuki devices data: Failed to update data for Nuki device 604932253
Traceback (most recent call last):
  File "/usr/src/homeassistant/homeassistant/helpers/update_coordinator.py", line 187, in _async_refresh
    self.data = await self._async_update_data()
  File "/usr/src/homeassistant/homeassistant/helpers/update_coordinator.py", line 147, in _async_update_data
    return await self.update_method()
  File "/usr/src/homeassistant/homeassistant/components/nuki/__init__.py", line 106, in async_update_data
    await hass.async_add_executor_job(_update_devices, locks + openers)
  File "/usr/local/lib/python3.9/concurrent/futures/thread.py", line 52, in run
    result = self.fn(*self.args, **self.kwargs)
  File "/usr/src/homeassistant/homeassistant/components/nuki/__init__.py", line 45, in _update_devices
    device.update(level)
  File "/usr/local/lib/python3.9/site-packages/pynuki/device.py", line 81, in update
    raise NukiUpdateException(
pynuki.exceptions.NukiUpdateException: Failed to update data for Nuki device 604932253
2021-10-05 11:08:51 WARNING (SyncWorker_13) [pynuki] Call failed: <Response [200]>
2021-10-05 11:08:51 ERROR (MainThread) [homeassistant.components.nuki] Unexpected error fetching nuki devices data: Failed to update data for Nuki device 604932253
Traceback (most recent call last):
  File "/usr/src/homeassistant/homeassistant/helpers/update_coordinator.py", line 187, in _async_refresh
    self.data = await self._async_update_data()
  File "/usr/src/homeassistant/homeassistant/helpers/update_coordinator.py", line 147, in _async_update_data
    return await self.update_method()
  File "/usr/src/homeassistant/homeassistant/components/nuki/__init__.py", line 106, in async_update_data
    await hass.async_add_executor_job(_update_devices, locks + openers)
  File "/usr/local/lib/python3.9/concurrent/futures/thread.py", line 52, in run
    result = self.fn(*self.args, **self.kwargs)
  File "/usr/src/homeassistant/homeassistant/components/nuki/__init__.py", line 45, in _update_devices
    device.update(level)
  File "/usr/local/lib/python3.9/site-packages/pynuki/device.py", line 81, in update
    raise NukiUpdateException(
pynuki.exceptions.NukiUpdateException: Failed to update data for Nuki device 604932253
2021-10-05 11:10:55 WARNING (SyncWorker_3) [pynuki] Call failed: <Response [200]>
2021-10-05 11:10:55 ERROR (MainThread) [homeassistant.components.nuki] Unexpected error fetching nuki devices data: Failed to update data for Nuki device 604932253
Traceback (most recent call last):
  File "/usr/src/homeassistant/homeassistant/helpers/update_coordinator.py", line 187, in _async_refresh
    self.data = await self._async_update_data()
  File "/usr/src/homeassistant/homeassistant/helpers/update_coordinator.py", line 147, in _async_update_data
    return await self.update_method()
  File "/usr/src/homeassistant/homeassistant/components/nuki/__init__.py", line 106, in async_update_data
    await hass.async_add_executor_job(_update_devices, locks + openers)
  File "/usr/local/lib/python3.9/concurrent/futures/thread.py", line 52, in run
    result = self.fn(*self.args, **self.kwargs)
  File "/usr/src/homeassistant/homeassistant/components/nuki/__init__.py", line 45, in _update_devices
    device.update(level)
  File "/usr/local/lib/python3.9/site-packages/pynuki/device.py", line 81, in update
    raise NukiUpdateException(
pynuki.exceptions.NukiUpdateException: Failed to update data for Nuki device 604932253
2021-10-05 11:11:25 WARNING (SyncWorker_0) [pynuki] Call failed: <Response [200]>
2021-10-05 11:11:25 ERROR (MainThread) [homeassistant.components.nuki] Unexpected error fetching nuki devices data: Failed to update data for Nuki device 604932253
Traceback (most recent call last):
  File "/usr/src/homeassistant/homeassistant/helpers/update_coordinator.py", line 187, in _async_refresh
    self.data = await self._async_update_data()
  File "/usr/src/homeassistant/homeassistant/helpers/update_coordinator.py", line 147, in _async_update_data
    return await self.update_method()
  File "/usr/src/homeassistant/homeassistant/components/nuki/__init__.py", line 106, in async_update_data
    await hass.async_add_executor_job(_update_devices, locks + openers)
  File "/usr/local/lib/python3.9/concurrent/futures/thread.py", line 52, in run
    result = self.fn(*self.args, **self.kwargs)
  File "/usr/src/homeassistant/homeassistant/components/nuki/__init__.py", line 45, in _update_devices
    device.update(level)
  File "/usr/local/lib/python3.9/site-packages/pynuki/device.py", line 81, in update
    raise NukiUpdateException(
pynuki.exceptions.NukiUpdateException: Failed to update data for Nuki device 604932253
2021-10-05 11:12:56 WARNING (SyncWorker_17) [pynuki] Call failed: <Response [200]>
2021-10-05 11:12:56 ERROR (MainThread) [homeassistant.components.nuki] Unexpected error fetching nuki devices data: Failed to update data for Nuki device 604932253
Traceback (most recent call last):
  File "/usr/src/homeassistant/homeassistant/helpers/update_coordinator.py", line 187, in _async_refresh
    self.data = await self._async_update_data()
  File "/usr/src/homeassistant/homeassistant/helpers/update_coordinator.py", line 147, in _async_update_data
    return await self.update_method()
  File "/usr/src/homeassistant/homeassistant/components/nuki/__init__.py", line 106, in async_update_data
    await hass.async_add_executor_job(_update_devices, locks + openers)
  File "/usr/local/lib/python3.9/concurrent/futures/thread.py", line 52, in run
    result = self.fn(*self.args, **self.kwargs)
  File "/usr/src/homeassistant/homeassistant/components/nuki/__init__.py", line 45, in _update_devices
    device.update(level)
  File "/usr/local/lib/python3.9/site-packages/pynuki/device.py", line 81, in update
    raise NukiUpdateException(
pynuki.exceptions.NukiUpdateException: Failed to update data for Nuki device 604932253
2021-10-05 11:13:28 WARNING (SyncWorker_17) [pynuki] Call failed: <Response [200]>
2021-10-05 11:13:28 ERROR (MainThread) [homeassistant.components.nuki] Unexpected error fetching nuki devices data: Failed to update data for Nuki device 604932253
Traceback (most recent call last):
  File "/usr/src/homeassistant/homeassistant/helpers/update_coordinator.py", line 187, in _async_refresh
    self.data = await self._async_update_data()
  File "/usr/src/homeassistant/homeassistant/helpers/update_coordinator.py", line 147, in _async_update_data
    return await self.update_method()
  File "/usr/src/homeassistant/homeassistant/components/nuki/__init__.py", line 106, in async_update_data
    await hass.async_add_executor_job(_update_devices, locks + openers)
  File "/usr/local/lib/python3.9/concurrent/futures/thread.py", line 52, in run
    result = self.fn(*self.args, **self.kwargs)
  File "/usr/src/homeassistant/homeassistant/components/nuki/__init__.py", line 45, in _update_devices
    device.update(level)
  File "/usr/local/lib/python3.9/site-packages/pynuki/device.py", line 81, in update
    raise NukiUpdateException(
pynuki.exceptions.NukiUpdateException: Failed to update data for Nuki device 604932253
2021-10-05 11:13:59 WARNING (SyncWorker_10) [pynuki] Call failed: <Response [200]>
2021-10-05 11:13:59 ERROR (MainThread) [homeassistant.components.nuki] Unexpected error fetching nuki devices data: Failed to update data for Nuki device 604932253
Traceback (most recent call last):
  File "/usr/src/homeassistant/homeassistant/helpers/update_coordinator.py", line 187, in _async_refresh
    self.data = await self._async_update_data()
  File "/usr/src/homeassistant/homeassistant/helpers/update_coordinator.py", line 147, in _async_update_data
    return await self.update_method()
  File "/usr/src/homeassistant/homeassistant/components/nuki/__init__.py", line 106, in async_update_data
    await hass.async_add_executor_job(_update_devices, locks + openers)
  File "/usr/local/lib/python3.9/concurrent/futures/thread.py", line 52, in run
    result = self.fn(*self.args, **self.kwargs)
  File "/usr/src/homeassistant/homeassistant/components/nuki/__init__.py", line 45, in _update_devices
    device.update(level)
  File "/usr/local/lib/python3.9/site-packages/pynuki/device.py", line 81, in update
    raise NukiUpdateException(
pynuki.exceptions.NukiUpdateException: Failed to update data for Nuki device 604932253
2021-10-05 11:15:00 WARNING (MainThread) [homeassistant.components.automation] Error evaluating condition in '🪟 ramen - sluit raam Amilya (Bart en Madouce)':
In 'condition' (item 2 of 2):
  In 'or' (item 2 of 2):
    In 'state':
      In 'state' condition: unknown entity input_boolean.kamer_amylia_window_pause
2021-10-05 11:17:33 WARNING (SyncWorker_12) [pynuki] Call failed: <Response [200]>
2021-10-05 11:17:33 ERROR (MainThread) [homeassistant.components.nuki] Unexpected error fetching nuki devices data: Failed to update data for Nuki device 604932253
Traceback (most recent call last):
  File "/usr/src/homeassistant/homeassistant/helpers/update_coordinator.py", line 187, in _async_refresh
    self.data = await self._async_update_data()
  File "/usr/src/homeassistant/homeassistant/helpers/update_coordinator.py", line 147, in _async_update_data
    return await self.update_method()
  File "/usr/src/homeassistant/homeassistant/components/nuki/__init__.py", line 106, in async_update_data
    await hass.async_add_executor_job(_update_devices, locks + openers)
  File "/usr/local/lib/python3.9/concurrent/futures/thread.py", line 52, in run
    result = self.fn(*self.args, **self.kwargs)
  File "/usr/src/homeassistant/homeassistant/components/nuki/__init__.py", line 45, in _update_devices
    device.update(level)
  File "/usr/local/lib/python3.9/site-packages/pynuki/device.py", line 81, in update
    raise NukiUpdateException(
pynuki.exceptions.NukiUpdateException: Failed to update data for Nuki device 604932253
2021-10-05 11:18:04 WARNING (SyncWorker_11) [pynuki] Call failed: <Response [200]>
2021-10-05 11:18:04 ERROR (MainThread) [homeassistant.components.nuki] Unexpected error fetching nuki devices data: Failed to update data for Nuki device 604932253
Traceback (most recent call last):
  File "/usr/src/homeassistant/homeassistant/helpers/update_coordinator.py", line 187, in _async_refresh
    self.data = await self._async_update_data()
  File "/usr/src/homeassistant/homeassistant/helpers/update_coordinator.py", line 147, in _async_update_data
    return await self.update_method()
  File "/usr/src/homeassistant/homeassistant/components/nuki/__init__.py", line 106, in async_update_data
    await hass.async_add_executor_job(_update_devices, locks + openers)
  File "/usr/local/lib/python3.9/concurrent/futures/thread.py", line 52, in run
    result = self.fn(*self.args, **self.kwargs)
  File "/usr/src/homeassistant/homeassistant/components/nuki/__init__.py", line 45, in _update_devices
    device.update(level)
  File "/usr/local/lib/python3.9/site-packages/pynuki/device.py", line 81, in update
    raise NukiUpdateException(
pynuki.exceptions.NukiUpdateException: Failed to update data for Nuki device 604932253
2021-10-05 11:23:10 WARNING (SyncWorker_0) [pynuki] Call failed: <Response [200]>
2021-10-05 11:23:10 ERROR (MainThread) [homeassistant.components.nuki] Unexpected error fetching nuki devices data: Failed to update data for Nuki device 604932253
Traceback (most recent call last):
  File "/usr/src/homeassistant/homeassistant/helpers/update_coordinator.py", line 187, in _async_refresh
    self.data = await self._async_update_data()
  File "/usr/src/homeassistant/homeassistant/helpers/update_coordinator.py", line 147, in _async_update_data
    return await self.update_method()
  File "/usr/src/homeassistant/homeassistant/components/nuki/__init__.py", line 106, in async_update_data
    await hass.async_add_executor_job(_update_devices, locks + openers)
  File "/usr/local/lib/python3.9/concurrent/futures/thread.py", line 52, in run
    result = self.fn(*self.args, **self.kwargs)
  File "/usr/src/homeassistant/homeassistant/components/nuki/__init__.py", line 45, in _update_devices
    device.update(level)
  File "/usr/local/lib/python3.9/site-packages/pynuki/device.py", line 81, in update
    raise NukiUpdateException(
pynuki.exceptions.NukiUpdateException: Failed to update data for Nuki device 604932253
2021-10-05 11:23:48 WARNING (SyncWorker_1) [buienalarm.pybuienalarm] Error fetching data safely: 502 Server Error: Bad Gateway for url: https://cdn-secure.buienalarm.nl/api/3.4/forecast.php?lat=50.878800118427755&lon=4.749415398691782&region=nl&unit=mm%2Fu
2021-10-05 11:25:14 WARNING (SyncWorker_4) [pynuki] Call failed: <Response [200]>
2021-10-05 11:25:14 ERROR (MainThread) [homeassistant.components.nuki] Unexpected error fetching nuki devices data: Failed to update data for Nuki device 604932253
Traceback (most recent call last):
  File "/usr/src/homeassistant/homeassistant/helpers/update_coordinator.py", line 187, in _async_refresh
    self.data = await self._async_update_data()
  File "/usr/src/homeassistant/homeassistant/helpers/update_coordinator.py", line 147, in _async_update_data
    return await self.update_method()
  File "/usr/src/homeassistant/homeassistant/components/nuki/__init__.py", line 106, in async_update_data
    await hass.async_add_executor_job(_update_devices, locks + openers)
  File "/usr/local/lib/python3.9/concurrent/futures/thread.py", line 52, in run
    result = self.fn(*self.args, **self.kwargs)
  File "/usr/src/homeassistant/homeassistant/components/nuki/__init__.py", line 45, in _update_devices
    device.update(level)
  File "/usr/local/lib/python3.9/site-packages/pynuki/device.py", line 81, in update
    raise NukiUpdateException(
pynuki.exceptions.NukiUpdateException: Failed to update data for Nuki device 604932253
2021-10-05 11:26:47 WARNING (SyncWorker_0) [pynuki] Call failed: <Response [200]>
2021-10-05 11:26:47 ERROR (MainThread) [homeassistant.components.nuki] Unexpected error fetching nuki devices data: Failed to update data for Nuki device 604932253
Traceback (most recent call last):
  File "/usr/src/homeassistant/homeassistant/helpers/update_coordinator.py", line 187, in _async_refresh
    self.data = await self._async_update_data()
  File "/usr/src/homeassistant/homeassistant/helpers/update_coordinator.py", line 147, in _async_update_data
    return await self.update_method()
  File "/usr/src/homeassistant/homeassistant/components/nuki/__init__.py", line 106, in async_update_data
    await hass.async_add_executor_job(_update_devices, locks + openers)
  File "/usr/local/lib/python3.9/concurrent/futures/thread.py", line 52, in run
    result = self.fn(*self.args, **self.kwargs)
  File "/usr/src/homeassistant/homeassistant/components/nuki/__init__.py", line 45, in _update_devices
    device.update(level)
  File "/usr/local/lib/python3.9/site-packages/pynuki/device.py", line 81, in update
    raise NukiUpdateException(
pynuki.exceptions.NukiUpdateException: Failed to update data for Nuki device 604932253
2021-10-05 11:27:48 WARNING (SyncWorker_14) [pynuki] Call failed: <Response [200]>
2021-10-05 11:27:48 ERROR (MainThread) [homeassistant.components.nuki] Unexpected error fetching nuki devices data: Failed to update data for Nuki device 604932253
Traceback (most recent call last):
  File "/usr/src/homeassistant/homeassistant/helpers/update_coordinator.py", line 187, in _async_refresh
    self.data = await self._async_update_data()
  File "/usr/src/homeassistant/homeassistant/helpers/update_coordinator.py", line 147, in _async_update_data
    return await self.update_method()
  File "/usr/src/homeassistant/homeassistant/components/nuki/__init__.py", line 106, in async_update_data
    await hass.async_add_executor_job(_update_devices, locks + openers)
  File "/usr/local/lib/python3.9/concurrent/futures/thread.py", line 52, in run
    result = self.fn(*self.args, **self.kwargs)
  File "/usr/src/homeassistant/homeassistant/components/nuki/__init__.py", line 45, in _update_devices
    device.update(level)
  File "/usr/local/lib/python3.9/site-packages/pynuki/device.py", line 81, in update
    raise NukiUpdateException(
pynuki.exceptions.NukiUpdateException: Failed to update data for Nuki device 604932253
2021-10-05 11:28:18 WARNING (SyncWorker_17) [pynuki] Call failed: <Response [200]>
2021-10-05 11:28:18 ERROR (MainThread) [homeassistant.components.nuki] Unexpected error fetching nuki devices data: Failed to update data for Nuki device 604932253
Traceback (most recent call last):
  File "/usr/src/homeassistant/homeassistant/helpers/update_coordinator.py", line 187, in _async_refresh
    self.data = await self._async_update_data()
  File "/usr/src/homeassistant/homeassistant/helpers/update_coordinator.py", line 147, in _async_update_data
    return await self.update_method()
  File "/usr/src/homeassistant/homeassistant/components/nuki/__init__.py", line 106, in async_update_data
    await hass.async_add_executor_job(_update_devices, locks + openers)
  File "/usr/local/lib/python3.9/concurrent/futures/thread.py", line 52, in run
    result = self.fn(*self.args, **self.kwargs)
  File "/usr/src/homeassistant/homeassistant/components/nuki/__init__.py", line 45, in _update_devices
    device.update(level)
  File "/usr/local/lib/python3.9/site-packages/pynuki/device.py", line 81, in update
    raise NukiUpdateException(
pynuki.exceptions.NukiUpdateException: Failed to update data for Nuki device 604932253
2021-10-05 11:29:52 WARNING (SyncWorker_3) [pynuki] Call failed: <Response [200]>
2021-10-05 11:29:52 ERROR (MainThread) [homeassistant.components.nuki] Unexpected error fetching nuki devices data: Failed to update data for Nuki device 604932253
Traceback (most recent call last):
  File "/usr/src/homeassistant/homeassistant/helpers/update_coordinator.py", line 187, in _async_refresh
    self.data = await self._async_update_data()
  File "/usr/src/homeassistant/homeassistant/helpers/update_coordinator.py", line 147, in _async_update_data
    return await self.update_method()
  File "/usr/src/homeassistant/homeassistant/components/nuki/__init__.py", line 106, in async_update_data
    await hass.async_add_executor_job(_update_devices, locks + openers)
  File "/usr/local/lib/python3.9/concurrent/futures/thread.py", line 52, in run
    result = self.fn(*self.args, **self.kwargs)
  File "/usr/src/homeassistant/homeassistant/components/nuki/__init__.py", line 45, in _update_devices
    device.update(level)
  File "/usr/local/lib/python3.9/site-packages/pynuki/device.py", line 81, in update
    raise NukiUpdateException(
pynuki.exceptions.NukiUpdateException: Failed to update data for Nuki device 604932253
2021-10-05 11:30:00 WARNING (MainThread) [homeassistant.components.automation] Error evaluating condition in '🪟 ramen - sluit raam Amilya (Bart en Madouce)':
In 'condition' (item 2 of 2):
  In 'or' (item 2 of 2):
    In 'state':
      In 'state' condition: unknown entity input_boolean.kamer_amylia_window_pause
2021-10-05 11:31:05 ERROR (MainThread) [homeassistant.config] Invalid config for [automation]: required key not provided @ data['action'][4]['domain']. Got None. (See ?, line ?). 
2021-10-05 11:31:05 ERROR (MainThread) [homeassistant.config] Invalid config for [automation]: [title] is an invalid option for [automation]. Check: automation->action->1->title. (See ?, line ?). 
2021-10-05 11:31:05 ERROR (MainThread) [homeassistant.config] Invalid config for [automation]: must be a value between 0 and 59 for dictionary value @ data['minutes']. Got None. (See ?, line ?). 
2021-10-05 11:31:05 ERROR (MainThread) [homeassistant.config] Invalid config for [automation]: must be a value between 0 and 59 for dictionary value @ data['minutes']. Got None. (See ?, line ?). 
2021-10-05 11:32:27 WARNING (SyncWorker_0) [pynuki] Call failed: <Response [200]>
2021-10-05 11:32:27 ERROR (MainThread) [homeassistant.components.nuki] Unexpected error fetching nuki devices data: Failed to update data for Nuki device 604932253
Traceback (most recent call last):
  File "/usr/src/homeassistant/homeassistant/helpers/update_coordinator.py", line 187, in _async_refresh
    self.data = await self._async_update_data()
  File "/usr/src/homeassistant/homeassistant/helpers/update_coordinator.py", line 147, in _async_update_data
    return await self.update_method()
  File "/usr/src/homeassistant/homeassistant/components/nuki/__init__.py", line 106, in async_update_data
    await hass.async_add_executor_job(_update_devices, locks + openers)
  File "/usr/local/lib/python3.9/concurrent/futures/thread.py", line 52, in run
    result = self.fn(*self.args, **self.kwargs)
  File "/usr/src/homeassistant/homeassistant/components/nuki/__init__.py", line 45, in _update_devices
    device.update(level)
  File "/usr/local/lib/python3.9/site-packages/pynuki/device.py", line 81, in update
    raise NukiUpdateException(
pynuki.exceptions.NukiUpdateException: Failed to update data for Nuki device 604932253
2021-10-05 11:32:43 ERROR (MainThread) [homeassistant.config] Invalid config for [automation]: required key not provided @ data['action'][4]['domain']. Got None. (See ?, line ?). 
2021-10-05 11:32:43 ERROR (MainThread) [homeassistant.config] Invalid config for [automation]: [title] is an invalid option for [automation]. Check: automation->action->1->title. (See ?, line ?). 
2021-10-05 11:32:43 ERROR (MainThread) [homeassistant.config] Invalid config for [automation]: must be a value between 0 and 59 for dictionary value @ data['minutes']. Got None. (See ?, line ?). 
2021-10-05 11:32:43 ERROR (MainThread) [homeassistant.config] Invalid config for [automation]: must be a value between 0 and 59 for dictionary value @ data['minutes']. Got None. (See ?, line ?). 
2021-10-05 11:32:50 ERROR (MainThread) [homeassistant.config] Invalid config for [automation]: required key not provided @ data['action'][4]['domain']. Got None. (See ?, line ?). 
2021-10-05 11:32:50 ERROR (MainThread) [homeassistant.config] Invalid config for [automation]: [title] is an invalid option for [automation]. Check: automation->action->1->title. (See ?, line ?). 
2021-10-05 11:32:50 ERROR (MainThread) [homeassistant.config] Invalid config for [automation]: must be a value between 0 and 59 for dictionary value @ data['minutes']. Got None. (See ?, line ?). 
2021-10-05 11:32:50 ERROR (MainThread) [homeassistant.config] Invalid config for [automation]: must be a value between 0 and 59 for dictionary value @ data['minutes']. Got None. (See ?, line ?). 
2021-10-05 11:32:51 ERROR (MainThread) [homeassistant.helpers.entity] Update for sensor.master_bedroom_tv_on_today fails
Traceback (most recent call last):
  File "/usr/src/homeassistant/homeassistant/helpers/entity.py", line 446, in async_update_ha_state
    await self.async_device_update()
  File "/usr/src/homeassistant/homeassistant/helpers/entity.py", line 641, in async_device_update
    raise exc
  File "/usr/src/homeassistant/homeassistant/components/history_stats/sensor.py", line 221, in async_update
    await self.hass.async_add_executor_job(
  File "/usr/local/lib/python3.9/concurrent/futures/thread.py", line 52, in run
    result = self.fn(*self.args, **self.kwargs)
  File "/usr/src/homeassistant/homeassistant/components/history_stats/sensor.py", line 227, in _update
    history_list = history.state_changes_during_period(
  File "/usr/src/homeassistant/homeassistant/components/recorder/history.py", line 142, in state_changes_during_period
    with session_scope(hass=hass) as session:
  File "/usr/local/lib/python3.9/contextlib.py", line 119, in __enter__
    return next(self.gen)
  File "/usr/src/homeassistant/homeassistant/components/recorder/util.py", line 59, in session_scope
    session = hass.data[DATA_INSTANCE].get_session()
TypeError: 'NoneType' object is not callable
