2021-11-20 12:28:07 WARNING (SyncWorker_0) [homeassistant.loader] We found a custom integration average which has not been tested by Home Assistant. This component might cause stability problems, be sure to disable it if you experience issues with Home Assistant
2021-11-20 12:28:07 WARNING (SyncWorker_1) [homeassistant.loader] We found a custom integration adaptive_lighting which has not been tested by Home Assistant. This component might cause stability problems, be sure to disable it if you experience issues with Home Assistant
2021-11-20 12:28:07 WARNING (SyncWorker_2) [homeassistant.loader] We found a custom integration xiaomi_miio_airpurifier which has not been tested by Home Assistant. This component might cause stability problems, be sure to disable it if you experience issues with Home Assistant
2021-11-20 12:28:07 WARNING (SyncWorker_1) [homeassistant.loader] We found a custom integration localtuya which has not been tested by Home Assistant. This component might cause stability problems, be sure to disable it if you experience issues with Home Assistant
2021-11-20 12:28:07 WARNING (SyncWorker_3) [homeassistant.loader] We found a custom integration audiconnect which has not been tested by Home Assistant. This component might cause stability problems, be sure to disable it if you experience issues with Home Assistant
2021-11-20 12:28:07 WARNING (SyncWorker_5) [homeassistant.loader] We found a custom integration monitor_docker which has not been tested by Home Assistant. This component might cause stability problems, be sure to disable it if you experience issues with Home Assistant
2021-11-20 12:28:07 WARNING (SyncWorker_0) [homeassistant.loader] We found a custom integration xiaomi_miio_fan which has not been tested by Home Assistant. This component might cause stability problems, be sure to disable it if you experience issues with Home Assistant
2021-11-20 12:28:07 WARNING (SyncWorker_6) [homeassistant.loader] We found a custom integration hacs which has not been tested by Home Assistant. This component might cause stability problems, be sure to disable it if you experience issues with Home Assistant
2021-11-20 12:28:07 WARNING (SyncWorker_8) [homeassistant.loader] We found a custom integration shelly which has not been tested by Home Assistant. This component might cause stability problems, be sure to disable it if you experience issues with Home Assistant
2021-11-20 12:28:07 WARNING (SyncWorker_4) [homeassistant.loader] We found a custom integration powercalc which has not been tested by Home Assistant. This component might cause stability problems, be sure to disable it if you experience issues with Home Assistant
2021-11-20 12:28:07 WARNING (SyncWorker_9) [homeassistant.loader] We found a custom integration tuya_v2 which has not been tested by Home Assistant. This component might cause stability problems, be sure to disable it if you experience issues with Home Assistant
2021-11-20 12:28:07 WARNING (SyncWorker_5) [homeassistant.loader] We found a custom integration huesyncbox which has not been tested by Home Assistant. This component might cause stability problems, be sure to disable it if you experience issues with Home Assistant
2021-11-20 12:28:07 WARNING (SyncWorker_0) [homeassistant.loader] We found a custom integration frigate which has not been tested by Home Assistant. This component might cause stability problems, be sure to disable it if you experience issues with Home Assistant
2021-11-20 12:28:07 WARNING (SyncWorker_8) [homeassistant.loader] We found a custom integration googlewifi which has not been tested by Home Assistant. This component might cause stability problems, be sure to disable it if you experience issues with Home Assistant
2021-11-20 12:28:07 WARNING (SyncWorker_4) [homeassistant.loader] We found a custom integration anniversaries which has not been tested by Home Assistant. This component might cause stability problems, be sure to disable it if you experience issues with Home Assistant
2021-11-20 12:28:07 WARNING (SyncWorker_6) [homeassistant.loader] We found a custom integration deepstack_face which has not been tested by Home Assistant. This component might cause stability problems, be sure to disable it if you experience issues with Home Assistant
2021-11-20 12:28:07 WARNING (SyncWorker_10) [homeassistant.loader] We found a custom integration thermal_comfort which has not been tested by Home Assistant. This component might cause stability problems, be sure to disable it if you experience issues with Home Assistant
2021-11-20 12:28:07 WARNING (SyncWorker_7) [homeassistant.loader] We found a custom integration buienalarm which has not been tested by Home Assistant. This component might cause stability problems, be sure to disable it if you experience issues with Home Assistant
2021-11-20 12:28:07 WARNING (SyncWorker_11) [homeassistant.loader] We found a custom integration xiaomi_miot which has not been tested by Home Assistant. This component might cause stability problems, be sure to disable it if you experience issues with Home Assistant
2021-11-20 12:28:07 WARNING (SyncWorker_12) [homeassistant.loader] We found a custom integration tgtg which has not been tested by Home Assistant. This component might cause stability problems, be sure to disable it if you experience issues with Home Assistant
2021-11-20 12:28:07 WARNING (SyncWorker_0) [homeassistant.loader] We found a custom integration ytube_music_player which has not been tested by Home Assistant. This component might cause stability problems, be sure to disable it if you experience issues with Home Assistant
2021-11-20 12:28:07 WARNING (SyncWorker_1) [homeassistant.loader] We found a custom integration google_home which has not been tested by Home Assistant. This component might cause stability problems, be sure to disable it if you experience issues with Home Assistant
2021-11-20 12:28:07 WARNING (SyncWorker_4) [homeassistant.loader] We found a custom integration afvalbeheer which has not been tested by Home Assistant. This component might cause stability problems, be sure to disable it if you experience issues with Home Assistant
2021-11-20 12:28:15 ERROR (SyncWorker_10) [homeassistant.components.influxdb] Cannot connect to InfluxDB due to '<urllib3.connection.HTTPConnection object at 0xffff9eb1d220>: Failed to establish a new connection: [Errno 111] Connection refused'. Please check that the provided connection details (host, port, etc.) are correct and that your InfluxDB server is running and accessible. Retrying in 60 seconds.
2021-11-20 12:28:16 ERROR (MainThread) [homeassistant.config] Invalid config for [automation]: expected str for dictionary value @ data['from']. Got None. (See ?, line ?). 
2021-11-20 12:28:16 ERROR (MainThread) [homeassistant.config] Invalid config for [automation]: required key not provided @ data['trigger'][1]['platform']. Got None. (See ?, line ?). 
2021-11-20 12:28:16 ERROR (MainThread) [homeassistant.config] Invalid config for [automation]: Unexpected value for condition: 'None'. Expected and, device, not, numeric_state, or, state, sun, template, time, trigger, zone @ data['condition'][0]. Got None. (See ?, line ?). 
2021-11-20 12:28:16 ERROR (MainThread) [homeassistant.config] Invalid config for [automation]: Unexpected value for condition: 'None'. Expected and, device, not, numeric_state, or, state, sun, template, time, trigger, zone @ data['condition'][0]. Got None. (See ?, line ?). 
2021-11-20 12:28:16 ERROR (MainThread) [homeassistant.config] Invalid config for [automation]: required key not provided @ data['action'][4]['domain']. Got None. (See ?, line ?). 
2021-11-20 12:28:16 ERROR (MainThread) [homeassistant.config] Invalid config for [automation]: must be a value between 0 and 59 for dictionary value @ data['minutes']. Got None. (See ?, line ?). 
2021-11-20 12:28:16 ERROR (MainThread) [homeassistant.config] Invalid config for [automation]: must be a value between 0 and 59 for dictionary value @ data['minutes']. Got None. (See ?, line ?). 
2021-11-20 12:28:22 WARNING (MainThread) [homeassistant.setup] Setup of input_datetime is taking over 10 seconds.
2021-11-20 12:28:22 WARNING (MainThread) [homeassistant.components.fan] Platform xiaomi_miio_fan not ready yet: Unable to discover the device 192.168.86.29; Retrying in background in 30 seconds
2021-11-20 12:28:22 WARNING (MainThread) [homeassistant.components.fan] Platform xiaomi_miio_fan not ready yet: Unable to discover the device 192.168.86.28; Retrying in background in 30 seconds
2021-11-20 12:28:23 WARNING (MainThread) [homeassistant.setup] Setup of input_number is taking over 10 seconds.
2021-11-20 12:28:23 WARNING (MainThread) [homeassistant.setup] Setup of input_text is taking over 10 seconds.
2021-11-20 12:28:25 WARNING (MainThread) [homeassistant.config_entries] Config entry '192.168.86.83' for synology_dsm integration not ready yet: ConnectionError = <urllib3.connection.HTTPSConnection object at 0xffff93b641f0>: Failed to establish a new connection: [Errno 113] Host is unreachable; Retrying in background
2021-11-20 12:28:33 WARNING (MainThread) [homeassistant.components.media_player] Setup of media_player platform samsungtv is taking over 10 seconds.
2021-11-20 12:28:34 WARNING (MainThread) [homeassistant.components.light] Platform netatmo not ready yet: None; Retrying in background in 30 seconds
2021-11-20 12:28:34 WARNING (MainThread) [homeassistant.components.select] Platform netatmo not ready yet: None; Retrying in background in 30 seconds
2021-11-20 12:28:35 WARNING (MainThread) [homeassistant.components.integration.sensor] Could not restore last state: [<class 'decimal.ConversionSyntax'>]
2021-11-20 12:28:36 ERROR (MainThread) [custom_components.powercalc.sensors.power] Skipping sensor setup light.buiten: ('No lookup file found for mode', 'brightness')
2021-11-20 12:28:37 WARNING (MainThread) [homeassistant.components.binary_sensor] Updating ping binary_sensor took longer than the scheduled update interval 0:00:05
2021-11-20 12:28:37 WARNING (MainThread) [homeassistant.components.media_player] Setup of media_player platform dlna_dmr is taking over 10 seconds.
2021-11-20 12:28:37 WARNING (MainThread) [homeassistant.components.energy.sensor] Found unexpected state_class None for sensor.tv_energy
2021-11-20 12:28:37 WARNING (MainThread) [homeassistant.config_entries] Config entry 'OnHub' for upnp integration not ready yet; Retrying in background
2021-11-20 12:28:38 WARNING (MainThread) [homeassistant.components.sensor] Platform netatmo not ready yet: None; Retrying in background in 30 seconds
2021-11-20 12:28:39 ERROR (MainThread) [homeassistant.components.sensor] scrape: Error on device update!
Traceback (most recent call last):
  File "/usr/src/homeassistant/homeassistant/helpers/entity_platform.py", line 431, in _async_add_entity
    await entity.async_device_update(warning=False)
  File "/usr/src/homeassistant/homeassistant/helpers/entity.py", line 651, in async_device_update
    await task
  File "/usr/src/homeassistant/homeassistant/components/scrape/sensor.py", line 166, in async_update
    await self._async_update_from_rest_data()
  File "/usr/src/homeassistant/homeassistant/components/scrape/sensor.py", line 179, in _async_update_from_rest_data
    value = await self.hass.async_add_executor_job(self._extract_value)
  File "/usr/local/lib/python3.9/concurrent/futures/thread.py", line 52, in run
    result = self.fn(*self.args, **self.kwargs)
  File "/usr/src/homeassistant/homeassistant/components/scrape/sensor.py", line 155, in _extract_value
    tag = raw_data.select(self._select)[self._index]
  File "/usr/local/lib/python3.9/site-packages/bs4/element.py", line 1949, in select
    results = soupsieve.select(selector, self, namespaces, limit, **kwargs)
  File "/usr/local/lib/python3.9/site-packages/soupsieve/__init__.py", line 144, in select
    return compile(select, namespaces, flags, **kwargs).select(tag, limit)
  File "/usr/local/lib/python3.9/site-packages/soupsieve/__init__.py", line 67, in compile
    return cp._cached_css_compile(pattern, ns, cs, flags)
  File "/usr/local/lib/python3.9/site-packages/soupsieve/css_parser.py", line 218, in _cached_css_compile
    CSSParser(
  File "/usr/local/lib/python3.9/site-packages/soupsieve/css_parser.py", line 1159, in process_selectors
    return self.parse_selectors(self.selector_iter(self.pattern), index, flags)
  File "/usr/local/lib/python3.9/site-packages/soupsieve/css_parser.py", line 985, in parse_selectors
    key, m = next(iselector)
  File "/usr/local/lib/python3.9/site-packages/soupsieve/css_parser.py", line 1152, in selector_iter
    raise SelectorSyntaxError(msg, self.pattern, index)
soupsieve.util.SelectorSyntaxError: Invalid character '<' position 0
  line 1:
<span _ngcontent-app-root-c173="">Offline</span>
^
2021-11-20 12:28:42 WARNING (MainThread) [homeassistant.components.sensor] Setup of sensor platform scrape is taking over 10 seconds.
2021-11-20 12:28:42 WARNING (MainThread) [homeassistant.components.sensor] Setup of sensor platform scrape is taking over 10 seconds.
2021-11-20 12:28:42 WARNING (MainThread) [homeassistant.components.sensor] Setup of sensor platform scrape is taking over 10 seconds.
2021-11-20 12:28:42 WARNING (MainThread) [homeassistant.components.sensor] Setup of sensor platform scrape is taking over 10 seconds.
2021-11-20 12:28:42 WARNING (MainThread) [homeassistant.components.sensor] Setup of sensor platform scrape is taking over 10 seconds.
2021-11-20 12:28:42 WARNING (MainThread) [homeassistant.components.binary_sensor] Updating ping binary_sensor took longer than the scheduled update interval 0:00:05
2021-11-20 12:28:42 WARNING (MainThread) [homeassistant.components.media_player] Updating huesyncbox media_player took longer than the scheduled update interval 0:00:02
2021-11-20 12:28:42 WARNING (MainThread) [homeassistant.helpers.entity] Update of binary_sensor.google_server is taking over 10 seconds
2021-11-20 12:28:43 ERROR (MainThread) [homeassistant.components.camera] Error while setting up netatmo platform for camera
Traceback (most recent call last):
  File "/usr/local/lib/python3.9/site-packages/aiohttp/connector.py", line 969, in _wrap_create_connection
    return await self._loop.create_connection(*args, **kwargs)  # type: ignore  # noqa
  File "/usr/local/lib/python3.9/asyncio/base_events.py", line 1056, in create_connection
    raise exceptions[0]
  File "/usr/local/lib/python3.9/asyncio/base_events.py", line 1041, in create_connection
    sock = await self._connect_sock(
  File "/usr/local/lib/python3.9/asyncio/base_events.py", line 955, in _connect_sock
    await self.sock_connect(sock, address)
  File "/usr/local/lib/python3.9/asyncio/selector_events.py", line 502, in sock_connect
    return await fut
  File "/usr/local/lib/python3.9/asyncio/selector_events.py", line 537, in _sock_connect_cb
    raise OSError(err, f'Connect call failed {address}')
OSError: [Errno 113] Connect call failed ('169.254.155.60', 80)

The above exception was the direct cause of the following exception:

Traceback (most recent call last):
  File "/usr/src/homeassistant/homeassistant/helpers/entity_platform.py", line 249, in _async_setup_platform
    await asyncio.shield(task)
  File "/usr/src/homeassistant/homeassistant/components/netatmo/camera.py", line 58, in async_setup_entry
    await data_handler.register_data_class(
  File "/usr/src/homeassistant/homeassistant/components/netatmo/data_handler.py", line 187, in register_data_class
    await self.async_fetch_data(data_class_entry)
  File "/usr/src/homeassistant/homeassistant/components/netatmo/data_handler.py", line 144, in async_fetch_data
    await self.data[data_class_entry].async_update()
  File "/usr/local/lib/python3.9/site-packages/pyatmo/camera.py", line 652, in async_update
    await self._async_update_all_camera_urls()
  File "/usr/local/lib/python3.9/site-packages/pyatmo/camera.py", line 662, in _async_update_all_camera_urls
    await self.async_update_camera_urls(camera_id)
  File "/usr/local/lib/python3.9/site-packages/pyatmo/camera.py", line 728, in async_update_camera_urls
    ] = await self._async_check_url(
  File "/usr/local/lib/python3.9/site-packages/pyatmo/camera.py", line 735, in _async_check_url
    resp = await self.auth.async_post_request(url=f"{url}/command/ping")
  File "/usr/local/lib/python3.9/site-packages/pyatmo/auth.py", line 339, in async_post_request
    async with self.websession.post(
  File "/usr/local/lib/python3.9/site-packages/aiohttp/client.py", line 1117, in __aenter__
    self._resp = await self._coro
  File "/usr/local/lib/python3.9/site-packages/aiohttp/client.py", line 520, in _request
    conn = await self._connector.connect(
  File "/usr/local/lib/python3.9/site-packages/aiohttp/connector.py", line 535, in connect
    proto = await self._create_connection(req, traces, timeout)
  File "/usr/local/lib/python3.9/site-packages/aiohttp/connector.py", line 892, in _create_connection
    _, proto = await self._create_direct_connection(req, traces, timeout)
  File "/usr/local/lib/python3.9/site-packages/aiohttp/connector.py", line 1051, in _create_direct_connection
    raise last_exc
  File "/usr/local/lib/python3.9/site-packages/aiohttp/connector.py", line 1020, in _create_direct_connection
    transp, proto = await self._wrap_create_connection(
  File "/usr/local/lib/python3.9/site-packages/aiohttp/connector.py", line 975, in _wrap_create_connection
    raise client_error(req.connection_key, exc) from exc
aiohttp.client_exceptions.ClientConnectorError: Cannot connect to host 169.254.155.60:80 ssl:default [Connect call failed ('169.254.155.60', 80)]
2021-11-20 12:29:18 WARNING (MainThread) [homeassistant.components.fan] Setup of fan platform xiaomi_miio_fan is taking over 10 seconds.
2021-11-20 12:29:18 WARNING (MainThread) [homeassistant.components.fan] Setup of fan platform xiaomi_miio_fan is taking over 10 seconds.
2021-11-20 12:29:18 ERROR (SyncWorker_25) [homeassistant.components.influxdb] Cannot connect to InfluxDB due to '<urllib3.connection.HTTPConnection object at 0xffff84afaf40>: Failed to establish a new connection: [Errno 111] Connection refused'. Please check that the provided connection details (host, port, etc.) are correct and that your InfluxDB server is running and accessible. Retrying in 60 seconds.
2021-11-20 12:29:21 ERROR (MainThread) [homeassistant.components.mobile_app.notify] Timeout sending notification to https://mobile-apps.home-assistant.io/api/sendPush/android/v1
2021-11-20 12:29:21 ERROR (MainThread) [homeassistant.components.google_assistant.http] Request for https://homegraph.googleapis.com/v1/devices:requestSync failed: 500
2021-11-20 12:29:21 WARNING (MainThread) [homeassistant.components.binary_sensor] Updating ping binary_sensor took longer than the scheduled update interval 0:00:05
2021-11-20 12:29:21 WARNING (MainThread) [homeassistant.helpers.entity] Update of binary_sensor.google_server is taking over 10 seconds
2021-11-20 12:29:21 WARNING (MainThread) [homeassistant.components.media_player] Updating samsungtv media_player took longer than the scheduled update interval 0:00:10
2021-11-20 12:29:21 WARNING (MainThread) [homeassistant.components.media_player] Updating huesyncbox media_player took longer than the scheduled update interval 0:00:02
2021-11-20 12:29:23 ERROR (MainThread) [homeassistant.components.google_assistant.http] Request for https://homegraph.googleapis.com/v1/devices:reportStateAndNotification failed: 404
2021-11-20 12:29:23 WARNING (MainThread) [homeassistant.components.binary_sensor] Updating ping binary_sensor took longer than the scheduled update interval 0:00:05
2021-11-20 12:29:23 WARNING (MainThread) [homeassistant.components.media_player] Updating huesyncbox media_player took longer than the scheduled update interval 0:00:02
2021-11-20 12:29:43 WARNING (MainThread) [homeassistant.components.binary_sensor] Updating ping binary_sensor took longer than the scheduled update interval 0:00:05
2021-11-20 12:29:53 WARNING (MainThread) [homeassistant.components.binary_sensor] Updating ping binary_sensor took longer than the scheduled update interval 0:00:05
2021-11-20 12:29:54 ERROR (MainThread) [homeassistant.components.google_assistant.http] Request for https://homegraph.googleapis.com/v1/devices:reportStateAndNotification failed: 404
2021-11-20 12:30:21 ERROR (SyncWorker_8) [homeassistant.components.influxdb] Cannot connect to InfluxDB due to '<urllib3.connection.HTTPConnection object at 0xffff852c1e80>: Failed to establish a new connection: [Errno 111] Connection refused'. Please check that the provided connection details (host, port, etc.) are correct and that your InfluxDB server is running and accessible. Retrying in 60 seconds.
2021-11-20 12:31:21 ERROR (SyncWorker_15) [homeassistant.components.influxdb] Cannot connect to InfluxDB due to '<urllib3.connection.HTTPConnection object at 0xffff84bfbbe0>: Failed to establish a new connection: [Errno 111] Connection refused'. Please check that the provided connection details (host, port, etc.) are correct and that your InfluxDB server is running and accessible. Retrying in 60 seconds.
2021-11-20 12:32:21 ERROR (SyncWorker_9) [homeassistant.components.influxdb] Cannot connect to InfluxDB due to '<urllib3.connection.HTTPConnection object at 0xffff9caaf550>: Failed to establish a new connection: [Errno 111] Connection refused'. Please check that the provided connection details (host, port, etc.) are correct and that your InfluxDB server is running and accessible. Retrying in 60 seconds.
2021-11-20 12:33:21 ERROR (SyncWorker_17) [homeassistant.components.influxdb] Cannot connect to InfluxDB due to '<urllib3.connection.HTTPConnection object at 0xffff84bf3ac0>: Failed to establish a new connection: [Errno 111] Connection refused'. Please check that the provided connection details (host, port, etc.) are correct and that your InfluxDB server is running and accessible. Retrying in 60 seconds.
2021-11-20 12:34:21 ERROR (SyncWorker_1) [homeassistant.components.influxdb] Cannot connect to InfluxDB due to '<urllib3.connection.HTTPConnection object at 0xffff849d64c0>: Failed to establish a new connection: [Errno 111] Connection refused'. Please check that the provided connection details (host, port, etc.) are correct and that your InfluxDB server is running and accessible. Retrying in 60 seconds.
2021-11-20 12:34:55 ERROR (MainThread) [homeassistant.components.google_assistant.http] Request for https://homegraph.googleapis.com/v1/devices:reportStateAndNotification failed: 404
2021-11-20 12:35:21 ERROR (SyncWorker_24) [homeassistant.components.influxdb] Cannot connect to InfluxDB due to '<urllib3.connection.HTTPConnection object at 0xffff84c99310>: Failed to establish a new connection: [Errno 111] Connection refused'. Please check that the provided connection details (host, port, etc.) are correct and that your InfluxDB server is running and accessible. Retrying in 60 seconds.
2021-11-20 12:36:21 ERROR (SyncWorker_7) [homeassistant.components.influxdb] Cannot connect to InfluxDB due to '<urllib3.connection.HTTPConnection object at 0xffff849d60d0>: Failed to establish a new connection: [Errno 111] Connection refused'. Please check that the provided connection details (host, port, etc.) are correct and that your InfluxDB server is running and accessible. Retrying in 60 seconds.
2021-11-20 12:37:21 ERROR (SyncWorker_24) [homeassistant.components.influxdb] Cannot connect to InfluxDB due to '<urllib3.connection.HTTPConnection object at 0xffff8f938d90>: Failed to establish a new connection: [Errno 111] Connection refused'. Please check that the provided connection details (host, port, etc.) are correct and that your InfluxDB server is running and accessible. Retrying in 60 seconds.
2021-11-20 12:38:21 ERROR (SyncWorker_0) [homeassistant.components.influxdb] Cannot connect to InfluxDB due to '<urllib3.connection.HTTPConnection object at 0xffff86959be0>: Failed to establish a new connection: [Errno 111] Connection refused'. Please check that the provided connection details (host, port, etc.) are correct and that your InfluxDB server is running and accessible. Retrying in 60 seconds.
2021-11-20 12:39:21 ERROR (SyncWorker_20) [homeassistant.components.influxdb] Cannot connect to InfluxDB due to '<urllib3.connection.HTTPConnection object at 0xffff84b16a90>: Failed to establish a new connection: [Errno 111] Connection refused'. Please check that the provided connection details (host, port, etc.) are correct and that your InfluxDB server is running and accessible. Retrying in 60 seconds.
2021-11-20 12:40:21 ERROR (SyncWorker_11) [homeassistant.components.influxdb] Cannot connect to InfluxDB due to '<urllib3.connection.HTTPConnection object at 0xffff83ca1580>: Failed to establish a new connection: [Errno 111] Connection refused'. Please check that the provided connection details (host, port, etc.) are correct and that your InfluxDB server is running and accessible. Retrying in 60 seconds.
2021-11-20 12:40:46 WARNING (MainThread) [haffmpeg.tools] Timeout reading image.
2021-11-20 12:41:21 ERROR (SyncWorker_21) [homeassistant.components.influxdb] Cannot connect to InfluxDB due to '<urllib3.connection.HTTPConnection object at 0xffff6d696be0>: Failed to establish a new connection: [Errno 111] Connection refused'. Please check that the provided connection details (host, port, etc.) are correct and that your InfluxDB server is running and accessible. Retrying in 60 seconds.
2021-11-20 12:42:21 ERROR (SyncWorker_18) [homeassistant.components.influxdb] Cannot connect to InfluxDB due to '<urllib3.connection.HTTPConnection object at 0xffff6d6a3fa0>: Failed to establish a new connection: [Errno 111] Connection refused'. Please check that the provided connection details (host, port, etc.) are correct and that your InfluxDB server is running and accessible. Retrying in 60 seconds.
2021-11-20 12:42:53 ERROR (MainThread) [homeassistant.config] Invalid config for [automation]: expected str for dictionary value @ data['from']. Got None. (See ?, line ?). 
2021-11-20 12:42:53 ERROR (MainThread) [homeassistant.config] Invalid config for [automation]: required key not provided @ data['trigger'][1]['platform']. Got None. (See ?, line ?). 
2021-11-20 12:42:53 ERROR (MainThread) [homeassistant.config] Invalid config for [automation]: Unexpected value for condition: 'None'. Expected and, device, not, numeric_state, or, state, sun, template, time, trigger, zone @ data['condition'][0]. Got None. (See ?, line ?). 
2021-11-20 12:42:53 ERROR (MainThread) [homeassistant.config] Invalid config for [automation]: Unexpected value for condition: 'None'. Expected and, device, not, numeric_state, or, state, sun, template, time, trigger, zone @ data['condition'][0]. Got None. (See ?, line ?). 
2021-11-20 12:42:54 ERROR (MainThread) [homeassistant.config] Invalid config for [automation]: required key not provided @ data['action'][4]['domain']. Got None. (See ?, line ?). 
2021-11-20 12:42:55 ERROR (MainThread) [homeassistant.config] Invalid config for [automation]: must be a value between 0 and 59 for dictionary value @ data['minutes']. Got None. (See ?, line ?). 
2021-11-20 12:42:55 ERROR (MainThread) [homeassistant.config] Invalid config for [automation]: must be a value between 0 and 59 for dictionary value @ data['minutes']. Got None. (See ?, line ?). 
2021-11-20 12:42:57 WARNING (Thread-115) [homeassistant.util.executor] Thread[SyncWorker_13] is still running at shutdown: File "/usr/local/lib/python3.9/threading.py", line 930, in _bootstrap
    self._bootstrap_inner()
  File "/usr/local/lib/python3.9/threading.py", line 973, in _bootstrap_inner
    self.run()
  File "/usr/local/lib/python3.9/threading.py", line 910, in run
    self._target(*self._args, **self._kwargs)
  File "/usr/local/lib/python3.9/concurrent/futures/thread.py", line 77, in _worker
    work_item.run()
  File "/usr/local/lib/python3.9/concurrent/futures/thread.py", line 52, in run
    result = self.fn(*self.args, **self.kwargs)
  File "/usr/local/lib/python3.9/site-packages/synology_dsm/synology_dsm.py", line 161, in login
    result = self.get(API_AUTH, "login", params)
  File "/usr/local/lib/python3.9/site-packages/synology_dsm/synology_dsm.py", line 214, in get
    return self._request("GET", api, method, params, **kwargs)
  File "/usr/local/lib/python3.9/site-packages/synology_dsm/synology_dsm.py", line 232, in _request
    self.discover_apis()
  File "/usr/local/lib/python3.9/site-packages/synology_dsm/synology_dsm.py", line 132, in discover_apis
    self._apis = self.get(API_INFO, "query")["data"]
  File "/usr/local/lib/python3.9/site-packages/synology_dsm/synology_dsm.py", line 214, in get
    return self._request("GET", api, method, params, **kwargs)
  File "/usr/local/lib/python3.9/site-packages/synology_dsm/synology_dsm.py", line 265, in _request
    response = self._execute_request(request_method, url, params, **kwargs)
  File "/usr/local/lib/python3.9/site-packages/synology_dsm/synology_dsm.py", line 295, in _execute_request
    response = self._session.get(
  File "/usr/local/lib/python3.9/site-packages/requests/sessions.py", line 555, in get
    return self.request('GET', url, **kwargs)
  File "/usr/local/lib/python3.9/site-packages/requests/sessions.py", line 542, in request
    resp = self.send(prep, **send_kwargs)
  File "/usr/local/lib/python3.9/site-packages/requests/sessions.py", line 655, in send
    r = adapter.send(request, **kwargs)
  File "/usr/local/lib/python3.9/site-packages/requests/adapters.py", line 439, in send
    resp = conn.urlopen(
  File "/usr/local/lib/python3.9/site-packages/urllib3/connectionpool.py", line 699, in urlopen
    httplib_response = self._make_request(
  File "/usr/local/lib/python3.9/site-packages/urllib3/connectionpool.py", line 382, in _make_request
    self._validate_conn(conn)
  File "/usr/local/lib/python3.9/site-packages/urllib3/connectionpool.py", line 1010, in _validate_conn
    conn.connect()
  File "/usr/local/lib/python3.9/site-packages/urllib3/connection.py", line 358, in connect
    conn = self._new_conn()
  File "/usr/local/lib/python3.9/site-packages/urllib3/connection.py", line 174, in _new_conn
    conn = connection.create_connection(
  File "/usr/local/lib/python3.9/site-packages/urllib3/util/connection.py", line 86, in create_connection
    sock.connect(sa)
