2021-11-08 09:03:01 WARNING (SyncWorker_0) [homeassistant.loader] We found a custom integration adaptive_lighting which has not been tested by Home Assistant. This component might cause stability problems, be sure to disable it if you experience issues with Home Assistant
2021-11-08 09:03:01 WARNING (SyncWorker_1) [homeassistant.loader] We found a custom integration average which has not been tested by Home Assistant. This component might cause stability problems, be sure to disable it if you experience issues with Home Assistant
2021-11-08 09:03:01 WARNING (SyncWorker_2) [homeassistant.loader] We found a custom integration xiaomi_miio_airpurifier which has not been tested by Home Assistant. This component might cause stability problems, be sure to disable it if you experience issues with Home Assistant
2021-11-08 09:03:01 WARNING (SyncWorker_3) [homeassistant.loader] We found a custom integration audiconnect which has not been tested by Home Assistant. This component might cause stability problems, be sure to disable it if you experience issues with Home Assistant
2021-11-08 09:03:01 WARNING (SyncWorker_2) [homeassistant.loader] We found a custom integration monitor_docker which has not been tested by Home Assistant. This component might cause stability problems, be sure to disable it if you experience issues with Home Assistant
2021-11-08 09:03:01 WARNING (SyncWorker_3) [homeassistant.loader] We found a custom integration tuya_v2 which has not been tested by Home Assistant. This component might cause stability problems, be sure to disable it if you experience issues with Home Assistant
2021-11-08 09:03:01 WARNING (SyncWorker_2) [homeassistant.loader] We found a custom integration buienalarm which has not been tested by Home Assistant. This component might cause stability problems, be sure to disable it if you experience issues with Home Assistant
2021-11-08 09:03:01 WARNING (SyncWorker_4) [homeassistant.loader] We found a custom integration powercalc which has not been tested by Home Assistant. This component might cause stability problems, be sure to disable it if you experience issues with Home Assistant
2021-11-08 09:03:01 WARNING (SyncWorker_1) [homeassistant.loader] We found a custom integration localtuya which has not been tested by Home Assistant. This component might cause stability problems, be sure to disable it if you experience issues with Home Assistant
2021-11-08 09:03:01 WARNING (SyncWorker_2) [homeassistant.loader] We found a custom integration thermal_comfort which has not been tested by Home Assistant. This component might cause stability problems, be sure to disable it if you experience issues with Home Assistant
2021-11-08 09:03:01 WARNING (SyncWorker_0) [homeassistant.loader] We found a custom integration shelly which has not been tested by Home Assistant. This component might cause stability problems, be sure to disable it if you experience issues with Home Assistant
2021-11-08 09:03:01 WARNING (SyncWorker_4) [homeassistant.loader] We found a custom integration googlewifi which has not been tested by Home Assistant. This component might cause stability problems, be sure to disable it if you experience issues with Home Assistant
2021-11-08 09:03:01 WARNING (SyncWorker_2) [homeassistant.loader] We found a custom integration deepstack_face which has not been tested by Home Assistant. This component might cause stability problems, be sure to disable it if you experience issues with Home Assistant
2021-11-08 09:03:01 WARNING (SyncWorker_3) [homeassistant.loader] We found a custom integration xiaomi_miot which has not been tested by Home Assistant. This component might cause stability problems, be sure to disable it if you experience issues with Home Assistant
2021-11-08 09:03:01 WARNING (SyncWorker_5) [homeassistant.loader] We found a custom integration hacs which has not been tested by Home Assistant. This component might cause stability problems, be sure to disable it if you experience issues with Home Assistant
2021-11-08 09:03:01 WARNING (SyncWorker_8) [homeassistant.loader] We found a custom integration ytube_music_player which has not been tested by Home Assistant. This component might cause stability problems, be sure to disable it if you experience issues with Home Assistant
2021-11-08 09:03:01 WARNING (SyncWorker_3) [homeassistant.loader] We found a custom integration google_home which has not been tested by Home Assistant. This component might cause stability problems, be sure to disable it if you experience issues with Home Assistant
2021-11-08 09:03:01 WARNING (SyncWorker_0) [homeassistant.loader] We found a custom integration frigate which has not been tested by Home Assistant. This component might cause stability problems, be sure to disable it if you experience issues with Home Assistant
2021-11-08 09:03:01 WARNING (SyncWorker_6) [homeassistant.loader] We found a custom integration xiaomi_miio_fan which has not been tested by Home Assistant. This component might cause stability problems, be sure to disable it if you experience issues with Home Assistant
2021-11-08 09:03:01 WARNING (SyncWorker_2) [homeassistant.loader] We found a custom integration afvalbeheer which has not been tested by Home Assistant. This component might cause stability problems, be sure to disable it if you experience issues with Home Assistant
2021-11-08 09:03:01 WARNING (SyncWorker_7) [homeassistant.loader] We found a custom integration huesyncbox which has not been tested by Home Assistant. This component might cause stability problems, be sure to disable it if you experience issues with Home Assistant
2021-11-08 09:03:01 WARNING (SyncWorker_9) [homeassistant.loader] We found a custom integration anniversaries which has not been tested by Home Assistant. This component might cause stability problems, be sure to disable it if you experience issues with Home Assistant
2021-11-08 09:03:07 ERROR (SyncWorker_2) [homeassistant.components.influxdb] InfluxDB bucket is not accessible due to '(401)
Reason: Unauthorized
HTTP response headers: HTTPHeaderDict({'Content-Type': 'application/json; charset=utf-8', 'X-Influxdb-Build': 'OSS', 'X-Influxdb-Version': '2.1.0', 'X-Platform-Error-Code': 'unauthorized', 'Date': 'Mon, 08 Nov 2021 09:03:07 GMT', 'Content-Length': '55'})
HTTP response body: {"code":"unauthorized","message":"unauthorized access"}
'. Please check that the bucket, org and token are correct and that the token has the correct permissions set. Retrying in 60 seconds.
2021-11-08 09:03:10 WARNING (MainThread) [homeassistant.helpers.frame] Detected integration that called async_timeout.timeout with loop keyword argument. The loop keyword argument is deprecated and calls will fail after Home Assistant 2022.2. Please report issue for pi_hole using this method at homeassistant/components/pi_hole/__init__.py, line 111: await api.get_data()
2021-11-08 09:03:10 ERROR (MainThread) [homeassistant.config] Invalid config for [automation]: expected str for dictionary value @ data['from']. Got None. (See ?, line ?). 
2021-11-08 09:03:11 ERROR (MainThread) [homeassistant.config] Invalid config for [automation]: required key not provided @ data['action'][4]['domain']. Got None. (See ?, line ?). 
2021-11-08 09:03:11 ERROR (MainThread) [homeassistant.config] Invalid config for [automation]: must be a value between 0 and 59 for dictionary value @ data['minutes']. Got None. (See ?, line ?). 
2021-11-08 09:03:11 ERROR (MainThread) [homeassistant.config] Invalid config for [automation]: must be a value between 0 and 59 for dictionary value @ data['minutes']. Got None. (See ?, line ?). 
2021-11-08 09:03:16 WARNING (MainThread) [homeassistant.setup] Setup of counter is taking over 10 seconds.
2021-11-08 09:03:16 WARNING (MainThread) [homeassistant.setup] Setup of input_text is taking over 10 seconds.
2021-11-08 09:03:16 WARNING (MainThread) [homeassistant.components.fan] Platform xiaomi_miio_fan not ready yet: Unable to discover the device 192.168.86.28; Retrying in background in 30 seconds
2021-11-08 09:03:16 WARNING (MainThread) [homeassistant.components.fan] Platform xiaomi_miio_fan not ready yet: Unable to discover the device 192.168.86.29; Retrying in background in 30 seconds
2021-11-08 09:03:17 WARNING (MainThread) [homeassistant.setup] Setup of input_select is taking over 10 seconds.
2021-11-08 09:03:17 WARNING (MainThread) [homeassistant.setup] Setup of input_number is taking over 10 seconds.
2021-11-08 09:03:17 WARNING (MainThread) [homeassistant.helpers.frame] Detected integration that called async_timeout.timeout with loop keyword argument. The loop keyword argument is deprecated and calls will fail after Home Assistant 2022.2. Please report issue for pi_hole using this method at homeassistant/components/pi_hole/__init__.py, line 119: await api.get_data()
2021-11-08 09:03:18 WARNING (MainThread) [homeassistant.setup] Setup of timer is taking over 10 seconds.
2021-11-08 09:03:20 WARNING (MainThread) [homeassistant.config_entries] Config entry '192.168.86.83' for synology_dsm integration not ready yet: ConnectionError = <urllib3.connection.HTTPSConnection object at 0xffff8f42e340>: Failed to establish a new connection: [Errno 113] Host is unreachable; Retrying in background
2021-11-08 09:03:22 WARNING (MainThread) [homeassistant.components.light] Platform netatmo not ready yet: None; Retrying in background in 30 seconds
2021-11-08 09:03:22 WARNING (MainThread) [homeassistant.components.select] Platform netatmo not ready yet: None; Retrying in background in 30 seconds
2021-11-08 09:03:23 WARNING (MainThread) [homeassistant.components.hue.light] Please check for software updates of the douche bulb in the Philips Hue App.
2021-11-08 09:03:23 WARNING (MainThread) [homeassistant.components.hue.light] Please check for software updates of the wasbak rechts bulb in the Philips Hue App.
2021-11-08 09:03:26 ERROR (MainThread) [custom_components.powercalc.sensors.power] Skipping sensor setup light.buiten: ('No lookup file found for mode', 'brightness')
2021-11-08 09:03:27 ERROR (MainThread) [homeassistant.components.hue.sensor_base] Timeout fetching sensor data
2021-11-08 09:03:27 ERROR (MainThread) [homeassistant.components.hue.sensor_base] Timeout fetching sensor data
2021-11-08 09:03:27 WARNING (MainThread) [homeassistant.components.media_player] Setup of media_player platform samsungtv is taking over 10 seconds.
2021-11-08 09:03:28 WARNING (MainThread) [homeassistant.components.climate] Platform netatmo not ready yet: None; Retrying in background in 30 seconds
2021-11-08 09:03:28 WARNING (MainThread) [homeassistant.components.camera] Platform netatmo not ready yet: None; Retrying in background in 30 seconds
2021-11-08 09:03:29 WARNING (MainThread) [homeassistant.helpers.frame] Detected integration that called async_timeout.timeout with loop keyword argument. The loop keyword argument is deprecated and calls will fail after Home Assistant 2022.2. Please report issue for pi_hole using this method at homeassistant/components/pi_hole/__init__.py, line 119: await api.get_data()
2021-11-08 09:03:29 WARNING (MainThread) [homeassistant.components.sensor] Platform netatmo not ready yet: None; Retrying in background in 30 seconds
2021-11-08 09:03:30 WARNING (MainThread) [homeassistant.config_entries] Config entry 'OnHub' for upnp integration not ready yet; Retrying in background
2021-11-08 09:03:31 WARNING (MainThread) [homeassistant.components.binary_sensor] Updating ping binary_sensor took longer than the scheduled update interval 0:00:05
2021-11-08 09:03:32 WARNING (MainThread) [homeassistant.components.sensor] Setup of sensor platform scrape is taking over 10 seconds.
2021-11-08 09:03:32 WARNING (MainThread) [homeassistant.components.sensor] Setup of sensor platform scrape is taking over 10 seconds.
2021-11-08 09:03:32 WARNING (MainThread) [homeassistant.components.sensor] Setup of sensor platform scrape is taking over 10 seconds.
2021-11-08 09:03:32 WARNING (MainThread) [homeassistant.components.sensor] Setup of sensor platform scrape is taking over 10 seconds.
2021-11-08 09:03:32 WARNING (MainThread) [homeassistant.components.sensor] Setup of sensor platform scrape is taking over 10 seconds.
2021-11-08 09:03:32 WARNING (MainThread) [homeassistant.components.sensor] Setup of sensor platform scrape is taking over 10 seconds.
2021-11-08 09:03:35 ERROR (MainThread) [homeassistant.components.sensor] scrape: Error on device update!
Traceback (most recent call last):
  File "/usr/src/homeassistant/homeassistant/helpers/entity_platform.py", line 431, in _async_add_entity
    await entity.async_device_update(warning=False)
  File "/usr/src/homeassistant/homeassistant/helpers/entity.py", line 645, in async_device_update
    await task
  File "/usr/src/homeassistant/homeassistant/components/scrape/sensor.py", line 166, in async_update
    await self._async_update_from_rest_data()
  File "/usr/src/homeassistant/homeassistant/components/scrape/sensor.py", line 179, in _async_update_from_rest_data
    value = await self.hass.async_add_executor_job(self._extract_value)
  File "/usr/local/lib/python3.9/concurrent/futures/thread.py", line 52, in run
    result = self.fn(*self.args, **self.kwargs)
  File "/usr/src/homeassistant/homeassistant/components/scrape/sensor.py", line 155, in _extract_value
    tag = raw_data.select(self._select)[self._index]
  File "/usr/local/lib/python3.9/site-packages/bs4/element.py", line 1949, in select
    results = soupsieve.select(selector, self, namespaces, limit, **kwargs)
  File "/usr/local/lib/python3.9/site-packages/soupsieve/__init__.py", line 144, in select
    return compile(select, namespaces, flags, **kwargs).select(tag, limit)
  File "/usr/local/lib/python3.9/site-packages/soupsieve/__init__.py", line 67, in compile
    return cp._cached_css_compile(pattern, ns, cs, flags)
  File "/usr/local/lib/python3.9/site-packages/soupsieve/css_parser.py", line 218, in _cached_css_compile
    CSSParser(
  File "/usr/local/lib/python3.9/site-packages/soupsieve/css_parser.py", line 1159, in process_selectors
    return self.parse_selectors(self.selector_iter(self.pattern), index, flags)
  File "/usr/local/lib/python3.9/site-packages/soupsieve/css_parser.py", line 985, in parse_selectors
    key, m = next(iselector)
  File "/usr/local/lib/python3.9/site-packages/soupsieve/css_parser.py", line 1152, in selector_iter
    raise SelectorSyntaxError(msg, self.pattern, index)
soupsieve.util.SelectorSyntaxError: Invalid character '<' position 0
  line 1:
<span _ngcontent-app-root-c173="">Offline</span>
^
2021-11-08 09:04:02 WARNING (MainThread) [homeassistant.components.fan] Setup of fan platform xiaomi_miio_fan is taking over 10 seconds.
2021-11-08 09:04:02 WARNING (MainThread) [homeassistant.components.fan] Setup of fan platform xiaomi_miio_fan is taking over 10 seconds.
2021-11-08 09:04:05 ERROR (Thread-6) [pychromecast.discovery] Unhandled exception in worker thread
Traceback (most recent call last):
  File "/usr/local/lib/python3.9/site-packages/pychromecast/discovery.py", line 272, in run
    self._poll_hosts()
  File "/usr/local/lib/python3.9/site-packages/pychromecast/discovery.py", line 359, in _poll_hosts
    self._update_devices(host, devices, uuids)
  File "/usr/local/lib/python3.9/site-packages/pychromecast/discovery.py", line 382, in _update_devices
    callback()
  File "/usr/src/homeassistant/homeassistant/components/cast/discovery.py", line 70, in update_cast
    discover_chromecast(hass, browser.devices[uuid])
  File "/usr/src/homeassistant/homeassistant/components/cast/discovery.py", line 39, in discover_chromecast
    info = info.fill_out_missing_chromecast_info()
  File "/usr/src/homeassistant/homeassistant/components/cast/helpers.py", line 89, in fill_out_missing_chromecast_info
    http_device_status = dial.get_device_status(
  File "/usr/local/lib/python3.9/site-packages/pychromecast/dial.py", line 116, in get_device_status
    status = _get_status(
  File "/usr/local/lib/python3.9/site-packages/pychromecast/dial.py", line 76, in _get_status
    host, _, _ = get_host_from_service(service, zconf)
  File "/usr/local/lib/python3.9/site-packages/pychromecast/dial.py", line 37, in get_host_from_service
    service_info = zconf.get_service_info("_googlecast._tcp.local.", service.data)
  File "/usr/local/lib/python3.9/site-packages/zeroconf/_core.py", line 523, in get_service_info
    if info.request(self, timeout, question_type):
  File "/usr/local/lib/python3.9/site-packages/zeroconf/_services/info.py", line 458, in request
    return bool(run_coro_with_timeout(self.async_request(zc, timeout, question_type), zc.loop, timeout))
  File "/usr/local/lib/python3.9/site-packages/zeroconf/_utils/asyncio.py", line 95, in run_coro_with_timeout
    return asyncio.run_coroutine_threadsafe(aw, loop).result(
  File "/usr/local/lib/python3.9/concurrent/futures/_base.py", line 447, in result
    raise TimeoutError()
concurrent.futures._base.TimeoutError
2021-11-08 09:04:05 ERROR (Thread-6) [root] Uncaught thread exception
Traceback (most recent call last):
  File "/usr/local/lib/python3.9/threading.py", line 973, in _bootstrap_inner
    self.run()
  File "/usr/local/lib/python3.9/site-packages/pychromecast/discovery.py", line 272, in run
    self._poll_hosts()
  File "/usr/local/lib/python3.9/site-packages/pychromecast/discovery.py", line 359, in _poll_hosts
    self._update_devices(host, devices, uuids)
  File "/usr/local/lib/python3.9/site-packages/pychromecast/discovery.py", line 382, in _update_devices
    callback()
  File "/usr/src/homeassistant/homeassistant/components/cast/discovery.py", line 70, in update_cast
    discover_chromecast(hass, browser.devices[uuid])
  File "/usr/src/homeassistant/homeassistant/components/cast/discovery.py", line 39, in discover_chromecast
    info = info.fill_out_missing_chromecast_info()
  File "/usr/src/homeassistant/homeassistant/components/cast/helpers.py", line 89, in fill_out_missing_chromecast_info
    http_device_status = dial.get_device_status(
  File "/usr/local/lib/python3.9/site-packages/pychromecast/dial.py", line 116, in get_device_status
    status = _get_status(
  File "/usr/local/lib/python3.9/site-packages/pychromecast/dial.py", line 76, in _get_status
    host, _, _ = get_host_from_service(service, zconf)
  File "/usr/local/lib/python3.9/site-packages/pychromecast/dial.py", line 37, in get_host_from_service
    service_info = zconf.get_service_info("_googlecast._tcp.local.", service.data)
  File "/usr/local/lib/python3.9/site-packages/zeroconf/_core.py", line 523, in get_service_info
    if info.request(self, timeout, question_type):
  File "/usr/local/lib/python3.9/site-packages/zeroconf/_services/info.py", line 458, in request
    return bool(run_coro_with_timeout(self.async_request(zc, timeout, question_type), zc.loop, timeout))
  File "/usr/local/lib/python3.9/site-packages/zeroconf/_utils/asyncio.py", line 95, in run_coro_with_timeout
    return asyncio.run_coroutine_threadsafe(aw, loop).result(
  File "/usr/local/lib/python3.9/concurrent/futures/_base.py", line 447, in result
    raise TimeoutError()
concurrent.futures._base.TimeoutError
2021-11-08 09:04:05 ERROR (MainThread) [homeassistant.components.mobile_app.notify] Timeout sending notification to https://mobile-apps.home-assistant.io/api/sendPush/android/v1
2021-11-08 09:04:05 WARNING (MainThread) [homeassistant.components.media_player] Updating huesyncbox media_player took longer than the scheduled update interval 0:00:02
2021-11-08 09:04:05 WARNING (MainThread) [homeassistant.components.binary_sensor] Updating ping binary_sensor took longer than the scheduled update interval 0:00:05
2021-11-08 09:04:06 WARNING (MainThread) [homeassistant.helpers.entity] Update of binary_sensor.google_server is taking over 10 seconds
2021-11-08 09:04:06 WARNING (MainThread) [homeassistant.components.media_player] Updating samsungtv media_player took longer than the scheduled update interval 0:00:10
2021-11-08 09:04:08 WARNING (MainThread) [homeassistant.components.binary_sensor] Updating ping binary_sensor took longer than the scheduled update interval 0:00:05
2021-11-08 09:04:09 ERROR (MainThread) [homeassistant.components.google_assistant.http] Request for https://homegraph.googleapis.com/v1/devices:requestSync failed: 500
2021-11-08 09:04:09 ERROR (SyncWorker_13) [homeassistant.components.influxdb] InfluxDB bucket is not accessible due to '(401)
Reason: Unauthorized
HTTP response headers: HTTPHeaderDict({'Content-Type': 'application/json; charset=utf-8', 'X-Influxdb-Build': 'OSS', 'X-Influxdb-Version': '2.1.0', 'X-Platform-Error-Code': 'unauthorized', 'Date': 'Mon, 08 Nov 2021 09:04:09 GMT', 'Content-Length': '55'})
HTTP response body: {"code":"unauthorized","message":"unauthorized access"}
'. Please check that the bucket, org and token are correct and that the token has the correct permissions set. Retrying in 60 seconds.
2021-11-08 09:04:12 ERROR (MainThread) [homeassistant.components.google_assistant.http] Request for https://homegraph.googleapis.com/v1/devices:reportStateAndNotification failed: 404
2021-11-08 09:04:48 WARNING (MainThread) [homeassistant.components.binary_sensor] Updating ping binary_sensor took longer than the scheduled update interval 0:00:05
2021-11-08 09:05:09 ERROR (SyncWorker_11) [homeassistant.components.influxdb] InfluxDB bucket is not accessible due to '(401)
Reason: Unauthorized
HTTP response headers: HTTPHeaderDict({'Content-Type': 'application/json; charset=utf-8', 'X-Influxdb-Build': 'OSS', 'X-Influxdb-Version': '2.1.0', 'X-Platform-Error-Code': 'unauthorized', 'Date': 'Mon, 08 Nov 2021 09:05:09 GMT', 'Content-Length': '55'})
HTTP response body: {"code":"unauthorized","message":"unauthorized access"}
'. Please check that the bucket, org and token are correct and that the token has the correct permissions set. Retrying in 60 seconds.
2021-11-08 09:05:47 ERROR (MainThread) [homeassistant.config] Invalid config for [automation]: expected str for dictionary value @ data['from']. Got None. (See ?, line ?). 
2021-11-08 09:05:47 ERROR (MainThread) [homeassistant.config] Invalid config for [automation]: required key not provided @ data['action'][4]['domain']. Got None. (See ?, line ?). 
2021-11-08 09:05:47 ERROR (MainThread) [homeassistant.config] Invalid config for [automation]: must be a value between 0 and 59 for dictionary value @ data['minutes']. Got None. (See ?, line ?). 
2021-11-08 09:05:47 ERROR (MainThread) [homeassistant.config] Invalid config for [automation]: must be a value between 0 and 59 for dictionary value @ data['minutes']. Got None. (See ?, line ?). 
2021-11-08 09:06:09 ERROR (SyncWorker_14) [homeassistant.components.influxdb] InfluxDB bucket is not accessible due to '(401)
Reason: Unauthorized
HTTP response headers: HTTPHeaderDict({'Content-Type': 'application/json; charset=utf-8', 'X-Influxdb-Build': 'OSS', 'X-Influxdb-Version': '2.1.0', 'X-Platform-Error-Code': 'unauthorized', 'Date': 'Mon, 08 Nov 2021 09:06:09 GMT', 'Content-Length': '55'})
HTTP response body: {"code":"unauthorized","message":"unauthorized access"}
'. Please check that the bucket, org and token are correct and that the token has the correct permissions set. Retrying in 60 seconds.
2021-11-08 09:07:09 ERROR (SyncWorker_7) [homeassistant.components.influxdb] InfluxDB bucket is not accessible due to '(401)
Reason: Unauthorized
HTTP response headers: HTTPHeaderDict({'Content-Type': 'application/json; charset=utf-8', 'X-Influxdb-Build': 'OSS', 'X-Influxdb-Version': '2.1.0', 'X-Platform-Error-Code': 'unauthorized', 'Date': 'Mon, 08 Nov 2021 09:07:09 GMT', 'Content-Length': '55'})
HTTP response body: {"code":"unauthorized","message":"unauthorized access"}
'. Please check that the bucket, org and token are correct and that the token has the correct permissions set. Retrying in 60 seconds.
2021-11-08 09:08:09 ERROR (SyncWorker_13) [homeassistant.components.influxdb] InfluxDB bucket is not accessible due to '(401)
Reason: Unauthorized
HTTP response headers: HTTPHeaderDict({'Content-Type': 'application/json; charset=utf-8', 'X-Influxdb-Build': 'OSS', 'X-Influxdb-Version': '2.1.0', 'X-Platform-Error-Code': 'unauthorized', 'Date': 'Mon, 08 Nov 2021 09:08:09 GMT', 'Content-Length': '55'})
HTTP response body: {"code":"unauthorized","message":"unauthorized access"}
'. Please check that the bucket, org and token are correct and that the token has the correct permissions set. Retrying in 60 seconds.
2021-11-08 09:08:29 WARNING (MainThread) [homeassistant.helpers.frame] Detected integration that called async_timeout.timeout with loop keyword argument. The loop keyword argument is deprecated and calls will fail after Home Assistant 2022.2. Please report issue for pi_hole using this method at homeassistant/components/pi_hole/__init__.py, line 119: await api.get_data()
2021-11-08 09:09:09 ERROR (SyncWorker_8) [homeassistant.components.influxdb] InfluxDB bucket is not accessible due to '(401)
Reason: Unauthorized
HTTP response headers: HTTPHeaderDict({'Content-Type': 'application/json; charset=utf-8', 'X-Influxdb-Build': 'OSS', 'X-Influxdb-Version': '2.1.0', 'X-Platform-Error-Code': 'unauthorized', 'Date': 'Mon, 08 Nov 2021 09:09:09 GMT', 'Content-Length': '55'})
HTTP response body: {"code":"unauthorized","message":"unauthorized access"}
'. Please check that the bucket, org and token are correct and that the token has the correct permissions set. Retrying in 60 seconds.
2021-11-08 09:10:10 ERROR (SyncWorker_6) [homeassistant.components.influxdb] InfluxDB bucket is not accessible due to '(401)
Reason: Unauthorized
HTTP response headers: HTTPHeaderDict({'Content-Type': 'application/json; charset=utf-8', 'X-Influxdb-Build': 'OSS', 'X-Influxdb-Version': '2.1.0', 'X-Platform-Error-Code': 'unauthorized', 'Date': 'Mon, 08 Nov 2021 09:10:10 GMT', 'Content-Length': '55'})
HTTP response body: {"code":"unauthorized","message":"unauthorized access"}
'. Please check that the bucket, org and token are correct and that the token has the correct permissions set. Retrying in 60 seconds.
2021-11-08 09:11:10 ERROR (SyncWorker_1) [homeassistant.components.influxdb] InfluxDB bucket is not accessible due to '(401)
Reason: Unauthorized
HTTP response headers: HTTPHeaderDict({'Content-Type': 'application/json; charset=utf-8', 'X-Influxdb-Build': 'OSS', 'X-Influxdb-Version': '2.1.0', 'X-Platform-Error-Code': 'unauthorized', 'Date': 'Mon, 08 Nov 2021 09:11:10 GMT', 'Content-Length': '55'})
HTTP response body: {"code":"unauthorized","message":"unauthorized access"}
'. Please check that the bucket, org and token are correct and that the token has the correct permissions set. Retrying in 60 seconds.
2021-11-08 09:12:10 ERROR (SyncWorker_7) [homeassistant.components.influxdb] InfluxDB bucket is not accessible due to '(401)
Reason: Unauthorized
HTTP response headers: HTTPHeaderDict({'Content-Type': 'application/json; charset=utf-8', 'X-Influxdb-Build': 'OSS', 'X-Influxdb-Version': '2.1.0', 'X-Platform-Error-Code': 'unauthorized', 'Date': 'Mon, 08 Nov 2021 09:12:10 GMT', 'Content-Length': '55'})
HTTP response body: {"code":"unauthorized","message":"unauthorized access"}
'. Please check that the bucket, org and token are correct and that the token has the correct permissions set. Retrying in 60 seconds.
2021-11-08 09:13:10 ERROR (SyncWorker_14) [homeassistant.components.influxdb] InfluxDB bucket is not accessible due to '(401)
Reason: Unauthorized
HTTP response headers: HTTPHeaderDict({'Content-Type': 'application/json; charset=utf-8', 'X-Influxdb-Build': 'OSS', 'X-Influxdb-Version': '2.1.0', 'X-Platform-Error-Code': 'unauthorized', 'Date': 'Mon, 08 Nov 2021 09:13:10 GMT', 'Content-Length': '55'})
HTTP response body: {"code":"unauthorized","message":"unauthorized access"}
'. Please check that the bucket, org and token are correct and that the token has the correct permissions set. Retrying in 60 seconds.
2021-11-08 09:13:29 WARNING (MainThread) [homeassistant.helpers.frame] Detected integration that called async_timeout.timeout with loop keyword argument. The loop keyword argument is deprecated and calls will fail after Home Assistant 2022.2. Please report issue for pi_hole using this method at homeassistant/components/pi_hole/__init__.py, line 119: await api.get_data()
2021-11-08 09:13:31 ERROR (MainThread) [homeassistant.components.google_assistant.http] Request for https://homegraph.googleapis.com/v1/devices:reportStateAndNotification failed: 404
2021-11-08 09:14:10 ERROR (SyncWorker_7) [homeassistant.components.influxdb] InfluxDB bucket is not accessible due to '(401)
Reason: Unauthorized
HTTP response headers: HTTPHeaderDict({'Content-Type': 'application/json; charset=utf-8', 'X-Influxdb-Build': 'OSS', 'X-Influxdb-Version': '2.1.0', 'X-Platform-Error-Code': 'unauthorized', 'Date': 'Mon, 08 Nov 2021 09:14:10 GMT', 'Content-Length': '55'})
HTTP response body: {"code":"unauthorized","message":"unauthorized access"}
'. Please check that the bucket, org and token are correct and that the token has the correct permissions set. Retrying in 60 seconds.
2021-11-08 09:14:39 ERROR (MainThread) [homeassistant.config] Invalid config for [automation]: expected str for dictionary value @ data['from']. Got None. (See ?, line ?). 
2021-11-08 09:14:39 ERROR (MainThread) [homeassistant.config] Invalid config for [automation]: required key not provided @ data['action'][4]['domain']. Got None. (See ?, line ?). 
2021-11-08 09:14:39 ERROR (MainThread) [homeassistant.config] Invalid config for [automation]: must be a value between 0 and 59 for dictionary value @ data['minutes']. Got None. (See ?, line ?). 
2021-11-08 09:14:39 ERROR (MainThread) [homeassistant.config] Invalid config for [automation]: must be a value between 0 and 59 for dictionary value @ data['minutes']. Got None. (See ?, line ?). 
2021-11-08 09:14:45 ERROR (MainThread) [homeassistant.config] Invalid config for [automation]: expected str for dictionary value @ data['from']. Got None. (See ?, line ?). 
2021-11-08 09:14:45 ERROR (MainThread) [homeassistant.config] Invalid config for [automation]: required key not provided @ data['action'][4]['domain']. Got None. (See ?, line ?). 
2021-11-08 09:14:45 ERROR (MainThread) [homeassistant.config] Invalid config for [automation]: must be a value between 0 and 59 for dictionary value @ data['minutes']. Got None. (See ?, line ?). 
2021-11-08 09:14:45 ERROR (MainThread) [homeassistant.config] Invalid config for [automation]: must be a value between 0 and 59 for dictionary value @ data['minutes']. Got None. (See ?, line ?). 
2021-11-08 09:14:46 ERROR (MainThread) [homeassistant.helpers.entity] Update for sensor.master_bedroom_tv_on_today fails
Traceback (most recent call last):
  File "/usr/src/homeassistant/homeassistant/helpers/entity.py", line 462, in async_update_ha_state
    await self.async_device_update()
  File "/usr/src/homeassistant/homeassistant/helpers/entity.py", line 652, in async_device_update
    raise exc
  File "/usr/src/homeassistant/homeassistant/components/history_stats/sensor.py", line 221, in async_update
    await self.hass.async_add_executor_job(
  File "/usr/local/lib/python3.9/concurrent/futures/thread.py", line 52, in run
    result = self.fn(*self.args, **self.kwargs)
  File "/usr/src/homeassistant/homeassistant/components/history_stats/sensor.py", line 227, in _update
    history_list = history.state_changes_during_period(
  File "/usr/src/homeassistant/homeassistant/components/recorder/history.py", line 147, in state_changes_during_period
    with session_scope(hass=hass) as session:
  File "/usr/local/lib/python3.9/contextlib.py", line 119, in __enter__
    return next(self.gen)
  File "/usr/src/homeassistant/homeassistant/components/recorder/util.py", line 73, in session_scope
    session = hass.data[DATA_INSTANCE].get_session()
TypeError: 'NoneType' object is not callable
2021-11-08 09:14:46 ERROR (MainThread) [homeassistant.helpers.entity] Update for sensor.veranda_speaker_on_today fails
Traceback (most recent call last):
  File "/usr/src/homeassistant/homeassistant/helpers/entity.py", line 462, in async_update_ha_state
    await self.async_device_update()
  File "/usr/src/homeassistant/homeassistant/helpers/entity.py", line 652, in async_device_update
    raise exc
  File "/usr/src/homeassistant/homeassistant/components/history_stats/sensor.py", line 221, in async_update
    await self.hass.async_add_executor_job(
  File "/usr/local/lib/python3.9/concurrent/futures/thread.py", line 52, in run
    result = self.fn(*self.args, **self.kwargs)
  File "/usr/src/homeassistant/homeassistant/components/history_stats/sensor.py", line 227, in _update
    history_list = history.state_changes_during_period(
  File "/usr/src/homeassistant/homeassistant/components/recorder/history.py", line 147, in state_changes_during_period
    with session_scope(hass=hass) as session:
  File "/usr/local/lib/python3.9/contextlib.py", line 119, in __enter__
    return next(self.gen)
  File "/usr/src/homeassistant/homeassistant/components/recorder/util.py", line 73, in session_scope
    session = hass.data[DATA_INSTANCE].get_session()
TypeError: 'NoneType' object is not callable
