2021-11-04 22:37:18 WARNING (SyncWorker_1) [homeassistant.loader] We found a custom integration average which has not been tested by Home Assistant. This component might cause stability problems, be sure to disable it if you experience issues with Home Assistant
2021-11-04 22:37:18 WARNING (SyncWorker_2) [homeassistant.loader] We found a custom integration xiaomi_miio_airpurifier which has not been tested by Home Assistant. This component might cause stability problems, be sure to disable it if you experience issues with Home Assistant
2021-11-04 22:37:18 WARNING (SyncWorker_0) [homeassistant.loader] We found a custom integration adaptive_lighting which has not been tested by Home Assistant. This component might cause stability problems, be sure to disable it if you experience issues with Home Assistant
2021-11-04 22:37:18 WARNING (SyncWorker_1) [homeassistant.loader] We found a custom integration powercalc which has not been tested by Home Assistant. This component might cause stability problems, be sure to disable it if you experience issues with Home Assistant
2021-11-04 22:37:18 WARNING (SyncWorker_0) [homeassistant.loader] We found a custom integration monitor_docker which has not been tested by Home Assistant. This component might cause stability problems, be sure to disable it if you experience issues with Home Assistant
2021-11-04 22:37:18 WARNING (SyncWorker_1) [homeassistant.loader] We found a custom integration shelly which has not been tested by Home Assistant. This component might cause stability problems, be sure to disable it if you experience issues with Home Assistant
2021-11-04 22:37:18 WARNING (SyncWorker_5) [homeassistant.loader] We found a custom integration hacs which has not been tested by Home Assistant. This component might cause stability problems, be sure to disable it if you experience issues with Home Assistant
2021-11-04 22:37:18 WARNING (SyncWorker_0) [homeassistant.loader] We found a custom integration huesyncbox which has not been tested by Home Assistant. This component might cause stability problems, be sure to disable it if you experience issues with Home Assistant
2021-11-04 22:37:18 WARNING (SyncWorker_2) [homeassistant.loader] We found a custom integration xiaomi_miio_fan which has not been tested by Home Assistant. This component might cause stability problems, be sure to disable it if you experience issues with Home Assistant
2021-11-04 22:37:18 WARNING (SyncWorker_3) [homeassistant.loader] We found a custom integration audiconnect which has not been tested by Home Assistant. This component might cause stability problems, be sure to disable it if you experience issues with Home Assistant
2021-11-04 22:37:18 WARNING (SyncWorker_6) [homeassistant.loader] We found a custom integration localtuya which has not been tested by Home Assistant. This component might cause stability problems, be sure to disable it if you experience issues with Home Assistant
2021-11-04 22:37:18 WARNING (SyncWorker_0) [homeassistant.loader] We found a custom integration anniversaries which has not been tested by Home Assistant. This component might cause stability problems, be sure to disable it if you experience issues with Home Assistant
2021-11-04 22:37:18 WARNING (SyncWorker_1) [homeassistant.loader] We found a custom integration deepstack_face which has not been tested by Home Assistant. This component might cause stability problems, be sure to disable it if you experience issues with Home Assistant
2021-11-04 22:37:18 WARNING (SyncWorker_6) [homeassistant.loader] We found a custom integration googlewifi which has not been tested by Home Assistant. This component might cause stability problems, be sure to disable it if you experience issues with Home Assistant
2021-11-04 22:37:18 WARNING (SyncWorker_7) [homeassistant.loader] We found a custom integration tuya_v2 which has not been tested by Home Assistant. This component might cause stability problems, be sure to disable it if you experience issues with Home Assistant
2021-11-04 22:37:18 WARNING (SyncWorker_2) [homeassistant.loader] We found a custom integration google_home which has not been tested by Home Assistant. This component might cause stability problems, be sure to disable it if you experience issues with Home Assistant
2021-11-04 22:37:18 WARNING (SyncWorker_4) [homeassistant.loader] We found a custom integration thermal_comfort which has not been tested by Home Assistant. This component might cause stability problems, be sure to disable it if you experience issues with Home Assistant
2021-11-04 22:37:18 WARNING (SyncWorker_3) [homeassistant.loader] We found a custom integration xiaomi_miot which has not been tested by Home Assistant. This component might cause stability problems, be sure to disable it if you experience issues with Home Assistant
2021-11-04 22:37:18 WARNING (SyncWorker_1) [homeassistant.loader] We found a custom integration afvalbeheer which has not been tested by Home Assistant. This component might cause stability problems, be sure to disable it if you experience issues with Home Assistant
2021-11-04 22:37:18 WARNING (SyncWorker_9) [homeassistant.loader] We found a custom integration ytube_music_player which has not been tested by Home Assistant. This component might cause stability problems, be sure to disable it if you experience issues with Home Assistant
2021-11-04 22:37:18 WARNING (SyncWorker_8) [homeassistant.loader] We found a custom integration buienalarm which has not been tested by Home Assistant. This component might cause stability problems, be sure to disable it if you experience issues with Home Assistant
2021-11-04 22:37:26 ERROR (SyncWorker_7) [homeassistant.components.influxdb] InfluxDB bucket is not accessible due to '(401)
Reason: Unauthorized
HTTP response headers: HTTPHeaderDict({'Content-Type': 'application/json; charset=utf-8', 'X-Influxdb-Build': 'OSS', 'X-Influxdb-Version': '2.0.9', 'X-Platform-Error-Code': 'unauthorized', 'Date': 'Thu, 04 Nov 2021 22:37:26 GMT', 'Content-Length': '55'})
HTTP response body: {"code":"unauthorized","message":"unauthorized access"}
'. Please check that the bucket, org and token are correct and that the token has the correct permissions set. Retrying in 60 seconds.
2021-11-04 22:37:29 ERROR (MainThread) [homeassistant.config] Invalid config for [automation]: expected str for dictionary value @ data['from']. Got None. (See ?, line ?). 
2021-11-04 22:37:29 ERROR (MainThread) [homeassistant.config] Invalid config for [automation]: required key not provided @ data['action'][4]['domain']. Got None. (See ?, line ?). 
2021-11-04 22:37:29 ERROR (MainThread) [homeassistant.config] Invalid config for [automation]: must be a value between 0 and 59 for dictionary value @ data['minutes']. Got None. (See ?, line ?). 
2021-11-04 22:37:29 ERROR (MainThread) [homeassistant.config] Invalid config for [automation]: must be a value between 0 and 59 for dictionary value @ data['minutes']. Got None. (See ?, line ?). 
2021-11-04 22:37:34 WARNING (MainThread) [homeassistant.setup] Setup of timer is taking over 10 seconds.
2021-11-04 22:37:34 WARNING (MainThread) [homeassistant.setup] Setup of counter is taking over 10 seconds.
2021-11-04 22:37:34 WARNING (MainThread) [homeassistant.setup] Setup of input_text is taking over 10 seconds.
2021-11-04 22:37:34 WARNING (MainThread) [homeassistant.setup] Setup of input_number is taking over 10 seconds.
2021-11-04 22:37:34 WARNING (MainThread) [homeassistant.setup] Setup of zone is taking over 10 seconds.
2021-11-04 22:37:34 WARNING (MainThread) [homeassistant.setup] Setup of input_datetime is taking over 10 seconds.
2021-11-04 22:37:34 WARNING (MainThread) [homeassistant.setup] Setup of input_boolean is taking over 10 seconds.
2021-11-04 22:37:34 WARNING (MainThread) [homeassistant.setup] Setup of input_select is taking over 10 seconds.
2021-11-04 22:37:34 WARNING (MainThread) [homeassistant.components.fan] Platform xiaomi_miio_fan not ready yet: Unable to discover the device 192.168.86.29; Retrying in background in 30 seconds
2021-11-04 22:37:34 WARNING (MainThread) [homeassistant.components.fan] Platform xiaomi_miio_fan not ready yet: Unable to discover the device 192.168.86.28; Retrying in background in 30 seconds
2021-11-04 22:37:37 WARNING (MainThread) [homeassistant.config_entries] Config entry '192.168.86.83' for synology_dsm integration not ready yet: ConnectionError = <urllib3.connection.HTTPSConnection object at 0xffffa0eaa4c0>: Failed to establish a new connection: [Errno 113] Host is unreachable; Retrying in background
2021-11-04 22:37:40 ERROR (MainThread) [custom_components.powercalc.sensors.power] Skipping sensor setup light.buiten: ('No lookup file found for mode', 'brightness')
2021-11-04 22:37:40 WARNING (MainThread) [homeassistant.components.hue.light] Please check for software updates of the wasbak rechts bulb in the Philips Hue App.
2021-11-04 22:37:42 WARNING (MainThread) [homeassistant.components.light] Platform netatmo not ready yet: None; Retrying in background in 30 seconds
2021-11-04 22:37:42 WARNING (MainThread) [homeassistant.components.select] Platform netatmo not ready yet: None; Retrying in background in 30 seconds
2021-11-04 22:37:45 ERROR (MainThread) [homeassistant.components.sensor] scrape: Error on device update!
Traceback (most recent call last):
  File "/usr/src/homeassistant/homeassistant/helpers/entity_platform.py", line 431, in _async_add_entity
    await entity.async_device_update(warning=False)
  File "/usr/src/homeassistant/homeassistant/helpers/entity.py", line 651, in async_device_update
    await task
  File "/usr/src/homeassistant/homeassistant/components/scrape/sensor.py", line 166, in async_update
    await self._async_update_from_rest_data()
  File "/usr/src/homeassistant/homeassistant/components/scrape/sensor.py", line 179, in _async_update_from_rest_data
    value = await self.hass.async_add_executor_job(self._extract_value)
  File "/usr/local/lib/python3.9/concurrent/futures/thread.py", line 52, in run
    result = self.fn(*self.args, **self.kwargs)
  File "/usr/src/homeassistant/homeassistant/components/scrape/sensor.py", line 155, in _extract_value
    tag = raw_data.select(self._select)[self._index]
  File "/usr/local/lib/python3.9/site-packages/bs4/element.py", line 1949, in select
    results = soupsieve.select(selector, self, namespaces, limit, **kwargs)
  File "/usr/local/lib/python3.9/site-packages/soupsieve/__init__.py", line 98, in select
    return compile(select, namespaces, flags, **kwargs).select(tag, limit)
  File "/usr/local/lib/python3.9/site-packages/soupsieve/__init__.py", line 62, in compile
    return cp._cached_css_compile(pattern, namespaces, custom, flags)
  File "/usr/local/lib/python3.9/site-packages/soupsieve/css_parser.py", line 211, in _cached_css_compile
    CSSParser(pattern, custom=custom_selectors, flags=flags).process_selectors(),
  File "/usr/local/lib/python3.9/site-packages/soupsieve/css_parser.py", line 1058, in process_selectors
    return self.parse_selectors(self.selector_iter(self.pattern), index, flags)
  File "/usr/local/lib/python3.9/site-packages/soupsieve/css_parser.py", line 909, in parse_selectors
    key, m = next(iselector)
  File "/usr/local/lib/python3.9/site-packages/soupsieve/css_parser.py", line 1051, in selector_iter
    raise SelectorSyntaxError(msg, self.pattern, index)
soupsieve.util.SelectorSyntaxError: Invalid character '<' position 0
  line 1:
<span _ngcontent-app-root-c173="">Offline</span>
^
2021-11-04 22:37:47 WARNING (MainThread) [homeassistant.components.sensor] Platform netatmo not ready yet: None; Retrying in background in 30 seconds
2021-11-04 22:37:47 WARNING (MainThread) [homeassistant.config_entries] Config entry 'OnHub' for upnp integration not ready yet; Retrying in background
2021-11-04 22:37:49 WARNING (MainThread) [homeassistant.components.sensor] Setup of sensor platform scrape is taking over 10 seconds.
2021-11-04 22:37:49 WARNING (MainThread) [homeassistant.components.sensor] Setup of sensor platform scrape is taking over 10 seconds.
2021-11-04 22:37:52 WARNING (MainThread) [homeassistant.components.camera] Setup of camera platform netatmo is taking over 10 seconds.
2021-11-04 22:37:54 ERROR (MainThread) [homeassistant.components.camera] Error while setting up netatmo platform for camera
Traceback (most recent call last):
  File "/usr/local/lib/python3.9/site-packages/aiohttp/connector.py", line 969, in _wrap_create_connection
    return await self._loop.create_connection(*args, **kwargs)  # type: ignore  # noqa
  File "/usr/local/lib/python3.9/asyncio/base_events.py", line 1056, in create_connection
    raise exceptions[0]
  File "/usr/local/lib/python3.9/asyncio/base_events.py", line 1041, in create_connection
    sock = await self._connect_sock(
  File "/usr/local/lib/python3.9/asyncio/base_events.py", line 955, in _connect_sock
    await self.sock_connect(sock, address)
  File "/usr/local/lib/python3.9/asyncio/selector_events.py", line 502, in sock_connect
    return await fut
  File "/usr/local/lib/python3.9/asyncio/selector_events.py", line 537, in _sock_connect_cb
    raise OSError(err, f'Connect call failed {address}')
OSError: [Errno 113] Connect call failed ('169.254.215.165', 80)

The above exception was the direct cause of the following exception:

Traceback (most recent call last):
  File "/usr/src/homeassistant/homeassistant/helpers/entity_platform.py", line 249, in _async_setup_platform
    await asyncio.shield(task)
  File "/usr/src/homeassistant/homeassistant/components/netatmo/camera.py", line 58, in async_setup_entry
    await data_handler.register_data_class(
  File "/usr/src/homeassistant/homeassistant/components/netatmo/data_handler.py", line 187, in register_data_class
    await self.async_fetch_data(data_class_entry)
  File "/usr/src/homeassistant/homeassistant/components/netatmo/data_handler.py", line 144, in async_fetch_data
    await self.data[data_class_entry].async_update()
  File "/usr/local/lib/python3.9/site-packages/pyatmo/camera.py", line 652, in async_update
    await self._async_update_all_camera_urls()
  File "/usr/local/lib/python3.9/site-packages/pyatmo/camera.py", line 662, in _async_update_all_camera_urls
    await self.async_update_camera_urls(camera_id)
  File "/usr/local/lib/python3.9/site-packages/pyatmo/camera.py", line 728, in async_update_camera_urls
    ] = await self._async_check_url(
  File "/usr/local/lib/python3.9/site-packages/pyatmo/camera.py", line 735, in _async_check_url
    resp = await self.auth.async_post_request(url=f"{url}/command/ping")
  File "/usr/local/lib/python3.9/site-packages/pyatmo/auth.py", line 339, in async_post_request
    async with self.websession.post(
  File "/usr/local/lib/python3.9/site-packages/aiohttp/client.py", line 1117, in __aenter__
    self._resp = await self._coro
  File "/usr/local/lib/python3.9/site-packages/aiohttp/client.py", line 520, in _request
    conn = await self._connector.connect(
  File "/usr/local/lib/python3.9/site-packages/aiohttp/connector.py", line 535, in connect
    proto = await self._create_connection(req, traces, timeout)
  File "/usr/local/lib/python3.9/site-packages/aiohttp/connector.py", line 892, in _create_connection
    _, proto = await self._create_direct_connection(req, traces, timeout)
  File "/usr/local/lib/python3.9/site-packages/aiohttp/connector.py", line 1051, in _create_direct_connection
    raise last_exc
  File "/usr/local/lib/python3.9/site-packages/aiohttp/connector.py", line 1020, in _create_direct_connection
    transp, proto = await self._wrap_create_connection(
  File "/usr/local/lib/python3.9/site-packages/aiohttp/connector.py", line 975, in _wrap_create_connection
    raise client_error(req.connection_key, exc) from exc
aiohttp.client_exceptions.ClientConnectorError: Cannot connect to host 169.254.215.165:80 ssl:default [Connect call failed ('169.254.215.165', 80)]
2021-11-04 22:38:07 WARNING (MainThread) [homeassistant.helpers.template] Template warning: 'float' got invalid input 'unknown' when rendering template '{{ states('sensor.tv_living_on_today') | float * 0.085 | round(3) }}' but no default was specified. Currently 'float' will return '0', however this template will fail to render in Home Assistant core 2022.1
2021-11-04 22:38:07 WARNING (MainThread) [homeassistant.helpers.template] Template warning: 'float' got invalid input 'unknown' when rendering template '{{ states('sensor.tv_living_on_today') | float * 0.085 | round(3) }}' but no default was specified. Currently 'float' will return '0', however this template will fail to render in Home Assistant core 2022.1
2021-11-04 22:38:07 WARNING (MainThread) [homeassistant.helpers.template] Template warning: 'float' got invalid input 'unknown' when rendering template '{{ states('sensor.master_bedroom_TV_on_today') | float * 0.063 | round(3) }}' but no default was specified. Currently 'float' will return '0', however this template will fail to render in Home Assistant core 2022.1
2021-11-04 22:38:07 WARNING (MainThread) [homeassistant.helpers.template] Template warning: 'float' got invalid input 'unknown' when rendering template '{{ states('sensor.master_bedroom_TV_on_today') | float * 0.063 | round(3) }}' but no default was specified. Currently 'float' will return '0', however this template will fail to render in Home Assistant core 2022.1
2021-11-04 22:38:17 WARNING (MainThread) [homeassistant.components.media_player] Updating huesyncbox media_player took longer than the scheduled update interval 0:00:02
2021-11-04 22:38:17 WARNING (MainThread) [homeassistant.components.binary_sensor] Updating ping binary_sensor took longer than the scheduled update interval 0:00:05
2021-11-04 22:38:17 ERROR (MainThread) [homeassistant] Error doing job: Task exception was never retrieved
Traceback (most recent call last):
  File "/usr/src/homeassistant/homeassistant/components/netatmo/__init__.py", line 220, in register_webhook
    await hass.data[DOMAIN][entry.entry_id][AUTH].async_addwebhook(webhook_url)
  File "/usr/local/lib/python3.9/site-packages/pyatmo/auth.py", line 381, in async_addwebhook
    resp = await self.async_post_request(WEBHOOK_URL_ADD, {"url": webhook_url})
  File "/usr/local/lib/python3.9/site-packages/pyatmo/auth.py", line 339, in async_post_request
    async with self.websession.post(
  File "/usr/local/lib/python3.9/site-packages/aiohttp/client.py", line 1117, in __aenter__
    self._resp = await self._coro
  File "/usr/local/lib/python3.9/site-packages/aiohttp/client.py", line 619, in _request
    break
  File "/usr/local/lib/python3.9/site-packages/aiohttp/helpers.py", line 656, in __exit__
    raise asyncio.TimeoutError from None
asyncio.exceptions.TimeoutError
2021-11-04 22:38:17 WARNING (MainThread) [homeassistant.components.fan] Setup of fan platform xiaomi_miio_fan is taking over 10 seconds.
2021-11-04 22:38:17 WARNING (MainThread) [homeassistant.components.fan] Setup of fan platform xiaomi_miio_fan is taking over 10 seconds.
2021-11-04 22:38:17 WARNING (MainThread) [homeassistant.helpers.entity] Update of binary_sensor.google_server is taking over 10 seconds
2021-11-04 22:38:18 ERROR (MainThread) [homeassistant.components.mobile_app.notify] Timeout sending notification to https://mobile-apps.home-assistant.io/api/sendPush/android/v1
2021-11-04 22:38:20 WARNING (MainThread) [homeassistant.components.binary_sensor] Updating ping binary_sensor took longer than the scheduled update interval 0:00:05
2021-11-04 22:38:23 ERROR (MainThread) [homeassistant.components.google_assistant.http] Request for https://homegraph.googleapis.com/v1/devices:requestSync failed: 500
2021-11-04 22:38:27 ERROR (SyncWorker_10) [homeassistant.components.influxdb] InfluxDB bucket is not accessible due to '(401)
Reason: Unauthorized
HTTP response headers: HTTPHeaderDict({'Content-Type': 'application/json; charset=utf-8', 'X-Influxdb-Build': 'OSS', 'X-Influxdb-Version': '2.0.9', 'X-Platform-Error-Code': 'unauthorized', 'Date': 'Thu, 04 Nov 2021 22:38:27 GMT', 'Content-Length': '55'})
HTTP response body: {"code":"unauthorized","message":"unauthorized access"}
'. Please check that the bucket, org and token are correct and that the token has the correct permissions set. Retrying in 60 seconds.
2021-11-04 22:38:29 ERROR (MainThread) [homeassistant.components.google_assistant.http] Request for https://homegraph.googleapis.com/v1/devices:reportStateAndNotification failed: 404
2021-11-04 22:39:00 WARNING (MainThread) [homeassistant.components.binary_sensor] Updating ping binary_sensor took longer than the scheduled update interval 0:00:05
2021-11-04 22:39:10 WARNING (MainThread) [homeassistant.components.binary_sensor] Updating ping binary_sensor took longer than the scheduled update interval 0:00:05
2021-11-04 22:39:27 ERROR (SyncWorker_14) [homeassistant.components.influxdb] InfluxDB bucket is not accessible due to '(401)
Reason: Unauthorized
HTTP response headers: HTTPHeaderDict({'Content-Type': 'application/json; charset=utf-8', 'X-Influxdb-Build': 'OSS', 'X-Influxdb-Version': '2.0.9', 'X-Platform-Error-Code': 'unauthorized', 'Date': 'Thu, 04 Nov 2021 22:39:27 GMT', 'Content-Length': '55'})
HTTP response body: {"code":"unauthorized","message":"unauthorized access"}
'. Please check that the bucket, org and token are correct and that the token has the correct permissions set. Retrying in 60 seconds.
2021-11-04 22:39:35 WARNING (MainThread) [homeassistant.components.binary_sensor] Updating ping binary_sensor took longer than the scheduled update interval 0:00:05
2021-11-04 22:40:27 ERROR (SyncWorker_0) [homeassistant.components.influxdb] InfluxDB bucket is not accessible due to '(401)
Reason: Unauthorized
HTTP response headers: HTTPHeaderDict({'Content-Type': 'application/json; charset=utf-8', 'X-Influxdb-Build': 'OSS', 'X-Influxdb-Version': '2.0.9', 'X-Platform-Error-Code': 'unauthorized', 'Date': 'Thu, 04 Nov 2021 22:40:27 GMT', 'Content-Length': '55'})
HTTP response body: {"code":"unauthorized","message":"unauthorized access"}
'. Please check that the bucket, org and token are correct and that the token has the correct permissions set. Retrying in 60 seconds.
2021-11-04 22:41:27 ERROR (SyncWorker_16) [homeassistant.components.influxdb] InfluxDB bucket is not accessible due to '(401)
Reason: Unauthorized
HTTP response headers: HTTPHeaderDict({'Content-Type': 'application/json; charset=utf-8', 'X-Influxdb-Build': 'OSS', 'X-Influxdb-Version': '2.0.9', 'X-Platform-Error-Code': 'unauthorized', 'Date': 'Thu, 04 Nov 2021 22:41:27 GMT', 'Content-Length': '55'})
HTTP response body: {"code":"unauthorized","message":"unauthorized access"}
'. Please check that the bucket, org and token are correct and that the token has the correct permissions set. Retrying in 60 seconds.
2021-11-04 22:42:13 ERROR (MainThread) [homeassistant.components.google_assistant.http] Request for https://homegraph.googleapis.com/v1/devices:reportStateAndNotification failed: 404
2021-11-04 22:42:18 ERROR (MainThread) [homeassistant.components.google_assistant.http] Request for https://homegraph.googleapis.com/v1/devices:reportStateAndNotification failed: 404
2021-11-04 22:42:27 ERROR (SyncWorker_12) [homeassistant.components.influxdb] InfluxDB bucket is not accessible due to '(401)
Reason: Unauthorized
HTTP response headers: HTTPHeaderDict({'Content-Type': 'application/json; charset=utf-8', 'X-Influxdb-Build': 'OSS', 'X-Influxdb-Version': '2.0.9', 'X-Platform-Error-Code': 'unauthorized', 'Date': 'Thu, 04 Nov 2021 22:42:27 GMT', 'Content-Length': '55'})
HTTP response body: {"code":"unauthorized","message":"unauthorized access"}
'. Please check that the bucket, org and token are correct and that the token has the correct permissions set. Retrying in 60 seconds.
2021-11-04 22:42:48 WARNING (SyncWorker_26) [buienalarm.pybuienalarm] Error fetching data safely: 502 Server Error: Bad Gateway for url: https://cdn-secure.buienalarm.nl/api/3.4/forecast.php?lat=50.878800118427755&lon=4.749415398691782&region=nl&unit=mm%2Fu
2021-11-04 22:43:27 ERROR (SyncWorker_12) [homeassistant.components.influxdb] InfluxDB bucket is not accessible due to '(401)
Reason: Unauthorized
HTTP response headers: HTTPHeaderDict({'Content-Type': 'application/json; charset=utf-8', 'X-Influxdb-Build': 'OSS', 'X-Influxdb-Version': '2.0.9', 'X-Platform-Error-Code': 'unauthorized', 'Date': 'Thu, 04 Nov 2021 22:43:27 GMT', 'Content-Length': '55'})
HTTP response body: {"code":"unauthorized","message":"unauthorized access"}
'. Please check that the bucket, org and token are correct and that the token has the correct permissions set. Retrying in 60 seconds.
2021-11-04 22:44:27 ERROR (SyncWorker_22) [homeassistant.components.influxdb] InfluxDB bucket is not accessible due to '(401)
Reason: Unauthorized
HTTP response headers: HTTPHeaderDict({'Content-Type': 'application/json; charset=utf-8', 'X-Influxdb-Build': 'OSS', 'X-Influxdb-Version': '2.0.9', 'X-Platform-Error-Code': 'unauthorized', 'Date': 'Thu, 04 Nov 2021 22:44:27 GMT', 'Content-Length': '55'})
HTTP response body: {"code":"unauthorized","message":"unauthorized access"}
'. Please check that the bucket, org and token are correct and that the token has the correct permissions set. Retrying in 60 seconds.
2021-11-04 22:45:27 ERROR (SyncWorker_26) [homeassistant.components.influxdb] InfluxDB bucket is not accessible due to '(401)
Reason: Unauthorized
HTTP response headers: HTTPHeaderDict({'Content-Type': 'application/json; charset=utf-8', 'X-Influxdb-Build': 'OSS', 'X-Influxdb-Version': '2.0.9', 'X-Platform-Error-Code': 'unauthorized', 'Date': 'Thu, 04 Nov 2021 22:45:27 GMT', 'Content-Length': '55'})
HTTP response body: {"code":"unauthorized","message":"unauthorized access"}
'. Please check that the bucket, org and token are correct and that the token has the correct permissions set. Retrying in 60 seconds.
2021-11-04 22:46:27 ERROR (SyncWorker_17) [homeassistant.components.influxdb] InfluxDB bucket is not accessible due to '(401)
Reason: Unauthorized
HTTP response headers: HTTPHeaderDict({'Content-Type': 'application/json; charset=utf-8', 'X-Influxdb-Build': 'OSS', 'X-Influxdb-Version': '2.0.9', 'X-Platform-Error-Code': 'unauthorized', 'Date': 'Thu, 04 Nov 2021 22:46:27 GMT', 'Content-Length': '55'})
HTTP response body: {"code":"unauthorized","message":"unauthorized access"}
'. Please check that the bucket, org and token are correct and that the token has the correct permissions set. Retrying in 60 seconds.
2021-11-04 22:47:27 ERROR (SyncWorker_19) [homeassistant.components.influxdb] InfluxDB bucket is not accessible due to '(401)
Reason: Unauthorized
HTTP response headers: HTTPHeaderDict({'Content-Type': 'application/json; charset=utf-8', 'X-Influxdb-Build': 'OSS', 'X-Influxdb-Version': '2.0.9', 'X-Platform-Error-Code': 'unauthorized', 'Date': 'Thu, 04 Nov 2021 22:47:27 GMT', 'Content-Length': '55'})
HTTP response body: {"code":"unauthorized","message":"unauthorized access"}
'. Please check that the bucket, org and token are correct and that the token has the correct permissions set. Retrying in 60 seconds.
2021-11-04 22:47:30 WARNING (MainThread) [homeassistant.components.binary_sensor] Updating ping binary_sensor took longer than the scheduled update interval 0:00:05
2021-11-04 22:48:27 ERROR (SyncWorker_14) [homeassistant.components.influxdb] InfluxDB bucket is not accessible due to '(401)
Reason: Unauthorized
HTTP response headers: HTTPHeaderDict({'Content-Type': 'application/json; charset=utf-8', 'X-Influxdb-Build': 'OSS', 'X-Influxdb-Version': '2.0.9', 'X-Platform-Error-Code': 'unauthorized', 'Date': 'Thu, 04 Nov 2021 22:48:27 GMT', 'Content-Length': '55'})
HTTP response body: {"code":"unauthorized","message":"unauthorized access"}
'. Please check that the bucket, org and token are correct and that the token has the correct permissions set. Retrying in 60 seconds.
2021-11-04 22:49:27 ERROR (SyncWorker_22) [homeassistant.components.influxdb] InfluxDB bucket is not accessible due to '(401)
Reason: Unauthorized
HTTP response headers: HTTPHeaderDict({'Content-Type': 'application/json; charset=utf-8', 'X-Influxdb-Build': 'OSS', 'X-Influxdb-Version': '2.0.9', 'X-Platform-Error-Code': 'unauthorized', 'Date': 'Thu, 04 Nov 2021 22:49:27 GMT', 'Content-Length': '55'})
HTTP response body: {"code":"unauthorized","message":"unauthorized access"}
'. Please check that the bucket, org and token are correct and that the token has the correct permissions set. Retrying in 60 seconds.
2021-11-04 22:50:27 ERROR (SyncWorker_9) [homeassistant.components.influxdb] InfluxDB bucket is not accessible due to '(401)
Reason: Unauthorized
HTTP response headers: HTTPHeaderDict({'Content-Type': 'application/json; charset=utf-8', 'X-Influxdb-Build': 'OSS', 'X-Influxdb-Version': '2.0.9', 'X-Platform-Error-Code': 'unauthorized', 'Date': 'Thu, 04 Nov 2021 22:50:27 GMT', 'Content-Length': '55'})
HTTP response body: {"code":"unauthorized","message":"unauthorized access"}
'. Please check that the bucket, org and token are correct and that the token has the correct permissions set. Retrying in 60 seconds.
2021-11-04 22:51:27 ERROR (SyncWorker_6) [homeassistant.components.influxdb] InfluxDB bucket is not accessible due to '(401)
Reason: Unauthorized
HTTP response headers: HTTPHeaderDict({'Content-Type': 'application/json; charset=utf-8', 'X-Influxdb-Build': 'OSS', 'X-Influxdb-Version': '2.0.9', 'X-Platform-Error-Code': 'unauthorized', 'Date': 'Thu, 04 Nov 2021 22:51:27 GMT', 'Content-Length': '55'})
HTTP response body: {"code":"unauthorized","message":"unauthorized access"}
'. Please check that the bucket, org and token are correct and that the token has the correct permissions set. Retrying in 60 seconds.
2021-11-04 22:52:27 ERROR (SyncWorker_11) [homeassistant.components.influxdb] InfluxDB bucket is not accessible due to '(401)
Reason: Unauthorized
HTTP response headers: HTTPHeaderDict({'Content-Type': 'application/json; charset=utf-8', 'X-Influxdb-Build': 'OSS', 'X-Influxdb-Version': '2.0.9', 'X-Platform-Error-Code': 'unauthorized', 'Date': 'Thu, 04 Nov 2021 22:52:27 GMT', 'Content-Length': '55'})
HTTP response body: {"code":"unauthorized","message":"unauthorized access"}
'. Please check that the bucket, org and token are correct and that the token has the correct permissions set. Retrying in 60 seconds.
2021-11-04 22:53:10 ERROR (MainThread) [homeassistant.components.google_assistant.http] Request for https://homegraph.googleapis.com/v1/devices:reportStateAndNotification failed: 404
2021-11-04 22:53:27 ERROR (SyncWorker_7) [homeassistant.components.influxdb] InfluxDB bucket is not accessible due to '(401)
Reason: Unauthorized
HTTP response headers: HTTPHeaderDict({'Content-Type': 'application/json; charset=utf-8', 'X-Influxdb-Build': 'OSS', 'X-Influxdb-Version': '2.0.9', 'X-Platform-Error-Code': 'unauthorized', 'Date': 'Thu, 04 Nov 2021 22:53:27 GMT', 'Content-Length': '55'})
HTTP response body: {"code":"unauthorized","message":"unauthorized access"}
'. Please check that the bucket, org and token are correct and that the token has the correct permissions set. Retrying in 60 seconds.
2021-11-04 22:54:27 ERROR (SyncWorker_2) [homeassistant.components.influxdb] InfluxDB bucket is not accessible due to '(401)
Reason: Unauthorized
HTTP response headers: HTTPHeaderDict({'Content-Type': 'application/json; charset=utf-8', 'X-Influxdb-Build': 'OSS', 'X-Influxdb-Version': '2.0.9', 'X-Platform-Error-Code': 'unauthorized', 'Date': 'Thu, 04 Nov 2021 22:54:27 GMT', 'Content-Length': '55'})
HTTP response body: {"code":"unauthorized","message":"unauthorized access"}
'. Please check that the bucket, org and token are correct and that the token has the correct permissions set. Retrying in 60 seconds.
2021-11-04 22:55:27 ERROR (SyncWorker_22) [homeassistant.components.influxdb] InfluxDB bucket is not accessible due to '(401)
Reason: Unauthorized
HTTP response headers: HTTPHeaderDict({'Content-Type': 'application/json; charset=utf-8', 'X-Influxdb-Build': 'OSS', 'X-Influxdb-Version': '2.0.9', 'X-Platform-Error-Code': 'unauthorized', 'Date': 'Thu, 04 Nov 2021 22:55:27 GMT', 'Content-Length': '55'})
HTTP response body: {"code":"unauthorized","message":"unauthorized access"}
'. Please check that the bucket, org and token are correct and that the token has the correct permissions set. Retrying in 60 seconds.
2021-11-04 22:56:27 ERROR (SyncWorker_13) [homeassistant.components.influxdb] InfluxDB bucket is not accessible due to '(401)
Reason: Unauthorized
HTTP response headers: HTTPHeaderDict({'Content-Type': 'application/json; charset=utf-8', 'X-Influxdb-Build': 'OSS', 'X-Influxdb-Version': '2.0.9', 'X-Platform-Error-Code': 'unauthorized', 'Date': 'Thu, 04 Nov 2021 22:56:27 GMT', 'Content-Length': '55'})
HTTP response body: {"code":"unauthorized","message":"unauthorized access"}
'. Please check that the bucket, org and token are correct and that the token has the correct permissions set. Retrying in 60 seconds.
2021-11-04 22:57:27 ERROR (SyncWorker_11) [homeassistant.components.influxdb] InfluxDB bucket is not accessible due to '(401)
Reason: Unauthorized
HTTP response headers: HTTPHeaderDict({'Content-Type': 'application/json; charset=utf-8', 'X-Influxdb-Build': 'OSS', 'X-Influxdb-Version': '2.0.9', 'X-Platform-Error-Code': 'unauthorized', 'Date': 'Thu, 04 Nov 2021 22:57:27 GMT', 'Content-Length': '55'})
HTTP response body: {"code":"unauthorized","message":"unauthorized access"}
'. Please check that the bucket, org and token are correct and that the token has the correct permissions set. Retrying in 60 seconds.
2021-11-04 22:58:27 ERROR (SyncWorker_6) [homeassistant.components.influxdb] InfluxDB bucket is not accessible due to '(401)
Reason: Unauthorized
HTTP response headers: HTTPHeaderDict({'Content-Type': 'application/json; charset=utf-8', 'X-Influxdb-Build': 'OSS', 'X-Influxdb-Version': '2.0.9', 'X-Platform-Error-Code': 'unauthorized', 'Date': 'Thu, 04 Nov 2021 22:58:27 GMT', 'Content-Length': '55'})
HTTP response body: {"code":"unauthorized","message":"unauthorized access"}
'. Please check that the bucket, org and token are correct and that the token has the correct permissions set. Retrying in 60 seconds.
2021-11-04 22:59:27 ERROR (SyncWorker_10) [homeassistant.components.influxdb] InfluxDB bucket is not accessible due to '(401)
Reason: Unauthorized
HTTP response headers: HTTPHeaderDict({'Content-Type': 'application/json; charset=utf-8', 'X-Influxdb-Build': 'OSS', 'X-Influxdb-Version': '2.0.9', 'X-Platform-Error-Code': 'unauthorized', 'Date': 'Thu, 04 Nov 2021 22:59:27 GMT', 'Content-Length': '55'})
HTTP response body: {"code":"unauthorized","message":"unauthorized access"}
'. Please check that the bucket, org and token are correct and that the token has the correct permissions set. Retrying in 60 seconds.
2021-11-04 23:00:27 ERROR (SyncWorker_27) [homeassistant.components.influxdb] InfluxDB bucket is not accessible due to '(401)
Reason: Unauthorized
HTTP response headers: HTTPHeaderDict({'Content-Type': 'application/json; charset=utf-8', 'X-Influxdb-Build': 'OSS', 'X-Influxdb-Version': '2.0.9', 'X-Platform-Error-Code': 'unauthorized', 'Date': 'Thu, 04 Nov 2021 23:00:27 GMT', 'Content-Length': '55'})
HTTP response body: {"code":"unauthorized","message":"unauthorized access"}
'. Please check that the bucket, org and token are correct and that the token has the correct permissions set. Retrying in 60 seconds.
2021-11-04 23:00:40 ERROR (MainThread) [homeassistant.components.google_assistant.http] Request for https://homegraph.googleapis.com/v1/devices:reportStateAndNotification failed: 404
2021-11-04 23:01:03 ERROR (MainThread) [homeassistant.components.google_assistant.http] Request for https://homegraph.googleapis.com/v1/devices:reportStateAndNotification failed: 404
2021-11-04 23:01:28 ERROR (SyncWorker_19) [homeassistant.components.influxdb] InfluxDB bucket is not accessible due to '(401)
Reason: Unauthorized
HTTP response headers: HTTPHeaderDict({'Content-Type': 'application/json; charset=utf-8', 'X-Influxdb-Build': 'OSS', 'X-Influxdb-Version': '2.0.9', 'X-Platform-Error-Code': 'unauthorized', 'Date': 'Thu, 04 Nov 2021 23:01:28 GMT', 'Content-Length': '55'})
HTTP response body: {"code":"unauthorized","message":"unauthorized access"}
'. Please check that the bucket, org and token are correct and that the token has the correct permissions set. Retrying in 60 seconds.
2021-11-04 23:02:28 ERROR (SyncWorker_11) [homeassistant.components.influxdb] InfluxDB bucket is not accessible due to '(401)
Reason: Unauthorized
HTTP response headers: HTTPHeaderDict({'Content-Type': 'application/json; charset=utf-8', 'X-Influxdb-Build': 'OSS', 'X-Influxdb-Version': '2.0.9', 'X-Platform-Error-Code': 'unauthorized', 'Date': 'Thu, 04 Nov 2021 23:02:28 GMT', 'Content-Length': '55'})
HTTP response body: {"code":"unauthorized","message":"unauthorized access"}
'. Please check that the bucket, org and token are correct and that the token has the correct permissions set. Retrying in 60 seconds.
2021-11-04 23:03:17 WARNING (MainThread) [homeassistant.helpers.service] Unable to find referenced entities media_player.living_speaker
2021-11-04 23:03:17 WARNING (MainThread) [homeassistant.helpers.service] Unable to find referenced entities media_player.veranda_speaker_2
2021-11-04 23:03:27 WARNING (MainThread) [homeassistant.helpers.service] Unable to find referenced entities camera.netatmo_eikenbos_oprit
2021-11-04 23:03:28 ERROR (SyncWorker_17) [homeassistant.components.influxdb] InfluxDB bucket is not accessible due to '(401)
Reason: Unauthorized
HTTP response headers: HTTPHeaderDict({'Content-Type': 'application/json; charset=utf-8', 'X-Influxdb-Build': 'OSS', 'X-Influxdb-Version': '2.0.9', 'X-Platform-Error-Code': 'unauthorized', 'Date': 'Thu, 04 Nov 2021 23:03:28 GMT', 'Content-Length': '55'})
HTTP response body: {"code":"unauthorized","message":"unauthorized access"}
'. Please check that the bucket, org and token are correct and that the token has the correct permissions set. Retrying in 60 seconds.
2021-11-04 23:03:29 ERROR (MainThread) [homeassistant.components.google_assistant.http] Request for https://homegraph.googleapis.com/v1/devices:reportStateAndNotification failed: 404
2021-11-04 23:04:28 ERROR (SyncWorker_12) [homeassistant.components.influxdb] InfluxDB bucket is not accessible due to '(401)
Reason: Unauthorized
HTTP response headers: HTTPHeaderDict({'Content-Type': 'application/json; charset=utf-8', 'X-Influxdb-Build': 'OSS', 'X-Influxdb-Version': '2.0.9', 'X-Platform-Error-Code': 'unauthorized', 'Date': 'Thu, 04 Nov 2021 23:04:28 GMT', 'Content-Length': '55'})
HTTP response body: {"code":"unauthorized","message":"unauthorized access"}
'. Please check that the bucket, org and token are correct and that the token has the correct permissions set. Retrying in 60 seconds.
2021-11-04 23:04:57 WARNING (MainThread) [homeassistant.helpers.service] Unable to find referenced entities media_player.living_speaker
2021-11-04 23:05:06 WARNING (MainThread) [homeassistant.components.binary_sensor] Updating ping binary_sensor took longer than the scheduled update interval 0:00:05
2021-11-04 23:05:28 ERROR (SyncWorker_9) [homeassistant.components.influxdb] InfluxDB bucket is not accessible due to '(401)
Reason: Unauthorized
HTTP response headers: HTTPHeaderDict({'Content-Type': 'application/json; charset=utf-8', 'X-Influxdb-Build': 'OSS', 'X-Influxdb-Version': '2.0.9', 'X-Platform-Error-Code': 'unauthorized', 'Date': 'Thu, 04 Nov 2021 23:05:28 GMT', 'Content-Length': '55'})
HTTP response body: {"code":"unauthorized","message":"unauthorized access"}
'. Please check that the bucket, org and token are correct and that the token has the correct permissions set. Retrying in 60 seconds.
2021-11-04 23:06:19 ERROR (MainThread) [homeassistant.components.google_assistant.http] Request for https://homegraph.googleapis.com/v1/devices:reportStateAndNotification failed: 404
2021-11-04 23:06:28 ERROR (SyncWorker_7) [homeassistant.components.influxdb] InfluxDB bucket is not accessible due to '(401)
Reason: Unauthorized
HTTP response headers: HTTPHeaderDict({'Content-Type': 'application/json; charset=utf-8', 'X-Influxdb-Build': 'OSS', 'X-Influxdb-Version': '2.0.9', 'X-Platform-Error-Code': 'unauthorized', 'Date': 'Thu, 04 Nov 2021 23:06:28 GMT', 'Content-Length': '55'})
HTTP response body: {"code":"unauthorized","message":"unauthorized access"}
'. Please check that the bucket, org and token are correct and that the token has the correct permissions set. Retrying in 60 seconds.
2021-11-04 23:07:28 ERROR (SyncWorker_9) [homeassistant.components.influxdb] InfluxDB bucket is not accessible due to '(401)
Reason: Unauthorized
HTTP response headers: HTTPHeaderDict({'Content-Type': 'application/json; charset=utf-8', 'X-Influxdb-Build': 'OSS', 'X-Influxdb-Version': '2.0.9', 'X-Platform-Error-Code': 'unauthorized', 'Date': 'Thu, 04 Nov 2021 23:07:28 GMT', 'Content-Length': '55'})
HTTP response body: {"code":"unauthorized","message":"unauthorized access"}
'. Please check that the bucket, org and token are correct and that the token has the correct permissions set. Retrying in 60 seconds.
2021-11-04 23:07:44 ERROR (MainThread) [homeassistant.config] Invalid config for [automation]: expected str for dictionary value @ data['from']. Got None. (See ?, line ?). 
2021-11-04 23:07:44 ERROR (MainThread) [homeassistant.config] Invalid config for [automation]: required key not provided @ data['action'][4]['domain']. Got None. (See ?, line ?). 
2021-11-04 23:07:44 ERROR (MainThread) [homeassistant.config] Invalid config for [automation]: must be a value between 0 and 59 for dictionary value @ data['minutes']. Got None. (See ?, line ?). 
2021-11-04 23:07:44 ERROR (MainThread) [homeassistant.config] Invalid config for [automation]: must be a value between 0 and 59 for dictionary value @ data['minutes']. Got None. (See ?, line ?). 
2021-11-04 23:07:50 WARNING (Thread-110) [homeassistant.util.executor] Thread[SyncWorker_3] is still running at shutdown: File "/usr/local/lib/python3.9/threading.py", line 930, in _bootstrap
    self._bootstrap_inner()
  File "/usr/local/lib/python3.9/threading.py", line 973, in _bootstrap_inner
    self.run()
  File "/usr/local/lib/python3.9/threading.py", line 910, in run
    self._target(*self._args, **self._kwargs)
  File "/usr/local/lib/python3.9/concurrent/futures/thread.py", line 77, in _worker
    work_item.run()
  File "/usr/local/lib/python3.9/concurrent/futures/thread.py", line 52, in run
    result = self.fn(*self.args, **self.kwargs)
  File "/usr/src/homeassistant/homeassistant/components/tado/__init__.py", line 75, in <lambda>
    lambda now: tadoconnector.update(),
  File "/usr/src/homeassistant/homeassistant/util/__init__.py", line 277, in wrapper
    result = method(*args, **kwargs)
  File "/usr/src/homeassistant/homeassistant/components/tado/__init__.py", line 159, in update
    self.update_devices()
  File "/usr/src/homeassistant/homeassistant/components/tado/__init__.py", line 169, in update_devices
    devices = self.tado.getDevices()
  File "/usr/local/lib/python3.9/site-packages/PyTado/interface.py", line 170, in getDevices
    data = self._apiCall(cmd)
  File "/usr/local/lib/python3.9/site-packages/PyTado/interface.py", line 81, in _apiCall
    response = self._http_session.request(method, url, timeout=self.timeout,
  File "/usr/local/lib/python3.9/site-packages/requests/sessions.py", line 542, in request
    resp = self.send(prep, **send_kwargs)
  File "/usr/local/lib/python3.9/site-packages/requests/sessions.py", line 655, in send
    r = adapter.send(request, **kwargs)
  File "/usr/local/lib/python3.9/site-packages/requests/adapters.py", line 439, in send
    resp = conn.urlopen(
  File "/usr/local/lib/python3.9/site-packages/urllib3/connectionpool.py", line 699, in urlopen
    httplib_response = self._make_request(
  File "/usr/local/lib/python3.9/site-packages/urllib3/connectionpool.py", line 382, in _make_request
    self._validate_conn(conn)
  File "/usr/local/lib/python3.9/site-packages/urllib3/connectionpool.py", line 1010, in _validate_conn
    conn.connect()
  File "/usr/local/lib/python3.9/site-packages/urllib3/connection.py", line 358, in connect
    conn = self._new_conn()
  File "/usr/local/lib/python3.9/site-packages/urllib3/connection.py", line 174, in _new_conn
    conn = connection.create_connection(
  File "/usr/local/lib/python3.9/site-packages/urllib3/util/connection.py", line 73, in create_connection
    for res in socket.getaddrinfo(host, port, family, socket.SOCK_STREAM):
  File "/usr/local/lib/python3.9/socket.py", line 954, in getaddrinfo
    for res in _socket.getaddrinfo(host, port, family, type, proto, flags):
2021-11-04 23:07:50 ERROR (MainThread) [homeassistant] Error doing job: Future exception was never retrieved
Traceback (most recent call last):
  File "/usr/local/lib/python3.9/concurrent/futures/thread.py", line 52, in run
    result = self.fn(*self.args, **self.kwargs)
  File "/usr/src/homeassistant/homeassistant/components/tado/__init__.py", line 75, in <lambda>
    lambda now: tadoconnector.update(),
  File "/usr/src/homeassistant/homeassistant/util/__init__.py", line 277, in wrapper
    result = method(*args, **kwargs)
  File "/usr/src/homeassistant/homeassistant/components/tado/__init__.py", line 159, in update
    self.update_devices()
  File "/usr/src/homeassistant/homeassistant/components/tado/__init__.py", line 169, in update_devices
    devices = self.tado.getDevices()
  File "/usr/local/lib/python3.9/site-packages/PyTado/interface.py", line 170, in getDevices
    data = self._apiCall(cmd)
  File "/usr/local/lib/python3.9/site-packages/PyTado/interface.py", line 81, in _apiCall
    response = self._http_session.request(method, url, timeout=self.timeout,
  File "/usr/local/lib/python3.9/site-packages/requests/sessions.py", line 542, in request
    resp = self.send(prep, **send_kwargs)
  File "/usr/local/lib/python3.9/site-packages/requests/sessions.py", line 655, in send
    r = adapter.send(request, **kwargs)
  File "/usr/local/lib/python3.9/site-packages/requests/adapters.py", line 439, in send
    resp = conn.urlopen(
  File "/usr/local/lib/python3.9/site-packages/urllib3/connectionpool.py", line 699, in urlopen
    httplib_response = self._make_request(
  File "/usr/local/lib/python3.9/site-packages/urllib3/connectionpool.py", line 382, in _make_request
    self._validate_conn(conn)
  File "/usr/local/lib/python3.9/site-packages/urllib3/connectionpool.py", line 1010, in _validate_conn
    conn.connect()
  File "/usr/local/lib/python3.9/site-packages/urllib3/connection.py", line 358, in connect
    conn = self._new_conn()
  File "/usr/local/lib/python3.9/site-packages/urllib3/connection.py", line 174, in _new_conn
    conn = connection.create_connection(
  File "/usr/local/lib/python3.9/site-packages/urllib3/util/connection.py", line 73, in create_connection
    for res in socket.getaddrinfo(host, port, family, socket.SOCK_STREAM):
  File "/usr/local/lib/python3.9/socket.py", line 954, in getaddrinfo
    for res in _socket.getaddrinfo(host, port, family, type, proto, flags):
SystemExit
