2021-11-11 09:28:37 WARNING (SyncWorker_0) [homeassistant.loader] We found a custom integration average which has not been tested by Home Assistant. This component might cause stability problems, be sure to disable it if you experience issues with Home Assistant
2021-11-11 09:28:37 WARNING (SyncWorker_1) [homeassistant.loader] We found a custom integration adaptive_lighting which has not been tested by Home Assistant. This component might cause stability problems, be sure to disable it if you experience issues with Home Assistant
2021-11-11 09:28:37 WARNING (SyncWorker_2) [homeassistant.loader] We found a custom integration xiaomi_miio_airpurifier which has not been tested by Home Assistant. This component might cause stability problems, be sure to disable it if you experience issues with Home Assistant
2021-11-11 09:28:37 WARNING (SyncWorker_4) [homeassistant.loader] We found a custom integration powercalc which has not been tested by Home Assistant. This component might cause stability problems, be sure to disable it if you experience issues with Home Assistant
2021-11-11 09:28:37 WARNING (SyncWorker_3) [homeassistant.loader] We found a custom integration audiconnect which has not been tested by Home Assistant. This component might cause stability problems, be sure to disable it if you experience issues with Home Assistant
2021-11-11 09:28:37 WARNING (SyncWorker_5) [homeassistant.loader] We found a custom integration monitor_docker which has not been tested by Home Assistant. This component might cause stability problems, be sure to disable it if you experience issues with Home Assistant
2021-11-11 09:28:37 WARNING (SyncWorker_2) [homeassistant.loader] We found a custom integration localtuya which has not been tested by Home Assistant. This component might cause stability problems, be sure to disable it if you experience issues with Home Assistant
2021-11-11 09:28:37 WARNING (SyncWorker_6) [homeassistant.loader] We found a custom integration hacs which has not been tested by Home Assistant. This component might cause stability problems, be sure to disable it if you experience issues with Home Assistant
2021-11-11 09:28:37 WARNING (SyncWorker_1) [homeassistant.loader] We found a custom integration shelly which has not been tested by Home Assistant. This component might cause stability problems, be sure to disable it if you experience issues with Home Assistant
2021-11-11 09:28:37 WARNING (SyncWorker_7) [homeassistant.loader] We found a custom integration xiaomi_miio_fan which has not been tested by Home Assistant. This component might cause stability problems, be sure to disable it if you experience issues with Home Assistant
2021-11-11 09:28:37 WARNING (SyncWorker_0) [homeassistant.loader] We found a custom integration tuya_v2 which has not been tested by Home Assistant. This component might cause stability problems, be sure to disable it if you experience issues with Home Assistant
2021-11-11 09:28:37 WARNING (SyncWorker_9) [homeassistant.loader] We found a custom integration buienalarm which has not been tested by Home Assistant. This component might cause stability problems, be sure to disable it if you experience issues with Home Assistant
2021-11-11 09:28:37 WARNING (SyncWorker_2) [homeassistant.loader] We found a custom integration thermal_comfort which has not been tested by Home Assistant. This component might cause stability problems, be sure to disable it if you experience issues with Home Assistant
2021-11-11 09:28:37 WARNING (SyncWorker_4) [homeassistant.loader] We found a custom integration frigate which has not been tested by Home Assistant. This component might cause stability problems, be sure to disable it if you experience issues with Home Assistant
2021-11-11 09:28:37 WARNING (SyncWorker_6) [homeassistant.loader] We found a custom integration xiaomi_miot which has not been tested by Home Assistant. This component might cause stability problems, be sure to disable it if you experience issues with Home Assistant
2021-11-11 09:28:37 WARNING (SyncWorker_8) [homeassistant.loader] We found a custom integration huesyncbox which has not been tested by Home Assistant. This component might cause stability problems, be sure to disable it if you experience issues with Home Assistant
2021-11-11 09:28:37 WARNING (SyncWorker_11) [homeassistant.loader] We found a custom integration ytube_music_player which has not been tested by Home Assistant. This component might cause stability problems, be sure to disable it if you experience issues with Home Assistant
2021-11-11 09:28:37 WARNING (SyncWorker_3) [homeassistant.loader] We found a custom integration google_home which has not been tested by Home Assistant. This component might cause stability problems, be sure to disable it if you experience issues with Home Assistant
2021-11-11 09:28:37 WARNING (SyncWorker_1) [homeassistant.loader] We found a custom integration anniversaries which has not been tested by Home Assistant. This component might cause stability problems, be sure to disable it if you experience issues with Home Assistant
2021-11-11 09:28:37 WARNING (SyncWorker_10) [homeassistant.loader] We found a custom integration googlewifi which has not been tested by Home Assistant. This component might cause stability problems, be sure to disable it if you experience issues with Home Assistant
2021-11-11 09:28:37 WARNING (SyncWorker_0) [homeassistant.loader] We found a custom integration afvalbeheer which has not been tested by Home Assistant. This component might cause stability problems, be sure to disable it if you experience issues with Home Assistant
2021-11-11 09:28:37 WARNING (SyncWorker_7) [homeassistant.loader] We found a custom integration deepstack_face which has not been tested by Home Assistant. This component might cause stability problems, be sure to disable it if you experience issues with Home Assistant
2021-11-11 09:28:42 ERROR (SyncWorker_1) [homeassistant.components.influxdb] Cannot connect to InfluxDB due to '<urllib3.connection.HTTPConnection object at 0xffff879a1250>: Failed to establish a new connection: [Errno 111] Connection refused'. Please check that the provided connection details (host, port, etc.) are correct and that your InfluxDB server is running and accessible. Retrying in 60 seconds.
2021-11-11 09:28:46 ERROR (MainThread) [homeassistant.config] Invalid config for [automation]: expected str for dictionary value @ data['from']. Got None. (See ?, line ?). 
2021-11-11 09:28:46 ERROR (MainThread) [homeassistant.config] Invalid config for [automation]: required key not provided @ data['trigger'][1]['platform']. Got None. (See ?, line ?). 
2021-11-11 09:28:46 ERROR (MainThread) [homeassistant.config] Invalid config for [automation]: Unexpected value for condition: 'None'. Expected and, device, not, numeric_state, or, state, sun, template, time, trigger, zone @ data['condition'][0]. Got None. (See ?, line ?). 
2021-11-11 09:28:46 ERROR (MainThread) [homeassistant.config] Invalid config for [automation]: Unexpected value for condition: 'None'. Expected and, device, not, numeric_state, or, state, sun, template, time, trigger, zone @ data['condition'][0]. Got None. (See ?, line ?). 
2021-11-11 09:28:46 ERROR (MainThread) [homeassistant.config] Invalid config for [automation]: required key not provided @ data['action'][4]['domain']. Got None. (See ?, line ?). 
2021-11-11 09:28:46 ERROR (MainThread) [homeassistant.config] Invalid config for [automation]: must be a value between 0 and 59 for dictionary value @ data['minutes']. Got None. (See ?, line ?). 
2021-11-11 09:28:46 ERROR (MainThread) [homeassistant.config] Invalid config for [automation]: must be a value between 0 and 59 for dictionary value @ data['minutes']. Got None. (See ?, line ?). 
2021-11-11 09:28:51 WARNING (MainThread) [homeassistant.setup] Setup of counter is taking over 10 seconds.
2021-11-11 09:28:51 WARNING (MainThread) [homeassistant.setup] Setup of zone is taking over 10 seconds.
2021-11-11 09:28:51 WARNING (MainThread) [homeassistant.setup] Setup of input_select is taking over 10 seconds.
2021-11-11 09:28:51 WARNING (MainThread) [homeassistant.setup] Setup of timer is taking over 10 seconds.
2021-11-11 09:28:51 WARNING (MainThread) [homeassistant.components.fan] Platform xiaomi_miio_fan not ready yet: Unable to discover the device 192.168.86.28; Retrying in background in 30 seconds
2021-11-11 09:28:51 WARNING (MainThread) [homeassistant.components.fan] Platform xiaomi_miio_fan not ready yet: Unable to discover the device 192.168.86.29; Retrying in background in 30 seconds
2021-11-11 09:28:54 WARNING (MainThread) [homeassistant.components.webhook] Received message for unregistered webhook 5fc6e46f1fd47b1a3e7ad935efdabc15f9dc421ed850271abc891db73beb0aa4 from 192.168.86.24
2021-11-11 09:28:54 WARNING (MainThread) [homeassistant.config_entries] Config entry '192.168.86.83' for synology_dsm integration not ready yet: ConnectionError = <urllib3.connection.HTTPSConnection object at 0xffff7b7b61c0>: Failed to establish a new connection: [Errno 113] Host is unreachable; Retrying in background
2021-11-11 09:28:56 WARNING (MainThread) [homeassistant.setup] Setup of input_number is taking over 10 seconds.
2021-11-11 09:28:57 WARNING (MainThread) [homeassistant.components.light] Platform netatmo not ready yet: None; Retrying in background in 30 seconds
2021-11-11 09:28:57 WARNING (MainThread) [homeassistant.components.select] Platform netatmo not ready yet: None; Retrying in background in 30 seconds
2021-11-11 09:28:59 ERROR (MainThread) [custom_components.powercalc.sensors.power] Skipping sensor setup light.buiten: ('No lookup file found for mode', 'brightness')
2021-11-11 09:28:59 WARNING (MainThread) [homeassistant.components.hue.light] Please check for software updates of the douche bulb in the Philips Hue App.
2021-11-11 09:29:00 WARNING (MainThread) [homeassistant.components.energy.sensor] Found unexpected state_class None for sensor.tv_energy
2021-11-11 09:29:02 WARNING (MainThread) [homeassistant.components.sensor] Platform netatmo not ready yet: None; Retrying in background in 30 seconds
2021-11-11 09:29:05 WARNING (MainThread) [homeassistant.config_entries] Config entry 'OnHub' for upnp integration not ready yet; Retrying in background
2021-11-11 09:29:05 WARNING (MainThread) [homeassistant.components.binary_sensor] Updating ping binary_sensor took longer than the scheduled update interval 0:00:05
2021-11-11 09:29:05 ERROR (MainThread) [homeassistant.components.sensor] scrape: Error on device update!
Traceback (most recent call last):
  File "/usr/src/homeassistant/homeassistant/helpers/entity_platform.py", line 431, in _async_add_entity
    await entity.async_device_update(warning=False)
  File "/usr/src/homeassistant/homeassistant/helpers/entity.py", line 651, in async_device_update
    await task
  File "/usr/src/homeassistant/homeassistant/components/scrape/sensor.py", line 166, in async_update
    await self._async_update_from_rest_data()
  File "/usr/src/homeassistant/homeassistant/components/scrape/sensor.py", line 179, in _async_update_from_rest_data
    value = await self.hass.async_add_executor_job(self._extract_value)
  File "/usr/local/lib/python3.9/concurrent/futures/thread.py", line 52, in run
    result = self.fn(*self.args, **self.kwargs)
  File "/usr/src/homeassistant/homeassistant/components/scrape/sensor.py", line 155, in _extract_value
    tag = raw_data.select(self._select)[self._index]
  File "/usr/local/lib/python3.9/site-packages/bs4/element.py", line 1949, in select
    results = soupsieve.select(selector, self, namespaces, limit, **kwargs)
  File "/usr/local/lib/python3.9/site-packages/soupsieve/__init__.py", line 144, in select
    return compile(select, namespaces, flags, **kwargs).select(tag, limit)
  File "/usr/local/lib/python3.9/site-packages/soupsieve/__init__.py", line 67, in compile
    return cp._cached_css_compile(pattern, ns, cs, flags)
  File "/usr/local/lib/python3.9/site-packages/soupsieve/css_parser.py", line 218, in _cached_css_compile
    CSSParser(
  File "/usr/local/lib/python3.9/site-packages/soupsieve/css_parser.py", line 1159, in process_selectors
    return self.parse_selectors(self.selector_iter(self.pattern), index, flags)
  File "/usr/local/lib/python3.9/site-packages/soupsieve/css_parser.py", line 985, in parse_selectors
    key, m = next(iselector)
  File "/usr/local/lib/python3.9/site-packages/soupsieve/css_parser.py", line 1152, in selector_iter
    raise SelectorSyntaxError(msg, self.pattern, index)
soupsieve.util.SelectorSyntaxError: Invalid character '<' position 0
  line 1:
<span _ngcontent-app-root-c173="">Offline</span>
^
2021-11-11 09:29:07 WARNING (MainThread) [homeassistant.components.sensor] Setup of sensor platform scrape is taking over 10 seconds.
2021-11-11 09:29:07 WARNING (MainThread) [homeassistant.components.sensor] Setup of sensor platform scrape is taking over 10 seconds.
2021-11-11 09:29:07 WARNING (MainThread) [homeassistant.components.sensor] Setup of sensor platform scrape is taking over 10 seconds.
2021-11-11 09:29:07 WARNING (MainThread) [homeassistant.components.sensor] Setup of sensor platform scrape is taking over 10 seconds.
2021-11-11 09:29:07 WARNING (MainThread) [homeassistant.components.sensor] Setup of sensor platform scrape is taking over 10 seconds.
2021-11-11 09:29:28 WARNING (stream_worker) [libav.hls] skipping 1 segments ahead, expired from playlists
2021-11-11 09:29:29 ERROR (MainThread) [homeassistant.components.google_assistant.http] Request for https://homegraph.googleapis.com/v1/devices:requestSync failed: 500
2021-11-11 09:29:30 WARNING (MainThread) [homeassistant.components.media_player] Updating huesyncbox media_player took longer than the scheduled update interval 0:00:02
2021-11-11 09:29:31 WARNING (stream_worker) [libav.hls] skipping 1 segments ahead, expired from playlists
2021-11-11 09:29:34 WARNING (MainThread) [homeassistant.components.binary_sensor] Updating ping binary_sensor took longer than the scheduled update interval 0:00:05
2021-11-11 09:29:44 WARNING (MainThread) [homeassistant.helpers.entity] Update of binary_sensor.google_server is taking over 10 seconds
2021-11-11 09:29:44 WARNING (MainThread) [homeassistant.components.binary_sensor] Updating ping binary_sensor took longer than the scheduled update interval 0:00:05
2021-11-11 09:29:45 ERROR (SyncWorker_0) [homeassistant.components.influxdb] Cannot connect to InfluxDB due to '<urllib3.connection.HTTPConnection object at 0xffff7ffcecd0>: Failed to establish a new connection: [Errno 111] Connection refused'. Please check that the provided connection details (host, port, etc.) are correct and that your InfluxDB server is running and accessible. Retrying in 60 seconds.
2021-11-11 09:29:45 WARNING (MainThread) [homeassistant.components.media_player] Updating huesyncbox media_player took longer than the scheduled update interval 0:00:02
2021-11-11 09:29:47 ERROR (MainThread) [homeassistant.components.google_assistant.http] Request for https://homegraph.googleapis.com/v1/devices:reportStateAndNotification failed: 404
2021-11-11 09:30:13 WARNING (MainThread) [homeassistant.components.binary_sensor] Updating ping binary_sensor took longer than the scheduled update interval 0:00:05
2021-11-11 09:30:23 WARNING (MainThread) [homeassistant.components.binary_sensor] Updating ping binary_sensor took longer than the scheduled update interval 0:00:05
2021-11-11 09:30:45 ERROR (SyncWorker_3) [homeassistant.components.influxdb] Cannot connect to InfluxDB due to '<urllib3.connection.HTTPConnection object at 0xffff5a8842e0>: Failed to establish a new connection: [Errno 111] Connection refused'. Please check that the provided connection details (host, port, etc.) are correct and that your InfluxDB server is running and accessible. Retrying in 60 seconds.
2021-11-11 09:31:45 ERROR (SyncWorker_5) [homeassistant.components.influxdb] Cannot connect to InfluxDB due to '<urllib3.connection.HTTPConnection object at 0xffff6c044eb0>: Failed to establish a new connection: [Errno 111] Connection refused'. Please check that the provided connection details (host, port, etc.) are correct and that your InfluxDB server is running and accessible. Retrying in 60 seconds.
2021-11-11 09:32:25 ERROR (MainThread) [homeassistant.components.google_assistant.http] Request for https://homegraph.googleapis.com/v1/devices:reportStateAndNotification failed: 404
2021-11-11 09:32:45 ERROR (SyncWorker_18) [homeassistant.components.influxdb] Cannot connect to InfluxDB due to '<urllib3.connection.HTTPConnection object at 0xffff6c0a9c40>: Failed to establish a new connection: [Errno 111] Connection refused'. Please check that the provided connection details (host, port, etc.) are correct and that your InfluxDB server is running and accessible. Retrying in 60 seconds.
2021-11-11 09:33:40 ERROR (MainThread) [homeassistant.components.google_assistant.http] Request for https://homegraph.googleapis.com/v1/devices:reportStateAndNotification failed: 404
2021-11-11 09:33:45 ERROR (SyncWorker_20) [homeassistant.components.influxdb] Cannot connect to InfluxDB due to '<urllib3.connection.HTTPConnection object at 0xffff696919a0>: Failed to establish a new connection: [Errno 111] Connection refused'. Please check that the provided connection details (host, port, etc.) are correct and that your InfluxDB server is running and accessible. Retrying in 60 seconds.
2021-11-11 09:34:45 ERROR (SyncWorker_21) [homeassistant.components.influxdb] Cannot connect to InfluxDB due to '<urllib3.connection.HTTPConnection object at 0xffff70c53f40>: Failed to establish a new connection: [Errno 111] Connection refused'. Please check that the provided connection details (host, port, etc.) are correct and that your InfluxDB server is running and accessible. Retrying in 60 seconds.
2021-11-11 09:35:45 ERROR (SyncWorker_8) [homeassistant.components.influxdb] Cannot connect to InfluxDB due to '<urllib3.connection.HTTPConnection object at 0xffff6966e670>: Failed to establish a new connection: [Errno 111] Connection refused'. Please check that the provided connection details (host, port, etc.) are correct and that your InfluxDB server is running and accessible. Retrying in 60 seconds.
2021-11-11 09:36:45 ERROR (SyncWorker_18) [homeassistant.components.influxdb] Cannot connect to InfluxDB due to '<urllib3.connection.HTTPConnection object at 0xffff6d2fee50>: Failed to establish a new connection: [Errno 111] Connection refused'. Please check that the provided connection details (host, port, etc.) are correct and that your InfluxDB server is running and accessible. Retrying in 60 seconds.
2021-11-11 09:37:45 ERROR (SyncWorker_1) [homeassistant.components.influxdb] Cannot connect to InfluxDB due to '<urllib3.connection.HTTPConnection object at 0xffff69637940>: Failed to establish a new connection: [Errno 111] Connection refused'. Please check that the provided connection details (host, port, etc.) are correct and that your InfluxDB server is running and accessible. Retrying in 60 seconds.
2021-11-11 09:38:41 WARNING (MainThread) [haffmpeg.tools] Timeout reading image.
2021-11-11 09:38:45 ERROR (SyncWorker_22) [homeassistant.components.influxdb] Cannot connect to InfluxDB due to '<urllib3.connection.HTTPConnection object at 0xffff5a12d340>: Failed to establish a new connection: [Errno 111] Connection refused'. Please check that the provided connection details (host, port, etc.) are correct and that your InfluxDB server is running and accessible. Retrying in 60 seconds.
2021-11-11 09:38:48 WARNING (MainThread) [homeassistant.components.binary_sensor] Updating ping binary_sensor took longer than the scheduled update interval 0:00:05
2021-11-11 09:38:50 ERROR (MainThread) [homeassistant.components.google_assistant.http] Request for https://homegraph.googleapis.com/v1/devices:reportStateAndNotification failed: 404
2021-11-11 09:39:45 ERROR (SyncWorker_21) [homeassistant.components.influxdb] Cannot connect to InfluxDB due to '<urllib3.connection.HTTPConnection object at 0xffff705b60a0>: Failed to establish a new connection: [Errno 111] Connection refused'. Please check that the provided connection details (host, port, etc.) are correct and that your InfluxDB server is running and accessible. Retrying in 60 seconds.
2021-11-11 09:40:04 WARNING (MainThread) [haffmpeg.tools] Timeout reading image.
2021-11-11 09:40:45 ERROR (SyncWorker_5) [homeassistant.components.influxdb] Cannot connect to InfluxDB due to '<urllib3.connection.HTTPConnection object at 0xffff705ca4c0>: Failed to establish a new connection: [Errno 111] Connection refused'. Please check that the provided connection details (host, port, etc.) are correct and that your InfluxDB server is running and accessible. Retrying in 60 seconds.
2021-11-11 09:41:08 WARNING (MainThread) [homeassistant.components.binary_sensor] Updating ping binary_sensor took longer than the scheduled update interval 0:00:05
2021-11-11 09:41:45 ERROR (SyncWorker_17) [homeassistant.components.influxdb] Cannot connect to InfluxDB due to '<urllib3.connection.HTTPConnection object at 0xffff56c32730>: Failed to establish a new connection: [Errno 111] Connection refused'. Please check that the provided connection details (host, port, etc.) are correct and that your InfluxDB server is running and accessible. Retrying in 60 seconds.
2021-11-11 09:42:45 ERROR (SyncWorker_20) [homeassistant.components.influxdb] Cannot connect to InfluxDB due to '<urllib3.connection.HTTPConnection object at 0xffff5aa331f0>: Failed to establish a new connection: [Errno 111] Connection refused'. Please check that the provided connection details (host, port, etc.) are correct and that your InfluxDB server is running and accessible. Retrying in 60 seconds.
2021-11-11 09:43:45 ERROR (SyncWorker_7) [homeassistant.components.influxdb] Cannot connect to InfluxDB due to '<urllib3.connection.HTTPConnection object at 0xffff7944c7f0>: Failed to establish a new connection: [Errno 111] Connection refused'. Please check that the provided connection details (host, port, etc.) are correct and that your InfluxDB server is running and accessible. Retrying in 60 seconds.
2021-11-11 09:44:45 ERROR (SyncWorker_20) [homeassistant.components.influxdb] Cannot connect to InfluxDB due to '<urllib3.connection.HTTPConnection object at 0xffff7299a880>: Failed to establish a new connection: [Errno 111] Connection refused'. Please check that the provided connection details (host, port, etc.) are correct and that your InfluxDB server is running and accessible. Retrying in 60 seconds.
2021-11-11 09:45:45 ERROR (SyncWorker_16) [homeassistant.components.influxdb] Cannot connect to InfluxDB due to '<urllib3.connection.HTTPConnection object at 0xffff5aa25b20>: Failed to establish a new connection: [Errno 111] Connection refused'. Please check that the provided connection details (host, port, etc.) are correct and that your InfluxDB server is running and accessible. Retrying in 60 seconds.
2021-11-11 09:46:45 ERROR (SyncWorker_6) [homeassistant.components.influxdb] Cannot connect to InfluxDB due to '<urllib3.connection.HTTPConnection object at 0xffff5a10e220>: Failed to establish a new connection: [Errno 111] Connection refused'. Please check that the provided connection details (host, port, etc.) are correct and that your InfluxDB server is running and accessible. Retrying in 60 seconds.
2021-11-11 09:47:45 ERROR (SyncWorker_8) [homeassistant.components.influxdb] Cannot connect to InfluxDB due to '<urllib3.connection.HTTPConnection object at 0xffff6c37b070>: Failed to establish a new connection: [Errno 111] Connection refused'. Please check that the provided connection details (host, port, etc.) are correct and that your InfluxDB server is running and accessible. Retrying in 60 seconds.
2021-11-11 09:47:52 ERROR (MainThread) [homeassistant.config] Invalid config for [automation]: expected str for dictionary value @ data['from']. Got None. (See ?, line ?). 
2021-11-11 09:47:52 ERROR (MainThread) [homeassistant.config] Invalid config for [automation]: required key not provided @ data['trigger'][1]['platform']. Got None. (See ?, line ?). 
2021-11-11 09:47:52 ERROR (MainThread) [homeassistant.config] Invalid config for [automation]: Unexpected value for condition: 'None'. Expected and, device, not, numeric_state, or, state, sun, template, time, trigger, zone @ data['condition'][0]. Got None. (See ?, line ?). 
2021-11-11 09:47:52 ERROR (MainThread) [homeassistant.config] Invalid config for [automation]: Unexpected value for condition: 'None'. Expected and, device, not, numeric_state, or, state, sun, template, time, trigger, zone @ data['condition'][0]. Got None. (See ?, line ?). 
2021-11-11 09:47:52 ERROR (MainThread) [homeassistant.config] Invalid config for [automation]: required key not provided @ data['action'][4]['domain']. Got None. (See ?, line ?). 
2021-11-11 09:47:52 ERROR (MainThread) [homeassistant.config] Invalid config for [automation]: must be a value between 0 and 59 for dictionary value @ data['minutes']. Got None. (See ?, line ?). 
2021-11-11 09:47:52 ERROR (MainThread) [homeassistant.config] Invalid config for [automation]: must be a value between 0 and 59 for dictionary value @ data['minutes']. Got None. (See ?, line ?). 
2021-11-11 09:48:03 ERROR (MainThread) [homeassistant.config] Invalid config for [automation]: expected str for dictionary value @ data['from']. Got None. (See ?, line ?). 
2021-11-11 09:48:03 ERROR (MainThread) [homeassistant.config] Invalid config for [automation]: required key not provided @ data['trigger'][1]['platform']. Got None. (See ?, line ?). 
2021-11-11 09:48:03 ERROR (MainThread) [homeassistant.config] Invalid config for [automation]: Unexpected value for condition: 'None'. Expected and, device, not, numeric_state, or, state, sun, template, time, trigger, zone @ data['condition'][0]. Got None. (See ?, line ?). 
2021-11-11 09:48:03 ERROR (MainThread) [homeassistant.config] Invalid config for [automation]: Unexpected value for condition: 'None'. Expected and, device, not, numeric_state, or, state, sun, template, time, trigger, zone @ data['condition'][0]. Got None. (See ?, line ?). 
2021-11-11 09:48:03 ERROR (MainThread) [homeassistant.config] Invalid config for [automation]: required key not provided @ data['action'][4]['domain']. Got None. (See ?, line ?). 
2021-11-11 09:48:03 ERROR (MainThread) [homeassistant.config] Invalid config for [automation]: must be a value between 0 and 59 for dictionary value @ data['minutes']. Got None. (See ?, line ?). 
2021-11-11 09:48:03 ERROR (MainThread) [homeassistant.config] Invalid config for [automation]: must be a value between 0 and 59 for dictionary value @ data['minutes']. Got None. (See ?, line ?). 
2021-11-11 09:48:04 ERROR (MainThread) [homeassistant.helpers.entity] Update for sensor.master_bedroom_tv_aan_vandaag fails
Traceback (most recent call last):
  File "/usr/src/homeassistant/homeassistant/helpers/entity.py", line 468, in async_update_ha_state
    await self.async_device_update()
  File "/usr/src/homeassistant/homeassistant/helpers/entity.py", line 658, in async_device_update
    raise exc
  File "/usr/src/homeassistant/homeassistant/components/history_stats/sensor.py", line 221, in async_update
    await self.hass.async_add_executor_job(
  File "/usr/local/lib/python3.9/concurrent/futures/thread.py", line 52, in run
    result = self.fn(*self.args, **self.kwargs)
  File "/usr/src/homeassistant/homeassistant/components/history_stats/sensor.py", line 227, in _update
    history_list = history.state_changes_during_period(
  File "/usr/src/homeassistant/homeassistant/components/recorder/history.py", line 147, in state_changes_during_period
    with session_scope(hass=hass) as session:
  File "/usr/local/lib/python3.9/contextlib.py", line 119, in __enter__
    return next(self.gen)
  File "/usr/src/homeassistant/homeassistant/components/recorder/util.py", line 73, in session_scope
    session = hass.data[DATA_INSTANCE].get_session()
TypeError: 'NoneType' object is not callable
