2021-10-07 18:13:34 WARNING (SyncWorker_0) [homeassistant.loader] We found a custom integration average which has not been tested by Home Assistant. This component might cause stability problems, be sure to disable it if you experience issues with Home Assistant
2021-10-07 18:13:34 WARNING (SyncWorker_0) [homeassistant.loader] We found a custom integration xiaomi_miio_airpurifier which has not been tested by Home Assistant. This component might cause stability problems, be sure to disable it if you experience issues with Home Assistant
2021-10-07 18:13:34 WARNING (SyncWorker_1) [homeassistant.loader] We found a custom integration hacs which has not been tested by Home Assistant. This component might cause stability problems, be sure to disable it if you experience issues with Home Assistant
2021-10-07 18:13:34 WARNING (SyncWorker_2) [homeassistant.loader] We found a custom integration powercalc which has not been tested by Home Assistant. This component might cause stability problems, be sure to disable it if you experience issues with Home Assistant
2021-10-07 18:13:34 WARNING (SyncWorker_7) [homeassistant.loader] We found a custom integration tuya_v2 which has not been tested by Home Assistant. This component might cause stability problems, be sure to disable it if you experience issues with Home Assistant
2021-10-07 18:13:34 WARNING (SyncWorker_3) [homeassistant.loader] We found a custom integration audiconnect which has not been tested by Home Assistant. This component might cause stability problems, be sure to disable it if you experience issues with Home Assistant
2021-10-07 18:13:34 WARNING (SyncWorker_5) [homeassistant.loader] We found a custom integration localtuya which has not been tested by Home Assistant. This component might cause stability problems, be sure to disable it if you experience issues with Home Assistant
2021-10-07 18:13:34 WARNING (SyncWorker_6) [homeassistant.loader] We found a custom integration shelly which has not been tested by Home Assistant. This component might cause stability problems, be sure to disable it if you experience issues with Home Assistant
2021-10-07 18:13:34 WARNING (SyncWorker_4) [homeassistant.loader] We found a custom integration monitor_docker which has not been tested by Home Assistant. This component might cause stability problems, be sure to disable it if you experience issues with Home Assistant
2021-10-07 18:13:34 WARNING (SyncWorker_0) [homeassistant.loader] We found a custom integration xiaomi_miio_fan which has not been tested by Home Assistant. This component might cause stability problems, be sure to disable it if you experience issues with Home Assistant
2021-10-07 18:13:34 WARNING (SyncWorker_1) [homeassistant.loader] We found a custom integration huesyncbox which has not been tested by Home Assistant. This component might cause stability problems, be sure to disable it if you experience issues with Home Assistant
2021-10-07 18:13:34 WARNING (SyncWorker_4) [homeassistant.loader] We found a custom integration thermal_comfort which has not been tested by Home Assistant. This component might cause stability problems, be sure to disable it if you experience issues with Home Assistant
2021-10-07 18:13:34 WARNING (SyncWorker_9) [homeassistant.loader] We found a custom integration buienalarm which has not been tested by Home Assistant. This component might cause stability problems, be sure to disable it if you experience issues with Home Assistant
2021-10-07 18:13:34 WARNING (SyncWorker_10) [homeassistant.loader] We found a custom integration anniversaries which has not been tested by Home Assistant. This component might cause stability problems, be sure to disable it if you experience issues with Home Assistant
2021-10-07 18:13:34 WARNING (SyncWorker_7) [homeassistant.loader] We found a custom integration google_home which has not been tested by Home Assistant. This component might cause stability problems, be sure to disable it if you experience issues with Home Assistant
2021-10-07 18:13:34 WARNING (SyncWorker_2) [homeassistant.loader] We found a custom integration xiaomi_miot which has not been tested by Home Assistant. This component might cause stability problems, be sure to disable it if you experience issues with Home Assistant
2021-10-07 18:13:34 WARNING (SyncWorker_4) [homeassistant.loader] We found a custom integration ytube_music_player which has not been tested by Home Assistant. This component might cause stability problems, be sure to disable it if you experience issues with Home Assistant
2021-10-07 18:13:34 WARNING (SyncWorker_0) [homeassistant.loader] We found a custom integration deepstack_face which has not been tested by Home Assistant. This component might cause stability problems, be sure to disable it if you experience issues with Home Assistant
2021-10-07 18:13:34 WARNING (SyncWorker_1) [homeassistant.loader] We found a custom integration afvalbeheer which has not been tested by Home Assistant. This component might cause stability problems, be sure to disable it if you experience issues with Home Assistant
2021-10-07 18:13:34 WARNING (SyncWorker_6) [homeassistant.loader] We found a custom integration googlewifi which has not been tested by Home Assistant. This component might cause stability problems, be sure to disable it if you experience issues with Home Assistant
2021-10-07 18:13:40 ERROR (MainThread) [homeassistant.config] Invalid config for [automation]: required key not provided @ data['action'][4]['domain']. Got None. (See ?, line ?). 
2021-10-07 18:13:40 ERROR (MainThread) [homeassistant.config] Invalid config for [automation]: [title] is an invalid option for [automation]. Check: automation->action->1->title. (See ?, line ?). 
2021-10-07 18:13:40 ERROR (MainThread) [homeassistant.config] Invalid config for [automation]: must be a value between 0 and 59 for dictionary value @ data['minutes']. Got None. (See ?, line ?). 
2021-10-07 18:13:40 ERROR (MainThread) [homeassistant.config] Invalid config for [automation]: must be a value between 0 and 59 for dictionary value @ data['minutes']. Got None. (See ?, line ?). 
2021-10-07 18:13:51 WARNING (MainThread) [homeassistant.components.webhook] Received message for unregistered webhook 8b8f82ade2e454d538c7b1b55e021814b7aa12b9fa3693773bc28dc044af0487 from 192.168.86.34
2021-10-07 18:13:52 WARNING (MainThread) [homeassistant.components.webhook] Received message for unregistered webhook 80adf825ef6b969ee3c95fc54091652f8a80fe790532f31c6bff63908742af08 from 192.168.86.26
2021-10-07 18:13:52 WARNING (MainThread) [homeassistant.components.webhook] Received message for unregistered webhook 8b8f82ade2e454d538c7b1b55e021814b7aa12b9fa3693773bc28dc044af0487 from 192.168.86.34
2021-10-07 18:13:52 WARNING (MainThread) [homeassistant.components.webhook] Received message for unregistered webhook 8b8f82ade2e454d538c7b1b55e021814b7aa12b9fa3693773bc28dc044af0487 from 192.168.86.34
2021-10-07 18:14:06 WARNING (MainThread) [homeassistant.components.webhook] Received message for unregistered webhook 80adf825ef6b969ee3c95fc54091652f8a80fe790532f31c6bff63908742af08 from 192.168.86.26
2021-10-07 18:14:08 ERROR (MainThread) [homeassistant.config_entries] Error setting up entry bartland@gmail.com for tuya
Traceback (most recent call last):
  File "/usr/src/homeassistant/homeassistant/config_entries.py", line 304, in async_setup
    result = await component.async_setup_entry(hass, self)  # type: ignore
  File "/usr/src/homeassistant/homeassistant/components/tuya/__init__.py", line 59, in async_setup_entry
    success = await _init_tuya_sdk(hass, entry)
  File "/usr/src/homeassistant/homeassistant/components/tuya/__init__.py", line 71, in _init_tuya_sdk
    auth_type = AuthType(entry.data[CONF_AUTH_TYPE])
KeyError: 'auth_type'
2021-10-07 18:14:08 ERROR (MainThread) [homeassistant.setup] Setup failed for tuya_v2: Unable to import component: cannot import name 'ProjectType' from 'tuya_iot' (/usr/local/lib/python3.9/site-packages/tuya_iot/__init__.py)
2021-10-07 18:14:15 WARNING (MainThread) [homeassistant.config_entries] Config entry '192.168.86.83' for synology_dsm integration not ready yet: ConnectionError = <urllib3.connection.HTTPSConnection object at 0xffffa5cf9460>: Failed to establish a new connection: [Errno 113] Host is unreachable; Retrying in background
2021-10-07 18:14:16 WARNING (MainThread) [homeassistant.components.hue.light] Please check for software updates of the douche bulb in the Philips Hue App.
2021-10-07 18:14:16 WARNING (MainThread) [homeassistant.components.hue.light] Please check for software updates of the wasbak rechts bulb in the Philips Hue App.
2021-10-07 18:14:16 WARNING (MainThread) [homeassistant.components.hue.light] Please check for software updates of the bad bulb in the Philips Hue App.
2021-10-07 18:14:16 WARNING (MainThread) [homeassistant.components.hue.light] Please check for software updates of the Amilya plafond 2 bulb in the Philips Hue App.
2021-10-07 18:14:16 WARNING (MainThread) [homeassistant.components.hue.light] Please check for software updates of the Amilya plafond 1 bulb in the Philips Hue App.
2021-10-07 18:14:18 WARNING (MainThread) [homeassistant.components.light] Platform netatmo not ready yet: None; Retrying in background in 30 seconds
2021-10-07 18:14:18 WARNING (MainThread) [homeassistant.components.fan] Platform xiaomi_miio_fan not ready yet: Unable to discover the device 192.168.86.28; Retrying in background in 30 seconds
2021-10-07 18:14:18 WARNING (MainThread) [homeassistant.components.fan] Platform xiaomi_miio_fan not ready yet: Unable to discover the device 192.168.86.29; Retrying in background in 30 seconds
2021-10-07 18:14:18 WARNING (MainThread) [homeassistant.components.select] Platform netatmo not ready yet: None; Retrying in background in 30 seconds
2021-10-07 18:14:19 WARNING (MainThread) [homeassistant.components.sensor] Platform netatmo not ready yet: None; Retrying in background in 30 seconds
2021-10-07 18:14:19 ERROR (SyncWorker_8) [glocaltokens.client] [Device - Nest Wifi router(id=2f2a9d15-0ae2-4ffe-b6c1-2ef24c742b8a)] local_auth_token must follow the correct format
2021-10-07 18:14:19 ERROR (SyncWorker_8) [glocaltokens.client] [Device - Nest Wifi router(id=e1e5a8d5-d21f-444d-95a9-c76d78c9bc79)] local_auth_token must follow the correct format
2021-10-07 18:14:19 ERROR (SyncWorker_8) [glocaltokens.client] [Device - Nest Wifi router(id=ea3de37c-ca74-4689-8171-1681b2f4f924)] local_auth_token must follow the correct format
2021-10-07 18:14:22 ERROR (MainThread) [homeassistant.components.sensor] scrape: Error on device update!
Traceback (most recent call last):
  File "/usr/src/homeassistant/homeassistant/helpers/entity_platform.py", line 431, in _async_add_entity
    await entity.async_device_update(warning=False)
  File "/usr/src/homeassistant/homeassistant/helpers/entity.py", line 618, in async_device_update
    await task
  File "/usr/src/homeassistant/homeassistant/components/scrape/sensor.py", line 139, in async_update
    await self._async_update_from_rest_data()
  File "/usr/src/homeassistant/homeassistant/components/scrape/sensor.py", line 152, in _async_update_from_rest_data
    value = await self.hass.async_add_executor_job(self._extract_value)
  File "/usr/local/lib/python3.9/concurrent/futures/thread.py", line 52, in run
    result = self.fn(*self.args, **self.kwargs)
  File "/usr/src/homeassistant/homeassistant/components/scrape/sensor.py", line 128, in _extract_value
    tag = raw_data.select(self._select)[self._index]
  File "/usr/local/lib/python3.9/site-packages/bs4/element.py", line 1949, in select
    results = soupsieve.select(selector, self, namespaces, limit, **kwargs)
  File "/usr/local/lib/python3.9/site-packages/soupsieve/__init__.py", line 98, in select
    return compile(select, namespaces, flags, **kwargs).select(tag, limit)
  File "/usr/local/lib/python3.9/site-packages/soupsieve/__init__.py", line 62, in compile
    return cp._cached_css_compile(pattern, namespaces, custom, flags)
  File "/usr/local/lib/python3.9/site-packages/soupsieve/css_parser.py", line 211, in _cached_css_compile
    CSSParser(pattern, custom=custom_selectors, flags=flags).process_selectors(),
  File "/usr/local/lib/python3.9/site-packages/soupsieve/css_parser.py", line 1058, in process_selectors
    return self.parse_selectors(self.selector_iter(self.pattern), index, flags)
  File "/usr/local/lib/python3.9/site-packages/soupsieve/css_parser.py", line 909, in parse_selectors
    key, m = next(iselector)
  File "/usr/local/lib/python3.9/site-packages/soupsieve/css_parser.py", line 1051, in selector_iter
    raise SelectorSyntaxError(msg, self.pattern, index)
soupsieve.util.SelectorSyntaxError: Invalid character '<' position 0
  line 1:
<span _ngcontent-app-root-c173="">Offline</span>
^
2021-10-07 18:14:23 ERROR (MainThread) [homeassistant.components.camera] Error while setting up netatmo platform for camera
Traceback (most recent call last):
  File "/usr/local/lib/python3.9/site-packages/aiohttp/connector.py", line 969, in _wrap_create_connection
    return await self._loop.create_connection(*args, **kwargs)  # type: ignore  # noqa
  File "/usr/local/lib/python3.9/asyncio/base_events.py", line 1056, in create_connection
    raise exceptions[0]
  File "/usr/local/lib/python3.9/asyncio/base_events.py", line 1041, in create_connection
    sock = await self._connect_sock(
  File "/usr/local/lib/python3.9/asyncio/base_events.py", line 955, in _connect_sock
    await self.sock_connect(sock, address)
  File "/usr/local/lib/python3.9/asyncio/selector_events.py", line 502, in sock_connect
    return await fut
  File "/usr/local/lib/python3.9/asyncio/selector_events.py", line 537, in _sock_connect_cb
    raise OSError(err, f'Connect call failed {address}')
OSError: [Errno 113] Connect call failed ('169.254.113.236', 80)

The above exception was the direct cause of the following exception:

Traceback (most recent call last):
  File "/usr/src/homeassistant/homeassistant/helpers/entity_platform.py", line 249, in _async_setup_platform
    await asyncio.shield(task)
  File "/usr/src/homeassistant/homeassistant/components/netatmo/camera.py", line 57, in async_setup_entry
    await data_handler.register_data_class(
  File "/usr/src/homeassistant/homeassistant/components/netatmo/data_handler.py", line 192, in register_data_class
    await self.async_fetch_data(data_class_entry)
  File "/usr/src/homeassistant/homeassistant/components/netatmo/data_handler.py", line 149, in async_fetch_data
    await self.data[data_class_entry].async_update()
  File "/usr/local/lib/python3.9/site-packages/pyatmo/camera.py", line 652, in async_update
    await self._async_update_all_camera_urls()
  File "/usr/local/lib/python3.9/site-packages/pyatmo/camera.py", line 662, in _async_update_all_camera_urls
    await self.async_update_camera_urls(camera_id)
  File "/usr/local/lib/python3.9/site-packages/pyatmo/camera.py", line 728, in async_update_camera_urls
    ] = await self._async_check_url(
  File "/usr/local/lib/python3.9/site-packages/pyatmo/camera.py", line 735, in _async_check_url
    resp = await self.auth.async_post_request(url=f"{url}/command/ping")
  File "/usr/local/lib/python3.9/site-packages/pyatmo/auth.py", line 339, in async_post_request
    async with self.websession.post(
  File "/usr/local/lib/python3.9/site-packages/aiohttp/client.py", line 1117, in __aenter__
    self._resp = await self._coro
  File "/usr/local/lib/python3.9/site-packages/aiohttp/client.py", line 520, in _request
    conn = await self._connector.connect(
  File "/usr/local/lib/python3.9/site-packages/aiohttp/connector.py", line 535, in connect
    proto = await self._create_connection(req, traces, timeout)
  File "/usr/local/lib/python3.9/site-packages/aiohttp/connector.py", line 892, in _create_connection
    _, proto = await self._create_direct_connection(req, traces, timeout)
  File "/usr/local/lib/python3.9/site-packages/aiohttp/connector.py", line 1051, in _create_direct_connection
    raise last_exc
  File "/usr/local/lib/python3.9/site-packages/aiohttp/connector.py", line 1020, in _create_direct_connection
    transp, proto = await self._wrap_create_connection(
  File "/usr/local/lib/python3.9/site-packages/aiohttp/connector.py", line 975, in _wrap_create_connection
    raise client_error(req.connection_key, exc) from exc
aiohttp.client_exceptions.ClientConnectorError: Cannot connect to host 169.254.113.236:80 ssl:default [Connect call failed ('169.254.113.236', 80)]
2021-10-07 18:14:24 WARNING (MainThread) [homeassistant.config_entries] Config entry 'OnHub' for upnp integration not ready yet; Retrying in background
2021-10-07 18:14:33 WARNING (MainThread) [homeassistant.helpers.template] Template warning: 'float' got invalid input 'unknown' when rendering template '{{ states('sensor.tv_living_on_today') | float * 0.085 | round(3) }}' but no default was specified. Currently 'float' will return '0', however this template will fail to render in Home Assistant core 2021.12
2021-10-07 18:14:33 WARNING (MainThread) [homeassistant.helpers.template] Template warning: 'float' got invalid input 'unknown' when rendering template '{{ states('sensor.tv_living_on_today') | float * 0.085 | round(3) }}' but no default was specified. Currently 'float' will return '0', however this template will fail to render in Home Assistant core 2021.12
2021-10-07 18:14:33 WARNING (MainThread) [homeassistant.helpers.template] Template warning: 'float' got invalid input 'unknown' when rendering template '{{ states('sensor.master_bedroom_TV_on_today') | float * 0.063 | round(3) }}' but no default was specified. Currently 'float' will return '0', however this template will fail to render in Home Assistant core 2021.12
2021-10-07 18:14:33 WARNING (MainThread) [homeassistant.helpers.template] Template warning: 'float' got invalid input 'unknown' when rendering template '{{ states('sensor.master_bedroom_TV_on_today') | float * 0.063 | round(3) }}' but no default was specified. Currently 'float' will return '0', however this template will fail to render in Home Assistant core 2021.12
2021-10-07 18:14:37 WARNING (MainThread) [homeassistant.components.media_player] Updating huesyncbox media_player took longer than the scheduled update interval 0:00:02
2021-10-07 18:14:47 ERROR (MainThread) [homeassistant.components.google_assistant.http] Request for https://homegraph.googleapis.com/v1/devices:requestSync failed: 500
2021-10-07 18:14:47 ERROR (MainThread) [homeassistant.components.google_assistant.http] Request for https://homegraph.googleapis.com/v1/devices:reportStateAndNotification failed: 404
2021-10-07 18:25:52 ERROR (MainThread) [homeassistant.config] Invalid config for [automation]: required key not provided @ data['action'][4]['domain']. Got None. (See ?, line ?). 
2021-10-07 18:25:52 ERROR (MainThread) [homeassistant.config] Invalid config for [automation]: [title] is an invalid option for [automation]. Check: automation->action->1->title. (See ?, line ?). 
2021-10-07 18:25:52 ERROR (MainThread) [homeassistant.config] Invalid config for [automation]: must be a value between 0 and 59 for dictionary value @ data['minutes']. Got None. (See ?, line ?). 
2021-10-07 18:25:52 ERROR (MainThread) [homeassistant.config] Invalid config for [automation]: must be a value between 0 and 59 for dictionary value @ data['minutes']. Got None. (See ?, line ?). 
2021-10-07 18:25:53 ERROR (MainThread) [homeassistant.config] Invalid config for [automation]: required key not provided @ data['action']. Got None
required key not provided @ data['trigger']. Got None. (See ?, line ?). 
2021-10-07 18:25:58 ERROR (MainThread) [homeassistant.config] Invalid config for [automation]: required key not provided @ data['action'][4]['domain']. Got None. (See ?, line ?). 
2021-10-07 18:25:58 ERROR (MainThread) [homeassistant.config] Invalid config for [automation]: [title] is an invalid option for [automation]. Check: automation->action->1->title. (See ?, line ?). 
2021-10-07 18:25:58 ERROR (MainThread) [homeassistant.config] Invalid config for [automation]: must be a value between 0 and 59 for dictionary value @ data['minutes']. Got None. (See ?, line ?). 
2021-10-07 18:25:58 ERROR (MainThread) [homeassistant.config] Invalid config for [automation]: must be a value between 0 and 59 for dictionary value @ data['minutes']. Got None. (See ?, line ?). 
2021-10-07 18:25:58 ERROR (MainThread) [homeassistant.config] Invalid config for [automation]: required key not provided @ data['action']. Got None
required key not provided @ data['trigger']. Got None. (See ?, line ?). 
