2021-11-20 10:05:39 WARNING (SyncWorker_0) [homeassistant.loader] We found a custom integration average which has not been tested by Home Assistant. This component might cause stability problems, be sure to disable it if you experience issues with Home Assistant
2021-11-20 10:05:39 WARNING (SyncWorker_3) [homeassistant.loader] We found a custom integration audiconnect which has not been tested by Home Assistant. This component might cause stability problems, be sure to disable it if you experience issues with Home Assistant
2021-11-20 10:05:39 WARNING (SyncWorker_1) [homeassistant.loader] We found a custom integration adaptive_lighting which has not been tested by Home Assistant. This component might cause stability problems, be sure to disable it if you experience issues with Home Assistant
2021-11-20 10:05:39 WARNING (SyncWorker_2) [homeassistant.loader] We found a custom integration xiaomi_miio_airpurifier which has not been tested by Home Assistant. This component might cause stability problems, be sure to disable it if you experience issues with Home Assistant
2021-11-20 10:05:39 WARNING (SyncWorker_0) [homeassistant.loader] We found a custom integration hacs which has not been tested by Home Assistant. This component might cause stability problems, be sure to disable it if you experience issues with Home Assistant
2021-11-20 10:05:39 WARNING (SyncWorker_4) [homeassistant.loader] We found a custom integration powercalc which has not been tested by Home Assistant. This component might cause stability problems, be sure to disable it if you experience issues with Home Assistant
2021-11-20 10:05:39 WARNING (SyncWorker_1) [homeassistant.loader] We found a custom integration xiaomi_miio_fan which has not been tested by Home Assistant. This component might cause stability problems, be sure to disable it if you experience issues with Home Assistant
2021-11-20 10:05:39 WARNING (SyncWorker_6) [homeassistant.loader] We found a custom integration localtuya which has not been tested by Home Assistant. This component might cause stability problems, be sure to disable it if you experience issues with Home Assistant
2021-11-20 10:05:39 WARNING (SyncWorker_5) [homeassistant.loader] We found a custom integration monitor_docker which has not been tested by Home Assistant. This component might cause stability problems, be sure to disable it if you experience issues with Home Assistant
2021-11-20 10:05:39 WARNING (SyncWorker_7) [homeassistant.loader] We found a custom integration shelly which has not been tested by Home Assistant. This component might cause stability problems, be sure to disable it if you experience issues with Home Assistant
2021-11-20 10:05:39 WARNING (SyncWorker_3) [homeassistant.loader] We found a custom integration huesyncbox which has not been tested by Home Assistant. This component might cause stability problems, be sure to disable it if you experience issues with Home Assistant
2021-11-20 10:05:39 WARNING (SyncWorker_1) [homeassistant.loader] We found a custom integration frigate which has not been tested by Home Assistant. This component might cause stability problems, be sure to disable it if you experience issues with Home Assistant
2021-11-20 10:05:39 WARNING (SyncWorker_8) [homeassistant.loader] We found a custom integration tuya_v2 which has not been tested by Home Assistant. This component might cause stability problems, be sure to disable it if you experience issues with Home Assistant
2021-11-20 10:05:39 WARNING (SyncWorker_4) [homeassistant.loader] We found a custom integration thermal_comfort which has not been tested by Home Assistant. This component might cause stability problems, be sure to disable it if you experience issues with Home Assistant
2021-11-20 10:05:39 WARNING (SyncWorker_3) [homeassistant.loader] We found a custom integration ytube_music_player which has not been tested by Home Assistant. This component might cause stability problems, be sure to disable it if you experience issues with Home Assistant
2021-11-20 10:05:39 WARNING (SyncWorker_5) [homeassistant.loader] We found a custom integration tgtg which has not been tested by Home Assistant. This component might cause stability problems, be sure to disable it if you experience issues with Home Assistant
2021-11-20 10:05:39 WARNING (SyncWorker_10) [homeassistant.loader] We found a custom integration xiaomi_miot which has not been tested by Home Assistant. This component might cause stability problems, be sure to disable it if you experience issues with Home Assistant
2021-11-20 10:05:39 WARNING (SyncWorker_1) [homeassistant.loader] We found a custom integration deepstack_face which has not been tested by Home Assistant. This component might cause stability problems, be sure to disable it if you experience issues with Home Assistant
2021-11-20 10:05:39 WARNING (SyncWorker_0) [homeassistant.loader] We found a custom integration buienalarm which has not been tested by Home Assistant. This component might cause stability problems, be sure to disable it if you experience issues with Home Assistant
2021-11-20 10:05:39 WARNING (SyncWorker_6) [homeassistant.loader] We found a custom integration google_home which has not been tested by Home Assistant. This component might cause stability problems, be sure to disable it if you experience issues with Home Assistant
2021-11-20 10:05:39 WARNING (SyncWorker_2) [homeassistant.loader] We found a custom integration googlewifi which has not been tested by Home Assistant. This component might cause stability problems, be sure to disable it if you experience issues with Home Assistant
2021-11-20 10:05:39 WARNING (SyncWorker_4) [homeassistant.loader] We found a custom integration afvalbeheer which has not been tested by Home Assistant. This component might cause stability problems, be sure to disable it if you experience issues with Home Assistant
2021-11-20 10:05:39 WARNING (SyncWorker_7) [homeassistant.loader] We found a custom integration anniversaries which has not been tested by Home Assistant. This component might cause stability problems, be sure to disable it if you experience issues with Home Assistant
2021-11-20 10:05:47 ERROR (SyncWorker_2) [homeassistant.components.influxdb] Cannot connect to InfluxDB due to '<urllib3.connection.HTTPConnection object at 0xffffaaa5e5b0>: Failed to establish a new connection: [Errno 111] Connection refused'. Please check that the provided connection details (host, port, etc.) are correct and that your InfluxDB server is running and accessible. Retrying in 60 seconds.
2021-11-20 10:05:50 ERROR (MainThread) [homeassistant.config] Invalid config for [automation]: expected str for dictionary value @ data['from']. Got None. (See ?, line ?). 
2021-11-20 10:05:50 ERROR (MainThread) [homeassistant.config] Invalid config for [automation]: required key not provided @ data['trigger'][1]['platform']. Got None. (See ?, line ?). 
2021-11-20 10:05:50 ERROR (MainThread) [homeassistant.config] Invalid config for [automation]: Unexpected value for condition: 'None'. Expected and, device, not, numeric_state, or, state, sun, template, time, trigger, zone @ data['condition'][0]. Got None. (See ?, line ?). 
2021-11-20 10:05:50 ERROR (MainThread) [homeassistant.config] Invalid config for [automation]: Unexpected value for condition: 'None'. Expected and, device, not, numeric_state, or, state, sun, template, time, trigger, zone @ data['condition'][0]. Got None. (See ?, line ?). 
2021-11-20 10:05:50 ERROR (MainThread) [homeassistant.config] Invalid config for [automation]: required key not provided @ data['action'][4]['domain']. Got None. (See ?, line ?). 
2021-11-20 10:05:50 ERROR (MainThread) [homeassistant.config] Invalid config for [automation]: must be a value between 0 and 59 for dictionary value @ data['minutes']. Got None. (See ?, line ?). 
2021-11-20 10:05:50 ERROR (MainThread) [homeassistant.config] Invalid config for [automation]: must be a value between 0 and 59 for dictionary value @ data['minutes']. Got None. (See ?, line ?). 
2021-11-20 10:05:56 WARNING (MainThread) [homeassistant.setup] Setup of input_text is taking over 10 seconds.
2021-11-20 10:05:56 WARNING (MainThread) [homeassistant.setup] Setup of zone is taking over 10 seconds.
2021-11-20 10:05:56 WARNING (MainThread) [homeassistant.setup] Setup of counter is taking over 10 seconds.
2021-11-20 10:05:56 WARNING (MainThread) [homeassistant.components.fan] Platform xiaomi_miio_fan not ready yet: Unable to discover the device 192.168.86.29; Retrying in background in 30 seconds
2021-11-20 10:05:56 WARNING (MainThread) [homeassistant.components.fan] Platform xiaomi_miio_fan not ready yet: Unable to discover the device 192.168.86.28; Retrying in background in 30 seconds
2021-11-20 10:05:59 WARNING (MainThread) [homeassistant.setup] Setup of input_number is taking over 10 seconds.
2021-11-20 10:05:59 WARNING (MainThread) [homeassistant.config_entries] Config entry '192.168.86.83' for synology_dsm integration not ready yet: ConnectionError = <urllib3.connection.HTTPSConnection object at 0xffff9f7325e0>: Failed to establish a new connection: [Errno 113] Host is unreachable; Retrying in background
2021-11-20 10:06:02 WARNING (MainThread) [homeassistant.components.light] Platform netatmo not ready yet: None; Retrying in background in 30 seconds
2021-11-20 10:06:02 WARNING (MainThread) [homeassistant.components.select] Platform netatmo not ready yet: None; Retrying in background in 30 seconds
2021-11-20 10:06:04 WARNING (MainThread) [homeassistant.components.integration.sensor] Could not restore last state: [<class 'decimal.ConversionSyntax'>]
2021-11-20 10:06:05 WARNING (MainThread) [homeassistant.components.energy.sensor] Found unexpected state_class None for sensor.tv_energy
2021-11-20 10:06:06 ERROR (MainThread) [custom_components.powercalc.sensors.power] Skipping sensor setup light.buiten: ('No lookup file found for mode', 'brightness')
2021-11-20 10:06:07 WARNING (MainThread) [homeassistant.components.sensor] Platform netatmo not ready yet: None; Retrying in background in 30 seconds
2021-11-20 10:06:08 ERROR (MainThread) [homeassistant.components.sensor] scrape: Error on device update!
Traceback (most recent call last):
  File "/usr/src/homeassistant/homeassistant/helpers/entity_platform.py", line 431, in _async_add_entity
    await entity.async_device_update(warning=False)
  File "/usr/src/homeassistant/homeassistant/helpers/entity.py", line 651, in async_device_update
    await task
  File "/usr/src/homeassistant/homeassistant/components/scrape/sensor.py", line 166, in async_update
    await self._async_update_from_rest_data()
  File "/usr/src/homeassistant/homeassistant/components/scrape/sensor.py", line 179, in _async_update_from_rest_data
    value = await self.hass.async_add_executor_job(self._extract_value)
  File "/usr/local/lib/python3.9/concurrent/futures/thread.py", line 52, in run
    result = self.fn(*self.args, **self.kwargs)
  File "/usr/src/homeassistant/homeassistant/components/scrape/sensor.py", line 155, in _extract_value
    tag = raw_data.select(self._select)[self._index]
  File "/usr/local/lib/python3.9/site-packages/bs4/element.py", line 1949, in select
    results = soupsieve.select(selector, self, namespaces, limit, **kwargs)
  File "/usr/local/lib/python3.9/site-packages/soupsieve/__init__.py", line 144, in select
    return compile(select, namespaces, flags, **kwargs).select(tag, limit)
  File "/usr/local/lib/python3.9/site-packages/soupsieve/__init__.py", line 67, in compile
    return cp._cached_css_compile(pattern, ns, cs, flags)
  File "/usr/local/lib/python3.9/site-packages/soupsieve/css_parser.py", line 218, in _cached_css_compile
    CSSParser(
  File "/usr/local/lib/python3.9/site-packages/soupsieve/css_parser.py", line 1159, in process_selectors
    return self.parse_selectors(self.selector_iter(self.pattern), index, flags)
  File "/usr/local/lib/python3.9/site-packages/soupsieve/css_parser.py", line 985, in parse_selectors
    key, m = next(iselector)
  File "/usr/local/lib/python3.9/site-packages/soupsieve/css_parser.py", line 1152, in selector_iter
    raise SelectorSyntaxError(msg, self.pattern, index)
soupsieve.util.SelectorSyntaxError: Invalid character '<' position 0
  line 1:
<span _ngcontent-app-root-c173="">Offline</span>
^
2021-11-20 10:06:10 WARNING (MainThread) [homeassistant.components.binary_sensor] Updating ping binary_sensor took longer than the scheduled update interval 0:00:05
2021-11-20 10:06:10 WARNING (MainThread) [homeassistant.config_entries] Config entry 'OnHub' for upnp integration not ready yet; Retrying in background
2021-11-20 10:06:11 ERROR (MainThread) [homeassistant.components.camera] Error while setting up netatmo platform for camera
Traceback (most recent call last):
  File "/usr/local/lib/python3.9/site-packages/aiohttp/connector.py", line 969, in _wrap_create_connection
    return await self._loop.create_connection(*args, **kwargs)  # type: ignore  # noqa
  File "/usr/local/lib/python3.9/asyncio/base_events.py", line 1056, in create_connection
    raise exceptions[0]
  File "/usr/local/lib/python3.9/asyncio/base_events.py", line 1041, in create_connection
    sock = await self._connect_sock(
  File "/usr/local/lib/python3.9/asyncio/base_events.py", line 955, in _connect_sock
    await self.sock_connect(sock, address)
  File "/usr/local/lib/python3.9/asyncio/selector_events.py", line 502, in sock_connect
    return await fut
  File "/usr/local/lib/python3.9/asyncio/selector_events.py", line 537, in _sock_connect_cb
    raise OSError(err, f'Connect call failed {address}')
OSError: [Errno 113] Connect call failed ('169.254.155.60', 80)

The above exception was the direct cause of the following exception:

Traceback (most recent call last):
  File "/usr/src/homeassistant/homeassistant/helpers/entity_platform.py", line 249, in _async_setup_platform
    await asyncio.shield(task)
  File "/usr/src/homeassistant/homeassistant/components/netatmo/camera.py", line 58, in async_setup_entry
    await data_handler.register_data_class(
  File "/usr/src/homeassistant/homeassistant/components/netatmo/data_handler.py", line 187, in register_data_class
    await self.async_fetch_data(data_class_entry)
  File "/usr/src/homeassistant/homeassistant/components/netatmo/data_handler.py", line 144, in async_fetch_data
    await self.data[data_class_entry].async_update()
  File "/usr/local/lib/python3.9/site-packages/pyatmo/camera.py", line 652, in async_update
    await self._async_update_all_camera_urls()
  File "/usr/local/lib/python3.9/site-packages/pyatmo/camera.py", line 662, in _async_update_all_camera_urls
    await self.async_update_camera_urls(camera_id)
  File "/usr/local/lib/python3.9/site-packages/pyatmo/camera.py", line 728, in async_update_camera_urls
    ] = await self._async_check_url(
  File "/usr/local/lib/python3.9/site-packages/pyatmo/camera.py", line 735, in _async_check_url
    resp = await self.auth.async_post_request(url=f"{url}/command/ping")
  File "/usr/local/lib/python3.9/site-packages/pyatmo/auth.py", line 339, in async_post_request
    async with self.websession.post(
  File "/usr/local/lib/python3.9/site-packages/aiohttp/client.py", line 1117, in __aenter__
    self._resp = await self._coro
  File "/usr/local/lib/python3.9/site-packages/aiohttp/client.py", line 520, in _request
    conn = await self._connector.connect(
  File "/usr/local/lib/python3.9/site-packages/aiohttp/connector.py", line 535, in connect
    proto = await self._create_connection(req, traces, timeout)
  File "/usr/local/lib/python3.9/site-packages/aiohttp/connector.py", line 892, in _create_connection
    _, proto = await self._create_direct_connection(req, traces, timeout)
  File "/usr/local/lib/python3.9/site-packages/aiohttp/connector.py", line 1051, in _create_direct_connection
    raise last_exc
  File "/usr/local/lib/python3.9/site-packages/aiohttp/connector.py", line 1020, in _create_direct_connection
    transp, proto = await self._wrap_create_connection(
  File "/usr/local/lib/python3.9/site-packages/aiohttp/connector.py", line 975, in _wrap_create_connection
    raise client_error(req.connection_key, exc) from exc
aiohttp.client_exceptions.ClientConnectorError: Cannot connect to host 169.254.155.60:80 ssl:default [Connect call failed ('169.254.155.60', 80)]
2021-11-20 10:06:36 WARNING (MainThread) [homeassistant.components.fan] Setup of fan platform xiaomi_miio_fan is taking over 10 seconds.
2021-11-20 10:06:36 WARNING (MainThread) [homeassistant.components.fan] Setup of fan platform xiaomi_miio_fan is taking over 10 seconds.
2021-11-20 10:06:38 WARNING (MainThread) [homeassistant.components.binary_sensor] Updating ping binary_sensor took longer than the scheduled update interval 0:00:05
2021-11-20 10:06:38 ERROR (MainThread) [homeassistant.components.hue.light] Timeout fetching light data
2021-11-20 10:06:38 WARNING (MainThread) [homeassistant.helpers.entity] Update of binary_sensor.google_server is taking over 10 seconds
2021-11-20 10:06:38 ERROR (MainThread) [homeassistant.components.mobile_app.notify] Timeout sending notification to https://mobile-apps.home-assistant.io/api/sendPush/android/v1
2021-11-20 10:06:39 WARNING (MainThread) [homeassistant.components.media_player] Updating huesyncbox media_player took longer than the scheduled update interval 0:00:02
2021-11-20 10:06:42 ERROR (MainThread) [homeassistant.components.google_assistant.http] Request for https://homegraph.googleapis.com/v1/devices:requestSync failed: 500
2021-11-20 10:06:49 ERROR (SyncWorker_8) [homeassistant.components.influxdb] Cannot connect to InfluxDB due to '<urllib3.connection.HTTPConnection object at 0xffff7fef11f0>: Failed to establish a new connection: [Errno 111] Connection refused'. Please check that the provided connection details (host, port, etc.) are correct and that your InfluxDB server is running and accessible. Retrying in 60 seconds.
2021-11-20 10:06:52 ERROR (MainThread) [homeassistant.components.google_assistant.http] Request for https://homegraph.googleapis.com/v1/devices:reportStateAndNotification failed: 404
2021-11-20 10:07:11 WARNING (MainThread) [homeassistant.components.binary_sensor] Updating ping binary_sensor took longer than the scheduled update interval 0:00:05
2021-11-20 10:07:21 WARNING (MainThread) [homeassistant.components.binary_sensor] Updating ping binary_sensor took longer than the scheduled update interval 0:00:05
2021-11-20 10:07:31 WARNING (MainThread) [homeassistant.components.binary_sensor] Updating ping binary_sensor took longer than the scheduled update interval 0:00:05
2021-11-20 10:07:49 ERROR (SyncWorker_19) [homeassistant.components.influxdb] Cannot connect to InfluxDB due to '<urllib3.connection.HTTPConnection object at 0xffff7fe946a0>: Failed to establish a new connection: [Errno 111] Connection refused'. Please check that the provided connection details (host, port, etc.) are correct and that your InfluxDB server is running and accessible. Retrying in 60 seconds.
2021-11-20 10:08:49 ERROR (SyncWorker_7) [homeassistant.components.influxdb] Cannot connect to InfluxDB due to '<urllib3.connection.HTTPConnection object at 0xffff7ff832b0>: Failed to establish a new connection: [Errno 111] Connection refused'. Please check that the provided connection details (host, port, etc.) are correct and that your InfluxDB server is running and accessible. Retrying in 60 seconds.
2021-11-20 10:09:49 ERROR (SyncWorker_12) [homeassistant.components.influxdb] Cannot connect to InfluxDB due to '<urllib3.connection.HTTPConnection object at 0xffff94199be0>: Failed to establish a new connection: [Errno 111] Connection refused'. Please check that the provided connection details (host, port, etc.) are correct and that your InfluxDB server is running and accessible. Retrying in 60 seconds.
2021-11-20 10:10:49 ERROR (SyncWorker_8) [homeassistant.components.influxdb] Cannot connect to InfluxDB due to '<urllib3.connection.HTTPConnection object at 0xffff90631f70>: Failed to establish a new connection: [Errno 111] Connection refused'. Please check that the provided connection details (host, port, etc.) are correct and that your InfluxDB server is running and accessible. Retrying in 60 seconds.
2021-11-20 10:11:49 ERROR (SyncWorker_15) [homeassistant.components.influxdb] Cannot connect to InfluxDB due to '<urllib3.connection.HTTPConnection object at 0xffff912b8af0>: Failed to establish a new connection: [Errno 111] Connection refused'. Please check that the provided connection details (host, port, etc.) are correct and that your InfluxDB server is running and accessible. Retrying in 60 seconds.
2021-11-20 10:12:49 ERROR (SyncWorker_7) [homeassistant.components.influxdb] Cannot connect to InfluxDB due to '<urllib3.connection.HTTPConnection object at 0xffff90e39550>: Failed to establish a new connection: [Errno 111] Connection refused'. Please check that the provided connection details (host, port, etc.) are correct and that your InfluxDB server is running and accessible. Retrying in 60 seconds.
2021-11-20 10:13:00 ERROR (MainThread) [homeassistant.components.google_assistant.http] Request for https://homegraph.googleapis.com/v1/devices:reportStateAndNotification failed: 404
2021-11-20 10:13:00 ERROR (MainThread) [homeassistant.components.google_assistant.http] Request for https://homegraph.googleapis.com/v1/devices:reportStateAndNotification failed: 404
2021-11-20 10:13:00 ERROR (MainThread) [homeassistant.components.google_assistant.http] Request for https://homegraph.googleapis.com/v1/devices:reportStateAndNotification failed: 404
2021-11-20 10:13:01 ERROR (MainThread) [homeassistant.components.google_assistant.http] Request for https://homegraph.googleapis.com/v1/devices:reportStateAndNotification failed: 404
2021-11-20 10:13:33 ERROR (MainThread) [homeassistant.components.google_assistant.http] Request for https://homegraph.googleapis.com/v1/devices:reportStateAndNotification failed: 404
2021-11-20 10:13:49 ERROR (SyncWorker_19) [homeassistant.components.influxdb] Cannot connect to InfluxDB due to '<urllib3.connection.HTTPConnection object at 0xffff7f716c70>: Failed to establish a new connection: [Errno 111] Connection refused'. Please check that the provided connection details (host, port, etc.) are correct and that your InfluxDB server is running and accessible. Retrying in 60 seconds.
2021-11-20 10:14:02 ERROR (MainThread) [homeassistant.components.google_assistant.http] Request for https://homegraph.googleapis.com/v1/devices:reportStateAndNotification failed: 404
2021-11-20 10:14:03 ERROR (MainThread) [homeassistant.components.google_assistant.http] Request for https://homegraph.googleapis.com/v1/devices:reportStateAndNotification failed: 404
2021-11-20 10:14:49 ERROR (SyncWorker_4) [homeassistant.components.influxdb] Cannot connect to InfluxDB due to '<urllib3.connection.HTTPConnection object at 0xffff7c43a8b0>: Failed to establish a new connection: [Errno 111] Connection refused'. Please check that the provided connection details (host, port, etc.) are correct and that your InfluxDB server is running and accessible. Retrying in 60 seconds.
2021-11-20 10:15:46 ERROR (MainThread) [homeassistant.components.google_assistant.http] Request for https://homegraph.googleapis.com/v1/devices:reportStateAndNotification failed: 404
2021-11-20 10:15:49 ERROR (SyncWorker_13) [homeassistant.components.influxdb] Cannot connect to InfluxDB due to '<urllib3.connection.HTTPConnection object at 0xffff7c27df10>: Failed to establish a new connection: [Errno 111] Connection refused'. Please check that the provided connection details (host, port, etc.) are correct and that your InfluxDB server is running and accessible. Retrying in 60 seconds.
2021-11-20 10:15:56 WARNING (MainThread) [homeassistant.components.binary_sensor] Updating ping binary_sensor took longer than the scheduled update interval 0:00:05
2021-11-20 10:16:10 WARNING (MainThread) [haffmpeg.tools] Timeout reading image.
2021-11-20 10:16:14 ERROR (MainThread) [homeassistant.components.google_assistant.http] Request for https://homegraph.googleapis.com/v1/devices:reportStateAndNotification failed: 404
2021-11-20 10:16:49 ERROR (SyncWorker_7) [homeassistant.components.influxdb] Cannot connect to InfluxDB due to '<urllib3.connection.HTTPConnection object at 0xffff905eba30>: Failed to establish a new connection: [Errno 111] Connection refused'. Please check that the provided connection details (host, port, etc.) are correct and that your InfluxDB server is running and accessible. Retrying in 60 seconds.
2021-11-20 10:17:49 ERROR (SyncWorker_16) [homeassistant.components.influxdb] Cannot connect to InfluxDB due to '<urllib3.connection.HTTPConnection object at 0xffff90e30f40>: Failed to establish a new connection: [Errno 111] Connection refused'. Please check that the provided connection details (host, port, etc.) are correct and that your InfluxDB server is running and accessible. Retrying in 60 seconds.
2021-11-20 10:18:49 ERROR (SyncWorker_2) [homeassistant.components.influxdb] Cannot connect to InfluxDB due to '<urllib3.connection.HTTPConnection object at 0xffff943fbee0>: Failed to establish a new connection: [Errno 111] Connection refused'. Please check that the provided connection details (host, port, etc.) are correct and that your InfluxDB server is running and accessible. Retrying in 60 seconds.
2021-11-20 10:19:49 ERROR (SyncWorker_6) [homeassistant.components.influxdb] Cannot connect to InfluxDB due to '<urllib3.connection.HTTPConnection object at 0xffff7fe1ef10>: Failed to establish a new connection: [Errno 111] Connection refused'. Please check that the provided connection details (host, port, etc.) are correct and that your InfluxDB server is running and accessible. Retrying in 60 seconds.
2021-11-20 10:20:49 ERROR (SyncWorker_21) [homeassistant.components.influxdb] Cannot connect to InfluxDB due to '<urllib3.connection.HTTPConnection object at 0xffff7c4fa0d0>: Failed to establish a new connection: [Errno 111] Connection refused'. Please check that the provided connection details (host, port, etc.) are correct and that your InfluxDB server is running and accessible. Retrying in 60 seconds.
2021-11-20 10:21:49 ERROR (SyncWorker_10) [homeassistant.components.influxdb] Cannot connect to InfluxDB due to '<urllib3.connection.HTTPConnection object at 0xffff7c54caf0>: Failed to establish a new connection: [Errno 111] Connection refused'. Please check that the provided connection details (host, port, etc.) are correct and that your InfluxDB server is running and accessible. Retrying in 60 seconds.
2021-11-20 10:22:49 ERROR (SyncWorker_5) [homeassistant.components.influxdb] Cannot connect to InfluxDB due to '<urllib3.connection.HTTPConnection object at 0xffff90e76c40>: Failed to establish a new connection: [Errno 111] Connection refused'. Please check that the provided connection details (host, port, etc.) are correct and that your InfluxDB server is running and accessible. Retrying in 60 seconds.
2021-11-20 10:23:49 ERROR (SyncWorker_12) [homeassistant.components.influxdb] Cannot connect to InfluxDB due to '<urllib3.connection.HTTPConnection object at 0xffff7975d970>: Failed to establish a new connection: [Errno 111] Connection refused'. Please check that the provided connection details (host, port, etc.) are correct and that your InfluxDB server is running and accessible. Retrying in 60 seconds.
2021-11-20 10:24:49 ERROR (SyncWorker_12) [homeassistant.components.influxdb] Cannot connect to InfluxDB due to '<urllib3.connection.HTTPConnection object at 0xffff7feeb280>: Failed to establish a new connection: [Errno 111] Connection refused'. Please check that the provided connection details (host, port, etc.) are correct and that your InfluxDB server is running and accessible. Retrying in 60 seconds.
2021-11-20 10:25:49 ERROR (SyncWorker_1) [homeassistant.components.influxdb] Cannot connect to InfluxDB due to '<urllib3.connection.HTTPConnection object at 0xffff9623fc10>: Failed to establish a new connection: [Errno 111] Connection refused'. Please check that the provided connection details (host, port, etc.) are correct and that your InfluxDB server is running and accessible. Retrying in 60 seconds.
2021-11-20 10:26:49 ERROR (SyncWorker_10) [homeassistant.components.influxdb] Cannot connect to InfluxDB due to '<urllib3.connection.HTTPConnection object at 0xffff8fd8b910>: Failed to establish a new connection: [Errno 111] Connection refused'. Please check that the provided connection details (host, port, etc.) are correct and that your InfluxDB server is running and accessible. Retrying in 60 seconds.
2021-11-20 10:27:49 ERROR (SyncWorker_1) [homeassistant.components.influxdb] Cannot connect to InfluxDB due to '<urllib3.connection.HTTPConnection object at 0xffff7f62d4c0>: Failed to establish a new connection: [Errno 111] Connection refused'. Please check that the provided connection details (host, port, etc.) are correct and that your InfluxDB server is running and accessible. Retrying in 60 seconds.
2021-11-20 10:28:37 WARNING (MainThread) [homeassistant.components.binary_sensor] Updating ping binary_sensor took longer than the scheduled update interval 0:00:05
2021-11-20 10:28:49 ERROR (SyncWorker_14) [homeassistant.components.influxdb] Cannot connect to InfluxDB due to '<urllib3.connection.HTTPConnection object at 0xffff7b93fac0>: Failed to establish a new connection: [Errno 111] Connection refused'. Please check that the provided connection details (host, port, etc.) are correct and that your InfluxDB server is running and accessible. Retrying in 60 seconds.
2021-11-20 10:29:49 ERROR (SyncWorker_21) [homeassistant.components.influxdb] Cannot connect to InfluxDB due to '<urllib3.connection.HTTPConnection object at 0xffff8fd27df0>: Failed to establish a new connection: [Errno 111] Connection refused'. Please check that the provided connection details (host, port, etc.) are correct and that your InfluxDB server is running and accessible. Retrying in 60 seconds.
2021-11-20 10:30:49 ERROR (SyncWorker_8) [homeassistant.components.influxdb] Cannot connect to InfluxDB due to '<urllib3.connection.HTTPConnection object at 0xffff8fe2fd30>: Failed to establish a new connection: [Errno 111] Connection refused'. Please check that the provided connection details (host, port, etc.) are correct and that your InfluxDB server is running and accessible. Retrying in 60 seconds.
2021-11-20 10:31:49 ERROR (SyncWorker_15) [homeassistant.components.influxdb] Cannot connect to InfluxDB due to '<urllib3.connection.HTTPConnection object at 0xffff90e0f9d0>: Failed to establish a new connection: [Errno 111] Connection refused'. Please check that the provided connection details (host, port, etc.) are correct and that your InfluxDB server is running and accessible. Retrying in 60 seconds.
2021-11-20 10:32:49 ERROR (SyncWorker_14) [homeassistant.components.influxdb] Cannot connect to InfluxDB due to '<urllib3.connection.HTTPConnection object at 0xffff7c4a3ac0>: Failed to establish a new connection: [Errno 111] Connection refused'. Please check that the provided connection details (host, port, etc.) are correct and that your InfluxDB server is running and accessible. Retrying in 60 seconds.
2021-11-20 10:33:49 ERROR (SyncWorker_2) [homeassistant.components.influxdb] Cannot connect to InfluxDB due to '<urllib3.connection.HTTPConnection object at 0xffff7c338a60>: Failed to establish a new connection: [Errno 111] Connection refused'. Please check that the provided connection details (host, port, etc.) are correct and that your InfluxDB server is running and accessible. Retrying in 60 seconds.
2021-11-20 10:34:49 ERROR (SyncWorker_13) [homeassistant.components.influxdb] Cannot connect to InfluxDB due to '<urllib3.connection.HTTPConnection object at 0xffff947f69d0>: Failed to establish a new connection: [Errno 111] Connection refused'. Please check that the provided connection details (host, port, etc.) are correct and that your InfluxDB server is running and accessible. Retrying in 60 seconds.
2021-11-20 10:35:49 ERROR (SyncWorker_5) [homeassistant.components.influxdb] Cannot connect to InfluxDB due to '<urllib3.connection.HTTPConnection object at 0xffff7ff12310>: Failed to establish a new connection: [Errno 111] Connection refused'. Please check that the provided connection details (host, port, etc.) are correct and that your InfluxDB server is running and accessible. Retrying in 60 seconds.
2021-11-20 10:35:58 WARNING (MainThread) [homeassistant.components.binary_sensor] Updating ping binary_sensor took longer than the scheduled update interval 0:00:05
2021-11-20 10:36:49 ERROR (SyncWorker_21) [homeassistant.components.influxdb] Cannot connect to InfluxDB due to '<urllib3.connection.HTTPConnection object at 0xffff79780a30>: Failed to establish a new connection: [Errno 111] Connection refused'. Please check that the provided connection details (host, port, etc.) are correct and that your InfluxDB server is running and accessible. Retrying in 60 seconds.
2021-11-20 10:37:50 ERROR (SyncWorker_2) [homeassistant.components.influxdb] Cannot connect to InfluxDB due to '<urllib3.connection.HTTPConnection object at 0xffff8fdb2100>: Failed to establish a new connection: [Errno 111] Connection refused'. Please check that the provided connection details (host, port, etc.) are correct and that your InfluxDB server is running and accessible. Retrying in 60 seconds.
2021-11-20 10:38:23 WARNING (MainThread) [homeassistant.components.binary_sensor] Updating ping binary_sensor took longer than the scheduled update interval 0:00:05
2021-11-20 10:38:43 WARNING (MainThread) [homeassistant.components.binary_sensor] Updating ping binary_sensor took longer than the scheduled update interval 0:00:05
2021-11-20 10:38:50 ERROR (SyncWorker_0) [homeassistant.components.influxdb] Cannot connect to InfluxDB due to '<urllib3.connection.HTTPConnection object at 0xffff915094f0>: Failed to establish a new connection: [Errno 111] Connection refused'. Please check that the provided connection details (host, port, etc.) are correct and that your InfluxDB server is running and accessible. Retrying in 60 seconds.
2021-11-20 10:39:29 ERROR (MainThread) [homeassistant.components.google_assistant.http] Request for https://homegraph.googleapis.com/v1/devices:reportStateAndNotification failed: 404
2021-11-20 10:39:50 ERROR (SyncWorker_8) [homeassistant.components.influxdb] Cannot connect to InfluxDB due to '<urllib3.connection.HTTPConnection object at 0xffff8fdf4910>: Failed to establish a new connection: [Errno 111] Connection refused'. Please check that the provided connection details (host, port, etc.) are correct and that your InfluxDB server is running and accessible. Retrying in 60 seconds.
2021-11-20 10:40:43 WARNING (MainThread) [homeassistant.components.binary_sensor] Updating ping binary_sensor took longer than the scheduled update interval 0:00:05
2021-11-20 10:40:50 ERROR (SyncWorker_10) [homeassistant.components.influxdb] Cannot connect to InfluxDB due to '<urllib3.connection.HTTPConnection object at 0xffff7c314e50>: Failed to establish a new connection: [Errno 111] Connection refused'. Please check that the provided connection details (host, port, etc.) are correct and that your InfluxDB server is running and accessible. Retrying in 60 seconds.
2021-11-20 10:41:23 ERROR (MainThread) [homeassistant.helpers.entity] Update for sensor.veranda_speaker_aan_vandaag fails
Traceback (most recent call last):
  File "/usr/src/homeassistant/homeassistant/helpers/entity.py", line 468, in async_update_ha_state
    await self.async_device_update()
  File "/usr/src/homeassistant/homeassistant/helpers/entity.py", line 658, in async_device_update
    raise exc
  File "/usr/src/homeassistant/homeassistant/components/history_stats/sensor.py", line 221, in async_update
    await self.hass.async_add_executor_job(
  File "/usr/local/lib/python3.9/concurrent/futures/thread.py", line 52, in run
    result = self.fn(*self.args, **self.kwargs)
  File "/usr/src/homeassistant/homeassistant/components/history_stats/sensor.py", line 227, in _update
    history_list = history.state_changes_during_period(
  File "/usr/src/homeassistant/homeassistant/components/recorder/history.py", line 147, in state_changes_during_period
    with session_scope(hass=hass) as session:
  File "/usr/local/lib/python3.9/contextlib.py", line 119, in __enter__
    return next(self.gen)
  File "/usr/src/homeassistant/homeassistant/components/recorder/util.py", line 73, in session_scope
    session = hass.data[DATA_INSTANCE].get_session()
TypeError: 'NoneType' object is not callable
2021-11-20 10:41:23 ERROR (MainThread) [homeassistant.helpers.entity] Update for sensor.master_bedroom_tv_aan_vandaag fails
Traceback (most recent call last):
  File "/usr/src/homeassistant/homeassistant/helpers/entity.py", line 468, in async_update_ha_state
    await self.async_device_update()
  File "/usr/src/homeassistant/homeassistant/helpers/entity.py", line 658, in async_device_update
    raise exc
  File "/usr/src/homeassistant/homeassistant/components/history_stats/sensor.py", line 221, in async_update
    await self.hass.async_add_executor_job(
  File "/usr/local/lib/python3.9/concurrent/futures/thread.py", line 52, in run
    result = self.fn(*self.args, **self.kwargs)
  File "/usr/src/homeassistant/homeassistant/components/history_stats/sensor.py", line 227, in _update
    history_list = history.state_changes_during_period(
  File "/usr/src/homeassistant/homeassistant/components/recorder/history.py", line 147, in state_changes_during_period
    with session_scope(hass=hass) as session:
  File "/usr/local/lib/python3.9/contextlib.py", line 119, in __enter__
    return next(self.gen)
  File "/usr/src/homeassistant/homeassistant/components/recorder/util.py", line 73, in session_scope
    session = hass.data[DATA_INSTANCE].get_session()
TypeError: 'NoneType' object is not callable
