2021-10-09 14:34:23 WARNING (SyncWorker_0) [homeassistant.loader] We found a custom integration xiaomi_miio_airpurifier which has not been tested by Home Assistant. This component might cause stability problems, be sure to disable it if you experience issues with Home Assistant
2021-10-09 14:34:23 WARNING (SyncWorker_2) [homeassistant.loader] We found a custom integration average which has not been tested by Home Assistant. This component might cause stability problems, be sure to disable it if you experience issues with Home Assistant
2021-10-09 14:34:23 WARNING (SyncWorker_1) [homeassistant.loader] We found a custom integration powercalc which has not been tested by Home Assistant. This component might cause stability problems, be sure to disable it if you experience issues with Home Assistant
2021-10-09 14:34:23 WARNING (SyncWorker_3) [homeassistant.loader] We found a custom integration audiconnect which has not been tested by Home Assistant. This component might cause stability problems, be sure to disable it if you experience issues with Home Assistant
2021-10-09 14:34:23 WARNING (SyncWorker_4) [homeassistant.loader] We found a custom integration monitor_docker which has not been tested by Home Assistant. This component might cause stability problems, be sure to disable it if you experience issues with Home Assistant
2021-10-09 14:34:23 WARNING (SyncWorker_5) [homeassistant.loader] We found a custom integration hacs which has not been tested by Home Assistant. This component might cause stability problems, be sure to disable it if you experience issues with Home Assistant
2021-10-09 14:34:23 WARNING (SyncWorker_4) [homeassistant.loader] We found a custom integration shelly which has not been tested by Home Assistant. This component might cause stability problems, be sure to disable it if you experience issues with Home Assistant
2021-10-09 14:34:23 WARNING (SyncWorker_6) [homeassistant.loader] We found a custom integration localtuya which has not been tested by Home Assistant. This component might cause stability problems, be sure to disable it if you experience issues with Home Assistant
2021-10-09 14:34:23 WARNING (SyncWorker_7) [homeassistant.loader] We found a custom integration huesyncbox which has not been tested by Home Assistant. This component might cause stability problems, be sure to disable it if you experience issues with Home Assistant
2021-10-09 14:34:23 WARNING (SyncWorker_4) [homeassistant.loader] We found a custom integration thermal_comfort which has not been tested by Home Assistant. This component might cause stability problems, be sure to disable it if you experience issues with Home Assistant
2021-10-09 14:34:23 WARNING (SyncWorker_8) [homeassistant.loader] We found a custom integration buienalarm which has not been tested by Home Assistant. This component might cause stability problems, be sure to disable it if you experience issues with Home Assistant
2021-10-09 14:34:23 WARNING (SyncWorker_9) [homeassistant.loader] We found a custom integration anniversaries which has not been tested by Home Assistant. This component might cause stability problems, be sure to disable it if you experience issues with Home Assistant
2021-10-09 14:34:23 WARNING (SyncWorker_0) [homeassistant.loader] We found a custom integration googlewifi which has not been tested by Home Assistant. This component might cause stability problems, be sure to disable it if you experience issues with Home Assistant
2021-10-09 14:34:23 WARNING (SyncWorker_2) [homeassistant.loader] We found a custom integration ytube_music_player which has not been tested by Home Assistant. This component might cause stability problems, be sure to disable it if you experience issues with Home Assistant
2021-10-09 14:34:23 WARNING (SyncWorker_3) [homeassistant.loader] We found a custom integration xiaomi_miio_fan which has not been tested by Home Assistant. This component might cause stability problems, be sure to disable it if you experience issues with Home Assistant
2021-10-09 14:34:23 WARNING (SyncWorker_6) [homeassistant.loader] We found a custom integration deepstack_face which has not been tested by Home Assistant. This component might cause stability problems, be sure to disable it if you experience issues with Home Assistant
2021-10-09 14:34:23 WARNING (SyncWorker_10) [homeassistant.loader] We found a custom integration google_home which has not been tested by Home Assistant. This component might cause stability problems, be sure to disable it if you experience issues with Home Assistant
2021-10-09 14:34:23 WARNING (SyncWorker_5) [homeassistant.loader] We found a custom integration xiaomi_miot which has not been tested by Home Assistant. This component might cause stability problems, be sure to disable it if you experience issues with Home Assistant
2021-10-09 14:34:23 WARNING (SyncWorker_7) [homeassistant.loader] We found a custom integration afvalbeheer which has not been tested by Home Assistant. This component might cause stability problems, be sure to disable it if you experience issues with Home Assistant
2021-10-09 14:34:31 ERROR (MainThread) [homeassistant.config] Invalid config for [automation]: required key not provided @ data['action'][4]['domain']. Got None. (See ?, line ?). 
2021-10-09 14:34:31 ERROR (MainThread) [homeassistant.config] Invalid config for [automation]: [title] is an invalid option for [automation]. Check: automation->action->1->title. (See ?, line ?). 
2021-10-09 14:34:31 ERROR (MainThread) [homeassistant.config] Invalid config for [automation]: must be a value between 0 and 59 for dictionary value @ data['minutes']. Got None. (See ?, line ?). 
2021-10-09 14:34:31 ERROR (MainThread) [homeassistant.config] Invalid config for [automation]: must be a value between 0 and 59 for dictionary value @ data['minutes']. Got None. (See ?, line ?). 
2021-10-09 14:34:36 WARNING (MainThread) [homeassistant.components.fan] Platform xiaomi_miio_fan not ready yet: Unable to discover the device 192.168.86.29; Retrying in background in 30 seconds
2021-10-09 14:34:36 WARNING (MainThread) [homeassistant.components.fan] Platform xiaomi_miio_fan not ready yet: Unable to discover the device 192.168.86.28; Retrying in background in 30 seconds
2021-10-09 14:34:38 WARNING (MainThread) [homeassistant.setup] Setup of input_number is taking over 10 seconds.
2021-10-09 14:34:39 WARNING (MainThread) [homeassistant.config_entries] Config entry '192.168.86.83' for synology_dsm integration not ready yet: ConnectionError = <urllib3.connection.HTTPSConnection object at 0xffff8b2c4700>: Failed to establish a new connection: [Errno 113] Host is unreachable; Retrying in background
2021-10-09 14:34:40 WARNING (MainThread) [homeassistant.components.light] Platform netatmo not ready yet: None; Retrying in background in 30 seconds
2021-10-09 14:34:41 WARNING (MainThread) [homeassistant.components.select] Platform netatmo not ready yet: None; Retrying in background in 30 seconds
2021-10-09 14:34:41 WARNING (MainThread) [homeassistant.components.hue.light] Please check for software updates of the douche bulb in the Philips Hue App.
2021-10-09 14:34:41 WARNING (MainThread) [homeassistant.components.hue.light] Please check for software updates of the wasbak rechts bulb in the Philips Hue App.
2021-10-09 14:34:41 WARNING (MainThread) [homeassistant.components.hue.light] Please check for software updates of the bad bulb in the Philips Hue App.
2021-10-09 14:34:41 WARNING (MainThread) [homeassistant.components.hue.light] Please check for software updates of the Amilya plafond 2 bulb in the Philips Hue App.
2021-10-09 14:34:41 WARNING (MainThread) [homeassistant.components.hue.light] Please check for software updates of the Amilya plafond 1 bulb in the Philips Hue App.
2021-10-09 14:34:42 WARNING (MainThread) [homeassistant.components.sensor] Platform netatmo not ready yet: None; Retrying in background in 30 seconds
2021-10-09 14:34:44 ERROR (MainThread) [homeassistant.components.sensor] scrape: Error on device update!
Traceback (most recent call last):
  File "/usr/src/homeassistant/homeassistant/helpers/entity_platform.py", line 431, in _async_add_entity
    await entity.async_device_update(warning=False)
  File "/usr/src/homeassistant/homeassistant/helpers/entity.py", line 618, in async_device_update
    await task
  File "/usr/src/homeassistant/homeassistant/components/scrape/sensor.py", line 139, in async_update
    await self._async_update_from_rest_data()
  File "/usr/src/homeassistant/homeassistant/components/scrape/sensor.py", line 152, in _async_update_from_rest_data
    value = await self.hass.async_add_executor_job(self._extract_value)
  File "/usr/local/lib/python3.9/concurrent/futures/thread.py", line 52, in run
    result = self.fn(*self.args, **self.kwargs)
  File "/usr/src/homeassistant/homeassistant/components/scrape/sensor.py", line 128, in _extract_value
    tag = raw_data.select(self._select)[self._index]
  File "/usr/local/lib/python3.9/site-packages/bs4/element.py", line 1949, in select
    results = soupsieve.select(selector, self, namespaces, limit, **kwargs)
  File "/usr/local/lib/python3.9/site-packages/soupsieve/__init__.py", line 98, in select
    return compile(select, namespaces, flags, **kwargs).select(tag, limit)
  File "/usr/local/lib/python3.9/site-packages/soupsieve/__init__.py", line 62, in compile
    return cp._cached_css_compile(pattern, namespaces, custom, flags)
  File "/usr/local/lib/python3.9/site-packages/soupsieve/css_parser.py", line 211, in _cached_css_compile
    CSSParser(pattern, custom=custom_selectors, flags=flags).process_selectors(),
  File "/usr/local/lib/python3.9/site-packages/soupsieve/css_parser.py", line 1058, in process_selectors
    return self.parse_selectors(self.selector_iter(self.pattern), index, flags)
  File "/usr/local/lib/python3.9/site-packages/soupsieve/css_parser.py", line 909, in parse_selectors
    key, m = next(iselector)
  File "/usr/local/lib/python3.9/site-packages/soupsieve/css_parser.py", line 1051, in selector_iter
    raise SelectorSyntaxError(msg, self.pattern, index)
soupsieve.util.SelectorSyntaxError: Invalid character '<' position 0
  line 1:
<span _ngcontent-app-root-c173="">Offline</span>
^
2021-10-09 14:34:48 ERROR (MainThread) [homeassistant.components.camera] Error while setting up netatmo platform for camera
Traceback (most recent call last):
  File "/usr/local/lib/python3.9/site-packages/aiohttp/connector.py", line 969, in _wrap_create_connection
    return await self._loop.create_connection(*args, **kwargs)  # type: ignore  # noqa
  File "/usr/local/lib/python3.9/asyncio/base_events.py", line 1056, in create_connection
    raise exceptions[0]
  File "/usr/local/lib/python3.9/asyncio/base_events.py", line 1041, in create_connection
    sock = await self._connect_sock(
  File "/usr/local/lib/python3.9/asyncio/base_events.py", line 955, in _connect_sock
    await self.sock_connect(sock, address)
  File "/usr/local/lib/python3.9/asyncio/selector_events.py", line 502, in sock_connect
    return await fut
  File "/usr/local/lib/python3.9/asyncio/selector_events.py", line 537, in _sock_connect_cb
    raise OSError(err, f'Connect call failed {address}')
OSError: [Errno 113] Connect call failed ('169.254.113.236', 80)

The above exception was the direct cause of the following exception:

Traceback (most recent call last):
  File "/usr/src/homeassistant/homeassistant/helpers/entity_platform.py", line 249, in _async_setup_platform
    await asyncio.shield(task)
  File "/usr/src/homeassistant/homeassistant/components/netatmo/camera.py", line 57, in async_setup_entry
    await data_handler.register_data_class(
  File "/usr/src/homeassistant/homeassistant/components/netatmo/data_handler.py", line 192, in register_data_class
    await self.async_fetch_data(data_class_entry)
  File "/usr/src/homeassistant/homeassistant/components/netatmo/data_handler.py", line 149, in async_fetch_data
    await self.data[data_class_entry].async_update()
  File "/usr/local/lib/python3.9/site-packages/pyatmo/camera.py", line 652, in async_update
    await self._async_update_all_camera_urls()
  File "/usr/local/lib/python3.9/site-packages/pyatmo/camera.py", line 662, in _async_update_all_camera_urls
    await self.async_update_camera_urls(camera_id)
  File "/usr/local/lib/python3.9/site-packages/pyatmo/camera.py", line 728, in async_update_camera_urls
    ] = await self._async_check_url(
  File "/usr/local/lib/python3.9/site-packages/pyatmo/camera.py", line 735, in _async_check_url
    resp = await self.auth.async_post_request(url=f"{url}/command/ping")
  File "/usr/local/lib/python3.9/site-packages/pyatmo/auth.py", line 339, in async_post_request
    async with self.websession.post(
  File "/usr/local/lib/python3.9/site-packages/aiohttp/client.py", line 1117, in __aenter__
    self._resp = await self._coro
  File "/usr/local/lib/python3.9/site-packages/aiohttp/client.py", line 520, in _request
    conn = await self._connector.connect(
  File "/usr/local/lib/python3.9/site-packages/aiohttp/connector.py", line 535, in connect
    proto = await self._create_connection(req, traces, timeout)
  File "/usr/local/lib/python3.9/site-packages/aiohttp/connector.py", line 892, in _create_connection
    _, proto = await self._create_direct_connection(req, traces, timeout)
  File "/usr/local/lib/python3.9/site-packages/aiohttp/connector.py", line 1051, in _create_direct_connection
    raise last_exc
  File "/usr/local/lib/python3.9/site-packages/aiohttp/connector.py", line 1020, in _create_direct_connection
    transp, proto = await self._wrap_create_connection(
  File "/usr/local/lib/python3.9/site-packages/aiohttp/connector.py", line 975, in _wrap_create_connection
    raise client_error(req.connection_key, exc) from exc
aiohttp.client_exceptions.ClientConnectorError: Cannot connect to host 169.254.113.236:80 ssl:default [Connect call failed ('169.254.113.236', 80)]
2021-10-09 14:34:48 ERROR (SyncWorker_0) [glocaltokens.client] [Device - Nest Wifi router(id=2f2a9d15-0ae2-4ffe-b6c1-2ef24c742b8a)] local_auth_token must follow the correct format
2021-10-09 14:34:48 ERROR (SyncWorker_0) [glocaltokens.client] [Device - Nest Wifi router(id=e1e5a8d5-d21f-444d-95a9-c76d78c9bc79)] local_auth_token must follow the correct format
2021-10-09 14:34:48 ERROR (SyncWorker_0) [glocaltokens.client] [Device - Nest Wifi router(id=ea3de37c-ca74-4689-8171-1681b2f4f924)] local_auth_token must follow the correct format
2021-10-09 14:34:48 WARNING (MainThread) [homeassistant.config_entries] Config entry 'OnHub' for upnp integration not ready yet; Retrying in background
2021-10-09 14:34:57 WARNING (MainThread) [homeassistant.helpers.template] Template warning: 'float' got invalid input 'unknown' when rendering template '{{ states('sensor.tv_living_on_today') | float * 0.085 | round(3) }}' but no default was specified. Currently 'float' will return '0', however this template will fail to render in Home Assistant core 2021.12
2021-10-09 14:34:57 WARNING (MainThread) [homeassistant.helpers.template] Template warning: 'float' got invalid input 'unknown' when rendering template '{{ states('sensor.tv_living_on_today') | float * 0.085 | round(3) }}' but no default was specified. Currently 'float' will return '0', however this template will fail to render in Home Assistant core 2021.12
2021-10-09 14:34:57 WARNING (MainThread) [homeassistant.helpers.template] Template warning: 'float' got invalid input 'unknown' when rendering template '{{ states('sensor.master_bedroom_TV_on_today') | float * 0.063 | round(3) }}' but no default was specified. Currently 'float' will return '0', however this template will fail to render in Home Assistant core 2021.12
2021-10-09 14:34:57 WARNING (MainThread) [homeassistant.helpers.template] Template warning: 'float' got invalid input 'unknown' when rendering template '{{ states('sensor.master_bedroom_TV_on_today') | float * 0.063 | round(3) }}' but no default was specified. Currently 'float' will return '0', however this template will fail to render in Home Assistant core 2021.12
2021-10-09 14:35:00 WARNING (MainThread) [homeassistant.components.media_player] Updating huesyncbox media_player took longer than the scheduled update interval 0:00:02
2021-10-09 14:35:01 WARNING (MainThread) [homeassistant.components.automation] Error evaluating condition in '💨 Air Quality Index < 8 = purifier off':
In 'condition':
  In 'numeric_state':
    In 'numeric_state' condition: attribute 'aqi' (of entity fan.xiaomi_air_purifier_3h) does not exist
2021-10-09 14:35:01 WARNING (MainThread) [homeassistant.components.automation] Error evaluating condition in '💨 Air Quality Index > 8 = purifier on':
In 'condition' (item 1 of 3):
  In 'numeric_state':
    In 'numeric_state' condition: attribute 'aqi' (of entity fan.xiaomi_air_purifier_3h) does not exist
2021-10-09 14:35:06 ERROR (MainThread) [homeassistant.components.hue.sensor_base] Timeout fetching sensor data
2021-10-09 14:35:06 ERROR (MainThread) [homeassistant] Error doing job: Task exception was never retrieved
Traceback (most recent call last):
  File "/usr/src/homeassistant/homeassistant/components/netatmo/__init__.py", line 198, in register_webhook
    await hass.data[DOMAIN][entry.entry_id][AUTH].async_addwebhook(webhook_url)
  File "/usr/local/lib/python3.9/site-packages/pyatmo/auth.py", line 381, in async_addwebhook
    resp = await self.async_post_request(WEBHOOK_URL_ADD, {"url": webhook_url})
  File "/usr/local/lib/python3.9/site-packages/pyatmo/auth.py", line 339, in async_post_request
    async with self.websession.post(
  File "/usr/local/lib/python3.9/site-packages/aiohttp/client.py", line 1117, in __aenter__
    self._resp = await self._coro
  File "/usr/local/lib/python3.9/site-packages/aiohttp/client.py", line 544, in _request
    await resp.start(conn)
  File "/usr/local/lib/python3.9/site-packages/aiohttp/client_reqrep.py", line 905, in start
    self._continue = None
  File "/usr/local/lib/python3.9/site-packages/aiohttp/helpers.py", line 656, in __exit__
    raise asyncio.TimeoutError from None
asyncio.exceptions.TimeoutError
2021-10-09 14:35:13 ERROR (MainThread) [homeassistant.components.mobile_app.notify] Timeout sending notification to https://mobile-apps.home-assistant.io/api/sendPush/android/v1
2021-10-09 14:35:14 ERROR (MainThread) [homeassistant.components.google_assistant.http] Request for https://homegraph.googleapis.com/v1/devices:requestSync failed: 500
2021-10-09 14:35:32 ERROR (MainThread) [homeassistant.components.google_assistant.http] Request for https://homegraph.googleapis.com/v1/devices:reportStateAndNotification failed: 404
2021-10-09 14:39:44 WARNING (MainThread) [homeassistant.helpers.template] Template warning: 'float' got invalid input 'unknown' when rendering template '{{ states('sensor.gram_badkamer_diff_outside') | float >= 1 }}' but no default was specified. Currently 'float' will return '0', however this template will fail to render in Home Assistant core 2021.12
2021-10-09 14:40:00 WARNING (MainThread) [homeassistant.components.automation] Error evaluating condition in '💨 Air Quality Index > 8 = purifier on':
In 'condition' (item 1 of 3):
  In 'numeric_state':
    In 'numeric_state' condition: attribute 'aqi' (of entity fan.xiaomi_air_purifier_3h) does not exist
2021-10-09 14:40:00 WARNING (MainThread) [homeassistant.components.automation] Error evaluating condition in '💨 Air Quality Index < 8 = purifier off':
In 'condition':
  In 'numeric_state':
    In 'numeric_state' condition: attribute 'aqi' (of entity fan.xiaomi_air_purifier_3h) does not exist
2021-10-09 14:44:17 ERROR (MainThread) [custom_components.xiaomi_miio_airpurifier.fan] Got exception while fetching the state: Unable to discover the device 192.168.86.250 , _retry=20
2021-10-09 14:44:47 ERROR (MainThread) [custom_components.xiaomi_miio_airpurifier.fan] Got exception while fetching the state: Unable to discover the device 192.168.86.250 , _retry=21
2021-10-09 14:45:00 WARNING (MainThread) [homeassistant.components.automation] Error evaluating condition in '💨 Air Quality Index < 8 = purifier off':
In 'condition':
  In 'numeric_state':
    In 'numeric_state' condition: attribute 'aqi' (of entity fan.xiaomi_air_purifier_3h) does not exist
2021-10-09 14:45:00 WARNING (MainThread) [homeassistant.components.automation] Error evaluating condition in '💨 Air Quality Index > 8 = purifier on':
In 'condition' (item 1 of 3):
  In 'numeric_state':
    In 'numeric_state' condition: attribute 'aqi' (of entity fan.xiaomi_air_purifier_3h) does not exist
2021-10-09 14:45:17 ERROR (MainThread) [custom_components.xiaomi_miio_airpurifier.fan] Got exception while fetching the state: Unable to discover the device 192.168.86.250 , _retry=22
2021-10-09 14:45:47 ERROR (MainThread) [custom_components.xiaomi_miio_airpurifier.fan] Got exception while fetching the state: Unable to discover the device 192.168.86.250 , _retry=23
2021-10-09 14:46:17 ERROR (MainThread) [custom_components.xiaomi_miio_airpurifier.fan] Got exception while fetching the state: Unable to discover the device 192.168.86.250 , _retry=24
2021-10-09 14:46:46 WARNING (MainThread) [homeassistant.helpers.template] Template warning: 'float' got invalid input 'unknown' when rendering template '{{ states('sensor.gram_berging_diff_outside') | float >= 1 }}' but no default was specified. Currently 'float' will return '0', however this template will fail to render in Home Assistant core 2021.12
2021-10-09 14:46:46 WARNING (MainThread) [homeassistant.helpers.template] Template warning: 'float' got invalid input 'unknown' when rendering template '{{ states('sensor.gram_badkamer_diff_outside') | float >= 1 }}' but no default was specified. Currently 'float' will return '0', however this template will fail to render in Home Assistant core 2021.12
2021-10-09 14:46:46 WARNING (MainThread) [homeassistant.helpers.template] Template warning: 'float' got invalid input 'unknown' when rendering template '{{ states('sensor.gram_gang_diff_outside') | float >= 1 }}' but no default was specified. Currently 'float' will return '0', however this template will fail to render in Home Assistant core 2021.12
2021-10-09 14:46:46 WARNING (MainThread) [homeassistant.helpers.template] Template warning: 'float' got invalid input 'unknown' when rendering template '{{ states('sensor.gram_kamer_alunya_diff_outside') | float >= 1 }}' but no default was specified. Currently 'float' will return '0', however this template will fail to render in Home Assistant core 2021.12
2021-10-09 14:46:46 WARNING (MainThread) [homeassistant.helpers.template] Template warning: 'float' got invalid input 'unknown' when rendering template '{{ states('sensor.gram_veranda_diff_outside') | float >= 1 }}' but no default was specified. Currently 'float' will return '0', however this template will fail to render in Home Assistant core 2021.12
2021-10-09 14:46:47 ERROR (MainThread) [custom_components.xiaomi_miio_airpurifier.fan] Got exception while fetching the state: Unable to discover the device 192.168.86.250 , _retry=25
2021-10-09 14:47:17 ERROR (MainThread) [custom_components.xiaomi_miio_airpurifier.fan] Got exception while fetching the state: Unable to discover the device 192.168.86.250 , _retry=26
2021-10-09 14:47:47 ERROR (MainThread) [custom_components.xiaomi_miio_airpurifier.fan] Got exception while fetching the state: Unable to discover the device 192.168.86.250 , _retry=27
2021-10-09 14:48:03 ERROR (MainThread) [custom_components.googlewifi] Error fetching GoogleWifi data: Error connecting to GoogleWifi: 
2021-10-09 14:48:17 ERROR (MainThread) [custom_components.xiaomi_miio_airpurifier.fan] Got exception while fetching the state: Unable to discover the device 192.168.86.250 , _retry=28
2021-10-09 14:48:47 ERROR (MainThread) [custom_components.xiaomi_miio_airpurifier.fan] Got exception while fetching the state: Unable to discover the device 192.168.86.250 , _retry=29
2021-10-09 14:49:17 ERROR (MainThread) [custom_components.xiaomi_miio_airpurifier.fan] Got exception while fetching the state: Unable to discover the device 192.168.86.250 , _retry=30
2021-10-09 14:49:47 ERROR (MainThread) [custom_components.xiaomi_miio_airpurifier.fan] Got exception while fetching the state: Unable to discover the device 192.168.86.250 , _retry=31
2021-10-09 14:50:00 WARNING (MainThread) [homeassistant.components.automation] Error evaluating condition in '💨 Air Quality Index < 8 = purifier off':
In 'condition':
  In 'numeric_state':
    In 'numeric_state' condition: attribute 'aqi' (of entity fan.xiaomi_air_purifier_3h) does not exist
2021-10-09 14:50:00 WARNING (MainThread) [homeassistant.components.automation] Error evaluating condition in '💨 Air Quality Index > 8 = purifier on':
In 'condition' (item 1 of 3):
  In 'numeric_state':
    In 'numeric_state' condition: attribute 'aqi' (of entity fan.xiaomi_air_purifier_3h) does not exist
2021-10-09 14:50:17 ERROR (MainThread) [custom_components.xiaomi_miio_airpurifier.fan] Got exception while fetching the state: Unable to discover the device 192.168.86.250 , _retry=32
2021-10-09 14:50:47 ERROR (MainThread) [custom_components.xiaomi_miio_airpurifier.fan] Got exception while fetching the state: Unable to discover the device 192.168.86.250 , _retry=33
2021-10-09 14:51:17 ERROR (MainThread) [custom_components.xiaomi_miio_airpurifier.fan] Got exception while fetching the state: Unable to discover the device 192.168.86.250 , _retry=34
2021-10-09 14:51:47 ERROR (MainThread) [custom_components.xiaomi_miio_airpurifier.fan] Got exception while fetching the state: Unable to discover the device 192.168.86.250 , _retry=35
2021-10-09 14:52:17 ERROR (MainThread) [custom_components.xiaomi_miio_airpurifier.fan] Got exception while fetching the state: Unable to discover the device 192.168.86.250 , _retry=36
2021-10-09 14:52:47 ERROR (MainThread) [custom_components.xiaomi_miio_airpurifier.fan] Got exception while fetching the state: Unable to discover the device 192.168.86.250 , _retry=37
2021-10-09 14:53:05 ERROR (MainThread) [custom_components.googlewifi] Error fetching GoogleWifi data: Error connecting to GoogleWifi: 
2021-10-09 14:53:18 ERROR (MainThread) [custom_components.xiaomi_miio_airpurifier.fan] Got exception while fetching the state: Unable to discover the device 192.168.86.250 , _retry=38
2021-10-09 14:53:47 ERROR (MainThread) [custom_components.xiaomi_miio_airpurifier.fan] Got exception while fetching the state: Unable to discover the device 192.168.86.250 , _retry=39
2021-10-09 14:54:17 ERROR (MainThread) [custom_components.xiaomi_miio_airpurifier.fan] Got exception while fetching the state: Unable to discover the device 192.168.86.250 , _retry=40
2021-10-09 14:54:47 ERROR (MainThread) [custom_components.xiaomi_miio_airpurifier.fan] Got exception while fetching the state: Unable to discover the device 192.168.86.250 , _retry=41
2021-10-09 14:55:00 WARNING (MainThread) [homeassistant.components.automation] Error evaluating condition in '💨 Air Quality Index > 8 = purifier on':
In 'condition' (item 1 of 3):
  In 'numeric_state':
    In 'numeric_state' condition: attribute 'aqi' (of entity fan.xiaomi_air_purifier_3h) does not exist
2021-10-09 14:55:00 WARNING (MainThread) [homeassistant.components.automation] Error evaluating condition in '💨 Air Quality Index < 8 = purifier off':
In 'condition':
  In 'numeric_state':
    In 'numeric_state' condition: attribute 'aqi' (of entity fan.xiaomi_air_purifier_3h) does not exist
2021-10-09 14:55:17 ERROR (MainThread) [custom_components.xiaomi_miio_airpurifier.fan] Got exception while fetching the state: Unable to discover the device 192.168.86.250 , _retry=42
2021-10-09 14:55:47 ERROR (MainThread) [custom_components.xiaomi_miio_airpurifier.fan] Got exception while fetching the state: Unable to discover the device 192.168.86.250 , _retry=43
2021-10-09 14:56:17 ERROR (MainThread) [custom_components.xiaomi_miio_airpurifier.fan] Got exception while fetching the state: Unable to discover the device 192.168.86.250 , _retry=44
2021-10-09 14:56:47 ERROR (MainThread) [custom_components.xiaomi_miio_airpurifier.fan] Got exception while fetching the state: Unable to discover the device 192.168.86.250 , _retry=45
2021-10-09 14:57:17 ERROR (MainThread) [custom_components.xiaomi_miio_airpurifier.fan] Got exception while fetching the state: Unable to discover the device 192.168.86.250 , _retry=46
2021-10-09 14:57:47 ERROR (MainThread) [custom_components.xiaomi_miio_airpurifier.fan] Got exception while fetching the state: Unable to discover the device 192.168.86.250 , _retry=47
2021-10-09 14:58:17 ERROR (MainThread) [custom_components.xiaomi_miio_airpurifier.fan] Got exception while fetching the state: Unable to discover the device 192.168.86.250 , _retry=48
2021-10-09 14:58:46 WARNING (MainThread) [homeassistant.helpers.template] Template warning: 'float' got invalid input 'unknown' when rendering template '{{ states('sensor.gram_berging_diff_outside') | float >= 1 }}' but no default was specified. Currently 'float' will return '0', however this template will fail to render in Home Assistant core 2021.12
2021-10-09 14:58:46 WARNING (MainThread) [homeassistant.helpers.template] Template warning: 'float' got invalid input 'unknown' when rendering template '{{ states('sensor.gram_badkamer_diff_outside') | float >= 1 }}' but no default was specified. Currently 'float' will return '0', however this template will fail to render in Home Assistant core 2021.12
2021-10-09 14:58:46 WARNING (MainThread) [homeassistant.helpers.template] Template warning: 'float' got invalid input 'unknown' when rendering template '{{ states('sensor.gram_gang_diff_outside') | float >= 1 }}' but no default was specified. Currently 'float' will return '0', however this template will fail to render in Home Assistant core 2021.12
2021-10-09 14:58:46 WARNING (MainThread) [homeassistant.helpers.template] Template warning: 'float' got invalid input 'unknown' when rendering template '{{ states('sensor.gram_kamer_alunya_diff_outside') | float >= 1 }}' but no default was specified. Currently 'float' will return '0', however this template will fail to render in Home Assistant core 2021.12
2021-10-09 14:58:46 WARNING (MainThread) [homeassistant.helpers.template] Template warning: 'float' got invalid input 'unknown' when rendering template '{{ states('sensor.gram_berging_diff_outside') | float >= 1 }}' but no default was specified. Currently 'float' will return '0', however this template will fail to render in Home Assistant core 2021.12
2021-10-09 14:58:46 WARNING (MainThread) [homeassistant.helpers.template] Template warning: 'float' got invalid input 'unknown' when rendering template '{{ states('sensor.gram_badkamer_diff_outside') | float >= 1 }}' but no default was specified. Currently 'float' will return '0', however this template will fail to render in Home Assistant core 2021.12
2021-10-09 14:58:46 WARNING (MainThread) [homeassistant.helpers.template] Template warning: 'float' got invalid input 'unknown' when rendering template '{{ states('sensor.gram_gang_diff_outside') | float >= 1 }}' but no default was specified. Currently 'float' will return '0', however this template will fail to render in Home Assistant core 2021.12
2021-10-09 14:58:46 WARNING (MainThread) [homeassistant.helpers.template] Template warning: 'float' got invalid input 'unknown' when rendering template '{{ states('sensor.gram_kamer_alunya_diff_outside') | float >= 1 }}' but no default was specified. Currently 'float' will return '0', however this template will fail to render in Home Assistant core 2021.12
2021-10-09 14:58:47 ERROR (MainThread) [custom_components.xiaomi_miio_airpurifier.fan] Got exception while fetching the state: Unable to discover the device 192.168.86.250 , _retry=49
2021-10-09 14:59:17 ERROR (MainThread) [custom_components.xiaomi_miio_airpurifier.fan] Got exception while fetching the state: Unable to discover the device 192.168.86.250 , _retry=50
2021-10-09 14:59:47 ERROR (MainThread) [custom_components.xiaomi_miio_airpurifier.fan] Got exception while fetching the state: Unable to discover the device 192.168.86.250 , _retry=51
2021-10-09 15:00:00 WARNING (MainThread) [homeassistant.components.automation] Error evaluating condition in '💨 Air Quality Index < 8 = purifier off':
In 'condition':
  In 'numeric_state':
    In 'numeric_state' condition: attribute 'aqi' (of entity fan.xiaomi_air_purifier_3h) does not exist
2021-10-09 15:00:00 WARNING (MainThread) [homeassistant.components.automation] Error evaluating condition in '💨 Air Quality Index > 8 = purifier on':
In 'condition' (item 1 of 3):
  In 'numeric_state':
    In 'numeric_state' condition: attribute 'aqi' (of entity fan.xiaomi_air_purifier_3h) does not exist
2021-10-09 15:00:17 ERROR (MainThread) [custom_components.xiaomi_miio_airpurifier.fan] Got exception while fetching the state: Unable to discover the device 192.168.86.250 , _retry=52
2021-10-09 15:00:47 ERROR (MainThread) [custom_components.xiaomi_miio_airpurifier.fan] Got exception while fetching the state: Unable to discover the device 192.168.86.250 , _retry=53
2021-10-09 15:01:17 ERROR (MainThread) [custom_components.xiaomi_miio_airpurifier.fan] Got exception while fetching the state: Unable to discover the device 192.168.86.250 , _retry=54
2021-10-09 15:01:47 ERROR (MainThread) [custom_components.xiaomi_miio_airpurifier.fan] Got exception while fetching the state: Unable to discover the device 192.168.86.250 , _retry=55
2021-10-09 15:02:17 ERROR (MainThread) [custom_components.xiaomi_miio_airpurifier.fan] Got exception while fetching the state: Unable to discover the device 192.168.86.250 , _retry=56
2021-10-09 15:02:47 ERROR (MainThread) [custom_components.xiaomi_miio_airpurifier.fan] Got exception while fetching the state: Unable to discover the device 192.168.86.250 , _retry=57
2021-10-09 15:03:17 ERROR (MainThread) [custom_components.xiaomi_miio_airpurifier.fan] Got exception while fetching the state: Unable to discover the device 192.168.86.250 , _retry=58
2021-10-09 15:03:47 ERROR (MainThread) [custom_components.xiaomi_miio_airpurifier.fan] Got exception while fetching the state: Unable to discover the device 192.168.86.250 , _retry=59
2021-10-09 15:04:17 ERROR (MainThread) [custom_components.xiaomi_miio_airpurifier.fan] Got exception while fetching the state: Unable to discover the device 192.168.86.250 , _retry=60
2021-10-09 15:04:47 ERROR (MainThread) [custom_components.xiaomi_miio_airpurifier.fan] Got exception while fetching the state: Unable to discover the device 192.168.86.250 , _retry=61
2021-10-09 15:05:00 WARNING (MainThread) [homeassistant.components.automation] Error evaluating condition in '💨 Air Quality Index > 8 = purifier on':
In 'condition' (item 1 of 3):
  In 'numeric_state':
    In 'numeric_state' condition: attribute 'aqi' (of entity fan.xiaomi_air_purifier_3h) does not exist
2021-10-09 15:05:00 WARNING (MainThread) [homeassistant.components.automation] Error evaluating condition in '💨 Air Quality Index < 8 = purifier off':
In 'condition':
  In 'numeric_state':
    In 'numeric_state' condition: attribute 'aqi' (of entity fan.xiaomi_air_purifier_3h) does not exist
2021-10-09 15:05:17 ERROR (MainThread) [custom_components.xiaomi_miio_airpurifier.fan] Got exception while fetching the state: Unable to discover the device 192.168.86.250 , _retry=62
2021-10-09 15:05:35 ERROR (MainThread) [homeassistant.config] Invalid config for [automation]: required key not provided @ data['action'][4]['domain']. Got None. (See ?, line ?). 
2021-10-09 15:05:35 ERROR (MainThread) [homeassistant.config] Invalid config for [automation]: [title] is an invalid option for [automation]. Check: automation->action->1->title. (See ?, line ?). 
2021-10-09 15:05:35 ERROR (MainThread) [homeassistant.config] Invalid config for [automation]: must be a value between 0 and 59 for dictionary value @ data['minutes']. Got None. (See ?, line ?). 
2021-10-09 15:05:35 ERROR (MainThread) [homeassistant.config] Invalid config for [automation]: must be a value between 0 and 59 for dictionary value @ data['minutes']. Got None. (See ?, line ?). 
2021-10-09 15:05:48 ERROR (MainThread) [custom_components.xiaomi_miio_airpurifier.fan] Got exception while fetching the state: Unable to discover the device 192.168.86.250 , _retry=63
2021-10-09 15:06:18 ERROR (MainThread) [custom_components.xiaomi_miio_airpurifier.fan] Got exception while fetching the state: Unable to discover the device 192.168.86.250 , _retry=64
2021-10-09 15:06:48 ERROR (MainThread) [custom_components.xiaomi_miio_airpurifier.fan] Got exception while fetching the state: Unable to discover the device 192.168.86.250 , _retry=65
2021-10-09 15:06:50 ERROR (MainThread) [homeassistant.config] Invalid config for [automation]: required key not provided @ data['action'][4]['domain']. Got None. (See ?, line ?). 
2021-10-09 15:06:50 ERROR (MainThread) [homeassistant.config] Invalid config for [automation]: [title] is an invalid option for [automation]. Check: automation->action->1->title. (See ?, line ?). 
2021-10-09 15:06:50 ERROR (MainThread) [homeassistant.config] Invalid config for [automation]: must be a value between 0 and 59 for dictionary value @ data['minutes']. Got None. (See ?, line ?). 
2021-10-09 15:06:50 ERROR (MainThread) [homeassistant.config] Invalid config for [automation]: must be a value between 0 and 59 for dictionary value @ data['minutes']. Got None. (See ?, line ?). 
2021-10-09 15:06:56 ERROR (MainThread) [homeassistant.config] Invalid config for [automation]: required key not provided @ data['action'][4]['domain']. Got None. (See ?, line ?). 
2021-10-09 15:06:56 ERROR (MainThread) [homeassistant.config] Invalid config for [automation]: [title] is an invalid option for [automation]. Check: automation->action->1->title. (See ?, line ?). 
2021-10-09 15:06:56 ERROR (MainThread) [homeassistant.config] Invalid config for [automation]: must be a value between 0 and 59 for dictionary value @ data['minutes']. Got None. (See ?, line ?). 
2021-10-09 15:06:56 ERROR (MainThread) [homeassistant.config] Invalid config for [automation]: must be a value between 0 and 59 for dictionary value @ data['minutes']. Got None. (See ?, line ?). 
2021-10-09 15:06:56 ERROR (MainThread) [homeassistant.helpers.entity] Update for sensor.master_bedroom_tv_on_today fails
Traceback (most recent call last):
  File "/usr/src/homeassistant/homeassistant/helpers/entity.py", line 438, in async_update_ha_state
    await self.async_device_update()
  File "/usr/src/homeassistant/homeassistant/helpers/entity.py", line 625, in async_device_update
    raise exc
  File "/usr/src/homeassistant/homeassistant/components/history_stats/sensor.py", line 221, in async_update
    await self.hass.async_add_executor_job(
  File "/usr/local/lib/python3.9/concurrent/futures/thread.py", line 52, in run
    result = self.fn(*self.args, **self.kwargs)
  File "/usr/src/homeassistant/homeassistant/components/history_stats/sensor.py", line 227, in _update
    history_list = history.state_changes_during_period(
  File "/usr/src/homeassistant/homeassistant/components/recorder/history.py", line 147, in state_changes_during_period
    with session_scope(hass=hass) as session:
  File "/usr/local/lib/python3.9/contextlib.py", line 119, in __enter__
    return next(self.gen)
  File "/usr/src/homeassistant/homeassistant/components/recorder/util.py", line 60, in session_scope
    session = hass.data[DATA_INSTANCE].get_session()
TypeError: 'NoneType' object is not callable
