2021-09-26 19:49:51 WARNING (SyncWorker_3) [homeassistant.loader] We found a custom integration powercalc which has not been tested by Home Assistant. This component might cause stability problems, be sure to disable it if you experience issues with Home Assistant
2021-09-26 19:49:51 WARNING (SyncWorker_0) [homeassistant.loader] We found a custom integration xiaomi_miio_airpurifier which has not been tested by Home Assistant. This component might cause stability problems, be sure to disable it if you experience issues with Home Assistant
2021-09-26 19:49:51 WARNING (SyncWorker_4) [homeassistant.loader] We found a custom integration monitor_docker which has not been tested by Home Assistant. This component might cause stability problems, be sure to disable it if you experience issues with Home Assistant
2021-09-26 19:49:51 WARNING (SyncWorker_5) [homeassistant.loader] We found a custom integration hacs which has not been tested by Home Assistant. This component might cause stability problems, be sure to disable it if you experience issues with Home Assistant
2021-09-26 19:49:51 WARNING (SyncWorker_1) [homeassistant.loader] We found a custom integration average which has not been tested by Home Assistant. This component might cause stability problems, be sure to disable it if you experience issues with Home Assistant
2021-09-26 19:49:51 WARNING (SyncWorker_2) [homeassistant.loader] We found a custom integration audiconnect which has not been tested by Home Assistant. This component might cause stability problems, be sure to disable it if you experience issues with Home Assistant
2021-09-26 19:49:51 WARNING (SyncWorker_6) [homeassistant.loader] We found a custom integration localtuya which has not been tested by Home Assistant. This component might cause stability problems, be sure to disable it if you experience issues with Home Assistant
2021-09-26 19:49:51 WARNING (SyncWorker_7) [homeassistant.loader] We found a custom integration xiaomi_miio_fan which has not been tested by Home Assistant. This component might cause stability problems, be sure to disable it if you experience issues with Home Assistant
2021-09-26 19:49:51 WARNING (SyncWorker_0) [homeassistant.loader] We found a custom integration shelly which has not been tested by Home Assistant. This component might cause stability problems, be sure to disable it if you experience issues with Home Assistant
2021-09-26 19:49:51 WARNING (SyncWorker_6) [homeassistant.loader] We found a custom integration anniversaries which has not been tested by Home Assistant. This component might cause stability problems, be sure to disable it if you experience issues with Home Assistant
2021-09-26 19:49:51 WARNING (SyncWorker_4) [homeassistant.loader] We found a custom integration tuya_v2 which has not been tested by Home Assistant. This component might cause stability problems, be sure to disable it if you experience issues with Home Assistant
2021-09-26 19:49:51 WARNING (SyncWorker_9) [homeassistant.loader] We found a custom integration thermal_comfort which has not been tested by Home Assistant. This component might cause stability problems, be sure to disable it if you experience issues with Home Assistant
2021-09-26 19:49:51 WARNING (SyncWorker_8) [homeassistant.loader] We found a custom integration deepstack_face which has not been tested by Home Assistant. This component might cause stability problems, be sure to disable it if you experience issues with Home Assistant
2021-09-26 19:49:51 WARNING (SyncWorker_2) [homeassistant.loader] We found a custom integration buienalarm which has not been tested by Home Assistant. This component might cause stability problems, be sure to disable it if you experience issues with Home Assistant
2021-09-26 19:49:51 WARNING (SyncWorker_3) [homeassistant.loader] We found a custom integration huesyncbox which has not been tested by Home Assistant. This component might cause stability problems, be sure to disable it if you experience issues with Home Assistant
2021-09-26 19:49:51 WARNING (SyncWorker_10) [homeassistant.loader] We found a custom integration googlewifi which has not been tested by Home Assistant. This component might cause stability problems, be sure to disable it if you experience issues with Home Assistant
2021-09-26 19:49:51 WARNING (SyncWorker_1) [homeassistant.loader] We found a custom integration xiaomi_miot which has not been tested by Home Assistant. This component might cause stability problems, be sure to disable it if you experience issues with Home Assistant
2021-09-26 19:49:51 WARNING (SyncWorker_11) [homeassistant.loader] We found a custom integration ytube_music_player which has not been tested by Home Assistant. This component might cause stability problems, be sure to disable it if you experience issues with Home Assistant
2021-09-26 19:49:51 WARNING (SyncWorker_6) [homeassistant.loader] We found a custom integration afvalbeheer which has not been tested by Home Assistant. This component might cause stability problems, be sure to disable it if you experience issues with Home Assistant
2021-09-26 19:49:51 WARNING (SyncWorker_7) [homeassistant.loader] We found a custom integration google_home which has not been tested by Home Assistant. This component might cause stability problems, be sure to disable it if you experience issues with Home Assistant
2021-09-26 19:50:02 ERROR (MainThread) [homeassistant.config] Invalid config for [automation]: required key not provided @ data['action'][4]['domain']. Got None. (See ?, line ?). 
2021-09-26 19:50:02 ERROR (MainThread) [homeassistant.config] Invalid config for [automation]: [title] is an invalid option for [automation]. Check: automation->action->1->title. (See ?, line ?). 
2021-09-26 19:50:03 ERROR (MainThread) [homeassistant.config] Invalid config for [automation]: must be a value between 0 and 59 for dictionary value @ data['minutes']. Got None. (See ?, line ?). 
2021-09-26 19:50:03 ERROR (MainThread) [homeassistant.config] Invalid config for [automation]: must be a value between 0 and 59 for dictionary value @ data['minutes']. Got None. (See ?, line ?). 
2021-09-26 19:50:07 ERROR (MainThread) [hole] Can not load data from *hole: 192.168.86.101:8081
2021-09-26 19:50:07 WARNING (MainThread) [homeassistant.components.pi_hole] Failed to connect: Can not load data from *hole: 192.168.86.101:8081
2021-09-26 19:50:07 WARNING (MainThread) [homeassistant.config_entries] Config entry 'pihole' for pi_hole integration not ready yet: Can not load data from *hole: 192.168.86.101:8081; Retrying in background
2021-09-26 19:50:07 WARNING (MainThread) [homeassistant.setup] Setup of input_boolean is taking over 10 seconds.
2021-09-26 19:50:07 WARNING (MainThread) [homeassistant.setup] Setup of zone is taking over 10 seconds.
2021-09-26 19:50:07 WARNING (MainThread) [homeassistant.setup] Setup of counter is taking over 10 seconds.
2021-09-26 19:50:07 WARNING (MainThread) [homeassistant.components.fan] Platform xiaomi_miio_fan not ready yet: Unable to discover the device 192.168.86.29; Retrying in background in 30 seconds
2021-09-26 19:50:07 WARNING (MainThread) [homeassistant.components.fan] Platform xiaomi_miio_fan not ready yet: Unable to discover the device 192.168.86.28; Retrying in background in 30 seconds
2021-09-26 19:50:10 WARNING (MainThread) [homeassistant.config_entries] Config entry '192.168.86.83' for synology_dsm integration not ready yet: {'api': None, 'code': -1, 'reason': 'Unknown', 'details': 'ConnectionError = <urllib3.connection.HTTPSConnection object at 0xffff8ca7d040>: Failed to establish a new connection: [Errno 113] Host is unreachable'}; Retrying in background
2021-09-26 19:50:11 ERROR (MainThread) [homeassistant.components.automation] Platform automation does not generate unique IDs. ID 1632427763962 already exists - ignoring automation.verwarming_aan_en_raam_open_verwarming_uit
2021-09-26 19:50:16 WARNING (MainThread) [homeassistant.components.light] Platform netatmo not ready yet: None; Retrying in background in 30 seconds
2021-09-26 19:50:16 WARNING (MainThread) [homeassistant.components.select] Platform netatmo not ready yet: None; Retrying in background in 30 seconds
2021-09-26 19:50:18 ERROR (MainThread) [homeassistant.components.hue.sensor_base] Timeout fetching sensor data
2021-09-26 19:50:18 WARNING (MainThread) [homeassistant.components.media_player] Setup of media_player platform samsungtv is taking over 10 seconds.
2021-09-26 19:50:18 ERROR (MainThread) [homeassistant.components.hue.sensor_base] Timeout fetching sensor data
2021-09-26 19:50:18 WARNING (MainThread) [homeassistant.components.hue.light] Please check for software updates of the douche bulb in the Philips Hue App.
2021-09-26 19:50:18 WARNING (MainThread) [homeassistant.components.hue.light] Please check for software updates of the wasbak rechts bulb in the Philips Hue App.
2021-09-26 19:50:18 WARNING (MainThread) [homeassistant.components.hue.light] Please check for software updates of the bad bulb in the Philips Hue App.
2021-09-26 19:50:18 WARNING (MainThread) [homeassistant.components.hue.light] Please check for software updates of the Amilya plafond 2 bulb in the Philips Hue App.
2021-09-26 19:50:18 WARNING (MainThread) [homeassistant.components.hue.light] Please check for software updates of the Amilya plafond 1 bulb in the Philips Hue App.
2021-09-26 19:50:19 WARNING (MainThread) [homeassistant.components.camera] Platform netatmo not ready yet: None; Retrying in background in 30 seconds
2021-09-26 19:50:19 WARNING (MainThread) [homeassistant.components.climate] Platform netatmo not ready yet: None; Retrying in background in 30 seconds
2021-09-26 19:50:19 ERROR (SyncWorker_7) [glocaltokens.client] [Device - Nest Wifi router(id=2f2a9d15-0ae2-4ffe-b6c1-2ef24c742b8a)] local_auth_token must follow the correct format
2021-09-26 19:50:19 ERROR (SyncWorker_7) [glocaltokens.client] [Device - Nest Wifi router(id=e1e5a8d5-d21f-444d-95a9-c76d78c9bc79)] local_auth_token must follow the correct format
2021-09-26 19:50:19 ERROR (SyncWorker_7) [glocaltokens.client] [Device - Nest Wifi router(id=ea3de37c-ca74-4689-8171-1681b2f4f924)] local_auth_token must follow the correct format
2021-09-26 19:50:20 WARNING (MainThread) [homeassistant.components.sensor] Platform netatmo not ready yet: None; Retrying in background in 30 seconds
2021-09-26 19:50:21 WARNING (MainThread) [homeassistant.components.sensor] Setup of sensor platform scrape is taking over 10 seconds.
2021-09-26 19:50:21 WARNING (MainThread) [homeassistant.components.sensor] Setup of sensor platform scrape is taking over 10 seconds.
2021-09-26 19:50:21 WARNING (MainThread) [homeassistant.components.sensor] Setup of sensor platform scrape is taking over 10 seconds.
2021-09-26 19:50:21 WARNING (MainThread) [homeassistant.components.sensor] Setup of sensor platform scrape is taking over 10 seconds.
2021-09-26 19:50:21 WARNING (MainThread) [homeassistant.components.sensor] Setup of sensor platform scrape is taking over 10 seconds.
2021-09-26 19:50:21 WARNING (MainThread) [homeassistant.components.sensor] Setup of sensor platform scrape is taking over 10 seconds.
2021-09-26 19:50:21 WARNING (MainThread) [homeassistant.components.sensor] Setup of sensor platform scrape is taking over 10 seconds.
2021-09-26 19:50:21 WARNING (MainThread) [homeassistant.config_entries] Config entry 'OnHub' for upnp integration not ready yet; Retrying in background
2021-09-26 19:50:21 ERROR (MainThread) [homeassistant.components.sensor] scrape: Error on device update!
Traceback (most recent call last):
  File "/usr/src/homeassistant/homeassistant/helpers/entity_platform.py", line 431, in _async_add_entity
    await entity.async_device_update(warning=False)
  File "/usr/src/homeassistant/homeassistant/helpers/entity.py", line 633, in async_device_update
    await task
  File "/usr/src/homeassistant/homeassistant/components/scrape/sensor.py", line 139, in async_update
    await self._async_update_from_rest_data()
  File "/usr/src/homeassistant/homeassistant/components/scrape/sensor.py", line 152, in _async_update_from_rest_data
    value = await self.hass.async_add_executor_job(self._extract_value)
  File "/usr/local/lib/python3.9/concurrent/futures/thread.py", line 52, in run
    result = self.fn(*self.args, **self.kwargs)
  File "/usr/src/homeassistant/homeassistant/components/scrape/sensor.py", line 128, in _extract_value
    tag = raw_data.select(self._select)[self._index]
  File "/usr/local/lib/python3.9/site-packages/bs4/element.py", line 1869, in select
    results = soupsieve.select(selector, self, namespaces, limit, **kwargs)
  File "/usr/local/lib/python3.9/site-packages/soupsieve/__init__.py", line 98, in select
    return compile(select, namespaces, flags, **kwargs).select(tag, limit)
  File "/usr/local/lib/python3.9/site-packages/soupsieve/__init__.py", line 62, in compile
    return cp._cached_css_compile(pattern, namespaces, custom, flags)
  File "/usr/local/lib/python3.9/site-packages/soupsieve/css_parser.py", line 211, in _cached_css_compile
    CSSParser(pattern, custom=custom_selectors, flags=flags).process_selectors(),
  File "/usr/local/lib/python3.9/site-packages/soupsieve/css_parser.py", line 1058, in process_selectors
    return self.parse_selectors(self.selector_iter(self.pattern), index, flags)
  File "/usr/local/lib/python3.9/site-packages/soupsieve/css_parser.py", line 909, in parse_selectors
    key, m = next(iselector)
  File "/usr/local/lib/python3.9/site-packages/soupsieve/css_parser.py", line 1051, in selector_iter
    raise SelectorSyntaxError(msg, self.pattern, index)
soupsieve.util.SelectorSyntaxError: Invalid character '<' position 0
  line 1:
<span _ngcontent-app-root-c173="">Offline</span>
^
2021-09-26 19:50:49 WARNING (MainThread) [homeassistant.components.media_player] Updating huesyncbox media_player took longer than the scheduled update interval 0:00:02
2021-09-26 19:50:59 ERROR (MainThread) [homeassistant.components.mobile_app.notify] Timeout sending notification to https://mobile-apps.home-assistant.io/api/sendPush/android/v1
2021-09-26 19:50:59 WARNING (MainThread) [homeassistant.components.media_player] Updating samsungtv media_player took longer than the scheduled update interval 0:00:10
2021-09-26 19:51:00 WARNING (MainThread) [homeassistant.components.sensor] Setup of sensor platform pi_hole is taking over 10 seconds.
2021-09-26 20:32:36 ERROR (MainThread) [homeassistant] Error doing job: Task exception was never retrieved
Traceback (most recent call last):
  File "/usr/src/homeassistant/homeassistant/components/discovery/__init__.py", line 194, in scan_devices
    results = await hass.async_add_executor_job(
  File "/usr/local/lib/python3.9/concurrent/futures/thread.py", line 52, in run
    result = self.fn(*self.args, **self.kwargs)
  File "/usr/src/homeassistant/homeassistant/components/discovery/__init__.py", line 226, in _discover
    for service in netdisco.get_info(disc):
  File "/usr/local/lib/python3.9/site-packages/netdisco/discovery.py", line 108, in get_info
    return self.discoverables[dis].get_info()
  File "/usr/local/lib/python3.9/site-packages/netdisco/discoverables/__init__.py", line 28, in get_info
    return [self.info_from_entry(entry) for entry in self.get_entries()]
  File "/usr/local/lib/python3.9/site-packages/netdisco/discoverables/__init__.py", line 28, in <listcomp>
    return [self.info_from_entry(entry) for entry in self.get_entries()]
  File "/usr/local/lib/python3.9/site-packages/netdisco/discoverables/__init__.py", line 129, in info_from_entry
    ATTR_HOST: str(ipaddress.ip_address(entry.addresses[0])),
IndexError: list index out of range
2021-09-26 20:40:12 ERROR (MainThread) [custom_components.googlewifi] Error fetching GoogleWifi data: Error connecting to GoogleWifi: 
2021-09-26 20:45:10 ERROR (MainThread) [homeassistant.components.mobile_app.notify] Timeout sending notification to https://mobile-apps.home-assistant.io/api/sendPush/android/v1
2021-09-26 21:15:10 ERROR (MainThread) [homeassistant.components.mobile_app.notify] Timeout sending notification to https://mobile-apps.home-assistant.io/api/sendPush/android/v1
2021-09-26 22:25:17 WARNING (SyncWorker_12) [buienalarm.pybuienalarm] Error fetching data safely: 503 Server Error: Service Unavailable for url: https://cdn-secure.buienalarm.nl/api/3.4/forecast.php?lat=50.878800118427755&lon=4.749415398691782&region=nl&unit=mm%2Fu
2021-09-26 22:52:01 ERROR (MainThread) [custom_components.googlewifi] Unexpected error fetching GoogleWifi data: 'operation'
Traceback (most recent call last):
  File "/usr/src/homeassistant/homeassistant/helpers/update_coordinator.py", line 187, in _async_refresh
    self.data = await self._async_update_data()
  File "/config/custom_components/googlewifi/__init__.py", line 171, in _async_update_data
    system_data = await self.api.get_systems()
  File "/usr/local/lib/python3.9/site-packages/googlewifi/__init__.py", line 191, in get_systems
    return await self.structure_systems(response)
  File "/usr/local/lib/python3.9/site-packages/googlewifi/__init__.py", line 284, in structure_systems
    sensitive_info = await self.get_sensitive_info(system_id=this_system["id"], station_ids=station_ids)
  File "/usr/local/lib/python3.9/site-packages/googlewifi/__init__.py", line 611, in get_sensitive_info
    operation_id = await self.start_retrieve_sensitive_info(
  File "/usr/local/lib/python3.9/site-packages/googlewifi/__init__.py", line 589, in start_retrieve_sensitive_info
    operation_id = response["operation"]["operationId"]
KeyError: 'operation'
2021-09-27 00:47:01 ERROR (MainThread) [aiohttp.server] Error handling request
Traceback (most recent call last):
  File "/usr/local/lib/python3.9/site-packages/aiohttp/web_protocol.py", line 314, in data_received
    messages, upgraded, tail = self._request_parser.feed_data(data)
  File "aiohttp/_http_parser.pyx", line 546, in aiohttp._http_parser.HttpParser.feed_data
aiohttp.http_exceptions.BadHttpMessage: 400, message='invalid constant string'
2021-09-27 00:47:08 ERROR (MainThread) [aiohttp.server] Error handling request
Traceback (most recent call last):
  File "/usr/local/lib/python3.9/site-packages/aiohttp/web_protocol.py", line 314, in data_received
    messages, upgraded, tail = self._request_parser.feed_data(data)
  File "aiohttp/_http_parser.pyx", line 546, in aiohttp._http_parser.HttpParser.feed_data
aiohttp.http_exceptions.BadStatusLine: 400, message="Bad status line 'invalid HTTP method'"
2021-09-27 00:47:10 ERROR (MainThread) [aiohttp.server] Error handling request
Traceback (most recent call last):
  File "/usr/local/lib/python3.9/site-packages/aiohttp/web_protocol.py", line 314, in data_received
    messages, upgraded, tail = self._request_parser.feed_data(data)
  File "aiohttp/_http_parser.pyx", line 546, in aiohttp._http_parser.HttpParser.feed_data
aiohttp.http_exceptions.BadStatusLine: 400, message="Bad status line 'invalid HTTP method'"
2021-09-27 00:47:12 ERROR (MainThread) [aiohttp.server] Error handling request
Traceback (most recent call last):
  File "/usr/local/lib/python3.9/site-packages/aiohttp/web_protocol.py", line 314, in data_received
    messages, upgraded, tail = self._request_parser.feed_data(data)
  File "aiohttp/_http_parser.pyx", line 546, in aiohttp._http_parser.HttpParser.feed_data
aiohttp.http_exceptions.BadStatusLine: 400, message="Bad status line 'invalid HTTP method'"
2021-09-27 00:47:13 ERROR (MainThread) [aiohttp.server] Error handling request
Traceback (most recent call last):
  File "/usr/local/lib/python3.9/site-packages/aiohttp/web_protocol.py", line 314, in data_received
    messages, upgraded, tail = self._request_parser.feed_data(data)
  File "aiohttp/_http_parser.pyx", line 546, in aiohttp._http_parser.HttpParser.feed_data
aiohttp.http_exceptions.BadStatusLine: 400, message="Bad status line 'invalid HTTP method'"
2021-09-27 00:47:14 ERROR (MainThread) [aiohttp.server] Error handling request
Traceback (most recent call last):
  File "/usr/local/lib/python3.9/site-packages/aiohttp/web_protocol.py", line 314, in data_received
    messages, upgraded, tail = self._request_parser.feed_data(data)
  File "aiohttp/_http_parser.pyx", line 546, in aiohttp._http_parser.HttpParser.feed_data
aiohttp.http_exceptions.BadStatusLine: 400, message="Bad status line 'invalid HTTP method'"
2021-09-27 00:47:15 ERROR (MainThread) [aiohttp.server] Error handling request
Traceback (most recent call last):
  File "/usr/local/lib/python3.9/site-packages/aiohttp/web_protocol.py", line 314, in data_received
    messages, upgraded, tail = self._request_parser.feed_data(data)
  File "aiohttp/_http_parser.pyx", line 546, in aiohttp._http_parser.HttpParser.feed_data
aiohttp.http_exceptions.BadStatusLine: 400, message="Bad status line 'invalid HTTP method'"
2021-09-27 00:47:16 ERROR (MainThread) [aiohttp.server] Error handling request
Traceback (most recent call last):
  File "/usr/local/lib/python3.9/site-packages/aiohttp/web_protocol.py", line 314, in data_received
    messages, upgraded, tail = self._request_parser.feed_data(data)
  File "aiohttp/_http_parser.pyx", line 546, in aiohttp._http_parser.HttpParser.feed_data
aiohttp.http_exceptions.BadStatusLine: 400, message="Bad status line 'invalid HTTP method'"
2021-09-27 00:47:18 ERROR (MainThread) [aiohttp.server] Error handling request
Traceback (most recent call last):
  File "/usr/local/lib/python3.9/site-packages/aiohttp/web_protocol.py", line 314, in data_received
    messages, upgraded, tail = self._request_parser.feed_data(data)
  File "aiohttp/_http_parser.pyx", line 546, in aiohttp._http_parser.HttpParser.feed_data
aiohttp.http_exceptions.InvalidURLError: 400, message='invalid URL'
2021-09-27 00:47:52 ERROR (MainThread) [aiohttp.server] Error handling request
Traceback (most recent call last):
  File "/usr/local/lib/python3.9/site-packages/aiohttp/web_protocol.py", line 314, in data_received
    messages, upgraded, tail = self._request_parser.feed_data(data)
  File "aiohttp/_http_parser.pyx", line 546, in aiohttp._http_parser.HttpParser.feed_data
aiohttp.http_exceptions.BadStatusLine: 400, message="Bad status line 'invalid HTTP method'"
2021-09-27 00:48:14 ERROR (MainThread) [aiohttp.server] Error handling request
Traceback (most recent call last):
  File "/usr/local/lib/python3.9/site-packages/aiohttp/web_protocol.py", line 314, in data_received
    messages, upgraded, tail = self._request_parser.feed_data(data)
  File "aiohttp/_http_parser.pyx", line 546, in aiohttp._http_parser.HttpParser.feed_data
aiohttp.http_exceptions.BadStatusLine: 400, message="Bad status line 'invalid HTTP method'"
2021-09-27 00:52:47 WARNING (Thread-16) [pychromecast.socket_client] [(192.168.86.35):8009] Heartbeat timeout, resetting connection
2021-09-27 00:53:11 WARNING (Thread-23) [pychromecast.socket_client] [Master bedroom speaker(192.168.86.42):8009] Heartbeat timeout, resetting connection
2021-09-27 00:53:17 ERROR (Thread-16) [pychromecast.socket_client] [(192.168.86.35):8009] Failed to connect to service ServiceInfo(type='host', data=('192.168.86.35', 8009)), retrying in 5.0s
2021-09-27 00:53:26 ERROR (Thread-23) [pychromecast.socket_client] [Master bedroom speaker(192.168.86.42):8009] Failed to connect to service ServiceInfo(type='host', data=('192.168.86.42', 8009)), retrying in 5.0s
2021-09-27 00:57:15 ERROR (SyncWorker_1) [glocaltokens.client] [Device - Nest Wifi router(id=2f2a9d15-0ae2-4ffe-b6c1-2ef24c742b8a)] local_auth_token must follow the correct format
2021-09-27 00:57:15 ERROR (SyncWorker_1) [glocaltokens.client] [Device - Nest Wifi router(id=e1e5a8d5-d21f-444d-95a9-c76d78c9bc79)] local_auth_token must follow the correct format
2021-09-27 00:57:15 ERROR (SyncWorker_1) [glocaltokens.client] [Device - Nest Wifi router(id=ea3de37c-ca74-4689-8171-1681b2f4f924)] local_auth_token must follow the correct format
2021-09-27 01:02:43 WARNING (MainThread) [homeassistant.helpers.service] Unable to find referenced entities media_player.veranda_speaker_2
2021-09-27 01:09:59 WARNING (MainThread) [homeassistant.helpers.service] Unable to find referenced entities media_player.veranda_speaker_2
2021-09-27 01:18:33 ERROR (MainThread) [custom_components.googlewifi] Unexpected error fetching GoogleWifi data: 'NoneType' object is not iterable
Traceback (most recent call last):
  File "/usr/src/homeassistant/homeassistant/helpers/update_coordinator.py", line 187, in _async_refresh
    self.data = await self._async_update_data()
  File "/config/custom_components/googlewifi/__init__.py", line 171, in _async_update_data
    system_data = await self.api.get_systems()
  File "/usr/local/lib/python3.9/site-packages/googlewifi/__init__.py", line 191, in get_systems
    return await self.structure_systems(response)
  File "/usr/local/lib/python3.9/site-packages/googlewifi/__init__.py", line 289, in structure_systems
    for this_station in system_metrics.get("stationMetrics"):
TypeError: 'NoneType' object is not iterable
2021-09-27 01:45:31 WARNING (Thread-21) [pychromecast.socket_client] [Living Chromecast(192.168.86.32):8009] Heartbeat timeout, resetting connection
2021-09-27 01:45:47 ERROR (Thread-21) [pychromecast.socket_client] [Living Chromecast(192.168.86.32):8009] Failed to connect to service ServiceInfo(type='host', data=('192.168.86.32', 8009)), retrying in 5.0s
2021-09-27 02:29:02 WARNING (Thread-20) [pychromecast.socket_client] [Alunya speaker(192.168.86.37):8009] Heartbeat timeout, resetting connection
2021-09-27 02:29:09 ERROR (Thread-20) [pychromecast.socket_client] [Alunya speaker(192.168.86.37):8009] Failed to connect to service ServiceInfo(type='host', data=('192.168.86.37', 8009)), retrying in 5.0s
2021-09-27 02:32:58 ERROR (SyncWorker_12) [glocaltokens.client] [Device - Nest Wifi router(id=2f2a9d15-0ae2-4ffe-b6c1-2ef24c742b8a)] local_auth_token must follow the correct format
2021-09-27 02:32:58 ERROR (SyncWorker_12) [glocaltokens.client] [Device - Nest Wifi router(id=e1e5a8d5-d21f-444d-95a9-c76d78c9bc79)] local_auth_token must follow the correct format
2021-09-27 02:32:58 ERROR (SyncWorker_12) [glocaltokens.client] [Device - Nest Wifi router(id=ea3de37c-ca74-4689-8171-1681b2f4f924)] local_auth_token must follow the correct format
2021-09-27 05:00:10 ERROR (MainThread) [homeassistant.components.mobile_app.notify] Timeout sending notification to https://mobile-apps.home-assistant.io/api/sendPush/android/v1
2021-09-27 05:11:03 WARNING (MainThread) [homeassistant.helpers.service] Unable to find referenced entities media_player.veranda_speaker_2
2021-09-27 05:15:31 WARNING (MainThread) [homeassistant.helpers.service] Unable to find referenced entities media_player.veranda_speaker_2
2021-09-27 05:23:18 ERROR (MainThread) [custom_components.audiconnect.audi_connect_account] Unable to update the vehicle position of WAUZZZGE6MB019131: 204, message='No Content', url=URL('https://fal-3a.prd.eu.dp.vwg-connect.com/fs-car/bs/cf/v1/Audi/BE/vehicles/WAUZZZGE6MB019131/position')
2021-09-27 05:45:23 WARNING (MainThread) [homeassistant.helpers.service] Unable to find referenced entities media_player.veranda_speaker_2
2021-09-27 06:15:10 ERROR (MainThread) [homeassistant.components.mobile_app.notify] Timeout sending notification to https://mobile-apps.home-assistant.io/api/sendPush/android/v1
2021-09-27 06:41:38 ERROR (MainThread) [custom_components.googlewifi] Error fetching GoogleWifi data: Error connecting to GoogleWifi: 
2021-09-27 06:45:10 ERROR (MainThread) [homeassistant.components.mobile_app.notify] Timeout sending notification to https://mobile-apps.home-assistant.io/api/sendPush/android/v1
2021-09-27 08:30:10 ERROR (MainThread) [homeassistant.components.mobile_app.notify] Timeout sending notification to https://mobile-apps.home-assistant.io/api/sendPush/android/v1
2021-09-27 09:11:26 ERROR (MainThread) [homeassistant.components.scrape.sensor] Unable to extract data from HTML for precip_rate_leuven24_wunderground
2021-09-27 09:14:23 ERROR (MainThread) [homeassistant.components.scrape.sensor] Unable to extract data from HTML for humidity_leuven24_wunderground
2021-09-27 09:14:23 ERROR (MainThread) [homeassistant.components.scrape.sensor] Unable to extract data from HTML for temp_leuven24_wunderground
2021-09-27 09:14:26 ERROR (MainThread) [homeassistant.components.scrape.sensor] Unable to extract data from HTML for precip_rate_leuven24_wunderground
2021-09-27 09:55:59 WARNING (MainThread) [homeassistant.helpers.service] Unable to find referenced entities media_player.veranda_speaker_2
2021-09-27 10:26:50 WARNING (MainThread) [homeassistant.helpers.service] Unable to find referenced entities media_player.veranda_speaker_2
2021-09-27 10:27:27 ERROR (Thread-18) [homeassistant.components.cast.media_player] Failed to cast media http://cloudrad.io/radioop/?DIST=TuneIn&TGT=TuneIn&maxServers=2&partnertok=eyJhbGciOiJIUzI1NiIsImtpZCI6InR1bmVpbiIsInR5cCI6IkpXVCJ9.eyJ0cnVzdGVkX3BhcnRuZXIiOnRydWUsImlhdCI6MTYzMjczODQ0MSwiaXNzIjoidGlzcnYifQ.cJRY2HLAix6m4vSRIUZSiVvZW0Xh3vLxDTp_fuOUZ64. Please make sure the URL is: Reachable from the cast device and either a publicly resolvable hostname or an IP address
2021-09-27 10:27:27 ERROR (Thread-18) [homeassistant.components.cast.media_player] Failed to cast media http://cloudrad.io/radioop/?DIST=TuneIn&TGT=TuneIn&maxServers=2&partnertok=eyJhbGciOiJIUzI1NiIsImtpZCI6InR1bmVpbiIsInR5cCI6IkpXVCJ9.eyJ0cnVzdGVkX3BhcnRuZXIiOnRydWUsImlhdCI6MTYzMjczODQ0MSwiaXNzIjoidGlzcnYifQ.cJRY2HLAix6m4vSRIUZSiVvZW0Xh3vLxDTp_fuOUZ64. Please make sure the URL is: Reachable from the cast device and either a publicly resolvable hostname or an IP address
2021-09-27 10:27:27 ERROR (Thread-18) [homeassistant.components.cast.media_player] Failed to cast media http://cloudrad.io/radioop/;?DIST=TuneIn&TGT=TuneIn&maxServers=2&partnertok=eyJhbGciOiJIUzI1NiIsImtpZCI6InR1bmVpbiIsInR5cCI6IkpXVCJ9.eyJ0cnVzdGVkX3BhcnRuZXIiOnRydWUsImlhdCI6MTYzMjczODQ0MSwiaXNzIjoidGlzcnYifQ.cJRY2HLAix6m4vSRIUZSiVvZW0Xh3vLxDTp_fuOUZ64. Please make sure the URL is: Reachable from the cast device and either a publicly resolvable hostname or an IP address
2021-09-27 10:27:27 ERROR (Thread-18) [homeassistant.components.cast.media_player] Failed to cast media http://cloudrad.io/radioop/;?DIST=TuneIn&TGT=TuneIn&maxServers=2&partnertok=eyJhbGciOiJIUzI1NiIsImtpZCI6InR1bmVpbiIsInR5cCI6IkpXVCJ9.eyJ0cnVzdGVkX3BhcnRuZXIiOnRydWUsImlhdCI6MTYzMjczODQ0MSwiaXNzIjoidGlzcnYifQ.cJRY2HLAix6m4vSRIUZSiVvZW0Xh3vLxDTp_fuOUZ64. Please make sure the URL is: Reachable from the cast device and either a publicly resolvable hostname or an IP address
2021-09-27 10:27:27 ERROR (Thread-18) [homeassistant.components.cast.media_player] Failed to cast media http://cloudrad.io/radioop/;?DIST=TuneIn&TGT=TuneIn&maxServers=2&partnertok=eyJhbGciOiJIUzI1NiIsImtpZCI6InR1bmVpbiIsInR5cCI6IkpXVCJ9.eyJ0cnVzdGVkX3BhcnRuZXIiOnRydWUsImlhdCI6MTYzMjczODQ0MSwiaXNzIjoidGlzcnYifQ.cJRY2HLAix6m4vSRIUZSiVvZW0Xh3vLxDTp_fuOUZ64. Please make sure the URL is: Reachable from the cast device and either a publicly resolvable hostname or an IP address
2021-09-27 10:27:27 ERROR (Thread-18) [homeassistant.components.cast.media_player] Failed to cast media http://cloudrad.io/radioop/;?DIST=TuneIn&TGT=TuneIn&maxServers=2&partnertok=eyJhbGciOiJIUzI1NiIsImtpZCI6InR1bmVpbiIsInR5cCI6IkpXVCJ9.eyJ0cnVzdGVkX3BhcnRuZXIiOnRydWUsImlhdCI6MTYzMjczODQ0MSwiaXNzIjoidGlzcnYifQ.cJRY2HLAix6m4vSRIUZSiVvZW0Xh3vLxDTp_fuOUZ64. Please make sure the URL is: Reachable from the cast device and either a publicly resolvable hostname or an IP address
2021-09-27 10:27:27 ERROR (Thread-18) [homeassistant.components.cast.media_player] Failed to cast media http://cloudrad.io/radioop/;?DIST=TuneIn&TGT=TuneIn&maxServers=2&partnertok=eyJhbGciOiJIUzI1NiIsImtpZCI6InR1bmVpbiIsInR5cCI6IkpXVCJ9.eyJ0cnVzdGVkX3BhcnRuZXIiOnRydWUsImlhdCI6MTYzMjczODQ0MSwiaXNzIjoidGlzcnYifQ.cJRY2HLAix6m4vSRIUZSiVvZW0Xh3vLxDTp_fuOUZ64. Please make sure the URL is: Reachable from the cast device and either a publicly resolvable hostname or an IP address
2021-09-27 10:27:29 ERROR (Thread-18) [homeassistant.components.cast.media_player] Failed to cast media . Please make sure the URL is: Reachable from the cast device and either a publicly resolvable hostname or an IP address
2021-09-27 10:27:30 ERROR (Thread-18) [homeassistant.components.cast.media_player] Failed to cast media http://playerservices.streamtheworld.com/api/livestream-redirect/JOE.mp3?pname=tunein&dist=tunein&DIST=TuneIn&TGT=TuneIn&maxServers=2&tdtok=eyJ0eXAiOiJKV1QiLCJhbGciOiJIUzI1NiIsImtpZCI6ImZTeXA4In0.eyJpc3MiOiJ0aXNydiIsInN1YiI6IjIxMDY0IiwiaWF0IjoxNjMyNzM4NDQ5LCJ0ZC1yZWciOmZhbHNlfQ.HNtwFNxoVISb-dOMkTxCxUvvHjuWzWflaCy6dUMiB7U&partnertok=eyJhbGciOiJIUzI1NiIsImtpZCI6InR1bmVpbiIsInR5cCI6IkpXVCJ9.eyJ0cnVzdGVkX3BhcnRuZXIiOnRydWUsImlhdCI6MTYzMjczODQ0OSwiaXNzIjoidGlzcnYifQ.F8cQkO-MTjIqc7yVNXTXOYfaPnRa5xJjkUcPFm-r0DM. Please make sure the URL is: Reachable from the cast device and either a publicly resolvable hostname or an IP address
2021-09-27 10:42:29 ERROR (MainThread) [custom_components.googlewifi] Error fetching GoogleWifi data: Error connecting to GoogleWifi: 
2021-09-27 12:18:07 WARNING (MainThread) [homeassistant.helpers.service] Unable to find referenced entities media_player.veranda_speaker_2
2021-09-27 12:42:59 ERROR (MainThread) [custom_components.googlewifi] Unexpected error fetching GoogleWifi data: 'NoneType' object is not iterable
Traceback (most recent call last):
  File "/usr/src/homeassistant/homeassistant/helpers/update_coordinator.py", line 187, in _async_refresh
    self.data = await self._async_update_data()
  File "/config/custom_components/googlewifi/__init__.py", line 171, in _async_update_data
    system_data = await self.api.get_systems()
  File "/usr/local/lib/python3.9/site-packages/googlewifi/__init__.py", line 191, in get_systems
    return await self.structure_systems(response)
  File "/usr/local/lib/python3.9/site-packages/googlewifi/__init__.py", line 289, in structure_systems
    for this_station in system_metrics.get("stationMetrics"):
TypeError: 'NoneType' object is not iterable
2021-09-27 12:44:31 WARNING (MainThread) [homeassistant.components.automation] Error evaluating condition in 'Regen en raam open = melding':
In 'condition':
  In 'state':
    In 'state' condition: unknown entity binary_sensor.kamer_amilya_window_sensor
2021-09-27 12:44:31 ERROR (MainThread) [homeassistant.components.automation.het_regent] het regent: Error executing script. Invalid data for call_service at pos 1: extra keys not allowed @ data['tag']
2021-09-27 12:44:31 ERROR (MainThread) [homeassistant.components.automation.het_regent] Error while executing automation automation.het_regent: extra keys not allowed @ data['tag']
2021-09-27 12:55:17 WARNING (SyncWorker_5) [buienalarm.pybuienalarm] Error fetching data safely: 503 Server Error: Service Unavailable for url: https://cdn-secure.buienalarm.nl/api/3.4/forecast.php?lat=50.878800118427755&lon=4.749415398691782&region=nl&unit=mm%2Fu
2021-09-27 13:08:30 WARNING (MainThread) [homeassistant.components.automation] Error evaluating condition in 'Regen en raam open = melding':
In 'condition':
  In 'state':
    In 'state' condition: unknown entity binary_sensor.kamer_amilya_window_sensor
2021-09-27 13:08:30 ERROR (MainThread) [homeassistant.components.automation.het_regent] het regent: Error executing script. Invalid data for call_service at pos 1: extra keys not allowed @ data['tag']
2021-09-27 13:08:30 ERROR (MainThread) [homeassistant.components.automation.het_regent] Error while executing automation automation.het_regent: extra keys not allowed @ data['tag']
2021-09-27 13:41:27 WARNING (MainThread) [homeassistant.components.automation] Error evaluating condition in 'Regen en raam open = melding':
In 'condition':
  In 'state':
    In 'state' condition: unknown entity binary_sensor.kamer_amilya_window_sensor
2021-09-27 13:41:27 ERROR (MainThread) [homeassistant.components.automation.het_regent] het regent: Error executing script. Invalid data for call_service at pos 1: extra keys not allowed @ data['tag']
2021-09-27 13:41:27 ERROR (MainThread) [homeassistant.components.automation.het_regent] Error while executing automation automation.het_regent: extra keys not allowed @ data['tag']
2021-09-27 13:45:27 WARNING (SyncWorker_11) [buienalarm.pybuienalarm] Error fetching data safely: HTTPSConnectionPool(host='cdn-secure.buienalarm.nl', port=443): Read timed out. (read timeout=10.0)
2021-09-27 14:28:03 WARNING (MainThread) [homeassistant.components.media_player] Updating huesyncbox media_player took longer than the scheduled update interval 0:00:02
2021-09-27 14:28:05 WARNING (MainThread) [homeassistant.components.media_player] Updating huesyncbox media_player took longer than the scheduled update interval 0:00:02
2021-09-27 14:28:09 WARNING (MainThread) [homeassistant.components.media_player] Updating huesyncbox media_player took longer than the scheduled update interval 0:00:02
2021-09-27 15:03:38 WARNING (MainThread) [homeassistant.helpers.service] Unable to find referenced entities media_player.veranda_speaker_2
2021-09-27 15:10:48 WARNING (MainThread) [homeassistant.helpers.service] Unable to find referenced entities media_player.veranda_speaker_2
2021-09-27 15:12:52 WARNING (MainThread) [homeassistant.helpers.service] Unable to find referenced entities media_player.veranda_speaker_2
2021-09-27 15:23:47 WARNING (MainThread) [homeassistant.helpers.service] Unable to find referenced entities media_player.veranda_speaker_2
2021-09-27 15:27:22 WARNING (MainThread) [homeassistant.helpers.service] Unable to find referenced entities media_player.veranda_speaker_2
2021-09-27 15:29:56 WARNING (MainThread) [homeassistant.helpers.service] Unable to find referenced entities media_player.veranda_speaker_2
2021-09-27 15:33:26 WARNING (MainThread) [homeassistant.helpers.service] Unable to find referenced entities media_player.veranda_speaker_2
2021-09-27 16:40:37 WARNING (SyncWorker_4) [buienalarm.pybuienalarm] Error fetching data safely: HTTPSConnectionPool(host='cdn-secure.buienalarm.nl', port=443): Read timed out. (read timeout=10.0)
2021-09-27 17:23:58 WARNING (MainThread) [homeassistant.helpers.service] Unable to find referenced entities media_player.veranda_speaker_2
2021-09-27 17:35:37 WARNING (SyncWorker_4) [buienalarm.pybuienalarm] Error fetching data safely: 502 Server Error: Bad Gateway for url: https://cdn-secure.buienalarm.nl/api/3.4/forecast.php?lat=50.878800118427755&lon=4.749415398691782&region=nl&unit=mm%2Fu
2021-09-27 17:43:35 ERROR (MainThread) [custom_components.googlewifi] Unexpected error fetching GoogleWifi data: 'NoneType' object is not iterable
Traceback (most recent call last):
  File "/usr/src/homeassistant/homeassistant/helpers/update_coordinator.py", line 187, in _async_refresh
    self.data = await self._async_update_data()
  File "/config/custom_components/googlewifi/__init__.py", line 171, in _async_update_data
    system_data = await self.api.get_systems()
  File "/usr/local/lib/python3.9/site-packages/googlewifi/__init__.py", line 191, in get_systems
    return await self.structure_systems(response)
  File "/usr/local/lib/python3.9/site-packages/googlewifi/__init__.py", line 289, in structure_systems
    for this_station in system_metrics.get("stationMetrics"):
TypeError: 'NoneType' object is not iterable
2021-09-27 17:53:07 WARNING (MainThread) [homeassistant.helpers.service] Unable to find referenced entities media_player.veranda_speaker_2
2021-09-27 17:55:37 WARNING (SyncWorker_6) [buienalarm.pybuienalarm] Error fetching data safely: 502 Server Error: Bad Gateway for url: https://cdn-secure.buienalarm.nl/api/3.4/forecast.php?lat=50.878800118427755&lon=4.749415398691782&region=nl&unit=mm%2Fu
2021-09-27 17:59:30 WARNING (MainThread) [homeassistant.helpers.service] Unable to find referenced entities media_player.veranda_speaker_2
2021-09-27 18:10:59 WARNING (MainThread) [homeassistant.helpers.service] Unable to find referenced entities media_player.veranda_speaker_2
2021-09-27 18:15:37 WARNING (SyncWorker_6) [buienalarm.pybuienalarm] Error fetching data safely: 502 Server Error: Bad Gateway for url: https://cdn-secure.buienalarm.nl/api/3.4/forecast.php?lat=50.878800118427755&lon=4.749415398691782&region=nl&unit=mm%2Fu
2021-09-27 18:20:38 WARNING (SyncWorker_11) [buienalarm.pybuienalarm] Error fetching data safely: 502 Server Error: Bad Gateway for url: https://cdn-secure.buienalarm.nl/api/3.4/forecast.php?lat=50.878800118427755&lon=4.749415398691782&region=nl&unit=mm%2Fu
2021-09-27 18:40:38 WARNING (SyncWorker_13) [buienalarm.pybuienalarm] Error fetching data safely: 502 Server Error: Bad Gateway for url: https://cdn-secure.buienalarm.nl/api/3.4/forecast.php?lat=50.878800118427755&lon=4.749415398691782&region=nl&unit=mm%2Fu
2021-09-27 18:49:55 WARNING (MainThread) [homeassistant.helpers.service] Unable to find referenced entities media_player.veranda_speaker_2
2021-09-27 18:52:10 WARNING (MainThread) [homeassistant.helpers.service] Unable to find referenced entities media_player.veranda_speaker_2
2021-09-27 18:55:38 WARNING (SyncWorker_12) [buienalarm.pybuienalarm] Error fetching data safely: 502 Server Error: Bad Gateway for url: https://cdn-secure.buienalarm.nl/api/3.4/forecast.php?lat=50.878800118427755&lon=4.749415398691782&region=nl&unit=mm%2Fu
2021-09-27 19:20:38 WARNING (SyncWorker_10) [buienalarm.pybuienalarm] Error fetching data safely: 502 Server Error: Bad Gateway for url: https://cdn-secure.buienalarm.nl/api/3.4/forecast.php?lat=50.878800118427755&lon=4.749415398691782&region=nl&unit=mm%2Fu
2021-09-27 19:32:04 WARNING (MainThread) [homeassistant.helpers.service] Unable to find referenced entities media_player.veranda_speaker_2
2021-09-27 19:35:38 WARNING (SyncWorker_2) [buienalarm.pybuienalarm] Error fetching data safely: 502 Server Error: Bad Gateway for url: https://cdn-secure.buienalarm.nl/api/3.4/forecast.php?lat=50.878800118427755&lon=4.749415398691782&region=nl&unit=mm%2Fu
2021-09-27 19:43:59 ERROR (MainThread) [custom_components.googlewifi] Error fetching GoogleWifi data: Error connecting to GoogleWifi: 
2021-09-27 19:52:04 WARNING (MainThread) [homeassistant.components.media_player] Updating huesyncbox media_player took longer than the scheduled update interval 0:00:02
2021-09-27 19:55:38 WARNING (SyncWorker_6) [buienalarm.pybuienalarm] Error fetching data safely: 502 Server Error: Bad Gateway for url: https://cdn-secure.buienalarm.nl/api/3.4/forecast.php?lat=50.878800118427755&lon=4.749415398691782&region=nl&unit=mm%2Fu
2021-09-27 20:00:38 WARNING (SyncWorker_0) [buienalarm.pybuienalarm] Error fetching data safely: 502 Server Error: Bad Gateway for url: https://cdn-secure.buienalarm.nl/api/3.4/forecast.php?lat=50.878800118427755&lon=4.749415398691782&region=nl&unit=mm%2Fu
2021-09-27 20:03:56 WARNING (MainThread) [homeassistant.helpers.service] Unable to find referenced entities media_player.veranda_speaker_2
2021-09-27 20:20:38 WARNING (SyncWorker_6) [buienalarm.pybuienalarm] Error fetching data safely: 502 Server Error: Bad Gateway for url: https://cdn-secure.buienalarm.nl/api/3.4/forecast.php?lat=50.878800118427755&lon=4.749415398691782&region=nl&unit=mm%2Fu
2021-09-27 20:27:10 ERROR (MainThread) [custom_components.audiconnect.audi_connect_account] Unable to obtain the vehicle status report of WAUZZZGE6MB019131: Cannot connect to host fal-3a.prd.eu.dp.vwg-connect.com:443 ssl:default [None]
2021-09-27 20:27:10 ERROR (MainThread) [custom_components.audiconnect.audi_connect_account] Unable to update the vehicle position of WAUZZZGE6MB019131: Cannot connect to host fal-3a.prd.eu.dp.vwg-connect.com:443 ssl:default [None]
2021-09-27 20:27:10 ERROR (MainThread) [custom_components.audiconnect.audi_connect_account] Unable to obtain the vehicle climatisation state for WAUZZZGE6MB019131: Cannot connect to host fal-3a.prd.eu.dp.vwg-connect.com:443 ssl:default [None]
2021-09-27 20:27:10 ERROR (MainThread) [custom_components.audiconnect.audi_connect_account] Unable to obtain the vehicle charger state for WAUZZZGE6MB019131: Cannot connect to host fal-3a.prd.eu.dp.vwg-connect.com:443 ssl:default [None]
2021-09-27 20:40:38 WARNING (SyncWorker_6) [buienalarm.pybuienalarm] Error fetching data safely: 502 Server Error: Bad Gateway for url: https://cdn-secure.buienalarm.nl/api/3.4/forecast.php?lat=50.878800118427755&lon=4.749415398691782&region=nl&unit=mm%2Fu
2021-09-27 20:50:33 WARNING (MainThread) [homeassistant.helpers.entity] Update of sensor.temp_leuven24_wunderground is taking over 10 seconds
2021-09-27 20:50:33 ERROR (MainThread) [homeassistant.components.rest.data] Error fetching data: https://www.wunderground.com/dashboard/pws/ILEUVE24 failed with 
2021-09-27 20:50:33 ERROR (MainThread) [homeassistant.components.scrape.sensor] Unable to retrieve data for temp_leuven24_wunderground
2021-09-27 20:55:38 WARNING (SyncWorker_2) [buienalarm.pybuienalarm] Error fetching data safely: 502 Server Error: Bad Gateway for url: https://cdn-secure.buienalarm.nl/api/3.4/forecast.php?lat=50.878800118427755&lon=4.749415398691782&region=nl&unit=mm%2Fu
2021-09-27 21:00:05 ERROR (MainThread) [homeassistant.components.speedtestdotnet] Error fetching speedtestdotnet data: Unable to connect to servers to test latency.
2021-09-27 21:00:38 WARNING (SyncWorker_17) [buienalarm.pybuienalarm] Error fetching data safely: 502 Server Error: Bad Gateway for url: https://cdn-secure.buienalarm.nl/api/3.4/forecast.php?lat=50.878800118427755&lon=4.749415398691782&region=nl&unit=mm%2Fu
2021-09-27 21:01:19 ERROR (MainThread) [custom_components.hacs] atomic7777/atomic_calendar - Repository is archived.
2021-09-27 21:15:38 WARNING (SyncWorker_13) [buienalarm.pybuienalarm] Error fetching data safely: 502 Server Error: Bad Gateway for url: https://cdn-secure.buienalarm.nl/api/3.4/forecast.php?lat=50.878800118427755&lon=4.749415398691782&region=nl&unit=mm%2Fu
2021-09-27 21:40:38 WARNING (SyncWorker_4) [buienalarm.pybuienalarm] Error fetching data safely: 502 Server Error: Bad Gateway for url: https://cdn-secure.buienalarm.nl/api/3.4/forecast.php?lat=50.878800118427755&lon=4.749415398691782&region=nl&unit=mm%2Fu
2021-09-27 22:20:38 WARNING (SyncWorker_14) [buienalarm.pybuienalarm] Error fetching data safely: 502 Server Error: Bad Gateway for url: https://cdn-secure.buienalarm.nl/api/3.4/forecast.php?lat=50.878800118427755&lon=4.749415398691782&region=nl&unit=mm%2Fu
2021-09-27 22:25:38 WARNING (SyncWorker_16) [buienalarm.pybuienalarm] Error fetching data safely: 503 Server Error: Service Unavailable for url: https://cdn-secure.buienalarm.nl/api/3.4/forecast.php?lat=50.878800118427755&lon=4.749415398691782&region=nl&unit=mm%2Fu
2021-09-27 22:40:48 WARNING (SyncWorker_4) [buienalarm.pybuienalarm] Error fetching data safely: HTTPSConnectionPool(host='cdn-secure.buienalarm.nl', port=443): Read timed out. (read timeout=10.0)
2021-09-27 22:55:48 WARNING (SyncWorker_6) [buienalarm.pybuienalarm] Error fetching data safely: 502 Server Error: Bad Gateway for url: https://cdn-secure.buienalarm.nl/api/3.4/forecast.php?lat=50.878800118427755&lon=4.749415398691782&region=nl&unit=mm%2Fu
2021-09-27 23:00:48 WARNING (SyncWorker_14) [buienalarm.pybuienalarm] Error fetching data safely: 502 Server Error: Bad Gateway for url: https://cdn-secure.buienalarm.nl/api/3.4/forecast.php?lat=50.878800118427755&lon=4.749415398691782&region=nl&unit=mm%2Fu
2021-09-28 00:00:48 WARNING (SyncWorker_6) [buienalarm.pybuienalarm] Error fetching data safely: 502 Server Error: Bad Gateway for url: https://cdn-secure.buienalarm.nl/api/3.4/forecast.php?lat=50.878800118427755&lon=4.749415398691782&region=nl&unit=mm%2Fu
2021-09-28 00:20:48 WARNING (SyncWorker_3) [buienalarm.pybuienalarm] Error fetching data safely: 502 Server Error: Bad Gateway for url: https://cdn-secure.buienalarm.nl/api/3.4/forecast.php?lat=50.878800118427755&lon=4.749415398691782&region=nl&unit=mm%2Fu
2021-09-28 00:24:42 WARNING (Thread-21) [pychromecast.socket_client] [Living Chromecast(192.168.86.32):8009] Heartbeat timeout, resetting connection
2021-09-28 00:24:57 ERROR (Thread-21) [pychromecast.socket_client] [Living Chromecast(192.168.86.32):8009] Failed to connect to service ServiceInfo(type='host', data=('192.168.86.32', 8009)), retrying in 5.0s
2021-09-28 00:33:25 WARNING (Thread-23) [pychromecast.socket_client] [Master bedroom speaker(192.168.86.42):8009] Heartbeat timeout, resetting connection
2021-09-28 00:39:51 ERROR (SyncWorker_10) [glocaltokens.client] [Device - Nest Wifi router(id=2f2a9d15-0ae2-4ffe-b6c1-2ef24c742b8a)] local_auth_token must follow the correct format
2021-09-28 00:39:51 ERROR (SyncWorker_10) [glocaltokens.client] [Device - Nest Wifi router(id=e1e5a8d5-d21f-444d-95a9-c76d78c9bc79)] local_auth_token must follow the correct format
2021-09-28 00:39:51 ERROR (SyncWorker_10) [glocaltokens.client] [Device - Nest Wifi router(id=ea3de37c-ca74-4689-8171-1681b2f4f924)] local_auth_token must follow the correct format
2021-09-28 00:45:05 ERROR (MainThread) [custom_components.googlewifi] Error fetching GoogleWifi data: Error connecting to GoogleWifi: 
2021-09-28 00:55:48 WARNING (SyncWorker_6) [buienalarm.pybuienalarm] Error fetching data safely: 502 Server Error: Bad Gateway for url: https://cdn-secure.buienalarm.nl/api/3.4/forecast.php?lat=50.878800118427755&lon=4.749415398691782&region=nl&unit=mm%2Fu
2021-09-28 01:22:21 ERROR (Thread-17) [pychromecast.socket_client] [Groep_living_veranda(192.168.86.244):32106] Error reading from socket.
2021-09-28 01:22:21 WARNING (Thread-17) [pychromecast.socket_client] [Groep_living_veranda(192.168.86.244):32106] Error communicating with socket, resetting connection
2021-09-28 01:22:21 ERROR (Thread-18) [pychromecast.socket_client] [Living speaker(192.168.86.244):8009] Error reading from socket.
2021-09-28 01:22:21 WARNING (Thread-18) [pychromecast.socket_client] [Living speaker(192.168.86.244):8009] Error communicating with socket, resetting connection
2021-09-28 01:22:21 ERROR (Thread-17) [pychromecast.socket_client] [Groep_living_veranda(192.168.86.244):32106] Failed to connect to service ServiceInfo(type='host', data=('192.168.86.244', 32106)), retrying in 5.0s
2021-09-28 01:22:21 ERROR (Thread-18) [pychromecast.socket_client] [Living speaker(192.168.86.244):8009] Failed to connect to service ServiceInfo(type='mdns', data='google-nest-hub-f462ed96d0e5940e88b752d709fcc230._googlecast._tcp.local.'), retrying in 5.0s
2021-09-28 01:26:26 ERROR (SyncWorker_11) [glocaltokens.client] [Device - Nest Wifi router(id=2f2a9d15-0ae2-4ffe-b6c1-2ef24c742b8a)] local_auth_token must follow the correct format
2021-09-28 01:26:26 ERROR (SyncWorker_11) [glocaltokens.client] [Device - Nest Wifi router(id=e1e5a8d5-d21f-444d-95a9-c76d78c9bc79)] local_auth_token must follow the correct format
2021-09-28 01:26:26 ERROR (SyncWorker_11) [glocaltokens.client] [Device - Nest Wifi router(id=ea3de37c-ca74-4689-8171-1681b2f4f924)] local_auth_token must follow the correct format
2021-09-28 01:35:48 WARNING (SyncWorker_13) [buienalarm.pybuienalarm] Error fetching data safely: 502 Server Error: Bad Gateway for url: https://cdn-secure.buienalarm.nl/api/3.4/forecast.php?lat=50.878800118427755&lon=4.749415398691782&region=nl&unit=mm%2Fu
2021-09-28 01:40:48 WARNING (SyncWorker_13) [buienalarm.pybuienalarm] Error fetching data safely: 502 Server Error: Bad Gateway for url: https://cdn-secure.buienalarm.nl/api/3.4/forecast.php?lat=50.878800118427755&lon=4.749415398691782&region=nl&unit=mm%2Fu
2021-09-28 02:00:48 WARNING (SyncWorker_15) [buienalarm.pybuienalarm] Error fetching data safely: 502 Server Error: Bad Gateway for url: https://cdn-secure.buienalarm.nl/api/3.4/forecast.php?lat=50.878800118427755&lon=4.749415398691782&region=nl&unit=mm%2Fu
2021-09-28 02:15:48 WARNING (SyncWorker_2) [buienalarm.pybuienalarm] Error fetching data safely: 502 Server Error: Bad Gateway for url: https://cdn-secure.buienalarm.nl/api/3.4/forecast.php?lat=50.878800118427755&lon=4.749415398691782&region=nl&unit=mm%2Fu
2021-09-28 02:20:48 WARNING (SyncWorker_8) [buienalarm.pybuienalarm] Error fetching data safely: 502 Server Error: Bad Gateway for url: https://cdn-secure.buienalarm.nl/api/3.4/forecast.php?lat=50.878800118427755&lon=4.749415398691782&region=nl&unit=mm%2Fu
2021-09-28 02:34:42 WARNING (Thread-16) [pychromecast.socket_client] [(192.168.86.35):8009] Heartbeat timeout, resetting connection
2021-09-28 02:40:57 ERROR (SyncWorker_17) [glocaltokens.client] [Device - Nest Wifi router(id=2f2a9d15-0ae2-4ffe-b6c1-2ef24c742b8a)] local_auth_token must follow the correct format
2021-09-28 02:40:57 ERROR (SyncWorker_17) [glocaltokens.client] [Device - Nest Wifi router(id=e1e5a8d5-d21f-444d-95a9-c76d78c9bc79)] local_auth_token must follow the correct format
2021-09-28 02:40:57 ERROR (SyncWorker_17) [glocaltokens.client] [Device - Nest Wifi router(id=ea3de37c-ca74-4689-8171-1681b2f4f924)] local_auth_token must follow the correct format
2021-09-28 02:40:58 WARNING (Thread-20) [pychromecast.socket_client] [Alunya speaker(192.168.86.37):8009] Heartbeat timeout, resetting connection
2021-09-28 02:41:14 ERROR (Thread-20) [pychromecast.socket_client] [Alunya speaker(192.168.86.37):8009] Failed to connect to service ServiceInfo(type='host', data=('192.168.86.37', 8009)), retrying in 5.0s
2021-09-28 02:55:48 WARNING (SyncWorker_15) [buienalarm.pybuienalarm] Error fetching data safely: 502 Server Error: Bad Gateway for url: https://cdn-secure.buienalarm.nl/api/3.4/forecast.php?lat=50.878800118427755&lon=4.749415398691782&region=nl&unit=mm%2Fu
2021-09-28 03:00:48 WARNING (SyncWorker_8) [buienalarm.pybuienalarm] Error fetching data safely: 502 Server Error: Bad Gateway for url: https://cdn-secure.buienalarm.nl/api/3.4/forecast.php?lat=50.878800118427755&lon=4.749415398691782&region=nl&unit=mm%2Fu
2021-09-28 03:20:48 WARNING (SyncWorker_11) [buienalarm.pybuienalarm] Error fetching data safely: 502 Server Error: Bad Gateway for url: https://cdn-secure.buienalarm.nl/api/3.4/forecast.php?lat=50.878800118427755&lon=4.749415398691782&region=nl&unit=mm%2Fu
2021-09-28 04:40:31 ERROR (MainThread) [homeassistant.components.scrape.sensor] Unable to extract data from HTML for uvindex_leuven24_wunderground
2021-09-28 04:40:34 ERROR (MainThread) [homeassistant.components.scrape.sensor] Unable to extract data from HTML for precip_total_leuven24_wunderground
2021-09-28 04:40:48 WARNING (SyncWorker_10) [buienalarm.pybuienalarm] Error fetching data safely: 502 Server Error: Bad Gateway for url: https://cdn-secure.buienalarm.nl/api/3.4/forecast.php?lat=50.878800118427755&lon=4.749415398691782&region=nl&unit=mm%2Fu
2021-09-28 05:10:19 ERROR (MainThread) [custom_components.googlewifi] Error fetching GoogleWifi data: Error connecting to GoogleWifi: 
2021-09-28 05:20:48 WARNING (SyncWorker_17) [buienalarm.pybuienalarm] Error fetching data safely: 502 Server Error: Bad Gateway for url: https://cdn-secure.buienalarm.nl/api/3.4/forecast.php?lat=50.878800118427755&lon=4.749415398691782&region=nl&unit=mm%2Fu
2021-09-28 05:39:00 ERROR (Thread-22) [pychromecast.socket_client] [Master Bedroom TV(192.168.86.40):8009] Error reading from socket.
2021-09-28 05:39:00 WARNING (Thread-22) [pychromecast.socket_client] [Master Bedroom TV(192.168.86.40):8009] Error communicating with socket, resetting connection
2021-09-28 05:48:24 WARNING (MainThread) [homeassistant.helpers.service] Unable to find referenced entities media_player.veranda_speaker_2
2021-09-28 05:51:51 WARNING (MainThread) [homeassistant.helpers.service] Unable to find referenced entities media_player.veranda_speaker_2
2021-09-28 05:54:21 WARNING (MainThread) [homeassistant.helpers.service] Unable to find referenced entities media_player.veranda_speaker_2
2021-09-28 05:58:26 WARNING (MainThread) [homeassistant.helpers.service] Unable to find referenced entities media_player.veranda_speaker_2
2021-09-28 06:00:48 WARNING (SyncWorker_17) [buienalarm.pybuienalarm] Error fetching data safely: 502 Server Error: Bad Gateway for url: https://cdn-secure.buienalarm.nl/api/3.4/forecast.php?lat=50.878800118427755&lon=4.749415398691782&region=nl&unit=mm%2Fu
2021-09-28 06:20:48 WARNING (SyncWorker_7) [buienalarm.pybuienalarm] Error fetching data safely: 502 Server Error: Bad Gateway for url: https://cdn-secure.buienalarm.nl/api/3.4/forecast.php?lat=50.878800118427755&lon=4.749415398691782&region=nl&unit=mm%2Fu
2021-09-28 06:37:03 ERROR (MainThread) [homeassistant.config] Invalid config for [automation]: required key not provided @ data['action'][4]['domain']. Got None. (See ?, line ?). 
2021-09-28 06:37:03 ERROR (MainThread) [homeassistant.config] Invalid config for [automation]: [title] is an invalid option for [automation]. Check: automation->action->1->title. (See ?, line ?). 
2021-09-28 06:37:03 ERROR (MainThread) [homeassistant.config] Invalid config for [automation]: must be a value between 0 and 59 for dictionary value @ data['minutes']. Got None. (See ?, line ?). 
2021-09-28 06:37:03 ERROR (MainThread) [homeassistant.config] Invalid config for [automation]: must be a value between 0 and 59 for dictionary value @ data['minutes']. Got None. (See ?, line ?). 
2021-09-28 06:37:10 ERROR (MainThread) [homeassistant.config] Invalid config for [automation]: required key not provided @ data['action'][4]['domain']. Got None. (See ?, line ?). 
2021-09-28 06:37:10 ERROR (MainThread) [homeassistant.config] Invalid config for [automation]: [title] is an invalid option for [automation]. Check: automation->action->1->title. (See ?, line ?). 
2021-09-28 06:37:10 ERROR (MainThread) [homeassistant.config] Invalid config for [automation]: must be a value between 0 and 59 for dictionary value @ data['minutes']. Got None. (See ?, line ?). 
2021-09-28 06:37:10 ERROR (MainThread) [homeassistant.config] Invalid config for [automation]: must be a value between 0 and 59 for dictionary value @ data['minutes']. Got None. (See ?, line ?). 
