2021-10-10 17:16:27 WARNING (SyncWorker_0) [homeassistant.loader] We found a custom integration average which has not been tested by Home Assistant. This component might cause stability problems, be sure to disable it if you experience issues with Home Assistant
2021-10-10 17:16:27 WARNING (SyncWorker_1) [homeassistant.loader] We found a custom integration xiaomi_miio_airpurifier which has not been tested by Home Assistant. This component might cause stability problems, be sure to disable it if you experience issues with Home Assistant
2021-10-10 17:16:27 WARNING (SyncWorker_3) [homeassistant.loader] We found a custom integration powercalc which has not been tested by Home Assistant. This component might cause stability problems, be sure to disable it if you experience issues with Home Assistant
2021-10-10 17:16:27 WARNING (SyncWorker_2) [homeassistant.loader] We found a custom integration audiconnect which has not been tested by Home Assistant. This component might cause stability problems, be sure to disable it if you experience issues with Home Assistant
2021-10-10 17:16:27 WARNING (SyncWorker_4) [homeassistant.loader] We found a custom integration monitor_docker which has not been tested by Home Assistant. This component might cause stability problems, be sure to disable it if you experience issues with Home Assistant
2021-10-10 17:16:27 WARNING (SyncWorker_0) [homeassistant.loader] We found a custom integration localtuya which has not been tested by Home Assistant. This component might cause stability problems, be sure to disable it if you experience issues with Home Assistant
2021-10-10 17:16:27 WARNING (SyncWorker_6) [homeassistant.loader] We found a custom integration xiaomi_miio_fan which has not been tested by Home Assistant. This component might cause stability problems, be sure to disable it if you experience issues with Home Assistant
2021-10-10 17:16:27 WARNING (SyncWorker_5) [homeassistant.loader] We found a custom integration huesyncbox which has not been tested by Home Assistant. This component might cause stability problems, be sure to disable it if you experience issues with Home Assistant
2021-10-10 17:16:27 WARNING (SyncWorker_1) [homeassistant.loader] We found a custom integration hacs which has not been tested by Home Assistant. This component might cause stability problems, be sure to disable it if you experience issues with Home Assistant
2021-10-10 17:16:27 WARNING (SyncWorker_8) [homeassistant.loader] We found a custom integration buienalarm which has not been tested by Home Assistant. This component might cause stability problems, be sure to disable it if you experience issues with Home Assistant
2021-10-10 17:16:27 WARNING (SyncWorker_3) [homeassistant.loader] We found a custom integration thermal_comfort which has not been tested by Home Assistant. This component might cause stability problems, be sure to disable it if you experience issues with Home Assistant
2021-10-10 17:16:27 WARNING (SyncWorker_7) [homeassistant.loader] We found a custom integration shelly which has not been tested by Home Assistant. This component might cause stability problems, be sure to disable it if you experience issues with Home Assistant
2021-10-10 17:16:27 WARNING (SyncWorker_0) [homeassistant.loader] We found a custom integration anniversaries which has not been tested by Home Assistant. This component might cause stability problems, be sure to disable it if you experience issues with Home Assistant
2021-10-10 17:16:27 WARNING (SyncWorker_2) [homeassistant.loader] We found a custom integration xiaomi_miot which has not been tested by Home Assistant. This component might cause stability problems, be sure to disable it if you experience issues with Home Assistant
2021-10-10 17:16:27 WARNING (SyncWorker_4) [homeassistant.loader] We found a custom integration googlewifi which has not been tested by Home Assistant. This component might cause stability problems, be sure to disable it if you experience issues with Home Assistant
2021-10-10 17:16:27 WARNING (SyncWorker_5) [homeassistant.loader] We found a custom integration deepstack_face which has not been tested by Home Assistant. This component might cause stability problems, be sure to disable it if you experience issues with Home Assistant
2021-10-10 17:16:27 WARNING (SyncWorker_6) [homeassistant.loader] We found a custom integration ytube_music_player which has not been tested by Home Assistant. This component might cause stability problems, be sure to disable it if you experience issues with Home Assistant
2021-10-10 17:16:27 WARNING (SyncWorker_9) [homeassistant.loader] We found a custom integration afvalbeheer which has not been tested by Home Assistant. This component might cause stability problems, be sure to disable it if you experience issues with Home Assistant
2021-10-10 17:16:27 WARNING (SyncWorker_10) [homeassistant.loader] We found a custom integration google_home which has not been tested by Home Assistant. This component might cause stability problems, be sure to disable it if you experience issues with Home Assistant
2021-10-10 17:16:34 ERROR (MainThread) [homeassistant.config] Invalid config for [automation]: required key not provided @ data['action'][4]['domain']. Got None. (See ?, line ?). 
2021-10-10 17:16:34 ERROR (MainThread) [homeassistant.config] Invalid config for [automation]: [title] is an invalid option for [automation]. Check: automation->action->1->title. (See ?, line ?). 
2021-10-10 17:16:35 ERROR (MainThread) [homeassistant.config] Invalid config for [automation]: must be a value between 0 and 59 for dictionary value @ data['minutes']. Got None. (See ?, line ?). 
2021-10-10 17:16:35 ERROR (MainThread) [homeassistant.config] Invalid config for [automation]: must be a value between 0 and 59 for dictionary value @ data['minutes']. Got None. (See ?, line ?). 
2021-10-10 17:16:40 WARNING (MainThread) [homeassistant.components.fan] Platform xiaomi_miio_fan not ready yet: Unable to discover the device 192.168.86.29; Retrying in background in 30 seconds
2021-10-10 17:16:40 WARNING (MainThread) [homeassistant.components.fan] Platform xiaomi_miio_fan not ready yet: Unable to discover the device 192.168.86.28; Retrying in background in 30 seconds
2021-10-10 17:16:41 WARNING (MainThread) [homeassistant.components.webhook] Received message for unregistered webhook 8b8f82ade2e454d538c7b1b55e021814b7aa12b9fa3693773bc28dc044af0487 from 192.168.86.34
2021-10-10 17:16:41 WARNING (MainThread) [homeassistant.setup] Setup of input_number is taking over 10 seconds.
2021-10-10 17:16:43 WARNING (MainThread) [homeassistant.config_entries] Config entry '192.168.86.83' for synology_dsm integration not ready yet: ConnectionError = <urllib3.connection.HTTPSConnection object at 0xffffa39f2eb0>: Failed to establish a new connection: [Errno 113] Host is unreachable; Retrying in background
2021-10-10 17:16:44 WARNING (MainThread) [homeassistant.components.light] Platform netatmo not ready yet: None; Retrying in background in 30 seconds
2021-10-10 17:16:45 WARNING (MainThread) [homeassistant.components.hue.light] Please check for software updates of the douche bulb in the Philips Hue App.
2021-10-10 17:16:45 WARNING (MainThread) [homeassistant.components.hue.light] Please check for software updates of the wasbak rechts bulb in the Philips Hue App.
2021-10-10 17:16:45 WARNING (MainThread) [homeassistant.components.hue.light] Please check for software updates of the bad bulb in the Philips Hue App.
2021-10-10 17:16:45 WARNING (MainThread) [homeassistant.components.hue.light] Please check for software updates of the Inkomhal bulb in the Philips Hue App.
2021-10-10 17:16:45 WARNING (MainThread) [homeassistant.components.hue.light] Please check for software updates of the Amilya plafond 2 bulb in the Philips Hue App.
2021-10-10 17:16:45 WARNING (MainThread) [homeassistant.components.hue.light] Please check for software updates of the Amilya plafond 1 bulb in the Philips Hue App.
2021-10-10 17:16:45 WARNING (MainThread) [homeassistant.components.select] Platform netatmo not ready yet: None; Retrying in background in 30 seconds
2021-10-10 17:16:46 WARNING (MainThread) [homeassistant.components.sensor] Platform netatmo not ready yet: None; Retrying in background in 30 seconds
2021-10-10 17:16:48 ERROR (SyncWorker_9) [glocaltokens.client] [Device - Nest Wifi router(id=2f2a9d15-0ae2-4ffe-b6c1-2ef24c742b8a)] local_auth_token must follow the correct format
2021-10-10 17:16:48 ERROR (SyncWorker_9) [glocaltokens.client] [Device - Nest Wifi router(id=e1e5a8d5-d21f-444d-95a9-c76d78c9bc79)] local_auth_token must follow the correct format
2021-10-10 17:16:48 ERROR (SyncWorker_9) [glocaltokens.client] [Device - Nest Wifi router(id=ea3de37c-ca74-4689-8171-1681b2f4f924)] local_auth_token must follow the correct format
2021-10-10 17:16:48 ERROR (MainThread) [homeassistant.components.sensor] scrape: Error on device update!
Traceback (most recent call last):
  File "/usr/src/homeassistant/homeassistant/helpers/entity_platform.py", line 431, in _async_add_entity
    await entity.async_device_update(warning=False)
  File "/usr/src/homeassistant/homeassistant/helpers/entity.py", line 618, in async_device_update
    await task
  File "/usr/src/homeassistant/homeassistant/components/scrape/sensor.py", line 139, in async_update
    await self._async_update_from_rest_data()
  File "/usr/src/homeassistant/homeassistant/components/scrape/sensor.py", line 152, in _async_update_from_rest_data
    value = await self.hass.async_add_executor_job(self._extract_value)
  File "/usr/local/lib/python3.9/concurrent/futures/thread.py", line 52, in run
    result = self.fn(*self.args, **self.kwargs)
  File "/usr/src/homeassistant/homeassistant/components/scrape/sensor.py", line 128, in _extract_value
    tag = raw_data.select(self._select)[self._index]
  File "/usr/local/lib/python3.9/site-packages/bs4/element.py", line 1949, in select
    results = soupsieve.select(selector, self, namespaces, limit, **kwargs)
  File "/usr/local/lib/python3.9/site-packages/soupsieve/__init__.py", line 98, in select
    return compile(select, namespaces, flags, **kwargs).select(tag, limit)
  File "/usr/local/lib/python3.9/site-packages/soupsieve/__init__.py", line 62, in compile
    return cp._cached_css_compile(pattern, namespaces, custom, flags)
  File "/usr/local/lib/python3.9/site-packages/soupsieve/css_parser.py", line 211, in _cached_css_compile
    CSSParser(pattern, custom=custom_selectors, flags=flags).process_selectors(),
  File "/usr/local/lib/python3.9/site-packages/soupsieve/css_parser.py", line 1058, in process_selectors
    return self.parse_selectors(self.selector_iter(self.pattern), index, flags)
  File "/usr/local/lib/python3.9/site-packages/soupsieve/css_parser.py", line 909, in parse_selectors
    key, m = next(iselector)
  File "/usr/local/lib/python3.9/site-packages/soupsieve/css_parser.py", line 1051, in selector_iter
    raise SelectorSyntaxError(msg, self.pattern, index)
soupsieve.util.SelectorSyntaxError: Invalid character '<' position 0
  line 1:
<span _ngcontent-app-root-c173="">Offline</span>
^
2021-10-10 17:16:52 WARNING (MainThread) [homeassistant.config_entries] Config entry 'OnHub' for upnp integration not ready yet; Retrying in background
2021-10-10 17:16:57 WARNING (MainThread) [homeassistant.helpers.template] Template warning: 'float' got invalid input 'unknown' when rendering template '{{ states('sensor.tv_living_on_today') | float * 0.085 | round(3) }}' but no default was specified. Currently 'float' will return '0', however this template will fail to render in Home Assistant core 2021.12
2021-10-10 17:16:57 WARNING (MainThread) [homeassistant.helpers.template] Template warning: 'float' got invalid input 'unknown' when rendering template '{{ states('sensor.tv_living_on_today') | float * 0.085 | round(3) }}' but no default was specified. Currently 'float' will return '0', however this template will fail to render in Home Assistant core 2021.12
2021-10-10 17:16:57 WARNING (MainThread) [homeassistant.helpers.template] Template warning: 'float' got invalid input 'unknown' when rendering template '{{ states('sensor.master_bedroom_TV_on_today') | float * 0.063 | round(3) }}' but no default was specified. Currently 'float' will return '0', however this template will fail to render in Home Assistant core 2021.12
2021-10-10 17:16:57 WARNING (MainThread) [homeassistant.helpers.template] Template warning: 'float' got invalid input 'unknown' when rendering template '{{ states('sensor.master_bedroom_TV_on_today') | float * 0.063 | round(3) }}' but no default was specified. Currently 'float' will return '0', however this template will fail to render in Home Assistant core 2021.12
2021-10-10 17:17:07 WARNING (MainThread) [homeassistant.components.media_player] Updating huesyncbox media_player took longer than the scheduled update interval 0:00:02
2021-10-10 17:17:14 WARNING (MainThread) [homeassistant.components.media_player] Updating huesyncbox media_player took longer than the scheduled update interval 0:00:02
2021-10-10 17:17:15 ERROR (MainThread) [homeassistant.components.google_assistant.http] Request for https://homegraph.googleapis.com/v1/devices:requestSync failed: 500
2021-10-10 17:17:18 WARNING (MainThread) [homeassistant.components.media_player] Updating huesyncbox media_player took longer than the scheduled update interval 0:00:02
2021-10-10 17:17:35 ERROR (MainThread) [homeassistant.components.google_assistant.http] Request for https://homegraph.googleapis.com/v1/devices:reportStateAndNotification failed: 404
2021-10-10 17:20:53 WARNING (MainThread) [homeassistant.helpers.template] Template warning: 'float' got invalid input 'unknown' when rendering template '{{ states('sensor.gram_badkamer_diff_outside') | float >= 1 }}' but no default was specified. Currently 'float' will return '0', however this template will fail to render in Home Assistant core 2021.12
2021-10-10 17:20:53 WARNING (MainThread) [homeassistant.helpers.template] Template warning: 'float' got invalid input 'unknown' when rendering template '{{ states('sensor.gram_badkamer_diff_outside') | float >= 1 }}' but no default was specified. Currently 'float' will return '0', however this template will fail to render in Home Assistant core 2021.12
2021-10-10 17:23:19 WARNING (MainThread) [homeassistant.helpers.service] Unable to find referenced entities media_player.veranda_speaker_2
2021-10-10 17:26:54 ERROR (MainThread) [custom_components.audiconnect.audi_connect_account] Unable to update the vehicle position of WAUZZZGE6MB019131: 204, message='No Content', url=URL('https://fal-3a.prd.eu.dp.vwg-connect.com/fs-car/bs/cf/v1/Audi/BE/vehicles/WAUZZZGE6MB019131/position')
2021-10-10 17:29:43 WARNING (MainThread) [homeassistant.helpers.service] Unable to find referenced entities media_player.veranda_speaker_2
2021-10-10 17:39:09 ERROR (MainThread) [custom_components.googlewifi] Unexpected error fetching GoogleWifi data: 'NoneType' object is not iterable
Traceback (most recent call last):
  File "/usr/src/homeassistant/homeassistant/helpers/update_coordinator.py", line 187, in _async_refresh
    self.data = await self._async_update_data()
  File "/config/custom_components/googlewifi/__init__.py", line 171, in _async_update_data
    system_data = await self.api.get_systems()
  File "/usr/local/lib/python3.9/site-packages/googlewifi/__init__.py", line 191, in get_systems
    return await self.structure_systems(response)
  File "/usr/local/lib/python3.9/site-packages/googlewifi/__init__.py", line 289, in structure_systems
    for this_station in system_metrics.get("stationMetrics"):
TypeError: 'NoneType' object is not iterable
2021-10-10 17:52:45 ERROR (MainThread) [custom_components.googlewifi] Unexpected error fetching GoogleWifi data: 'NoneType' object is not iterable
Traceback (most recent call last):
  File "/usr/src/homeassistant/homeassistant/helpers/update_coordinator.py", line 187, in _async_refresh
    self.data = await self._async_update_data()
  File "/config/custom_components/googlewifi/__init__.py", line 171, in _async_update_data
    system_data = await self.api.get_systems()
  File "/usr/local/lib/python3.9/site-packages/googlewifi/__init__.py", line 191, in get_systems
    return await self.structure_systems(response)
  File "/usr/local/lib/python3.9/site-packages/googlewifi/__init__.py", line 289, in structure_systems
    for this_station in system_metrics.get("stationMetrics"):
TypeError: 'NoneType' object is not iterable
2021-10-10 17:55:00 WARNING (MainThread) [homeassistant.components.automation] Error evaluating condition in '💨 Air Quality Index < 8 = purifier off':
In 'condition':
  In 'numeric_state':
    In 'numeric_state' condition: entity fan.xiaomi_air_purifier_3h state 'None' cannot be processed as a number
2021-10-10 18:06:56 ERROR (MainThread) [homeassistant.components.scrape.sensor] Unable to extract data from HTML for precip_total_leuven24_wunderground
2021-10-10 18:07:51 ERROR (MainThread) [homeassistant.components.scrape.sensor] Unable to extract data from HTML for precip_rate_leuven24_wunderground
2021-10-10 18:08:49 ERROR (MainThread) [homeassistant.components.scrape.sensor] Unable to extract data from HTML for humidity_leuven24_wunderground
2021-10-10 18:08:49 ERROR (MainThread) [homeassistant.components.scrape.sensor] Unable to extract data from HTML for temp_leuven24_wunderground
2021-10-10 18:10:51 ERROR (MainThread) [homeassistant.components.scrape.sensor] Unable to extract data from HTML for precip_rate_leuven24_wunderground
2021-10-10 18:16:28 ERROR (MainThread) [custom_components.googlewifi] Error fetching GoogleWifi data: Error connecting to GoogleWifi: 
2021-10-10 18:18:41 ERROR (MainThread) [custom_components.googlewifi] Error fetching GoogleWifi data: Error connecting to GoogleWifi: 
2021-10-10 18:19:21 ERROR (MainThread) [custom_components.googlewifi] Unexpected error fetching GoogleWifi data: 'NoneType' object is not iterable
Traceback (most recent call last):
  File "/usr/src/homeassistant/homeassistant/helpers/update_coordinator.py", line 187, in _async_refresh
    self.data = await self._async_update_data()
  File "/config/custom_components/googlewifi/__init__.py", line 171, in _async_update_data
    system_data = await self.api.get_systems()
  File "/usr/local/lib/python3.9/site-packages/googlewifi/__init__.py", line 191, in get_systems
    return await self.structure_systems(response)
  File "/usr/local/lib/python3.9/site-packages/googlewifi/__init__.py", line 289, in structure_systems
    for this_station in system_metrics.get("stationMetrics"):
TypeError: 'NoneType' object is not iterable
2021-10-10 18:32:20 WARNING (MainThread) [homeassistant.helpers.service] Unable to find referenced entities media_player.veranda_speaker_2
2021-10-10 18:35:05 ERROR (MainThread) [custom_components.googlewifi] Error fetching GoogleWifi data: Error connecting to GoogleWifi: 
2021-10-10 18:44:49 WARNING (MainThread) [homeassistant.helpers.template] Template warning: 'float' got invalid input 'unknown' when rendering template '{{ states('sensor.gram_badkamer_diff_outside') | float >= 1 }}' but no default was specified. Currently 'float' will return '0', however this template will fail to render in Home Assistant core 2021.12
2021-10-10 18:52:49 WARNING (MainThread) [homeassistant.helpers.template] Template warning: 'float' got invalid input 'unknown' when rendering template '{{ states('sensor.gram_badkamer_diff_outside') | float >= 1 }}' but no default was specified. Currently 'float' will return '0', however this template will fail to render in Home Assistant core 2021.12
2021-10-10 18:56:49 WARNING (MainThread) [homeassistant.helpers.template] Template warning: 'float' got invalid input 'unknown' when rendering template '{{ states('sensor.gram_badkamer_diff_outside') | float >= 1 }}' but no default was specified. Currently 'float' will return '0', however this template will fail to render in Home Assistant core 2021.12
2021-10-10 18:56:49 WARNING (MainThread) [homeassistant.helpers.template] Template warning: 'float' got invalid input 'unknown' when rendering template '{{ states('sensor.gram_badkamer_diff_outside') | float >= 1 }}' but no default was specified. Currently 'float' will return '0', however this template will fail to render in Home Assistant core 2021.12
2021-10-10 18:58:18 ERROR (MainThread) [custom_components.googlewifi] Error fetching GoogleWifi data: Error connecting to GoogleWifi: 
2021-10-10 18:59:37 ERROR (MainThread) [custom_components.googlewifi] Unexpected error fetching GoogleWifi data: 'operationState'
Traceback (most recent call last):
  File "/usr/src/homeassistant/homeassistant/helpers/update_coordinator.py", line 187, in _async_refresh
    self.data = await self._async_update_data()
  File "/config/custom_components/googlewifi/__init__.py", line 171, in _async_update_data
    system_data = await self.api.get_systems()
  File "/usr/local/lib/python3.9/site-packages/googlewifi/__init__.py", line 191, in get_systems
    return await self.structure_systems(response)
  File "/usr/local/lib/python3.9/site-packages/googlewifi/__init__.py", line 284, in structure_systems
    sensitive_info = await self.get_sensitive_info(system_id=this_system["id"], station_ids=station_ids)
  File "/usr/local/lib/python3.9/site-packages/googlewifi/__init__.py", line 616, in get_sensitive_info
    status = status["operationState"]
KeyError: 'operationState'
2021-10-10 19:04:49 WARNING (MainThread) [homeassistant.helpers.template] Template warning: 'float' got invalid input 'unknown' when rendering template '{{ states('sensor.gram_badkamer_diff_outside') | float >= 1 }}' but no default was specified. Currently 'float' will return '0', however this template will fail to render in Home Assistant core 2021.12
2021-10-10 19:08:49 WARNING (MainThread) [homeassistant.helpers.template] Template warning: 'float' got invalid input 'unknown' when rendering template '{{ states('sensor.gram_badkamer_diff_outside') | float >= 1 }}' but no default was specified. Currently 'float' will return '0', however this template will fail to render in Home Assistant core 2021.12
2021-10-10 19:08:49 WARNING (MainThread) [homeassistant.helpers.template] Template warning: 'float' got invalid input 'unknown' when rendering template '{{ states('sensor.gram_badkamer_diff_outside') | float >= 1 }}' but no default was specified. Currently 'float' will return '0', however this template will fail to render in Home Assistant core 2021.12
2021-10-10 19:15:58 ERROR (MainThread) [homeassistant.config] Invalid config for [automation]: required key not provided @ data['action'][4]['domain']. Got None. (See ?, line ?). 
2021-10-10 19:15:58 ERROR (MainThread) [homeassistant.config] Invalid config for [automation]: [title] is an invalid option for [automation]. Check: automation->action->1->title. (See ?, line ?). 
2021-10-10 19:15:58 ERROR (MainThread) [homeassistant.config] Invalid config for [automation]: must be a value between 0 and 59 for dictionary value @ data['minutes']. Got None. (See ?, line ?). 
2021-10-10 19:15:58 ERROR (MainThread) [homeassistant.config] Invalid config for [automation]: must be a value between 0 and 59 for dictionary value @ data['minutes']. Got None. (See ?, line ?). 
2021-10-10 19:16:15 ERROR (MainThread) [homeassistant.config] Invalid config for [automation]: required key not provided @ data['action'][4]['domain']. Got None. (See ?, line ?). 
2021-10-10 19:16:15 ERROR (MainThread) [homeassistant.config] Invalid config for [automation]: [title] is an invalid option for [automation]. Check: automation->action->1->title. (See ?, line ?). 
2021-10-10 19:16:15 ERROR (MainThread) [homeassistant.config] Invalid config for [automation]: must be a value between 0 and 59 for dictionary value @ data['minutes']. Got None. (See ?, line ?). 
2021-10-10 19:16:15 ERROR (MainThread) [homeassistant.config] Invalid config for [automation]: must be a value between 0 and 59 for dictionary value @ data['minutes']. Got None. (See ?, line ?). 
