2021-11-13 13:18:22 WARNING (SyncWorker_0) [homeassistant.loader] We found a custom integration average which has not been tested by Home Assistant. This component might cause stability problems, be sure to disable it if you experience issues with Home Assistant
2021-11-13 13:18:22 WARNING (SyncWorker_1) [homeassistant.loader] We found a custom integration adaptive_lighting which has not been tested by Home Assistant. This component might cause stability problems, be sure to disable it if you experience issues with Home Assistant
2021-11-13 13:18:22 WARNING (SyncWorker_2) [homeassistant.loader] We found a custom integration xiaomi_miio_airpurifier which has not been tested by Home Assistant. This component might cause stability problems, be sure to disable it if you experience issues with Home Assistant
2021-11-13 13:18:22 WARNING (SyncWorker_3) [homeassistant.loader] We found a custom integration audiconnect which has not been tested by Home Assistant. This component might cause stability problems, be sure to disable it if you experience issues with Home Assistant
2021-11-13 13:18:22 WARNING (SyncWorker_5) [homeassistant.loader] We found a custom integration monitor_docker which has not been tested by Home Assistant. This component might cause stability problems, be sure to disable it if you experience issues with Home Assistant
2021-11-13 13:18:22 WARNING (SyncWorker_3) [homeassistant.loader] We found a custom integration hacs which has not been tested by Home Assistant. This component might cause stability problems, be sure to disable it if you experience issues with Home Assistant
2021-11-13 13:18:22 WARNING (SyncWorker_1) [homeassistant.loader] We found a custom integration tuya_v2 which has not been tested by Home Assistant. This component might cause stability problems, be sure to disable it if you experience issues with Home Assistant
2021-11-13 13:18:22 WARNING (SyncWorker_4) [homeassistant.loader] We found a custom integration powercalc which has not been tested by Home Assistant. This component might cause stability problems, be sure to disable it if you experience issues with Home Assistant
2021-11-13 13:18:22 WARNING (SyncWorker_7) [homeassistant.loader] We found a custom integration shelly which has not been tested by Home Assistant. This component might cause stability problems, be sure to disable it if you experience issues with Home Assistant
2021-11-13 13:18:22 WARNING (SyncWorker_9) [homeassistant.loader] We found a custom integration thermal_comfort which has not been tested by Home Assistant. This component might cause stability problems, be sure to disable it if you experience issues with Home Assistant
2021-11-13 13:18:22 WARNING (SyncWorker_0) [homeassistant.loader] We found a custom integration xiaomi_miio_fan which has not been tested by Home Assistant. This component might cause stability problems, be sure to disable it if you experience issues with Home Assistant
2021-11-13 13:18:22 WARNING (SyncWorker_8) [homeassistant.loader] We found a custom integration buienalarm which has not been tested by Home Assistant. This component might cause stability problems, be sure to disable it if you experience issues with Home Assistant
2021-11-13 13:18:22 WARNING (SyncWorker_6) [homeassistant.loader] We found a custom integration localtuya which has not been tested by Home Assistant. This component might cause stability problems, be sure to disable it if you experience issues with Home Assistant
2021-11-13 13:18:22 WARNING (SyncWorker_5) [homeassistant.loader] We found a custom integration huesyncbox which has not been tested by Home Assistant. This component might cause stability problems, be sure to disable it if you experience issues with Home Assistant
2021-11-13 13:18:22 WARNING (SyncWorker_3) [homeassistant.loader] We found a custom integration xiaomi_miot which has not been tested by Home Assistant. This component might cause stability problems, be sure to disable it if you experience issues with Home Assistant
2021-11-13 13:18:22 WARNING (SyncWorker_1) [homeassistant.loader] We found a custom integration ytube_music_player which has not been tested by Home Assistant. This component might cause stability problems, be sure to disable it if you experience issues with Home Assistant
2021-11-13 13:18:22 WARNING (SyncWorker_4) [homeassistant.loader] We found a custom integration anniversaries which has not been tested by Home Assistant. This component might cause stability problems, be sure to disable it if you experience issues with Home Assistant
2021-11-13 13:18:22 WARNING (SyncWorker_2) [homeassistant.loader] We found a custom integration frigate which has not been tested by Home Assistant. This component might cause stability problems, be sure to disable it if you experience issues with Home Assistant
2021-11-13 13:18:22 WARNING (SyncWorker_9) [homeassistant.loader] We found a custom integration google_home which has not been tested by Home Assistant. This component might cause stability problems, be sure to disable it if you experience issues with Home Assistant
2021-11-13 13:18:22 WARNING (SyncWorker_7) [homeassistant.loader] We found a custom integration afvalbeheer which has not been tested by Home Assistant. This component might cause stability problems, be sure to disable it if you experience issues with Home Assistant
2021-11-13 13:18:22 WARNING (SyncWorker_11) [homeassistant.loader] We found a custom integration googlewifi which has not been tested by Home Assistant. This component might cause stability problems, be sure to disable it if you experience issues with Home Assistant
2021-11-13 13:18:22 WARNING (SyncWorker_12) [homeassistant.loader] We found a custom integration deepstack_face which has not been tested by Home Assistant. This component might cause stability problems, be sure to disable it if you experience issues with Home Assistant
2021-11-13 13:18:29 ERROR (SyncWorker_9) [homeassistant.components.influxdb] Cannot connect to InfluxDB due to '<urllib3.connection.HTTPConnection object at 0xffff8ddd29a0>: Failed to establish a new connection: [Errno 111] Connection refused'. Please check that the provided connection details (host, port, etc.) are correct and that your InfluxDB server is running and accessible. Retrying in 60 seconds.
2021-11-13 13:18:31 ERROR (MainThread) [homeassistant.config] Invalid config for [automation]: expected str for dictionary value @ data['from']. Got None. (See ?, line ?). 
2021-11-13 13:18:31 ERROR (MainThread) [homeassistant.config] Invalid config for [automation]: required key not provided @ data['trigger'][1]['platform']. Got None. (See ?, line ?). 
2021-11-13 13:18:31 ERROR (MainThread) [homeassistant.config] Invalid config for [automation]: Unexpected value for condition: 'None'. Expected and, device, not, numeric_state, or, state, sun, template, time, trigger, zone @ data['condition'][0]. Got None. (See ?, line ?). 
2021-11-13 13:18:31 ERROR (MainThread) [homeassistant.config] Invalid config for [automation]: Unexpected value for condition: 'None'. Expected and, device, not, numeric_state, or, state, sun, template, time, trigger, zone @ data['condition'][0]. Got None. (See ?, line ?). 
2021-11-13 13:18:32 ERROR (MainThread) [homeassistant.config] Invalid config for [automation]: required key not provided @ data['action'][4]['domain']. Got None. (See ?, line ?). 
2021-11-13 13:18:32 ERROR (MainThread) [homeassistant.config] Invalid config for [automation]: must be a value between 0 and 59 for dictionary value @ data['minutes']. Got None. (See ?, line ?). 
2021-11-13 13:18:32 ERROR (MainThread) [homeassistant.config] Invalid config for [automation]: must be a value between 0 and 59 for dictionary value @ data['minutes']. Got None. (See ?, line ?). 
2021-11-13 13:18:37 WARNING (MainThread) [homeassistant.setup] Setup of timer is taking over 10 seconds.
2021-11-13 13:18:37 WARNING (MainThread) [homeassistant.components.fan] Platform xiaomi_miio_fan not ready yet: Unable to discover the device 192.168.86.28; Retrying in background in 30 seconds
2021-11-13 13:18:37 WARNING (MainThread) [homeassistant.components.fan] Platform xiaomi_miio_fan not ready yet: Unable to discover the device 192.168.86.29; Retrying in background in 30 seconds
2021-11-13 13:18:40 WARNING (MainThread) [homeassistant.setup] Setup of input_number is taking over 10 seconds.
2021-11-13 13:18:41 WARNING (MainThread) [homeassistant.config_entries] Config entry '192.168.86.83' for synology_dsm integration not ready yet: ConnectionError = <urllib3.connection.HTTPSConnection object at 0xffff82d657c0>: Failed to establish a new connection: [Errno 113] Host is unreachable; Retrying in background
2021-11-13 13:18:43 ERROR (MainThread) [homeassistant.config] Unknown error validating config for integration platform for sensor component with PLATFORM_SCHEMA
Traceback (most recent call last):
  File "/usr/src/homeassistant/homeassistant/config.py", line 895, in async_process_component_config
    p_validated = platform.PLATFORM_SCHEMA(p_config)  # type: ignore
  File "/usr/local/lib/python3.9/site-packages/voluptuous/validators.py", line 218, in __call__
    return self._exec((Schema(val) for val in self.validators), v)
  File "/usr/local/lib/python3.9/site-packages/voluptuous/validators.py", line 337, in _exec
    v = func(v)
  File "/usr/local/lib/python3.9/site-packages/voluptuous/schema_builder.py", line 272, in __call__
    return self._compiled([], data)
  File "/usr/local/lib/python3.9/site-packages/voluptuous/schema_builder.py", line 817, in validate_callable
    return schema(data)
  File "/usr/local/lib/python3.9/site-packages/voluptuous/schema_builder.py", line 272, in __call__
    return self._compiled([], data)
  File "/usr/local/lib/python3.9/site-packages/voluptuous/schema_builder.py", line 594, in validate_dict
    return base_validate(path, iteritems(data), out)
  File "/usr/local/lib/python3.9/site-packages/voluptuous/schema_builder.py", line 386, in validate_mapping
    cval = cvalue(key_path, value)
  File "/usr/local/lib/python3.9/site-packages/voluptuous/schema_builder.py", line 817, in validate_callable
    return schema(data)
  File "/usr/local/lib/python3.9/site-packages/voluptuous/validators.py", line 741, in __call__
    'value must be one of {}'.format(sorted(self.container)))
TypeError: '<' not supported between instances of 'str' and 'NoneType'
2021-11-13 13:18:43 ERROR (MainThread) [homeassistant.config] Unknown error validating config for integration platform for sensor component with PLATFORM_SCHEMA
Traceback (most recent call last):
  File "/usr/src/homeassistant/homeassistant/config.py", line 895, in async_process_component_config
    p_validated = platform.PLATFORM_SCHEMA(p_config)  # type: ignore
  File "/usr/local/lib/python3.9/site-packages/voluptuous/validators.py", line 218, in __call__
    return self._exec((Schema(val) for val in self.validators), v)
  File "/usr/local/lib/python3.9/site-packages/voluptuous/validators.py", line 337, in _exec
    v = func(v)
  File "/usr/local/lib/python3.9/site-packages/voluptuous/schema_builder.py", line 272, in __call__
    return self._compiled([], data)
  File "/usr/local/lib/python3.9/site-packages/voluptuous/schema_builder.py", line 817, in validate_callable
    return schema(data)
  File "/usr/local/lib/python3.9/site-packages/voluptuous/schema_builder.py", line 272, in __call__
    return self._compiled([], data)
  File "/usr/local/lib/python3.9/site-packages/voluptuous/schema_builder.py", line 594, in validate_dict
    return base_validate(path, iteritems(data), out)
  File "/usr/local/lib/python3.9/site-packages/voluptuous/schema_builder.py", line 386, in validate_mapping
    cval = cvalue(key_path, value)
  File "/usr/local/lib/python3.9/site-packages/voluptuous/schema_builder.py", line 817, in validate_callable
    return schema(data)
  File "/usr/local/lib/python3.9/site-packages/voluptuous/validators.py", line 741, in __call__
    'value must be one of {}'.format(sorted(self.container)))
TypeError: '<' not supported between instances of 'str' and 'NoneType'
2021-11-13 13:18:43 ERROR (MainThread) [homeassistant.config] Unknown error validating config for integration platform for sensor component with PLATFORM_SCHEMA
Traceback (most recent call last):
  File "/usr/src/homeassistant/homeassistant/config.py", line 895, in async_process_component_config
    p_validated = platform.PLATFORM_SCHEMA(p_config)  # type: ignore
  File "/usr/local/lib/python3.9/site-packages/voluptuous/validators.py", line 218, in __call__
    return self._exec((Schema(val) for val in self.validators), v)
  File "/usr/local/lib/python3.9/site-packages/voluptuous/validators.py", line 337, in _exec
    v = func(v)
  File "/usr/local/lib/python3.9/site-packages/voluptuous/schema_builder.py", line 272, in __call__
    return self._compiled([], data)
  File "/usr/local/lib/python3.9/site-packages/voluptuous/schema_builder.py", line 817, in validate_callable
    return schema(data)
  File "/usr/local/lib/python3.9/site-packages/voluptuous/schema_builder.py", line 272, in __call__
    return self._compiled([], data)
  File "/usr/local/lib/python3.9/site-packages/voluptuous/schema_builder.py", line 594, in validate_dict
    return base_validate(path, iteritems(data), out)
  File "/usr/local/lib/python3.9/site-packages/voluptuous/schema_builder.py", line 386, in validate_mapping
    cval = cvalue(key_path, value)
  File "/usr/local/lib/python3.9/site-packages/voluptuous/schema_builder.py", line 817, in validate_callable
    return schema(data)
  File "/usr/local/lib/python3.9/site-packages/voluptuous/validators.py", line 741, in __call__
    'value must be one of {}'.format(sorted(self.container)))
TypeError: '<' not supported between instances of 'str' and 'NoneType'
2021-11-13 13:18:43 ERROR (MainThread) [homeassistant.config] Unknown error validating config for integration platform for sensor component with PLATFORM_SCHEMA
Traceback (most recent call last):
  File "/usr/src/homeassistant/homeassistant/config.py", line 895, in async_process_component_config
    p_validated = platform.PLATFORM_SCHEMA(p_config)  # type: ignore
  File "/usr/local/lib/python3.9/site-packages/voluptuous/validators.py", line 218, in __call__
    return self._exec((Schema(val) for val in self.validators), v)
  File "/usr/local/lib/python3.9/site-packages/voluptuous/validators.py", line 337, in _exec
    v = func(v)
  File "/usr/local/lib/python3.9/site-packages/voluptuous/schema_builder.py", line 272, in __call__
    return self._compiled([], data)
  File "/usr/local/lib/python3.9/site-packages/voluptuous/schema_builder.py", line 817, in validate_callable
    return schema(data)
  File "/usr/local/lib/python3.9/site-packages/voluptuous/schema_builder.py", line 272, in __call__
    return self._compiled([], data)
  File "/usr/local/lib/python3.9/site-packages/voluptuous/schema_builder.py", line 594, in validate_dict
    return base_validate(path, iteritems(data), out)
  File "/usr/local/lib/python3.9/site-packages/voluptuous/schema_builder.py", line 386, in validate_mapping
    cval = cvalue(key_path, value)
  File "/usr/local/lib/python3.9/site-packages/voluptuous/schema_builder.py", line 817, in validate_callable
    return schema(data)
  File "/usr/local/lib/python3.9/site-packages/voluptuous/validators.py", line 741, in __call__
    'value must be one of {}'.format(sorted(self.container)))
TypeError: '<' not supported between instances of 'str' and 'NoneType'
2021-11-13 13:18:45 WARNING (MainThread) [homeassistant.components.light] Platform netatmo not ready yet: None; Retrying in background in 30 seconds
2021-11-13 13:18:45 WARNING (MainThread) [homeassistant.components.select] Platform netatmo not ready yet: None; Retrying in background in 30 seconds
2021-11-13 13:18:45 WARNING (MainThread) [homeassistant.components.hue.light] Please check for software updates of the douche bulb in the Philips Hue App.
2021-11-13 13:18:48 ERROR (MainThread) [homeassistant.components.automation] Platform automation does not generate unique IDs. ID 1629798091047 already exists - ignoring automation.madouce_verlaat_huis_check_mobiel_internet
2021-11-13 13:18:49 ERROR (MainThread) [custom_components.powercalc.sensors.power] Skipping sensor setup light.buiten: ('No lookup file found for mode', 'brightness')
2021-11-13 13:18:49 ERROR (MainThread) [homeassistant.components.hue.sensor_base] Timeout fetching sensor data
2021-11-13 13:18:49 ERROR (MainThread) [homeassistant.components.hue.sensor_base] Timeout fetching sensor data
2021-11-13 13:18:49 WARNING (MainThread) [homeassistant.components.energy.sensor] Found unexpected state_class None for sensor.tv_energy
2021-11-13 13:18:50 WARNING (MainThread) [homeassistant.components.camera] Platform netatmo not ready yet: None; Retrying in background in 30 seconds
2021-11-13 13:18:50 WARNING (MainThread) [homeassistant.components.climate] Platform netatmo not ready yet: None; Retrying in background in 30 seconds
2021-11-13 13:18:50 WARNING (MainThread) [homeassistant.components.binary_sensor] Updating ping binary_sensor took longer than the scheduled update interval 0:00:05
2021-11-13 13:18:50 WARNING (MainThread) [homeassistant.components.sensor] Platform netatmo not ready yet: None; Retrying in background in 30 seconds
2021-11-13 13:18:51 WARNING (MainThread) [homeassistant.config_entries] Config entry 'OnHub' for upnp integration not ready yet; Retrying in background
2021-11-13 13:18:53 ERROR (MainThread) [homeassistant.components.sensor] scrape: Error on device update!
Traceback (most recent call last):
  File "/usr/src/homeassistant/homeassistant/helpers/entity_platform.py", line 431, in _async_add_entity
    await entity.async_device_update(warning=False)
  File "/usr/src/homeassistant/homeassistant/helpers/entity.py", line 651, in async_device_update
    await task
  File "/usr/src/homeassistant/homeassistant/components/scrape/sensor.py", line 166, in async_update
    await self._async_update_from_rest_data()
  File "/usr/src/homeassistant/homeassistant/components/scrape/sensor.py", line 179, in _async_update_from_rest_data
    value = await self.hass.async_add_executor_job(self._extract_value)
  File "/usr/local/lib/python3.9/concurrent/futures/thread.py", line 52, in run
    result = self.fn(*self.args, **self.kwargs)
  File "/usr/src/homeassistant/homeassistant/components/scrape/sensor.py", line 155, in _extract_value
    tag = raw_data.select(self._select)[self._index]
  File "/usr/local/lib/python3.9/site-packages/bs4/element.py", line 1949, in select
    results = soupsieve.select(selector, self, namespaces, limit, **kwargs)
  File "/usr/local/lib/python3.9/site-packages/soupsieve/__init__.py", line 144, in select
    return compile(select, namespaces, flags, **kwargs).select(tag, limit)
  File "/usr/local/lib/python3.9/site-packages/soupsieve/__init__.py", line 67, in compile
    return cp._cached_css_compile(pattern, ns, cs, flags)
  File "/usr/local/lib/python3.9/site-packages/soupsieve/css_parser.py", line 218, in _cached_css_compile
    CSSParser(
  File "/usr/local/lib/python3.9/site-packages/soupsieve/css_parser.py", line 1159, in process_selectors
    return self.parse_selectors(self.selector_iter(self.pattern), index, flags)
  File "/usr/local/lib/python3.9/site-packages/soupsieve/css_parser.py", line 985, in parse_selectors
    key, m = next(iselector)
  File "/usr/local/lib/python3.9/site-packages/soupsieve/css_parser.py", line 1152, in selector_iter
    raise SelectorSyntaxError(msg, self.pattern, index)
soupsieve.util.SelectorSyntaxError: Invalid character '<' position 0
  line 1:
<span _ngcontent-app-root-c173="">Offline</span>
^
2021-11-13 13:18:53 WARNING (MainThread) [homeassistant.components.sensor] Setup of sensor platform scrape is taking over 10 seconds.
2021-11-13 13:18:53 WARNING (MainThread) [homeassistant.components.sensor] Setup of sensor platform scrape is taking over 10 seconds.
2021-11-13 13:18:53 WARNING (MainThread) [homeassistant.components.sensor] Setup of sensor platform scrape is taking over 10 seconds.
2021-11-13 13:18:53 WARNING (MainThread) [homeassistant.components.sensor] Setup of sensor platform scrape is taking over 10 seconds.
2021-11-13 13:18:53 WARNING (MainThread) [homeassistant.components.sensor] Setup of sensor platform scrape is taking over 10 seconds.
2021-11-13 13:18:53 WARNING (MainThread) [homeassistant.components.sensor] Setup of sensor platform scrape is taking over 10 seconds.
2021-11-13 13:18:56 WARNING (MainThread) [homeassistant.components.binary_sensor] Updating ping binary_sensor took longer than the scheduled update interval 0:00:05
2021-11-13 13:19:13 WARNING (MainThread) [homeassistant.components.binary_sensor] Updating ping binary_sensor took longer than the scheduled update interval 0:00:05
2021-11-13 13:19:24 ERROR (MainThread) [homeassistant.components.google_assistant.http] Request for https://homegraph.googleapis.com/v1/devices:requestSync failed: 500
2021-11-13 13:19:24 WARNING (MainThread) [homeassistant.components.binary_sensor] Updating ping binary_sensor took longer than the scheduled update interval 0:00:05
2021-11-13 13:19:24 WARNING (MainThread) [homeassistant.helpers.entity] Update of binary_sensor.google_server is taking over 10 seconds
2021-11-13 13:19:24 ERROR (MainThread) [homeassistant.components.hue.light] Timeout fetching group data
2021-11-13 13:19:25 WARNING (MainThread) [homeassistant.components.media_player] Updating huesyncbox media_player took longer than the scheduled update interval 0:00:02
2021-11-13 13:19:30 ERROR (SyncWorker_17) [homeassistant.components.influxdb] Cannot connect to InfluxDB due to '<urllib3.connection.HTTPConnection object at 0xffff780c6d90>: Failed to establish a new connection: [Errno 111] Connection refused'. Please check that the provided connection details (host, port, etc.) are correct and that your InfluxDB server is running and accessible. Retrying in 60 seconds.
2021-11-13 13:19:32 ERROR (MainThread) [homeassistant.components.google_assistant.http] Request for https://homegraph.googleapis.com/v1/devices:reportStateAndNotification failed: 404
2021-11-13 13:19:33 WARNING (MainThread) [homeassistant.components.binary_sensor] Updating ping binary_sensor took longer than the scheduled update interval 0:00:05
2021-11-13 13:19:53 WARNING (MainThread) [homeassistant.components.binary_sensor] Updating ping binary_sensor took longer than the scheduled update interval 0:00:05
2021-11-13 13:20:30 ERROR (SyncWorker_19) [homeassistant.components.influxdb] Cannot connect to InfluxDB due to '<urllib3.connection.HTTPConnection object at 0xffff762ac6d0>: Failed to establish a new connection: [Errno 111] Connection refused'. Please check that the provided connection details (host, port, etc.) are correct and that your InfluxDB server is running and accessible. Retrying in 60 seconds.
2021-11-13 13:20:37 ERROR (MainThread) [homeassistant.components.google_assistant.http] Request for https://homegraph.googleapis.com/v1/devices:reportStateAndNotification failed: 404
2021-11-13 13:20:51 ERROR (MainThread) [homeassistant.components.google_assistant.http] Request for https://homegraph.googleapis.com/v1/devices:reportStateAndNotification failed: 404
2021-11-13 13:21:08 ERROR (MainThread) [homeassistant.components.google_assistant.http] Request for https://homegraph.googleapis.com/v1/devices:reportStateAndNotification failed: 404
2021-11-13 13:21:20 ERROR (MainThread) [homeassistant.components.google_assistant.http] Request for https://homegraph.googleapis.com/v1/devices:reportStateAndNotification failed: 404
2021-11-13 13:21:30 ERROR (SyncWorker_18) [homeassistant.components.influxdb] Cannot connect to InfluxDB due to '<urllib3.connection.HTTPConnection object at 0xffff8682ca30>: Failed to establish a new connection: [Errno 111] Connection refused'. Please check that the provided connection details (host, port, etc.) are correct and that your InfluxDB server is running and accessible. Retrying in 60 seconds.
2021-11-13 13:22:30 ERROR (SyncWorker_18) [homeassistant.components.influxdb] Cannot connect to InfluxDB due to '<urllib3.connection.HTTPConnection object at 0xffff81954910>: Failed to establish a new connection: [Errno 111] Connection refused'. Please check that the provided connection details (host, port, etc.) are correct and that your InfluxDB server is running and accessible. Retrying in 60 seconds.
2021-11-13 13:23:30 ERROR (SyncWorker_9) [homeassistant.components.influxdb] Cannot connect to InfluxDB due to '<urllib3.connection.HTTPConnection object at 0xffff73bb6940>: Failed to establish a new connection: [Errno 111] Connection refused'. Please check that the provided connection details (host, port, etc.) are correct and that your InfluxDB server is running and accessible. Retrying in 60 seconds.
2021-11-13 13:24:30 ERROR (SyncWorker_18) [homeassistant.components.influxdb] Cannot connect to InfluxDB due to '<urllib3.connection.HTTPConnection object at 0xffff74e98070>: Failed to establish a new connection: [Errno 111] Connection refused'. Please check that the provided connection details (host, port, etc.) are correct and that your InfluxDB server is running and accessible. Retrying in 60 seconds.
2021-11-13 13:25:30 ERROR (SyncWorker_2) [homeassistant.components.influxdb] Cannot connect to InfluxDB due to '<urllib3.connection.HTTPConnection object at 0xffff64628f40>: Failed to establish a new connection: [Errno 111] Connection refused'. Please check that the provided connection details (host, port, etc.) are correct and that your InfluxDB server is running and accessible. Retrying in 60 seconds.
2021-11-13 13:26:30 ERROR (SyncWorker_7) [homeassistant.components.influxdb] Cannot connect to InfluxDB due to '<urllib3.connection.HTTPConnection object at 0xffff73b3bd90>: Failed to establish a new connection: [Errno 111] Connection refused'. Please check that the provided connection details (host, port, etc.) are correct and that your InfluxDB server is running and accessible. Retrying in 60 seconds.
2021-11-13 13:27:30 ERROR (SyncWorker_13) [homeassistant.components.influxdb] Cannot connect to InfluxDB due to '<urllib3.connection.HTTPConnection object at 0xffff756dd310>: Failed to establish a new connection: [Errno 111] Connection refused'. Please check that the provided connection details (host, port, etc.) are correct and that your InfluxDB server is running and accessible. Retrying in 60 seconds.
2021-11-13 13:28:30 ERROR (SyncWorker_0) [homeassistant.components.influxdb] Cannot connect to InfluxDB due to '<urllib3.connection.HTTPConnection object at 0xffff75c1fb50>: Failed to establish a new connection: [Errno 111] Connection refused'. Please check that the provided connection details (host, port, etc.) are correct and that your InfluxDB server is running and accessible. Retrying in 60 seconds.
2021-11-13 13:29:00 ERROR (MainThread) [custom_components.audiconnect.audi_connect_account] Unable to update the vehicle position of WAUZZZGE6MB019131: 204, message='No Content', url=URL('https://fal-3a.prd.eu.dp.vwg-connect.com/fs-car/bs/cf/v1/Audi/BE/vehicles/WAUZZZGE6MB019131/position')
2021-11-13 13:29:30 ERROR (SyncWorker_6) [homeassistant.components.influxdb] Cannot connect to InfluxDB due to '<urllib3.connection.HTTPConnection object at 0xffff75a69c40>: Failed to establish a new connection: [Errno 111] Connection refused'. Please check that the provided connection details (host, port, etc.) are correct and that your InfluxDB server is running and accessible. Retrying in 60 seconds.
2021-11-13 13:30:30 ERROR (SyncWorker_18) [homeassistant.components.influxdb] Cannot connect to InfluxDB due to '<urllib3.connection.HTTPConnection object at 0xffff64635250>: Failed to establish a new connection: [Errno 111] Connection refused'. Please check that the provided connection details (host, port, etc.) are correct and that your InfluxDB server is running and accessible. Retrying in 60 seconds.
2021-11-13 13:31:30 ERROR (SyncWorker_13) [homeassistant.components.influxdb] Cannot connect to InfluxDB due to '<urllib3.connection.HTTPConnection object at 0xffff611cc940>: Failed to establish a new connection: [Errno 111] Connection refused'. Please check that the provided connection details (host, port, etc.) are correct and that your InfluxDB server is running and accessible. Retrying in 60 seconds.
2021-11-13 13:31:53 ERROR (MainThread) [homeassistant.config] Invalid config for [automation]: expected str for dictionary value @ data['from']. Got None. (See ?, line ?). 
2021-11-13 13:31:53 ERROR (MainThread) [homeassistant.config] Invalid config for [automation]: required key not provided @ data['trigger'][1]['platform']. Got None. (See ?, line ?). 
2021-11-13 13:31:53 ERROR (MainThread) [homeassistant.config] Invalid config for [automation]: Unexpected value for condition: 'None'. Expected and, device, not, numeric_state, or, state, sun, template, time, trigger, zone @ data['condition'][0]. Got None. (See ?, line ?). 
2021-11-13 13:31:53 ERROR (MainThread) [homeassistant.config] Invalid config for [automation]: Unexpected value for condition: 'None'. Expected and, device, not, numeric_state, or, state, sun, template, time, trigger, zone @ data['condition'][0]. Got None. (See ?, line ?). 
2021-11-13 13:31:53 ERROR (MainThread) [homeassistant.config] Invalid config for [automation]: required key not provided @ data['action'][4]['domain']. Got None. (See ?, line ?). 
2021-11-13 13:31:53 ERROR (MainThread) [homeassistant.config] Invalid config for [automation]: must be a value between 0 and 59 for dictionary value @ data['minutes']. Got None. (See ?, line ?). 
2021-11-13 13:31:53 ERROR (MainThread) [homeassistant.config] Invalid config for [automation]: must be a value between 0 and 59 for dictionary value @ data['minutes']. Got None. (See ?, line ?). 
